ts_event,ts_recv,rtype,publisher_id,instrument_id,action,side,depth,price,size,flags,ts_in_delta,sequence,bid_px_00,ask_px_00,bid_sz_00,ask_sz_00,bid_ct_00,ask_ct_00,bid_px_01,ask_px_01,bid_sz_01,ask_sz_01,bid_ct_01,ask_ct_01,bid_px_02,ask_px_02,bid_sz_02,ask_sz_02,bid_ct_02,ask_ct_02,bid_px_03,ask_px_03,bid_sz_03,ask_sz_03,bid_ct_03,ask_ct_03,bid_px_04,ask_px_04,bid_sz_04,ask_sz_04,bid_ct_04,ask_ct_04,bid_px_05,ask_px_05,bid_sz_05,ask_sz_05,bid_ct_05,ask_ct_05,bid_px_06,ask_px_06,bid_sz_06,ask_sz_06,bid_ct_06,ask_ct_06,bid_px_07,ask_px_07,bid_sz_07,ask_sz_07,bid_ct_07,ask_ct_07,bid_px_08,ask_px_08,bid_sz_08,ask_sz_08,bid_ct_08,ask_ct_08,bid_px_09,ask_px_09,bid_sz_09,ask_sz_09,bid_ct_09,ask_ct_09,symbol,best_level_ofi,multi_level_ofi,integrated_ofi_1s,cross_asset_ofi
2024-10-21 12:16:49.709446277+00:00,2024-10-21T12:16:49.709612912Z,10,2,38,A,A,0,234.09,200,130,166635,12585999,233.7,234.09,1200,400,1,2,233.68,234.1,227,100,2,1,233.66,234.13,1,400,1,1,233.58,234.17,505,1,2,1,233.53,234.25,10,100,1,1,233.5,234.41,100,600,1,2,233.45,234.43,15,105,1,2,233.4,234.5,110,63,2,4,233.39,234.75,10,1,1,1,233.31,234.79,110,2000,2,1,AAPL,-200.0,-200.0,0.0,
2024-10-21 12:16:50.277262708+00:00,2024-10-21T12:16:50.277429428Z,10,2,38,C,B,1,233.68,27,130,166720,12586408,233.7,234.09,1200,400,1,2,233.68,234.1,200,100,1,1,233.66,234.13,1,400,1,1,233.58,234.17,505,1,2,1,233.53,234.25,10,100,1,1,233.5,234.41,100,600,1,2,233.45,234.43,15,105,1,2,233.4,234.5,110,63,2,4,233.39,234.75,10,1,1,1,233.31,234.79,110,2000,2,1,AAPL,0.0,-27.0,0.0,
2024-10-21 12:16:50.277350058+00:00,2024-10-21T12:16:50.277516325Z,10,2,38,A,A,3,234.17,27,130,166267,12586409,233.7,234.09,1200,400,1,2,233.68,234.1,200,100,1,1,233.66,234.13,1,400,1,1,233.58,234.17,505,28,2,2,233.53,234.25,10,100,1,1,233.5,234.41,100,600,1,2,233.45,234.43,15,105,1,2,233.4,234.5,110,63,2,4,233.39,234.75,10,1,1,1,233.31,234.79,110,2000,2,1,AAPL,0.0,-27.0,0.0,
2024-10-21 12:16:50.277381197+00:00,2024-10-21T12:16:50.277547866Z,10,2,38,A,B,1,233.69,27,130,166669,12586410,233.7,234.09,1200,400,1,2,233.69,234.1,27,100,1,1,233.68,234.13,200,400,1,1,233.66,234.17,1,28,1,2,233.58,234.25,505,100,2,1,233.53,234.41,10,600,1,2,233.5,234.43,100,105,1,2,233.45,234.5,15,63,1,4,233.4,234.75,110,1,2,1,233.39,234.79,10,2000,1,1,AAPL,0.0,0.0,0.0,
2024-10-21 12:16:50.981459165+00:00,2024-10-21T12:16:50.981625530Z,10,2,38,A,B,0,233.7,200,130,166365,12587468,233.7,234.09,1400,400,2,2,233.69,234.1,27,100,1,1,233.66,234.13,1,400,1,1,233.58,234.17,505,28,2,2,233.53,234.25,10,100,1,1,233.5,234.41,100,600,1,2,233.45,234.43,15,105,1,2,233.4,234.5,110,63,2,4,233.39,234.75,10,1,1,1,233.31,234.79,110,2000,2,1,AAPL,200.0,200.0,200.0,
2024-10-21 12:16:51.768772781+00:00,2024-10-21T12:16:51.768939105Z,10,2,38,A,B,0,233.85,141,130,166324,12588253,233.85,234.09,141,400,1,2,233.7,234.1,1400,100,2,1,233.69,234.13,27,400,1,1,233.66,234.17,1,28,1,2,233.58,234.25,505,100,2,1,233.53,234.41,10,600,1,2,233.5,234.43,100,105,1,2,233.45,234.5,15,63,1,4,233.4,234.75,110,1,2,1,233.39,234.79,10,2000,1,1,AAPL,0.0,0.0,200.0,
2024-10-21 12:16:54.799759269+00:00,2024-10-21T12:16:54.799926585Z,10,2,38,T,N,0,233.86,13,130,167316,12591024,233.85,234.09,141,400,1,2,233.7,234.1,1400,100,2,1,233.69,234.13,27,400,1,1,233.66,234.17,1,28,1,2,233.58,234.25,505,100,2,1,233.53,234.41,10,600,1,2,233.5,234.43,100,105,1,2,233.45,234.5,15,63,1,4,233.4,234.75,110,1,2,1,233.39,234.79,10,2000,1,1,AAPL,0.0,0.0,0.0,
2024-10-21 12:16:54.862528040+00:00,2024-10-21T12:16:54.862694065Z,10,2,38,C,A,3,234.17,27,130,166025,12591058,233.85,234.09,141,400,1,2,233.7,234.1,1400,100,2,1,233.69,234.13,27,400,1,1,233.66,234.17,1,1,1,1,233.58,234.25,505,100,2,1,233.53,234.41,10,600,1,2,233.5,234.43,100,105,1,2,233.45,234.5,15,63,1,4,233.4,234.75,110,1,2,1,233.39,234.79,10,2000,1,1,AAPL,0.0,27.0,0.0,
2024-10-21 12:16:54.862652964+00:00,2024-10-21T12:16:54.862819345Z,10,2,38,A,A,3,234.16,30,130,166381,12591059,233.85,234.09,141,400,1,2,233.7,234.1,1400,100,2,1,233.69,234.13,27,400,1,1,233.66,234.16,1,30,1,1,233.58,234.17,505,1,2,1,233.53,234.25,10,100,1,1,233.5,234.41,100,600,1,2,233.45,234.43,15,105,1,2,233.4,234.5,110,63,2,4,233.39,234.75,10,1,1,1,AAPL,0.0,0.0,0.0,
2024-10-21 12:17:02.456505763+00:00,2024-10-21T12:17:02.456671669Z,10,2,38,C,A,0,234.09,200,130,165906,12600010,233.85,234.09,141,200,1,1,233.7,234.1,1400,100,2,1,233.69,234.13,27,400,1,1,233.66,234.16,1,30,1,1,233.58,234.17,505,1,2,1,233.53,234.25,10,100,1,1,233.5,234.41,100,600,1,2,233.45,234.43,15,105,1,2,233.4,234.5,110,63,2,4,233.39,234.75,10,1,1,1,AAPL,200.0,200.0,200.0,
2024-10-21 12:17:02.456518211+00:00,2024-10-21T12:17:02.456684400Z,10,2,38,A,A,0,234.08,400,130,166189,12600011,233.85,234.08,141,400,1,1,233.7,234.1,1400,100,2,1,233.69,234.13,27,400,1,1,233.66,234.16,1,30,1,1,233.58,234.17,505,1,2,1,233.53,234.25,10,100,1,1,233.5,234.41,100,600,1,2,233.45,234.43,15,105,1,2,233.4,234.5,110,63,2,4,233.39,234.75,10,1,1,1,AAPL,0.0,0.0,200.0,
2024-10-21 12:17:02.692703742+00:00,2024-10-21T12:17:02.692870111Z,10,2,38,A,B,1,233.7,200,130,166369,12600199,233.85,234.08,141,400,1,1,233.7,234.1,1600,100,3,1,233.69,234.13,27,400,1,1,233.66,234.16,1,30,1,1,233.58,234.17,505,1,2,1,233.53,234.25,10,100,1,1,233.5,234.41,100,600,1,2,233.45,234.43,15,105,1,2,233.4,234.5,110,63,2,4,233.39,234.75,10,1,1,1,AAPL,0.0,200.0,200.0,
2024-10-21 12:17:02.695735412+00:00,2024-10-21T12:17:02.695901737Z,10,2,38,A,B,1,233.73,27,130,166325,12600202,233.85,234.08,141,400,1,1,233.73,234.1,27,100,1,1,233.7,234.13,1600,400,3,1,233.69,234.16,27,30,1,1,233.66,234.17,1,1,1,1,233.58,234.25,505,100,2,1,233.53,234.41,10,600,1,2,233.5,234.43,100,105,1,2,233.45,234.5,15,63,1,4,233.4,234.75,110,1,2,1,AAPL,0.0,0.0,200.0,
2024-10-21 12:17:02.695762734+00:00,2024-10-21T12:17:02.695928779Z,10,2,38,C,B,3,233.69,27,130,166045,12600203,233.85,234.08,141,400,1,1,233.73,234.1,27,100,1,1,233.7,234.13,1600,400,3,1,233.66,234.16,1,30,1,1,233.58,234.17,505,1,2,1,233.53,234.25,10,100,1,1,233.5,234.41,100,600,1,2,233.45,234.43,15,105,1,2,233.4,234.5,110,63,2,4,233.39,234.75,10,1,1,1,AAPL,0.0,0.0,200.0,
2024-10-21 12:17:02.743941560+00:00,2024-10-21T12:17:02.744107650Z,10,2,38,C,B,2,233.7,200,130,166090,12600243,233.85,234.08,141,400,1,1,233.73,234.1,27,100,1,1,233.7,234.13,1400,400,2,1,233.66,234.16,1,30,1,1,233.58,234.17,505,1,2,1,233.53,234.25,10,100,1,1,233.5,234.41,100,600,1,2,233.45,234.43,15,105,1,2,233.4,234.5,110,63,2,4,233.39,234.75,10,1,1,1,AAPL,0.0,-200.0,200.0,
2024-10-21 12:17:02.743954174+00:00,2024-10-21T12:17:02.744120623Z,10,2,38,A,B,1,233.77,200,130,166449,12600244,233.85,234.08,141,400,1,1,233.77,234.1,200,100,1,1,233.73,234.13,27,400,1,1,233.7,234.16,1200,30,1,1,233.66,234.17,1,1,1,1,233.58,234.25,505,100,2,1,233.53,234.41,10,600,1,2,233.5,234.43,100,105,1,2,233.45,234.5,15,63,1,4,233.4,234.75,110,1,2,1,AAPL,0.0,0.0,200.0,
2024-10-21 12:17:04.308725875+00:00,2024-10-21T12:17:04.308892470Z,10,2,38,C,A,3,234.16,30,130,166595,12602099,233.85,234.08,141,400,1,1,233.77,234.1,200,100,1,1,233.73,234.13,27,400,1,1,233.7,234.17,1200,1,1,1,233.66,234.25,1,100,1,1,233.58,234.41,505,600,2,2,233.53,234.43,10,105,1,2,233.5,234.5,100,63,1,4,233.45,234.75,15,1,1,1,233.4,234.79,110,2000,2,1,AAPL,0.0,0.0,0.0,
2024-10-21 12:17:04.308776780+00:00,2024-10-21T12:17:04.308942951Z,10,2,38,A,A,3,234.15,26,130,166171,12602100,233.85,234.08,141,400,1,1,233.77,234.1,200,100,1,1,233.73,234.13,27,400,1,1,233.7,234.15,1200,26,1,1,233.66,234.17,1,1,1,1,233.58,234.25,505,100,2,1,233.53,234.41,10,600,1,2,233.5,234.43,100,105,1,2,233.45,234.5,15,63,1,4,233.4,234.75,110,1,2,1,AAPL,0.0,0.0,0.0,
2024-10-21 12:17:06.048294911+00:00,2024-10-21T12:17:06.048460890Z,10,2,38,C,B,1,233.77,200,130,165979,12604816,233.85,234.08,141,400,1,1,233.73,234.1,27,100,1,1,233.7,234.13,1200,400,1,1,233.66,234.15,1,26,1,1,233.58,234.17,505,1,2,1,233.53,234.25,10,100,1,1,233.5,234.41,100,600,1,2,233.45,234.43,15,105,1,2,233.4,234.5,110,63,2,4,233.39,234.75,10,1,1,1,AAPL,0.0,0.0,0.0,
2024-10-21 12:17:06.048308319+00:00,2024-10-21T12:17:06.048474822Z,10,2,38,A,B,1,233.74,200,130,166503,12604817,233.85,234.08,141,400,1,1,233.74,234.1,200,100,1,1,233.73,234.13,27,400,1,1,233.7,234.15,1200,26,1,1,233.66,234.17,1,1,1,1,233.58,234.25,505,100,2,1,233.53,234.41,10,600,1,2,233.5,234.43,100,105,1,2,233.45,234.5,15,63,1,4,233.4,234.75,110,1,2,1,AAPL,0.0,0.0,0.0,
2024-10-21 12:17:07.403868087+00:00,2024-10-21T12:17:07.404034239Z,10,2,38,A,B,1,233.74,200,130,166152,12606471,233.85,234.08,141,400,1,1,233.74,234.1,400,100,2,1,233.73,234.13,27,400,1,1,233.7,234.15,1200,26,1,1,233.66,234.17,1,1,1,1,233.58,234.25,505,100,2,1,233.53,234.41,10,600,1,2,233.5,234.43,100,105,1,2,233.45,234.5,15,63,1,4,233.4,234.75,110,1,2,1,AAPL,0.0,200.0,0.0,
2024-10-21 12:17:07.458672320+00:00,2024-10-21T12:17:07.458838488Z,10,2,38,C,B,1,233.74,200,130,166168,12606559,233.85,234.08,141,400,1,1,233.74,234.1,200,100,1,1,233.73,234.13,27,400,1,1,233.7,234.15,1200,26,1,1,233.66,234.17,1,1,1,1,233.58,234.25,505,100,2,1,233.53,234.41,10,600,1,2,233.5,234.43,100,105,1,2,233.45,234.5,15,63,1,4,233.4,234.75,110,1,2,1,AAPL,0.0,-200.0,0.0,
2024-10-21 12:17:07.458684918+00:00,2024-10-21T12:17:07.458851802Z,10,2,38,A,B,1,233.77,200,130,166884,12606560,233.85,234.08,141,400,1,1,233.77,234.1,200,100,1,1,233.73,234.13,27,400,1,1,233.7,234.15,1200,26,1,1,233.66,234.17,1,1,1,1,233.58,234.25,505,100,2,1,233.53,234.41,10,600,1,2,233.5,234.43,100,105,1,2,233.45,234.5,15,63,1,4,233.4,234.75,110,1,2,1,AAPL,0.0,0.0,0.0,
2024-10-21 12:17:10.980069944+00:00,2024-10-21T12:17:10.980236242Z,10,2,38,C,B,1,233.77,200,130,166298,12610019,233.85,234.08,141,400,1,1,233.73,234.1,27,100,1,1,233.7,234.13,1200,400,1,1,233.66,234.15,1,26,1,1,233.58,234.17,505,1,2,1,233.53,234.25,10,100,1,1,233.5,234.41,100,600,1,2,233.45,234.43,15,105,1,2,233.4,234.5,110,63,2,4,233.39,234.75,10,1,1,1,AAPL,0.0,0.0,0.0,
2024-10-21 12:17:10.980083268+00:00,2024-10-21T12:17:10.980249439Z,10,2,38,A,B,1,233.74,200,130,166171,12610020,233.85,234.08,141,400,1,1,233.74,234.1,200,100,1,1,233.73,234.13,27,400,1,1,233.7,234.15,1200,26,1,1,233.66,234.17,1,1,1,1,233.58,234.25,505,100,2,1,233.53,234.41,10,600,1,2,233.5,234.43,100,105,1,2,233.45,234.5,15,63,1,4,233.4,234.75,110,1,2,1,AAPL,0.0,0.0,0.0,
2024-10-21 12:17:16.046891679+00:00,2024-10-21T12:17:16.047057825Z,10,2,38,A,B,1,233.74,200,130,166146,12615898,233.85,234.08,141,400,1,1,233.74,234.1,400,100,2,1,233.73,234.13,27,400,1,1,233.7,234.15,1200,26,1,1,233.66,234.17,1,1,1,1,233.58,234.25,505,100,2,1,233.53,234.41,10,600,1,2,233.5,234.43,100,105,1,2,233.45,234.5,15,63,1,4,233.4,234.75,110,1,2,1,AAPL,0.0,200.0,0.0,
2024-10-21 12:17:16.101320234+00:00,2024-10-21T12:17:16.101486118Z,10,2,38,C,B,1,233.74,200,130,165884,12616034,233.85,234.08,141,400,1,1,233.74,234.1,200,100,1,1,233.73,234.13,27,400,1,1,233.7,234.15,1200,26,1,1,233.66,234.17,1,1,1,1,233.58,234.25,505,100,2,1,233.53,234.41,10,600,1,2,233.5,234.43,100,105,1,2,233.45,234.5,15,63,1,4,233.4,234.75,110,1,2,1,AAPL,0.0,-200.0,0.0,
2024-10-21 12:17:16.101332500+00:00,2024-10-21T12:17:16.101498861Z,10,2,38,A,B,1,233.77,200,130,166361,12616035,233.85,234.08,141,400,1,1,233.77,234.1,200,100,1,1,233.73,234.13,27,400,1,1,233.7,234.15,1200,26,1,1,233.66,234.17,1,1,1,1,233.58,234.25,505,100,2,1,233.53,234.41,10,600,1,2,233.5,234.43,100,105,1,2,233.45,234.5,15,63,1,4,233.4,234.75,110,1,2,1,AAPL,0.0,0.0,0.0,
2024-10-21 12:17:18.814227520+00:00,2024-10-21T12:17:18.814393783Z,10,2,38,A,B,0,233.9,10,130,166263,12619312,233.9,234.08,10,400,1,1,233.85,234.1,141,100,1,1,233.77,234.13,200,400,1,1,233.73,234.15,27,26,1,1,233.7,234.17,1200,1,1,1,233.66,234.25,1,100,1,1,233.58,234.41,505,600,2,2,233.53,234.43,10,105,1,2,233.5,234.5,100,63,1,4,233.45,234.75,15,1,1,1,AAPL,0.0,0.0,0.0,
2024-10-21 12:17:20.656823195+00:00,2024-10-21T12:17:20.656989311Z,10,2,38,C,B,2,233.77,200,130,166116,12621045,233.9,234.08,10,400,1,1,233.85,234.1,141,100,1,1,233.73,234.13,27,400,1,1,233.7,234.15,1200,26,1,1,233.66,234.17,1,1,1,1,233.58,234.25,505,100,2,1,233.53,234.41,10,600,1,2,233.5,234.43,100,105,1,2,233.45,234.5,15,63,1,4,233.4,234.75,110,1,2,1,AAPL,0.0,0.0,0.0,
2024-10-21 12:17:20.662283454+00:00,2024-10-21T12:17:20.662449680Z,10,2,38,A,A,0,234.05,100,130,166226,12621054,233.9,234.05,10,100,1,1,233.85,234.08,141,400,1,1,233.73,234.1,27,100,1,1,233.7,234.13,1200,400,1,1,233.66,234.15,1,26,1,1,233.58,234.17,505,1,2,1,233.53,234.25,10,100,1,1,233.5,234.41,100,600,1,2,233.45,234.43,15,105,1,2,233.4,234.5,110,63,2,4,AAPL,0.0,0.0,0.0,
2024-10-21 12:17:20.662744252+00:00,2024-10-21T12:17:20.662910009Z,10,2,38,C,A,0,234.05,100,130,165757,12621055,233.9,234.08,10,400,1,1,233.85,234.1,141,100,1,1,233.73,234.13,27,400,1,1,233.7,234.15,1200,26,1,1,233.66,234.17,1,1,1,1,233.58,234.25,505,100,2,1,233.53,234.41,10,600,1,2,233.5,234.43,100,105,1,2,233.45,234.5,15,63,1,4,233.4,234.75,110,1,2,1,AAPL,0.0,0.0,0.0,
2024-10-21 12:17:20.719761250+00:00,2024-10-21T12:17:20.719927826Z,10,2,38,C,A,0,234.08,200,130,166576,12621104,233.9,234.08,10,200,1,1,233.85,234.1,141,100,1,1,233.73,234.13,27,400,1,1,233.7,234.15,1200,26,1,1,233.66,234.17,1,1,1,1,233.58,234.25,505,100,2,1,233.53,234.41,10,600,1,2,233.5,234.43,100,105,1,2,233.45,234.5,15,63,1,4,233.4,234.75,110,1,2,1,AAPL,200.0,200.0,200.0,
2024-10-21 12:17:20.762539880+00:00,2024-10-21T12:17:20.762706336Z,10,2,38,A,B,2,233.77,200,130,166456,12621151,233.9,234.08,10,200,1,1,233.85,234.1,141,100,1,1,233.77,234.13,200,400,1,1,233.73,234.15,27,26,1,1,233.7,234.17,1200,1,1,1,233.66,234.25,1,100,1,1,233.58,234.41,505,600,2,2,233.53,234.43,10,105,1,2,233.5,234.5,100,63,1,4,233.45,234.75,15,1,1,1,AAPL,0.0,0.0,200.0,
2024-10-21 12:17:21.078904005+00:00,2024-10-21T12:17:21.079070269Z,10,2,38,A,B,2,233.77,200,130,166264,12621965,233.9,234.08,10,200,1,1,233.85,234.1,141,100,1,1,233.77,234.13,400,400,2,1,233.73,234.15,27,26,1,1,233.7,234.17,1200,1,1,1,233.66,234.25,1,100,1,1,233.58,234.41,505,600,2,2,233.53,234.43,10,105,1,2,233.5,234.5,100,63,1,4,233.45,234.75,15,1,1,1,AAPL,0.0,200.0,200.0,
2024-10-21 12:17:21.133609901+00:00,2024-10-21T12:17:21.133776008Z,10,2,38,C,B,2,233.77,200,130,166107,12622031,233.9,234.08,10,200,1,1,233.85,234.1,141,100,1,1,233.77,234.13,200,400,1,1,233.73,234.15,27,26,1,1,233.7,234.17,1200,1,1,1,233.66,234.25,1,100,1,1,233.58,234.41,505,600,2,2,233.53,234.43,10,105,1,2,233.5,234.5,100,63,1,4,233.45,234.75,15,1,1,1,AAPL,0.0,-200.0,200.0,
2024-10-21 12:17:21.133623109+00:00,2024-10-21T12:17:21.133789577Z,10,2,38,A,B,2,233.8,400,130,166468,12622032,233.9,234.08,10,200,1,1,233.85,234.1,141,100,1,1,233.8,234.13,400,400,1,1,233.73,234.15,27,26,1,1,233.7,234.17,1200,1,1,1,233.66,234.25,1,100,1,1,233.58,234.41,505,600,2,2,233.53,234.43,10,105,1,2,233.5,234.5,100,63,1,4,233.45,234.75,15,1,1,1,AAPL,0.0,0.0,200.0,
2024-10-21 12:17:21.840211165+00:00,2024-10-21T12:17:21.840377137Z,10,2,38,C,A,0,234.08,200,130,165972,12622599,233.9,234.1,10,100,1,1,233.85,234.13,141,400,1,1,233.8,234.15,400,26,1,1,233.73,234.17,27,1,1,1,233.7,234.25,1200,100,1,1,233.66,234.41,1,600,1,2,233.58,234.43,505,105,2,2,233.53,234.5,10,63,1,4,233.5,234.75,100,1,1,1,233.45,234.79,15,2000,1,1,AAPL,0.0,0.0,0.0,
2024-10-21 12:17:21.840224418+00:00,2024-10-21T12:17:21.840390874Z,10,2,38,A,A,2,234.14,200,130,166456,12622600,233.9,234.1,10,100,1,1,233.85,234.13,141,400,1,1,233.8,234.14,400,200,1,1,233.73,234.15,27,26,1,1,233.7,234.17,1200,1,1,1,233.66,234.25,1,100,1,1,233.58,234.41,505,600,2,2,233.53,234.43,10,105,1,2,233.5,234.5,100,63,1,4,233.45,234.75,15,1,1,1,AAPL,0.0,0.0,0.0,
2024-10-21 12:17:22.072304747+00:00,2024-10-21T12:17:22.072471402Z,10,2,38,A,A,1,234.13,200,130,166655,12622909,233.9,234.1,10,100,1,1,233.85,234.13,141,600,1,2,233.8,234.15,400,26,1,1,233.73,234.17,27,1,1,1,233.7,234.25,1200,100,1,1,233.66,234.41,1,600,1,2,233.58,234.43,505,105,2,2,233.53,234.5,10,63,1,4,233.5,234.75,100,1,1,1,233.45,234.79,15,2000,1,1,AAPL,0.0,-200.0,0.0,
2024-10-21 12:17:22.085707892+00:00,2024-10-21T12:17:22.085874150Z,10,2,38,A,A,0,234.0,50,130,166258,12622918,233.9,234.0,10,50,1,1,233.85,234.1,141,100,1,1,233.8,234.13,400,600,1,2,233.73,234.15,27,26,1,1,233.7,234.17,1200,1,1,1,233.66,234.25,1,100,1,1,233.58,234.41,505,600,2,2,233.53,234.43,10,105,1,2,233.5,234.5,100,63,1,4,233.45,234.75,15,1,1,1,AAPL,0.0,0.0,0.0,
2024-10-21 12:17:24.840366131+00:00,2024-10-21T12:17:24.840534781Z,10,2,38,A,A,2,234.13,200,130,168650,12624574,233.9,234.0,10,50,1,1,233.85,234.1,141,100,1,1,233.8,234.13,400,800,1,3,233.73,234.15,27,26,1,1,233.7,234.17,1200,1,1,1,233.66,234.25,1,100,1,1,233.58,234.41,505,600,2,2,233.53,234.43,10,105,1,2,233.5,234.5,100,63,1,4,233.45,234.75,15,1,1,1,AAPL,0.0,-200.0,0.0,
2024-10-21 12:17:24.840795392+00:00,2024-10-21T12:17:24.840961517Z,10,2,38,A,A,1,234.1,28,130,166125,12624575,233.9,234.0,10,50,1,1,233.85,234.1,141,128,1,2,233.8,234.13,400,800,1,3,233.73,234.15,27,26,1,1,233.7,234.17,1200,1,1,1,233.66,234.25,1,100,1,1,233.58,234.41,505,600,2,2,233.53,234.43,10,105,1,2,233.5,234.5,100,63,1,4,233.45,234.75,15,1,1,1,AAPL,0.0,-28.0,0.0,
2024-10-21 12:17:24.840821231+00:00,2024-10-21T12:17:24.840987330Z,10,2,38,C,A,3,234.15,26,130,166099,12624576,233.9,234.0,10,50,1,1,233.85,234.1,141,128,1,2,233.8,234.13,400,800,1,3,233.73,234.17,27,1,1,1,233.7,234.25,1200,100,1,1,233.66,234.41,1,600,1,2,233.58,234.43,505,105,2,2,233.53,234.5,10,63,1,4,233.5,234.75,100,1,1,1,233.45,234.79,15,2000,1,1,AAPL,0.0,0.0,0.0,
2024-10-21 12:17:24.896015668+00:00,2024-10-21T12:17:24.896181576Z,10,2,38,C,A,2,234.13,200,130,165908,12624585,233.9,234.0,10,50,1,1,233.85,234.1,141,128,1,2,233.8,234.13,400,600,1,2,233.73,234.17,27,1,1,1,233.7,234.25,1200,100,1,1,233.66,234.41,1,600,1,2,233.58,234.43,505,105,2,2,233.53,234.5,10,63,1,4,233.5,234.75,100,1,1,1,233.45,234.79,15,2000,1,1,AAPL,0.0,200.0,0.0,
2024-10-21 12:17:24.896030774+00:00,2024-10-21T12:17:24.896197156Z,10,2,38,A,A,1,234.04,200,130,166382,12624586,233.9,234.0,10,50,1,1,233.85,234.04,141,200,1,1,233.8,234.1,400,128,1,2,233.73,234.13,27,400,1,1,233.7,234.17,1200,1,1,1,233.66,234.25,1,100,1,1,233.58,234.41,505,600,2,2,233.53,234.43,10,105,1,2,233.5,234.5,100,63,1,4,233.45,234.75,15,1,1,1,AAPL,0.0,0.0,0.0,
2024-10-21 12:17:26.219727754+00:00,2024-10-21T12:17:26.219893772Z,10,2,38,C,A,2,234.1,28,130,166018,12625936,233.9,234.0,10,50,1,1,233.85,234.04,141,200,1,1,233.8,234.1,400,100,1,1,233.73,234.13,27,400,1,1,233.7,234.17,1200,1,1,1,233.66,234.25,1,100,1,1,233.58,234.41,505,600,2,2,233.53,234.43,10,105,1,2,233.5,234.5,100,63,1,4,233.45,234.75,15,1,1,1,AAPL,0.0,28.0,0.0,
2024-10-21 12:17:26.219824269+00:00,2024-10-21T12:17:26.219990353Z,10,2,38,A,A,2,234.09,27,130,166084,12625937,233.9,234.0,10,50,1,1,233.85,234.04,141,200,1,1,233.8,234.09,400,27,1,1,233.73,234.1,27,100,1,1,233.7,234.13,1200,400,1,1,233.66,234.17,1,1,1,1,233.58,234.25,505,100,2,1,233.53,234.41,10,600,1,2,233.5,234.43,100,105,1,2,233.45,234.5,15,63,1,4,AAPL,0.0,0.0,0.0,
2024-10-21 12:17:26.286945437+00:00,2024-10-21T12:17:26.287111991Z,10,2,38,A,A,1,234.03,200,130,166554,12626109,233.9,234.0,10,50,1,1,233.85,234.03,141,200,1,1,233.8,234.09,400,27,1,1,233.73,234.1,27,100,1,1,233.7,234.13,1200,400,1,1,233.66,234.17,1,1,1,1,233.58,234.25,505,100,2,1,233.53,234.41,10,600,1,2,233.5,234.43,100,105,1,2,233.45,234.5,15,63,1,4,AAPL,0.0,0.0,0.0,
2024-10-21 12:17:30.761645371+00:00,2024-10-21T12:17:30.761811610Z,10,2,38,C,A,1,234.03,200,130,166239,12633053,233.9,234.0,10,50,1,1,233.85,234.09,141,27,1,1,233.8,234.1,400,100,1,1,233.73,234.13,27,400,1,1,233.7,234.17,1200,1,1,1,233.66,234.25,1,100,1,1,233.58,234.41,505,600,2,2,233.53,234.43,10,105,1,2,233.5,234.5,100,63,1,4,233.45,234.75,15,1,1,1,AAPL,0.0,0.0,0.0,
2024-10-21 12:17:30.761657680+00:00,2024-10-21T12:17:30.761824012Z,10,2,38,A,A,1,234.08,200,130,166332,12633054,233.9,234.0,10,50,1,1,233.85,234.08,141,200,1,1,233.8,234.09,400,27,1,1,233.73,234.1,27,100,1,1,233.7,234.13,1200,400,1,1,233.66,234.17,1,1,1,1,233.58,234.25,505,100,2,1,233.53,234.41,10,600,1,2,233.5,234.43,100,105,1,2,233.45,234.5,15,63,1,4,AAPL,0.0,0.0,0.0,
2024-10-21 12:17:30.762940179+00:00,2024-10-21T12:17:30.763106554Z,10,2,38,A,A,1,234.08,200,130,166375,12633055,233.9,234.0,10,50,1,1,233.85,234.08,141,400,1,2,233.8,234.09,400,27,1,1,233.73,234.1,27,100,1,1,233.7,234.13,1200,400,1,1,233.66,234.17,1,1,1,1,233.58,234.25,505,100,2,1,233.53,234.41,10,600,1,2,233.5,234.43,100,105,1,2,233.45,234.5,15,63,1,4,AAPL,0.0,-200.0,0.0,
2024-10-21 12:17:30.764592400+00:00,2024-10-21T12:17:30.764758511Z,10,2,38,C,A,2,234.09,27,130,166111,12633057,233.9,234.0,10,50,1,1,233.85,234.08,141,400,1,2,233.8,234.1,400,100,1,1,233.73,234.13,27,400,1,1,233.7,234.17,1200,1,1,1,233.66,234.25,1,100,1,1,233.58,234.41,505,600,2,2,233.53,234.43,10,105,1,2,233.5,234.5,100,63,1,4,233.45,234.75,15,1,1,1,AAPL,0.0,0.0,0.0,
2024-10-21 12:17:30.764692359+00:00,2024-10-21T12:17:30.764858610Z,10,2,38,A,A,4,234.15,29,130,166251,12633058,233.9,234.0,10,50,1,1,233.85,234.08,141,400,1,2,233.8,234.1,400,100,1,1,233.73,234.13,27,400,1,1,233.7,234.15,1200,29,1,1,233.66,234.17,1,1,1,1,233.58,234.25,505,100,2,1,233.53,234.41,10,600,1,2,233.5,234.43,100,105,1,2,233.45,234.5,15,63,1,4,AAPL,0.0,0.0,0.0,
2024-10-21 12:17:33.378283593+00:00,2024-10-21T12:17:33.378449675Z,10,2,38,C,B,2,233.8,400,130,166082,12636437,233.9,234.0,10,50,1,1,233.85,234.08,141,400,1,2,233.73,234.1,27,100,1,1,233.7,234.13,1200,400,1,1,233.66,234.15,1,29,1,1,233.58,234.17,505,1,2,1,233.53,234.25,10,100,1,1,233.5,234.41,100,600,1,2,233.45,234.43,15,105,1,2,233.4,234.5,110,63,2,4,AAPL,0.0,0.0,0.0,
2024-10-21 12:17:33.378297030+00:00,2024-10-21T12:17:33.378463077Z,10,2,38,A,B,2,233.77,200,130,166047,12636438,233.9,234.0,10,50,1,1,233.85,234.08,141,400,1,2,233.77,234.1,200,100,1,1,233.73,234.13,27,400,1,1,233.7,234.15,1200,29,1,1,233.66,234.17,1,1,1,1,233.58,234.25,505,100,2,1,233.53,234.41,10,600,1,2,233.5,234.43,100,105,1,2,233.45,234.5,15,63,1,4,AAPL,0.0,0.0,0.0,
2024-10-21 12:17:33.764809990+00:00,2024-10-21T12:17:33.764976450Z,10,2,38,A,A,2,234.09,29,130,166460,12637750,233.9,234.0,10,50,1,1,233.85,234.08,141,400,1,2,233.77,234.09,200,29,1,1,233.73,234.1,27,100,1,1,233.7,234.13,1200,400,1,1,233.66,234.15,1,29,1,1,233.58,234.17,505,1,2,1,233.53,234.25,10,100,1,1,233.5,234.41,100,600,1,2,233.45,234.43,15,105,1,2,AAPL,0.0,0.0,0.0,
2024-10-21 12:17:33.764834502+00:00,2024-10-21T12:17:33.765000603Z,10,2,38,C,A,5,234.15,29,130,166101,12637751,233.9,234.0,10,50,1,1,233.85,234.08,141,400,1,2,233.77,234.09,200,29,1,1,233.73,234.1,27,100,1,1,233.7,234.13,1200,400,1,1,233.66,234.17,1,1,1,1,233.58,234.25,505,100,2,1,233.53,234.41,10,600,1,2,233.5,234.43,100,105,1,2,233.45,234.5,15,63,1,4,AAPL,0.0,0.0,0.0,
2024-10-21 12:17:33.822822391+00:00,2024-10-21T12:17:33.822988558Z,10,2,38,C,A,1,234.08,200,130,166167,12637806,233.9,234.0,10,50,1,1,233.85,234.08,141,200,1,1,233.77,234.09,200,29,1,1,233.73,234.1,27,100,1,1,233.7,234.13,1200,400,1,1,233.66,234.17,1,1,1,1,233.58,234.25,505,100,2,1,233.53,234.41,10,600,1,2,233.5,234.43,100,105,1,2,233.45,234.5,15,63,1,4,AAPL,0.0,200.0,0.0,
2024-10-21 12:17:33.822835795+00:00,2024-10-21T12:17:33.823002310Z,10,2,38,A,A,1,234.03,200,130,166515,12637807,233.9,234.0,10,50,1,1,233.85,234.03,141,200,1,1,233.77,234.09,200,29,1,1,233.73,234.1,27,100,1,1,233.7,234.13,1200,400,1,1,233.66,234.17,1,1,1,1,233.58,234.25,505,100,2,1,233.53,234.41,10,600,1,2,233.5,234.43,100,105,1,2,233.45,234.5,15,63,1,4,AAPL,0.0,0.0,0.0,
2024-10-21 12:17:35.461400679+00:00,2024-10-21T12:17:35.461566586Z,10,2,38,C,A,1,234.03,200,130,165907,12639539,233.9,234.0,10,50,1,1,233.85,234.09,141,29,1,1,233.77,234.1,200,100,1,1,233.73,234.13,27,400,1,1,233.7,234.17,1200,1,1,1,233.66,234.25,1,100,1,1,233.58,234.41,505,600,2,2,233.53,234.43,10,105,1,2,233.5,234.5,100,63,1,4,233.45,234.75,15,1,1,1,AAPL,0.0,0.0,0.0,
2024-10-21 12:17:35.461412055+00:00,2024-10-21T12:17:35.461578939Z,10,2,38,A,A,1,234.08,400,130,166884,12639540,233.9,234.0,10,50,1,1,233.85,234.08,141,400,1,1,233.77,234.09,200,29,1,1,233.73,234.1,27,100,1,1,233.7,234.13,1200,400,1,1,233.66,234.17,1,1,1,1,233.58,234.25,505,100,2,1,233.53,234.41,10,600,1,2,233.5,234.43,100,105,1,2,233.45,234.5,15,63,1,4,AAPL,0.0,0.0,0.0,
2024-10-21 12:17:35.469991264+00:00,2024-10-21T12:17:35.470157228Z,10,2,38,C,A,2,234.09,29,130,165964,12639580,233.9,234.0,10,50,1,1,233.85,234.08,141,400,1,1,233.77,234.1,200,100,1,1,233.73,234.13,27,400,1,1,233.7,234.17,1200,1,1,1,233.66,234.25,1,100,1,1,233.58,234.41,505,600,2,2,233.53,234.43,10,105,1,2,233.5,234.5,100,63,1,4,233.45,234.75,15,1,1,1,AAPL,0.0,0.0,0.0,
2024-10-21 12:17:35.470045707+00:00,2024-10-21T12:17:35.470212130Z,10,2,38,A,A,4,234.15,28,130,166423,12639581,233.9,234.0,10,50,1,1,233.85,234.08,141,400,1,1,233.77,234.1,200,100,1,1,233.73,234.13,27,400,1,1,233.7,234.15,1200,28,1,1,233.66,234.17,1,1,1,1,233.58,234.25,505,100,2,1,233.53,234.41,10,600,1,2,233.5,234.43,100,105,1,2,233.45,234.5,15,63,1,4,AAPL,0.0,0.0,0.0,
2024-10-21 12:17:37.663629357+00:00,2024-10-21T12:17:37.663795596Z,10,2,38,A,B,2,233.77,200,130,166239,12641761,233.9,234.0,10,50,1,1,233.85,234.08,141,400,1,1,233.77,234.1,400,100,2,1,233.73,234.13,27,400,1,1,233.7,234.15,1200,28,1,1,233.66,234.17,1,1,1,1,233.58,234.25,505,100,2,1,233.53,234.41,10,600,1,2,233.5,234.43,100,105,1,2,233.45,234.5,15,63,1,4,AAPL,0.0,200.0,0.0,
2024-10-21 12:17:37.718594298+00:00,2024-10-21T12:17:37.718760543Z,10,2,38,C,B,2,233.77,200,130,166245,12641892,233.9,234.0,10,50,1,1,233.85,234.08,141,400,1,1,233.77,234.1,200,100,1,1,233.73,234.13,27,400,1,1,233.7,234.15,1200,28,1,1,233.66,234.17,1,1,1,1,233.58,234.25,505,100,2,1,233.53,234.41,10,600,1,2,233.5,234.43,100,105,1,2,233.45,234.5,15,63,1,4,AAPL,0.0,-200.0,0.0,
2024-10-21 12:17:37.718605853+00:00,2024-10-21T12:17:37.718772651Z,10,2,38,A,B,2,233.8,400,130,166798,12641893,233.9,234.0,10,50,1,1,233.85,234.08,141,400,1,1,233.8,234.1,400,100,1,1,233.73,234.13,27,400,1,1,233.7,234.15,1200,28,1,1,233.66,234.17,1,1,1,1,233.58,234.25,505,100,2,1,233.53,234.41,10,600,1,2,233.5,234.43,100,105,1,2,233.45,234.5,15,63,1,4,AAPL,0.0,0.0,0.0,
2024-10-21 12:17:38.521127910+00:00,2024-10-21T12:17:38.521294530Z,10,2,38,A,A,1,234.04,200,130,166620,12642639,233.9,234.0,10,50,1,1,233.85,234.04,141,200,1,1,233.8,234.1,400,100,1,1,233.73,234.13,27,400,1,1,233.7,234.15,1200,28,1,1,233.66,234.17,1,1,1,1,233.58,234.25,505,100,2,1,233.53,234.41,10,600,1,2,233.5,234.43,100,105,1,2,233.45,234.5,15,63,1,4,AAPL,0.0,0.0,0.0,
2024-10-21 12:17:39.973547435+00:00,2024-10-21T12:17:39.973713394Z,10,2,38,C,A,4,234.15,28,130,165959,12644151,233.9,234.0,10,50,1,1,233.85,234.04,141,200,1,1,233.8,234.1,400,100,1,1,233.73,234.13,27,400,1,1,233.7,234.17,1200,1,1,1,233.66,234.25,1,100,1,1,233.58,234.41,505,600,2,2,233.53,234.43,10,105,1,2,233.5,234.5,100,63,1,4,233.45,234.75,15,1,1,1,AAPL,0.0,0.0,0.0,
2024-10-21 12:17:39.973585910+00:00,2024-10-21T12:17:39.973752037Z,10,2,38,A,A,2,234.1,27,130,166127,12644152,233.9,234.0,10,50,1,1,233.85,234.04,141,200,1,1,233.8,234.1,400,127,1,2,233.73,234.13,27,400,1,1,233.7,234.17,1200,1,1,1,233.66,234.25,1,100,1,1,233.58,234.41,505,600,2,2,233.53,234.43,10,105,1,2,233.5,234.5,100,63,1,4,233.45,234.75,15,1,1,1,AAPL,0.0,-27.0,0.0,
2024-10-21 12:17:47.135873221+00:00,2024-10-21T12:17:47.136044765Z,10,2,38,T,A,0,233.9,10,0,171544,12650095,233.9,234.0,10,50,1,1,233.85,234.04,141,200,1,1,233.8,234.1,400,127,1,2,233.73,234.13,27,400,1,1,233.7,234.17,1200,1,1,1,233.66,234.25,1,100,1,1,233.58,234.41,505,600,2,2,233.53,234.43,10,105,1,2,233.5,234.5,100,63,1,4,233.45,234.75,15,1,1,1,AAPL,0.0,0.0,0.0,
2024-10-21 12:17:47.135873221+00:00,2024-10-21T12:17:47.136044765Z,10,2,38,T,A,0,233.85,141,0,171544,12650096,233.85,234.0,141,50,1,1,233.8,234.04,400,200,1,1,233.73,234.1,27,127,1,2,233.7,234.13,1200,400,1,1,233.66,234.17,1,1,1,1,233.58,234.25,505,100,2,1,233.53,234.41,10,600,1,2,233.5,234.43,100,105,1,2,233.45,234.5,15,63,1,4,233.4,234.75,110,1,2,1,AAPL,0.0,0.0,0.0,
2024-10-21 12:17:47.135873221+00:00,2024-10-21T12:17:47.136044765Z,10,2,38,T,N,0,233.85,50,130,171544,12650097,233.8,234.0,400,50,1,1,233.73,234.04,27,200,1,1,233.7,234.1,1200,127,1,2,233.66,234.13,1,400,1,1,233.58,234.17,505,1,2,1,233.53,234.25,10,100,1,1,233.5,234.41,100,600,1,2,233.45,234.43,15,105,1,2,233.4,234.5,110,63,2,4,233.39,234.75,10,1,1,1,AAPL,0.0,0.0,0.0,
2024-10-21 12:17:47.135900626+00:00,2024-10-21T12:17:47.136066911Z,10,2,38,A,A,0,233.98,100,130,166285,12650098,233.8,233.98,400,100,1,1,233.73,234.0,27,50,1,1,233.7,234.04,1200,200,1,1,233.66,234.1,1,127,1,2,233.58,234.13,505,400,2,1,233.53,234.17,10,1,1,1,233.5,234.25,100,100,1,1,233.45,234.41,15,600,1,2,233.4,234.43,110,105,2,2,233.39,234.5,10,63,1,4,AAPL,0.0,0.0,0.0,
2024-10-21 12:17:47.135905168+00:00,2024-10-21T12:17:47.136072149Z,10,2,38,A,A,0,233.97,100,130,166981,12650099,233.8,233.97,400,100,1,1,233.73,233.98,27,100,1,1,233.7,234.0,1200,50,1,1,233.66,234.04,1,200,1,1,233.58,234.1,505,127,2,2,233.53,234.13,10,400,1,1,233.5,234.17,100,1,1,1,233.45,234.25,15,100,1,1,233.4,234.41,110,600,2,2,233.39,234.43,10,105,1,2,AAPL,0.0,0.0,0.0,
2024-10-21 12:17:47.135906292+00:00,2024-10-21T12:17:47.136074817Z,10,2,38,A,A,0,233.95,162,130,168525,12650101,233.8,233.95,400,162,1,1,233.73,233.97,27,200,1,2,233.7,233.98,1200,100,1,1,233.66,234.0,1,50,1,1,233.58,234.04,505,200,2,1,233.53,234.1,10,127,1,2,233.5,234.13,100,400,1,1,233.45,234.17,15,1,1,1,233.4,234.25,110,100,2,1,233.39,234.41,10,600,1,2,AAPL,0.0,0.0,0.0,
2024-10-21 12:17:47.135913885+00:00,2024-10-21T12:17:47.136079816Z,10,2,38,A,A,0,233.92,100,130,165931,12650102,233.8,233.92,400,100,1,1,233.73,233.95,27,162,1,1,233.7,233.97,1200,200,1,2,233.66,233.98,1,100,1,1,233.58,234.0,505,50,2,1,233.53,234.04,10,200,1,1,233.5,234.1,100,127,1,2,233.45,234.13,15,400,1,1,233.4,234.17,110,1,2,1,233.39,234.25,10,100,1,1,AAPL,0.0,0.0,0.0,
2024-10-21 12:17:47.135916592+00:00,2024-10-21T12:17:47.136082565Z,10,2,38,A,A,3,233.98,100,130,165973,12650103,233.8,233.92,400,100,1,1,233.73,233.95,27,162,1,1,233.7,233.97,1200,200,1,2,233.66,233.98,1,200,1,2,233.58,234.0,505,50,2,1,233.53,234.04,10,200,1,1,233.5,234.1,100,127,1,2,233.45,234.13,15,400,1,1,233.4,234.17,110,1,2,1,233.39,234.25,10,100,1,1,AAPL,0.0,-100.0,0.0,
2024-10-21 12:17:47.135925594+00:00,2024-10-21T12:17:47.136093537Z,10,2,38,A,A,2,233.97,100,130,167943,12650104,233.8,233.92,400,100,1,1,233.73,233.95,27,162,1,1,233.7,233.97,1200,300,1,3,233.66,233.98,1,200,1,2,233.58,234.0,505,50,2,1,233.53,234.04,10,200,1,1,233.5,234.1,100,127,1,2,233.45,234.13,15,400,1,1,233.4,234.17,110,1,2,1,233.39,234.25,10,100,1,1,AAPL,0.0,-100.0,0.0,
2024-10-21 12:17:47.135933669+00:00,2024-10-21T12:17:47.136099687Z,10,2,38,A,A,1,233.93,35,130,166018,12650105,233.8,233.92,400,100,1,1,233.73,233.93,27,35,1,1,233.7,233.95,1200,162,1,1,233.66,233.97,1,300,1,3,233.58,233.98,505,200,2,2,233.53,234.0,10,50,1,1,233.5,234.04,100,200,1,1,233.45,234.1,15,127,1,2,233.4,234.13,110,400,2,1,233.39,234.17,10,1,1,1,AAPL,0.0,0.0,0.0,
2024-10-21 12:17:47.135937314+00:00,2024-10-21T12:17:47.136103482Z,10,2,38,C,A,4,233.98,100,130,166168,12650106,233.8,233.92,400,100,1,1,233.73,233.93,27,35,1,1,233.7,233.95,1200,162,1,1,233.66,233.97,1,300,1,3,233.58,233.98,505,100,2,1,233.53,234.0,10,50,1,1,233.5,234.04,100,200,1,1,233.45,234.1,15,127,1,2,233.4,234.13,110,400,2,1,233.39,234.17,10,1,1,1,AAPL,0.0,100.0,0.0,
2024-10-21 12:17:47.135940686+00:00,2024-10-21T12:17:47.136107460Z,10,2,38,A,A,3,233.97,100,130,166774,12650107,233.8,233.92,400,100,1,1,233.73,233.93,27,35,1,1,233.7,233.95,1200,162,1,1,233.66,233.97,1,400,1,4,233.58,233.98,505,100,2,1,233.53,234.0,10,50,1,1,233.5,234.04,100,200,1,1,233.45,234.1,15,127,1,2,233.4,234.13,110,400,2,1,233.39,234.17,10,1,1,1,AAPL,0.0,-100.0,0.0,
2024-10-21 12:17:47.135946914+00:00,2024-10-21T12:17:47.136114326Z,10,2,38,A,A,0,233.97,35,130,167412,12650109,233.8,233.93,400,35,1,1,233.73,233.95,27,162,1,1,233.7,233.97,1200,435,1,5,233.66,233.98,1,100,1,1,233.58,234.0,505,50,2,1,233.53,234.04,10,200,1,1,233.5,234.1,100,127,1,2,233.45,234.13,15,400,1,1,233.4,234.17,110,1,2,1,233.39,234.25,10,100,1,1,AAPL,0.0,0.0,0.0,
2024-10-21 12:17:47.135952535+00:00,2024-10-21T12:17:47.136118512Z,10,2,38,C,A,3,233.98,100,130,165977,12650110,233.8,233.93,400,35,1,1,233.73,233.95,27,162,1,1,233.7,233.97,1200,435,1,5,233.66,234.0,1,50,1,1,233.58,234.04,505,200,2,1,233.53,234.1,10,127,1,2,233.5,234.13,100,400,1,1,233.45,234.17,15,1,1,1,233.4,234.25,110,100,2,1,233.39,234.41,10,600,1,2,AAPL,0.0,0.0,0.0,
2024-10-21 12:17:47.135958456+00:00,2024-10-21T12:17:47.136124318Z,10,2,38,C,B,0,233.8,400,130,165862,12650111,233.73,233.93,27,35,1,1,233.7,233.95,1200,162,1,1,233.66,233.97,1,435,1,5,233.58,234.0,505,50,2,1,233.53,234.04,10,200,1,1,233.5,234.1,100,127,1,2,233.45,234.13,15,400,1,1,233.4,234.17,110,1,2,1,233.39,234.25,10,100,1,1,233.31,234.41,110,600,2,2,AAPL,0.0,0.0,0.0,
2024-10-21 12:17:47.135968023+00:00,2024-10-21T12:17:47.136134998Z,10,2,38,C,A,1,233.95,162,128,166975,12650112,233.73,233.93,27,35,1,1,233.7,233.97,1200,435,1,5,233.66,234.0,1,50,1,1,233.58,234.04,505,200,2,1,233.53,234.1,10,127,1,2,233.5,234.13,100,400,1,1,233.45,234.17,15,1,1,1,233.4,234.25,110,100,2,1,233.39,234.41,10,600,1,2,233.31,234.43,110,105,2,2,AAPL,0.0,0.0,0.0,
2024-10-21 12:17:47.136008874+00:00,2024-10-21T12:17:47.136176630Z,10,2,38,C,A,1,233.97,100,130,167756,12650118,233.73,233.93,27,35,1,1,233.7,233.97,1200,335,1,4,233.66,234.0,1,50,1,1,233.58,234.04,505,200,2,1,233.53,234.1,10,127,1,2,233.5,234.13,100,400,1,1,233.45,234.17,15,1,1,1,233.4,234.25,110,100,2,1,233.39,234.41,10,600,1,2,233.31,234.43,110,105,2,2,AAPL,0.0,100.0,0.0,
2024-10-21 12:17:47.136054541+00:00,2024-10-21T12:17:47.136220660Z,10,2,38,C,A,1,233.97,100,130,166119,12650119,233.73,233.93,27,35,1,1,233.7,233.97,1200,235,1,3,233.66,234.0,1,50,1,1,233.58,234.04,505,200,2,1,233.53,234.1,10,127,1,2,233.5,234.13,100,400,1,1,233.45,234.17,15,1,1,1,233.4,234.25,110,100,2,1,233.39,234.41,10,600,1,2,233.31,234.43,110,105,2,2,AAPL,0.0,100.0,0.0,
2024-10-21 12:17:47.136218636+00:00,2024-10-21T12:17:47.136384565Z,10,2,38,C,A,1,233.97,100,130,165929,12650120,233.73,233.93,27,35,1,1,233.7,233.97,1200,135,1,2,233.66,234.0,1,50,1,1,233.58,234.04,505,200,2,1,233.53,234.1,10,127,1,2,233.5,234.13,100,400,1,1,233.45,234.17,15,1,1,1,233.4,234.25,110,100,2,1,233.39,234.41,10,600,1,2,233.31,234.43,110,105,2,2,AAPL,0.0,100.0,0.0,
2024-10-21 12:17:47.136225295+00:00,2024-10-21T12:17:47.136391264Z,10,2,38,C,A,1,233.97,100,130,165969,12650121,233.73,233.93,27,35,1,1,233.7,233.97,1200,35,1,1,233.66,234.0,1,50,1,1,233.58,234.04,505,200,2,1,233.53,234.1,10,127,1,2,233.5,234.13,100,400,1,1,233.45,234.17,15,1,1,1,233.4,234.25,110,100,2,1,233.39,234.41,10,600,1,2,233.31,234.43,110,105,2,2,AAPL,0.0,100.0,0.0,
2024-10-21 12:17:47.136565013+00:00,2024-10-21T12:17:47.136731997Z,10,2,38,A,A,0,233.92,100,130,166984,12650123,233.73,233.92,27,100,1,1,233.7,233.93,1200,35,1,1,233.66,233.97,1,35,1,1,233.58,234.0,505,50,2,1,233.53,234.04,10,200,1,1,233.5,234.1,100,127,1,2,233.45,234.13,15,400,1,1,233.4,234.17,110,1,2,1,233.39,234.25,10,100,1,1,233.31,234.41,110,600,2,2,AAPL,0.0,0.0,0.0,
2024-10-21 12:17:47.137037920+00:00,2024-10-21T12:17:47.137204585Z,10,2,38,C,A,0,233.92,100,130,166665,12650124,233.73,233.93,27,35,1,1,233.7,233.97,1200,35,1,1,233.66,234.0,1,50,1,1,233.58,234.04,505,200,2,1,233.53,234.1,10,127,1,2,233.5,234.13,100,400,1,1,233.45,234.17,15,1,1,1,233.4,234.25,110,100,2,1,233.39,234.41,10,600,1,2,233.31,234.43,110,105,2,2,AAPL,0.0,0.0,0.0,
2024-10-21 12:17:47.156890091+00:00,2024-10-21T12:17:47.157056586Z,10,2,38,A,B,0,233.8,200,130,166495,12650144,233.8,233.93,200,35,1,1,233.73,233.97,27,35,1,1,233.7,234.0,1200,50,1,1,233.66,234.04,1,200,1,1,233.58,234.1,505,127,2,2,233.53,234.13,10,400,1,1,233.5,234.17,100,1,1,1,233.45,234.25,15,100,1,1,233.4,234.41,110,600,2,2,233.39,234.43,10,105,1,2,AAPL,0.0,0.0,0.0,
2024-10-21 12:17:47.189701537+00:00,2024-10-21T12:17:47.189868393Z,10,2,38,A,B,0,233.8,200,130,166856,12650170,233.8,233.93,400,35,2,1,233.73,233.97,27,35,1,1,233.7,234.0,1200,50,1,1,233.66,234.04,1,200,1,1,233.58,234.1,505,127,2,2,233.53,234.13,10,400,1,1,233.5,234.17,100,1,1,1,233.45,234.25,15,100,1,1,233.4,234.41,110,600,2,2,233.39,234.43,10,105,1,2,AAPL,200.0,200.0,200.0,
2024-10-21 12:17:47.200038724+00:00,2024-10-21T12:17:47.200204805Z,10,2,38,C,B,0,233.8,200,130,166081,12650190,233.8,233.93,200,35,1,1,233.73,233.97,27,35,1,1,233.7,234.0,1200,50,1,1,233.66,234.04,1,200,1,1,233.58,234.1,505,127,2,2,233.53,234.13,10,400,1,1,233.5,234.17,100,1,1,1,233.45,234.25,15,100,1,1,233.4,234.41,110,600,2,2,233.39,234.43,10,105,1,2,AAPL,-200.0,-200.0,0.0,
2024-10-21 12:17:47.200048226+00:00,2024-10-21T12:17:47.200214033Z,10,2,38,C,B,0,233.8,200,130,165807,12650191,233.73,233.93,27,35,1,1,233.7,233.97,1200,35,1,1,233.66,234.0,1,50,1,1,233.58,234.04,505,200,2,1,233.53,234.1,10,127,1,2,233.5,234.13,100,400,1,1,233.45,234.17,15,1,1,1,233.4,234.25,110,100,2,1,233.39,234.41,10,600,1,2,233.31,234.43,110,105,2,2,AAPL,0.0,0.0,0.0,
2024-10-21 12:17:47.200058794+00:00,2024-10-21T12:17:47.200225833Z,10,2,38,A,B,2,233.69,400,130,167039,12650192,233.73,233.93,27,35,1,1,233.7,233.97,1200,35,1,1,233.69,234.0,400,50,1,1,233.66,234.04,1,200,1,1,233.58,234.1,505,127,2,2,233.53,234.13,10,400,1,1,233.5,234.17,100,1,1,1,233.45,234.25,15,100,1,1,233.4,234.41,110,600,2,2,233.39,234.43,10,105,1,2,AAPL,0.0,0.0,0.0,
2024-10-21 12:17:47.203657195+00:00,2024-10-21T12:17:47.203824313Z,10,2,38,C,B,0,233.73,27,130,167118,12650207,233.7,233.93,1200,35,1,1,233.69,233.97,400,35,1,1,233.66,234.0,1,50,1,1,233.58,234.04,505,200,2,1,233.53,234.1,10,127,1,2,233.5,234.13,100,400,1,1,233.45,234.17,15,1,1,1,233.4,234.25,110,100,2,1,233.39,234.41,10,600,1,2,233.31,234.43,110,105,2,2,AAPL,0.0,0.0,0.0,
2024-10-21 12:17:47.203729908+00:00,2024-10-21T12:17:47.203896270Z,10,2,38,A,B,2,233.67,28,130,166362,12650208,233.7,233.93,1200,35,1,1,233.69,233.97,400,35,1,1,233.67,234.0,28,50,1,1,233.66,234.04,1,200,1,1,233.58,234.1,505,127,2,2,233.53,234.13,10,400,1,1,233.5,234.17,100,1,1,1,233.45,234.25,15,100,1,1,233.4,234.41,110,600,2,2,233.39,234.43,10,105,1,2,AAPL,0.0,0.0,0.0,
2024-10-21 12:17:47.207076580+00:00,2024-10-21T12:17:47.207242623Z,10,2,38,C,B,1,233.69,400,130,166043,12650217,233.7,233.93,1200,35,1,1,233.67,233.97,28,35,1,1,233.66,234.0,1,50,1,1,233.58,234.04,505,200,2,1,233.53,234.1,10,127,1,2,233.5,234.13,100,400,1,1,233.45,234.17,15,1,1,1,233.4,234.25,110,100,2,1,233.39,234.41,10,600,1,2,233.31,234.43,110,105,2,2,AAPL,0.0,0.0,0.0,
2024-10-21 12:17:47.240037346+00:00,2024-10-21T12:17:47.240203878Z,10,2,38,A,B,1,233.68,200,130,166532,12650248,233.7,233.93,1200,35,1,1,233.68,233.97,200,35,1,1,233.67,234.0,28,50,1,1,233.66,234.04,1,200,1,1,233.58,234.1,505,127,2,2,233.53,234.13,10,400,1,1,233.5,234.17,100,1,1,1,233.45,234.25,15,100,1,1,233.4,234.41,110,600,2,2,233.39,234.43,10,105,1,2,AAPL,0.0,0.0,0.0,
2024-10-21 12:17:47.240066169+00:00,2024-10-21T12:17:47.240232077Z,10,2,38,C,A,1,233.97,35,130,165908,12650249,233.7,233.93,1200,35,1,1,233.68,234.0,200,50,1,1,233.67,234.04,28,200,1,1,233.66,234.1,1,127,1,2,233.58,234.13,505,400,2,1,233.53,234.17,10,1,1,1,233.5,234.25,100,100,1,1,233.45,234.41,15,600,1,2,233.4,234.43,110,105,2,2,233.39,234.5,10,63,1,4,AAPL,0.0,0.0,0.0,
2024-10-21 12:17:47.260085243+00:00,2024-10-21T12:17:47.260251805Z,10,2,38,A,A,2,234.03,200,130,166562,12650278,233.7,233.93,1200,35,1,1,233.68,234.0,200,50,1,1,233.67,234.03,28,200,1,1,233.66,234.1,1,127,1,2,233.58,234.13,505,400,2,1,233.53,234.17,10,1,1,1,233.5,234.25,100,100,1,1,233.45,234.41,15,600,1,2,233.4,234.43,110,105,2,2,233.39,234.5,10,63,1,4,AAPL,0.0,0.0,0.0,
2024-10-21 12:17:47.386463721+00:00,2024-10-21T12:17:47.386630077Z,10,2,38,C,A,0,233.93,35,130,166356,12650325,233.7,234.0,1200,50,1,1,233.68,234.03,200,200,1,1,233.67,234.1,28,127,1,2,233.66,234.13,1,400,1,1,233.58,234.17,505,1,2,1,233.53,234.25,10,100,1,1,233.5,234.41,100,600,1,2,233.45,234.43,15,105,1,2,233.4,234.5,110,63,2,4,233.39,234.75,10,1,1,1,AAPL,0.0,0.0,0.0,
2024-10-21 12:17:57.663911195+00:00,2024-10-21T12:17:57.664077159Z,10,2,38,C,A,2,234.1,27,130,165964,12660246,233.7,234.0,1200,50,1,1,233.68,234.03,200,200,1,1,233.67,234.1,28,100,1,1,233.66,234.13,1,400,1,1,233.58,234.17,505,1,2,1,233.53,234.25,10,100,1,1,233.5,234.41,100,600,1,2,233.45,234.43,15,105,1,2,233.4,234.5,110,63,2,4,233.39,234.75,10,1,1,1,AAPL,0.0,27.0,0.0,
2024-10-21 12:17:57.664016909+00:00,2024-10-21T12:17:57.664183508Z,10,2,38,A,A,2,234.09,28,130,166599,12660247,233.7,234.0,1200,50,1,1,233.68,234.03,200,200,1,1,233.67,234.09,28,28,1,1,233.66,234.1,1,100,1,1,233.58,234.13,505,400,2,1,233.53,234.17,10,1,1,1,233.5,234.25,100,100,1,1,233.45,234.41,15,600,1,2,233.4,234.43,110,105,2,2,233.39,234.5,10,63,1,4,AAPL,0.0,0.0,0.0,
2024-10-21 12:17:57.861764830+00:00,2024-10-21T12:17:57.861930731Z,10,2,38,C,A,1,234.03,200,130,165901,12660371,233.7,234.0,1200,50,1,1,233.68,234.09,200,28,1,1,233.67,234.1,28,100,1,1,233.66,234.13,1,400,1,1,233.58,234.17,505,1,2,1,233.53,234.25,10,100,1,1,233.5,234.41,100,600,1,2,233.45,234.43,15,105,1,2,233.4,234.5,110,63,2,4,233.39,234.75,10,1,1,1,AAPL,0.0,0.0,0.0,
2024-10-21 12:17:57.861778012+00:00,2024-10-21T12:17:57.861944318Z,10,2,38,A,A,1,234.05,200,130,166306,12660372,233.7,234.0,1200,50,1,1,233.68,234.05,200,200,1,1,233.67,234.09,28,28,1,1,233.66,234.1,1,100,1,1,233.58,234.13,505,400,2,1,233.53,234.17,10,1,1,1,233.5,234.25,100,100,1,1,233.45,234.41,15,600,1,2,233.4,234.43,110,105,2,2,233.39,234.5,10,63,1,4,AAPL,0.0,0.0,0.0,
2024-10-21 12:17:57.861832789+00:00,2024-10-21T12:17:57.861998569Z,10,2,38,C,A,1,234.05,200,130,165780,12660373,233.7,234.0,1200,50,1,1,233.68,234.09,200,28,1,1,233.67,234.1,28,100,1,1,233.66,234.13,1,400,1,1,233.58,234.17,505,1,2,1,233.53,234.25,10,100,1,1,233.5,234.41,100,600,1,2,233.45,234.43,15,105,1,2,233.4,234.5,110,63,2,4,233.39,234.75,10,1,1,1,AAPL,0.0,0.0,0.0,
2024-10-21 12:17:57.861881332+00:00,2024-10-21T12:17:57.862047558Z,10,2,38,A,A,1,234.08,400,130,166226,12660374,233.7,234.0,1200,50,1,1,233.68,234.08,200,400,1,1,233.67,234.09,28,28,1,1,233.66,234.1,1,100,1,1,233.58,234.13,505,400,2,1,233.53,234.17,10,1,1,1,233.5,234.25,100,100,1,1,233.45,234.41,15,600,1,2,233.4,234.43,110,105,2,2,233.39,234.5,10,63,1,4,AAPL,0.0,0.0,0.0,
2024-10-21 12:17:57.862245512+00:00,2024-10-21T12:17:57.862411573Z,10,2,38,C,A,2,234.09,28,130,166061,12660376,233.7,234.0,1200,50,1,1,233.68,234.08,200,400,1,1,233.67,234.1,28,100,1,1,233.66,234.13,1,400,1,1,233.58,234.17,505,1,2,1,233.53,234.25,10,100,1,1,233.5,234.41,100,600,1,2,233.45,234.43,15,105,1,2,233.4,234.5,110,63,2,4,233.39,234.75,10,1,1,1,AAPL,0.0,0.0,0.0,
2024-10-21 12:17:57.917042270+00:00,2024-10-21T12:17:57.917208666Z,10,2,38,A,A,1,234.06,200,130,166396,12660452,233.7,234.0,1200,50,1,1,233.68,234.06,200,200,1,1,233.67,234.1,28,100,1,1,233.66,234.13,1,400,1,1,233.58,234.17,505,1,2,1,233.53,234.25,10,100,1,1,233.5,234.41,100,600,1,2,233.45,234.43,15,105,1,2,233.4,234.5,110,63,2,4,233.39,234.75,10,1,1,1,AAPL,0.0,0.0,0.0,
2024-10-21 12:17:58.077227750+00:00,2024-10-21T12:17:58.077394143Z,10,2,38,A,A,1,234.03,200,130,166393,12660553,233.7,234.0,1200,50,1,1,233.68,234.03,200,200,1,1,233.67,234.1,28,100,1,1,233.66,234.13,1,400,1,1,233.58,234.17,505,1,2,1,233.53,234.25,10,100,1,1,233.5,234.41,100,600,1,2,233.45,234.43,15,105,1,2,233.4,234.5,110,63,2,4,233.39,234.75,10,1,1,1,AAPL,0.0,0.0,0.0,
2024-10-21 12:18:00.232353557+00:00,2024-10-21T12:18:00.232519967Z,10,2,38,A,A,2,234.1,29,130,166410,12662424,233.7,234.0,1200,50,1,1,233.68,234.03,200,200,1,1,233.67,234.1,28,129,1,2,233.66,234.13,1,400,1,1,233.58,234.17,505,1,2,1,233.53,234.25,10,100,1,1,233.5,234.41,100,600,1,2,233.45,234.43,15,105,1,2,233.4,234.5,110,63,2,4,233.39,234.75,10,1,1,1,AAPL,0.0,-29.0,0.0,
2024-10-21 12:18:00.862130755+00:00,2024-10-21T12:18:00.862297139Z,10,2,38,A,A,1,234.03,200,130,166384,12663334,233.7,234.0,1200,50,1,1,233.68,234.03,200,400,1,2,233.67,234.1,28,129,1,2,233.66,234.13,1,400,1,1,233.58,234.17,505,1,2,1,233.53,234.25,10,100,1,1,233.5,234.41,100,600,1,2,233.45,234.43,15,105,1,2,233.4,234.5,110,63,2,4,233.39,234.75,10,1,1,1,AAPL,0.0,-200.0,0.0,
2024-10-21 12:18:01.682081842+00:00,2024-10-21T12:18:01.682248451Z,10,2,38,C,A,1,234.03,200,130,166609,12664484,233.7,234.0,1200,50,1,1,233.68,234.03,200,200,1,1,233.67,234.1,28,129,1,2,233.66,234.13,1,400,1,1,233.58,234.17,505,1,2,1,233.53,234.25,10,100,1,1,233.5,234.41,100,600,1,2,233.45,234.43,15,105,1,2,233.4,234.5,110,63,2,4,233.39,234.75,10,1,1,1,AAPL,0.0,200.0,0.0,
2024-10-21 12:18:01.684033789+00:00,2024-10-21T12:18:01.684200005Z,10,2,38,C,A,1,234.03,200,130,166216,12664487,233.7,234.0,1200,50,1,1,233.68,234.1,200,129,1,2,233.67,234.13,28,400,1,1,233.66,234.17,1,1,1,1,233.58,234.25,505,100,2,1,233.53,234.41,10,600,1,2,233.5,234.43,100,105,1,2,233.45,234.5,15,63,1,4,233.4,234.75,110,1,2,1,233.39,234.79,10,2000,1,1,AAPL,0.0,0.0,0.0,
2024-10-21 12:18:01.684046790+00:00,2024-10-21T12:18:01.684213363Z,10,2,38,A,A,1,234.06,200,130,166573,12664488,233.7,234.0,1200,50,1,1,233.68,234.06,200,200,1,1,233.67,234.1,28,129,1,2,233.66,234.13,1,400,1,1,233.58,234.17,505,1,2,1,233.53,234.25,10,100,1,1,233.5,234.41,100,600,1,2,233.45,234.43,15,105,1,2,233.4,234.5,110,63,2,4,233.39,234.75,10,1,1,1,AAPL,0.0,0.0,0.0,
2024-10-21 12:18:02.545068859+00:00,2024-10-21T12:18:02.545235211Z,10,2,38,A,A,1,234.05,200,130,166352,12665308,233.7,234.0,1200,50,1,1,233.68,234.05,200,200,1,1,233.67,234.1,28,129,1,2,233.66,234.13,1,400,1,1,233.58,234.17,505,1,2,1,233.53,234.25,10,100,1,1,233.5,234.41,100,600,1,2,233.45,234.43,15,105,1,2,233.4,234.5,110,63,2,4,233.39,234.75,10,1,1,1,AAPL,0.0,0.0,0.0,
2024-10-21 12:18:03.624100762+00:00,2024-10-21T12:18:03.624266534Z,10,2,38,C,A,1,234.05,200,130,165772,12666192,233.7,234.0,1200,50,1,1,233.68,234.1,200,129,1,2,233.67,234.13,28,400,1,1,233.66,234.17,1,1,1,1,233.58,234.25,505,100,2,1,233.53,234.41,10,600,1,2,233.5,234.43,100,105,1,2,233.45,234.5,15,63,1,4,233.4,234.75,110,1,2,1,233.39,234.79,10,2000,1,1,AAPL,0.0,0.0,0.0,
2024-10-21 12:18:03.624112266+00:00,2024-10-21T12:18:03.624278474Z,10,2,38,A,A,1,234.07,200,130,166208,12666193,233.7,234.0,1200,50,1,1,233.68,234.07,200,200,1,1,233.67,234.1,28,129,1,2,233.66,234.13,1,400,1,1,233.58,234.17,505,1,2,1,233.53,234.25,10,100,1,1,233.5,234.41,100,600,1,2,233.45,234.43,15,105,1,2,233.4,234.5,110,63,2,4,233.39,234.75,10,1,1,1,AAPL,0.0,0.0,0.0,
2024-10-21 12:18:03.629412395+00:00,2024-10-21T12:18:03.629578910Z,10,2,38,C,B,2,233.67,28,130,166515,12666256,233.7,234.0,1200,50,1,1,233.68,234.07,200,200,1,1,233.66,234.1,1,129,1,2,233.58,234.13,505,400,2,1,233.53,234.17,10,1,1,1,233.5,234.25,100,100,1,1,233.45,234.41,15,600,1,2,233.4,234.43,110,105,2,2,233.39,234.5,10,63,1,4,233.31,234.75,110,1,2,1,AAPL,0.0,0.0,0.0,
2024-10-21 12:18:03.629498033+00:00,2024-10-21T12:18:03.629664398Z,10,2,38,A,B,1,233.68,26,130,166365,12666257,233.7,234.0,1200,50,1,1,233.68,234.07,226,200,2,1,233.66,234.1,1,129,1,2,233.58,234.13,505,400,2,1,233.53,234.17,10,1,1,1,233.5,234.25,100,100,1,1,233.45,234.41,15,600,1,2,233.4,234.43,110,105,2,2,233.39,234.5,10,63,1,4,233.31,234.75,110,1,2,1,AAPL,0.0,26.0,0.0,
2024-10-21 12:18:03.696618449+00:00,2024-10-21T12:18:03.696785108Z,10,2,38,A,B,1,233.69,200,130,166659,12666492,233.7,234.0,1200,50,1,1,233.69,234.07,200,200,1,1,233.68,234.1,26,129,1,2,233.66,234.13,1,400,1,1,233.58,234.17,505,1,2,1,233.53,234.25,10,100,1,1,233.5,234.41,100,600,1,2,233.45,234.43,15,105,1,2,233.4,234.5,110,63,2,4,233.39,234.75,10,1,1,1,AAPL,0.0,0.0,0.0,
2024-10-21 12:18:04.737516809+00:00,2024-10-21T12:18:04.737683350Z,10,2,38,A,A,1,234.04,200,130,166541,12667659,233.7,234.0,1200,50,1,1,233.69,234.04,200,200,1,1,233.68,234.1,26,129,1,2,233.66,234.13,1,400,1,1,233.58,234.17,505,1,2,1,233.53,234.25,10,100,1,1,233.5,234.41,100,600,1,2,233.45,234.43,15,105,1,2,233.4,234.5,110,63,2,4,233.39,234.75,10,1,1,1,AAPL,0.0,0.0,0.0,
2024-10-21 12:18:05.203361341+00:00,2024-10-21T12:18:05.203527442Z,10,2,38,C,A,1,234.04,200,130,166101,12668336,233.7,234.0,1200,50,1,1,233.69,234.1,200,129,1,2,233.68,234.13,26,400,1,1,233.66,234.17,1,1,1,1,233.58,234.25,505,100,2,1,233.53,234.41,10,600,1,2,233.5,234.43,100,105,1,2,233.45,234.5,15,63,1,4,233.4,234.75,110,1,2,1,233.39,234.79,10,2000,1,1,AAPL,0.0,0.0,0.0,
2024-10-21 12:18:05.203373864+00:00,2024-10-21T12:18:05.203540356Z,10,2,38,A,A,1,234.07,200,130,166492,12668337,233.7,234.0,1200,50,1,1,233.69,234.07,200,200,1,1,233.68,234.1,26,129,1,2,233.66,234.13,1,400,1,1,233.58,234.17,505,1,2,1,233.53,234.25,10,100,1,1,233.5,234.41,100,600,1,2,233.45,234.43,15,105,1,2,233.4,234.5,110,63,2,4,233.39,234.75,10,1,1,1,AAPL,0.0,0.0,0.0,
2024-10-21 12:18:08.259009052+00:00,2024-10-21T12:18:08.259175673Z,10,2,38,A,A,1,234.04,200,130,166621,12670951,233.7,234.0,1200,50,1,1,233.69,234.04,200,200,1,1,233.68,234.1,26,129,1,2,233.66,234.13,1,400,1,1,233.58,234.17,505,1,2,1,233.53,234.25,10,100,1,1,233.5,234.41,100,600,1,2,233.45,234.43,15,105,1,2,233.4,234.5,110,63,2,4,233.39,234.75,10,1,1,1,AAPL,0.0,0.0,0.0,
2024-10-21 12:18:08.926535769+00:00,2024-10-21T12:18:08.926701808Z,10,2,38,C,A,1,234.04,200,130,166039,12671724,233.7,234.0,1200,50,1,1,233.69,234.1,200,129,1,2,233.68,234.13,26,400,1,1,233.66,234.17,1,1,1,1,233.58,234.25,505,100,2,1,233.53,234.41,10,600,1,2,233.5,234.43,100,105,1,2,233.45,234.5,15,63,1,4,233.4,234.75,110,1,2,1,233.39,234.79,10,2000,1,1,AAPL,0.0,0.0,0.0,
2024-10-21 12:18:08.926548505+00:00,2024-10-21T12:18:08.926714890Z,10,2,38,A,A,1,234.07,200,130,166385,12671725,233.7,234.0,1200,50,1,1,233.69,234.07,200,200,1,1,233.68,234.1,26,129,1,2,233.66,234.13,1,400,1,1,233.58,234.17,505,1,2,1,233.53,234.25,10,100,1,1,233.5,234.41,100,600,1,2,233.45,234.43,15,105,1,2,233.4,234.5,110,63,2,4,233.39,234.75,10,1,1,1,AAPL,0.0,0.0,0.0,
2024-10-21 12:18:10.662438649+00:00,2024-10-21T12:18:10.662605099Z,10,2,38,A,A,1,234.04,200,130,166450,12673023,233.7,234.0,1200,50,1,1,233.69,234.04,200,200,1,1,233.68,234.1,26,129,1,2,233.66,234.13,1,400,1,1,233.58,234.17,505,1,2,1,233.53,234.25,10,100,1,1,233.5,234.41,100,600,1,2,233.45,234.43,15,105,1,2,233.4,234.5,110,63,2,4,233.39,234.75,10,1,1,1,AAPL,0.0,0.0,0.0,
2024-10-21 12:18:11.927260518+00:00,2024-10-21T12:18:11.927426711Z,10,2,38,A,A,1,234.04,200,130,166193,12675018,233.7,234.0,1200,50,1,1,233.69,234.04,200,400,1,2,233.68,234.1,26,129,1,2,233.66,234.13,1,400,1,1,233.58,234.17,505,1,2,1,233.53,234.25,10,100,1,1,233.5,234.41,100,600,1,2,233.45,234.43,15,105,1,2,233.4,234.5,110,63,2,4,233.39,234.75,10,1,1,1,AAPL,0.0,-200.0,0.0,
2024-10-21 12:18:20.285727761+00:00,2024-10-21T12:18:20.285893902Z,10,2,38,C,A,2,234.1,29,130,166141,12682022,233.7,234.0,1200,50,1,1,233.69,234.04,200,400,1,2,233.68,234.1,26,100,1,1,233.66,234.13,1,400,1,1,233.58,234.17,505,1,2,1,233.53,234.25,10,100,1,1,233.5,234.41,100,600,1,2,233.45,234.43,15,105,1,2,233.4,234.5,110,63,2,4,233.39,234.75,10,1,1,1,AAPL,0.0,29.0,0.0,
2024-10-21 12:18:20.285772241+00:00,2024-10-21T12:18:20.285938798Z,10,2,38,A,A,2,234.05,27,130,166557,12682023,233.7,234.0,1200,50,1,1,233.69,234.04,200,400,1,2,233.68,234.05,26,27,1,1,233.66,234.1,1,100,1,1,233.58,234.13,505,400,2,1,233.53,234.17,10,1,1,1,233.5,234.25,100,100,1,1,233.45,234.41,15,600,1,2,233.4,234.43,110,105,2,2,233.39,234.5,10,63,1,4,AAPL,0.0,0.0,0.0,
2024-10-21 12:18:20.342095696+00:00,2024-10-21T12:18:20.342261946Z,10,2,38,C,A,1,234.04,200,130,166250,12682048,233.7,234.0,1200,50,1,1,233.69,234.04,200,200,1,1,233.68,234.05,26,27,1,1,233.66,234.1,1,100,1,1,233.58,234.13,505,400,2,1,233.53,234.17,10,1,1,1,233.5,234.25,100,100,1,1,233.45,234.41,15,600,1,2,233.4,234.43,110,105,2,2,233.39,234.5,10,63,1,4,AAPL,0.0,200.0,0.0,
2024-10-21 12:18:20.342109232+00:00,2024-10-21T12:18:20.342275574Z,10,2,38,A,A,0,233.99,200,130,166342,12682049,233.7,233.99,1200,200,1,1,233.69,234.0,200,50,1,1,233.68,234.05,26,27,1,1,233.66,234.1,1,100,1,1,233.58,234.13,505,400,2,1,233.53,234.17,10,1,1,1,233.5,234.25,100,100,1,1,233.45,234.41,15,600,1,2,233.4,234.43,110,105,2,2,233.39,234.5,10,63,1,4,AAPL,0.0,0.0,0.0,
2024-10-21 12:18:30.059494751+00:00,2024-10-21T12:18:30.059661118Z,10,2,38,A,A,0,233.98,200,130,166367,12688662,233.7,233.98,1200,200,1,1,233.69,234.0,200,50,1,1,233.68,234.05,26,27,1,1,233.66,234.1,1,100,1,1,233.58,234.13,505,400,2,1,233.53,234.17,10,1,1,1,233.5,234.25,100,100,1,1,233.45,234.41,15,600,1,2,233.4,234.43,110,105,2,2,233.39,234.5,10,63,1,4,AAPL,0.0,0.0,0.0,
2024-10-21 12:18:30.076519305+00:00,2024-10-21T12:18:30.076685634Z,10,2,38,A,A,0,233.97,200,130,166329,12688696,233.7,233.97,1200,200,1,1,233.69,234.0,200,50,1,1,233.68,234.05,26,27,1,1,233.66,234.1,1,100,1,1,233.58,234.13,505,400,2,1,233.53,234.17,10,1,1,1,233.5,234.25,100,100,1,1,233.45,234.41,15,600,1,2,233.4,234.43,110,105,2,2,233.39,234.5,10,63,1,4,AAPL,0.0,0.0,0.0,
2024-10-21 12:18:38.165859345+00:00,2024-10-21T12:18:38.166025153Z,10,2,38,C,A,0,233.97,200,130,165808,12695042,233.7,234.0,1200,50,1,1,233.69,234.05,200,27,1,1,233.68,234.1,26,100,1,1,233.66,234.13,1,400,1,1,233.58,234.17,505,1,2,1,233.53,234.25,10,100,1,1,233.5,234.41,100,600,1,2,233.45,234.43,15,105,1,2,233.4,234.5,110,63,2,4,233.39,234.75,10,1,1,1,AAPL,0.0,0.0,0.0,
2024-10-21 12:18:38.165871291+00:00,2024-10-21T12:18:38.166038009Z,10,2,38,A,A,0,233.99,200,130,166718,12695043,233.7,233.99,1200,200,1,1,233.69,234.0,200,50,1,1,233.68,234.05,26,27,1,1,233.66,234.1,1,100,1,1,233.58,234.13,505,400,2,1,233.53,234.17,10,1,1,1,233.5,234.25,100,100,1,1,233.45,234.41,15,600,1,2,233.4,234.43,110,105,2,2,233.39,234.5,10,63,1,4,AAPL,0.0,0.0,0.0,
2024-10-21 12:18:38.170782768+00:00,2024-10-21T12:18:38.170948726Z,10,2,38,C,B,1,233.69,200,130,165958,12695084,233.7,233.99,1200,200,1,1,233.68,234.0,26,50,1,1,233.66,234.05,1,27,1,1,233.58,234.1,505,100,2,1,233.53,234.13,10,400,1,1,233.5,234.17,100,1,1,1,233.45,234.25,15,100,1,1,233.4,234.41,110,600,2,2,233.39,234.43,10,105,1,2,233.31,234.5,110,63,2,4,AAPL,0.0,0.0,0.0,
2024-10-21 12:18:38.170792741+00:00,2024-10-21T12:18:38.170958770Z,10,2,38,A,B,2,233.66,200,130,166029,12695085,233.7,233.99,1200,200,1,1,233.68,234.0,26,50,1,1,233.66,234.05,201,27,2,1,233.58,234.1,505,100,2,1,233.53,234.13,10,400,1,1,233.5,234.17,100,1,1,1,233.45,234.25,15,100,1,1,233.4,234.41,110,600,2,2,233.39,234.43,10,105,1,2,233.31,234.5,110,63,2,4,AAPL,0.0,200.0,0.0,
2024-10-21 12:18:38.189694615+00:00,2024-10-21T12:18:38.189860689Z,10,2,38,C,B,1,233.68,26,130,166074,12695165,233.7,233.99,1200,200,1,1,233.66,234.0,201,50,2,1,233.58,234.05,505,27,2,1,233.53,234.1,10,100,1,1,233.5,234.13,100,400,1,1,233.45,234.17,15,1,1,1,233.4,234.25,110,100,2,1,233.39,234.41,10,600,1,2,233.31,234.43,110,105,2,2,233.3,234.5,100,63,1,4,AAPL,0.0,0.0,0.0,
2024-10-21 12:18:38.189791855+00:00,2024-10-21T12:18:38.189958263Z,10,2,38,A,B,2,233.62,28,130,166408,12695166,233.7,233.99,1200,200,1,1,233.66,234.0,201,50,2,1,233.62,234.05,28,27,1,1,233.58,234.1,505,100,2,1,233.53,234.13,10,400,1,1,233.5,234.17,100,1,1,1,233.45,234.25,15,100,1,1,233.4,234.41,110,600,2,2,233.39,234.43,10,105,1,2,233.31,234.5,110,63,2,4,AAPL,0.0,0.0,0.0,
2024-10-21 12:18:40.408086849+00:00,2024-10-21T12:18:40.408253176Z,10,2,38,C,B,2,233.62,28,130,166327,12697055,233.7,233.99,1200,200,1,1,233.66,234.0,201,50,2,1,233.58,234.05,505,27,2,1,233.53,234.1,10,100,1,1,233.5,234.13,100,400,1,1,233.45,234.17,15,1,1,1,233.4,234.25,110,100,2,1,233.39,234.41,10,600,1,2,233.31,234.43,110,105,2,2,233.3,234.5,100,63,1,4,AAPL,0.0,0.0,0.0,
2024-10-21 12:18:40.408137058+00:00,2024-10-21T12:18:40.408303418Z,10,2,38,A,B,2,233.63,26,130,166360,12697056,233.7,233.99,1200,200,1,1,233.66,234.0,201,50,2,1,233.63,234.05,26,27,1,1,233.58,234.1,505,100,2,1,233.53,234.13,10,400,1,1,233.5,234.17,100,1,1,1,233.45,234.25,15,100,1,1,233.4,234.41,110,600,2,2,233.39,234.43,10,105,1,2,233.31,234.5,110,63,2,4,AAPL,0.0,0.0,0.0,
2024-10-21 12:18:41.179991523+00:00,2024-10-21T12:18:41.180157281Z,10,2,38,C,B,2,233.63,26,130,165758,12697907,233.7,233.99,1200,200,1,1,233.66,234.0,201,50,2,1,233.58,234.05,505,27,2,1,233.53,234.1,10,100,1,1,233.5,234.13,100,400,1,1,233.45,234.17,15,1,1,1,233.4,234.25,110,100,2,1,233.39,234.41,10,600,1,2,233.31,234.43,110,105,2,2,233.3,234.5,100,63,1,4,AAPL,0.0,0.0,0.0,
2024-10-21 12:18:41.180118662+00:00,2024-10-21T12:18:41.180284870Z,10,2,38,A,B,1,233.68,30,130,166208,12697911,233.7,233.99,1200,200,1,1,233.68,234.0,30,50,1,1,233.66,234.05,201,27,2,1,233.58,234.1,505,100,2,1,233.53,234.13,10,400,1,1,233.5,234.17,100,1,1,1,233.45,234.25,15,100,1,1,233.4,234.41,110,600,2,2,233.39,234.43,10,105,1,2,233.31,234.5,110,63,2,4,AAPL,0.0,0.0,0.0,
2024-10-21 12:18:41.233925482+00:00,2024-10-21T12:18:41.234091711Z,10,2,38,A,B,0,233.74,200,130,166229,12697993,233.74,233.99,200,200,1,1,233.7,234.0,1200,50,1,1,233.68,234.05,30,27,1,1,233.66,234.1,1,100,1,1,233.58,234.13,505,400,2,1,233.53,234.17,10,1,1,1,233.5,234.25,100,100,1,1,233.45,234.41,15,600,1,2,233.4,234.43,110,105,2,2,233.39,234.5,10,63,1,4,AAPL,0.0,0.0,0.0,
2024-10-21 12:18:44.453502831+00:00,2024-10-21T12:18:44.453669428Z,10,2,38,A,A,0,233.98,200,130,166597,12700269,233.74,233.98,200,200,1,1,233.7,234.0,1200,50,1,1,233.68,234.05,30,27,1,1,233.66,234.1,1,100,1,1,233.58,234.13,505,400,2,1,233.53,234.17,10,1,1,1,233.5,234.25,100,100,1,1,233.45,234.41,15,600,1,2,233.4,234.43,110,105,2,2,233.39,234.5,10,63,1,4,AAPL,0.0,0.0,0.0,
2024-10-21 12:18:44.458571638+00:00,2024-10-21T12:18:44.458737649Z,10,2,38,C,B,0,233.74,200,130,166011,12700368,233.7,233.98,1200,200,1,1,233.68,234.0,30,50,1,1,233.66,234.05,1,27,1,1,233.58,234.1,505,100,2,1,233.53,234.13,10,400,1,1,233.5,234.17,100,1,1,1,233.45,234.25,15,100,1,1,233.4,234.41,110,600,2,2,233.39,234.43,10,105,1,2,233.31,234.5,110,63,2,4,AAPL,0.0,0.0,0.0,
2024-10-21 12:18:44.458583443+00:00,2024-10-21T12:18:44.458749682Z,10,2,38,A,B,2,233.66,200,130,166239,12700369,233.7,233.98,1200,200,1,1,233.68,234.0,30,50,1,1,233.66,234.05,201,27,2,1,233.58,234.1,505,100,2,1,233.53,234.13,10,400,1,1,233.5,234.17,100,1,1,1,233.45,234.25,15,100,1,1,233.4,234.41,110,600,2,2,233.39,234.43,10,105,1,2,233.31,234.5,110,63,2,4,AAPL,0.0,200.0,0.0,
2024-10-21 12:18:44.477818456+00:00,2024-10-21T12:18:44.477985018Z,10,2,38,C,B,1,233.68,30,130,166562,12700470,233.7,233.98,1200,200,1,1,233.66,234.0,201,50,2,1,233.58,234.05,505,27,2,1,233.53,234.1,10,100,1,1,233.5,234.13,100,400,1,1,233.45,234.17,15,1,1,1,233.4,234.25,110,100,2,1,233.39,234.41,10,600,1,2,233.31,234.43,110,105,2,2,233.3,234.5,100,63,1,4,AAPL,0.0,0.0,0.0,
2024-10-21 12:18:44.477924999+00:00,2024-10-21T12:18:44.478091299Z,10,2,38,A,B,2,233.62,28,130,166300,12700471,233.7,233.98,1200,200,1,1,233.66,234.0,201,50,2,1,233.62,234.05,28,27,1,1,233.58,234.1,505,100,2,1,233.53,234.13,10,400,1,1,233.5,234.17,100,1,1,1,233.45,234.25,15,100,1,1,233.4,234.41,110,600,2,2,233.39,234.43,10,105,1,2,233.31,234.5,110,63,2,4,AAPL,0.0,0.0,0.0,
2024-10-21 12:18:47.144489374+00:00,2024-10-21T12:18:47.144655653Z,10,2,38,A,A,0,233.97,200,130,166279,12703555,233.7,233.97,1200,200,1,1,233.66,234.0,201,50,2,1,233.62,234.05,28,27,1,1,233.58,234.1,505,100,2,1,233.53,234.13,10,400,1,1,233.5,234.17,100,1,1,1,233.45,234.25,15,100,1,1,233.4,234.41,110,600,2,2,233.39,234.43,10,105,1,2,233.31,234.5,110,63,2,4,AAPL,0.0,0.0,0.0,
2024-10-21 12:18:47.206323404+00:00,2024-10-21T12:18:47.206489928Z,10,2,38,A,B,1,233.66,200,130,166524,12703653,233.7,233.97,1200,200,1,1,233.66,234.0,401,50,3,1,233.62,234.05,28,27,1,1,233.58,234.1,505,100,2,1,233.53,234.13,10,400,1,1,233.5,234.17,100,1,1,1,233.45,234.25,15,100,1,1,233.4,234.41,110,600,2,2,233.39,234.43,10,105,1,2,233.31,234.5,110,63,2,4,AAPL,0.0,200.0,0.0,
2024-10-21 12:18:47.260861161+00:00,2024-10-21T12:18:47.261027171Z,10,2,38,C,B,1,233.66,200,130,166010,12703745,233.7,233.97,1200,200,1,1,233.66,234.0,201,50,2,1,233.62,234.05,28,27,1,1,233.58,234.1,505,100,2,1,233.53,234.13,10,400,1,1,233.5,234.17,100,1,1,1,233.45,234.25,15,100,1,1,233.4,234.41,110,600,2,2,233.39,234.43,10,105,1,2,233.31,234.5,110,63,2,4,AAPL,0.0,-200.0,0.0,
2024-10-21 12:18:47.260873969+00:00,2024-10-21T12:18:47.261040389Z,10,2,38,A,B,0,233.7,200,130,166420,12703746,233.7,233.97,1400,200,2,1,233.66,234.0,1,50,1,1,233.62,234.05,28,27,1,1,233.58,234.1,505,100,2,1,233.53,234.13,10,400,1,1,233.5,234.17,100,1,1,1,233.45,234.25,15,100,1,1,233.4,234.41,110,600,2,2,233.39,234.43,10,105,1,2,233.31,234.5,110,63,2,4,AAPL,200.0,0.0,200.0,
2024-10-21 12:18:47.459461214+00:00,2024-10-21T12:18:47.459627907Z,10,2,38,A,B,0,233.7,200,130,166693,12703881,233.7,233.97,1600,200,3,1,233.66,234.0,1,50,1,1,233.62,234.05,28,27,1,1,233.58,234.1,505,100,2,1,233.53,234.13,10,400,1,1,233.5,234.17,100,1,1,1,233.45,234.25,15,100,1,1,233.4,234.41,110,600,2,2,233.39,234.43,10,105,1,2,233.31,234.5,110,63,2,4,AAPL,200.0,200.0,400.0,
2024-10-21 12:18:47.513983492+00:00,2024-10-21T12:18:47.514149868Z,10,2,38,C,B,0,233.7,200,130,166376,12703892,233.7,233.97,1400,200,2,1,233.66,234.0,1,50,1,1,233.62,234.05,28,27,1,1,233.58,234.1,505,100,2,1,233.53,234.13,10,400,1,1,233.5,234.17,100,1,1,1,233.45,234.25,15,100,1,1,233.4,234.41,110,600,2,2,233.39,234.43,10,105,1,2,233.31,234.5,110,63,2,4,AAPL,-200.0,-200.0,200.0,
2024-10-21 12:18:47.513995474+00:00,2024-10-21T12:18:47.514162028Z,10,2,38,A,B,0,233.74,200,130,166554,12703893,233.74,233.97,200,200,1,1,233.7,234.0,1200,50,1,1,233.66,234.05,1,27,1,1,233.62,234.1,28,100,1,1,233.58,234.13,505,400,2,1,233.53,234.17,10,1,1,1,233.5,234.25,100,100,1,1,233.45,234.41,15,600,1,2,233.4,234.43,110,105,2,2,233.39,234.5,10,63,1,4,AAPL,0.0,0.0,200.0,
2024-10-21 12:18:48.012656935+00:00,2024-10-21T12:18:48.012823351Z,10,2,38,C,A,0,233.97,200,130,166416,12704330,233.74,234.0,200,50,1,1,233.7,234.05,1200,27,1,1,233.66,234.1,1,100,1,1,233.62,234.13,28,400,1,1,233.58,234.17,505,1,2,1,233.53,234.25,10,100,1,1,233.5,234.41,100,600,1,2,233.45,234.43,15,105,1,2,233.4,234.5,110,63,2,4,233.39,234.75,10,1,1,1,AAPL,0.0,0.0,200.0,
2024-10-21 12:18:48.012670562+00:00,2024-10-21T12:18:48.012837187Z,10,2,38,A,A,1,234.03,200,130,166625,12704331,233.74,234.0,200,50,1,1,233.7,234.03,1200,200,1,1,233.66,234.05,1,27,1,1,233.62,234.1,28,100,1,1,233.58,234.13,505,400,2,1,233.53,234.17,10,1,1,1,233.5,234.25,100,100,1,1,233.45,234.41,15,600,1,2,233.4,234.43,110,105,2,2,233.39,234.5,10,63,1,4,AAPL,0.0,0.0,200.0,
2024-10-21 12:18:48.012835297+00:00,2024-10-21T12:18:48.013001331Z,10,2,38,A,A,1,234.03,200,130,166034,12704332,233.74,234.0,200,50,1,1,233.7,234.03,1200,400,1,2,233.66,234.05,1,27,1,1,233.62,234.1,28,100,1,1,233.58,234.13,505,400,2,1,233.53,234.17,10,1,1,1,233.5,234.25,100,100,1,1,233.45,234.41,15,600,1,2,233.4,234.43,110,105,2,2,233.39,234.5,10,63,1,4,AAPL,0.0,-200.0,200.0,
2024-10-21 12:18:48.013209412+00:00,2024-10-21T12:18:48.013375765Z,10,2,38,C,A,2,234.05,27,130,166353,12704333,233.74,234.0,200,50,1,1,233.7,234.03,1200,400,1,2,233.66,234.1,1,100,1,1,233.62,234.13,28,400,1,1,233.58,234.17,505,1,2,1,233.53,234.25,10,100,1,1,233.5,234.41,100,600,1,2,233.45,234.43,15,105,1,2,233.4,234.5,110,63,2,4,233.39,234.75,10,1,1,1,AAPL,0.0,0.0,200.0,
2024-10-21 12:18:48.013312876+00:00,2024-10-21T12:18:48.013479203Z,10,2,38,A,A,2,234.1,28,130,166327,12704334,233.74,234.0,200,50,1,1,233.7,234.03,1200,400,1,2,233.66,234.1,1,128,1,2,233.62,234.13,28,400,1,1,233.58,234.17,505,1,2,1,233.53,234.25,10,100,1,1,233.5,234.41,100,600,1,2,233.45,234.43,15,105,1,2,233.4,234.5,110,63,2,4,233.39,234.75,10,1,1,1,AAPL,0.0,-28.0,200.0,
2024-10-21 12:18:48.070285169+00:00,2024-10-21T12:18:48.070451078Z,10,2,38,C,A,1,234.03,200,130,165909,12704401,233.74,234.0,200,50,1,1,233.7,234.03,1200,200,1,1,233.66,234.1,1,128,1,2,233.62,234.13,28,400,1,1,233.58,234.17,505,1,2,1,233.53,234.25,10,100,1,1,233.5,234.41,100,600,1,2,233.45,234.43,15,105,1,2,233.4,234.5,110,63,2,4,233.39,234.75,10,1,1,1,AAPL,0.0,200.0,200.0,
2024-10-21 12:18:48.070297042+00:00,2024-10-21T12:18:48.070465807Z,10,2,38,A,A,0,233.97,200,128,168765,12704402,233.74,233.97,200,200,1,1,233.7,234.0,1200,50,1,1,233.66,234.1,1,128,1,2,233.62,234.13,28,400,1,1,233.58,234.17,505,1,2,1,233.53,234.25,10,100,1,1,233.5,234.41,100,600,1,2,233.45,234.43,15,105,1,2,233.4,234.5,110,63,2,4,233.39,234.75,10,1,1,1,AAPL,0.0,0.0,200.0,
2024-10-21 12:18:48.199908254+00:00,2024-10-21T12:18:48.200074274Z,10,2,38,C,B,0,233.74,200,130,166020,12704576,233.7,233.97,1200,200,1,1,233.66,234.0,1,50,1,1,233.62,234.1,28,128,1,2,233.58,234.13,505,400,2,1,233.53,234.17,10,1,1,1,233.5,234.25,100,100,1,1,233.45,234.41,15,600,1,2,233.4,234.43,110,105,2,2,233.39,234.5,10,63,1,4,233.31,234.75,110,1,2,1,AAPL,0.0,0.0,200.0,
2024-10-21 12:18:48.199920865+00:00,2024-10-21T12:18:48.200087164Z,10,2,38,A,B,1,233.68,200,130,166299,12704577,233.7,233.97,1200,200,1,1,233.68,234.0,200,50,1,1,233.66,234.1,1,128,1,2,233.62,234.13,28,400,1,1,233.58,234.17,505,1,2,1,233.53,234.25,10,100,1,1,233.5,234.41,100,600,1,2,233.45,234.43,15,105,1,2,233.4,234.5,110,63,2,4,233.39,234.75,10,1,1,1,AAPL,0.0,0.0,200.0,
2024-10-21 12:18:48.199942139+00:00,2024-10-21T12:18:48.200108087Z,10,2,38,C,B,1,233.68,200,130,165948,12704578,233.7,233.97,1200,200,1,1,233.66,234.0,1,50,1,1,233.62,234.1,28,128,1,2,233.58,234.13,505,400,2,1,233.53,234.17,10,1,1,1,233.5,234.25,100,100,1,1,233.45,234.41,15,600,1,2,233.4,234.43,110,105,2,2,233.39,234.5,10,63,1,4,233.31,234.75,110,1,2,1,AAPL,0.0,0.0,200.0,
2024-10-21 12:18:48.200029266+00:00,2024-10-21T12:18:48.200195970Z,10,2,38,A,B,2,233.65,200,130,166704,12704579,233.7,233.97,1200,200,1,1,233.66,234.0,1,50,1,1,233.65,234.1,200,128,1,2,233.62,234.13,28,400,1,1,233.58,234.17,505,1,2,1,233.53,234.25,10,100,1,1,233.5,234.41,100,600,1,2,233.45,234.43,15,105,1,2,233.4,234.5,110,63,2,4,233.39,234.75,10,1,1,1,AAPL,0.0,0.0,200.0,
2024-10-21 12:18:48.200502296+00:00,2024-10-21T12:18:48.200668344Z,10,2,38,C,B,3,233.62,28,130,166048,12704580,233.7,233.97,1200,200,1,1,233.66,234.0,1,50,1,1,233.65,234.1,200,128,1,2,233.58,234.13,505,400,2,1,233.53,234.17,10,1,1,1,233.5,234.25,100,100,1,1,233.45,234.41,15,600,1,2,233.4,234.43,110,105,2,2,233.39,234.5,10,63,1,4,233.31,234.75,110,1,2,1,AAPL,0.0,0.0,200.0,
2024-10-21 12:18:48.200553666+00:00,2024-10-21T12:18:48.200720265Z,10,2,38,A,B,1,233.67,27,130,166599,12704581,233.7,233.97,1200,200,1,1,233.67,234.0,27,50,1,1,233.66,234.1,1,128,1,2,233.65,234.13,200,400,1,1,233.58,234.17,505,1,2,1,233.53,234.25,10,100,1,1,233.5,234.41,100,600,1,2,233.45,234.43,15,105,1,2,233.4,234.5,110,63,2,4,233.39,234.75,10,1,1,1,AAPL,0.0,0.0,200.0,
2024-10-21 12:18:48.213222660+00:00,2024-10-21T12:18:48.213389240Z,10,2,38,C,B,1,233.67,27,130,166580,12704589,233.7,233.97,1200,200,1,1,233.66,234.0,1,50,1,1,233.65,234.1,200,128,1,2,233.58,234.13,505,400,2,1,233.53,234.17,10,1,1,1,233.5,234.25,100,100,1,1,233.45,234.41,15,600,1,2,233.4,234.43,110,105,2,2,233.39,234.5,10,63,1,4,233.31,234.75,110,1,2,1,AAPL,0.0,0.0,200.0,
2024-10-21 12:18:49.922943623+00:00,2024-10-21T12:18:49.923109783Z,10,2,38,C,A,2,234.1,28,130,166160,12706013,233.7,233.97,1200,200,1,1,233.66,234.0,1,50,1,1,233.65,234.1,200,100,1,1,233.58,234.13,505,400,2,1,233.53,234.17,10,1,1,1,233.5,234.25,100,100,1,1,233.45,234.41,15,600,1,2,233.4,234.43,110,105,2,2,233.39,234.5,10,63,1,4,233.31,234.75,110,1,2,1,AAPL,0.0,28.0,0.0,
2024-10-21 12:18:49.923091366+00:00,2024-10-21T12:18:49.923258127Z,10,2,38,A,A,2,234.05,28,130,166761,12706014,233.7,233.97,1200,200,1,1,233.66,234.0,1,50,1,1,233.65,234.05,200,28,1,1,233.58,234.1,505,100,2,1,233.53,234.13,10,400,1,1,233.5,234.17,100,1,1,1,233.45,234.25,15,100,1,1,233.4,234.41,110,600,2,2,233.39,234.43,10,105,1,2,233.31,234.5,110,63,2,4,AAPL,0.0,0.0,0.0,
2024-10-21 12:18:51.254925630+00:00,2024-10-21T12:18:51.255092000Z,10,2,38,A,B,1,233.69,200,130,166370,12707192,233.7,233.97,1200,200,1,1,233.69,234.0,200,50,1,1,233.66,234.05,1,28,1,1,233.58,234.1,505,100,2,1,233.53,234.13,10,400,1,1,233.5,234.17,100,1,1,1,233.45,234.25,15,100,1,1,233.4,234.41,110,600,2,2,233.39,234.43,10,105,1,2,233.31,234.5,110,63,2,4,AAPL,0.0,0.0,0.0,
2024-10-21 12:18:51.423329256+00:00,2024-10-21T12:18:51.423495230Z,10,2,38,C,A,2,234.05,28,130,165974,12707840,233.7,233.97,1200,200,1,1,233.69,234.0,200,50,1,1,233.66,234.1,1,100,1,1,233.58,234.13,505,400,2,1,233.53,234.17,10,1,1,1,233.5,234.25,100,100,1,1,233.45,234.41,15,600,1,2,233.4,234.43,110,105,2,2,233.39,234.5,10,63,1,4,233.31,234.75,110,1,2,1,AAPL,0.0,0.0,0.0,
2024-10-21 12:18:51.423381788+00:00,2024-10-21T12:18:51.423548073Z,10,2,38,A,A,2,234.04,30,130,166285,12707841,233.7,233.97,1200,200,1,1,233.69,234.0,200,50,1,1,233.66,234.04,1,30,1,1,233.58,234.1,505,100,2,1,233.53,234.13,10,400,1,1,233.5,234.17,100,1,1,1,233.45,234.25,15,100,1,1,233.4,234.41,110,600,2,2,233.39,234.43,10,105,1,2,233.31,234.5,110,63,2,4,AAPL,0.0,0.0,0.0,
2024-10-21 12:18:51.430250460+00:00,2024-10-21T12:18:51.430417250Z,10,2,38,A,B,1,233.69,200,130,166790,12707856,233.7,233.97,1200,200,1,1,233.69,234.0,400,50,2,1,233.66,234.04,1,30,1,1,233.58,234.1,505,100,2,1,233.53,234.13,10,400,1,1,233.5,234.17,100,1,1,1,233.45,234.25,15,100,1,1,233.4,234.41,110,600,2,2,233.39,234.43,10,105,1,2,233.31,234.5,110,63,2,4,AAPL,0.0,200.0,0.0,
2024-10-21 12:18:53.922913086+00:00,2024-10-21T12:18:53.923079620Z,10,2,38,A,B,3,233.62,27,130,166534,12710377,233.7,233.97,1200,200,1,1,233.69,234.0,400,50,2,1,233.66,234.04,1,30,1,1,233.62,234.1,27,100,1,1,233.58,234.13,505,400,2,1,233.53,234.17,10,1,1,1,233.5,234.25,100,100,1,1,233.45,234.41,15,600,1,2,233.4,234.43,110,105,2,2,233.39,234.5,10,63,1,4,AAPL,0.0,0.0,0.0,
2024-10-21 12:19:00.083834280+00:00,2024-10-21T12:19:00.084000089Z,10,2,38,C,B,1,233.69,200,130,165809,12715313,233.7,233.97,1200,200,1,1,233.69,234.0,200,50,1,1,233.66,234.04,1,30,1,1,233.62,234.1,27,100,1,1,233.58,234.13,505,400,2,1,233.53,234.17,10,1,1,1,233.5,234.25,100,100,1,1,233.45,234.41,15,600,1,2,233.4,234.43,110,105,2,2,233.39,234.5,10,63,1,4,AAPL,0.0,-200.0,0.0,
2024-10-21 12:19:00.083843895+00:00,2024-10-21T12:19:00.084009808Z,10,2,38,C,B,1,233.69,200,130,165913,12715314,233.7,233.97,1200,200,1,1,233.66,234.0,1,50,1,1,233.62,234.04,27,30,1,1,233.58,234.1,505,100,2,1,233.53,234.13,10,400,1,1,233.5,234.17,100,1,1,1,233.45,234.25,15,100,1,1,233.4,234.41,110,600,2,2,233.39,234.43,10,105,1,2,233.31,234.5,110,63,2,4,AAPL,0.0,0.0,0.0,
2024-10-21 12:19:00.083854884+00:00,2024-10-21T12:19:00.084021335Z,10,2,38,A,B,1,233.68,200,130,166451,12715315,233.7,233.97,1200,200,1,1,233.68,234.0,200,50,1,1,233.66,234.04,1,30,1,1,233.62,234.1,27,100,1,1,233.58,234.13,505,400,2,1,233.53,234.17,10,1,1,1,233.5,234.25,100,100,1,1,233.45,234.41,15,600,1,2,233.4,234.43,110,105,2,2,233.39,234.5,10,63,1,4,AAPL,0.0,0.0,0.0,
2024-10-21 12:19:00.143474250+00:00,2024-10-21T12:19:00.143641105Z,10,2,38,A,B,1,233.69,200,130,166855,12715619,233.7,233.97,1200,200,1,1,233.69,234.0,200,50,1,1,233.66,234.04,1,30,1,1,233.62,234.1,27,100,1,1,233.58,234.13,505,400,2,1,233.53,234.17,10,1,1,1,233.5,234.25,100,100,1,1,233.45,234.41,15,600,1,2,233.4,234.43,110,105,2,2,233.39,234.5,10,63,1,4,AAPL,0.0,0.0,0.0,
2024-10-21 12:19:00.197516009+00:00,2024-10-21T12:19:00.197681940Z,10,2,38,A,B,1,233.69,200,130,165931,12715801,233.7,233.97,1200,200,1,1,233.69,234.0,400,50,2,1,233.66,234.04,1,30,1,1,233.62,234.1,27,100,1,1,233.58,234.13,505,400,2,1,233.53,234.17,10,1,1,1,233.5,234.25,100,100,1,1,233.45,234.41,15,600,1,2,233.4,234.43,110,105,2,2,233.39,234.5,10,63,1,4,AAPL,0.0,200.0,0.0,
2024-10-21 12:19:00.198016624+00:00,2024-10-21T12:19:00.198183165Z,10,2,38,C,B,3,233.62,27,130,166541,12715804,233.7,233.97,1200,200,1,1,233.69,234.0,400,50,2,1,233.66,234.04,1,30,1,1,233.58,234.1,505,100,2,1,233.53,234.13,10,400,1,1,233.5,234.17,100,1,1,1,233.45,234.25,15,100,1,1,233.4,234.41,110,600,2,2,233.39,234.43,10,105,1,2,233.31,234.5,110,63,2,4,AAPL,0.0,0.0,0.0,
2024-10-21 12:19:00.198056773+00:00,2024-10-21T12:19:00.198223152Z,10,2,38,A,B,2,233.66,27,130,166379,12715805,233.7,233.97,1200,200,1,1,233.69,234.0,400,50,2,1,233.66,234.04,28,30,2,1,233.58,234.1,505,100,2,1,233.53,234.13,10,400,1,1,233.5,234.17,100,1,1,1,233.45,234.25,15,100,1,1,233.4,234.41,110,600,2,2,233.39,234.43,10,105,1,2,233.31,234.5,110,63,2,4,AAPL,0.0,27.0,0.0,
2024-10-21 12:19:00.251362837+00:00,2024-10-21T12:19:00.251528734Z,10,2,38,C,B,1,233.69,200,130,165897,12715921,233.7,233.97,1200,200,1,1,233.69,234.0,200,50,1,1,233.66,234.04,28,30,2,1,233.58,234.1,505,100,2,1,233.53,234.13,10,400,1,1,233.5,234.17,100,1,1,1,233.45,234.25,15,100,1,1,233.4,234.41,110,600,2,2,233.39,234.43,10,105,1,2,233.31,234.5,110,63,2,4,AAPL,0.0,-200.0,0.0,
2024-10-21 12:19:00.251375630+00:00,2024-10-21T12:19:00.251542039Z,10,2,38,A,B,0,233.73,200,130,166409,12715922,233.73,233.97,200,200,1,1,233.7,234.0,1200,50,1,1,233.66,234.04,28,30,2,1,233.58,234.1,505,100,2,1,233.53,234.13,10,400,1,1,233.5,234.17,100,1,1,1,233.45,234.25,15,100,1,1,233.4,234.41,110,600,2,2,233.39,234.43,10,105,1,2,233.31,234.5,110,63,2,4,AAPL,0.0,0.0,0.0,
2024-10-21 12:19:02.578739513+00:00,2024-10-21T12:19:02.578905341Z,10,2,38,C,B,0,233.73,200,130,165828,12718269,233.7,233.97,1200,200,1,1,233.66,234.0,28,50,2,1,233.58,234.04,505,30,2,1,233.53,234.1,10,100,1,1,233.5,234.13,100,400,1,1,233.45,234.17,15,1,1,1,233.4,234.25,110,100,2,1,233.39,234.41,10,600,1,2,233.31,234.43,110,105,2,2,233.3,234.5,100,63,1,4,AAPL,0.0,0.0,0.0,
2024-10-21 12:19:02.578752989+00:00,2024-10-21T12:19:02.578919174Z,10,2,38,A,B,1,233.68,200,130,166185,12718270,233.7,233.97,1200,200,1,1,233.68,234.0,200,50,1,1,233.66,234.04,28,30,2,1,233.58,234.1,505,100,2,1,233.53,234.13,10,400,1,1,233.5,234.17,100,1,1,1,233.45,234.25,15,100,1,1,233.4,234.41,110,600,2,2,233.39,234.43,10,105,1,2,233.31,234.5,110,63,2,4,AAPL,0.0,0.0,0.0,
2024-10-21 12:19:02.578784855+00:00,2024-10-21T12:19:02.578950637Z,10,2,38,C,B,1,233.68,200,130,165782,12718271,233.7,233.97,1200,200,1,1,233.66,234.0,28,50,2,1,233.58,234.04,505,30,2,1,233.53,234.1,10,100,1,1,233.5,234.13,100,400,1,1,233.45,234.17,15,1,1,1,233.4,234.25,110,100,2,1,233.39,234.41,10,600,1,2,233.31,234.43,110,105,2,2,233.3,234.5,100,63,1,4,AAPL,0.0,0.0,0.0,
2024-10-21 12:19:02.583722081+00:00,2024-10-21T12:19:02.583888440Z,10,2,38,A,B,2,233.65,200,130,166359,12718279,233.7,233.97,1200,200,1,1,233.66,234.0,28,50,2,1,233.65,234.04,200,30,1,1,233.58,234.1,505,100,2,1,233.53,234.13,10,400,1,1,233.5,234.17,100,1,1,1,233.45,234.25,15,100,1,1,233.4,234.41,110,600,2,2,233.39,234.43,10,105,1,2,233.31,234.5,110,63,2,4,AAPL,0.0,0.0,0.0,
2024-10-21 12:19:05.633956677+00:00,2024-10-21T12:19:05.634123171Z,10,2,38,A,B,0,233.73,200,130,166494,12720933,233.73,233.97,200,200,1,1,233.7,234.0,1200,50,1,1,233.66,234.04,28,30,2,1,233.58,234.1,505,100,2,1,233.53,234.13,10,400,1,1,233.5,234.17,100,1,1,1,233.45,234.25,15,100,1,1,233.4,234.41,110,600,2,2,233.39,234.43,10,105,1,2,233.31,234.5,110,63,2,4,AAPL,0.0,0.0,0.0,
2024-10-21 12:19:06.744561325+00:00,2024-10-21T12:19:06.744727908Z,10,2,38,A,A,0,233.96,200,130,166583,12722330,233.73,233.96,200,200,1,1,233.7,234.0,1200,50,1,1,233.66,234.04,28,30,2,1,233.58,234.1,505,100,2,1,233.53,234.13,10,400,1,1,233.5,234.17,100,1,1,1,233.45,234.25,15,100,1,1,233.4,234.41,110,600,2,2,233.39,234.43,10,105,1,2,233.31,234.5,110,63,2,4,AAPL,0.0,0.0,0.0,
2024-10-21 12:19:07.485167707+00:00,2024-10-21T12:19:07.485333806Z,10,2,38,C,B,0,233.73,200,130,166099,12723226,233.7,233.96,1200,200,1,1,233.66,234.0,28,50,2,1,233.58,234.04,505,30,2,1,233.53,234.1,10,100,1,1,233.5,234.13,100,400,1,1,233.45,234.17,15,1,1,1,233.4,234.25,110,100,2,1,233.39,234.41,10,600,1,2,233.31,234.43,110,105,2,2,233.3,234.5,100,63,1,4,AAPL,0.0,0.0,0.0,
2024-10-21 12:19:07.485180575+00:00,2024-10-21T12:19:07.485347068Z,10,2,38,A,B,1,233.66,200,130,166493,12723227,233.7,233.96,1200,200,1,1,233.66,234.0,228,50,3,1,233.58,234.04,505,30,2,1,233.53,234.1,10,100,1,1,233.5,234.13,100,400,1,1,233.45,234.17,15,1,1,1,233.4,234.25,110,100,2,1,233.39,234.41,10,600,1,2,233.31,234.43,110,105,2,2,233.3,234.5,100,63,1,4,AAPL,0.0,200.0,0.0,
2024-10-21 12:19:07.567472916+00:00,2024-10-21T12:19:07.567639201Z,10,2,38,A,A,2,234.03,27,130,166285,12723377,233.7,233.96,1200,200,1,1,233.66,234.0,228,50,3,1,233.58,234.03,505,27,2,1,233.53,234.04,10,30,1,1,233.5,234.1,100,100,1,1,233.45,234.13,15,400,1,1,233.4,234.17,110,1,2,1,233.39,234.25,10,100,1,1,233.31,234.41,110,600,2,2,233.3,234.43,100,105,1,2,AAPL,0.0,0.0,0.0,
2024-10-21 12:19:07.624621845+00:00,2024-10-21T12:19:07.624787875Z,10,2,38,C,A,3,234.04,30,130,166030,12723449,233.7,233.96,1200,200,1,1,233.66,234.0,228,50,3,1,233.58,234.03,505,27,2,1,233.53,234.1,10,100,1,1,233.5,234.13,100,400,1,1,233.45,234.17,15,1,1,1,233.4,234.25,110,100,2,1,233.39,234.41,10,600,1,2,233.31,234.43,110,105,2,2,233.3,234.5,100,63,1,4,AAPL,0.0,0.0,0.0,
2024-10-21 12:19:08.123983275+00:00,2024-10-21T12:19:08.124149233Z,10,2,38,C,A,0,233.96,200,130,165958,12724349,233.7,234.0,1200,50,1,1,233.66,234.03,228,27,3,1,233.58,234.1,505,100,2,1,233.53,234.13,10,400,1,1,233.5,234.17,100,1,1,1,233.45,234.25,15,100,1,1,233.4,234.41,110,600,2,2,233.39,234.43,10,105,1,2,233.31,234.5,110,63,2,4,233.3,234.75,100,1,1,1,AAPL,0.0,0.0,0.0,
2024-10-21 12:19:08.201710146+00:00,2024-10-21T12:19:08.201876654Z,10,2,38,A,A,0,233.96,200,130,166508,12724487,233.7,233.96,1200,200,1,1,233.66,234.0,228,50,3,1,233.58,234.03,505,27,2,1,233.53,234.1,10,100,1,1,233.5,234.13,100,400,1,1,233.45,234.17,15,1,1,1,233.4,234.25,110,100,2,1,233.39,234.41,10,600,1,2,233.31,234.43,110,105,2,2,233.3,234.5,100,63,1,4,AAPL,0.0,0.0,0.0,
2024-10-21 12:19:10.540372657+00:00,2024-10-21T12:19:10.540539563Z,10,2,38,A,B,1,233.68,200,130,166906,12726299,233.7,233.96,1200,200,1,1,233.68,234.0,200,50,1,1,233.66,234.03,28,27,2,1,233.58,234.1,505,100,2,1,233.53,234.13,10,400,1,1,233.5,234.17,100,1,1,1,233.45,234.25,15,100,1,1,233.4,234.41,110,600,2,2,233.39,234.43,10,105,1,2,233.31,234.5,110,63,2,4,AAPL,0.0,0.0,0.0,
2024-10-21 12:19:10.824415398+00:00,2024-10-21T12:19:10.824581833Z,10,2,38,C,A,7,234.41,39,130,166435,12726899,233.7,233.96,1200,200,1,1,233.68,234.0,200,50,1,1,233.66,234.03,28,27,2,1,233.58,234.1,505,100,2,1,233.53,234.13,10,400,1,1,233.5,234.17,100,1,1,1,233.45,234.25,15,100,1,1,233.4,234.41,110,561,2,2,233.39,234.43,10,105,1,2,233.31,234.5,110,63,2,4,AAPL,0.0,0.0,0.0,
2024-10-21 12:19:10.828162441+00:00,2024-10-21T12:19:10.828328587Z,10,2,38,A,A,7,234.41,39,130,166146,12726909,233.7,233.96,1200,200,1,1,233.68,234.0,200,50,1,1,233.66,234.03,28,27,2,1,233.58,234.1,505,100,2,1,233.53,234.13,10,400,1,1,233.5,234.17,100,1,1,1,233.45,234.25,15,100,1,1,233.4,234.41,110,600,2,3,233.39,234.43,10,105,1,2,233.31,234.5,110,63,2,4,AAPL,0.0,0.0,0.0,
2024-10-21 12:19:14.207440891+00:00,2024-10-21T12:19:14.207607166Z,10,2,38,A,B,1,233.68,200,130,166275,12730136,233.7,233.96,1200,200,1,1,233.68,234.0,400,50,2,1,233.66,234.03,28,27,2,1,233.58,234.1,505,100,2,1,233.53,234.13,10,400,1,1,233.5,234.17,100,1,1,1,233.45,234.25,15,100,1,1,233.4,234.41,110,600,2,3,233.39,234.43,10,105,1,2,233.31,234.5,110,63,2,4,AAPL,0.0,200.0,0.0,
2024-10-21 12:19:21.463656720+00:00,2024-10-21T12:19:21.463822961Z,10,2,38,C,A,7,234.41,39,130,166241,12734671,233.7,233.96,1200,200,1,1,233.68,234.0,400,50,2,1,233.66,234.03,28,27,2,1,233.58,234.1,505,100,2,1,233.53,234.13,10,400,1,1,233.5,234.17,100,1,1,1,233.45,234.25,15,100,1,1,233.4,234.41,110,561,2,2,233.39,234.43,10,105,1,2,233.31,234.5,110,63,2,4,AAPL,0.0,0.0,0.0,
2024-10-21 12:19:21.463763491+00:00,2024-10-21T12:19:21.463929496Z,10,2,38,C,A,7,234.41,61,130,166005,12734672,233.7,233.96,1200,200,1,1,233.68,234.0,400,50,2,1,233.66,234.03,28,27,2,1,233.58,234.1,505,100,2,1,233.53,234.13,10,400,1,1,233.5,234.17,100,1,1,1,233.45,234.25,15,100,1,1,233.4,234.41,110,500,2,1,233.39,234.43,10,105,1,2,233.31,234.5,110,63,2,4,AAPL,0.0,0.0,0.0,
2024-10-21 12:19:31.377322230+00:00,2024-10-21T12:19:31.377488376Z,10,2,38,C,A,0,233.96,200,130,166146,12742017,233.7,234.0,1200,50,1,1,233.68,234.03,400,27,2,1,233.66,234.1,28,100,2,1,233.58,234.13,505,400,2,1,233.53,234.17,10,1,1,1,233.5,234.25,100,100,1,1,233.45,234.41,15,500,1,1,233.4,234.43,110,105,2,2,233.39,234.5,10,63,1,4,233.31,234.75,110,1,2,1,AAPL,0.0,0.0,0.0,
2024-10-21 12:19:31.377334380+00:00,2024-10-21T12:19:31.377500536Z,10,2,38,A,A,0,233.98,200,130,166156,12742018,233.7,233.98,1200,200,1,1,233.68,234.0,400,50,2,1,233.66,234.03,28,27,2,1,233.58,234.1,505,100,2,1,233.53,234.13,10,400,1,1,233.5,234.17,100,1,1,1,233.45,234.25,15,100,1,1,233.4,234.41,110,500,2,1,233.39,234.43,10,105,1,2,233.31,234.5,110,63,2,4,AAPL,0.0,0.0,0.0,
2024-10-21 12:19:31.410847128+00:00,2024-10-21T12:19:31.411013263Z,10,2,38,C,A,0,233.98,200,130,166135,12742043,233.7,234.0,1200,50,1,1,233.68,234.03,400,27,2,1,233.66,234.1,28,100,2,1,233.58,234.13,505,400,2,1,233.53,234.17,10,1,1,1,233.5,234.25,100,100,1,1,233.45,234.41,15,500,1,1,233.4,234.43,110,105,2,2,233.39,234.5,10,63,1,4,233.31,234.75,110,1,2,1,AAPL,0.0,0.0,0.0,
2024-10-21 12:19:31.410860369+00:00,2024-10-21T12:19:31.411026550Z,10,2,38,A,A,1,234.03,200,130,166181,12742044,233.7,234.0,1200,50,1,1,233.68,234.03,400,227,2,2,233.66,234.1,28,100,2,1,233.58,234.13,505,400,2,1,233.53,234.17,10,1,1,1,233.5,234.25,100,100,1,1,233.45,234.41,15,500,1,1,233.4,234.43,110,105,2,2,233.39,234.5,10,63,1,4,233.31,234.75,110,1,2,1,AAPL,0.0,-200.0,0.0,
2024-10-21 12:19:31.424732441+00:00,2024-10-21T12:19:31.424898662Z,10,2,38,C,B,2,233.66,27,130,166221,12742086,233.7,234.0,1200,50,1,1,233.68,234.03,400,227,2,2,233.66,234.1,1,100,1,1,233.58,234.13,505,400,2,1,233.53,234.17,10,1,1,1,233.5,234.25,100,100,1,1,233.45,234.41,15,500,1,1,233.4,234.43,110,105,2,2,233.39,234.5,10,63,1,4,233.31,234.75,110,1,2,1,AAPL,0.0,-27.0,0.0,
2024-10-21 12:19:31.424790390+00:00,2024-10-21T12:19:31.424956553Z,10,2,38,A,B,2,233.67,30,130,166163,12742087,233.7,234.0,1200,50,1,1,233.68,234.03,400,227,2,2,233.67,234.1,30,100,1,1,233.66,234.13,1,400,1,1,233.58,234.17,505,1,2,1,233.53,234.25,10,100,1,1,233.5,234.41,100,500,1,1,233.45,234.43,15,105,1,2,233.4,234.5,110,63,2,4,233.39,234.75,10,1,1,1,AAPL,0.0,0.0,0.0,
2024-10-21 12:19:31.428123190+00:00,2024-10-21T12:19:31.428289474Z,10,2,38,C,A,1,234.03,27,130,166284,12742092,233.7,234.0,1200,50,1,1,233.68,234.03,400,200,2,1,233.67,234.1,30,100,1,1,233.66,234.13,1,400,1,1,233.58,234.17,505,1,2,1,233.53,234.25,10,100,1,1,233.5,234.41,100,500,1,1,233.45,234.43,15,105,1,2,233.4,234.5,110,63,2,4,233.39,234.75,10,1,1,1,AAPL,0.0,27.0,0.0,
2024-10-21 12:19:31.428166239+00:00,2024-10-21T12:19:31.428332471Z,10,2,38,A,A,2,234.09,30,130,166232,12742093,233.7,234.0,1200,50,1,1,233.68,234.03,400,200,2,1,233.67,234.09,30,30,1,1,233.66,234.1,1,100,1,1,233.58,234.13,505,400,2,1,233.53,234.17,10,1,1,1,233.5,234.25,100,100,1,1,233.45,234.41,15,500,1,1,233.4,234.43,110,105,2,2,233.39,234.5,10,63,1,4,AAPL,0.0,0.0,0.0,
2024-10-21 12:19:31.428177171+00:00,2024-10-21T12:19:31.428343415Z,10,2,38,C,B,1,233.68,200,130,166244,12742094,233.7,234.0,1200,50,1,1,233.68,234.03,200,200,1,1,233.67,234.09,30,30,1,1,233.66,234.1,1,100,1,1,233.58,234.13,505,400,2,1,233.53,234.17,10,1,1,1,233.5,234.25,100,100,1,1,233.45,234.41,15,500,1,1,233.4,234.43,110,105,2,2,233.39,234.5,10,63,1,4,AAPL,0.0,-200.0,0.0,
2024-10-21 12:19:31.428190903+00:00,2024-10-21T12:19:31.428357645Z,10,2,38,A,B,1,233.69,400,130,166742,12742095,233.7,234.0,1200,50,1,1,233.69,234.03,400,200,1,1,233.67,234.09,30,30,1,1,233.66,234.1,1,100,1,1,233.58,234.13,505,400,2,1,233.53,234.17,10,1,1,1,233.5,234.25,100,100,1,1,233.45,234.41,15,500,1,1,233.4,234.43,110,105,2,2,233.39,234.5,10,63,1,4,AAPL,0.0,0.0,0.0,
2024-10-21 12:19:35.701549120+00:00,2024-10-21T12:19:35.701715260Z,10,2,38,C,B,1,233.69,200,130,166140,12745727,233.7,234.0,1200,50,1,1,233.69,234.03,200,200,1,1,233.67,234.09,30,30,1,1,233.66,234.1,1,100,1,1,233.58,234.13,505,400,2,1,233.53,234.17,10,1,1,1,233.5,234.25,100,100,1,1,233.45,234.41,15,500,1,1,233.4,234.43,110,105,2,2,233.39,234.5,10,63,1,4,AAPL,0.0,-200.0,0.0,
2024-10-21 12:19:38.701678685+00:00,2024-10-21T12:19:38.701844794Z,10,2,38,A,B,1,233.69,200,130,166109,12748118,233.7,234.0,1200,50,1,1,233.69,234.03,400,200,2,1,233.67,234.09,30,30,1,1,233.66,234.1,1,100,1,1,233.58,234.13,505,400,2,1,233.53,234.17,10,1,1,1,233.5,234.25,100,100,1,1,233.45,234.41,15,500,1,1,233.4,234.43,110,105,2,2,233.39,234.5,10,63,1,4,AAPL,0.0,200.0,0.0,
2024-10-21 12:19:38.756179281+00:00,2024-10-21T12:19:38.756345640Z,10,2,38,C,B,1,233.69,200,130,166359,12748157,233.7,234.0,1200,50,1,1,233.69,234.03,200,200,1,1,233.67,234.09,30,30,1,1,233.66,234.1,1,100,1,1,233.58,234.13,505,400,2,1,233.53,234.17,10,1,1,1,233.5,234.25,100,100,1,1,233.45,234.41,15,500,1,1,233.4,234.43,110,105,2,2,233.39,234.5,10,63,1,4,AAPL,0.0,-200.0,0.0,
2024-10-21 12:19:38.756191248+00:00,2024-10-21T12:19:38.756358436Z,10,2,38,A,B,0,233.73,200,130,167188,12748158,233.73,234.0,200,50,1,1,233.7,234.03,1200,200,1,1,233.67,234.09,30,30,1,1,233.66,234.1,1,100,1,1,233.58,234.13,505,400,2,1,233.53,234.17,10,1,1,1,233.5,234.25,100,100,1,1,233.45,234.41,15,500,1,1,233.4,234.43,110,105,2,2,233.39,234.5,10,63,1,4,AAPL,0.0,0.0,0.0,
2024-10-21 12:19:40.083326842+00:00,2024-10-21T12:19:40.083493208Z,10,2,38,A,A,1,234.03,200,130,166366,12749182,233.73,234.0,200,50,1,1,233.7,234.03,1200,400,1,2,233.67,234.09,30,30,1,1,233.66,234.1,1,100,1,1,233.58,234.13,505,400,2,1,233.53,234.17,10,1,1,1,233.5,234.25,100,100,1,1,233.45,234.41,15,500,1,1,233.4,234.43,110,105,2,2,233.39,234.5,10,63,1,4,AAPL,0.0,-200.0,0.0,
2024-10-21 12:19:40.137972145+00:00,2024-10-21T12:19:40.138138274Z,10,2,38,C,A,1,234.03,200,130,166129,12749218,233.73,234.0,200,50,1,1,233.7,234.03,1200,200,1,1,233.67,234.09,30,30,1,1,233.66,234.1,1,100,1,1,233.58,234.13,505,400,2,1,233.53,234.17,10,1,1,1,233.5,234.25,100,100,1,1,233.45,234.41,15,500,1,1,233.4,234.43,110,105,2,2,233.39,234.5,10,63,1,4,AAPL,0.0,200.0,0.0,
2024-10-21 12:19:40.137983855+00:00,2024-10-21T12:19:40.138150186Z,10,2,38,A,A,1,234.02,200,130,166331,12749219,233.73,234.0,200,50,1,1,233.7,234.02,1200,200,1,1,233.67,234.09,30,30,1,1,233.66,234.1,1,100,1,1,233.58,234.13,505,400,2,1,233.53,234.17,10,1,1,1,233.5,234.25,100,100,1,1,233.45,234.41,15,500,1,1,233.4,234.43,110,105,2,2,233.39,234.5,10,63,1,4,AAPL,0.0,0.0,0.0,
2024-10-21 12:19:42.737152214+00:00,2024-10-21T12:19:42.737318215Z,10,2,38,C,B,0,233.73,200,130,166001,12752002,233.7,234.0,1200,50,1,1,233.67,234.02,30,200,1,1,233.66,234.09,1,30,1,1,233.58,234.1,505,100,2,1,233.53,234.13,10,400,1,1,233.5,234.17,100,1,1,1,233.45,234.25,15,100,1,1,233.4,234.41,110,500,2,1,233.39,234.43,10,105,1,2,233.31,234.5,110,63,2,4,AAPL,0.0,0.0,0.0,
2024-10-21 12:19:42.737165303+00:00,2024-10-21T12:19:42.737331418Z,10,2,38,A,B,1,233.68,200,130,166115,12752003,233.7,234.0,1200,50,1,1,233.68,234.02,200,200,1,1,233.67,234.09,30,30,1,1,233.66,234.1,1,100,1,1,233.58,234.13,505,400,2,1,233.53,234.17,10,1,1,1,233.5,234.25,100,100,1,1,233.45,234.41,15,500,1,1,233.4,234.43,110,105,2,2,233.39,234.5,10,63,1,4,AAPL,0.0,0.0,0.0,
2024-10-21 12:19:45.745918365+00:00,2024-10-21T12:19:45.746085184Z,10,2,38,A,B,1,233.68,200,130,166819,12754733,233.7,234.0,1200,50,1,1,233.68,234.02,400,200,2,1,233.67,234.09,30,30,1,1,233.66,234.1,1,100,1,1,233.58,234.13,505,400,2,1,233.53,234.17,10,1,1,1,233.5,234.25,100,100,1,1,233.45,234.41,15,500,1,1,233.4,234.43,110,105,2,2,233.39,234.5,10,63,1,4,AAPL,0.0,200.0,0.0,
2024-10-21 12:19:45.800477942+00:00,2024-10-21T12:19:45.800644123Z,10,2,38,C,B,1,233.68,200,130,166181,12754741,233.7,234.0,1200,50,1,1,233.68,234.02,200,200,1,1,233.67,234.09,30,30,1,1,233.66,234.1,1,100,1,1,233.58,234.13,505,400,2,1,233.53,234.17,10,1,1,1,233.5,234.25,100,100,1,1,233.45,234.41,15,500,1,1,233.4,234.43,110,105,2,2,233.39,234.5,10,63,1,4,AAPL,0.0,-200.0,0.0,
2024-10-21 12:19:45.800491117+00:00,2024-10-21T12:19:45.800657708Z,10,2,38,A,B,0,233.72,200,130,166591,12754742,233.72,234.0,200,50,1,1,233.7,234.02,1200,200,1,1,233.67,234.09,30,30,1,1,233.66,234.1,1,100,1,1,233.58,234.13,505,400,2,1,233.53,234.17,10,1,1,1,233.5,234.25,100,100,1,1,233.45,234.41,15,500,1,1,233.4,234.43,110,105,2,2,233.39,234.5,10,63,1,4,AAPL,0.0,0.0,0.0,
2024-10-21 12:19:57.871002706+00:00,2024-10-21T12:19:57.871170937Z,10,2,38,A,B,0,233.73,200,130,168231,12763861,233.73,234.0,200,50,1,1,233.7,234.02,1200,200,1,1,233.67,234.09,30,30,1,1,233.66,234.1,1,100,1,1,233.58,234.13,505,400,2,1,233.53,234.17,10,1,1,1,233.5,234.25,100,100,1,1,233.45,234.41,15,500,1,1,233.4,234.43,110,105,2,2,233.39,234.5,10,63,1,4,AAPL,0.0,0.0,0.0,
2024-10-21 12:20:02.012790106+00:00,2024-10-21T12:20:02.012956104Z,10,2,38,C,B,0,233.73,200,130,165998,12769134,233.7,234.0,1200,50,1,1,233.67,234.02,30,200,1,1,233.66,234.09,1,30,1,1,233.58,234.1,505,100,2,1,233.53,234.13,10,400,1,1,233.5,234.17,100,1,1,1,233.45,234.25,15,100,1,1,233.4,234.41,110,500,2,1,233.39,234.43,10,105,1,2,233.31,234.5,110,63,2,4,AAPL,0.0,0.0,0.0,
2024-10-21 12:20:02.012801350+00:00,2024-10-21T12:20:02.012967271Z,10,2,38,A,B,0,233.71,200,130,165921,12769136,233.71,234.0,200,50,1,1,233.7,234.02,1200,200,1,1,233.67,234.09,30,30,1,1,233.66,234.1,1,100,1,1,233.58,234.13,505,400,2,1,233.53,234.17,10,1,1,1,233.5,234.25,100,100,1,1,233.45,234.41,15,500,1,1,233.4,234.43,110,105,2,2,233.39,234.5,10,63,1,4,AAPL,0.0,0.0,0.0,
2024-10-21 12:20:02.012823085+00:00,2024-10-21T12:20:02.012989292Z,10,2,38,A,A,1,234.02,200,130,166207,12769137,233.71,234.0,200,50,1,1,233.7,234.02,1200,400,1,2,233.67,234.09,30,30,1,1,233.66,234.1,1,100,1,1,233.58,234.13,505,400,2,1,233.53,234.17,10,1,1,1,233.5,234.25,100,100,1,1,233.45,234.41,15,500,1,1,233.4,234.43,110,105,2,2,233.39,234.5,10,63,1,4,AAPL,0.0,-200.0,0.0,
2024-10-21 12:20:02.068202840+00:00,2024-10-21T12:20:02.068369244Z,10,2,38,A,B,0,233.72,200,130,166404,12769355,233.72,234.0,200,50,1,1,233.7,234.02,1200,400,1,2,233.67,234.09,30,30,1,1,233.66,234.1,1,100,1,1,233.58,234.13,505,400,2,1,233.53,234.17,10,1,1,1,233.5,234.25,100,100,1,1,233.45,234.41,15,500,1,1,233.4,234.43,110,105,2,2,233.39,234.5,10,63,1,4,AAPL,0.0,0.0,0.0,
2024-10-21 12:20:02.174072577+00:00,2024-10-21T12:20:02.174238719Z,10,2,38,C,A,1,234.02,200,130,166142,12769566,233.72,234.0,200,50,1,1,233.7,234.02,1200,200,1,1,233.67,234.09,30,30,1,1,233.66,234.1,1,100,1,1,233.58,234.13,505,400,2,1,233.53,234.17,10,1,1,1,233.5,234.25,100,100,1,1,233.45,234.41,15,500,1,1,233.4,234.43,110,105,2,2,233.39,234.5,10,63,1,4,AAPL,0.0,200.0,0.0,
2024-10-21 12:20:02.174084216+00:00,2024-10-21T12:20:02.174250737Z,10,2,38,A,A,1,234.01,200,130,166521,12769567,233.72,234.0,200,50,1,1,233.7,234.01,1200,200,1,1,233.67,234.09,30,30,1,1,233.66,234.1,1,100,1,1,233.58,234.13,505,400,2,1,233.53,234.17,10,1,1,1,233.5,234.25,100,100,1,1,233.45,234.41,15,500,1,1,233.4,234.43,110,105,2,2,233.39,234.5,10,63,1,4,AAPL,0.0,0.0,0.0,
2024-10-21 12:20:02.195761354+00:00,2024-10-21T12:20:02.195927659Z,10,2,38,A,A,2,234.08,27,130,166305,12769699,233.72,234.0,200,50,1,1,233.7,234.01,1200,200,1,1,233.67,234.08,30,27,1,1,233.66,234.09,1,30,1,1,233.58,234.1,505,100,2,1,233.53,234.13,10,400,1,1,233.5,234.17,100,1,1,1,233.45,234.25,15,100,1,1,233.4,234.41,110,500,2,1,233.39,234.43,10,105,1,2,AAPL,0.0,0.0,0.0,
2024-10-21 12:20:02.197099790+00:00,2024-10-21T12:20:02.197265893Z,10,2,38,C,A,3,234.09,30,130,166103,12769703,233.72,234.0,200,50,1,1,233.7,234.01,1200,200,1,1,233.67,234.08,30,27,1,1,233.66,234.1,1,100,1,1,233.58,234.13,505,400,2,1,233.53,234.17,10,1,1,1,233.5,234.25,100,100,1,1,233.45,234.41,15,500,1,1,233.4,234.43,110,105,2,2,233.39,234.5,10,63,1,4,AAPL,0.0,0.0,0.0,
2024-10-21 12:20:17.529659579+00:00,2024-10-21T12:20:17.529825881Z,10,2,38,C,A,1,234.01,200,130,166302,12783626,233.72,234.0,200,50,1,1,233.7,234.08,1200,27,1,1,233.67,234.1,30,100,1,1,233.66,234.13,1,400,1,1,233.58,234.17,505,1,2,1,233.53,234.25,10,100,1,1,233.5,234.41,100,500,1,1,233.45,234.43,15,105,1,2,233.4,234.5,110,63,2,4,233.39,234.75,10,1,1,1,AAPL,0.0,0.0,0.0,
2024-10-21 12:20:17.529671598+00:00,2024-10-21T12:20:17.529838088Z,10,2,38,A,A,1,234.02,200,130,166490,12783627,233.72,234.0,200,50,1,1,233.7,234.02,1200,200,1,1,233.67,234.08,30,27,1,1,233.66,234.1,1,100,1,1,233.58,234.13,505,400,2,1,233.53,234.17,10,1,1,1,233.5,234.25,100,100,1,1,233.45,234.41,15,500,1,1,233.4,234.43,110,105,2,2,233.39,234.5,10,63,1,4,AAPL,0.0,0.0,0.0,
2024-10-21 12:20:18.175151492+00:00,2024-10-21T12:20:18.175318074Z,10,2,38,A,B,0,233.73,200,130,166582,12784239,233.73,234.0,200,50,1,1,233.7,234.02,1200,200,1,1,233.67,234.08,30,27,1,1,233.66,234.1,1,100,1,1,233.58,234.13,505,400,2,1,233.53,234.17,10,1,1,1,233.5,234.25,100,100,1,1,233.45,234.41,15,500,1,1,233.4,234.43,110,105,2,2,233.39,234.5,10,63,1,4,AAPL,0.0,0.0,0.0,
2024-10-21 12:20:26.003671349+00:00,2024-10-21T12:20:26.003837302Z,10,2,38,C,B,0,233.73,200,130,165953,12790391,233.7,234.0,1200,50,1,1,233.67,234.02,30,200,1,1,233.66,234.08,1,27,1,1,233.58,234.1,505,100,2,1,233.53,234.13,10,400,1,1,233.5,234.17,100,1,1,1,233.45,234.25,15,100,1,1,233.4,234.41,110,500,2,1,233.39,234.43,10,105,1,2,233.31,234.5,110,63,2,4,AAPL,0.0,0.0,0.0,
2024-10-21 12:20:26.003684074+00:00,2024-10-21T12:20:26.003850219Z,10,2,38,A,B,1,233.69,200,130,166145,12790392,233.7,234.0,1200,50,1,1,233.69,234.02,200,200,1,1,233.67,234.08,30,27,1,1,233.66,234.1,1,100,1,1,233.58,234.13,505,400,2,1,233.53,234.17,10,1,1,1,233.5,234.25,100,100,1,1,233.45,234.41,15,500,1,1,233.4,234.43,110,105,2,2,233.39,234.5,10,63,1,4,AAPL,0.0,0.0,0.0,
2024-10-21 12:20:29.005849003+00:00,2024-10-21T12:20:29.006015290Z,10,2,38,A,B,1,233.69,200,130,166287,12792364,233.7,234.0,1200,50,1,1,233.69,234.02,400,200,2,1,233.67,234.08,30,27,1,1,233.66,234.1,1,100,1,1,233.58,234.13,505,400,2,1,233.53,234.17,10,1,1,1,233.5,234.25,100,100,1,1,233.45,234.41,15,500,1,1,233.4,234.43,110,105,2,2,233.39,234.5,10,63,1,4,AAPL,0.0,200.0,0.0,
2024-10-21 12:20:29.035461864+00:00,2024-10-21T12:20:29.035628478Z,10,2,38,A,B,0,233.8,5,130,166614,12792376,233.8,234.0,5,50,1,1,233.7,234.02,1200,200,1,1,233.69,234.08,400,27,2,1,233.67,234.1,30,100,1,1,233.66,234.13,1,400,1,1,233.58,234.17,505,1,2,1,233.53,234.25,10,100,1,1,233.5,234.41,100,500,1,1,233.45,234.43,15,105,1,2,233.4,234.5,110,63,2,4,AAPL,0.0,0.0,0.0,
2024-10-21 12:20:32.533970326+00:00,2024-10-21T12:20:32.534136508Z,10,2,38,C,A,2,234.08,27,130,166182,12795434,233.8,234.0,5,50,1,1,233.7,234.02,1200,200,1,1,233.69,234.1,400,100,2,1,233.67,234.13,30,400,1,1,233.66,234.17,1,1,1,1,233.58,234.25,505,100,2,1,233.53,234.41,10,500,1,1,233.5,234.43,100,105,1,2,233.45,234.5,15,63,1,4,233.4,234.75,110,1,2,1,AAPL,0.0,0.0,0.0,
2024-10-21 12:20:32.534015766+00:00,2024-10-21T12:20:32.534182863Z,10,2,38,A,A,2,234.04,27,130,167097,12795435,233.8,234.0,5,50,1,1,233.7,234.02,1200,200,1,1,233.69,234.04,400,27,2,1,233.67,234.1,30,100,1,1,233.66,234.13,1,400,1,1,233.58,234.17,505,1,2,1,233.53,234.25,10,100,1,1,233.5,234.41,100,500,1,1,233.45,234.43,15,105,1,2,233.4,234.5,110,63,2,4,AAPL,0.0,0.0,0.0,
2024-10-21 12:20:32.588585911+00:00,2024-10-21T12:20:32.588752733Z,10,2,38,A,A,0,233.99,200,130,166822,12795466,233.8,233.99,5,200,1,1,233.7,234.0,1200,50,1,1,233.69,234.04,400,27,2,1,233.67,234.1,30,100,1,1,233.66,234.13,1,400,1,1,233.58,234.17,505,1,2,1,233.53,234.25,10,100,1,1,233.5,234.41,100,500,1,1,233.45,234.43,15,105,1,2,233.4,234.5,110,63,2,4,AAPL,0.0,0.0,0.0,
2024-10-21 12:20:32.846313500+00:00,2024-10-21T12:20:32.846479452Z,10,2,38,C,A,0,233.99,200,130,165952,12795731,233.8,234.0,5,50,1,1,233.7,234.04,1200,27,1,1,233.69,234.1,400,100,2,1,233.67,234.13,30,400,1,1,233.66,234.17,1,1,1,1,233.58,234.25,505,100,2,1,233.53,234.41,10,500,1,1,233.5,234.43,100,105,1,2,233.45,234.5,15,63,1,4,233.4,234.75,110,1,2,1,AAPL,0.0,0.0,0.0,
2024-10-21 12:20:32.846324686+00:00,2024-10-21T12:20:32.846490898Z,10,2,38,A,A,1,234.03,400,130,166212,12795732,233.8,234.0,5,50,1,1,233.7,234.03,1200,400,1,1,233.69,234.04,400,27,2,1,233.67,234.1,30,100,1,1,233.66,234.13,1,400,1,1,233.58,234.17,505,1,2,1,233.53,234.25,10,100,1,1,233.5,234.41,100,500,1,1,233.45,234.43,15,105,1,2,233.4,234.5,110,63,2,4,AAPL,0.0,0.0,0.0,
2024-10-21 12:20:32.900943370+00:00,2024-10-21T12:20:32.901109636Z,10,2,38,A,A,0,233.98,200,130,166266,12795787,233.8,233.98,5,200,1,1,233.7,234.0,1200,50,1,1,233.69,234.04,400,27,2,1,233.67,234.1,30,100,1,1,233.66,234.13,1,400,1,1,233.58,234.17,505,1,2,1,233.53,234.25,10,100,1,1,233.5,234.41,100,500,1,1,233.45,234.43,15,105,1,2,233.4,234.5,110,63,2,4,AAPL,0.0,0.0,0.0,
2024-10-21 12:20:33.387796787+00:00,2024-10-21T12:20:33.387963355Z,10,2,38,A,A,0,233.97,200,130,166568,12796589,233.8,233.97,5,200,1,1,233.7,234.0,1200,50,1,1,233.69,234.04,400,27,2,1,233.67,234.1,30,100,1,1,233.66,234.13,1,400,1,1,233.58,234.17,505,1,2,1,233.53,234.25,10,100,1,1,233.5,234.41,100,500,1,1,233.45,234.43,15,105,1,2,233.4,234.5,110,63,2,4,AAPL,0.0,0.0,0.0,
2024-10-21 12:20:34.158518772+00:00,2024-10-21T12:20:34.158685217Z,10,2,38,A,A,0,233.97,200,130,166445,12797101,233.8,233.97,5,400,1,2,233.7,234.0,1200,50,1,1,233.69,234.04,400,27,2,1,233.67,234.1,30,100,1,1,233.66,234.13,1,400,1,1,233.58,234.17,505,1,2,1,233.53,234.25,10,100,1,1,233.5,234.41,100,500,1,1,233.45,234.43,15,105,1,2,233.4,234.5,110,63,2,4,AAPL,-200.0,-200.0,-200.0,
2024-10-21 12:20:53.732903004+00:00,2024-10-21T12:20:53.733069722Z,10,2,38,A,B,0,233.86,750,130,166718,12809362,233.86,233.97,750,400,1,2,233.8,234.0,5,50,1,1,233.7,234.04,1200,27,1,1,233.69,234.1,400,100,2,1,233.67,234.13,30,400,1,1,233.66,234.17,1,1,1,1,233.58,234.25,505,100,2,1,233.53,234.41,10,500,1,1,233.5,234.43,100,105,1,2,233.45,234.5,15,63,1,4,AAPL,0.0,0.0,0.0,
2024-10-21 12:20:54.066325257+00:00,2024-10-21T12:20:54.066491305Z,10,2,38,C,A,0,233.97,200,130,166048,12809626,233.86,233.97,750,200,1,1,233.8,234.0,5,50,1,1,233.7,234.04,1200,27,1,1,233.69,234.1,400,100,2,1,233.67,234.13,30,400,1,1,233.66,234.17,1,1,1,1,233.58,234.25,505,100,2,1,233.53,234.41,10,500,1,1,233.5,234.43,100,105,1,2,233.45,234.5,15,63,1,4,AAPL,200.0,200.0,200.0,
2024-10-21 12:20:54.066539893+00:00,2024-10-21T12:20:54.066706343Z,10,2,38,C,A,0,233.97,200,130,166450,12809627,233.86,234.0,750,50,1,1,233.8,234.04,5,27,1,1,233.7,234.1,1200,100,1,1,233.69,234.13,400,400,2,1,233.67,234.17,30,1,1,1,233.66,234.25,1,100,1,1,233.58,234.41,505,500,2,1,233.53,234.43,10,105,1,2,233.5,234.5,100,63,1,4,233.45,234.75,15,1,1,1,AAPL,0.0,0.0,200.0,
2024-10-21 12:20:54.087884313+00:00,2024-10-21T12:20:54.088050706Z,10,2,38,A,A,0,233.97,200,130,166393,12809662,233.86,233.97,750,200,1,1,233.8,234.0,5,50,1,1,233.7,234.04,1200,27,1,1,233.69,234.1,400,100,2,1,233.67,234.13,30,400,1,1,233.66,234.17,1,1,1,1,233.58,234.25,505,100,2,1,233.53,234.41,10,500,1,1,233.5,234.43,100,105,1,2,233.45,234.5,15,63,1,4,AAPL,0.0,0.0,200.0,
2024-10-21 12:20:54.138010479+00:00,2024-10-21T12:20:54.138176465Z,10,2,38,C,A,0,233.97,200,130,165986,12809687,233.86,234.0,750,50,1,1,233.8,234.04,5,27,1,1,233.7,234.1,1200,100,1,1,233.69,234.13,400,400,2,1,233.67,234.17,30,1,1,1,233.66,234.25,1,100,1,1,233.58,234.41,505,500,2,1,233.53,234.43,10,105,1,2,233.5,234.5,100,63,1,4,233.45,234.75,15,1,1,1,AAPL,0.0,0.0,200.0,
2024-10-21 12:20:54.138024196+00:00,2024-10-21T12:20:54.138190487Z,10,2,38,A,A,1,234.03,200,130,166291,12809688,233.86,234.0,750,50,1,1,233.8,234.03,5,200,1,1,233.7,234.04,1200,27,1,1,233.69,234.1,400,100,2,1,233.67,234.13,30,400,1,1,233.66,234.17,1,1,1,1,233.58,234.25,505,100,2,1,233.53,234.41,10,500,1,1,233.5,234.43,100,105,1,2,233.45,234.5,15,63,1,4,AAPL,0.0,0.0,200.0,
2024-10-21 12:20:54.138635039+00:00,2024-10-21T12:20:54.138801017Z,10,2,38,C,A,2,234.04,27,130,165978,12809691,233.86,234.0,750,50,1,1,233.8,234.03,5,200,1,1,233.7,234.1,1200,100,1,1,233.69,234.13,400,400,2,1,233.67,234.17,30,1,1,1,233.66,234.25,1,100,1,1,233.58,234.41,505,500,2,1,233.53,234.43,10,105,1,2,233.5,234.5,100,63,1,4,233.45,234.75,15,1,1,1,AAPL,0.0,0.0,200.0,
2024-10-21 12:20:54.138679423+00:00,2024-10-21T12:20:54.138845849Z,10,2,38,A,A,2,234.1,29,130,166426,12809692,233.86,234.0,750,50,1,1,233.8,234.03,5,200,1,1,233.7,234.1,1200,129,1,2,233.69,234.13,400,400,2,1,233.67,234.17,30,1,1,1,233.66,234.25,1,100,1,1,233.58,234.41,505,500,2,1,233.53,234.43,10,105,1,2,233.5,234.5,100,63,1,4,233.45,234.75,15,1,1,1,AAPL,0.0,-29.0,200.0,
2024-10-21 12:20:54.140701289+00:00,2024-10-21T12:20:54.140867485Z,10,2,38,A,A,1,234.03,200,130,166196,12809693,233.86,234.0,750,50,1,1,233.8,234.03,5,400,1,2,233.7,234.1,1200,129,1,2,233.69,234.13,400,400,2,1,233.67,234.17,30,1,1,1,233.66,234.25,1,100,1,1,233.58,234.41,505,500,2,1,233.53,234.43,10,105,1,2,233.5,234.5,100,63,1,4,233.45,234.75,15,1,1,1,AAPL,0.0,-200.0,200.0,
2024-10-21 12:20:54.259923109+00:00,2024-10-21T12:20:54.260089240Z,10,2,38,C,A,1,234.03,200,130,166131,12809712,233.86,234.0,750,50,1,1,233.8,234.03,5,200,1,1,233.7,234.1,1200,129,1,2,233.69,234.13,400,400,2,1,233.67,234.17,30,1,1,1,233.66,234.25,1,100,1,1,233.58,234.41,505,500,2,1,233.53,234.43,10,105,1,2,233.5,234.5,100,63,1,4,233.45,234.75,15,1,1,1,AAPL,0.0,200.0,200.0,
2024-10-21 12:20:54.259936081+00:00,2024-10-21T12:20:54.260102529Z,10,2,38,A,A,0,233.97,400,130,166448,12809713,233.86,233.97,750,400,1,1,233.8,234.0,5,50,1,1,233.7,234.1,1200,129,1,2,233.69,234.13,400,400,2,1,233.67,234.17,30,1,1,1,233.66,234.25,1,100,1,1,233.58,234.41,505,500,2,1,233.53,234.43,10,105,1,2,233.5,234.5,100,63,1,4,233.45,234.75,15,1,1,1,AAPL,0.0,0.0,200.0,
2024-10-21 12:20:54.367974373+00:00,2024-10-21T12:20:54.368140579Z,10,2,38,C,B,3,233.69,200,130,166206,12809780,233.86,233.97,750,400,1,1,233.8,234.0,5,50,1,1,233.7,234.1,1200,129,1,2,233.69,234.13,200,400,1,1,233.67,234.17,30,1,1,1,233.66,234.25,1,100,1,1,233.58,234.41,505,500,2,1,233.53,234.43,10,105,1,2,233.5,234.5,100,63,1,4,233.45,234.75,15,1,1,1,AAPL,0.0,-200.0,200.0,
2024-10-21 12:20:54.367988079+00:00,2024-10-21T12:20:54.368154412Z,10,2,38,A,B,2,233.71,200,130,166333,12809781,233.86,233.97,750,400,1,1,233.8,234.0,5,50,1,1,233.71,234.1,200,129,1,2,233.7,234.13,1200,400,1,1,233.67,234.17,30,1,1,1,233.66,234.25,1,100,1,1,233.58,234.41,505,500,2,1,233.53,234.43,10,105,1,2,233.5,234.5,100,63,1,4,233.45,234.75,15,1,1,1,AAPL,0.0,0.0,200.0,
2024-10-21 12:20:54.646524020+00:00,2024-10-21T12:20:54.646690573Z,10,2,38,A,B,2,233.71,200,130,166553,12810164,233.86,233.97,750,400,1,1,233.8,234.0,5,50,1,1,233.71,234.1,400,129,2,2,233.7,234.13,1200,400,1,1,233.67,234.17,30,1,1,1,233.66,234.25,1,100,1,1,233.58,234.41,505,500,2,1,233.53,234.43,10,105,1,2,233.5,234.5,100,63,1,4,233.45,234.75,15,1,1,1,AAPL,0.0,200.0,200.0,
2024-10-21 12:20:54.647311583+00:00,2024-10-21T12:20:54.647477883Z,10,2,38,C,B,4,233.67,30,130,166300,12810165,233.86,233.97,750,400,1,1,233.8,234.0,5,50,1,1,233.71,234.1,400,129,2,2,233.7,234.13,1200,400,1,1,233.66,234.17,1,1,1,1,233.58,234.25,505,100,2,1,233.53,234.41,10,500,1,1,233.5,234.43,100,105,1,2,233.45,234.5,15,63,1,4,233.4,234.75,110,1,2,1,AAPL,0.0,0.0,200.0,
2024-10-21 12:20:54.647352236+00:00,2024-10-21T12:20:54.647518689Z,10,2,38,A,B,2,233.73,26,130,166453,12810166,233.86,233.97,750,400,1,1,233.8,234.0,5,50,1,1,233.73,234.1,26,129,1,2,233.71,234.13,400,400,2,1,233.7,234.17,1200,1,1,1,233.66,234.25,1,100,1,1,233.58,234.41,505,500,2,1,233.53,234.43,10,105,1,2,233.5,234.5,100,63,1,4,233.45,234.75,15,1,1,1,AAPL,0.0,0.0,200.0,
2024-10-21 12:20:54.647382777+00:00,2024-10-21T12:20:54.647548709Z,10,2,38,C,A,2,234.1,29,130,165932,12810167,233.86,233.97,750,400,1,1,233.8,234.0,5,50,1,1,233.73,234.1,26,100,1,1,233.71,234.13,400,400,2,1,233.7,234.17,1200,1,1,1,233.66,234.25,1,100,1,1,233.58,234.41,505,500,2,1,233.53,234.43,10,105,1,2,233.5,234.5,100,63,1,4,233.45,234.75,15,1,1,1,AAPL,0.0,29.0,200.0,
2024-10-21 12:20:54.647423336+00:00,2024-10-21T12:20:54.647589469Z,10,2,38,A,A,2,234.04,27,130,166133,12810168,233.86,233.97,750,400,1,1,233.8,234.0,5,50,1,1,233.73,234.04,26,27,1,1,233.71,234.1,400,100,2,1,233.7,234.13,1200,400,1,1,233.66,234.17,1,1,1,1,233.58,234.25,505,100,2,1,233.53,234.41,10,500,1,1,233.5,234.43,100,105,1,2,233.45,234.5,15,63,1,4,AAPL,0.0,0.0,200.0,
2024-10-21 12:20:54.647922749+00:00,2024-10-21T12:20:54.648089003Z,10,2,38,C,A,0,233.97,200,130,166254,12810170,233.86,233.97,750,200,1,1,233.8,234.0,5,50,1,1,233.73,234.04,26,27,1,1,233.71,234.1,400,100,2,1,233.7,234.13,1200,400,1,1,233.66,234.17,1,1,1,1,233.58,234.25,505,100,2,1,233.53,234.41,10,500,1,1,233.5,234.43,100,105,1,2,233.45,234.5,15,63,1,4,AAPL,200.0,200.0,400.0,
2024-10-21 12:20:54.648117162+00:00,2024-10-21T12:20:54.648283192Z,10,2,38,C,A,0,233.97,200,130,166030,12810171,233.86,234.0,750,50,1,1,233.8,234.04,5,27,1,1,233.73,234.1,26,100,1,1,233.71,234.13,400,400,2,1,233.7,234.17,1200,1,1,1,233.66,234.25,1,100,1,1,233.58,234.41,505,500,2,1,233.53,234.43,10,105,1,2,233.5,234.5,100,63,1,4,233.45,234.75,15,1,1,1,AAPL,0.0,0.0,400.0,
2024-10-21 12:20:54.648128723+00:00,2024-10-21T12:20:54.648295052Z,10,2,38,A,A,1,234.03,400,130,166329,12810172,233.86,234.0,750,50,1,1,233.8,234.03,5,400,1,1,233.73,234.04,26,27,1,1,233.71,234.1,400,100,2,1,233.7,234.13,1200,400,1,1,233.66,234.17,1,1,1,1,233.58,234.25,505,100,2,1,233.53,234.41,10,500,1,1,233.5,234.43,100,105,1,2,233.45,234.5,15,63,1,4,AAPL,0.0,0.0,400.0,
2024-10-21 12:20:54.648446832+00:00,2024-10-21T12:20:54.648612547Z,10,2,38,C,A,2,234.04,27,130,165715,12810176,233.86,234.0,750,50,1,1,233.8,234.03,5,400,1,1,233.73,234.1,26,100,1,1,233.71,234.13,400,400,2,1,233.7,234.17,1200,1,1,1,233.66,234.25,1,100,1,1,233.58,234.41,505,500,2,1,233.53,234.43,10,105,1,2,233.5,234.5,100,63,1,4,233.45,234.75,15,1,1,1,AAPL,0.0,0.0,400.0,
2024-10-21 12:20:54.697200659+00:00,2024-10-21T12:20:54.697366809Z,10,2,38,C,B,3,233.71,200,130,166150,12810217,233.86,234.0,750,50,1,1,233.8,234.03,5,400,1,1,233.73,234.1,26,100,1,1,233.71,234.13,200,400,1,1,233.7,234.17,1200,1,1,1,233.66,234.25,1,100,1,1,233.58,234.41,505,500,2,1,233.53,234.43,10,105,1,2,233.5,234.5,100,63,1,4,233.45,234.75,15,1,1,1,AAPL,0.0,-200.0,400.0,
2024-10-21 12:20:54.697212843+00:00,2024-10-21T12:20:54.697379987Z,10,2,38,A,B,2,233.77,200,130,167144,12810218,233.86,234.0,750,50,1,1,233.8,234.03,5,400,1,1,233.77,234.1,200,100,1,1,233.73,234.13,26,400,1,1,233.7,234.17,1200,1,1,1,233.66,234.25,1,100,1,1,233.58,234.41,505,500,2,1,233.53,234.43,10,105,1,2,233.5,234.5,100,63,1,4,233.45,234.75,15,1,1,1,AAPL,0.0,0.0,400.0,
2024-10-21 12:20:54.708231641+00:00,2024-10-21T12:20:54.708397951Z,10,2,38,A,A,0,233.99,200,130,166310,12810231,233.86,233.99,750,200,1,1,233.8,234.0,5,50,1,1,233.77,234.1,200,100,1,1,233.73,234.13,26,400,1,1,233.7,234.17,1200,1,1,1,233.66,234.25,1,100,1,1,233.58,234.41,505,500,2,1,233.53,234.43,10,105,1,2,233.5,234.5,100,63,1,4,233.45,234.75,15,1,1,1,AAPL,0.0,0.0,400.0,
2024-10-21 12:20:56.393593183+00:00,2024-10-21T12:20:56.393759280Z,10,2,38,A,A,2,234.05,30,130,166097,12811166,233.86,233.99,750,200,1,1,233.8,234.0,5,50,1,1,233.77,234.05,200,30,1,1,233.73,234.1,26,100,1,1,233.7,234.13,1200,400,1,1,233.66,234.17,1,1,1,1,233.58,234.25,505,100,2,1,233.53,234.41,10,500,1,1,233.5,234.43,100,105,1,2,233.45,234.5,15,63,1,4,AAPL,0.0,0.0,0.0,
2024-10-21 12:20:56.654348888+00:00,2024-10-21T12:20:56.654514873Z,10,2,38,C,A,0,233.99,200,130,165985,12811490,233.86,234.0,750,50,1,1,233.8,234.05,5,30,1,1,233.77,234.1,200,100,1,1,233.73,234.13,26,400,1,1,233.7,234.17,1200,1,1,1,233.66,234.25,1,100,1,1,233.58,234.41,505,500,2,1,233.53,234.43,10,105,1,2,233.5,234.5,100,63,1,4,233.45,234.75,15,1,1,1,AAPL,0.0,0.0,0.0,
2024-10-21 12:20:56.654361253+00:00,2024-10-21T12:20:56.654527697Z,10,2,38,A,A,1,234.03,400,130,166444,12811491,233.86,234.0,750,50,1,1,233.8,234.03,5,400,1,1,233.77,234.05,200,30,1,1,233.73,234.1,26,100,1,1,233.7,234.13,1200,400,1,1,233.66,234.17,1,1,1,1,233.58,234.25,505,100,2,1,233.53,234.41,10,500,1,1,233.5,234.43,100,105,1,2,233.45,234.5,15,63,1,4,AAPL,0.0,0.0,0.0,
2024-10-21 12:20:56.655676466+00:00,2024-10-21T12:20:56.655842318Z,10,2,38,C,A,2,234.05,30,130,165852,12811493,233.86,234.0,750,50,1,1,233.8,234.03,5,400,1,1,233.77,234.1,200,100,1,1,233.73,234.13,26,400,1,1,233.7,234.17,1200,1,1,1,233.66,234.25,1,100,1,1,233.58,234.41,505,500,2,1,233.53,234.43,10,105,1,2,233.5,234.5,100,63,1,4,233.45,234.75,15,1,1,1,AAPL,0.0,0.0,0.0,
2024-10-21 12:21:00.388313049+00:00,2024-10-21T12:21:00.388479265Z,10,2,38,A,A,2,234.1,26,130,166216,12815663,233.86,234.0,750,50,1,1,233.8,234.03,5,400,1,1,233.77,234.1,200,126,1,2,233.73,234.13,26,400,1,1,233.7,234.17,1200,1,1,1,233.66,234.25,1,100,1,1,233.58,234.41,505,500,2,1,233.53,234.43,10,105,1,2,233.5,234.5,100,63,1,4,233.45,234.75,15,1,1,1,AAPL,0.0,-26.0,0.0,
2024-10-21 12:21:01.707857424+00:00,2024-10-21T12:21:01.708023897Z,10,2,38,A,A,0,234.0,200,130,166473,12817432,233.86,234.0,750,250,1,2,233.8,234.1,5,126,1,2,233.77,234.13,200,400,1,1,233.73,234.17,26,1,1,1,233.7,234.25,1200,100,1,1,233.66,234.41,1,500,1,1,233.58,234.43,505,105,2,2,233.53,234.5,10,63,1,4,233.5,234.75,100,1,1,1,233.45,234.79,15,2000,1,1,AAPL,-200.0,-200.0,-200.0,
2024-10-21 12:21:01.856825426+00:00,2024-10-21T12:21:01.856991707Z,10,2,38,C,A,0,234.0,200,130,166281,12817610,233.86,234.0,750,50,1,1,233.8,234.1,5,126,1,2,233.77,234.13,200,400,1,1,233.73,234.17,26,1,1,1,233.7,234.25,1200,100,1,1,233.66,234.41,1,500,1,1,233.58,234.43,505,105,2,2,233.53,234.5,10,63,1,4,233.5,234.75,100,1,1,1,233.45,234.79,15,2000,1,1,AAPL,200.0,200.0,0.0,
2024-10-21 12:21:01.856837629+00:00,2024-10-21T12:21:01.857003762Z,10,2,38,A,A,1,234.03,400,130,166133,12817611,233.86,234.0,750,50,1,1,233.8,234.03,5,400,1,1,233.77,234.1,200,126,1,2,233.73,234.13,26,400,1,1,233.7,234.17,1200,1,1,1,233.66,234.25,1,100,1,1,233.58,234.41,505,500,2,1,233.53,234.43,10,105,1,2,233.5,234.5,100,63,1,4,233.45,234.75,15,1,1,1,AAPL,0.0,0.0,0.0,
2024-10-21 12:21:06.853945458+00:00,2024-10-21T12:21:06.854114356Z,10,2,38,C,B,2,233.77,200,128,168898,12822045,233.86,234.0,750,50,1,1,233.8,234.03,5,400,1,1,233.73,234.1,26,126,1,2,233.7,234.13,1200,400,1,1,233.66,234.17,1,1,1,1,233.58,234.25,505,100,2,1,233.53,234.41,10,500,1,1,233.5,234.43,100,105,1,2,233.45,234.5,15,63,1,4,233.4,234.75,110,1,2,1,AAPL,0.0,0.0,0.0,
2024-10-21 12:21:06.917506080+00:00,2024-10-21T12:21:06.917672196Z,10,2,38,C,A,2,234.1,26,130,166116,12822954,233.86,234.0,750,50,1,1,233.8,234.03,5,400,1,1,233.73,234.1,26,100,1,1,233.7,234.13,1200,400,1,1,233.66,234.17,1,1,1,1,233.58,234.25,505,100,2,1,233.53,234.41,10,500,1,1,233.5,234.43,100,105,1,2,233.45,234.5,15,63,1,4,233.4,234.75,110,1,2,1,AAPL,0.0,26.0,0.0,
2024-10-21 12:21:06.917557816+00:00,2024-10-21T12:21:06.917723950Z,10,2,38,A,A,2,234.04,29,130,166134,12822956,233.86,234.0,750,50,1,1,233.8,234.03,5,400,1,1,233.73,234.04,26,29,1,1,233.7,234.1,1200,100,1,1,233.66,234.13,1,400,1,1,233.58,234.17,505,1,2,1,233.53,234.25,10,100,1,1,233.5,234.41,100,500,1,1,233.45,234.43,15,105,1,2,233.4,234.5,110,63,2,4,AAPL,0.0,0.0,0.0,
2024-10-21 12:21:06.921270364+00:00,2024-10-21T12:21:06.921436322Z,10,2,38,C,A,2,234.04,29,130,165958,12822971,233.86,234.0,750,50,1,1,233.8,234.03,5,400,1,1,233.73,234.1,26,100,1,1,233.7,234.13,1200,400,1,1,233.66,234.17,1,1,1,1,233.58,234.25,505,100,2,1,233.53,234.41,10,500,1,1,233.5,234.43,100,105,1,2,233.45,234.5,15,63,1,4,233.4,234.75,110,1,2,1,AAPL,0.0,0.0,0.0,
2024-10-21 12:21:06.921738635+00:00,2024-10-21T12:21:06.921907160Z,10,2,38,A,B,4,233.67,30,130,168525,12822978,233.86,234.0,750,50,1,1,233.8,234.03,5,400,1,1,233.73,234.1,26,100,1,1,233.7,234.13,1200,400,1,1,233.67,234.17,30,1,1,1,233.66,234.25,1,100,1,1,233.58,234.41,505,500,2,1,233.53,234.43,10,105,1,2,233.5,234.5,100,63,1,4,233.45,234.75,15,1,1,1,AAPL,0.0,0.0,0.0,
2024-10-21 12:21:06.921761416+00:00,2024-10-21T12:21:06.921927508Z,10,2,38,C,B,2,233.73,26,130,166092,12822980,233.86,234.0,750,50,1,1,233.8,234.03,5,400,1,1,233.7,234.1,1200,100,1,1,233.67,234.13,30,400,1,1,233.66,234.17,1,1,1,1,233.58,234.25,505,100,2,1,233.53,234.41,10,500,1,1,233.5,234.43,100,105,1,2,233.45,234.5,15,63,1,4,233.4,234.75,110,1,2,1,AAPL,0.0,0.0,0.0,
2024-10-21 12:21:06.954173708+00:00,2024-10-21T12:21:06.954339916Z,10,2,38,A,B,2,233.72,200,130,166208,12823107,233.86,234.0,750,50,1,1,233.8,234.03,5,400,1,1,233.72,234.1,200,100,1,1,233.7,234.13,1200,400,1,1,233.67,234.17,30,1,1,1,233.66,234.25,1,100,1,1,233.58,234.41,505,500,2,1,233.53,234.43,10,105,1,2,233.5,234.5,100,63,1,4,233.45,234.75,15,1,1,1,AAPL,0.0,0.0,0.0,
2024-10-21 12:21:07.982705400+00:00,2024-10-21T12:21:07.982871946Z,10,2,38,A,B,4,233.68,29,130,166546,12824965,233.86,234.0,750,50,1,1,233.8,234.03,5,400,1,1,233.72,234.1,200,100,1,1,233.7,234.13,1200,400,1,1,233.68,234.17,29,1,1,1,233.67,234.25,30,100,1,1,233.66,234.41,1,500,1,1,233.58,234.43,505,105,2,2,233.53,234.5,10,63,1,4,233.5,234.75,100,1,1,1,AAPL,0.0,0.0,0.0,
2024-10-21 12:21:07.982732401+00:00,2024-10-21T12:21:07.982898445Z,10,2,38,C,B,5,233.67,30,130,166044,12824966,233.86,234.0,750,50,1,1,233.8,234.03,5,400,1,1,233.72,234.1,200,100,1,1,233.7,234.13,1200,400,1,1,233.68,234.17,29,1,1,1,233.66,234.25,1,100,1,1,233.58,234.41,505,500,2,1,233.53,234.43,10,105,1,2,233.5,234.5,100,63,1,4,233.45,234.75,15,1,1,1,AAPL,0.0,0.0,0.0,
2024-10-21 12:21:08.049468728+00:00,2024-10-21T12:21:08.049635180Z,10,2,38,A,B,2,233.73,200,130,166452,12825229,233.86,234.0,750,50,1,1,233.8,234.03,5,400,1,1,233.73,234.1,200,100,1,1,233.7,234.13,1200,400,1,1,233.68,234.17,29,1,1,1,233.66,234.25,1,100,1,1,233.58,234.41,505,500,2,1,233.53,234.43,10,105,1,2,233.5,234.5,100,63,1,4,233.45,234.75,15,1,1,1,AAPL,0.0,0.0,0.0,
2024-10-21 12:21:08.155736487+00:00,2024-10-21T12:21:08.155903006Z,10,2,38,A,B,2,233.73,200,130,166519,12825740,233.86,234.0,750,50,1,1,233.8,234.03,5,400,1,1,233.73,234.1,400,100,2,1,233.7,234.13,1200,400,1,1,233.68,234.17,29,1,1,1,233.66,234.25,1,100,1,1,233.58,234.41,505,500,2,1,233.53,234.43,10,105,1,2,233.5,234.5,100,63,1,4,233.45,234.75,15,1,1,1,AAPL,0.0,200.0,0.0,
2024-10-21 12:21:08.156275244+00:00,2024-10-21T12:21:08.156442002Z,10,2,38,A,B,0,233.86,100,130,166758,12825741,233.86,234.0,850,50,2,1,233.8,234.03,5,400,1,1,233.73,234.1,400,100,2,1,233.7,234.13,1200,400,1,1,233.68,234.17,29,1,1,1,233.66,234.25,1,100,1,1,233.58,234.41,505,500,2,1,233.53,234.43,10,105,1,2,233.5,234.5,100,63,1,4,233.45,234.75,15,1,1,1,AAPL,100.0,100.0,100.0,
2024-10-21 12:21:08.214593412+00:00,2024-10-21T12:21:08.214759234Z,10,2,38,C,B,2,233.73,200,130,165822,12825863,233.86,234.0,850,50,2,1,233.8,234.03,5,400,1,1,233.73,234.1,200,100,1,1,233.7,234.13,1200,400,1,1,233.68,234.17,29,1,1,1,233.66,234.25,1,100,1,1,233.58,234.41,505,500,2,1,233.53,234.43,10,105,1,2,233.5,234.5,100,63,1,4,233.45,234.75,15,1,1,1,AAPL,0.0,-200.0,100.0,
2024-10-21 12:21:08.214604801+00:00,2024-10-21T12:21:08.214770994Z,10,2,38,A,B,2,233.76,400,130,166193,12825864,233.86,234.0,850,50,2,1,233.8,234.03,5,400,1,1,233.76,234.1,400,100,1,1,233.7,234.13,1200,400,1,1,233.68,234.17,29,1,1,1,233.66,234.25,1,100,1,1,233.58,234.41,505,500,2,1,233.53,234.43,10,105,1,2,233.5,234.5,100,63,1,4,233.45,234.75,15,1,1,1,AAPL,0.0,0.0,100.0,
2024-10-21 12:21:09.374232780+00:00,2024-10-21T12:21:09.374399277Z,10,2,38,A,A,2,234.06,26,130,166497,12827250,233.86,234.0,850,50,2,1,233.8,234.03,5,400,1,1,233.76,234.06,400,26,1,1,233.7,234.1,1200,100,1,1,233.68,234.13,29,400,1,1,233.66,234.17,1,1,1,1,233.58,234.25,505,100,2,1,233.53,234.41,10,500,1,1,233.5,234.43,100,105,1,2,233.45,234.5,15,63,1,4,AAPL,0.0,0.0,0.0,
2024-10-21 12:21:13.168540873+00:00,2024-10-21T12:21:13.168706863Z,10,2,38,C,B,0,233.86,100,130,165990,12830353,233.86,234.0,750,50,1,1,233.8,234.03,5,400,1,1,233.76,234.06,400,26,1,1,233.7,234.1,1200,100,1,1,233.68,234.13,29,400,1,1,233.66,234.17,1,1,1,1,233.58,234.25,505,100,2,1,233.53,234.41,10,500,1,1,233.5,234.43,100,105,1,2,233.45,234.5,15,63,1,4,AAPL,-100.0,-100.0,-100.0,
2024-10-21 12:21:16.960024614+00:00,2024-10-21T12:21:16.960190551Z,10,2,38,C,B,2,233.76,400,130,165937,12834954,233.86,234.0,750,50,1,1,233.8,234.03,5,400,1,1,233.7,234.06,1200,26,1,1,233.68,234.1,29,100,1,1,233.66,234.13,1,400,1,1,233.58,234.17,505,1,2,1,233.53,234.25,10,100,1,1,233.5,234.41,100,500,1,1,233.45,234.43,15,105,1,2,233.4,234.5,110,63,2,4,AAPL,0.0,0.0,0.0,
2024-10-21 12:21:16.960037598+00:00,2024-10-21T12:21:16.960203958Z,10,2,38,A,B,2,233.73,200,130,166360,12834955,233.86,234.0,750,50,1,1,233.8,234.03,5,400,1,1,233.73,234.06,200,26,1,1,233.7,234.1,1200,100,1,1,233.68,234.13,29,400,1,1,233.66,234.17,1,1,1,1,233.58,234.25,505,100,2,1,233.53,234.41,10,500,1,1,233.5,234.43,100,105,1,2,233.45,234.5,15,63,1,4,AAPL,0.0,0.0,0.0,
2024-10-21 12:21:17.837910042+00:00,2024-10-21T12:21:17.838076240Z,10,2,38,C,A,1,234.03,400,130,166198,12836232,233.86,234.0,750,50,1,1,233.8,234.06,5,26,1,1,233.73,234.1,200,100,1,1,233.7,234.13,1200,400,1,1,233.68,234.17,29,1,1,1,233.66,234.25,1,100,1,1,233.58,234.41,505,500,2,1,233.53,234.43,10,105,1,2,233.5,234.5,100,63,1,4,233.45,234.75,15,1,1,1,AAPL,0.0,0.0,0.0,
2024-10-21 12:21:17.837922361+00:00,2024-10-21T12:21:17.838088673Z,10,2,38,A,A,1,234.05,400,130,166312,12836233,233.86,234.0,750,50,1,1,233.8,234.05,5,400,1,1,233.73,234.06,200,26,1,1,233.7,234.1,1200,100,1,1,233.68,234.13,29,400,1,1,233.66,234.17,1,1,1,1,233.58,234.25,505,100,2,1,233.53,234.41,10,500,1,1,233.5,234.43,100,105,1,2,233.45,234.5,15,63,1,4,AAPL,0.0,0.0,0.0,
2024-10-21 12:21:17.892771425+00:00,2024-10-21T12:21:17.892937930Z,10,2,38,A,B,2,233.74,200,130,166505,12836353,233.86,234.0,750,50,1,1,233.8,234.05,5,400,1,1,233.74,234.06,200,26,1,1,233.7,234.1,1200,100,1,1,233.68,234.13,29,400,1,1,233.66,234.17,1,1,1,1,233.58,234.25,505,100,2,1,233.53,234.41,10,500,1,1,233.5,234.43,100,105,1,2,233.45,234.5,15,63,1,4,AAPL,0.0,0.0,0.0,
2024-10-21 12:21:18.021293469+00:00,2024-10-21T12:21:18.021459648Z,10,2,38,C,B,4,233.68,29,130,166179,12836833,233.86,234.0,750,50,1,1,233.8,234.05,5,400,1,1,233.74,234.06,200,26,1,1,233.7,234.1,1200,100,1,1,233.66,234.13,1,400,1,1,233.58,234.17,505,1,2,1,233.53,234.25,10,100,1,1,233.5,234.41,100,500,1,1,233.45,234.43,15,105,1,2,233.4,234.5,110,63,2,4,AAPL,0.0,0.0,0.0,
2024-10-21 12:21:18.047828600+00:00,2024-10-21T12:21:18.047995053Z,10,2,38,A,B,2,233.74,200,130,166453,12836959,233.86,234.0,750,50,1,1,233.8,234.05,5,400,1,1,233.74,234.06,400,26,2,1,233.7,234.1,1200,100,1,1,233.66,234.13,1,400,1,1,233.58,234.17,505,1,2,1,233.53,234.25,10,100,1,1,233.5,234.41,100,500,1,1,233.45,234.43,15,105,1,2,233.4,234.5,110,63,2,4,AAPL,0.0,200.0,0.0,
2024-10-21 12:21:18.102401275+00:00,2024-10-21T12:21:18.102567260Z,10,2,38,C,B,2,233.74,200,130,165985,12837042,233.86,234.0,750,50,1,1,233.8,234.05,5,400,1,1,233.74,234.06,200,26,1,1,233.7,234.1,1200,100,1,1,233.66,234.13,1,400,1,1,233.58,234.17,505,1,2,1,233.53,234.25,10,100,1,1,233.5,234.41,100,500,1,1,233.45,234.43,15,105,1,2,233.4,234.5,110,63,2,4,AAPL,0.0,-200.0,0.0,
2024-10-21 12:21:18.102413183+00:00,2024-10-21T12:21:18.102579613Z,10,2,38,A,B,2,233.77,400,130,166430,12837043,233.86,234.0,750,50,1,1,233.8,234.05,5,400,1,1,233.77,234.06,400,26,1,1,233.7,234.1,1200,100,1,1,233.66,234.13,1,400,1,1,233.58,234.17,505,1,2,1,233.53,234.25,10,100,1,1,233.5,234.41,100,500,1,1,233.45,234.43,15,105,1,2,233.4,234.5,110,63,2,4,AAPL,0.0,0.0,0.0,
2024-10-21 12:21:18.739881846+00:00,2024-10-21T12:21:18.740047899Z,10,2,38,C,A,1,234.05,200,130,166053,12837434,233.86,234.0,750,50,1,1,233.8,234.05,5,200,1,1,233.77,234.06,400,26,1,1,233.7,234.1,1200,100,1,1,233.66,234.13,1,400,1,1,233.58,234.17,505,1,2,1,233.53,234.25,10,100,1,1,233.5,234.41,100,500,1,1,233.45,234.43,15,105,1,2,233.4,234.5,110,63,2,4,AAPL,0.0,200.0,0.0,
2024-10-21 12:21:21.742772097+00:00,2024-10-21T12:21:21.742938480Z,10,2,38,A,A,1,234.05,200,130,166383,12841885,233.86,234.0,750,50,1,1,233.8,234.05,5,400,1,2,233.77,234.06,400,26,1,1,233.7,234.1,1200,100,1,1,233.66,234.13,1,400,1,1,233.58,234.17,505,1,2,1,233.53,234.25,10,100,1,1,233.5,234.41,100,500,1,1,233.45,234.43,15,105,1,2,233.4,234.5,110,63,2,4,AAPL,0.0,-200.0,0.0,
2024-10-21 12:21:26.102195386+00:00,2024-10-21T12:21:26.102361829Z,10,2,38,A,B,2,233.78,400,130,166443,12846472,233.86,234.0,750,50,1,1,233.8,234.05,5,400,1,2,233.78,234.06,400,26,1,1,233.7,234.1,1200,100,1,1,233.66,234.13,1,400,1,1,233.58,234.17,505,1,2,1,233.53,234.25,10,100,1,1,233.5,234.41,100,500,1,1,233.45,234.43,15,105,1,2,233.4,234.5,110,63,2,4,AAPL,0.0,0.0,0.0,
2024-10-21 12:21:26.482363138+00:00,2024-10-21T12:21:26.482529203Z,10,2,38,C,B,2,233.78,200,130,166065,12846917,233.86,234.0,750,50,1,1,233.8,234.05,5,400,1,2,233.78,234.06,200,26,1,1,233.7,234.1,1200,100,1,1,233.66,234.13,1,400,1,1,233.58,234.17,505,1,2,1,233.53,234.25,10,100,1,1,233.5,234.41,100,500,1,1,233.45,234.43,15,105,1,2,233.4,234.5,110,63,2,4,AAPL,0.0,-200.0,0.0,
2024-10-21 12:21:26.509547941+00:00,2024-10-21T12:21:26.509714476Z,10,2,38,A,B,2,233.78,200,130,166535,12846932,233.86,234.0,750,50,1,1,233.8,234.05,5,400,1,2,233.78,234.06,400,26,2,1,233.7,234.1,1200,100,1,1,233.66,234.13,1,400,1,1,233.58,234.17,505,1,2,1,233.53,234.25,10,100,1,1,233.5,234.41,100,500,1,1,233.45,234.43,15,105,1,2,233.4,234.5,110,63,2,4,AAPL,0.0,200.0,0.0,
2024-10-21 12:21:26.750764565+00:00,2024-10-21T12:21:26.750930428Z,10,2,38,C,B,2,233.78,200,130,165863,12847141,233.86,234.0,750,50,1,1,233.8,234.05,5,400,1,2,233.78,234.06,200,26,1,1,233.7,234.1,1200,100,1,1,233.66,234.13,1,400,1,1,233.58,234.17,505,1,2,1,233.53,234.25,10,100,1,1,233.5,234.41,100,500,1,1,233.45,234.43,15,105,1,2,233.4,234.5,110,63,2,4,AAPL,0.0,-200.0,0.0,
2024-10-21 12:21:26.750773173+00:00,2024-10-21T12:21:26.750938918Z,10,2,38,C,B,2,233.78,200,130,165745,12847142,233.86,234.0,750,50,1,1,233.8,234.05,5,400,1,2,233.7,234.06,1200,26,1,1,233.66,234.1,1,100,1,1,233.58,234.13,505,400,2,1,233.53,234.17,10,1,1,1,233.5,234.25,100,100,1,1,233.45,234.41,15,500,1,1,233.4,234.43,110,105,2,2,233.39,234.5,10,63,1,4,AAPL,0.0,0.0,0.0,
2024-10-21 12:21:26.750785721+00:00,2024-10-21T12:21:26.750951960Z,10,2,38,A,B,2,233.75,400,130,166239,12847143,233.86,234.0,750,50,1,1,233.8,234.05,5,400,1,2,233.75,234.06,400,26,1,1,233.7,234.1,1200,100,1,1,233.66,234.13,1,400,1,1,233.58,234.17,505,1,2,1,233.53,234.25,10,100,1,1,233.5,234.41,100,500,1,1,233.45,234.43,15,105,1,2,233.4,234.5,110,63,2,4,AAPL,0.0,0.0,0.0,
2024-10-21 12:21:26.804818995+00:00,2024-10-21T12:21:26.804985162Z,10,2,38,C,A,1,234.05,200,130,166167,12847412,233.86,234.0,750,50,1,1,233.8,234.05,5,200,1,1,233.75,234.06,400,26,1,1,233.7,234.1,1200,100,1,1,233.66,234.13,1,400,1,1,233.58,234.17,505,1,2,1,233.53,234.25,10,100,1,1,233.5,234.41,100,500,1,1,233.45,234.43,15,105,1,2,233.4,234.5,110,63,2,4,AAPL,0.0,200.0,0.0,
2024-10-21 12:21:26.804831024+00:00,2024-10-21T12:21:26.804997390Z,10,2,38,A,A,1,234.04,400,130,166366,12847413,233.86,234.0,750,50,1,1,233.8,234.04,5,400,1,1,233.75,234.06,400,26,1,1,233.7,234.1,1200,100,1,1,233.66,234.13,1,400,1,1,233.58,234.17,505,1,2,1,233.53,234.25,10,100,1,1,233.5,234.41,100,500,1,1,233.45,234.43,15,105,1,2,233.4,234.5,110,63,2,4,AAPL,0.0,0.0,0.0,
2024-10-21 12:21:26.876199312+00:00,2024-10-21T12:21:26.876365981Z,10,2,38,A,B,2,233.76,400,130,166669,12847641,233.86,234.0,750,50,1,1,233.8,234.04,5,400,1,1,233.76,234.06,400,26,1,1,233.7,234.1,1200,100,1,1,233.66,234.13,1,400,1,1,233.58,234.17,505,1,2,1,233.53,234.25,10,100,1,1,233.5,234.41,100,500,1,1,233.45,234.43,15,105,1,2,233.4,234.5,110,63,2,4,AAPL,0.0,0.0,0.0,
2024-10-21 12:21:28.271344736+00:00,2024-10-21T12:21:28.271511190Z,10,2,38,A,B,2,233.77,400,130,166454,12849143,233.86,234.0,750,50,1,1,233.8,234.04,5,400,1,1,233.77,234.06,400,26,1,1,233.7,234.1,1200,100,1,1,233.66,234.13,1,400,1,1,233.58,234.17,505,1,2,1,233.53,234.25,10,100,1,1,233.5,234.41,100,500,1,1,233.45,234.43,15,105,1,2,233.4,234.5,110,63,2,4,AAPL,0.0,0.0,0.0,
2024-10-21 12:21:29.830172186+00:00,2024-10-21T12:21:29.830338711Z,10,2,38,A,B,4,233.69,29,130,166525,12850583,233.86,234.0,750,50,1,1,233.8,234.04,5,400,1,1,233.77,234.06,400,26,1,1,233.7,234.1,1200,100,1,1,233.69,234.13,29,400,1,1,233.66,234.17,1,1,1,1,233.58,234.25,505,100,2,1,233.53,234.41,10,500,1,1,233.5,234.43,100,105,1,2,233.45,234.5,15,63,1,4,AAPL,0.0,0.0,0.0,
2024-10-21 12:21:43.255561253+00:00,2024-10-21T12:21:43.255727052Z,10,2,38,C,A,1,234.04,400,130,165799,12858522,233.86,234.0,750,50,1,1,233.8,234.06,5,26,1,1,233.77,234.1,400,100,1,1,233.7,234.13,1200,400,1,1,233.69,234.17,29,1,1,1,233.66,234.25,1,100,1,1,233.58,234.41,505,500,2,1,233.53,234.43,10,105,1,2,233.5,234.5,100,63,1,4,233.45,234.75,15,1,1,1,AAPL,0.0,0.0,0.0,
2024-10-21 12:21:43.255575289+00:00,2024-10-21T12:21:43.255741694Z,10,2,38,A,A,1,234.06,400,130,166405,12858523,233.86,234.0,750,50,1,1,233.8,234.06,5,426,1,2,233.77,234.1,400,100,1,1,233.7,234.13,1200,400,1,1,233.69,234.17,29,1,1,1,233.66,234.25,1,100,1,1,233.58,234.41,505,500,2,1,233.53,234.43,10,105,1,2,233.5,234.5,100,63,1,4,233.45,234.75,15,1,1,1,AAPL,0.0,-400.0,0.0,
2024-10-21 12:21:43.310928524+00:00,2024-10-21T12:21:43.311094812Z,10,2,38,A,A,1,234.05,200,130,166288,12858622,233.86,234.0,750,50,1,1,233.8,234.05,5,200,1,1,233.77,234.06,400,26,1,1,233.7,234.1,1200,100,1,1,233.69,234.13,29,400,1,1,233.66,234.17,1,1,1,1,233.58,234.25,505,100,2,1,233.53,234.41,10,500,1,1,233.5,234.43,100,105,1,2,233.45,234.5,15,63,1,4,AAPL,0.0,0.0,0.0,
2024-10-21 12:21:45.092124924+00:00,2024-10-21T12:21:45.092291237Z,10,2,38,A,B,2,233.78,400,130,166313,12859898,233.86,234.0,750,50,1,1,233.8,234.05,5,200,1,1,233.78,234.06,400,26,1,1,233.7,234.1,1200,100,1,1,233.69,234.13,29,400,1,1,233.66,234.17,1,1,1,1,233.58,234.25,505,100,2,1,233.53,234.41,10,500,1,1,233.5,234.43,100,105,1,2,233.45,234.5,15,63,1,4,AAPL,0.0,0.0,0.0,
2024-10-21 12:21:45.108232814+00:00,2024-10-21T12:21:45.108399049Z,10,2,38,C,B,4,233.69,29,130,166235,12859978,233.86,234.0,750,50,1,1,233.8,234.05,5,200,1,1,233.78,234.06,400,26,1,1,233.7,234.1,1200,100,1,1,233.66,234.13,1,400,1,1,233.58,234.17,505,1,2,1,233.53,234.25,10,100,1,1,233.5,234.41,100,500,1,1,233.45,234.43,15,105,1,2,233.4,234.5,110,63,2,4,AAPL,0.0,0.0,0.0,
2024-10-21 12:21:45.108296167+00:00,2024-10-21T12:21:45.108462494Z,10,2,38,A,B,3,233.7,29,130,166327,12859979,233.86,234.0,750,50,1,1,233.8,234.05,5,200,1,1,233.78,234.06,400,26,1,1,233.7,234.1,1229,100,2,1,233.66,234.13,1,400,1,1,233.58,234.17,505,1,2,1,233.53,234.25,10,100,1,1,233.5,234.41,100,500,1,1,233.45,234.43,15,105,1,2,233.4,234.5,110,63,2,4,AAPL,0.0,29.0,0.0,
2024-10-21 12:21:48.360630060+00:00,2024-10-21T12:21:48.360796158Z,10,2,38,C,A,1,234.05,200,130,166098,12862379,233.86,234.0,750,50,1,1,233.8,234.06,5,26,1,1,233.78,234.1,400,100,1,1,233.7,234.13,1229,400,2,1,233.66,234.17,1,1,1,1,233.58,234.25,505,100,2,1,233.53,234.41,10,500,1,1,233.5,234.43,100,105,1,2,233.45,234.5,15,63,1,4,233.4,234.75,110,1,2,1,AAPL,0.0,0.0,0.0,
2024-10-21 12:21:48.360641832+00:00,2024-10-21T12:21:48.360808085Z,10,2,38,A,A,2,234.07,200,130,166253,12862380,233.86,234.0,750,50,1,1,233.8,234.06,5,26,1,1,233.78,234.07,400,200,1,1,233.7,234.1,1229,100,2,1,233.66,234.13,1,400,1,1,233.58,234.17,505,1,2,1,233.53,234.25,10,100,1,1,233.5,234.41,100,500,1,1,233.45,234.43,15,105,1,2,233.4,234.5,110,63,2,4,AAPL,0.0,0.0,0.0,
2024-10-21 12:21:48.415524174+00:00,2024-10-21T12:21:48.415690677Z,10,2,38,A,B,2,233.79,400,130,166503,12862494,233.86,234.0,750,50,1,1,233.8,234.06,5,26,1,1,233.79,234.07,400,200,1,1,233.7,234.1,1229,100,2,1,233.66,234.13,1,400,1,1,233.58,234.17,505,1,2,1,233.53,234.25,10,100,1,1,233.5,234.41,100,500,1,1,233.45,234.43,15,105,1,2,233.4,234.5,110,63,2,4,AAPL,0.0,0.0,0.0,
2024-10-21 12:21:48.426249325+00:00,2024-10-21T12:21:48.426415426Z,10,2,38,C,B,3,233.7,29,130,166101,12862632,233.86,234.0,750,50,1,1,233.8,234.06,5,26,1,1,233.79,234.07,400,200,1,1,233.7,234.1,1200,100,1,1,233.66,234.13,1,400,1,1,233.58,234.17,505,1,2,1,233.53,234.25,10,100,1,1,233.5,234.41,100,500,1,1,233.45,234.43,15,105,1,2,233.4,234.5,110,63,2,4,AAPL,0.0,-29.0,0.0,
2024-10-21 12:21:48.426358775+00:00,2024-10-21T12:21:48.426524915Z,10,2,38,A,B,3,233.71,26,130,166140,12862634,233.86,234.0,750,50,1,1,233.8,234.06,5,26,1,1,233.79,234.07,400,200,1,1,233.71,234.1,26,100,1,1,233.7,234.13,1200,400,1,1,233.66,234.17,1,1,1,1,233.58,234.25,505,100,2,1,233.53,234.41,10,500,1,1,233.5,234.43,100,105,1,2,233.45,234.5,15,63,1,4,AAPL,0.0,0.0,0.0,
2024-10-21 12:21:48.440341021+00:00,2024-10-21T12:21:48.440507069Z,10,2,38,C,A,1,234.06,26,130,166048,12862704,233.86,234.0,750,50,1,1,233.8,234.07,5,200,1,1,233.79,234.1,400,100,1,1,233.71,234.13,26,400,1,1,233.7,234.17,1200,1,1,1,233.66,234.25,1,100,1,1,233.58,234.41,505,500,2,1,233.53,234.43,10,105,1,2,233.5,234.5,100,63,1,4,233.45,234.75,15,1,1,1,AAPL,0.0,0.0,0.0,
2024-10-21 12:21:48.582445356+00:00,2024-10-21T12:21:48.582611366Z,10,2,38,C,B,2,233.79,400,130,166010,12862943,233.86,234.0,750,50,1,1,233.8,234.07,5,200,1,1,233.71,234.1,26,100,1,1,233.7,234.13,1200,400,1,1,233.66,234.17,1,1,1,1,233.58,234.25,505,100,2,1,233.53,234.41,10,500,1,1,233.5,234.43,100,105,1,2,233.45,234.5,15,63,1,4,233.4,234.75,110,1,2,1,AAPL,0.0,0.0,0.0,
2024-10-21 12:21:48.582457462+00:00,2024-10-21T12:21:48.582623644Z,10,2,38,A,B,2,233.76,200,130,166182,12862944,233.86,234.0,750,50,1,1,233.8,234.07,5,200,1,1,233.76,234.1,200,100,1,1,233.71,234.13,26,400,1,1,233.7,234.17,1200,1,1,1,233.66,234.25,1,100,1,1,233.58,234.41,505,500,2,1,233.53,234.43,10,105,1,2,233.5,234.5,100,63,1,4,233.45,234.75,15,1,1,1,AAPL,0.0,0.0,0.0,
2024-10-21 12:21:48.968862759+00:00,2024-10-21T12:21:48.969029036Z,10,2,38,A,A,1,234.07,200,130,166277,12863250,233.86,234.0,750,50,1,1,233.8,234.07,5,400,1,2,233.76,234.1,200,100,1,1,233.71,234.13,26,400,1,1,233.7,234.17,1200,1,1,1,233.66,234.25,1,100,1,1,233.58,234.41,505,500,2,1,233.53,234.43,10,105,1,2,233.5,234.5,100,63,1,4,233.45,234.75,15,1,1,1,AAPL,0.0,-200.0,0.0,
2024-10-21 12:21:49.023156980+00:00,2024-10-21T12:21:49.023322916Z,10,2,38,C,A,1,234.07,200,130,165936,12863318,233.86,234.0,750,50,1,1,233.8,234.07,5,200,1,1,233.76,234.1,200,100,1,1,233.71,234.13,26,400,1,1,233.7,234.17,1200,1,1,1,233.66,234.25,1,100,1,1,233.58,234.41,505,500,2,1,233.53,234.43,10,105,1,2,233.5,234.5,100,63,1,4,233.45,234.75,15,1,1,1,AAPL,0.0,200.0,0.0,
2024-10-21 12:21:49.023170310+00:00,2024-10-21T12:21:49.023336867Z,10,2,38,A,A,1,234.03,200,130,166557,12863319,233.86,234.0,750,50,1,1,233.8,234.03,5,200,1,1,233.76,234.1,200,100,1,1,233.71,234.13,26,400,1,1,233.7,234.17,1200,1,1,1,233.66,234.25,1,100,1,1,233.58,234.41,505,500,2,1,233.53,234.43,10,105,1,2,233.5,234.5,100,63,1,4,233.45,234.75,15,1,1,1,AAPL,0.0,0.0,0.0,
2024-10-21 12:21:53.593348279+00:00,2024-10-21T12:21:53.593514833Z,10,2,38,A,B,2,233.76,200,130,166554,12866345,233.86,234.0,750,50,1,1,233.8,234.03,5,200,1,1,233.76,234.1,400,100,2,1,233.71,234.13,26,400,1,1,233.7,234.17,1200,1,1,1,233.66,234.25,1,100,1,1,233.58,234.41,505,500,2,1,233.53,234.43,10,105,1,2,233.5,234.5,100,63,1,4,233.45,234.75,15,1,1,1,AAPL,0.0,200.0,0.0,
2024-10-21 12:21:53.647894830+00:00,2024-10-21T12:21:53.648061859Z,10,2,38,C,B,2,233.76,200,130,167029,12866372,233.86,234.0,750,50,1,1,233.8,234.03,5,200,1,1,233.76,234.1,200,100,1,1,233.71,234.13,26,400,1,1,233.7,234.17,1200,1,1,1,233.66,234.25,1,100,1,1,233.58,234.41,505,500,2,1,233.53,234.43,10,105,1,2,233.5,234.5,100,63,1,4,233.45,234.75,15,1,1,1,AAPL,0.0,-200.0,0.0,
2024-10-21 12:21:53.647907823+00:00,2024-10-21T12:21:53.648074342Z,10,2,38,A,B,2,233.79,400,130,166519,12866373,233.86,234.0,750,50,1,1,233.8,234.03,5,200,1,1,233.79,234.1,400,100,1,1,233.71,234.13,26,400,1,1,233.7,234.17,1200,1,1,1,233.66,234.25,1,100,1,1,233.58,234.41,505,500,2,1,233.53,234.43,10,105,1,2,233.5,234.5,100,63,1,4,233.45,234.75,15,1,1,1,AAPL,0.0,0.0,0.0,
2024-10-21 12:21:55.660629861+00:00,2024-10-21T12:21:55.660797064Z,10,2,38,T,N,0,233.92,46,130,167203,12867692,233.86,234.0,750,50,1,1,233.8,234.03,5,200,1,1,233.79,234.1,400,100,1,1,233.71,234.13,26,400,1,1,233.7,234.17,1200,1,1,1,233.66,234.25,1,100,1,1,233.58,234.41,505,500,2,1,233.53,234.43,10,105,1,2,233.5,234.5,100,63,1,4,233.45,234.75,15,1,1,1,AAPL,0.0,0.0,0.0,
2024-10-21 12:22:01.337904135+00:00,2024-10-21T12:22:01.338070399Z,10,2,38,A,A,1,234.02,200,130,166264,12872899,233.86,234.0,750,50,1,1,233.8,234.02,5,200,1,1,233.79,234.1,400,100,1,1,233.71,234.13,26,400,1,1,233.7,234.17,1200,1,1,1,233.66,234.25,1,100,1,1,233.58,234.41,505,500,2,1,233.53,234.43,10,105,1,2,233.5,234.5,100,63,1,4,233.45,234.75,15,1,1,1,AAPL,0.0,0.0,0.0,
2024-10-21 12:22:03.706361217+00:00,2024-10-21T12:22:03.706527389Z,10,2,38,C,B,0,233.86,750,130,166172,12876552,233.8,234.0,5,50,1,1,233.79,234.02,400,200,1,1,233.71,234.1,26,100,1,1,233.7,234.13,1200,400,1,1,233.66,234.17,1,1,1,1,233.58,234.25,505,100,2,1,233.53,234.41,10,500,1,1,233.5,234.43,100,105,1,2,233.45,234.5,15,63,1,4,233.4,234.75,110,1,2,1,AAPL,0.0,0.0,0.0,
2024-10-21 12:22:03.777516702+00:00,2024-10-21T12:22:03.777683119Z,10,2,38,C,B,1,233.79,400,130,166417,12876583,233.8,234.0,5,50,1,1,233.71,234.02,26,200,1,1,233.7,234.1,1200,100,1,1,233.66,234.13,1,400,1,1,233.58,234.17,505,1,2,1,233.53,234.25,10,100,1,1,233.5,234.41,100,500,1,1,233.45,234.43,15,105,1,2,233.4,234.5,110,63,2,4,233.39,234.75,10,1,1,1,AAPL,0.0,0.0,0.0,
2024-10-21 12:22:03.777529729+00:00,2024-10-21T12:22:03.777696253Z,10,2,38,A,B,1,233.72,200,130,166524,12876584,233.8,234.0,5,50,1,1,233.72,234.02,200,200,1,1,233.71,234.1,26,100,1,1,233.7,234.13,1200,400,1,1,233.66,234.17,1,1,1,1,233.58,234.25,505,100,2,1,233.53,234.41,10,500,1,1,233.5,234.43,100,105,1,2,233.45,234.5,15,63,1,4,233.4,234.75,110,1,2,1,AAPL,0.0,0.0,0.0,
2024-10-21 12:22:03.781981187+00:00,2024-10-21T12:22:03.782147350Z,10,2,38,A,A,1,234.02,200,130,166163,12876586,233.8,234.0,5,50,1,1,233.72,234.02,200,400,1,2,233.71,234.1,26,100,1,1,233.7,234.13,1200,400,1,1,233.66,234.17,1,1,1,1,233.58,234.25,505,100,2,1,233.53,234.41,10,500,1,1,233.5,234.43,100,105,1,2,233.45,234.5,15,63,1,4,233.4,234.75,110,1,2,1,AAPL,0.0,-200.0,0.0,
2024-10-21 12:22:09.127308929+00:00,2024-10-21T12:22:09.127475230Z,10,2,38,A,A,2,234.08,28,130,166301,12879884,233.8,234.0,5,50,1,1,233.72,234.02,200,400,1,2,233.71,234.08,26,28,1,1,233.7,234.1,1200,100,1,1,233.66,234.13,1,400,1,1,233.58,234.17,505,1,2,1,233.53,234.25,10,100,1,1,233.5,234.41,100,500,1,1,233.45,234.43,15,105,1,2,233.4,234.5,110,63,2,4,AAPL,0.0,0.0,0.0,
2024-10-21 12:22:16.157355560+00:00,2024-10-21T12:22:16.157521352Z,10,2,38,C,B,2,233.71,26,130,165792,12885019,233.8,234.0,5,50,1,1,233.72,234.02,200,400,1,2,233.7,234.08,1200,28,1,1,233.66,234.1,1,100,1,1,233.58,234.13,505,400,2,1,233.53,234.17,10,1,1,1,233.5,234.25,100,100,1,1,233.45,234.41,15,500,1,1,233.4,234.43,110,105,2,2,233.39,234.5,10,63,1,4,AAPL,0.0,0.0,0.0,
2024-10-21 12:22:16.158383793+00:00,2024-10-21T12:22:16.158550111Z,10,2,38,A,B,1,233.72,28,130,166318,12885021,233.8,234.0,5,50,1,1,233.72,234.02,228,400,2,2,233.7,234.08,1200,28,1,1,233.66,234.1,1,100,1,1,233.58,234.13,505,400,2,1,233.53,234.17,10,1,1,1,233.5,234.25,100,100,1,1,233.45,234.41,15,500,1,1,233.4,234.43,110,105,2,2,233.39,234.5,10,63,1,4,AAPL,0.0,28.0,0.0,
2024-10-21 12:22:20.068422134+00:00,2024-10-21T12:22:20.068588488Z,10,2,38,A,B,1,233.73,200,130,166354,12888188,233.8,234.0,5,50,1,1,233.73,234.02,200,400,1,2,233.72,234.08,28,28,1,1,233.7,234.1,1200,100,1,1,233.66,234.13,1,400,1,1,233.58,234.17,505,1,2,1,233.53,234.25,10,100,1,1,233.5,234.41,100,500,1,1,233.45,234.43,15,105,1,2,233.4,234.5,110,63,2,4,AAPL,0.0,0.0,0.0,
2024-10-21 12:22:20.078770275+00:00,2024-10-21T12:22:20.078936626Z,10,2,38,A,B,1,233.73,29,130,166351,12888325,233.8,234.0,5,50,1,1,233.73,234.02,229,400,2,2,233.72,234.08,28,28,1,1,233.7,234.1,1200,100,1,1,233.66,234.13,1,400,1,1,233.58,234.17,505,1,2,1,233.53,234.25,10,100,1,1,233.5,234.41,100,500,1,1,233.45,234.43,15,105,1,2,233.4,234.5,110,63,2,4,AAPL,0.0,29.0,0.0,
2024-10-21 12:22:20.078850920+00:00,2024-10-21T12:22:20.079017156Z,10,2,38,C,B,2,233.72,28,130,166236,12888328,233.8,234.0,5,50,1,1,233.73,234.02,229,400,2,2,233.7,234.08,1200,28,1,1,233.66,234.1,1,100,1,1,233.58,234.13,505,400,2,1,233.53,234.17,10,1,1,1,233.5,234.25,100,100,1,1,233.45,234.41,15,500,1,1,233.4,234.43,110,105,2,2,233.39,234.5,10,63,1,4,AAPL,0.0,0.0,0.0,
2024-10-21 12:22:20.140239259+00:00,2024-10-21T12:22:20.140405333Z,10,2,38,C,A,2,234.08,28,130,166074,12888403,233.8,234.0,5,50,1,1,233.73,234.02,229,400,2,2,233.7,234.1,1200,100,1,1,233.66,234.13,1,400,1,1,233.58,234.17,505,1,2,1,233.53,234.25,10,100,1,1,233.5,234.41,100,500,1,1,233.45,234.43,15,105,1,2,233.4,234.5,110,63,2,4,233.39,234.75,10,1,1,1,AAPL,0.0,0.0,0.0,
2024-10-21 12:22:20.140291372+00:00,2024-10-21T12:22:20.140457549Z,10,2,38,A,A,2,234.04,30,130,166177,12888404,233.8,234.0,5,50,1,1,233.73,234.02,229,400,2,2,233.7,234.04,1200,30,1,1,233.66,234.1,1,100,1,1,233.58,234.13,505,400,2,1,233.53,234.17,10,1,1,1,233.5,234.25,100,100,1,1,233.45,234.41,15,500,1,1,233.4,234.43,110,105,2,2,233.39,234.5,10,63,1,4,AAPL,0.0,0.0,0.0,
2024-10-21 12:22:20.142525001+00:00,2024-10-21T12:22:20.142691051Z,10,2,38,C,A,1,234.02,200,130,166050,12888407,233.8,234.0,5,50,1,1,233.73,234.02,229,200,2,1,233.7,234.04,1200,30,1,1,233.66,234.1,1,100,1,1,233.58,234.13,505,400,2,1,233.53,234.17,10,1,1,1,233.5,234.25,100,100,1,1,233.45,234.41,15,500,1,1,233.4,234.43,110,105,2,2,233.39,234.5,10,63,1,4,AAPL,0.0,200.0,0.0,
2024-10-21 12:22:20.142535602+00:00,2024-10-21T12:22:20.142701567Z,10,2,38,C,A,1,234.02,200,130,165965,12888408,233.8,234.0,5,50,1,1,233.73,234.04,229,30,2,1,233.7,234.1,1200,100,1,1,233.66,234.13,1,400,1,1,233.58,234.17,505,1,2,1,233.53,234.25,10,100,1,1,233.5,234.41,100,500,1,1,233.45,234.43,15,105,1,2,233.4,234.5,110,63,2,4,233.39,234.75,10,1,1,1,AAPL,0.0,0.0,0.0,
2024-10-21 12:22:20.142546696+00:00,2024-10-21T12:22:20.142712784Z,10,2,38,A,A,1,234.03,200,130,166088,12888409,233.8,234.0,5,50,1,1,233.73,234.03,229,200,2,1,233.7,234.04,1200,30,1,1,233.66,234.1,1,100,1,1,233.58,234.13,505,400,2,1,233.53,234.17,10,1,1,1,233.5,234.25,100,100,1,1,233.45,234.41,15,500,1,1,233.4,234.43,110,105,2,2,233.39,234.5,10,63,1,4,AAPL,0.0,0.0,0.0,
2024-10-21 12:22:20.146234448+00:00,2024-10-21T12:22:20.146400458Z,10,2,38,C,A,2,234.04,30,130,166010,12888412,233.8,234.0,5,50,1,1,233.73,234.03,229,200,2,1,233.7,234.1,1200,100,1,1,233.66,234.13,1,400,1,1,233.58,234.17,505,1,2,1,233.53,234.25,10,100,1,1,233.5,234.41,100,500,1,1,233.45,234.43,15,105,1,2,233.4,234.5,110,63,2,4,233.39,234.75,10,1,1,1,AAPL,0.0,0.0,0.0,
2024-10-21 12:22:20.260745295+00:00,2024-10-21T12:22:20.260912200Z,10,2,38,A,A,1,234.02,200,130,166905,12888534,233.8,234.0,5,50,1,1,233.73,234.02,229,200,2,1,233.7,234.1,1200,100,1,1,233.66,234.13,1,400,1,1,233.58,234.17,505,1,2,1,233.53,234.25,10,100,1,1,233.5,234.41,100,500,1,1,233.45,234.43,15,105,1,2,233.4,234.5,110,63,2,4,233.39,234.75,10,1,1,1,AAPL,0.0,0.0,0.0,
2024-10-21 12:22:20.322223273+00:00,2024-10-21T12:22:20.322389944Z,10,2,38,A,A,1,234.02,200,130,166671,12888684,233.8,234.0,5,50,1,1,233.73,234.02,229,400,2,2,233.7,234.1,1200,100,1,1,233.66,234.13,1,400,1,1,233.58,234.17,505,1,2,1,233.53,234.25,10,100,1,1,233.5,234.41,100,500,1,1,233.45,234.43,15,105,1,2,233.4,234.5,110,63,2,4,233.39,234.75,10,1,1,1,AAPL,0.0,-200.0,0.0,
2024-10-21 12:22:21.536007375+00:00,2024-10-21T12:22:21.536173766Z,10,2,38,A,A,2,234.04,26,130,166391,12890037,233.8,234.0,5,50,1,1,233.73,234.02,229,400,2,2,233.7,234.04,1200,26,1,1,233.66,234.1,1,100,1,1,233.58,234.13,505,400,2,1,233.53,234.17,10,1,1,1,233.5,234.25,100,100,1,1,233.45,234.41,15,500,1,1,233.4,234.43,110,105,2,2,233.39,234.5,10,63,1,4,AAPL,0.0,0.0,0.0,
2024-10-21 12:22:21.539297131+00:00,2024-10-21T12:22:21.539463374Z,10,2,38,C,A,2,234.04,26,130,166243,12890041,233.8,234.0,5,50,1,1,233.73,234.02,229,400,2,2,233.7,234.1,1200,100,1,1,233.66,234.13,1,400,1,1,233.58,234.17,505,1,2,1,233.53,234.25,10,100,1,1,233.5,234.41,100,500,1,1,233.45,234.43,15,105,1,2,233.4,234.5,110,63,2,4,233.39,234.75,10,1,1,1,AAPL,0.0,0.0,0.0,
2024-10-21 12:22:21.583281944+00:00,2024-10-21T12:22:21.583448421Z,10,2,38,A,B,1,233.74,200,130,166477,12890469,233.8,234.0,5,50,1,1,233.74,234.02,200,400,1,2,233.73,234.1,29,100,1,1,233.7,234.13,1200,400,1,1,233.66,234.17,1,1,1,1,233.58,234.25,505,100,2,1,233.53,234.41,10,500,1,1,233.5,234.43,100,105,1,2,233.45,234.5,15,63,1,4,233.4,234.75,110,1,2,1,AAPL,0.0,0.0,0.0,
2024-10-21 12:22:22.095263170+00:00,2024-10-21T12:22:22.095429909Z,10,2,38,A,A,2,234.09,27,130,166739,12891303,233.8,234.0,5,50,1,1,233.74,234.02,200,400,1,2,233.73,234.09,29,27,1,1,233.7,234.1,1200,100,1,1,233.66,234.13,1,400,1,1,233.58,234.17,505,1,2,1,233.53,234.25,10,100,1,1,233.5,234.41,100,500,1,1,233.45,234.43,15,105,1,2,233.4,234.5,110,63,2,4,AAPL,0.0,0.0,0.0,
2024-10-21 12:22:22.945397458+00:00,2024-10-21T12:22:22.945563810Z,10,2,38,C,A,1,234.02,200,130,166352,12893143,233.8,234.0,5,50,1,1,233.74,234.02,200,200,1,1,233.73,234.09,29,27,1,1,233.7,234.1,1200,100,1,1,233.66,234.13,1,400,1,1,233.58,234.17,505,1,2,1,233.53,234.25,10,100,1,1,233.5,234.41,100,500,1,1,233.45,234.43,15,105,1,2,233.4,234.5,110,63,2,4,AAPL,0.0,200.0,0.0,
2024-10-21 12:22:22.945406901+00:00,2024-10-21T12:22:22.945572707Z,10,2,38,C,A,1,234.02,200,130,165806,12893145,233.8,234.0,5,50,1,1,233.74,234.09,200,27,1,1,233.73,234.1,29,100,1,1,233.7,234.13,1200,400,1,1,233.66,234.17,1,1,1,1,233.58,234.25,505,100,2,1,233.53,234.41,10,500,1,1,233.5,234.43,100,105,1,2,233.45,234.5,15,63,1,4,233.4,234.75,110,1,2,1,AAPL,0.0,0.0,0.0,
2024-10-21 12:22:22.945697032+00:00,2024-10-21T12:22:22.945862943Z,10,2,38,A,A,1,234.03,200,130,165911,12893175,233.8,234.0,5,50,1,1,233.74,234.03,200,200,1,1,233.73,234.09,29,27,1,1,233.7,234.1,1200,100,1,1,233.66,234.13,1,400,1,1,233.58,234.17,505,1,2,1,233.53,234.25,10,100,1,1,233.5,234.41,100,500,1,1,233.45,234.43,15,105,1,2,233.4,234.5,110,63,2,4,AAPL,0.0,0.0,0.0,
2024-10-21 12:22:22.986296201+00:00,2024-10-21T12:22:22.986462573Z,10,2,38,A,A,1,234.03,200,130,166372,12894197,233.8,234.0,5,50,1,1,233.74,234.03,200,400,1,2,233.73,234.09,29,27,1,1,233.7,234.1,1200,100,1,1,233.66,234.13,1,400,1,1,233.58,234.17,505,1,2,1,233.53,234.25,10,100,1,1,233.5,234.41,100,500,1,1,233.45,234.43,15,105,1,2,233.4,234.5,110,63,2,4,AAPL,0.0,-200.0,0.0,
2024-10-21 12:22:23.024563308+00:00,2024-10-21T12:22:23.024730389Z,10,2,38,C,A,1,234.03,200,128,167081,12894812,233.8,234.0,5,50,1,1,233.74,234.03,200,200,1,1,233.73,234.09,29,27,1,1,233.7,234.1,1200,100,1,1,233.66,234.13,1,400,1,1,233.58,234.17,505,1,2,1,233.53,234.25,10,100,1,1,233.5,234.41,100,500,1,1,233.45,234.43,15,105,1,2,233.4,234.5,110,63,2,4,AAPL,0.0,200.0,0.0,
2024-10-21 12:22:23.028903196+00:00,2024-10-21T12:22:23.029069095Z,10,2,38,C,A,1,234.03,200,130,165899,12894909,233.8,234.0,5,50,1,1,233.74,234.09,200,27,1,1,233.73,234.1,29,100,1,1,233.7,234.13,1200,400,1,1,233.66,234.17,1,1,1,1,233.58,234.25,505,100,2,1,233.53,234.41,10,500,1,1,233.5,234.43,100,105,1,2,233.45,234.5,15,63,1,4,233.4,234.75,110,1,2,1,AAPL,0.0,0.0,0.0,
2024-10-21 12:22:23.028915916+00:00,2024-10-21T12:22:23.029082382Z,10,2,38,A,A,1,234.08,200,130,166466,12894910,233.8,234.0,5,50,1,1,233.74,234.08,200,200,1,1,233.73,234.09,29,27,1,1,233.7,234.1,1200,100,1,1,233.66,234.13,1,400,1,1,233.58,234.17,505,1,2,1,233.53,234.25,10,100,1,1,233.5,234.41,100,500,1,1,233.45,234.43,15,105,1,2,233.4,234.5,110,63,2,4,AAPL,0.0,0.0,0.0,
2024-10-21 12:22:23.079803882+00:00,2024-10-21T12:22:23.079970068Z,10,2,38,A,B,0,233.88,3,130,166186,12895304,233.88,234.0,3,50,1,1,233.8,234.08,5,200,1,1,233.74,234.09,200,27,1,1,233.73,234.1,29,100,1,1,233.7,234.13,1200,400,1,1,233.66,234.17,1,1,1,1,233.58,234.25,505,100,2,1,233.53,234.41,10,500,1,1,233.5,234.43,100,105,1,2,233.45,234.5,15,63,1,4,AAPL,0.0,0.0,0.0,
2024-10-21 12:22:23.079851405+00:00,2024-10-21T12:22:23.080018858Z,10,2,38,T,N,0,233.92,17,130,167453,12895307,233.88,234.0,3,50,1,1,233.8,234.08,5,200,1,1,233.74,234.09,200,27,1,1,233.73,234.1,29,100,1,1,233.7,234.13,1200,400,1,1,233.66,234.17,1,1,1,1,233.58,234.25,505,100,2,1,233.53,234.41,10,500,1,1,233.5,234.43,100,105,1,2,233.45,234.5,15,63,1,4,AAPL,0.0,0.0,0.0,
2024-10-21 12:22:23.079869699+00:00,2024-10-21T12:22:23.080043588Z,10,2,38,T,N,0,233.98,13,0,173889,12895310,233.88,234.0,3,50,1,1,233.8,234.08,5,200,1,1,233.74,234.09,200,27,1,1,233.73,234.1,29,100,1,1,233.7,234.13,1200,400,1,1,233.66,234.17,1,1,1,1,233.58,234.25,505,100,2,1,233.53,234.41,10,500,1,1,233.5,234.43,100,105,1,2,233.45,234.5,15,63,1,4,AAPL,0.0,0.0,0.0,
2024-10-21 12:22:23.079869699+00:00,2024-10-21T12:22:23.080043588Z,10,2,38,T,N,0,233.98,21,0,173889,12895311,233.88,234.0,3,50,1,1,233.8,234.08,5,200,1,1,233.74,234.09,200,27,1,1,233.73,234.1,29,100,1,1,233.7,234.13,1200,400,1,1,233.66,234.17,1,1,1,1,233.58,234.25,505,100,2,1,233.53,234.41,10,500,1,1,233.5,234.43,100,105,1,2,233.45,234.5,15,63,1,4,AAPL,0.0,0.0,0.0,
2024-10-21 12:22:23.079869699+00:00,2024-10-21T12:22:23.080043588Z,10,2,38,T,N,0,233.98,18,0,173889,12895312,233.88,234.0,3,50,1,1,233.8,234.08,5,200,1,1,233.74,234.09,200,27,1,1,233.73,234.1,29,100,1,1,233.7,234.13,1200,400,1,1,233.66,234.17,1,1,1,1,233.58,234.25,505,100,2,1,233.53,234.41,10,500,1,1,233.5,234.43,100,105,1,2,233.45,234.5,15,63,1,4,AAPL,0.0,0.0,0.0,
2024-10-21 12:22:23.079869699+00:00,2024-10-21T12:22:23.080043588Z,10,2,38,T,B,0,234.0,48,128,173889,12895313,233.88,234.0,3,50,1,1,233.8,234.08,5,200,1,1,233.74,234.09,200,27,1,1,233.73,234.1,29,100,1,1,233.7,234.13,1200,400,1,1,233.66,234.17,1,1,1,1,233.58,234.25,505,100,2,1,233.53,234.41,10,500,1,1,233.5,234.43,100,105,1,2,233.45,234.5,15,63,1,4,AAPL,0.0,0.0,0.0,
2024-10-21 12:22:23.079869699+00:00,2024-10-21T12:22:23.080043588Z,10,2,38,C,A,0,234.0,48,128,173889,12895313,233.88,234.0,3,2,1,1,233.8,234.08,5,200,1,1,233.74,234.09,200,27,1,1,233.73,234.1,29,100,1,1,233.7,234.13,1200,400,1,1,233.66,234.17,1,1,1,1,233.58,234.25,505,100,2,1,233.53,234.41,10,500,1,1,233.5,234.43,100,105,1,2,233.45,234.5,15,63,1,4,AAPL,48.0,48.0,48.0,
2024-10-21 12:22:23.079955251+00:00,2024-10-21T12:22:23.080121046Z,10,2,38,C,A,1,234.08,200,130,165795,12895319,233.88,234.0,3,2,1,1,233.8,234.09,5,27,1,1,233.74,234.1,200,100,1,1,233.73,234.13,29,400,1,1,233.7,234.17,1200,1,1,1,233.66,234.25,1,100,1,1,233.58,234.41,505,500,2,1,233.53,234.43,10,105,1,2,233.5,234.5,100,63,1,4,233.45,234.75,15,1,1,1,AAPL,0.0,0.0,48.0,
2024-10-21 12:22:23.083910618+00:00,2024-10-21T12:22:23.084076713Z,10,2,38,C,B,0,233.88,3,130,166095,12895336,233.8,234.0,5,2,1,1,233.74,234.09,200,27,1,1,233.73,234.1,29,100,1,1,233.7,234.13,1200,400,1,1,233.66,234.17,1,1,1,1,233.58,234.25,505,100,2,1,233.53,234.41,10,500,1,1,233.5,234.43,100,105,1,2,233.45,234.5,15,63,1,4,233.4,234.75,110,1,2,1,AAPL,0.0,0.0,48.0,
2024-10-21 12:22:23.088151194+00:00,2024-10-21T12:22:23.088319645Z,10,2,38,A,B,0,233.91,100,128,168451,12895372,233.91,234.0,100,2,1,1,233.8,234.09,5,27,1,1,233.74,234.1,200,100,1,1,233.73,234.13,29,400,1,1,233.7,234.17,1200,1,1,1,233.66,234.25,1,100,1,1,233.58,234.41,505,500,2,1,233.53,234.43,10,105,1,2,233.5,234.5,100,63,1,4,233.45,234.75,15,1,1,1,AAPL,0.0,0.0,48.0,
2024-10-21 12:22:23.116151189+00:00,2024-10-21T12:22:23.116317544Z,10,2,38,A,A,1,234.08,200,130,166355,12895511,233.91,234.0,100,2,1,1,233.8,234.08,5,200,1,1,233.74,234.09,200,27,1,1,233.73,234.1,29,100,1,1,233.7,234.13,1200,400,1,1,233.66,234.17,1,1,1,1,233.58,234.25,505,100,2,1,233.53,234.41,10,500,1,1,233.5,234.43,100,105,1,2,233.45,234.5,15,63,1,4,AAPL,0.0,0.0,48.0,
2024-10-21 12:22:23.241854315+00:00,2024-10-21T12:22:23.242021318Z,10,2,38,A,A,1,234.07,200,130,167003,12895969,233.91,234.0,100,2,1,1,233.8,234.07,5,200,1,1,233.74,234.09,200,27,1,1,233.73,234.1,29,100,1,1,233.7,234.13,1200,400,1,1,233.66,234.17,1,1,1,1,233.58,234.25,505,100,2,1,233.53,234.41,10,500,1,1,233.5,234.43,100,105,1,2,233.45,234.5,15,63,1,4,AAPL,0.0,0.0,48.0,
2024-10-21 12:22:26.043027067+00:00,2024-10-21T12:22:26.043193578Z,10,2,38,A,A,1,234.07,200,130,166511,12901196,233.91,234.0,100,2,1,1,233.8,234.07,5,400,1,2,233.74,234.09,200,27,1,1,233.73,234.1,29,100,1,1,233.7,234.13,1200,400,1,1,233.66,234.17,1,1,1,1,233.58,234.25,505,100,2,1,233.53,234.41,10,500,1,1,233.5,234.43,100,105,1,2,233.45,234.5,15,63,1,4,AAPL,0.0,-200.0,0.0,
2024-10-21 12:22:26.221438925+00:00,2024-10-21T12:22:26.221605392Z,10,2,38,A,B,2,233.78,200,130,166467,12901441,233.91,234.0,100,2,1,1,233.8,234.07,5,400,1,2,233.78,234.09,200,27,1,1,233.73,234.1,29,100,1,1,233.7,234.13,1200,400,1,1,233.66,234.17,1,1,1,1,233.58,234.25,505,100,2,1,233.53,234.41,10,500,1,1,233.5,234.43,100,105,1,2,233.45,234.5,15,63,1,4,AAPL,0.0,0.0,0.0,
2024-10-21 12:22:29.394160247+00:00,2024-10-21T12:22:29.394326484Z,10,2,38,A,B,2,233.79,200,130,166237,12905660,233.91,234.0,100,2,1,1,233.8,234.07,5,400,1,2,233.79,234.09,200,27,1,1,233.73,234.1,29,100,1,1,233.7,234.13,1200,400,1,1,233.66,234.17,1,1,1,1,233.58,234.25,505,100,2,1,233.53,234.41,10,500,1,1,233.5,234.43,100,105,1,2,233.45,234.5,15,63,1,4,AAPL,0.0,0.0,0.0,
2024-10-21 12:22:36.707463498+00:00,2024-10-21T12:22:36.707629405Z,10,2,38,C,A,2,234.09,27,130,165907,12912830,233.91,234.0,100,2,1,1,233.8,234.07,5,400,1,2,233.79,234.1,200,100,1,1,233.73,234.13,29,400,1,1,233.7,234.17,1200,1,1,1,233.66,234.25,1,100,1,1,233.58,234.41,505,500,2,1,233.53,234.43,10,105,1,2,233.5,234.5,100,63,1,4,233.45,234.75,15,1,1,1,AAPL,0.0,0.0,0.0,
2024-10-21 12:22:36.707506060+00:00,2024-10-21T12:22:36.707672458Z,10,2,38,A,A,2,234.08,26,130,166398,12912831,233.91,234.0,100,2,1,1,233.8,234.07,5,400,1,2,233.79,234.08,200,26,1,1,233.73,234.1,29,100,1,1,233.7,234.13,1200,400,1,1,233.66,234.17,1,1,1,1,233.58,234.25,505,100,2,1,233.53,234.41,10,500,1,1,233.5,234.43,100,105,1,2,233.45,234.5,15,63,1,4,AAPL,0.0,0.0,0.0,
2024-10-21 12:22:40.428425309+00:00,2024-10-21T12:22:40.428593628Z,10,2,38,T,N,0,233.92,100,0,168319,12916971,233.91,234.0,100,2,1,1,233.8,234.07,5,400,1,2,233.79,234.08,200,26,1,1,233.73,234.1,29,100,1,1,233.7,234.13,1200,400,1,1,233.66,234.17,1,1,1,1,233.58,234.25,505,100,2,1,233.53,234.41,10,500,1,1,233.5,234.43,100,105,1,2,233.45,234.5,15,63,1,4,AAPL,0.0,0.0,0.0,
2024-10-21 12:22:40.428425309+00:00,2024-10-21T12:22:40.428593628Z,10,2,38,T,N,0,233.92,40,130,168319,12916972,233.91,234.0,100,2,1,1,233.8,234.07,5,400,1,2,233.79,234.08,200,26,1,1,233.73,234.1,29,100,1,1,233.7,234.13,1200,400,1,1,233.66,234.17,1,1,1,1,233.58,234.25,505,100,2,1,233.53,234.41,10,500,1,1,233.5,234.43,100,105,1,2,233.45,234.5,15,63,1,4,AAPL,0.0,0.0,0.0,
2024-10-21 12:23:09.008613373+00:00,2024-10-21T12:23:09.008779869Z,10,2,38,A,B,0,233.93,4,130,166496,12947436,233.93,234.0,4,2,1,1,233.91,234.07,100,400,1,2,233.8,234.08,5,26,1,1,233.79,234.1,200,100,1,1,233.73,234.13,29,400,1,1,233.7,234.17,1200,1,1,1,233.66,234.25,1,100,1,1,233.58,234.41,505,500,2,1,233.53,234.43,10,105,1,2,233.5,234.5,100,63,1,4,AAPL,0.0,0.0,0.0,
2024-10-21 12:23:09.008621599+00:00,2024-10-21T12:23:09.008787962Z,10,2,38,A,B,1,233.92,100,130,166363,12947438,233.93,234.0,4,2,1,1,233.92,234.07,100,400,1,2,233.91,234.08,100,26,1,1,233.8,234.1,5,100,1,1,233.79,234.13,200,400,1,1,233.73,234.17,29,1,1,1,233.7,234.25,1200,100,1,1,233.66,234.41,1,500,1,1,233.58,234.43,505,105,2,2,233.53,234.5,10,63,1,4,AAPL,0.0,0.0,0.0,
2024-10-21 12:23:09.008973422+00:00,2024-10-21T12:23:09.009139279Z,10,2,38,C,B,1,233.92,100,130,165857,12947440,233.93,234.0,4,2,1,1,233.91,234.07,100,400,1,2,233.8,234.08,5,26,1,1,233.79,234.1,200,100,1,1,233.73,234.13,29,400,1,1,233.7,234.17,1200,1,1,1,233.66,234.25,1,100,1,1,233.58,234.41,505,500,2,1,233.53,234.43,10,105,1,2,233.5,234.5,100,63,1,4,AAPL,0.0,0.0,0.0,
2024-10-21 12:23:09.009065871+00:00,2024-10-21T12:23:09.009232105Z,10,2,38,A,B,0,233.95,723,130,166234,12947441,233.95,234.0,723,2,1,1,233.93,234.07,4,400,1,2,233.91,234.08,100,26,1,1,233.8,234.1,5,100,1,1,233.79,234.13,200,400,1,1,233.73,234.17,29,1,1,1,233.7,234.25,1200,100,1,1,233.66,234.41,1,500,1,1,233.58,234.43,505,105,2,2,233.53,234.5,10,63,1,4,AAPL,0.0,0.0,0.0,
2024-10-21 12:23:09.047049975+00:00,2024-10-21T12:23:09.047215822Z,10,2,38,C,B,1,233.93,4,130,165847,12947464,233.95,234.0,723,2,1,1,233.91,234.07,100,400,1,2,233.8,234.08,5,26,1,1,233.79,234.1,200,100,1,1,233.73,234.13,29,400,1,1,233.7,234.17,1200,1,1,1,233.66,234.25,1,100,1,1,233.58,234.41,505,500,2,1,233.53,234.43,10,105,1,2,233.5,234.5,100,63,1,4,AAPL,0.0,0.0,0.0,
2024-10-21 12:23:09.047528450+00:00,2024-10-21T12:23:09.047694600Z,10,2,38,C,B,1,233.91,100,130,166150,12947466,233.95,234.0,723,2,1,1,233.8,234.07,5,400,1,2,233.79,234.08,200,26,1,1,233.73,234.1,29,100,1,1,233.7,234.13,1200,400,1,1,233.66,234.17,1,1,1,1,233.58,234.25,505,100,2,1,233.53,234.41,10,500,1,1,233.5,234.43,100,105,1,2,233.45,234.5,15,63,1,4,AAPL,0.0,0.0,0.0,
2024-10-21 12:23:09.079779485+00:00,2024-10-21T12:23:09.079945758Z,10,2,38,C,A,1,234.07,200,130,166273,12947479,233.95,234.0,723,2,1,1,233.8,234.07,5,200,1,1,233.79,234.08,200,26,1,1,233.73,234.1,29,100,1,1,233.7,234.13,1200,400,1,1,233.66,234.17,1,1,1,1,233.58,234.25,505,100,2,1,233.53,234.41,10,500,1,1,233.5,234.43,100,105,1,2,233.45,234.5,15,63,1,4,AAPL,0.0,200.0,0.0,
2024-10-21 12:23:09.081699019+00:00,2024-10-21T12:23:09.081865026Z,10,2,38,A,B,2,233.79,200,130,166007,12947480,233.95,234.0,723,2,1,1,233.8,234.07,5,200,1,1,233.79,234.08,400,26,2,1,233.73,234.1,29,100,1,1,233.7,234.13,1200,400,1,1,233.66,234.17,1,1,1,1,233.58,234.25,505,100,2,1,233.53,234.41,10,500,1,1,233.5,234.43,100,105,1,2,233.45,234.5,15,63,1,4,AAPL,0.0,200.0,0.0,
2024-10-21 12:23:09.087775155+00:00,2024-10-21T12:23:09.087941406Z,10,2,38,C,B,2,233.79,200,130,166251,12947484,233.95,234.0,723,2,1,1,233.8,234.07,5,200,1,1,233.79,234.08,200,26,1,1,233.73,234.1,29,100,1,1,233.7,234.13,1200,400,1,1,233.66,234.17,1,1,1,1,233.58,234.25,505,100,2,1,233.53,234.41,10,500,1,1,233.5,234.43,100,105,1,2,233.45,234.5,15,63,1,4,AAPL,0.0,-200.0,0.0,
2024-10-21 12:23:09.087785825+00:00,2024-10-21T12:23:09.087951571Z,10,2,38,C,B,2,233.79,200,130,165746,12947485,233.95,234.0,723,2,1,1,233.8,234.07,5,200,1,1,233.73,234.08,29,26,1,1,233.7,234.1,1200,100,1,1,233.66,234.13,1,400,1,1,233.58,234.17,505,1,2,1,233.53,234.25,10,100,1,1,233.5,234.41,100,500,1,1,233.45,234.43,15,105,1,2,233.4,234.5,110,63,2,4,AAPL,0.0,0.0,0.0,
2024-10-21 12:23:09.087797026+00:00,2024-10-21T12:23:09.087963244Z,10,2,38,A,B,2,233.78,200,130,166218,12947486,233.95,234.0,723,2,1,1,233.8,234.07,5,200,1,1,233.78,234.08,200,26,1,1,233.73,234.1,29,100,1,1,233.7,234.13,1200,400,1,1,233.66,234.17,1,1,1,1,233.58,234.25,505,100,2,1,233.53,234.41,10,500,1,1,233.5,234.43,100,105,1,2,233.45,234.5,15,63,1,4,AAPL,0.0,0.0,0.0,
2024-10-21 12:23:09.133329159+00:00,2024-10-21T12:23:09.133495750Z,10,2,38,A,B,2,233.79,200,130,166591,12947507,233.95,234.0,723,2,1,1,233.8,234.07,5,200,1,1,233.79,234.08,200,26,1,1,233.73,234.1,29,100,1,1,233.7,234.13,1200,400,1,1,233.66,234.17,1,1,1,1,233.58,234.25,505,100,2,1,233.53,234.41,10,500,1,1,233.5,234.43,100,105,1,2,233.45,234.5,15,63,1,4,AAPL,0.0,0.0,0.0,
2024-10-21 12:23:09.155634175+00:00,2024-10-21T12:23:09.155801329Z,10,2,38,C,B,3,233.73,29,130,167154,12947520,233.95,234.0,723,2,1,1,233.8,234.07,5,200,1,1,233.79,234.08,200,26,1,1,233.7,234.1,1200,100,1,1,233.66,234.13,1,400,1,1,233.58,234.17,505,1,2,1,233.53,234.25,10,100,1,1,233.5,234.41,100,500,1,1,233.45,234.43,15,105,1,2,233.4,234.5,110,63,2,4,AAPL,0.0,0.0,0.0,
2024-10-21 12:23:09.155732424+00:00,2024-10-21T12:23:09.155898909Z,10,2,38,A,B,3,233.77,26,130,166485,12947521,233.95,234.0,723,2,1,1,233.8,234.07,5,200,1,1,233.79,234.08,200,26,1,1,233.77,234.1,26,100,1,1,233.7,234.13,1200,400,1,1,233.66,234.17,1,1,1,1,233.58,234.25,505,100,2,1,233.53,234.41,10,500,1,1,233.5,234.43,100,105,1,2,233.45,234.5,15,63,1,4,AAPL,0.0,0.0,0.0,
2024-10-21 12:23:09.242822823+00:00,2024-10-21T12:23:09.242988929Z,10,2,38,C,A,2,234.08,26,130,166106,12947586,233.95,234.0,723,2,1,1,233.8,234.07,5,200,1,1,233.79,234.1,200,100,1,1,233.77,234.13,26,400,1,1,233.7,234.17,1200,1,1,1,233.66,234.25,1,100,1,1,233.58,234.41,505,500,2,1,233.53,234.43,10,105,1,2,233.5,234.5,100,63,1,4,233.45,234.75,15,1,1,1,AAPL,0.0,0.0,0.0,
2024-10-21 12:23:09.242876186+00:00,2024-10-21T12:23:09.243042523Z,10,2,38,A,A,4,234.14,29,130,166337,12947587,233.95,234.0,723,2,1,1,233.8,234.07,5,200,1,1,233.79,234.1,200,100,1,1,233.77,234.13,26,400,1,1,233.7,234.14,1200,29,1,1,233.66,234.17,1,1,1,1,233.58,234.25,505,100,2,1,233.53,234.41,10,500,1,1,233.5,234.43,100,105,1,2,233.45,234.5,15,63,1,4,AAPL,0.0,0.0,0.0,
2024-10-21 12:23:09.312635376+00:00,2024-10-21T12:23:09.312801998Z,10,2,38,A,B,1,233.81,200,130,166622,12947706,233.95,234.0,723,2,1,1,233.81,234.07,200,200,1,1,233.8,234.1,5,100,1,1,233.77,234.13,26,400,1,1,233.7,234.14,1200,29,1,1,233.66,234.17,1,1,1,1,233.58,234.25,505,100,2,1,233.53,234.41,10,500,1,1,233.5,234.43,100,105,1,2,233.45,234.5,15,63,1,4,AAPL,0.0,0.0,0.0,
2024-10-21 12:23:09.319468618+00:00,2024-10-21T12:23:09.319634626Z,10,2,38,A,A,1,234.07,200,130,166008,12947710,233.95,234.0,723,2,1,1,233.81,234.07,200,400,1,2,233.8,234.1,5,100,1,1,233.77,234.13,26,400,1,1,233.7,234.14,1200,29,1,1,233.66,234.17,1,1,1,1,233.58,234.25,505,100,2,1,233.53,234.41,10,500,1,1,233.5,234.43,100,105,1,2,233.45,234.5,15,63,1,4,AAPL,0.0,-200.0,0.0,
2024-10-21 12:23:09.729465211+00:00,2024-10-21T12:23:09.729631282Z,10,2,38,C,A,1,234.07,200,130,166071,12947991,233.95,234.0,723,2,1,1,233.81,234.07,200,200,1,1,233.8,234.1,5,100,1,1,233.77,234.13,26,400,1,1,233.7,234.14,1200,29,1,1,233.66,234.17,1,1,1,1,233.58,234.25,505,100,2,1,233.53,234.41,10,500,1,1,233.5,234.43,100,105,1,2,233.45,234.5,15,63,1,4,AAPL,0.0,200.0,0.0,
2024-10-21 12:23:09.784075201+00:00,2024-10-21T12:23:09.784241575Z,10,2,38,A,B,1,233.82,200,130,166374,12948038,233.95,234.0,723,2,1,1,233.82,234.07,200,200,1,1,233.8,234.1,5,100,1,1,233.77,234.13,26,400,1,1,233.7,234.14,1200,29,1,1,233.66,234.17,1,1,1,1,233.58,234.25,505,100,2,1,233.53,234.41,10,500,1,1,233.5,234.43,100,105,1,2,233.45,234.5,15,63,1,4,AAPL,0.0,0.0,0.0,
2024-10-21 12:23:11.099071185+00:00,2024-10-21T12:23:11.099239175Z,10,2,38,T,A,0,233.95,200,130,167990,12949099,233.95,234.0,723,2,1,1,233.82,234.07,200,200,1,1,233.8,234.1,5,100,1,1,233.77,234.13,26,400,1,1,233.7,234.14,1200,29,1,1,233.66,234.17,1,1,1,1,233.58,234.25,505,100,2,1,233.53,234.41,10,500,1,1,233.5,234.43,100,105,1,2,233.45,234.5,15,63,1,4,AAPL,0.0,0.0,0.0,
2024-10-21 12:23:11.099071185+00:00,2024-10-21T12:23:11.099239175Z,10,2,38,C,B,0,233.95,200,130,167990,12949099,233.95,234.0,523,2,1,1,233.82,234.07,200,200,1,1,233.8,234.1,5,100,1,1,233.77,234.13,26,400,1,1,233.7,234.14,1200,29,1,1,233.66,234.17,1,1,1,1,233.58,234.25,505,100,2,1,233.53,234.41,10,500,1,1,233.5,234.43,100,105,1,2,233.45,234.5,15,63,1,4,AAPL,-200.0,-200.0,-200.0,
2024-10-21 12:23:11.099138993+00:00,2024-10-21T12:23:11.099304941Z,10,2,38,C,B,1,233.82,200,130,165948,12949100,233.95,234.0,523,2,1,1,233.8,234.07,5,200,1,1,233.77,234.1,26,100,1,1,233.7,234.13,1200,400,1,1,233.66,234.14,1,29,1,1,233.58,234.17,505,1,2,1,233.53,234.25,10,100,1,1,233.5,234.41,100,500,1,1,233.45,234.43,15,105,1,2,233.4,234.5,110,63,2,4,AAPL,0.0,0.0,-200.0,
2024-10-21 12:23:11.171874633+00:00,2024-10-21T12:23:11.172041039Z,10,2,38,A,A,1,234.07,200,130,166406,12949158,233.95,234.0,523,2,1,1,233.8,234.07,5,400,1,2,233.77,234.1,26,100,1,1,233.7,234.13,1200,400,1,1,233.66,234.14,1,29,1,1,233.58,234.17,505,1,2,1,233.53,234.25,10,100,1,1,233.5,234.41,100,500,1,1,233.45,234.43,15,105,1,2,233.4,234.5,110,63,2,4,AAPL,0.0,-200.0,-200.0,
2024-10-21 12:23:11.208162821+00:00,2024-10-21T12:23:11.208329414Z,10,2,38,A,B,1,233.82,200,130,166593,12949167,233.95,234.0,523,2,1,1,233.82,234.07,200,400,1,2,233.8,234.1,5,100,1,1,233.77,234.13,26,400,1,1,233.7,234.14,1200,29,1,1,233.66,234.17,1,1,1,1,233.58,234.25,505,100,2,1,233.53,234.41,10,500,1,1,233.5,234.43,100,105,1,2,233.45,234.5,15,63,1,4,AAPL,0.0,0.0,-200.0,
2024-10-21 12:23:12.139603042+00:00,2024-10-21T12:23:12.139769418Z,10,2,38,A,B,1,233.84,200,130,166376,12950444,233.95,234.0,523,2,1,1,233.84,234.07,200,400,1,2,233.8,234.1,5,100,1,1,233.77,234.13,26,400,1,1,233.7,234.14,1200,29,1,1,233.66,234.17,1,1,1,1,233.58,234.25,505,100,2,1,233.53,234.41,10,500,1,1,233.5,234.43,100,105,1,2,233.45,234.5,15,63,1,4,AAPL,0.0,0.0,0.0,
2024-10-21 12:23:12.190123660+00:00,2024-10-21T12:23:12.190290255Z,10,2,38,C,A,4,234.14,29,130,166595,12950624,233.95,234.0,523,2,1,1,233.84,234.07,200,400,1,2,233.8,234.1,5,100,1,1,233.77,234.13,26,400,1,1,233.7,234.17,1200,1,1,1,233.66,234.25,1,100,1,1,233.58,234.41,505,500,2,1,233.53,234.43,10,105,1,2,233.5,234.5,100,63,1,4,233.45,234.75,15,1,1,1,AAPL,0.0,0.0,0.0,
2024-10-21 12:23:12.190244811+00:00,2024-10-21T12:23:12.190410859Z,10,2,38,A,A,2,234.09,28,130,166048,12950625,233.95,234.0,523,2,1,1,233.84,234.07,200,400,1,2,233.8,234.09,5,28,1,1,233.77,234.1,26,100,1,1,233.7,234.13,1200,400,1,1,233.66,234.17,1,1,1,1,233.58,234.25,505,100,2,1,233.53,234.41,10,500,1,1,233.5,234.43,100,105,1,2,233.45,234.5,15,63,1,4,AAPL,0.0,0.0,0.0,
2024-10-21 12:23:12.195254017+00:00,2024-10-21T12:23:12.195419708Z,10,2,38,C,A,2,234.09,28,130,165691,12950641,233.95,234.0,523,2,1,1,233.84,234.07,200,400,1,2,233.8,234.1,5,100,1,1,233.77,234.13,26,400,1,1,233.7,234.17,1200,1,1,1,233.66,234.25,1,100,1,1,233.58,234.41,505,500,2,1,233.53,234.43,10,105,1,2,233.5,234.5,100,63,1,4,233.45,234.75,15,1,1,1,AAPL,0.0,0.0,0.0,
2024-10-21 12:23:13.923503589+00:00,2024-10-21T12:23:13.923669862Z,10,2,38,A,A,4,234.14,27,130,166273,12952557,233.95,234.0,523,2,1,1,233.84,234.07,200,400,1,2,233.8,234.1,5,100,1,1,233.77,234.13,26,400,1,1,233.7,234.14,1200,27,1,1,233.66,234.17,1,1,1,1,233.58,234.25,505,100,2,1,233.53,234.41,10,500,1,1,233.5,234.43,100,105,1,2,233.45,234.5,15,63,1,4,AAPL,0.0,0.0,0.0,
2024-10-21 12:23:14.014125157+00:00,2024-10-21T12:23:14.014291143Z,10,2,38,C,B,1,233.84,200,130,165986,12953020,233.95,234.0,523,2,1,1,233.8,234.07,5,400,1,2,233.77,234.1,26,100,1,1,233.7,234.13,1200,400,1,1,233.66,234.14,1,27,1,1,233.58,234.17,505,1,2,1,233.53,234.25,10,100,1,1,233.5,234.41,100,500,1,1,233.45,234.43,15,105,1,2,233.4,234.5,110,63,2,4,AAPL,0.0,0.0,0.0,
2024-10-21 12:23:14.014138266+00:00,2024-10-21T12:23:14.014304377Z,10,2,38,A,B,1,233.8,400,130,166111,12953021,233.95,234.0,523,2,1,1,233.8,234.07,405,400,2,2,233.77,234.1,26,100,1,1,233.7,234.13,1200,400,1,1,233.66,234.14,1,27,1,1,233.58,234.17,505,1,2,1,233.53,234.25,10,100,1,1,233.5,234.41,100,500,1,1,233.45,234.43,15,105,1,2,233.4,234.5,110,63,2,4,AAPL,0.0,400.0,0.0,
2024-10-21 12:23:24.180057341+00:00,2024-10-21T12:23:24.180223668Z,10,2,38,A,B,1,233.84,200,130,166327,12963680,233.95,234.0,523,2,1,1,233.84,234.07,200,400,1,2,233.8,234.1,5,100,1,1,233.77,234.13,26,400,1,1,233.7,234.14,1200,27,1,1,233.66,234.17,1,1,1,1,233.58,234.25,505,100,2,1,233.53,234.41,10,500,1,1,233.5,234.43,100,105,1,2,233.45,234.5,15,63,1,4,AAPL,0.0,0.0,0.0,
2024-10-21 12:23:24.244388472+00:00,2024-10-21T12:23:24.244554625Z,10,2,38,C,B,3,233.77,26,130,166153,12963842,233.95,234.0,523,2,1,1,233.84,234.07,200,400,1,2,233.8,234.1,5,100,1,1,233.7,234.13,1200,400,1,1,233.66,234.14,1,27,1,1,233.58,234.17,505,1,2,1,233.53,234.25,10,100,1,1,233.5,234.41,100,500,1,1,233.45,234.43,15,105,1,2,233.4,234.5,110,63,2,4,AAPL,0.0,0.0,0.0,
2024-10-21 12:23:24.244727755+00:00,2024-10-21T12:23:24.244894113Z,10,2,38,A,B,3,233.78,29,130,166358,12963846,233.95,234.0,523,2,1,1,233.84,234.07,200,400,1,2,233.8,234.1,5,100,1,1,233.78,234.13,29,400,1,1,233.7,234.14,1200,27,1,1,233.66,234.17,1,1,1,1,233.58,234.25,505,100,2,1,233.53,234.41,10,500,1,1,233.5,234.43,100,105,1,2,233.45,234.5,15,63,1,4,AAPL,0.0,0.0,0.0,
2024-10-21 12:23:24.253824768+00:00,2024-10-21T12:23:24.253991498Z,10,2,38,A,B,1,233.85,200,130,166730,12963873,233.95,234.0,523,2,1,1,233.85,234.07,200,400,1,2,233.8,234.1,5,100,1,1,233.78,234.13,29,400,1,1,233.7,234.14,1200,27,1,1,233.66,234.17,1,1,1,1,233.58,234.25,505,100,2,1,233.53,234.41,10,500,1,1,233.5,234.43,100,105,1,2,233.45,234.5,15,63,1,4,AAPL,0.0,0.0,0.0,
2024-10-21 12:23:24.273148439+00:00,2024-10-21T12:23:24.273314409Z,10,2,38,C,A,4,234.14,27,130,165970,12963906,233.95,234.0,523,2,1,1,233.85,234.07,200,400,1,2,233.8,234.1,5,100,1,1,233.78,234.13,29,400,1,1,233.7,234.17,1200,1,1,1,233.66,234.25,1,100,1,1,233.58,234.41,505,500,2,1,233.53,234.43,10,105,1,2,233.5,234.5,100,63,1,4,233.45,234.75,15,1,1,1,AAPL,0.0,0.0,0.0,
2024-10-21 12:23:24.273199301+00:00,2024-10-21T12:23:24.273365393Z,10,2,38,A,A,2,234.09,30,130,166092,12963907,233.95,234.0,523,2,1,1,233.85,234.07,200,400,1,2,233.8,234.09,5,30,1,1,233.78,234.1,29,100,1,1,233.7,234.13,1200,400,1,1,233.66,234.17,1,1,1,1,233.58,234.25,505,100,2,1,233.53,234.41,10,500,1,1,233.5,234.43,100,105,1,2,233.45,234.5,15,63,1,4,AAPL,0.0,0.0,0.0,
2024-10-21 12:23:24.281024032+00:00,2024-10-21T12:23:24.281190133Z,10,2,38,C,A,2,234.09,30,130,166101,12963913,233.95,234.0,523,2,1,1,233.85,234.07,200,400,1,2,233.8,234.1,5,100,1,1,233.78,234.13,29,400,1,1,233.7,234.17,1200,1,1,1,233.66,234.25,1,100,1,1,233.58,234.41,505,500,2,1,233.53,234.43,10,105,1,2,233.5,234.5,100,63,1,4,233.45,234.75,15,1,1,1,AAPL,0.0,0.0,0.0,
2024-10-21 12:23:25.922987113+00:00,2024-10-21T12:23:25.923153392Z,10,2,38,A,A,4,234.15,29,130,166279,12965330,233.95,234.0,523,2,1,1,233.85,234.07,200,400,1,2,233.8,234.1,5,100,1,1,233.78,234.13,29,400,1,1,233.7,234.15,1200,29,1,1,233.66,234.17,1,1,1,1,233.58,234.25,505,100,2,1,233.53,234.41,10,500,1,1,233.5,234.43,100,105,1,2,233.45,234.5,15,63,1,4,AAPL,0.0,0.0,0.0,
2024-10-21 12:23:26.667483730+00:00,2024-10-21T12:23:26.667650199Z,10,2,38,C,A,4,234.15,29,130,166469,12965993,233.95,234.0,523,2,1,1,233.85,234.07,200,400,1,2,233.8,234.1,5,100,1,1,233.78,234.13,29,400,1,1,233.7,234.17,1200,1,1,1,233.66,234.25,1,100,1,1,233.58,234.41,505,500,2,1,233.53,234.43,10,105,1,2,233.5,234.5,100,63,1,4,233.45,234.75,15,1,1,1,AAPL,0.0,0.0,0.0,
2024-10-21 12:23:26.667566801+00:00,2024-10-21T12:23:26.667733223Z,10,2,38,A,A,2,234.09,26,130,166422,12965994,233.95,234.0,523,2,1,1,233.85,234.07,200,400,1,2,233.8,234.09,5,26,1,1,233.78,234.1,29,100,1,1,233.7,234.13,1200,400,1,1,233.66,234.17,1,1,1,1,233.58,234.25,505,100,2,1,233.53,234.41,10,500,1,1,233.5,234.43,100,105,1,2,233.45,234.5,15,63,1,4,AAPL,0.0,0.0,0.0,
2024-10-21 12:23:26.671669972+00:00,2024-10-21T12:23:26.671836031Z,10,2,38,C,A,2,234.09,26,130,166059,12965998,233.95,234.0,523,2,1,1,233.85,234.07,200,400,1,2,233.8,234.1,5,100,1,1,233.78,234.13,29,400,1,1,233.7,234.17,1200,1,1,1,233.66,234.25,1,100,1,1,233.58,234.41,505,500,2,1,233.53,234.43,10,105,1,2,233.5,234.5,100,63,1,4,233.45,234.75,15,1,1,1,AAPL,0.0,0.0,0.0,
2024-10-21 12:23:29.923042073+00:00,2024-10-21T12:23:29.923208530Z,10,2,38,A,A,4,234.15,26,130,166457,12968315,233.95,234.0,523,2,1,1,233.85,234.07,200,400,1,2,233.8,234.1,5,100,1,1,233.78,234.13,29,400,1,1,233.7,234.15,1200,26,1,1,233.66,234.17,1,1,1,1,233.58,234.25,505,100,2,1,233.53,234.41,10,500,1,1,233.5,234.43,100,105,1,2,233.45,234.5,15,63,1,4,AAPL,0.0,0.0,0.0,
2024-10-21 12:23:31.049271170+00:00,2024-10-21T12:23:31.049437219Z,10,2,38,C,B,1,233.85,200,130,166049,12969394,233.95,234.0,523,2,1,1,233.8,234.07,5,400,1,2,233.78,234.1,29,100,1,1,233.7,234.13,1200,400,1,1,233.66,234.15,1,26,1,1,233.58,234.17,505,1,2,1,233.53,234.25,10,100,1,1,233.5,234.41,100,500,1,1,233.45,234.43,15,105,1,2,233.4,234.5,110,63,2,4,AAPL,0.0,0.0,0.0,
2024-10-21 12:23:31.049283153+00:00,2024-10-21T12:23:31.049449290Z,10,2,38,A,B,1,233.83,200,130,166137,12969395,233.95,234.0,523,2,1,1,233.83,234.07,200,400,1,2,233.8,234.1,5,100,1,1,233.78,234.13,29,400,1,1,233.7,234.15,1200,26,1,1,233.66,234.17,1,1,1,1,233.58,234.25,505,100,2,1,233.53,234.41,10,500,1,1,233.5,234.43,100,105,1,2,233.45,234.5,15,63,1,4,AAPL,0.0,0.0,0.0,
2024-10-21 12:23:31.105200821+00:00,2024-10-21T12:23:31.105367441Z,10,2,38,A,B,1,233.84,200,130,166620,12969432,233.95,234.0,523,2,1,1,233.84,234.07,200,400,1,2,233.8,234.1,5,100,1,1,233.78,234.13,29,400,1,1,233.7,234.15,1200,26,1,1,233.66,234.17,1,1,1,1,233.58,234.25,505,100,2,1,233.53,234.41,10,500,1,1,233.5,234.43,100,105,1,2,233.45,234.5,15,63,1,4,AAPL,0.0,0.0,0.0,
2024-10-21 12:23:33.817825903+00:00,2024-10-21T12:23:33.817991958Z,10,2,38,C,B,1,233.84,200,130,166055,12972883,233.95,234.0,523,2,1,1,233.8,234.07,5,400,1,2,233.78,234.1,29,100,1,1,233.7,234.13,1200,400,1,1,233.66,234.15,1,26,1,1,233.58,234.17,505,1,2,1,233.53,234.25,10,100,1,1,233.5,234.41,100,500,1,1,233.45,234.43,15,105,1,2,233.4,234.5,110,63,2,4,AAPL,0.0,0.0,0.0,
2024-10-21 12:23:33.817837243+00:00,2024-10-21T12:23:33.818003417Z,10,2,38,A,B,1,233.8,400,130,166174,12972884,233.95,234.0,523,2,1,1,233.8,234.07,405,400,2,2,233.78,234.1,29,100,1,1,233.7,234.13,1200,400,1,1,233.66,234.15,1,26,1,1,233.58,234.17,505,1,2,1,233.53,234.25,10,100,1,1,233.5,234.41,100,500,1,1,233.45,234.43,15,105,1,2,233.4,234.5,110,63,2,4,AAPL,0.0,400.0,0.0,
2024-10-21 12:23:34.381673108+00:00,2024-10-21T12:23:34.381839108Z,10,2,38,C,A,4,234.15,26,130,166000,12973267,233.95,234.0,523,2,1,1,233.8,234.07,405,400,2,2,233.78,234.1,29,100,1,1,233.7,234.13,1200,400,1,1,233.66,234.17,1,1,1,1,233.58,234.25,505,100,2,1,233.53,234.41,10,500,1,1,233.5,234.43,100,105,1,2,233.45,234.5,15,63,1,4,233.4,234.75,110,1,2,1,AAPL,0.0,0.0,0.0,
2024-10-21 12:23:34.381786514+00:00,2024-10-21T12:23:34.381954269Z,10,2,38,A,A,4,234.14,27,130,167755,12973268,233.95,234.0,523,2,1,1,233.8,234.07,405,400,2,2,233.78,234.1,29,100,1,1,233.7,234.13,1200,400,1,1,233.66,234.14,1,27,1,1,233.58,234.17,505,1,2,1,233.53,234.25,10,100,1,1,233.5,234.41,100,500,1,1,233.45,234.43,15,105,1,2,233.4,234.5,110,63,2,4,AAPL,0.0,0.0,0.0,
2024-10-21 12:23:35.765078516+00:00,2024-10-21T12:23:35.765246828Z,10,2,38,T,A,0,233.95,100,130,168312,12974800,233.95,234.0,523,2,1,1,233.8,234.07,405,400,2,2,233.78,234.1,29,100,1,1,233.7,234.13,1200,400,1,1,233.66,234.14,1,27,1,1,233.58,234.17,505,1,2,1,233.53,234.25,10,100,1,1,233.5,234.41,100,500,1,1,233.45,234.43,15,105,1,2,233.4,234.5,110,63,2,4,AAPL,0.0,0.0,0.0,
2024-10-21 12:23:35.765078516+00:00,2024-10-21T12:23:35.765246828Z,10,2,38,C,B,0,233.95,100,130,168312,12974800,233.95,234.0,423,2,1,1,233.8,234.07,405,400,2,2,233.78,234.1,29,100,1,1,233.7,234.13,1200,400,1,1,233.66,234.14,1,27,1,1,233.58,234.17,505,1,2,1,233.53,234.25,10,100,1,1,233.5,234.41,100,500,1,1,233.45,234.43,15,105,1,2,233.4,234.5,110,63,2,4,AAPL,-100.0,-100.0,-100.0,
2024-10-21 12:23:35.765293055+00:00,2024-10-21T12:23:35.765460271Z,10,2,38,T,A,0,233.95,423,130,167216,12974807,233.95,234.0,423,2,1,1,233.8,234.07,405,400,2,2,233.78,234.1,29,100,1,1,233.7,234.13,1200,400,1,1,233.66,234.14,1,27,1,1,233.58,234.17,505,1,2,1,233.53,234.25,10,100,1,1,233.5,234.41,100,500,1,1,233.45,234.43,15,105,1,2,233.4,234.5,110,63,2,4,AAPL,0.0,0.0,-100.0,
2024-10-21 12:23:35.765293055+00:00,2024-10-21T12:23:35.765460271Z,10,2,38,C,B,0,233.95,423,130,167216,12974807,233.8,234.0,405,2,2,1,233.78,234.07,29,400,1,2,233.7,234.1,1200,100,1,1,233.66,234.13,1,400,1,1,233.58,234.14,505,27,2,1,233.53,234.17,10,1,1,1,233.5,234.25,100,100,1,1,233.45,234.41,15,500,1,1,233.4,234.43,110,105,2,2,233.39,234.5,10,63,1,4,AAPL,0.0,0.0,-100.0,
2024-10-21 12:23:35.765317844+00:00,2024-10-21T12:23:35.765484464Z,10,2,38,A,A,0,233.98,24,130,166620,12974809,233.8,233.98,405,124,2,2,233.78,234.0,29,2,1,1,233.7,234.07,1200,400,1,2,233.66,234.1,1,100,1,1,233.58,234.13,505,400,2,1,233.53,234.14,10,27,1,1,233.5,234.17,100,1,1,1,233.45,234.25,15,100,1,1,233.4,234.41,110,500,2,1,233.39,234.43,10,105,1,2,AAPL,0.0,0.0,-100.0,
2024-10-21 12:23:35.765319866+00:00,2024-10-21T12:23:35.765485889Z,10,2,38,A,A,1,233.99,100,130,166023,12974810,233.8,233.98,405,124,2,2,233.78,233.99,29,100,1,1,233.7,234.0,1200,2,1,1,233.66,234.07,1,400,1,2,233.58,234.1,505,100,2,1,233.53,234.13,10,400,1,1,233.5,234.14,100,27,1,1,233.45,234.17,15,1,1,1,233.4,234.25,110,100,2,1,233.39,234.41,10,500,1,1,AAPL,0.0,0.0,-100.0,
2024-10-21 12:23:35.765327695+00:00,2024-10-21T12:23:35.765493677Z,10,2,38,A,A,1,233.99,100,130,165982,12974811,233.8,233.98,405,124,2,2,233.78,233.99,29,200,1,2,233.7,234.0,1200,2,1,1,233.66,234.07,1,400,1,2,233.58,234.1,505,100,2,1,233.53,234.13,10,400,1,1,233.5,234.14,100,27,1,1,233.45,234.17,15,1,1,1,233.4,234.25,110,100,2,1,233.39,234.41,10,500,1,1,AAPL,0.0,-100.0,-100.0,
2024-10-21 12:23:35.765330068+00:00,2024-10-21T12:23:35.765497059Z,10,2,38,A,A,1,233.99,100,130,166991,12974812,233.8,233.98,405,124,2,2,233.78,233.99,29,300,1,3,233.7,234.0,1200,2,1,1,233.66,234.07,1,400,1,2,233.58,234.1,505,100,2,1,233.53,234.13,10,400,1,1,233.5,234.14,100,27,1,1,233.45,234.17,15,1,1,1,233.4,234.25,110,100,2,1,233.39,234.41,10,500,1,1,AAPL,0.0,-100.0,-100.0,
2024-10-21 12:23:35.765336405+00:00,2024-10-21T12:23:35.765503864Z,10,2,38,A,A,1,233.99,38,130,167459,12974813,233.8,233.98,405,124,2,2,233.78,233.99,29,338,1,4,233.7,234.0,1200,2,1,1,233.66,234.07,1,400,1,2,233.58,234.1,505,100,2,1,233.53,234.13,10,400,1,1,233.5,234.14,100,27,1,1,233.45,234.17,15,1,1,1,233.4,234.25,110,100,2,1,233.39,234.41,10,500,1,1,AAPL,0.0,-38.0,-100.0,
2024-10-21 12:23:35.765353728+00:00,2024-10-21T12:23:35.765520554Z,10,2,38,C,A,1,233.99,100,130,166826,12974817,233.8,233.98,405,124,2,2,233.78,233.99,29,238,1,3,233.7,234.0,1200,2,1,1,233.66,234.07,1,400,1,2,233.58,234.1,505,100,2,1,233.53,234.13,10,400,1,1,233.5,234.14,100,27,1,1,233.45,234.17,15,1,1,1,233.4,234.25,110,100,2,1,233.39,234.41,10,500,1,1,AAPL,0.0,100.0,-100.0,
2024-10-21 12:23:35.765358258+00:00,2024-10-21T12:23:35.765523939Z,10,2,38,C,N,0,233.8,400,130,165681,12974819,233.8,233.98,5,24,1,1,233.78,233.99,29,238,1,3,233.7,234.0,1200,2,1,1,233.66,234.07,1,400,1,2,233.58,234.1,505,100,2,1,233.53,234.13,10,400,1,1,233.5,234.14,100,27,1,1,233.45,234.17,15,1,1,1,233.4,234.25,110,100,2,1,233.39,234.41,10,500,1,1,AAPL,-300.0,-300.0,-400.0,
2024-10-21 12:23:35.765377342+00:00,2024-10-21T12:23:35.765545765Z,10,2,38,C,A,1,233.99,100,128,168423,12974821,233.8,233.98,5,24,1,1,233.78,233.99,29,138,1,2,233.7,234.0,1200,2,1,1,233.66,234.07,1,400,1,2,233.58,234.1,505,100,2,1,233.53,234.13,10,400,1,1,233.5,234.14,100,27,1,1,233.45,234.17,15,1,1,1,233.4,234.25,110,100,2,1,233.39,234.41,10,500,1,1,AAPL,0.0,100.0,-400.0,
2024-10-21 12:23:35.765712149+00:00,2024-10-21T12:23:35.765878037Z,10,2,38,C,A,1,233.99,100,130,165888,12974836,233.8,233.98,5,24,1,1,233.78,233.99,29,38,1,1,233.7,234.0,1200,2,1,1,233.66,234.07,1,400,1,2,233.58,234.1,505,100,2,1,233.53,234.13,10,400,1,1,233.5,234.14,100,27,1,1,233.45,234.17,15,1,1,1,233.4,234.25,110,100,2,1,233.39,234.41,10,500,1,1,AAPL,0.0,100.0,-400.0,
2024-10-21 12:23:35.833227941+00:00,2024-10-21T12:23:35.833393604Z,10,2,38,C,B,1,233.78,29,130,165663,12975154,233.8,233.98,5,24,1,1,233.7,233.99,1200,38,1,1,233.66,234.0,1,2,1,1,233.58,234.07,505,400,2,2,233.53,234.1,10,100,1,1,233.5,234.13,100,400,1,1,233.45,234.14,15,27,1,1,233.4,234.17,110,1,2,1,233.39,234.25,10,100,1,1,233.31,234.41,110,500,2,1,AAPL,0.0,0.0,-400.0,
2024-10-21 12:23:35.833269631+00:00,2024-10-21T12:23:35.833436011Z,10,2,38,A,B,1,233.71,30,130,166380,12975155,233.8,233.98,5,24,1,1,233.71,233.99,30,38,1,1,233.7,234.0,1200,2,1,1,233.66,234.07,1,400,1,2,233.58,234.1,505,100,2,1,233.53,234.13,10,400,1,1,233.5,234.14,100,27,1,1,233.45,234.17,15,1,1,1,233.4,234.25,110,100,2,1,233.39,234.41,10,500,1,1,AAPL,0.0,0.0,-400.0,
2024-10-21 12:23:35.833775320+00:00,2024-10-21T12:23:35.833941747Z,10,2,38,A,B,0,233.91,100,130,166427,12975156,233.91,233.98,100,24,1,1,233.8,233.99,5,38,1,1,233.71,234.0,30,2,1,1,233.7,234.07,1200,400,1,2,233.66,234.1,1,100,1,1,233.58,234.13,505,400,2,1,233.53,234.14,10,27,1,1,233.5,234.17,100,1,1,1,233.45,234.25,15,100,1,1,233.4,234.41,110,500,2,1,AAPL,0.0,0.0,-400.0,
2024-10-21 12:23:35.833795471+00:00,2024-10-21T12:23:35.833961308Z,10,2,38,C,A,0,233.98,24,130,165837,12975157,233.91,233.99,100,38,1,1,233.8,234.0,5,2,1,1,233.71,234.07,30,400,1,2,233.7,234.1,1200,100,1,1,233.66,234.13,1,400,1,1,233.58,234.14,505,27,2,1,233.53,234.17,10,1,1,1,233.5,234.25,100,100,1,1,233.45,234.41,15,500,1,1,233.4,234.43,110,105,2,2,AAPL,0.0,0.0,-400.0,
2024-10-21 12:23:35.836802755+00:00,2024-10-21T12:23:35.836968752Z,10,2,38,C,B,2,233.71,30,130,165997,12975162,233.91,233.99,100,38,1,1,233.8,234.0,5,2,1,1,233.7,234.07,1200,400,1,2,233.66,234.1,1,100,1,1,233.58,234.13,505,400,2,1,233.53,234.14,10,27,1,1,233.5,234.17,100,1,1,1,233.45,234.25,15,100,1,1,233.4,234.41,110,500,2,1,233.39,234.43,10,105,1,2,AAPL,0.0,0.0,-400.0,
2024-10-21 12:23:35.873762810+00:00,2024-10-21T12:23:35.873928834Z,10,2,38,C,A,0,233.99,38,130,166024,12975242,233.91,234.0,100,2,1,1,233.8,234.07,5,400,1,2,233.7,234.1,1200,100,1,1,233.66,234.13,1,400,1,1,233.58,234.14,505,27,2,1,233.53,234.17,10,1,1,1,233.5,234.25,100,100,1,1,233.45,234.41,15,500,1,1,233.4,234.43,110,105,2,2,233.39,234.5,10,63,1,4,AAPL,0.0,0.0,-400.0,
2024-10-21 12:23:35.901086187+00:00,2024-10-21T12:23:35.901252464Z,10,2,38,A,B,3,233.68,400,130,166277,12975273,233.91,234.0,100,2,1,1,233.8,234.07,5,400,1,2,233.7,234.1,1200,100,1,1,233.68,234.13,400,400,1,1,233.66,234.14,1,27,1,1,233.58,234.17,505,1,2,1,233.53,234.25,10,100,1,1,233.5,234.41,100,500,1,1,233.45,234.43,15,105,1,2,233.4,234.5,110,63,2,4,AAPL,0.0,0.0,-400.0,
2024-10-21 12:23:35.969121189+00:00,2024-10-21T12:23:35.969287724Z,10,2,38,A,B,3,233.69,400,130,166535,12975451,233.91,234.0,100,2,1,1,233.8,234.07,5,400,1,2,233.7,234.1,1200,100,1,1,233.69,234.13,400,400,1,1,233.66,234.14,1,27,1,1,233.58,234.17,505,1,2,1,233.53,234.25,10,100,1,1,233.5,234.41,100,500,1,1,233.45,234.43,15,105,1,2,233.4,234.5,110,63,2,4,AAPL,0.0,0.0,-400.0,
2024-10-21 12:23:36.000147454+00:00,2024-10-21T12:23:36.000313609Z,10,2,38,A,B,2,233.73,400,130,166155,12975478,233.91,234.0,100,2,1,1,233.8,234.07,5,400,1,2,233.73,234.1,400,100,1,1,233.7,234.13,1200,400,1,1,233.66,234.14,1,27,1,1,233.58,234.17,505,1,2,1,233.53,234.25,10,100,1,1,233.5,234.41,100,500,1,1,233.45,234.43,15,105,1,2,233.4,234.5,110,63,2,4,AAPL,0.0,0.0,-400.0,
2024-10-21 12:23:36.364328399+00:00,2024-10-21T12:23:36.364494386Z,10,2,38,A,B,3,233.71,27,130,165987,12975884,233.91,234.0,100,2,1,1,233.8,234.07,5,400,1,2,233.73,234.1,400,100,1,1,233.71,234.13,27,400,1,1,233.7,234.14,1200,27,1,1,233.66,234.17,1,1,1,1,233.58,234.25,505,100,2,1,233.53,234.41,10,500,1,1,233.5,234.43,100,105,1,2,233.45,234.5,15,63,1,4,AAPL,0.0,0.0,-400.0,
2024-10-21 12:23:36.417876919+00:00,2024-10-21T12:23:36.418044070Z,10,2,38,A,B,2,233.79,400,130,167151,12975910,233.91,234.0,100,2,1,1,233.8,234.07,5,400,1,2,233.79,234.1,400,100,1,1,233.71,234.13,27,400,1,1,233.7,234.14,1200,27,1,1,233.66,234.17,1,1,1,1,233.58,234.25,505,100,2,1,233.53,234.41,10,500,1,1,233.5,234.43,100,105,1,2,233.45,234.5,15,63,1,4,AAPL,0.0,0.0,-400.0,
2024-10-21 12:23:37.809399308+00:00,2024-10-21T12:23:37.809565585Z,10,2,38,C,A,1,234.07,200,130,166277,12978420,233.91,234.0,100,2,1,1,233.8,234.07,5,200,1,1,233.79,234.1,400,100,1,1,233.71,234.13,27,400,1,1,233.7,234.14,1200,27,1,1,233.66,234.17,1,1,1,1,233.58,234.25,505,100,2,1,233.53,234.41,10,500,1,1,233.5,234.43,100,105,1,2,233.45,234.5,15,63,1,4,AAPL,0.0,200.0,0.0,
2024-10-21 12:23:37.809411756+00:00,2024-10-21T12:23:37.809578123Z,10,2,38,A,A,1,234.02,200,130,166367,12978421,233.91,234.0,100,2,1,1,233.8,234.02,5,200,1,1,233.79,234.1,400,100,1,1,233.71,234.13,27,400,1,1,233.7,234.14,1200,27,1,1,233.66,234.17,1,1,1,1,233.58,234.25,505,100,2,1,233.53,234.41,10,500,1,1,233.5,234.43,100,105,1,2,233.45,234.5,15,63,1,4,AAPL,0.0,0.0,0.0,
2024-10-21 12:23:37.892403782+00:00,2024-10-21T12:23:37.892570179Z,10,2,38,A,A,1,234.01,200,130,166397,12978809,233.91,234.0,100,2,1,1,233.8,234.01,5,200,1,1,233.79,234.1,400,100,1,1,233.71,234.13,27,400,1,1,233.7,234.14,1200,27,1,1,233.66,234.17,1,1,1,1,233.58,234.25,505,100,2,1,233.53,234.41,10,500,1,1,233.5,234.43,100,105,1,2,233.45,234.5,15,63,1,4,AAPL,0.0,0.0,0.0,
2024-10-21 12:23:39.411730598+00:00,2024-10-21T12:23:39.411896692Z,10,2,38,C,A,4,234.14,27,130,166094,12981148,233.91,234.0,100,2,1,1,233.8,234.01,5,200,1,1,233.79,234.1,400,100,1,1,233.71,234.13,27,400,1,1,233.7,234.17,1200,1,1,1,233.66,234.25,1,100,1,1,233.58,234.41,505,500,2,1,233.53,234.43,10,105,1,2,233.5,234.5,100,63,1,4,233.45,234.75,15,1,1,1,AAPL,0.0,0.0,0.0,
2024-10-21 12:23:39.411789045+00:00,2024-10-21T12:23:39.411955539Z,10,2,38,A,A,2,234.08,30,130,166494,12981149,233.91,234.0,100,2,1,1,233.8,234.01,5,200,1,1,233.79,234.08,400,30,1,1,233.71,234.1,27,100,1,1,233.7,234.13,1200,400,1,1,233.66,234.17,1,1,1,1,233.58,234.25,505,100,2,1,233.53,234.41,10,500,1,1,233.5,234.43,100,105,1,2,233.45,234.5,15,63,1,4,AAPL,0.0,0.0,0.0,
2024-10-21 12:23:40.838462060+00:00,2024-10-21T12:23:40.838628426Z,10,2,38,C,B,3,233.71,27,130,166366,12982424,233.91,234.0,100,2,1,1,233.8,234.01,5,200,1,1,233.79,234.08,400,30,1,1,233.7,234.1,1200,100,1,1,233.66,234.13,1,400,1,1,233.58,234.17,505,1,2,1,233.53,234.25,10,100,1,1,233.5,234.41,100,500,1,1,233.45,234.43,15,105,1,2,233.4,234.5,110,63,2,4,AAPL,0.0,0.0,0.0,
2024-10-21 12:23:40.838495937+00:00,2024-10-21T12:23:40.838662378Z,10,2,38,A,B,3,233.77,28,130,166441,12982425,233.91,234.0,100,2,1,1,233.8,234.01,5,200,1,1,233.79,234.08,400,30,1,1,233.77,234.1,28,100,1,1,233.7,234.13,1200,400,1,1,233.66,234.17,1,1,1,1,233.58,234.25,505,100,2,1,233.53,234.41,10,500,1,1,233.5,234.43,100,105,1,2,233.45,234.5,15,63,1,4,AAPL,0.0,0.0,0.0,
2024-10-21 12:23:40.883854903+00:00,2024-10-21T12:23:40.884021980Z,10,2,38,A,B,1,233.82,200,130,167077,12982474,233.91,234.0,100,2,1,1,233.82,234.01,200,200,1,1,233.8,234.08,5,30,1,1,233.77,234.1,28,100,1,1,233.7,234.13,1200,400,1,1,233.66,234.17,1,1,1,1,233.58,234.25,505,100,2,1,233.53,234.41,10,500,1,1,233.5,234.43,100,105,1,2,233.45,234.5,15,63,1,4,AAPL,0.0,0.0,0.0,
2024-10-21 12:23:53.580500087+00:00,2024-10-21T12:23:53.580666026Z,10,2,38,A,A,0,233.97,4,130,165939,12991980,233.91,233.97,100,4,1,1,233.82,234.0,200,2,1,1,233.8,234.01,5,200,1,1,233.77,234.08,28,30,1,1,233.7,234.1,1200,100,1,1,233.66,234.13,1,400,1,1,233.58,234.17,505,1,2,1,233.53,234.25,10,100,1,1,233.5,234.41,100,500,1,1,233.45,234.43,15,105,1,2,AAPL,0.0,0.0,0.0,
2024-10-21 12:23:53.580531557+00:00,2024-10-21T12:23:53.580697675Z,10,2,38,C,B,1,233.82,200,130,166118,12991981,233.91,233.97,100,4,1,1,233.8,234.0,5,2,1,1,233.77,234.01,28,200,1,1,233.7,234.08,1200,30,1,1,233.66,234.1,1,100,1,1,233.58,234.13,505,400,2,1,233.53,234.17,10,1,1,1,233.5,234.25,100,100,1,1,233.45,234.41,15,500,1,1,233.4,234.43,110,105,2,2,AAPL,0.0,0.0,0.0,
2024-10-21 12:23:53.584590487+00:00,2024-10-21T12:23:53.584756226Z,10,2,38,C,A,0,233.97,4,130,165739,12991991,233.91,234.0,100,2,1,1,233.8,234.01,5,200,1,1,233.77,234.08,28,30,1,1,233.7,234.1,1200,100,1,1,233.66,234.13,1,400,1,1,233.58,234.17,505,1,2,1,233.53,234.25,10,100,1,1,233.5,234.41,100,500,1,1,233.45,234.43,15,105,1,2,233.4,234.5,110,63,2,4,AAPL,0.0,0.0,0.0,
2024-10-21 12:23:53.687318686+00:00,2024-10-21T12:23:53.687484901Z,10,2,38,A,B,1,233.82,200,130,166215,12992039,233.91,234.0,100,2,1,1,233.82,234.01,200,200,1,1,233.8,234.08,5,30,1,1,233.77,234.1,28,100,1,1,233.7,234.13,1200,400,1,1,233.66,234.17,1,1,1,1,233.58,234.25,505,100,2,1,233.53,234.41,10,500,1,1,233.5,234.43,100,105,1,2,233.45,234.5,15,63,1,4,AAPL,0.0,0.0,0.0,
2024-10-21 12:23:56.151717030+00:00,2024-10-21T12:23:56.151884878Z,10,2,38,T,A,0,233.91,100,130,167848,12994141,233.91,234.0,100,2,1,1,233.82,234.01,200,200,1,1,233.8,234.08,5,30,1,1,233.77,234.1,28,100,1,1,233.7,234.13,1200,400,1,1,233.66,234.17,1,1,1,1,233.58,234.25,505,100,2,1,233.53,234.41,10,500,1,1,233.5,234.43,100,105,1,2,233.45,234.5,15,63,1,4,AAPL,0.0,0.0,0.0,
2024-10-21 12:23:56.151717030+00:00,2024-10-21T12:23:56.151884878Z,10,2,38,C,B,0,233.91,100,130,167848,12994141,233.82,234.0,200,2,1,1,233.8,234.01,5,200,1,1,233.77,234.08,28,30,1,1,233.7,234.1,1200,100,1,1,233.66,234.13,1,400,1,1,233.58,234.17,505,1,2,1,233.53,234.25,10,100,1,1,233.5,234.41,100,500,1,1,233.45,234.43,15,105,1,2,233.4,234.5,110,63,2,4,AAPL,0.0,0.0,0.0,
2024-10-21 12:23:56.151739820+00:00,2024-10-21T12:23:56.151905940Z,10,2,38,A,A,0,233.95,100,130,166120,12994142,233.82,233.95,200,100,1,1,233.8,234.0,5,2,1,1,233.77,234.01,28,200,1,1,233.7,234.08,1200,30,1,1,233.66,234.1,1,100,1,1,233.58,234.13,505,400,2,1,233.53,234.17,10,1,1,1,233.5,234.25,100,100,1,1,233.45,234.41,15,500,1,1,233.4,234.43,110,105,2,2,AAPL,0.0,0.0,0.0,
2024-10-21 12:23:56.151743006+00:00,2024-10-21T12:23:56.151909152Z,10,2,38,A,A,1,233.98,100,130,166146,12994143,233.82,233.95,200,100,1,1,233.8,233.98,5,100,1,1,233.77,234.0,28,2,1,1,233.7,234.01,1200,200,1,1,233.66,234.08,1,30,1,1,233.58,234.1,505,100,2,1,233.53,234.13,10,400,1,1,233.5,234.17,100,1,1,1,233.45,234.25,15,100,1,1,233.4,234.41,110,500,2,1,AAPL,0.0,0.0,0.0,
2024-10-21 12:23:56.151744249+00:00,2024-10-21T12:23:56.151910443Z,10,2,38,A,A,1,233.96,25,130,166194,12994144,233.82,233.95,200,100,1,1,233.8,233.96,5,25,1,1,233.77,233.98,28,100,1,1,233.7,234.0,1200,2,1,1,233.66,234.01,1,200,1,1,233.58,234.08,505,30,2,1,233.53,234.1,10,100,1,1,233.5,234.13,100,400,1,1,233.45,234.17,15,1,1,1,233.4,234.25,110,100,2,1,AAPL,0.0,0.0,0.0,
2024-10-21 12:23:56.151751835+00:00,2024-10-21T12:23:56.151917914Z,10,2,38,A,A,2,233.98,100,130,166079,12994145,233.82,233.95,200,100,1,1,233.8,233.96,5,25,1,1,233.77,233.98,28,200,1,2,233.7,234.0,1200,2,1,1,233.66,234.01,1,200,1,1,233.58,234.08,505,30,2,1,233.53,234.1,10,100,1,1,233.5,234.13,100,400,1,1,233.45,234.17,15,1,1,1,233.4,234.25,110,100,2,1,AAPL,0.0,-100.0,0.0,
2024-10-21 12:23:56.151753407+00:00,2024-10-21T12:23:56.151922395Z,10,2,38,C,B,0,233.82,200,130,168988,12994147,233.8,233.95,5,100,1,1,233.77,233.96,28,25,1,1,233.7,233.98,1200,300,1,3,233.66,234.0,1,2,1,1,233.58,234.01,505,200,2,1,233.53,234.08,10,30,1,1,233.5,234.1,100,100,1,1,233.45,234.13,15,400,1,1,233.4,234.17,110,1,2,1,233.39,234.25,10,100,1,1,AAPL,0.0,-100.0,0.0,
2024-10-21 12:23:56.151760470+00:00,2024-10-21T12:23:56.151926634Z,10,2,38,A,A,1,233.96,30,130,166164,12994148,233.8,233.95,5,100,1,1,233.77,233.96,28,55,1,2,233.7,233.98,1200,300,1,3,233.66,234.0,1,2,1,1,233.58,234.01,505,200,2,1,233.53,234.08,10,30,1,1,233.5,234.1,100,100,1,1,233.45,234.13,15,400,1,1,233.4,234.17,110,1,2,1,233.39,234.25,10,100,1,1,AAPL,0.0,-30.0,0.0,
2024-10-21 12:23:56.151774406+00:00,2024-10-21T12:23:56.151940792Z,10,2,38,C,A,2,233.98,100,130,166386,12994150,233.8,233.95,5,100,1,1,233.77,233.96,28,55,1,2,233.7,233.98,1200,200,1,2,233.66,233.99,1,30,1,1,233.58,234.0,505,2,2,1,233.53,234.01,10,200,1,1,233.5,234.08,100,30,1,1,233.45,234.1,15,100,1,1,233.4,234.13,110,400,2,1,233.39,234.17,10,1,1,1,AAPL,0.0,100.0,0.0,
2024-10-21 12:23:56.151794726+00:00,2024-10-21T12:23:56.151962295Z,10,2,38,C,A,0,233.95,100,130,167569,12994152,233.8,233.96,5,55,1,2,233.77,233.98,28,200,1,2,233.7,233.99,1200,30,1,1,233.66,234.0,1,2,1,1,233.58,234.01,505,200,2,1,233.53,234.08,10,30,1,1,233.5,234.1,100,100,1,1,233.45,234.13,15,400,1,1,233.4,234.17,110,1,2,1,233.39,234.25,10,100,1,1,AAPL,0.0,0.0,0.0,
2024-10-21 12:23:56.151815406+00:00,2024-10-21T12:23:56.151983196Z,10,2,38,C,A,0,233.96,25,128,167790,12994153,233.8,233.96,5,30,1,1,233.77,233.98,28,200,1,2,233.7,233.99,1200,30,1,1,233.66,234.0,1,2,1,1,233.58,234.01,505,200,2,1,233.53,234.08,10,30,1,1,233.5,234.1,100,100,1,1,233.45,234.13,15,400,1,1,233.4,234.17,110,1,2,1,233.39,234.25,10,100,1,1,AAPL,25.0,25.0,25.0,
2024-10-21 12:23:56.151818053+00:00,2024-10-21T12:23:56.151984267Z,10,2,38,C,A,1,233.98,100,130,166214,12994155,233.8,233.96,5,30,1,1,233.77,233.98,28,100,1,1,233.7,233.99,1200,30,1,1,233.66,234.0,1,2,1,1,233.58,234.01,505,200,2,1,233.53,234.08,10,30,1,1,233.5,234.1,100,100,1,1,233.45,234.13,15,400,1,1,233.4,234.17,110,1,2,1,233.39,234.25,10,100,1,1,AAPL,0.0,100.0,25.0,
2024-10-21 12:23:56.151908869+00:00,2024-10-21T12:23:56.152075526Z,10,2,38,A,A,0,233.95,100,130,166657,12994157,233.8,233.95,5,100,1,1,233.77,233.96,28,30,1,1,233.7,233.98,1200,100,1,1,233.66,233.99,1,30,1,1,233.58,234.0,505,2,2,1,233.53,234.01,10,200,1,1,233.5,234.08,100,30,1,1,233.45,234.1,15,100,1,1,233.4,234.13,110,400,2,1,233.39,234.17,10,1,1,1,AAPL,0.0,0.0,25.0,
2024-10-21 12:23:56.152059304+00:00,2024-10-21T12:23:56.152225403Z,10,2,38,C,A,2,233.98,100,130,166099,12994158,233.8,233.95,5,100,1,1,233.77,233.96,28,30,1,1,233.7,233.99,1200,30,1,1,233.66,234.0,1,2,1,1,233.58,234.01,505,200,2,1,233.53,234.08,10,30,1,1,233.5,234.1,100,100,1,1,233.45,234.13,15,400,1,1,233.4,234.17,110,1,2,1,233.39,234.25,10,100,1,1,AAPL,0.0,0.0,25.0,
2024-10-21 12:23:56.152100943+00:00,2024-10-21T12:23:56.152267246Z,10,2,38,A,A,0,233.95,7,130,166303,12994159,233.8,233.95,5,107,1,2,233.77,233.96,28,30,1,1,233.7,233.99,1200,30,1,1,233.66,234.0,1,2,1,1,233.58,234.01,505,200,2,1,233.53,234.08,10,30,1,1,233.5,234.1,100,100,1,1,233.45,234.13,15,400,1,1,233.4,234.17,110,1,2,1,233.39,234.25,10,100,1,1,AAPL,-7.0,-7.0,18.0,
2024-10-21 12:23:56.152326897+00:00,2024-10-21T12:23:56.152492907Z,10,2,38,C,A,0,233.95,100,130,166010,12994160,233.8,233.95,5,7,1,1,233.77,233.96,28,30,1,1,233.7,233.99,1200,30,1,1,233.66,234.0,1,2,1,1,233.58,234.01,505,200,2,1,233.53,234.08,10,30,1,1,233.5,234.1,100,100,1,1,233.45,234.13,15,400,1,1,233.4,234.17,110,1,2,1,233.39,234.25,10,100,1,1,AAPL,100.0,100.0,118.0,
2024-10-21 12:23:56.156195112+00:00,2024-10-21T12:23:56.156361100Z,10,2,38,C,A,0,233.95,7,130,165988,12994163,233.8,233.96,5,30,1,1,233.77,233.99,28,30,1,1,233.7,234.0,1200,2,1,1,233.66,234.01,1,200,1,1,233.58,234.08,505,30,2,1,233.53,234.1,10,100,1,1,233.5,234.13,100,400,1,1,233.45,234.17,15,1,1,1,233.4,234.25,110,100,2,1,233.39,234.41,10,500,1,1,AAPL,0.0,0.0,118.0,
2024-10-21 12:23:56.222863616+00:00,2024-10-21T12:23:56.223030277Z,10,2,38,A,B,2,233.73,400,130,166661,12994197,233.8,233.96,5,30,1,1,233.77,233.99,28,30,1,1,233.73,234.0,400,2,1,1,233.7,234.01,1200,200,1,1,233.66,234.08,1,30,1,1,233.58,234.1,505,100,2,1,233.53,234.13,10,400,1,1,233.5,234.17,100,1,1,1,233.45,234.25,15,100,1,1,233.4,234.41,110,500,2,1,AAPL,0.0,0.0,118.0,
2024-10-21 12:23:56.223377764+00:00,2024-10-21T12:23:56.223543885Z,10,2,38,C,B,1,233.77,28,130,166121,12994198,233.8,233.96,5,30,1,1,233.73,233.99,400,30,1,1,233.7,234.0,1200,2,1,1,233.66,234.01,1,200,1,1,233.58,234.08,505,30,2,1,233.53,234.1,10,100,1,1,233.5,234.13,100,400,1,1,233.45,234.17,15,1,1,1,233.4,234.25,110,100,2,1,233.39,234.41,10,500,1,1,AAPL,0.0,0.0,118.0,
2024-10-21 12:23:56.223447893+00:00,2024-10-21T12:23:56.223614225Z,10,2,38,A,B,2,233.71,29,130,166332,12994199,233.8,233.96,5,30,1,1,233.73,233.99,400,30,1,1,233.71,234.0,29,2,1,1,233.7,234.01,1200,200,1,1,233.66,234.08,1,30,1,1,233.58,234.1,505,100,2,1,233.53,234.13,10,400,1,1,233.5,234.17,100,1,1,1,233.45,234.25,15,100,1,1,233.4,234.41,110,500,2,1,AAPL,0.0,0.0,118.0,
2024-10-21 12:23:56.253764723+00:00,2024-10-21T12:23:56.253930823Z,10,2,38,C,A,1,233.99,30,130,166100,12994211,233.8,233.96,5,30,1,1,233.73,234.0,400,2,1,1,233.71,234.01,29,200,1,1,233.7,234.08,1200,30,1,1,233.66,234.1,1,100,1,1,233.58,234.13,505,400,2,1,233.53,234.17,10,1,1,1,233.5,234.25,100,100,1,1,233.45,234.41,15,500,1,1,233.4,234.43,110,105,2,2,AAPL,0.0,0.0,118.0,
2024-10-21 12:23:56.403764720+00:00,2024-10-21T12:23:56.403930641Z,10,2,38,C,A,0,233.96,30,130,165921,12994800,233.8,234.0,5,2,1,1,233.73,234.01,400,200,1,1,233.71,234.08,29,30,1,1,233.7,234.1,1200,100,1,1,233.66,234.13,1,400,1,1,233.58,234.17,505,1,2,1,233.53,234.25,10,100,1,1,233.5,234.41,100,500,1,1,233.45,234.43,15,105,1,2,233.4,234.5,110,63,2,4,AAPL,0.0,0.0,118.0,
2024-10-21 12:23:59.004911131+00:00,2024-10-21T12:23:59.005077193Z,10,2,38,C,B,1,233.73,400,130,166062,12997239,233.8,234.0,5,2,1,1,233.71,234.01,29,200,1,1,233.7,234.08,1200,30,1,1,233.66,234.1,1,100,1,1,233.58,234.13,505,400,2,1,233.53,234.17,10,1,1,1,233.5,234.25,100,100,1,1,233.45,234.41,15,500,1,1,233.4,234.43,110,105,2,2,233.39,234.5,10,63,1,4,AAPL,0.0,0.0,0.0,
2024-10-21 12:23:59.004923443+00:00,2024-10-21T12:23:59.005089751Z,10,2,38,A,B,3,233.68,400,130,166308,12997240,233.8,234.0,5,2,1,1,233.71,234.01,29,200,1,1,233.7,234.08,1200,30,1,1,233.68,234.1,400,100,1,1,233.66,234.13,1,400,1,1,233.58,234.17,505,1,2,1,233.53,234.25,10,100,1,1,233.5,234.41,100,500,1,1,233.45,234.43,15,105,1,2,233.4,234.5,110,63,2,4,AAPL,0.0,0.0,0.0,
2024-10-21 12:23:59.008280403+00:00,2024-10-21T12:23:59.008446995Z,10,2,38,A,A,2,234.03,29,130,166592,12997243,233.8,234.0,5,2,1,1,233.71,234.01,29,200,1,1,233.7,234.03,1200,29,1,1,233.68,234.08,400,30,1,1,233.66,234.1,1,100,1,1,233.58,234.13,505,400,2,1,233.53,234.17,10,1,1,1,233.5,234.25,100,100,1,1,233.45,234.41,15,500,1,1,233.4,234.43,110,105,2,2,AAPL,0.0,0.0,0.0,
2024-10-21 12:23:59.008322912+00:00,2024-10-21T12:23:59.008489006Z,10,2,38,C,A,3,234.08,30,130,166094,12997244,233.8,234.0,5,2,1,1,233.71,234.01,29,200,1,1,233.7,234.03,1200,29,1,1,233.68,234.1,400,100,1,1,233.66,234.13,1,400,1,1,233.58,234.17,505,1,2,1,233.53,234.25,10,100,1,1,233.5,234.41,100,500,1,1,233.45,234.43,15,105,1,2,233.4,234.5,110,63,2,4,AAPL,0.0,0.0,0.0,
2024-10-21 12:23:59.011947596+00:00,2024-10-21T12:23:59.012113870Z,10,2,38,C,A,1,234.01,200,130,166274,12997249,233.8,234.0,5,2,1,1,233.71,234.03,29,29,1,1,233.7,234.1,1200,100,1,1,233.68,234.13,400,400,1,1,233.66,234.17,1,1,1,1,233.58,234.25,505,100,2,1,233.53,234.41,10,500,1,1,233.5,234.43,100,105,1,2,233.45,234.5,15,63,1,4,233.4,234.75,110,1,2,1,AAPL,0.0,0.0,0.0,
2024-10-21 12:23:59.011960403+00:00,2024-10-21T12:23:59.012126464Z,10,2,38,A,A,2,234.04,200,130,166061,12997250,233.8,234.0,5,2,1,1,233.71,234.03,29,29,1,1,233.7,234.04,1200,200,1,1,233.68,234.1,400,100,1,1,233.66,234.13,1,400,1,1,233.58,234.17,505,1,2,1,233.53,234.25,10,100,1,1,233.5,234.41,100,500,1,1,233.45,234.43,15,105,1,2,233.4,234.5,110,63,2,4,AAPL,0.0,0.0,0.0,
2024-10-21 12:23:59.013517894+00:00,2024-10-21T12:23:59.013684039Z,10,2,38,C,A,2,234.04,200,130,166145,12997253,233.8,234.0,5,2,1,1,233.71,234.03,29,29,1,1,233.7,234.1,1200,100,1,1,233.68,234.13,400,400,1,1,233.66,234.17,1,1,1,1,233.58,234.25,505,100,2,1,233.53,234.41,10,500,1,1,233.5,234.43,100,105,1,2,233.45,234.5,15,63,1,4,233.4,234.75,110,1,2,1,AAPL,0.0,0.0,0.0,
2024-10-21 12:23:59.013530559+00:00,2024-10-21T12:23:59.013696792Z,10,2,38,A,A,2,234.07,400,130,166233,12997254,233.8,234.0,5,2,1,1,233.71,234.03,29,29,1,1,233.7,234.07,1200,400,1,1,233.68,234.1,400,100,1,1,233.66,234.13,1,400,1,1,233.58,234.17,505,1,2,1,233.53,234.25,10,100,1,1,233.5,234.41,100,500,1,1,233.45,234.43,15,105,1,2,233.4,234.5,110,63,2,4,AAPL,0.0,0.0,0.0,
2024-10-21 12:23:59.014238552+00:00,2024-10-21T12:23:59.014404565Z,10,2,38,C,A,1,234.03,29,130,166013,12997255,233.8,234.0,5,2,1,1,233.71,234.07,29,400,1,1,233.7,234.1,1200,100,1,1,233.68,234.13,400,400,1,1,233.66,234.17,1,1,1,1,233.58,234.25,505,100,2,1,233.53,234.41,10,500,1,1,233.5,234.43,100,105,1,2,233.45,234.5,15,63,1,4,233.4,234.75,110,1,2,1,AAPL,0.0,0.0,0.0,
2024-10-21 12:23:59.017196811+00:00,2024-10-21T12:23:59.017362837Z,10,2,38,C,B,1,233.71,29,130,166026,12997256,233.8,234.0,5,2,1,1,233.7,234.07,1200,400,1,1,233.68,234.1,400,100,1,1,233.66,234.13,1,400,1,1,233.58,234.17,505,1,2,1,233.53,234.25,10,100,1,1,233.5,234.41,100,500,1,1,233.45,234.43,15,105,1,2,233.4,234.5,110,63,2,4,233.39,234.75,10,1,1,1,AAPL,0.0,0.0,0.0,
2024-10-21 12:23:59.017282783+00:00,2024-10-21T12:23:59.017449096Z,10,2,38,A,B,4,233.61,27,130,166313,12997257,233.8,234.0,5,2,1,1,233.7,234.07,1200,400,1,1,233.68,234.1,400,100,1,1,233.66,234.13,1,400,1,1,233.61,234.17,27,1,1,1,233.58,234.25,505,100,2,1,233.53,234.41,10,500,1,1,233.5,234.43,100,105,1,2,233.45,234.5,15,63,1,4,233.4,234.75,110,1,2,1,AAPL,0.0,0.0,0.0,
2024-10-21 12:23:59.074518650+00:00,2024-10-21T12:23:59.074684910Z,10,2,38,A,A,1,234.02,200,130,166260,12997280,233.8,234.0,5,2,1,1,233.7,234.02,1200,200,1,1,233.68,234.1,400,100,1,1,233.66,234.13,1,400,1,1,233.61,234.17,27,1,1,1,233.58,234.25,505,100,2,1,233.53,234.41,10,500,1,1,233.5,234.43,100,105,1,2,233.45,234.5,15,63,1,4,233.4,234.75,110,1,2,1,AAPL,0.0,0.0,0.0,
2024-10-21 12:24:00.591545399+00:00,2024-10-21T12:24:00.591711571Z,10,2,38,A,B,3,233.66,27,130,166172,12999539,233.8,234.0,5,2,1,1,233.7,234.02,1200,200,1,1,233.68,234.1,400,100,1,1,233.66,234.13,28,400,2,1,233.61,234.17,27,1,1,1,233.58,234.25,505,100,2,1,233.53,234.41,10,500,1,1,233.5,234.43,100,105,1,2,233.45,234.5,15,63,1,4,233.4,234.75,110,1,2,1,AAPL,0.0,27.0,0.0,
2024-10-21 12:24:00.591577923+00:00,2024-10-21T12:24:00.591743978Z,10,2,38,C,B,4,233.61,27,130,166055,12999540,233.8,234.0,5,2,1,1,233.7,234.02,1200,200,1,1,233.68,234.1,400,100,1,1,233.66,234.13,28,400,2,1,233.58,234.17,505,1,2,1,233.53,234.25,10,100,1,1,233.5,234.41,100,500,1,1,233.45,234.43,15,105,1,2,233.4,234.5,110,63,2,4,233.39,234.75,10,1,1,1,AAPL,0.0,0.0,0.0,
2024-10-21 12:24:00.591620074+00:00,2024-10-21T12:24:00.591786574Z,10,2,38,A,A,2,234.08,26,130,166500,12999541,233.8,234.0,5,2,1,1,233.7,234.02,1200,200,1,1,233.68,234.08,400,26,1,1,233.66,234.1,28,100,2,1,233.58,234.13,505,400,2,1,233.53,234.17,10,1,1,1,233.5,234.25,100,100,1,1,233.45,234.41,15,500,1,1,233.4,234.43,110,105,2,2,233.39,234.5,10,63,1,4,AAPL,0.0,0.0,0.0,
2024-10-21 12:24:00.639005885+00:00,2024-10-21T12:24:00.639172304Z,10,2,38,A,B,1,233.72,400,130,166419,12999658,233.8,234.0,5,2,1,1,233.72,234.02,400,200,1,1,233.7,234.08,1200,26,1,1,233.66,234.1,28,100,2,1,233.58,234.13,505,400,2,1,233.53,234.17,10,1,1,1,233.5,234.25,100,100,1,1,233.45,234.41,15,500,1,1,233.4,234.43,110,105,2,2,233.39,234.5,10,63,1,4,AAPL,0.0,0.0,0.0,
2024-10-21 12:24:00.649056842+00:00,2024-10-21T12:24:00.649223162Z,10,2,38,A,A,1,234.01,200,130,166320,12999723,233.8,234.0,5,2,1,1,233.72,234.01,400,200,1,1,233.7,234.08,1200,26,1,1,233.66,234.1,28,100,2,1,233.58,234.13,505,400,2,1,233.53,234.17,10,1,1,1,233.5,234.25,100,100,1,1,233.45,234.41,15,500,1,1,233.4,234.43,110,105,2,2,233.39,234.5,10,63,1,4,AAPL,0.0,0.0,0.0,
2024-10-21 12:24:02.009392935+00:00,2024-10-21T12:24:02.009559726Z,10,2,38,A,A,1,234.01,200,130,166791,13001036,233.8,234.0,5,2,1,1,233.72,234.01,400,400,1,2,233.7,234.08,1200,26,1,1,233.66,234.1,28,100,2,1,233.58,234.13,505,400,2,1,233.53,234.17,10,1,1,1,233.5,234.25,100,100,1,1,233.45,234.41,15,500,1,1,233.4,234.43,110,105,2,2,233.39,234.5,10,63,1,4,AAPL,0.0,-200.0,0.0,
2024-10-21 12:24:03.014231244+00:00,2024-10-21T12:24:03.014397743Z,10,2,38,A,B,1,233.73,400,130,166499,13002474,233.8,234.0,5,2,1,1,233.73,234.01,400,400,1,2,233.7,234.08,1200,26,1,1,233.66,234.1,28,100,2,1,233.58,234.13,505,400,2,1,233.53,234.17,10,1,1,1,233.5,234.25,100,100,1,1,233.45,234.41,15,500,1,1,233.4,234.43,110,105,2,2,233.39,234.5,10,63,1,4,AAPL,0.0,0.0,0.0,
2024-10-21 12:24:12.705753370+00:00,2024-10-21T12:24:12.705919587Z,10,2,38,C,A,2,234.08,26,130,166217,13011148,233.8,234.0,5,2,1,1,233.73,234.01,400,400,1,2,233.7,234.1,1200,100,1,1,233.66,234.13,28,400,2,1,233.58,234.17,505,1,2,1,233.53,234.25,10,100,1,1,233.5,234.41,100,500,1,1,233.45,234.43,15,105,1,2,233.4,234.5,110,63,2,4,233.39,234.75,10,1,1,1,AAPL,0.0,0.0,0.0,
2024-10-21 12:24:12.705792927+00:00,2024-10-21T12:24:12.705959304Z,10,2,38,A,A,2,234.03,27,130,166377,13011149,233.8,234.0,5,2,1,1,233.73,234.01,400,400,1,2,233.7,234.03,1200,27,1,1,233.66,234.1,28,100,2,1,233.58,234.13,505,400,2,1,233.53,234.17,10,1,1,1,233.5,234.25,100,100,1,1,233.45,234.41,15,500,1,1,233.4,234.43,110,105,2,2,233.39,234.5,10,63,1,4,AAPL,0.0,0.0,0.0,
2024-10-21 12:24:12.758652350+00:00,2024-10-21T12:24:12.758818645Z,10,2,38,C,A,1,234.01,200,130,166295,13011180,233.8,234.0,5,2,1,1,233.73,234.01,400,200,1,1,233.7,234.03,1200,27,1,1,233.66,234.1,28,100,2,1,233.58,234.13,505,400,2,1,233.53,234.17,10,1,1,1,233.5,234.25,100,100,1,1,233.45,234.41,15,500,1,1,233.4,234.43,110,105,2,2,233.39,234.5,10,63,1,4,AAPL,0.0,200.0,0.0,
2024-10-21 12:24:12.758665302+00:00,2024-10-21T12:24:12.758831773Z,10,2,38,A,A,0,233.96,200,130,166471,13011181,233.8,233.96,5,200,1,1,233.73,234.0,400,2,1,1,233.7,234.03,1200,27,1,1,233.66,234.1,28,100,2,1,233.58,234.13,505,400,2,1,233.53,234.17,10,1,1,1,233.5,234.25,100,100,1,1,233.45,234.41,15,500,1,1,233.4,234.43,110,105,2,2,233.39,234.5,10,63,1,4,AAPL,0.0,0.0,0.0,
2024-10-21 12:24:12.829796906+00:00,2024-10-21T12:24:12.829962896Z,10,2,38,C,B,1,233.73,400,130,165990,13011209,233.8,233.96,5,200,1,1,233.7,234.0,1200,2,1,1,233.66,234.03,28,27,2,1,233.58,234.1,505,100,2,1,233.53,234.13,10,400,1,1,233.5,234.17,100,1,1,1,233.45,234.25,15,100,1,1,233.4,234.41,110,500,2,1,233.39,234.43,10,105,1,2,233.31,234.5,110,63,2,4,AAPL,0.0,0.0,0.0,
2024-10-21 12:24:12.829810064+00:00,2024-10-21T12:24:12.829976396Z,10,2,38,A,B,2,233.68,400,130,166332,13011211,233.8,233.96,5,200,1,1,233.7,234.0,1200,2,1,1,233.68,234.03,400,27,1,1,233.66,234.1,28,100,2,1,233.58,234.13,505,400,2,1,233.53,234.17,10,1,1,1,233.5,234.25,100,100,1,1,233.45,234.41,15,500,1,1,233.4,234.43,110,105,2,2,233.39,234.5,10,63,1,4,AAPL,0.0,0.0,0.0,
2024-10-21 12:24:12.887759925+00:00,2024-10-21T12:24:12.887926720Z,10,2,38,A,B,1,233.71,200,130,166795,13011280,233.8,233.96,5,200,1,1,233.71,234.0,200,2,1,1,233.7,234.03,1200,27,1,1,233.66,234.1,28,100,2,1,233.58,234.13,505,400,2,1,233.53,234.17,10,1,1,1,233.5,234.25,100,100,1,1,233.45,234.41,15,500,1,1,233.4,234.43,110,105,2,2,233.39,234.5,10,63,1,4,AAPL,0.0,0.0,0.0,
2024-10-21 12:24:12.974071654+00:00,2024-10-21T12:24:12.974238049Z,10,2,38,A,A,0,233.96,200,130,166395,13011303,233.8,233.96,5,400,1,2,233.71,234.0,200,2,1,1,233.7,234.03,1200,27,1,1,233.66,234.1,28,100,2,1,233.58,234.13,505,400,2,1,233.53,234.17,10,1,1,1,233.5,234.25,100,100,1,1,233.45,234.41,15,500,1,1,233.4,234.43,110,105,2,2,233.39,234.5,10,63,1,4,AAPL,-200.0,-200.0,-200.0,
2024-10-21 12:24:12.981737142+00:00,2024-10-21T12:24:12.981903881Z,10,2,38,A,A,0,233.94,6,130,166739,13011309,233.8,233.94,5,6,1,1,233.71,233.96,200,400,1,2,233.7,234.0,1200,2,1,1,233.66,234.03,28,27,2,1,233.58,234.1,505,100,2,1,233.53,234.13,10,400,1,1,233.5,234.17,100,1,1,1,233.45,234.25,15,100,1,1,233.4,234.41,110,500,2,1,233.39,234.43,10,105,1,2,AAPL,0.0,0.0,-200.0,
2024-10-21 12:24:12.981783591+00:00,2024-10-21T12:24:12.981949530Z,10,2,38,C,B,1,233.71,200,130,165939,13011310,233.8,233.94,5,6,1,1,233.7,233.96,1200,400,1,2,233.66,234.0,28,2,2,1,233.58,234.03,505,27,2,1,233.53,234.1,10,100,1,1,233.5,234.13,100,400,1,1,233.45,234.17,15,1,1,1,233.4,234.25,110,100,2,1,233.39,234.41,10,500,1,1,233.31,234.43,110,105,2,2,AAPL,0.0,0.0,-200.0,
2024-10-21 12:24:12.985831565+00:00,2024-10-21T12:24:12.985997932Z,10,2,38,C,A,0,233.94,6,130,166367,13011317,233.8,233.96,5,400,1,2,233.7,234.0,1200,2,1,1,233.66,234.03,28,27,2,1,233.58,234.1,505,100,2,1,233.53,234.13,10,400,1,1,233.5,234.17,100,1,1,1,233.45,234.25,15,100,1,1,233.4,234.41,110,500,2,1,233.39,234.43,10,105,1,2,233.31,234.5,110,63,2,4,AAPL,0.0,0.0,-200.0,
