ts_event,ts_recv,rtype,publisher_id,instrument_id,action,side,depth,price,size,flags,ts_in_delta,sequence,bid_px_00,ask_px_00,bid_sz_00,ask_sz_00,bid_ct_00,ask_ct_00,bid_px_01,ask_px_01,bid_sz_01,ask_sz_01,bid_ct_01,ask_ct_01,bid_px_02,ask_px_02,bid_sz_02,ask_sz_02,bid_ct_02,ask_ct_02,bid_px_03,ask_px_03,bid_sz_03,ask_sz_03,bid_ct_03,ask_ct_03,bid_px_04,ask_px_04,bid_sz_04,ask_sz_04,bid_ct_04,ask_ct_04,bid_px_05,ask_px_05,bid_sz_05,ask_sz_05,bid_ct_05,ask_ct_05,bid_px_06,ask_px_06,bid_sz_06,ask_sz_06,bid_ct_06,ask_ct_06,bid_px_07,ask_px_07,bid_sz_07,ask_sz_07,bid_ct_07,ask_ct_07,bid_px_08,ask_px_08,bid_sz_08,ask_sz_08,bid_ct_08,ask_ct_08,bid_px_09,ask_px_09,bid_sz_09,ask_sz_09,bid_ct_09,ask_ct_09,symbol,best_level_ofi,multi_level_ofi,integrated_ofi_1s,cross_asset_ofi
2024-10-21 12:24:13.052603423+00:00,2024-10-21T12:24:13.052769828Z,10,2,38,A,B,3,233.62,400,130,166405,13011374,233.8,233.96,5,400,1,2,233.7,234.0,1200,2,1,1,233.66,234.03,28,27,2,1,233.62,234.1,400,100,1,1,233.58,234.13,505,400,2,1,233.53,234.17,10,1,1,1,233.5,234.25,100,100,1,1,233.45,234.41,15,500,1,1,233.4,234.43,110,105,2,2,233.39,234.5,10,63,1,4,AAPL,0.0,0.0,-200.0,
2024-10-21 12:24:13.053128647+00:00,2024-10-21T12:24:13.053294920Z,10,2,38,A,B,5,233.55,27,130,166273,13011375,233.8,233.96,5,400,1,2,233.7,234.0,1200,2,1,1,233.66,234.03,28,27,2,1,233.62,234.1,400,100,1,1,233.58,234.13,505,400,2,1,233.55,234.17,27,1,1,1,233.53,234.25,10,100,1,1,233.5,234.41,100,500,1,1,233.45,234.43,15,105,1,2,233.4,234.5,110,63,2,4,AAPL,0.0,0.0,-200.0,
2024-10-21 12:24:13.053154026+00:00,2024-10-21T12:24:13.053320162Z,10,2,38,C,B,2,233.66,27,130,166136,13011376,233.8,233.96,5,400,1,2,233.7,234.0,1200,2,1,1,233.66,234.03,1,27,1,1,233.62,234.1,400,100,1,1,233.58,234.13,505,400,2,1,233.55,234.17,27,1,1,1,233.53,234.25,10,100,1,1,233.5,234.41,100,500,1,1,233.45,234.43,15,105,1,2,233.4,234.5,110,63,2,4,AAPL,0.0,-27.0,-200.0,
2024-10-21 12:24:13.184858615+00:00,2024-10-21T12:24:13.185024995Z,10,2,38,A,B,3,233.63,200,130,166380,13011463,233.8,233.96,5,400,1,2,233.7,234.0,1200,2,1,1,233.66,234.03,1,27,1,1,233.63,234.1,200,100,1,1,233.58,234.13,505,400,2,1,233.55,234.17,27,1,1,1,233.53,234.25,10,100,1,1,233.5,234.41,100,500,1,1,233.45,234.43,15,105,1,2,233.4,234.5,110,63,2,4,AAPL,0.0,0.0,-200.0,
2024-10-21 12:24:13.202985661+00:00,2024-10-21T12:24:13.203151981Z,10,2,38,A,B,2,233.68,200,130,166320,13011562,233.8,233.96,5,400,1,2,233.7,234.0,1200,2,1,1,233.68,234.03,200,27,1,1,233.66,234.1,1,100,1,1,233.58,234.13,505,400,2,1,233.55,234.17,27,1,1,1,233.53,234.25,10,100,1,1,233.5,234.41,100,500,1,1,233.45,234.43,15,105,1,2,233.4,234.5,110,63,2,4,AAPL,0.0,0.0,-200.0,
2024-10-21 12:24:13.538400660+00:00,2024-10-21T12:24:13.538567140Z,10,2,38,A,B,2,233.68,200,130,166480,13011788,233.8,233.96,5,400,1,2,233.7,234.0,1200,2,1,1,233.68,234.03,400,27,2,1,233.66,234.1,1,100,1,1,233.58,234.13,505,400,2,1,233.55,234.17,27,1,1,1,233.53,234.25,10,100,1,1,233.5,234.41,100,500,1,1,233.45,234.43,15,105,1,2,233.4,234.5,110,63,2,4,AAPL,0.0,200.0,-200.0,
2024-10-21 12:24:13.589170912+00:00,2024-10-21T12:24:13.589336955Z,10,2,38,C,B,2,233.68,200,130,166043,13011843,233.8,233.96,5,400,1,2,233.7,234.0,1200,2,1,1,233.68,234.03,200,27,1,1,233.66,234.1,1,100,1,1,233.58,234.13,505,400,2,1,233.55,234.17,27,1,1,1,233.53,234.25,10,100,1,1,233.5,234.41,100,500,1,1,233.45,234.43,15,105,1,2,233.4,234.5,110,63,2,4,AAPL,0.0,-200.0,-200.0,
2024-10-21 12:24:13.589183060+00:00,2024-10-21T12:24:13.589349547Z,10,2,38,A,B,1,233.71,200,130,166487,13011844,233.8,233.96,5,400,1,2,233.71,234.0,200,2,1,1,233.7,234.03,1200,27,1,1,233.66,234.1,1,100,1,1,233.58,234.13,505,400,2,1,233.55,234.17,27,1,1,1,233.53,234.25,10,100,1,1,233.5,234.41,100,500,1,1,233.45,234.43,15,105,1,2,233.4,234.5,110,63,2,4,AAPL,0.0,0.0,-200.0,
2024-10-21 12:24:13.922992508+00:00,2024-10-21T12:24:13.923159059Z,10,2,38,C,B,5,233.55,27,130,166551,13011979,233.8,233.96,5,400,1,2,233.71,234.0,200,2,1,1,233.7,234.03,1200,27,1,1,233.66,234.1,1,100,1,1,233.58,234.13,505,400,2,1,233.53,234.17,10,1,1,1,233.5,234.25,100,100,1,1,233.45,234.41,15,500,1,1,233.4,234.43,110,105,2,2,233.39,234.5,10,63,1,4,AAPL,0.0,0.0,-200.0,
2024-10-21 12:24:13.923126726+00:00,2024-10-21T12:24:13.923293151Z,10,2,38,A,B,3,233.66,30,130,166425,13011980,233.8,233.96,5,400,1,2,233.71,234.0,200,2,1,1,233.7,234.03,1200,27,1,1,233.66,234.1,31,100,2,1,233.58,234.13,505,400,2,1,233.53,234.17,10,1,1,1,233.5,234.25,100,100,1,1,233.45,234.41,15,500,1,1,233.4,234.43,110,105,2,2,233.39,234.5,10,63,1,4,AAPL,0.0,30.0,-200.0,
2024-10-21 12:24:15.708838775+00:00,2024-10-21T12:24:15.709004892Z,10,2,38,C,A,2,234.03,27,130,166117,13013886,233.8,233.96,5,400,1,2,233.71,234.0,200,2,1,1,233.7,234.1,1200,100,1,1,233.66,234.13,31,400,2,1,233.58,234.17,505,1,2,1,233.53,234.25,10,100,1,1,233.5,234.41,100,500,1,1,233.45,234.43,15,105,1,2,233.4,234.5,110,63,2,4,233.39,234.75,10,1,1,1,AAPL,0.0,0.0,0.0,
2024-10-21 12:24:15.708973640+00:00,2024-10-21T12:24:15.709139884Z,10,2,38,A,A,1,233.98,29,130,166244,13013888,233.8,233.96,5,400,1,2,233.71,233.98,200,29,1,1,233.7,234.0,1200,2,1,1,233.66,234.1,31,100,2,1,233.58,234.13,505,400,2,1,233.53,234.17,10,1,1,1,233.5,234.25,100,100,1,1,233.45,234.41,15,500,1,1,233.4,234.43,110,105,2,2,233.39,234.5,10,63,1,4,AAPL,0.0,0.0,0.0,
2024-10-21 12:24:15.716580295+00:00,2024-10-21T12:24:15.716746619Z,10,2,38,C,A,1,233.98,29,130,166324,13013896,233.8,233.96,5,400,1,2,233.71,234.0,200,2,1,1,233.7,234.1,1200,100,1,1,233.66,234.13,31,400,2,1,233.58,234.17,505,1,2,1,233.53,234.25,10,100,1,1,233.5,234.41,100,500,1,1,233.45,234.43,15,105,1,2,233.4,234.5,110,63,2,4,233.39,234.75,10,1,1,1,AAPL,0.0,0.0,0.0,
2024-10-21 12:24:17.551956961+00:00,2024-10-21T12:24:17.552123107Z,10,2,38,A,A,2,234.03,27,130,166146,13015292,233.8,233.96,5,400,1,2,233.71,234.0,200,2,1,1,233.7,234.03,1200,27,1,1,233.66,234.1,31,100,2,1,233.58,234.13,505,400,2,1,233.53,234.17,10,1,1,1,233.5,234.25,100,100,1,1,233.45,234.41,15,500,1,1,233.4,234.43,110,105,2,2,233.39,234.5,10,63,1,4,AAPL,0.0,0.0,0.0,
2024-10-21 12:24:18.858127605+00:00,2024-10-21T12:24:18.858293636Z,10,2,38,A,B,0,233.8,100,130,166031,13016509,233.8,233.96,105,400,2,2,233.71,234.0,200,2,1,1,233.7,234.03,1200,27,1,1,233.66,234.1,31,100,2,1,233.58,234.13,505,400,2,1,233.53,234.17,10,1,1,1,233.5,234.25,100,100,1,1,233.45,234.41,15,500,1,1,233.4,234.43,110,105,2,2,233.39,234.5,10,63,1,4,AAPL,100.0,100.0,100.0,
2024-10-21 12:24:25.049338154+00:00,2024-10-21T12:24:25.049504145Z,10,2,38,C,A,2,234.03,27,130,165991,13021095,233.8,233.96,105,400,2,2,233.71,234.0,200,2,1,1,233.7,234.1,1200,100,1,1,233.66,234.13,31,400,2,1,233.58,234.17,505,1,2,1,233.53,234.25,10,100,1,1,233.5,234.41,100,500,1,1,233.45,234.43,15,105,1,2,233.4,234.5,110,63,2,4,233.39,234.75,10,1,1,1,AAPL,0.0,0.0,0.0,
2024-10-21 12:24:25.049382422+00:00,2024-10-21T12:24:25.049548880Z,10,2,38,A,A,1,233.98,28,130,166458,13021096,233.8,233.96,105,400,2,2,233.71,233.98,200,28,1,1,233.7,234.0,1200,2,1,1,233.66,234.1,31,100,2,1,233.58,234.13,505,400,2,1,233.53,234.17,10,1,1,1,233.5,234.25,100,100,1,1,233.45,234.41,15,500,1,1,233.4,234.43,110,105,2,2,233.39,234.5,10,63,1,4,AAPL,0.0,0.0,0.0,
2024-10-21 12:24:25.060079940+00:00,2024-10-21T12:24:25.060245863Z,10,2,38,C,A,1,233.98,28,130,165923,13021116,233.8,233.96,105,400,2,2,233.71,234.0,200,2,1,1,233.7,234.1,1200,100,1,1,233.66,234.13,31,400,2,1,233.58,234.17,505,1,2,1,233.53,234.25,10,100,1,1,233.5,234.41,100,500,1,1,233.45,234.43,15,105,1,2,233.4,234.5,110,63,2,4,233.39,234.75,10,1,1,1,AAPL,0.0,0.0,0.0,
2024-10-21 12:24:25.922924503+00:00,2024-10-21T12:24:25.923090996Z,10,2,38,A,A,2,234.03,26,130,166493,13021866,233.8,233.96,105,400,2,2,233.71,234.0,200,2,1,1,233.7,234.03,1200,26,1,1,233.66,234.1,31,100,2,1,233.58,234.13,505,400,2,1,233.53,234.17,10,1,1,1,233.5,234.25,100,100,1,1,233.45,234.41,15,500,1,1,233.4,234.43,110,105,2,2,233.39,234.5,10,63,1,4,AAPL,0.0,0.0,0.0,
2024-10-21 12:24:33.385173258+00:00,2024-10-21T12:24:33.385339105Z,10,2,38,C,A,2,234.03,26,130,165847,13026898,233.8,233.96,105,400,2,2,233.71,234.0,200,2,1,1,233.7,234.1,1200,100,1,1,233.66,234.13,31,400,2,1,233.58,234.17,505,1,2,1,233.53,234.25,10,100,1,1,233.5,234.41,100,500,1,1,233.45,234.43,15,105,1,2,233.4,234.5,110,63,2,4,233.39,234.75,10,1,1,1,AAPL,0.0,0.0,0.0,
2024-10-21 12:24:33.385196713+00:00,2024-10-21T12:24:33.385363270Z,10,2,38,A,A,1,233.98,29,130,166557,13026899,233.8,233.96,105,400,2,2,233.71,233.98,200,29,1,1,233.7,234.0,1200,2,1,1,233.66,234.1,31,100,2,1,233.58,234.13,505,400,2,1,233.53,234.17,10,1,1,1,233.5,234.25,100,100,1,1,233.45,234.41,15,500,1,1,233.4,234.43,110,105,2,2,233.39,234.5,10,63,1,4,AAPL,0.0,0.0,0.0,
2024-10-21 12:24:33.391191505+00:00,2024-10-21T12:24:33.391357628Z,10,2,38,C,A,1,233.98,29,130,166123,13026904,233.8,233.96,105,400,2,2,233.71,234.0,200,2,1,1,233.7,234.1,1200,100,1,1,233.66,234.13,31,400,2,1,233.58,234.17,505,1,2,1,233.53,234.25,10,100,1,1,233.5,234.41,100,500,1,1,233.45,234.43,15,105,1,2,233.4,234.5,110,63,2,4,233.39,234.75,10,1,1,1,AAPL,0.0,0.0,0.0,
2024-10-21 12:24:33.923102791+00:00,2024-10-21T12:24:33.923269202Z,10,2,38,A,A,2,234.03,26,130,166411,13027549,233.8,233.96,105,400,2,2,233.71,234.0,200,2,1,1,233.7,234.03,1200,26,1,1,233.66,234.1,31,100,2,1,233.58,234.13,505,400,2,1,233.53,234.17,10,1,1,1,233.5,234.25,100,100,1,1,233.45,234.41,15,500,1,1,233.4,234.43,110,105,2,2,233.39,234.5,10,63,1,4,AAPL,0.0,0.0,0.0,
2024-10-21 12:24:37.922944460+00:00,2024-10-21T12:24:37.923110609Z,10,2,38,C,A,2,234.03,26,130,166149,13030243,233.8,233.96,105,400,2,2,233.71,234.0,200,2,1,1,233.7,234.1,1200,100,1,1,233.66,234.13,31,400,2,1,233.58,234.17,505,1,2,1,233.53,234.25,10,100,1,1,233.5,234.41,100,500,1,1,233.45,234.43,15,105,1,2,233.4,234.5,110,63,2,4,233.39,234.75,10,1,1,1,AAPL,0.0,0.0,0.0,
2024-10-21 12:24:37.923028006+00:00,2024-10-21T12:24:37.923194567Z,10,2,38,A,A,1,233.98,27,130,166561,13030244,233.8,233.96,105,400,2,2,233.71,233.98,200,27,1,1,233.7,234.0,1200,2,1,1,233.66,234.1,31,100,2,1,233.58,234.13,505,400,2,1,233.53,234.17,10,1,1,1,233.5,234.25,100,100,1,1,233.45,234.41,15,500,1,1,233.4,234.43,110,105,2,2,233.39,234.5,10,63,1,4,AAPL,0.0,0.0,0.0,
2024-10-21 12:24:40.307674730+00:00,2024-10-21T12:24:40.307842089Z,10,2,38,T,N,0,233.84,127,130,167359,13031847,233.8,233.96,105,400,2,2,233.71,233.98,200,27,1,1,233.7,234.0,1200,2,1,1,233.66,234.1,31,100,2,1,233.58,234.13,505,400,2,1,233.53,234.17,10,1,1,1,233.5,234.25,100,100,1,1,233.45,234.41,15,500,1,1,233.4,234.43,110,105,2,2,233.39,234.5,10,63,1,4,AAPL,0.0,0.0,0.0,
2024-10-21 12:24:40.307995193+00:00,2024-10-21T12:24:40.308161486Z,10,2,38,A,B,0,233.8,2,130,166293,13031848,233.8,233.96,107,400,3,2,233.71,233.98,200,27,1,1,233.7,234.0,1200,2,1,1,233.66,234.1,31,100,2,1,233.58,234.13,505,400,2,1,233.53,234.17,10,1,1,1,233.5,234.25,100,100,1,1,233.45,234.41,15,500,1,1,233.4,234.43,110,105,2,2,233.39,234.5,10,63,1,4,AAPL,2.0,2.0,2.0,
2024-10-21 12:24:40.307996031+00:00,2024-10-21T12:24:40.308163000Z,10,2,38,A,B,1,233.79,100,130,166969,13031849,233.8,233.96,107,400,3,2,233.79,233.98,100,27,1,1,233.71,234.0,200,2,1,1,233.7,234.1,1200,100,1,1,233.66,234.13,31,400,2,1,233.58,234.17,505,1,2,1,233.53,234.25,10,100,1,1,233.5,234.41,100,500,1,1,233.45,234.43,15,105,1,2,233.4,234.5,110,63,2,4,AAPL,0.0,0.0,2.0,
2024-10-21 12:24:40.308007727+00:00,2024-10-21T12:24:40.308173860Z,10,2,38,C,B,0,233.8,2,130,166133,13031850,233.8,233.96,105,400,2,2,233.79,233.98,100,27,1,1,233.71,234.0,200,2,1,1,233.7,234.1,1200,100,1,1,233.66,234.13,31,400,2,1,233.58,234.17,505,1,2,1,233.53,234.25,10,100,1,1,233.5,234.41,100,500,1,1,233.45,234.43,15,105,1,2,233.4,234.5,110,63,2,4,AAPL,-2.0,-2.0,0.0,
2024-10-21 12:24:40.308025276+00:00,2024-10-21T12:24:40.308191984Z,10,2,38,C,A,0,233.96,200,130,166708,13031851,233.8,233.96,105,200,2,1,233.79,233.98,100,27,1,1,233.71,234.0,200,2,1,1,233.7,234.1,1200,100,1,1,233.66,234.13,31,400,2,1,233.58,234.17,505,1,2,1,233.53,234.25,10,100,1,1,233.5,234.41,100,500,1,1,233.45,234.43,15,105,1,2,233.4,234.5,110,63,2,4,AAPL,200.0,200.0,200.0,
2024-10-21 12:24:40.308036005+00:00,2024-10-21T12:24:40.308202091Z,10,2,38,C,A,0,233.96,200,130,166086,13031852,233.8,233.98,105,27,2,1,233.79,234.0,100,2,1,1,233.71,234.1,200,100,1,1,233.7,234.13,1200,400,1,1,233.66,234.17,31,1,2,1,233.58,234.25,505,100,2,1,233.53,234.41,10,500,1,1,233.5,234.43,100,105,1,2,233.45,234.5,15,63,1,4,233.4,234.75,110,1,2,1,AAPL,0.0,0.0,200.0,
2024-10-21 12:24:40.308405475+00:00,2024-10-21T12:24:40.308571346Z,10,2,38,C,B,1,233.79,100,130,165871,13031857,233.8,233.98,105,27,2,1,233.71,234.0,200,2,1,1,233.7,234.1,1200,100,1,1,233.66,234.13,31,400,2,1,233.58,234.17,505,1,2,1,233.53,234.25,10,100,1,1,233.5,234.41,100,500,1,1,233.45,234.43,15,105,1,2,233.4,234.5,110,63,2,4,233.39,234.75,10,1,1,1,AAPL,0.0,0.0,200.0,
2024-10-21 12:24:40.309748359+00:00,2024-10-21T12:24:40.309914708Z,10,2,38,A,B,1,233.79,100,130,166349,13031868,233.8,233.98,105,27,2,1,233.79,234.0,100,2,1,1,233.71,234.1,200,100,1,1,233.7,234.13,1200,400,1,1,233.66,234.17,31,1,2,1,233.58,234.25,505,100,2,1,233.53,234.41,10,500,1,1,233.5,234.43,100,105,1,2,233.45,234.5,15,63,1,4,233.4,234.75,110,1,2,1,AAPL,0.0,0.0,200.0,
2024-10-21 12:24:40.310193512+00:00,2024-10-21T12:24:40.310359600Z,10,2,38,C,B,1,233.79,100,130,166088,13031873,233.8,233.98,105,27,2,1,233.71,234.0,200,2,1,1,233.7,234.1,1200,100,1,1,233.66,234.13,31,400,2,1,233.58,234.17,505,1,2,1,233.53,234.25,10,100,1,1,233.5,234.41,100,500,1,1,233.45,234.43,15,105,1,2,233.4,234.5,110,63,2,4,233.39,234.75,10,1,1,1,AAPL,0.0,0.0,200.0,
2024-10-21 12:24:40.353810051+00:00,2024-10-21T12:24:40.353976280Z,10,2,38,A,A,0,233.96,200,130,166229,13031906,233.8,233.96,105,200,2,1,233.71,233.98,200,27,1,1,233.7,234.0,1200,2,1,1,233.66,234.1,31,100,2,1,233.58,234.13,505,400,2,1,233.53,234.17,10,1,1,1,233.5,234.25,100,100,1,1,233.45,234.41,15,500,1,1,233.4,234.43,110,105,2,2,233.39,234.5,10,63,1,4,AAPL,0.0,0.0,200.0,
2024-10-21 12:24:40.377247665+00:00,2024-10-21T12:24:40.377414086Z,10,2,38,C,A,0,233.96,200,130,166421,13031918,233.8,233.98,105,27,2,1,233.71,234.0,200,2,1,1,233.7,234.1,1200,100,1,1,233.66,234.13,31,400,2,1,233.58,234.17,505,1,2,1,233.53,234.25,10,100,1,1,233.5,234.41,100,500,1,1,233.45,234.43,15,105,1,2,233.4,234.5,110,63,2,4,233.39,234.75,10,1,1,1,AAPL,0.0,0.0,200.0,
2024-10-21 12:24:40.379809120+00:00,2024-10-21T12:24:40.379975554Z,10,2,38,C,A,0,233.98,27,130,166434,13031919,233.8,234.0,105,2,2,1,233.71,234.1,200,100,1,1,233.7,234.13,1200,400,1,1,233.66,234.17,31,1,2,1,233.58,234.25,505,100,2,1,233.53,234.41,10,500,1,1,233.5,234.43,100,105,1,2,233.45,234.5,15,63,1,4,233.4,234.75,110,1,2,1,233.39,234.79,10,2000,1,1,AAPL,0.0,0.0,200.0,
2024-10-21 12:24:40.415871461+00:00,2024-10-21T12:24:40.416037866Z,10,2,38,A,A,1,234.02,200,130,166405,13031935,233.8,234.0,105,2,2,1,233.71,234.02,200,200,1,1,233.7,234.1,1200,100,1,1,233.66,234.13,31,400,2,1,233.58,234.17,505,1,2,1,233.53,234.25,10,100,1,1,233.5,234.41,100,500,1,1,233.45,234.43,15,105,1,2,233.4,234.5,110,63,2,4,233.39,234.75,10,1,1,1,AAPL,0.0,0.0,200.0,
2024-10-21 12:24:40.464828695+00:00,2024-10-21T12:24:40.464995283Z,10,2,38,A,A,1,234.02,200,130,166588,13031977,233.8,234.0,105,2,2,1,233.71,234.02,200,400,1,2,233.7,234.1,1200,100,1,1,233.66,234.13,31,400,2,1,233.58,234.17,505,1,2,1,233.53,234.25,10,100,1,1,233.5,234.41,100,500,1,1,233.45,234.43,15,105,1,2,233.4,234.5,110,63,2,4,233.39,234.75,10,1,1,1,AAPL,0.0,-200.0,200.0,
2024-10-21 12:24:40.656837789+00:00,2024-10-21T12:24:40.657004232Z,10,2,38,C,B,1,233.71,200,130,166443,13032132,233.8,234.0,105,2,2,1,233.7,234.02,1200,400,1,2,233.66,234.1,31,100,2,1,233.58,234.13,505,400,2,1,233.53,234.17,10,1,1,1,233.5,234.25,100,100,1,1,233.45,234.41,15,500,1,1,233.4,234.43,110,105,2,2,233.39,234.5,10,63,1,4,233.31,234.75,110,1,2,1,AAPL,0.0,0.0,200.0,
2024-10-21 12:24:40.763590881+00:00,2024-10-21T12:24:40.763757375Z,10,2,38,A,B,1,233.71,200,130,166494,13032319,233.8,234.0,105,2,2,1,233.71,234.02,200,400,1,2,233.7,234.1,1200,100,1,1,233.66,234.13,31,400,2,1,233.58,234.17,505,1,2,1,233.53,234.25,10,100,1,1,233.5,234.41,100,500,1,1,233.45,234.43,15,105,1,2,233.4,234.5,110,63,2,4,233.39,234.75,10,1,1,1,AAPL,0.0,0.0,200.0,
2024-10-21 12:24:43.066357159+00:00,2024-10-21T12:24:43.066523534Z,10,2,38,A,B,0,233.88,1,130,166375,13033852,233.88,234.0,1,2,1,1,233.8,234.02,105,400,2,2,233.71,234.1,200,100,1,1,233.7,234.13,1200,400,1,1,233.66,234.17,31,1,2,1,233.58,234.25,505,100,2,1,233.53,234.41,10,500,1,1,233.5,234.43,100,105,1,2,233.45,234.5,15,63,1,4,233.4,234.75,110,1,2,1,AAPL,0.0,0.0,0.0,
2024-10-21 12:24:43.129440388+00:00,2024-10-21T12:24:43.129607008Z,10,2,38,A,A,2,234.09,27,130,166620,13033910,233.88,234.0,1,2,1,1,233.8,234.02,105,400,2,2,233.71,234.09,200,27,1,1,233.7,234.1,1200,100,1,1,233.66,234.13,31,400,2,1,233.58,234.17,505,1,2,1,233.53,234.25,10,100,1,1,233.5,234.41,100,500,1,1,233.45,234.43,15,105,1,2,233.4,234.5,110,63,2,4,AAPL,0.0,0.0,0.0,
2024-10-21 12:24:55.149943017+00:00,2024-10-21T12:24:55.150110202Z,10,2,38,T,A,0,233.88,1,130,167185,13042533,233.88,234.0,1,2,1,1,233.8,234.02,105,400,2,2,233.71,234.09,200,27,1,1,233.7,234.1,1200,100,1,1,233.66,234.13,31,400,2,1,233.58,234.17,505,1,2,1,233.53,234.25,10,100,1,1,233.5,234.41,100,500,1,1,233.45,234.43,15,105,1,2,233.4,234.5,110,63,2,4,AAPL,0.0,0.0,0.0,
2024-10-21 12:24:55.149943017+00:00,2024-10-21T12:24:55.150110202Z,10,2,38,C,B,0,233.88,1,130,167185,13042533,233.8,234.0,105,2,2,1,233.71,234.02,200,400,1,2,233.7,234.09,1200,27,1,1,233.66,234.1,31,100,2,1,233.58,234.13,505,400,2,1,233.53,234.17,10,1,1,1,233.5,234.25,100,100,1,1,233.45,234.41,15,500,1,1,233.4,234.43,110,105,2,2,233.39,234.5,10,63,1,4,AAPL,0.0,0.0,0.0,
2024-10-21 12:24:55.149972348+00:00,2024-10-21T12:24:55.150138721Z,10,2,38,A,A,0,233.94,38,130,166373,13042534,233.8,233.94,105,38,2,1,233.71,234.0,200,2,1,1,233.7,234.02,1200,400,1,2,233.66,234.09,31,27,2,1,233.58,234.1,505,100,2,1,233.53,234.13,10,400,1,1,233.5,234.17,100,1,1,1,233.45,234.25,15,100,1,1,233.4,234.41,110,500,2,1,233.39,234.43,10,105,1,2,AAPL,0.0,0.0,0.0,
2024-10-21 12:24:55.149990092+00:00,2024-10-21T12:24:55.150156298Z,10,2,38,A,A,0,233.94,26,130,166206,13042535,233.8,233.94,105,64,2,2,233.71,234.0,200,2,1,1,233.7,234.02,1200,400,1,2,233.66,234.09,31,27,2,1,233.58,234.1,505,100,2,1,233.53,234.13,10,400,1,1,233.5,234.17,100,1,1,1,233.45,234.25,15,100,1,1,233.4,234.41,110,500,2,1,233.39,234.43,10,105,1,2,AAPL,-26.0,-26.0,-26.0,
2024-10-21 12:24:55.150004189+00:00,2024-10-21T12:24:55.150170265Z,10,2,38,A,A,1,233.98,26,130,166076,13042536,233.8,233.94,105,64,2,2,233.71,233.98,200,26,1,1,233.7,234.0,1200,2,1,1,233.66,234.02,31,400,2,2,233.58,234.09,505,27,2,1,233.53,234.1,10,100,1,1,233.5,234.13,100,400,1,1,233.45,234.17,15,1,1,1,233.4,234.25,110,100,2,1,233.39,234.41,10,500,1,1,AAPL,0.0,0.0,-26.0,
2024-10-21 12:24:55.250051974+00:00,2024-10-21T12:24:55.250218188Z,10,2,38,C,A,0,233.94,38,130,166214,13042633,233.8,233.94,105,26,2,1,233.71,233.98,200,26,1,1,233.7,234.0,1200,2,1,1,233.66,234.02,31,400,2,2,233.58,234.09,505,27,2,1,233.53,234.1,10,100,1,1,233.5,234.13,100,400,1,1,233.45,234.17,15,1,1,1,233.4,234.25,110,100,2,1,233.39,234.41,10,500,1,1,AAPL,38.0,38.0,12.0,
2024-10-21 12:24:55.250079517+00:00,2024-10-21T12:24:55.250245636Z,10,2,38,C,A,1,233.98,26,130,166119,13042634,233.8,233.94,105,26,2,1,233.71,234.0,200,2,1,1,233.7,234.02,1200,400,1,2,233.66,234.09,31,27,2,1,233.58,234.1,505,100,2,1,233.53,234.13,10,400,1,1,233.5,234.17,100,1,1,1,233.45,234.25,15,100,1,1,233.4,234.41,110,500,2,1,233.39,234.43,10,105,1,2,AAPL,0.0,0.0,12.0,
2024-10-21 12:24:55.403764807+00:00,2024-10-21T12:24:55.403930872Z,10,2,38,C,A,0,233.94,26,130,166065,13042985,233.8,234.0,105,2,2,1,233.71,234.02,200,400,1,2,233.7,234.09,1200,27,1,1,233.66,234.1,31,100,2,1,233.58,234.13,505,400,2,1,233.53,234.17,10,1,1,1,233.5,234.25,100,100,1,1,233.45,234.41,15,500,1,1,233.4,234.43,110,105,2,2,233.39,234.5,10,63,1,4,AAPL,0.0,0.0,12.0,
2024-10-21 12:24:58.866984470+00:00,2024-10-21T12:24:58.867150506Z,10,2,38,A,A,0,233.95,200,130,166036,13044827,233.8,233.95,105,200,2,1,233.71,234.0,200,2,1,1,233.7,234.02,1200,400,1,2,233.66,234.09,31,27,2,1,233.58,234.1,505,100,2,1,233.53,234.13,10,400,1,1,233.5,234.17,100,1,1,1,233.45,234.25,15,100,1,1,233.4,234.41,110,500,2,1,233.39,234.43,10,105,1,2,AAPL,0.0,0.0,0.0,
2024-10-21 12:25:00.039201756+00:00,2024-10-21T12:25:00.039367879Z,10,2,38,C,A,3,234.09,27,130,166123,13045779,233.8,233.95,105,200,2,1,233.71,234.0,200,2,1,1,233.7,234.02,1200,400,1,2,233.66,234.1,31,100,2,1,233.58,234.13,505,400,2,1,233.53,234.17,10,1,1,1,233.5,234.25,100,100,1,1,233.45,234.41,15,500,1,1,233.4,234.43,110,105,2,2,233.39,234.5,10,63,1,4,AAPL,0.0,0.0,0.0,
2024-10-21 12:25:00.039255807+00:00,2024-10-21T12:25:00.039422307Z,10,2,38,C,B,3,233.66,30,130,166500,13045782,233.8,233.95,105,200,2,1,233.71,234.0,200,2,1,1,233.7,234.02,1200,400,1,2,233.66,234.1,1,100,1,1,233.58,234.13,505,400,2,1,233.53,234.17,10,1,1,1,233.5,234.25,100,100,1,1,233.45,234.41,15,500,1,1,233.4,234.43,110,105,2,2,233.39,234.5,10,63,1,4,AAPL,0.0,-30.0,0.0,
2024-10-21 12:25:00.940301280+00:00,2024-10-21T12:25:00.940467712Z,10,2,38,A,B,0,233.81,1,130,166432,13048050,233.81,233.95,1,200,1,1,233.8,234.0,105,2,2,1,233.71,234.02,200,400,1,2,233.7,234.1,1200,100,1,1,233.66,234.13,1,400,1,1,233.58,234.17,505,1,2,1,233.53,234.25,10,100,1,1,233.5,234.41,100,500,1,1,233.45,234.43,15,105,1,2,233.4,234.5,110,63,2,4,AAPL,0.0,0.0,0.0,
2024-10-21 12:25:03.425959742+00:00,2024-10-21T12:25:03.426126208Z,10,2,38,A,A,1,233.97,7,130,166466,13052492,233.81,233.95,1,200,1,1,233.8,233.97,105,7,2,1,233.71,234.0,200,2,1,1,233.7,234.02,1200,400,1,2,233.66,234.1,1,100,1,1,233.58,234.13,505,400,2,1,233.53,234.17,10,1,1,1,233.5,234.25,100,100,1,1,233.45,234.41,15,500,1,1,233.4,234.43,110,105,2,2,AAPL,0.0,0.0,0.0,
2024-10-21 12:25:07.929021771+00:00,2024-10-21T12:25:07.929188046Z,10,2,38,C,A,3,234.02,200,130,166275,13057385,233.81,233.95,1,200,1,1,233.8,233.97,105,7,2,1,233.71,234.0,200,2,1,1,233.7,234.02,1200,200,1,1,233.66,234.1,1,100,1,1,233.58,234.13,505,400,2,1,233.53,234.17,10,1,1,1,233.5,234.25,100,100,1,1,233.45,234.41,15,500,1,1,233.4,234.43,110,105,2,2,AAPL,0.0,200.0,0.0,
2024-10-21 12:25:07.929036599+00:00,2024-10-21T12:25:07.929203389Z,10,2,38,A,A,3,234.01,400,130,166790,13057386,233.81,233.95,1,200,1,1,233.8,233.97,105,7,2,1,233.71,234.0,200,2,1,1,233.7,234.01,1200,400,1,1,233.66,234.1,1,100,1,1,233.58,234.13,505,400,2,1,233.53,234.17,10,1,1,1,233.5,234.25,100,100,1,1,233.45,234.41,15,500,1,1,233.4,234.43,110,105,2,2,AAPL,0.0,0.0,0.0,
2024-10-21 12:25:08.718962947+00:00,2024-10-21T12:25:08.719128994Z,10,2,38,C,A,1,233.97,7,130,166047,13057965,233.81,233.95,1,200,1,1,233.8,234.0,105,2,2,1,233.71,234.01,200,400,1,1,233.7,234.1,1200,100,1,1,233.66,234.13,1,400,1,1,233.58,234.17,505,1,2,1,233.53,234.25,10,100,1,1,233.5,234.41,100,500,1,1,233.45,234.43,15,105,1,2,233.4,234.5,110,63,2,4,AAPL,0.0,0.0,0.0,
2024-10-21 12:25:08.828413687+00:00,2024-10-21T12:25:08.828580021Z,10,2,38,A,B,0,233.85,100,130,166334,13058052,233.85,233.95,100,200,1,1,233.81,234.0,1,2,1,1,233.8,234.01,105,400,2,1,233.71,234.1,200,100,1,1,233.7,234.13,1200,400,1,1,233.66,234.17,1,1,1,1,233.58,234.25,505,100,2,1,233.53,234.41,10,500,1,1,233.5,234.43,100,105,1,2,233.45,234.5,15,63,1,4,AAPL,0.0,0.0,0.0,
2024-10-21 12:25:09.009866477+00:00,2024-10-21T12:25:09.010032581Z,10,2,38,C,B,3,233.71,200,130,166104,13058226,233.85,233.95,100,200,1,1,233.81,234.0,1,2,1,1,233.8,234.01,105,400,2,1,233.7,234.1,1200,100,1,1,233.66,234.13,1,400,1,1,233.58,234.17,505,1,2,1,233.53,234.25,10,100,1,1,233.5,234.41,100,500,1,1,233.45,234.43,15,105,1,2,233.4,234.5,110,63,2,4,AAPL,0.0,0.0,0.0,
2024-10-21 12:25:09.009890544+00:00,2024-10-21T12:25:09.010056790Z,10,2,38,A,B,4,233.69,200,130,166246,13058227,233.85,233.95,100,200,1,1,233.81,234.0,1,2,1,1,233.8,234.01,105,400,2,1,233.7,234.1,1200,100,1,1,233.69,234.13,200,400,1,1,233.66,234.17,1,1,1,1,233.58,234.25,505,100,2,1,233.53,234.41,10,500,1,1,233.5,234.43,100,105,1,2,233.45,234.5,15,63,1,4,AAPL,0.0,0.0,0.0,
2024-10-21 12:25:09.088777165+00:00,2024-10-21T12:25:09.088943398Z,10,2,38,A,B,4,233.69,200,130,166233,13058312,233.85,233.95,100,200,1,1,233.81,234.0,1,2,1,1,233.8,234.01,105,400,2,1,233.7,234.1,1200,100,1,1,233.69,234.13,400,400,2,1,233.66,234.17,1,1,1,1,233.58,234.25,505,100,2,1,233.53,234.41,10,500,1,1,233.5,234.43,100,105,1,2,233.45,234.5,15,63,1,4,AAPL,0.0,200.0,0.0,
2024-10-21 12:25:09.146677151+00:00,2024-10-21T12:25:09.146843023Z,10,2,38,C,B,4,233.69,200,130,165872,13058371,233.85,233.95,100,200,1,1,233.81,234.0,1,2,1,1,233.8,234.01,105,400,2,1,233.7,234.1,1200,100,1,1,233.69,234.13,200,400,1,1,233.66,234.17,1,1,1,1,233.58,234.25,505,100,2,1,233.53,234.41,10,500,1,1,233.5,234.43,100,105,1,2,233.45,234.5,15,63,1,4,AAPL,0.0,-200.0,0.0,
2024-10-21 12:25:09.146689798+00:00,2024-10-21T12:25:09.146855993Z,10,2,38,A,B,3,233.72,400,130,166195,13058372,233.85,233.95,100,200,1,1,233.81,234.0,1,2,1,1,233.8,234.01,105,400,2,1,233.72,234.1,400,100,1,1,233.7,234.13,1200,400,1,1,233.66,234.17,1,1,1,1,233.58,234.25,505,100,2,1,233.53,234.41,10,500,1,1,233.5,234.43,100,105,1,2,233.45,234.5,15,63,1,4,AAPL,0.0,0.0,0.0,
2024-10-21 12:25:09.325236301+00:00,2024-10-21T12:25:09.325402278Z,10,2,38,C,B,3,233.72,400,130,165977,13058695,233.85,233.95,100,200,1,1,233.81,234.0,1,2,1,1,233.8,234.01,105,400,2,1,233.7,234.1,1200,100,1,1,233.66,234.13,1,400,1,1,233.58,234.17,505,1,2,1,233.53,234.25,10,100,1,1,233.5,234.41,100,500,1,1,233.45,234.43,15,105,1,2,233.4,234.5,110,63,2,4,AAPL,0.0,0.0,0.0,
2024-10-21 12:25:09.325248668+00:00,2024-10-21T12:25:09.325415366Z,10,2,38,A,B,4,233.69,200,130,166698,13058696,233.85,233.95,100,200,1,1,233.81,234.0,1,2,1,1,233.8,234.01,105,400,2,1,233.7,234.1,1200,100,1,1,233.69,234.13,200,400,1,1,233.66,234.17,1,1,1,1,233.58,234.25,505,100,2,1,233.53,234.41,10,500,1,1,233.5,234.43,100,105,1,2,233.45,234.5,15,63,1,4,AAPL,0.0,0.0,0.0,
2024-10-21 12:25:09.630030450+00:00,2024-10-21T12:25:09.630196737Z,10,2,38,A,B,4,233.69,200,130,166287,13059010,233.85,233.95,100,200,1,1,233.81,234.0,1,2,1,1,233.8,234.01,105,400,2,1,233.7,234.1,1200,100,1,1,233.69,234.13,400,400,2,1,233.66,234.17,1,1,1,1,233.58,234.25,505,100,2,1,233.53,234.41,10,500,1,1,233.5,234.43,100,105,1,2,233.45,234.5,15,63,1,4,AAPL,0.0,200.0,0.0,
2024-10-21 12:25:09.684292780+00:00,2024-10-21T12:25:09.684458949Z,10,2,38,C,B,4,233.69,200,130,166169,13059061,233.85,233.95,100,200,1,1,233.81,234.0,1,2,1,1,233.8,234.01,105,400,2,1,233.7,234.1,1200,100,1,1,233.69,234.13,200,400,1,1,233.66,234.17,1,1,1,1,233.58,234.25,505,100,2,1,233.53,234.41,10,500,1,1,233.5,234.43,100,105,1,2,233.45,234.5,15,63,1,4,AAPL,0.0,-200.0,0.0,
2024-10-21 12:25:09.684305729+00:00,2024-10-21T12:25:09.684472400Z,10,2,38,A,B,3,233.72,400,130,166671,13059062,233.85,233.95,100,200,1,1,233.81,234.0,1,2,1,1,233.8,234.01,105,400,2,1,233.72,234.1,400,100,1,1,233.7,234.13,1200,400,1,1,233.66,234.17,1,1,1,1,233.58,234.25,505,100,2,1,233.53,234.41,10,500,1,1,233.5,234.43,100,105,1,2,233.45,234.5,15,63,1,4,AAPL,0.0,0.0,0.0,
2024-10-21 12:25:10.726127491+00:00,2024-10-21T12:25:10.726294001Z,10,2,38,A,A,1,233.98,7,130,166510,13060271,233.85,233.95,100,200,1,1,233.81,233.98,1,7,1,1,233.8,234.0,105,2,2,1,233.72,234.01,400,400,1,1,233.7,234.1,1200,100,1,1,233.66,234.13,1,400,1,1,233.58,234.17,505,1,2,1,233.53,234.25,10,100,1,1,233.5,234.41,100,500,1,1,233.45,234.43,15,105,1,2,AAPL,0.0,0.0,0.0,
2024-10-21 12:25:16.348283664+00:00,2024-10-21T12:25:16.348450351Z,10,2,38,A,B,3,233.77,200,130,166687,13064852,233.85,233.95,100,200,1,1,233.81,233.98,1,7,1,1,233.8,234.0,105,2,2,1,233.77,234.01,200,400,1,1,233.7,234.1,1200,100,1,1,233.66,234.13,1,400,1,1,233.58,234.17,505,1,2,1,233.53,234.25,10,100,1,1,233.5,234.41,100,500,1,1,233.45,234.43,15,105,1,2,AAPL,0.0,0.0,0.0,
2024-10-21 12:25:25.279408267+00:00,2024-10-21T12:25:25.279574162Z,10,2,38,C,B,3,233.77,200,130,165895,13072236,233.85,233.95,100,200,1,1,233.81,233.98,1,7,1,1,233.8,234.0,105,2,2,1,233.7,234.01,1200,400,1,1,233.66,234.1,1,100,1,1,233.58,234.13,505,400,2,1,233.53,234.17,10,1,1,1,233.5,234.25,100,100,1,1,233.45,234.41,15,500,1,1,233.4,234.43,110,105,2,2,AAPL,0.0,0.0,0.0,
2024-10-21 12:25:25.279420038+00:00,2024-10-21T12:25:25.279586508Z,10,2,38,A,B,3,233.75,200,130,166470,13072237,233.85,233.95,100,200,1,1,233.81,233.98,1,7,1,1,233.8,234.0,105,2,2,1,233.75,234.01,200,400,1,1,233.7,234.1,1200,100,1,1,233.66,234.13,1,400,1,1,233.58,234.17,505,1,2,1,233.53,234.25,10,100,1,1,233.5,234.41,100,500,1,1,233.45,234.43,15,105,1,2,AAPL,0.0,0.0,0.0,
2024-10-21 12:25:25.341543400+00:00,2024-10-21T12:25:25.341710080Z,10,2,38,A,A,2,234.0,400,130,166680,13072382,233.85,233.95,100,200,1,1,233.81,233.98,1,7,1,1,233.8,234.0,105,402,2,2,233.75,234.1,200,100,1,1,233.7,234.13,1200,400,1,1,233.66,234.17,1,1,1,1,233.58,234.25,505,100,2,1,233.53,234.41,10,500,1,1,233.5,234.43,100,105,1,2,233.45,234.5,15,63,1,4,AAPL,0.0,-400.0,0.0,
2024-10-21 12:25:26.789218710+00:00,2024-10-21T12:25:26.789385215Z,10,2,38,A,A,2,233.99,400,130,166505,13074488,233.85,233.95,100,200,1,1,233.81,233.98,1,7,1,1,233.8,233.99,105,400,2,1,233.75,234.0,200,2,1,1,233.7,234.1,1200,100,1,1,233.66,234.13,1,400,1,1,233.58,234.17,505,1,2,1,233.53,234.25,10,100,1,1,233.5,234.41,100,500,1,1,233.45,234.43,15,105,1,2,AAPL,0.0,0.0,0.0,
2024-10-21 12:25:34.805904261+00:00,2024-10-21T12:25:34.806070616Z,10,2,38,A,B,0,233.86,4,130,166355,13082761,233.86,233.95,4,200,1,1,233.85,233.98,100,7,1,1,233.81,233.99,1,400,1,1,233.8,234.0,105,2,2,1,233.75,234.1,200,100,1,1,233.7,234.13,1200,400,1,1,233.66,234.17,1,1,1,1,233.58,234.25,505,100,2,1,233.53,234.41,10,500,1,1,233.5,234.43,100,105,1,2,AAPL,0.0,0.0,0.0,
2024-10-21 12:25:34.806661445+00:00,2024-10-21T12:25:34.806829112Z,10,2,38,C,B,0,233.86,4,130,167667,13082762,233.85,233.95,100,200,1,1,233.81,233.98,1,7,1,1,233.8,233.99,105,400,2,1,233.75,234.0,200,2,1,1,233.7,234.1,1200,100,1,1,233.66,234.13,1,400,1,1,233.58,234.17,505,1,2,1,233.53,234.25,10,100,1,1,233.5,234.41,100,500,1,1,233.45,234.43,15,105,1,2,AAPL,0.0,0.0,0.0,
2024-10-21 12:25:34.806990464+00:00,2024-10-21T12:25:34.807157514Z,10,2,38,T,N,0,233.93,100,130,167050,13082763,233.85,233.95,100,200,1,1,233.81,233.98,1,7,1,1,233.8,233.99,105,400,2,1,233.75,234.0,200,2,1,1,233.7,234.1,1200,100,1,1,233.66,234.13,1,400,1,1,233.58,234.17,505,1,2,1,233.53,234.25,10,100,1,1,233.5,234.41,100,500,1,1,233.45,234.43,15,105,1,2,AAPL,0.0,0.0,0.0,
2024-10-21 12:25:35.054480586+00:00,2024-10-21T12:25:35.054650784Z,10,2,38,T,N,0,233.91,101,0,170198,13083003,233.85,233.95,100,200,1,1,233.81,233.98,1,7,1,1,233.8,233.99,105,400,2,1,233.75,234.0,200,2,1,1,233.7,234.1,1200,100,1,1,233.66,234.13,1,400,1,1,233.58,234.17,505,1,2,1,233.53,234.25,10,100,1,1,233.5,234.41,100,500,1,1,233.45,234.43,15,105,1,2,AAPL,0.0,0.0,0.0,
2024-10-21 12:25:35.054480586+00:00,2024-10-21T12:25:35.054650784Z,10,2,38,T,N,0,233.93,50,0,170198,13083004,233.85,233.95,100,200,1,1,233.81,233.98,1,7,1,1,233.8,233.99,105,400,2,1,233.75,234.0,200,2,1,1,233.7,234.1,1200,100,1,1,233.66,234.13,1,400,1,1,233.58,234.17,505,1,2,1,233.53,234.25,10,100,1,1,233.5,234.41,100,500,1,1,233.45,234.43,15,105,1,2,AAPL,0.0,0.0,0.0,
2024-10-21 12:25:35.054480586+00:00,2024-10-21T12:25:35.054650784Z,10,2,38,T,B,0,233.95,79,130,170198,13083005,233.85,233.95,100,200,1,1,233.81,233.98,1,7,1,1,233.8,233.99,105,400,2,1,233.75,234.0,200,2,1,1,233.7,234.1,1200,100,1,1,233.66,234.13,1,400,1,1,233.58,234.17,505,1,2,1,233.53,234.25,10,100,1,1,233.5,234.41,100,500,1,1,233.45,234.43,15,105,1,2,AAPL,0.0,0.0,0.0,
2024-10-21 12:25:35.054480586+00:00,2024-10-21T12:25:35.054650784Z,10,2,38,C,A,0,233.95,79,130,170198,13083005,233.85,233.95,100,121,1,1,233.81,233.98,1,7,1,1,233.8,233.99,105,400,2,1,233.75,234.0,200,2,1,1,233.7,234.1,1200,100,1,1,233.66,234.13,1,400,1,1,233.58,234.17,505,1,2,1,233.53,234.25,10,100,1,1,233.5,234.41,100,500,1,1,233.45,234.43,15,105,1,2,AAPL,79.0,79.0,79.0,
2024-10-21 12:25:35.054558163+00:00,2024-10-21T12:25:35.054724289Z,10,2,38,C,A,2,233.99,400,130,166126,13083006,233.85,233.95,100,121,1,1,233.81,233.98,1,7,1,1,233.8,234.0,105,2,2,1,233.75,234.1,200,100,1,1,233.7,234.13,1200,400,1,1,233.66,234.17,1,1,1,1,233.58,234.25,505,100,2,1,233.53,234.41,10,500,1,1,233.5,234.43,100,105,1,2,233.45,234.5,15,63,1,4,AAPL,0.0,0.0,79.0,
2024-10-21 12:25:35.064902310+00:00,2024-10-21T12:25:35.065068431Z,10,2,38,A,A,2,234.0,200,130,166121,13083015,233.85,233.95,100,121,1,1,233.81,233.98,1,7,1,1,233.8,234.0,105,202,2,2,233.75,234.1,200,100,1,1,233.7,234.13,1200,400,1,1,233.66,234.17,1,1,1,1,233.58,234.25,505,100,2,1,233.53,234.41,10,500,1,1,233.5,234.43,100,105,1,2,233.45,234.5,15,63,1,4,AAPL,0.0,-200.0,79.0,
2024-10-21 12:25:35.147671307+00:00,2024-10-21T12:25:35.147837274Z,10,2,38,A,A,2,234.0,200,130,165967,13083092,233.85,233.95,100,121,1,1,233.81,233.98,1,7,1,1,233.8,234.0,105,402,2,3,233.75,234.1,200,100,1,1,233.7,234.13,1200,400,1,1,233.66,234.17,1,1,1,1,233.58,234.25,505,100,2,1,233.53,234.41,10,500,1,1,233.5,234.43,100,105,1,2,233.45,234.5,15,63,1,4,AAPL,0.0,-200.0,79.0,
2024-10-21 12:25:37.149112390+00:00,2024-10-21T12:25:37.149278847Z,10,2,38,C,A,1,233.98,7,130,166457,13084951,233.85,233.95,100,121,1,1,233.81,234.0,1,402,1,3,233.8,234.1,105,100,2,1,233.75,234.13,200,400,1,1,233.7,234.17,1200,1,1,1,233.66,234.25,1,100,1,1,233.58,234.41,505,500,2,1,233.53,234.43,10,105,1,2,233.5,234.5,100,63,1,4,233.45,234.59,15,60,1,1,AAPL,0.0,0.0,0.0,
2024-10-21 12:25:39.151789847+00:00,2024-10-21T12:25:39.151956133Z,10,2,38,A,A,8,234.44,7,130,166286,13087130,233.85,233.95,100,121,1,1,233.81,234.0,1,402,1,3,233.8,234.1,105,100,2,1,233.75,234.13,200,400,1,1,233.7,234.17,1200,1,1,1,233.66,234.25,1,100,1,1,233.58,234.41,505,500,2,1,233.53,234.43,10,105,1,2,233.5,234.44,100,7,1,1,233.45,234.5,15,63,1,4,AAPL,0.0,0.0,0.0,
2024-10-21 12:25:43.597387033+00:00,2024-10-21T12:25:43.597553367Z,10,2,38,A,B,3,233.76,200,130,166334,13091002,233.85,233.95,100,121,1,1,233.81,234.0,1,402,1,3,233.8,234.1,105,100,2,1,233.76,234.13,200,400,1,1,233.7,234.17,1200,1,1,1,233.66,234.25,1,100,1,1,233.58,234.41,505,500,2,1,233.53,234.43,10,105,1,2,233.5,234.44,100,7,1,1,233.45,234.5,15,63,1,4,AAPL,0.0,0.0,0.0,
2024-10-21 12:25:45.063448661+00:00,2024-10-21T12:25:45.063614991Z,10,2,38,A,B,3,233.77,200,130,166330,13092718,233.85,233.95,100,121,1,1,233.81,234.0,1,402,1,3,233.8,234.1,105,100,2,1,233.77,234.13,200,400,1,1,233.7,234.17,1200,1,1,1,233.66,234.25,1,100,1,1,233.58,234.41,505,500,2,1,233.53,234.43,10,105,1,2,233.5,234.44,100,7,1,1,233.45,234.5,15,63,1,4,AAPL,0.0,0.0,0.0,
2024-10-21 12:25:52.757291105+00:00,2024-10-21T12:25:52.757457183Z,10,2,38,C,B,3,233.77,200,130,166078,13098338,233.85,233.95,100,121,1,1,233.81,234.0,1,402,1,3,233.8,234.1,105,100,2,1,233.7,234.13,1200,400,1,1,233.66,234.17,1,1,1,1,233.58,234.25,505,100,2,1,233.53,234.41,10,500,1,1,233.5,234.43,100,105,1,2,233.45,234.44,15,7,1,1,233.4,234.5,110,63,2,4,AAPL,0.0,0.0,0.0,
2024-10-21 12:25:52.757304269+00:00,2024-10-21T12:25:52.757470818Z,10,2,38,A,B,3,233.75,200,130,166549,13098339,233.85,233.95,100,121,1,1,233.81,234.0,1,402,1,3,233.8,234.1,105,100,2,1,233.75,234.13,200,400,1,1,233.7,234.17,1200,1,1,1,233.66,234.25,1,100,1,1,233.58,234.41,505,500,2,1,233.53,234.43,10,105,1,2,233.5,234.44,100,7,1,1,233.45,234.5,15,63,1,4,AAPL,0.0,0.0,0.0,
2024-10-21 12:25:54.873237392+00:00,2024-10-21T12:25:54.873403967Z,10,2,38,A,B,1,233.81,1,130,166575,13100599,233.85,233.95,100,121,1,1,233.81,234.0,2,402,2,3,233.8,234.1,105,100,2,1,233.75,234.13,200,400,1,1,233.7,234.17,1200,1,1,1,233.66,234.25,1,100,1,1,233.58,234.41,505,500,2,1,233.53,234.43,10,105,1,2,233.5,234.44,100,7,1,1,233.45,234.5,15,63,1,4,AAPL,0.0,1.0,0.0,
2024-10-21 12:26:00.405695962+00:00,2024-10-21T12:26:00.405862083Z,10,2,38,C,A,8,234.44,7,130,166121,13106337,233.85,233.95,100,121,1,1,233.81,234.0,2,402,2,3,233.8,234.1,105,100,2,1,233.75,234.13,200,400,1,1,233.7,234.17,1200,1,1,1,233.66,234.25,1,100,1,1,233.58,234.41,505,500,2,1,233.53,234.43,10,105,1,2,233.5,234.5,100,63,1,4,233.45,234.59,15,60,1,1,AAPL,0.0,0.0,0.0,
2024-10-21 12:26:01.715279752+00:00,2024-10-21T12:26:01.715446829Z,10,2,38,A,B,3,233.76,200,130,167077,13108880,233.85,233.95,100,121,1,1,233.81,234.0,2,402,2,3,233.8,234.1,105,100,2,1,233.76,234.13,200,400,1,1,233.7,234.17,1200,1,1,1,233.66,234.25,1,100,1,1,233.58,234.41,505,500,2,1,233.53,234.43,10,105,1,2,233.5,234.5,100,63,1,4,233.45,234.59,15,60,1,1,AAPL,0.0,0.0,0.0,
2024-10-21 12:26:02.221924482+00:00,2024-10-21T12:26:02.222090992Z,10,2,38,A,B,3,233.77,200,130,166510,13109908,233.85,233.95,100,121,1,1,233.81,234.0,2,402,2,3,233.8,234.1,105,100,2,1,233.77,234.13,200,400,1,1,233.7,234.17,1200,1,1,1,233.66,234.25,1,100,1,1,233.58,234.41,505,500,2,1,233.53,234.43,10,105,1,2,233.5,234.5,100,63,1,4,233.45,234.59,15,60,1,1,AAPL,0.0,0.0,0.0,
2024-10-21 12:26:02.408536304+00:00,2024-10-21T12:26:02.408702630Z,10,2,38,A,A,2,234.07,7,130,166326,13110618,233.85,233.95,100,121,1,1,233.81,234.0,2,402,2,3,233.8,234.07,105,7,2,1,233.77,234.1,200,100,1,1,233.7,234.13,1200,400,1,1,233.66,234.17,1,1,1,1,233.58,234.25,505,100,2,1,233.53,234.41,10,500,1,1,233.5,234.43,100,105,1,2,233.45,234.5,15,63,1,4,AAPL,0.0,0.0,0.0,
2024-10-21 12:26:05.173881544+00:00,2024-10-21T12:26:05.174048295Z,10,2,38,A,B,0,233.86,100,130,166751,13112718,233.86,233.95,100,121,1,1,233.85,234.0,100,402,1,3,233.81,234.07,2,7,2,1,233.8,234.1,105,100,2,1,233.77,234.13,200,400,1,1,233.7,234.17,1200,1,1,1,233.66,234.25,1,100,1,1,233.58,234.41,505,500,2,1,233.53,234.43,10,105,1,2,233.5,234.5,100,63,1,4,AAPL,0.0,0.0,0.0,
2024-10-21 12:26:05.247215441+00:00,2024-10-21T12:26:05.247381714Z,10,2,38,C,A,1,234.0,200,130,166273,13112835,233.86,233.95,100,121,1,1,233.85,234.0,100,202,1,2,233.81,234.07,2,7,2,1,233.8,234.1,105,100,2,1,233.77,234.13,200,400,1,1,233.7,234.17,1200,1,1,1,233.66,234.25,1,100,1,1,233.58,234.41,505,500,2,1,233.53,234.43,10,105,1,2,233.5,234.5,100,63,1,4,AAPL,0.0,200.0,0.0,
2024-10-21 12:26:05.247226039+00:00,2024-10-21T12:26:05.247392056Z,10,2,38,C,A,1,234.0,200,130,166017,13112836,233.86,233.95,100,121,1,1,233.85,234.0,100,2,1,1,233.81,234.07,2,7,2,1,233.8,234.1,105,100,2,1,233.77,234.13,200,400,1,1,233.7,234.17,1200,1,1,1,233.66,234.25,1,100,1,1,233.58,234.41,505,500,2,1,233.53,234.43,10,105,1,2,233.5,234.5,100,63,1,4,AAPL,0.0,200.0,0.0,
2024-10-21 12:26:05.247237168+00:00,2024-10-21T12:26:05.247404052Z,10,2,38,A,A,2,234.01,200,130,166884,13112837,233.86,233.95,100,121,1,1,233.85,234.0,100,2,1,1,233.81,234.01,2,200,2,1,233.8,234.07,105,7,2,1,233.77,234.1,200,100,1,1,233.7,234.13,1200,400,1,1,233.66,234.17,1,1,1,1,233.58,234.25,505,100,2,1,233.53,234.41,10,500,1,1,233.5,234.43,100,105,1,2,AAPL,0.0,0.0,0.0,
2024-10-21 12:26:08.272451351+00:00,2024-10-21T12:26:08.272617784Z,10,2,38,A,B,4,233.78,200,130,166433,13116250,233.86,233.95,100,121,1,1,233.85,234.0,100,2,1,1,233.81,234.01,2,200,2,1,233.8,234.07,105,7,2,1,233.78,234.1,200,100,1,1,233.7,234.13,1200,400,1,1,233.66,234.17,1,1,1,1,233.58,234.25,505,100,2,1,233.53,234.41,10,500,1,1,233.5,234.43,100,105,1,2,AAPL,0.0,0.0,0.0,
2024-10-21 12:26:09.610903498+00:00,2024-10-21T12:26:09.611069894Z,10,2,38,C,B,1,233.85,100,130,166396,13117941,233.86,233.95,100,121,1,1,233.81,234.0,2,2,2,1,233.8,234.01,105,200,2,1,233.78,234.07,200,7,1,1,233.7,234.1,1200,100,1,1,233.66,234.13,1,400,1,1,233.58,234.17,505,1,2,1,233.53,234.25,10,100,1,1,233.5,234.41,100,500,1,1,233.45,234.43,15,105,1,2,AAPL,0.0,0.0,0.0,
2024-10-21 12:26:11.689776041+00:00,2024-10-21T12:26:11.689942070Z,10,2,38,C,A,2,234.01,200,130,166029,13119493,233.86,233.95,100,121,1,1,233.81,234.0,2,2,2,1,233.8,234.07,105,7,2,1,233.78,234.1,200,100,1,1,233.7,234.13,1200,400,1,1,233.66,234.17,1,1,1,1,233.58,234.25,505,100,2,1,233.53,234.41,10,500,1,1,233.5,234.43,100,105,1,2,233.45,234.5,15,63,1,4,AAPL,0.0,0.0,0.0,
2024-10-21 12:26:11.689788127+00:00,2024-10-21T12:26:11.689954364Z,10,2,38,A,A,2,234.03,200,130,166237,13119494,233.86,233.95,100,121,1,1,233.81,234.0,2,2,2,1,233.8,234.03,105,200,2,1,233.78,234.07,200,7,1,1,233.7,234.1,1200,100,1,1,233.66,234.13,1,400,1,1,233.58,234.17,505,1,2,1,233.53,234.25,10,100,1,1,233.5,234.41,100,500,1,1,233.45,234.43,15,105,1,2,AAPL,0.0,0.0,0.0,
2024-10-21 12:26:11.691787041+00:00,2024-10-21T12:26:11.691953516Z,10,2,38,A,A,2,234.03,200,130,166475,13119500,233.86,233.95,100,121,1,1,233.81,234.0,2,2,2,1,233.8,234.03,105,400,2,2,233.78,234.07,200,7,1,1,233.7,234.1,1200,100,1,1,233.66,234.13,1,400,1,1,233.58,234.17,505,1,2,1,233.53,234.25,10,100,1,1,233.5,234.41,100,500,1,1,233.45,234.43,15,105,1,2,AAPL,0.0,-200.0,0.0,
2024-10-21 12:26:11.746296162+00:00,2024-10-21T12:26:11.746463267Z,10,2,38,C,A,2,234.03,200,130,167105,13119630,233.86,233.95,100,121,1,1,233.81,234.0,2,2,2,1,233.8,234.03,105,200,2,1,233.78,234.07,200,7,1,1,233.7,234.1,1200,100,1,1,233.66,234.13,1,400,1,1,233.58,234.17,505,1,2,1,233.53,234.25,10,100,1,1,233.5,234.41,100,500,1,1,233.45,234.43,15,105,1,2,AAPL,0.0,200.0,0.0,
2024-10-21 12:26:11.746308007+00:00,2024-10-21T12:26:11.746474261Z,10,2,38,A,A,2,234.02,200,130,166254,13119632,233.86,233.95,100,121,1,1,233.81,234.0,2,2,2,1,233.8,234.02,105,200,2,1,233.78,234.07,200,7,1,1,233.7,234.1,1200,100,1,1,233.66,234.13,1,400,1,1,233.58,234.17,505,1,2,1,233.53,234.25,10,100,1,1,233.5,234.41,100,500,1,1,233.45,234.43,15,105,1,2,AAPL,0.0,0.0,0.0,
2024-10-21 12:26:13.045285946+00:00,2024-10-21T12:26:13.045453100Z,10,2,38,A,B,3,233.79,200,130,167154,13120862,233.86,233.95,100,121,1,1,233.81,234.0,2,2,2,1,233.8,234.02,105,200,2,1,233.79,234.07,200,7,1,1,233.7,234.1,1200,100,1,1,233.66,234.13,1,400,1,1,233.58,234.17,505,1,2,1,233.53,234.25,10,100,1,1,233.5,234.41,100,500,1,1,233.45,234.43,15,105,1,2,AAPL,0.0,0.0,0.0,
2024-10-21 12:26:20.829236958+00:00,2024-10-21T12:26:20.829403397Z,10,2,38,A,A,1,234.0,15,130,166439,13126283,233.86,233.95,100,121,1,1,233.81,234.0,2,17,2,2,233.8,234.02,105,200,2,1,233.79,234.07,200,7,1,1,233.7,234.1,1200,100,1,1,233.66,234.13,1,400,1,1,233.58,234.17,505,1,2,1,233.53,234.25,10,100,1,1,233.5,234.41,100,500,1,1,233.45,234.43,15,105,1,2,AAPL,0.0,-15.0,0.0,
2024-10-21 12:26:22.496350258+00:00,2024-10-21T12:26:22.496516455Z,10,2,38,C,A,3,234.07,7,130,166197,13127351,233.86,233.95,100,121,1,1,233.81,234.0,2,17,2,2,233.8,234.02,105,200,2,1,233.79,234.1,200,100,1,1,233.7,234.13,1200,400,1,1,233.66,234.17,1,1,1,1,233.58,234.25,505,100,2,1,233.53,234.41,10,500,1,1,233.5,234.43,100,105,1,2,233.45,234.5,15,63,1,4,AAPL,0.0,0.0,0.0,
2024-10-21 12:26:23.488892465+00:00,2024-10-21T12:26:23.489058780Z,10,2,38,C,B,3,233.79,200,130,166315,13128004,233.86,233.95,100,121,1,1,233.81,234.0,2,17,2,2,233.8,234.02,105,200,2,1,233.7,234.1,1200,100,1,1,233.66,234.13,1,400,1,1,233.58,234.17,505,1,2,1,233.53,234.25,10,100,1,1,233.5,234.41,100,500,1,1,233.45,234.43,15,105,1,2,233.4,234.5,110,63,2,4,AAPL,0.0,0.0,0.0,
2024-10-21 12:26:23.498360877+00:00,2024-10-21T12:26:23.498527505Z,10,2,38,A,B,3,233.78,200,130,166628,13128006,233.86,233.95,100,121,1,1,233.81,234.0,2,17,2,2,233.8,234.02,105,200,2,1,233.78,234.1,200,100,1,1,233.7,234.13,1200,400,1,1,233.66,234.17,1,1,1,1,233.58,234.25,505,100,2,1,233.53,234.41,10,500,1,1,233.5,234.43,100,105,1,2,233.45,234.5,15,63,1,4,AAPL,0.0,0.0,0.0,
2024-10-21 12:26:24.504437465+00:00,2024-10-21T12:26:24.504603959Z,10,2,38,A,A,7,234.41,7,130,166494,13128603,233.86,233.95,100,121,1,1,233.81,234.0,2,17,2,2,233.8,234.02,105,200,2,1,233.78,234.1,200,100,1,1,233.7,234.13,1200,400,1,1,233.66,234.17,1,1,1,1,233.58,234.25,505,100,2,1,233.53,234.41,10,507,1,2,233.5,234.43,100,105,1,2,233.45,234.5,15,63,1,4,AAPL,0.0,0.0,0.0,
2024-10-21 12:26:25.077457400+00:00,2024-10-21T12:26:25.077623504Z,10,2,38,C,B,3,233.78,200,130,166104,13129240,233.86,233.95,100,121,1,1,233.81,234.0,2,17,2,2,233.8,234.02,105,200,2,1,233.7,234.1,1200,100,1,1,233.66,234.13,1,400,1,1,233.58,234.17,505,1,2,1,233.53,234.25,10,100,1,1,233.5,234.41,100,507,1,2,233.45,234.43,15,105,1,2,233.4,234.5,110,63,2,4,AAPL,0.0,0.0,0.0,
2024-10-21 12:26:25.077469095+00:00,2024-10-21T12:26:25.077635518Z,10,2,38,A,B,3,233.76,200,130,166423,13129241,233.86,233.95,100,121,1,1,233.81,234.0,2,17,2,2,233.8,234.02,105,200,2,1,233.76,234.1,200,100,1,1,233.7,234.13,1200,400,1,1,233.66,234.17,1,1,1,1,233.58,234.25,505,100,2,1,233.53,234.41,10,507,1,2,233.5,234.43,100,105,1,2,233.45,234.5,15,63,1,4,AAPL,0.0,0.0,0.0,
2024-10-21 12:26:25.077482593+00:00,2024-10-21T12:26:25.077648690Z,10,2,38,A,A,2,234.02,200,130,166097,13129242,233.86,233.95,100,121,1,1,233.81,234.0,2,17,2,2,233.8,234.02,105,400,2,2,233.76,234.1,200,100,1,1,233.7,234.13,1200,400,1,1,233.66,234.17,1,1,1,1,233.58,234.25,505,100,2,1,233.53,234.41,10,507,1,2,233.5,234.43,100,105,1,2,233.45,234.5,15,63,1,4,AAPL,0.0,-200.0,0.0,
2024-10-21 12:26:25.129312037+00:00,2024-10-21T12:26:25.129478069Z,10,2,38,C,A,2,234.02,200,130,166032,13129411,233.86,233.95,100,121,1,1,233.81,234.0,2,17,2,2,233.8,234.02,105,200,2,1,233.76,234.1,200,100,1,1,233.7,234.13,1200,400,1,1,233.66,234.17,1,1,1,1,233.58,234.25,505,100,2,1,233.53,234.41,10,507,1,2,233.5,234.43,100,105,1,2,233.45,234.5,15,63,1,4,AAPL,0.0,200.0,0.0,
2024-10-21 12:26:25.129324093+00:00,2024-10-21T12:26:25.129491036Z,10,2,38,A,A,1,234.0,200,130,166943,13129412,233.86,233.95,100,121,1,1,233.81,234.0,2,217,2,3,233.8,234.1,105,100,2,1,233.76,234.13,200,400,1,1,233.7,234.17,1200,1,1,1,233.66,234.25,1,100,1,1,233.58,234.41,505,507,2,2,233.53,234.43,10,105,1,2,233.5,234.5,100,63,1,4,233.45,234.59,15,60,1,1,AAPL,0.0,-200.0,0.0,
2024-10-21 12:26:25.268638479+00:00,2024-10-21T12:26:25.268804920Z,10,2,38,A,B,3,233.77,200,130,166441,13129838,233.86,233.95,100,121,1,1,233.81,234.0,2,217,2,3,233.8,234.1,105,100,2,1,233.77,234.13,200,400,1,1,233.7,234.17,1200,1,1,1,233.66,234.25,1,100,1,1,233.58,234.41,505,507,2,2,233.53,234.43,10,105,1,2,233.5,234.5,100,63,1,4,233.45,234.59,15,60,1,1,AAPL,0.0,0.0,0.0,
2024-10-21 12:26:25.384088744+00:00,2024-10-21T12:26:25.384254820Z,10,2,38,C,A,1,234.0,200,130,166076,13130001,233.86,233.95,100,121,1,1,233.81,234.0,2,17,2,2,233.8,234.1,105,100,2,1,233.77,234.13,200,400,1,1,233.7,234.17,1200,1,1,1,233.66,234.25,1,100,1,1,233.58,234.41,505,507,2,2,233.53,234.43,10,105,1,2,233.5,234.5,100,63,1,4,233.45,234.59,15,60,1,1,AAPL,0.0,200.0,0.0,
2024-10-21 12:26:25.384100277+00:00,2024-10-21T12:26:25.384266211Z,10,2,38,A,A,2,234.02,200,130,165934,13130002,233.86,233.95,100,121,1,1,233.81,234.0,2,17,2,2,233.8,234.02,105,200,2,1,233.77,234.1,200,100,1,1,233.7,234.13,1200,400,1,1,233.66,234.17,1,1,1,1,233.58,234.25,505,100,2,1,233.53,234.41,10,507,1,2,233.5,234.43,100,105,1,2,233.45,234.5,15,63,1,4,AAPL,0.0,0.0,0.0,
2024-10-21 12:26:25.438886764+00:00,2024-10-21T12:26:25.439053026Z,10,2,38,A,B,3,233.78,200,130,166262,13130072,233.86,233.95,100,121,1,1,233.81,234.0,2,17,2,2,233.8,234.02,105,200,2,1,233.78,234.1,200,100,1,1,233.7,234.13,1200,400,1,1,233.66,234.17,1,1,1,1,233.58,234.25,505,100,2,1,233.53,234.41,10,507,1,2,233.5,234.43,100,105,1,2,233.45,234.5,15,63,1,4,AAPL,0.0,0.0,0.0,
2024-10-21 12:26:25.518902005+00:00,2024-10-21T12:26:25.519068296Z,10,2,38,A,A,2,234.01,200,130,166291,13130195,233.86,233.95,100,121,1,1,233.81,234.0,2,17,2,2,233.8,234.01,105,200,2,1,233.78,234.1,200,100,1,1,233.7,234.13,1200,400,1,1,233.66,234.17,1,1,1,1,233.58,234.25,505,100,2,1,233.53,234.41,10,507,1,2,233.5,234.43,100,105,1,2,233.45,234.5,15,63,1,4,AAPL,0.0,0.0,0.0,
2024-10-21 12:26:31.592891536+00:00,2024-10-21T12:26:31.593057846Z,10,2,38,C,A,7,234.41,7,130,166310,13135066,233.86,233.95,100,121,1,1,233.81,234.0,2,17,2,2,233.8,234.01,105,200,2,1,233.78,234.1,200,100,1,1,233.7,234.13,1200,400,1,1,233.66,234.17,1,1,1,1,233.58,234.25,505,100,2,1,233.53,234.41,10,500,1,1,233.5,234.43,100,105,1,2,233.45,234.5,15,63,1,4,AAPL,0.0,0.0,0.0,
2024-10-21 12:26:32.717433050+00:00,2024-10-21T12:26:32.717599837Z,10,2,38,A,A,0,233.95,10,130,166787,13137148,233.86,233.95,100,131,1,2,233.81,234.0,2,17,2,2,233.8,234.01,105,200,2,1,233.78,234.1,200,100,1,1,233.7,234.13,1200,400,1,1,233.66,234.17,1,1,1,1,233.58,234.25,505,100,2,1,233.53,234.41,10,500,1,1,233.5,234.43,100,105,1,2,233.45,234.5,15,63,1,4,AAPL,-10.0,-10.0,-10.0,
2024-10-21 12:26:32.717472823+00:00,2024-10-21T12:26:32.717638955Z,10,2,38,C,B,3,233.78,200,130,166132,13137150,233.86,233.95,100,131,1,2,233.81,234.0,2,17,2,2,233.8,234.01,105,200,2,1,233.7,234.1,1200,100,1,1,233.66,234.13,1,400,1,1,233.58,234.17,505,1,2,1,233.53,234.25,10,100,1,1,233.5,234.41,100,500,1,1,233.45,234.43,15,105,1,2,233.4,234.5,110,63,2,4,AAPL,0.0,0.0,-10.0,
2024-10-21 12:26:32.721528057+00:00,2024-10-21T12:26:32.721694410Z,10,2,38,C,A,0,233.95,10,130,166353,13137153,233.86,233.95,100,121,1,1,233.81,234.0,2,17,2,2,233.8,234.01,105,200,2,1,233.7,234.1,1200,100,1,1,233.66,234.13,1,400,1,1,233.58,234.17,505,1,2,1,233.53,234.25,10,100,1,1,233.5,234.41,100,500,1,1,233.45,234.43,15,105,1,2,233.4,234.5,110,63,2,4,AAPL,10.0,10.0,0.0,
2024-10-21 12:26:32.820683999+00:00,2024-10-21T12:26:32.820850700Z,10,2,38,A,B,3,233.78,200,130,166701,13137257,233.86,233.95,100,121,1,1,233.81,234.0,2,17,2,2,233.8,234.01,105,200,2,1,233.78,234.1,200,100,1,1,233.7,234.13,1200,400,1,1,233.66,234.17,1,1,1,1,233.58,234.25,505,100,2,1,233.53,234.41,10,500,1,1,233.5,234.43,100,105,1,2,233.45,234.5,15,63,1,4,AAPL,0.0,0.0,0.0,
2024-10-21 12:26:33.596060481+00:00,2024-10-21T12:26:33.596226968Z,10,2,38,A,A,7,234.41,7,130,166487,13137944,233.86,233.95,100,121,1,1,233.81,234.0,2,17,2,2,233.8,234.01,105,200,2,1,233.78,234.1,200,100,1,1,233.7,234.13,1200,400,1,1,233.66,234.17,1,1,1,1,233.58,234.25,505,100,2,1,233.53,234.41,10,507,1,2,233.5,234.43,100,105,1,2,233.45,234.5,15,63,1,4,AAPL,0.0,0.0,0.0,
2024-10-21 12:26:33.705296257+00:00,2024-10-21T12:26:33.705462618Z,10,2,38,C,B,3,233.78,200,130,166361,13138040,233.86,233.95,100,121,1,1,233.81,234.0,2,17,2,2,233.8,234.01,105,200,2,1,233.7,234.1,1200,100,1,1,233.66,234.13,1,400,1,1,233.58,234.17,505,1,2,1,233.53,234.25,10,100,1,1,233.5,234.41,100,507,1,2,233.45,234.43,15,105,1,2,233.4,234.5,110,63,2,4,AAPL,0.0,0.0,0.0,
2024-10-21 12:26:33.705309399+00:00,2024-10-21T12:26:33.705475821Z,10,2,38,A,B,3,233.73,400,130,166422,13138041,233.86,233.95,100,121,1,1,233.81,234.0,2,17,2,2,233.8,234.01,105,200,2,1,233.73,234.1,400,100,1,1,233.7,234.13,1200,400,1,1,233.66,234.17,1,1,1,1,233.58,234.25,505,100,2,1,233.53,234.41,10,507,1,2,233.5,234.43,100,105,1,2,233.45,234.5,15,63,1,4,AAPL,0.0,0.0,0.0,
2024-10-21 12:26:40.656134264+00:00,2024-10-21T12:26:40.656300037Z,10,2,38,C,A,2,234.01,200,130,165773,13145962,233.86,233.95,100,121,1,1,233.81,234.0,2,17,2,2,233.8,234.1,105,100,2,1,233.73,234.13,400,400,1,1,233.7,234.17,1200,1,1,1,233.66,234.25,1,100,1,1,233.58,234.41,505,507,2,2,233.53,234.43,10,105,1,2,233.5,234.5,100,63,1,4,233.45,234.59,15,60,1,1,AAPL,0.0,0.0,0.0,
2024-10-21 12:26:40.656147028+00:00,2024-10-21T12:26:40.656313085Z,10,2,38,A,A,2,234.03,400,130,166057,13145963,233.86,233.95,100,121,1,1,233.81,234.0,2,17,2,2,233.8,234.03,105,400,2,1,233.73,234.1,400,100,1,1,233.7,234.13,1200,400,1,1,233.66,234.17,1,1,1,1,233.58,234.25,505,100,2,1,233.53,234.41,10,507,1,2,233.5,234.43,100,105,1,2,233.45,234.5,15,63,1,4,AAPL,0.0,0.0,0.0,
2024-10-21 12:26:40.707506986+00:00,2024-10-21T12:26:40.707673608Z,10,2,38,A,B,3,233.74,400,130,166622,13146198,233.86,233.95,100,121,1,1,233.81,234.0,2,17,2,2,233.8,234.03,105,400,2,1,233.74,234.1,400,100,1,1,233.7,234.13,1200,400,1,1,233.66,234.17,1,1,1,1,233.58,234.25,505,100,2,1,233.53,234.41,10,507,1,2,233.5,234.43,100,105,1,2,233.45,234.5,15,63,1,4,AAPL,0.0,0.0,0.0,
2024-10-21 12:26:40.896535785+00:00,2024-10-21T12:26:40.896702274Z,10,2,38,A,A,2,234.02,400,130,166489,13146521,233.86,233.95,100,121,1,1,233.81,234.0,2,17,2,2,233.8,234.02,105,400,2,1,233.74,234.1,400,100,1,1,233.7,234.13,1200,400,1,1,233.66,234.17,1,1,1,1,233.58,234.25,505,100,2,1,233.53,234.41,10,507,1,2,233.5,234.43,100,105,1,2,233.45,234.5,15,63,1,4,AAPL,0.0,0.0,0.0,
2024-10-21 12:26:42.392534365+00:00,2024-10-21T12:26:42.392700431Z,10,2,38,C,A,7,234.41,7,130,166066,13148175,233.86,233.95,100,121,1,1,233.81,234.0,2,17,2,2,233.8,234.02,105,400,2,1,233.74,234.1,400,100,1,1,233.7,234.13,1200,400,1,1,233.66,234.17,1,1,1,1,233.58,234.25,505,100,2,1,233.53,234.41,10,500,1,1,233.5,234.43,100,105,1,2,233.45,234.5,15,63,1,4,AAPL,0.0,0.0,0.0,
2024-10-21 12:26:43.555613825+00:00,2024-10-21T12:26:43.555781301Z,10,2,38,T,A,0,233.86,100,130,167476,13148963,233.86,233.95,100,121,1,1,233.81,234.0,2,17,2,2,233.8,234.02,105,400,2,1,233.74,234.1,400,100,1,1,233.7,234.13,1200,400,1,1,233.66,234.17,1,1,1,1,233.58,234.25,505,100,2,1,233.53,234.41,10,500,1,1,233.5,234.43,100,105,1,2,233.45,234.5,15,63,1,4,AAPL,0.0,0.0,0.0,
2024-10-21 12:26:43.555613825+00:00,2024-10-21T12:26:43.555781301Z,10,2,38,C,B,0,233.86,100,130,167476,13148963,233.81,233.95,2,121,2,1,233.8,234.0,105,17,2,2,233.74,234.02,400,400,1,1,233.7,234.1,1200,100,1,1,233.66,234.13,1,400,1,1,233.58,234.17,505,1,2,1,233.53,234.25,10,100,1,1,233.5,234.41,100,500,1,1,233.45,234.43,15,105,1,2,233.4,234.5,110,63,2,4,AAPL,0.0,0.0,0.0,
2024-10-21 12:26:43.555625145+00:00,2024-10-21T12:26:43.555792717Z,10,2,38,A,B,0,233.86,100,130,167572,13148964,233.86,233.95,100,121,1,1,233.81,234.0,2,17,2,2,233.8,234.02,105,400,2,1,233.74,234.1,400,100,1,1,233.7,234.13,1200,400,1,1,233.66,234.17,1,1,1,1,233.58,234.25,505,100,2,1,233.53,234.41,10,500,1,1,233.5,234.43,100,105,1,2,233.45,234.5,15,63,1,4,AAPL,0.0,0.0,0.0,
2024-10-21 12:26:43.555636531+00:00,2024-10-21T12:26:43.555803052Z,10,2,38,A,A,0,233.9,100,130,166521,13148965,233.86,233.9,100,100,1,1,233.81,233.95,2,121,2,1,233.8,234.0,105,17,2,2,233.74,234.02,400,400,1,1,233.7,234.1,1200,100,1,1,233.66,234.13,1,400,1,1,233.58,234.17,505,1,2,1,233.53,234.25,10,100,1,1,233.5,234.41,100,500,1,1,233.45,234.43,15,105,1,2,AAPL,0.0,0.0,0.0,
2024-10-21 12:26:43.555641373+00:00,2024-10-21T12:26:43.555807607Z,10,2,38,A,A,1,233.91,200,130,166234,13148967,233.86,233.9,100,100,1,1,233.81,233.91,2,200,2,1,233.8,233.93,105,100,2,1,233.74,233.95,400,121,1,1,233.7,234.0,1200,17,1,2,233.66,234.02,1,400,1,1,233.58,234.1,505,100,2,1,233.53,234.13,10,400,1,1,233.5,234.17,100,1,1,1,233.45,234.25,15,100,1,1,AAPL,0.0,0.0,0.0,
2024-10-21 12:26:43.555648065+00:00,2024-10-21T12:26:43.555814614Z,10,2,38,A,A,2,233.93,100,130,166549,13148968,233.86,233.9,100,100,1,1,233.81,233.91,2,200,2,1,233.8,233.93,105,200,2,2,233.74,233.95,400,121,1,1,233.7,234.0,1200,17,1,2,233.66,234.02,1,400,1,1,233.58,234.1,505,100,2,1,233.53,234.13,10,400,1,1,233.5,234.17,100,1,1,1,233.45,234.25,15,100,1,1,AAPL,0.0,-100.0,0.0,
2024-10-21 12:26:43.555650058+00:00,2024-10-21T12:26:43.555816268Z,10,2,38,A,A,2,233.93,100,130,166210,13148969,233.86,233.9,100,100,1,1,233.81,233.91,2,200,2,1,233.8,233.93,105,300,2,3,233.74,233.95,400,121,1,1,233.7,234.0,1200,17,1,2,233.66,234.02,1,400,1,1,233.58,234.1,505,100,2,1,233.53,234.13,10,400,1,1,233.5,234.17,100,1,1,1,233.45,234.25,15,100,1,1,AAPL,0.0,-100.0,0.0,
2024-10-21 12:26:43.555653371+00:00,2024-10-21T12:26:43.555819727Z,10,2,38,C,A,1,233.91,200,130,166356,13148970,233.86,233.9,100,100,1,1,233.81,233.93,2,300,2,3,233.8,233.95,105,121,2,1,233.74,234.0,400,17,1,2,233.7,234.02,1200,400,1,1,233.66,234.1,1,100,1,1,233.58,234.13,505,400,2,1,233.53,234.17,10,1,1,1,233.5,234.25,100,100,1,1,233.45,234.41,15,500,1,1,AAPL,0.0,0.0,0.0,
2024-10-21 12:26:43.555663089+00:00,2024-10-21T12:26:43.555829005Z,10,2,38,A,A,1,233.91,23,130,165916,13148971,233.86,233.9,100,100,1,1,233.81,233.91,2,23,2,1,233.8,233.93,105,300,2,3,233.74,233.95,400,121,1,1,233.7,234.0,1200,17,1,2,233.66,234.02,1,400,1,1,233.58,234.1,505,100,2,1,233.53,234.13,10,400,1,1,233.5,234.17,100,1,1,1,233.45,234.25,15,100,1,1,AAPL,0.0,0.0,0.0,
2024-10-21 12:26:43.555678324+00:00,2024-10-21T12:26:43.555844094Z,10,2,38,C,A,0,233.9,100,130,165770,13148972,233.86,233.91,100,23,1,1,233.81,233.93,2,300,2,3,233.8,233.95,105,121,2,1,233.74,234.0,400,17,1,2,233.7,234.02,1200,400,1,1,233.66,234.1,1,100,1,1,233.58,234.13,505,400,2,1,233.53,234.17,10,1,1,1,233.5,234.25,100,100,1,1,233.45,234.41,15,500,1,1,AAPL,0.0,0.0,0.0,
2024-10-21 12:26:43.555692383+00:00,2024-10-21T12:26:43.555858526Z,10,2,38,C,A,1,233.93,100,130,166143,13148974,233.86,233.91,100,23,1,1,233.81,233.93,2,200,2,2,233.8,233.95,105,121,2,1,233.74,234.0,400,17,1,2,233.7,234.02,1200,400,1,1,233.66,234.1,1,100,1,1,233.58,234.13,505,400,2,1,233.53,234.17,10,1,1,1,233.5,234.25,100,100,1,1,233.45,234.41,15,500,1,1,AAPL,0.0,100.0,0.0,
2024-10-21 12:26:43.555700148+00:00,2024-10-21T12:26:43.555866497Z,10,2,38,C,A,1,233.93,100,130,166349,13148976,233.86,233.91,100,23,1,1,233.81,233.93,2,100,2,1,233.8,233.94,105,23,2,1,233.74,233.95,400,121,1,1,233.7,234.0,1200,17,1,2,233.66,234.02,1,400,1,1,233.58,234.1,505,100,2,1,233.53,234.13,10,400,1,1,233.5,234.17,100,1,1,1,233.45,234.25,15,100,1,1,AAPL,0.0,100.0,0.0,
2024-10-21 12:26:43.555711164+00:00,2024-10-21T12:26:43.555879570Z,10,2,38,T,A,0,233.86,50,130,168406,13148979,233.86,233.91,100,23,1,1,233.81,233.93,2,100,2,1,233.8,233.94,105,23,2,1,233.74,233.95,400,121,1,1,233.7,234.0,1200,17,1,2,233.66,234.02,1,400,1,1,233.58,234.1,505,100,2,1,233.53,234.13,10,400,1,1,233.5,234.17,100,1,1,1,233.45,234.25,15,100,1,1,AAPL,0.0,0.0,0.0,
2024-10-21 12:26:43.555711164+00:00,2024-10-21T12:26:43.555879570Z,10,2,38,C,B,0,233.86,50,130,168406,13148979,233.86,233.91,50,23,1,1,233.81,233.93,2,100,2,1,233.8,233.94,105,23,2,1,233.74,233.95,400,121,1,1,233.7,234.0,1200,17,1,2,233.66,234.02,1,400,1,1,233.58,234.1,505,100,2,1,233.53,234.13,10,400,1,1,233.5,234.17,100,1,1,1,233.45,234.25,15,100,1,1,AAPL,-50.0,-50.0,-50.0,
2024-10-21 12:26:43.555724858+00:00,2024-10-21T12:26:43.555892512Z,10,2,38,A,B,0,233.86,100,130,167654,13148980,233.86,233.91,150,23,2,1,233.81,233.93,2,100,2,1,233.8,233.94,105,23,2,1,233.74,233.95,400,121,1,1,233.7,234.0,1200,17,1,2,233.66,234.02,1,400,1,1,233.58,234.1,505,100,2,1,233.53,234.13,10,400,1,1,233.5,234.17,100,1,1,1,233.45,234.25,15,100,1,1,AAPL,100.0,100.0,50.0,
2024-10-21 12:26:43.555737821+00:00,2024-10-21T12:26:43.555904815Z,10,2,38,T,A,0,233.86,50,130,166994,13148981,233.86,233.91,150,23,2,1,233.81,233.93,2,100,2,1,233.8,233.94,105,23,2,1,233.74,233.95,400,121,1,1,233.7,234.0,1200,17,1,2,233.66,234.02,1,400,1,1,233.58,234.1,505,100,2,1,233.53,234.13,10,400,1,1,233.5,234.17,100,1,1,1,233.45,234.25,15,100,1,1,AAPL,0.0,0.0,50.0,
2024-10-21 12:26:43.555737821+00:00,2024-10-21T12:26:43.555904815Z,10,2,38,C,B,0,233.86,50,130,166994,13148981,233.86,233.91,100,23,1,1,233.81,233.93,2,100,2,1,233.8,233.94,105,23,2,1,233.74,233.95,400,121,1,1,233.7,234.0,1200,17,1,2,233.66,234.02,1,400,1,1,233.58,234.1,505,100,2,1,233.53,234.13,10,400,1,1,233.5,234.17,100,1,1,1,233.45,234.25,15,100,1,1,AAPL,-50.0,-50.0,0.0,
2024-10-21 12:26:43.555767270+00:00,2024-10-21T12:26:43.555933449Z,10,2,38,C,B,3,233.74,200,130,166179,13148982,233.86,233.91,100,23,1,1,233.81,233.93,2,100,2,1,233.8,233.94,105,23,2,1,233.74,233.95,200,121,1,1,233.7,234.0,1200,17,1,2,233.66,234.02,1,400,1,1,233.58,234.1,505,100,2,1,233.53,234.13,10,400,1,1,233.5,234.17,100,1,1,1,233.45,234.25,15,100,1,1,AAPL,0.0,-200.0,0.0,
2024-10-21 12:26:43.555789284+00:00,2024-10-21T12:26:43.555956286Z,10,2,38,C,B,3,233.74,200,130,167002,13148983,233.86,233.91,100,23,1,1,233.81,233.93,2,100,2,1,233.8,233.94,105,23,2,1,233.7,233.95,1200,121,1,1,233.66,234.0,1,17,1,2,233.58,234.02,505,400,2,1,233.53,234.1,10,100,1,1,233.5,234.13,100,400,1,1,233.45,234.17,15,1,1,1,233.4,234.25,110,100,2,1,AAPL,0.0,0.0,0.0,
2024-10-21 12:26:43.555989102+00:00,2024-10-21T12:26:43.556155095Z,10,2,38,C,A,1,233.93,100,130,165993,13148984,233.86,233.91,100,23,1,1,233.81,233.94,2,23,2,1,233.8,233.95,105,121,2,1,233.7,234.0,1200,17,1,2,233.66,234.02,1,400,1,1,233.58,234.1,505,100,2,1,233.53,234.13,10,400,1,1,233.5,234.17,100,1,1,1,233.45,234.25,15,100,1,1,233.4,234.41,110,500,2,1,AAPL,0.0,0.0,0.0,
2024-10-21 12:26:43.556335122+00:00,2024-10-21T12:26:43.556502258Z,10,2,38,T,A,0,233.86,5,130,167136,13148985,233.86,233.91,100,23,1,1,233.81,233.94,2,23,2,1,233.8,233.95,105,121,2,1,233.7,234.0,1200,17,1,2,233.66,234.02,1,400,1,1,233.58,234.1,505,100,2,1,233.53,234.13,10,400,1,1,233.5,234.17,100,1,1,1,233.45,234.25,15,100,1,1,233.4,234.41,110,500,2,1,AAPL,0.0,0.0,0.0,
2024-10-21 12:26:43.556335122+00:00,2024-10-21T12:26:43.556502258Z,10,2,38,C,B,0,233.86,5,130,167136,13148985,233.86,233.91,95,23,1,1,233.81,233.94,2,23,2,1,233.8,233.95,105,121,2,1,233.7,234.0,1200,17,1,2,233.66,234.02,1,400,1,1,233.58,234.1,505,100,2,1,233.53,234.13,10,400,1,1,233.5,234.17,100,1,1,1,233.45,234.25,15,100,1,1,233.4,234.41,110,500,2,1,AAPL,-5.0,-5.0,-5.0,
2024-10-21 12:26:43.556344203+00:00,2024-10-21T12:26:43.556510636Z,10,2,38,A,B,0,233.86,100,130,166433,13148986,233.86,233.91,195,23,2,1,233.81,233.94,2,23,2,1,233.8,233.95,105,121,2,1,233.7,234.0,1200,17,1,2,233.66,234.02,1,400,1,1,233.58,234.1,505,100,2,1,233.53,234.13,10,400,1,1,233.5,234.17,100,1,1,1,233.45,234.25,15,100,1,1,233.4,234.41,110,500,2,1,AAPL,100.0,100.0,95.0,
2024-10-21 12:26:43.602920183+00:00,2024-10-21T12:26:43.603087151Z,10,2,38,A,B,3,233.74,200,130,166968,13149063,233.86,233.91,195,23,2,1,233.81,233.94,2,23,2,1,233.8,233.95,105,121,2,1,233.74,234.0,200,17,1,2,233.7,234.02,1200,400,1,1,233.66,234.1,1,100,1,1,233.58,234.13,505,400,2,1,233.53,234.17,10,1,1,1,233.5,234.25,100,100,1,1,233.45,234.41,15,500,1,1,AAPL,0.0,0.0,95.0,
2024-10-21 12:26:43.632931005+00:00,2024-10-21T12:26:43.633097364Z,10,2,38,A,B,3,233.74,200,130,166359,13149078,233.86,233.91,195,23,2,1,233.81,233.94,2,23,2,1,233.8,233.95,105,121,2,1,233.74,234.0,400,17,2,2,233.7,234.02,1200,400,1,1,233.66,234.1,1,100,1,1,233.58,234.13,505,400,2,1,233.53,234.17,10,1,1,1,233.5,234.25,100,100,1,1,233.45,234.41,15,500,1,1,AAPL,0.0,200.0,95.0,
2024-10-21 12:26:43.663764676+00:00,2024-10-21T12:26:43.663930696Z,10,2,38,C,A,1,233.94,23,130,166020,13149095,233.86,233.91,195,23,2,1,233.81,233.95,2,121,2,1,233.8,234.0,105,17,2,2,233.74,234.02,400,400,2,1,233.7,234.1,1200,100,1,1,233.66,234.13,1,400,1,1,233.58,234.17,505,1,2,1,233.53,234.25,10,100,1,1,233.5,234.41,100,500,1,1,233.45,234.43,15,105,1,2,AAPL,0.0,0.0,95.0,
2024-10-21 12:26:43.813764689+00:00,2024-10-21T12:26:43.813930819Z,10,2,38,C,A,0,233.91,23,130,166130,13149215,233.86,233.95,195,121,2,1,233.81,234.0,2,17,2,2,233.8,234.02,105,400,2,1,233.74,234.1,400,100,2,1,233.7,234.13,1200,400,1,1,233.66,234.17,1,1,1,1,233.58,234.25,505,100,2,1,233.53,234.41,10,500,1,1,233.5,234.43,100,105,1,2,233.45,234.5,15,63,1,4,AAPL,0.0,0.0,95.0,
2024-10-21 12:26:44.395140599+00:00,2024-10-21T12:26:44.395306900Z,10,2,38,A,A,1,233.97,7,130,166301,13149756,233.86,233.95,195,121,2,1,233.81,233.97,2,7,2,1,233.8,234.0,105,17,2,2,233.74,234.02,400,400,2,1,233.7,234.1,1200,100,1,1,233.66,234.13,1,400,1,1,233.58,234.17,505,1,2,1,233.53,234.25,10,100,1,1,233.5,234.41,100,500,1,1,233.45,234.43,15,105,1,2,AAPL,0.0,0.0,95.0,
2024-10-21 12:26:47.316834945+00:00,2024-10-21T12:26:47.317000869Z,10,2,38,C,A,3,234.02,400,130,165924,13152409,233.86,233.95,195,121,2,1,233.81,233.97,2,7,2,1,233.8,234.0,105,17,2,2,233.74,234.1,400,100,2,1,233.7,234.13,1200,400,1,1,233.66,234.17,1,1,1,1,233.58,234.25,505,100,2,1,233.53,234.41,10,500,1,1,233.5,234.43,100,105,1,2,233.45,234.5,15,63,1,4,AAPL,0.0,0.0,0.0,
2024-10-21 12:26:47.316847348+00:00,2024-10-21T12:26:47.317013569Z,10,2,38,A,A,3,234.04,400,130,166221,13152410,233.86,233.95,195,121,2,1,233.81,233.97,2,7,2,1,233.8,234.0,105,17,2,2,233.74,234.04,400,400,2,1,233.7,234.1,1200,100,1,1,233.66,234.13,1,400,1,1,233.58,234.17,505,1,2,1,233.53,234.25,10,100,1,1,233.5,234.41,100,500,1,1,233.45,234.43,15,105,1,2,AAPL,0.0,0.0,0.0,
2024-10-21 12:26:47.371448271+00:00,2024-10-21T12:26:47.371614290Z,10,2,38,C,B,3,233.74,200,130,166019,13152673,233.86,233.95,195,121,2,1,233.81,233.97,2,7,2,1,233.8,234.0,105,17,2,2,233.74,234.04,200,400,1,1,233.7,234.1,1200,100,1,1,233.66,234.13,1,400,1,1,233.58,234.17,505,1,2,1,233.53,234.25,10,100,1,1,233.5,234.41,100,500,1,1,233.45,234.43,15,105,1,2,AAPL,0.0,-200.0,0.0,
2024-10-21 12:26:47.371461367+00:00,2024-10-21T12:26:47.371627679Z,10,2,38,A,B,3,233.76,400,130,166312,13152674,233.86,233.95,195,121,2,1,233.81,233.97,2,7,2,1,233.8,234.0,105,17,2,2,233.76,234.04,400,400,1,1,233.7,234.1,1200,100,1,1,233.66,234.13,1,400,1,1,233.58,234.17,505,1,2,1,233.53,234.25,10,100,1,1,233.5,234.41,100,500,1,1,233.45,234.43,15,105,1,2,AAPL,0.0,0.0,0.0,
2024-10-21 12:26:53.381650546+00:00,2024-10-21T12:26:53.381817361Z,10,2,38,A,B,3,233.77,400,130,166815,13157627,233.86,233.95,195,121,2,1,233.81,233.97,2,7,2,1,233.8,234.0,105,17,2,2,233.77,234.04,400,400,1,1,233.7,234.1,1200,100,1,1,233.66,234.13,1,400,1,1,233.58,234.17,505,1,2,1,233.53,234.25,10,100,1,1,233.5,234.41,100,500,1,1,233.45,234.43,15,105,1,2,AAPL,0.0,0.0,0.0,
2024-10-21 12:26:54.545723322+00:00,2024-10-21T12:26:54.545889324Z,10,2,38,C,B,3,233.77,400,130,166002,13158660,233.86,233.95,195,121,2,1,233.81,233.97,2,7,2,1,233.8,234.0,105,17,2,2,233.7,234.04,1200,400,1,1,233.66,234.1,1,100,1,1,233.58,234.13,505,400,2,1,233.53,234.17,10,1,1,1,233.5,234.25,100,100,1,1,233.45,234.41,15,500,1,1,233.4,234.43,110,105,2,2,AAPL,0.0,0.0,0.0,
2024-10-21 12:26:54.545735230+00:00,2024-10-21T12:26:54.545901500Z,10,2,38,A,B,3,233.76,400,130,166270,13158661,233.86,233.95,195,121,2,1,233.81,233.97,2,7,2,1,233.8,234.0,105,17,2,2,233.76,234.04,400,400,1,1,233.7,234.1,1200,100,1,1,233.66,234.13,1,400,1,1,233.58,234.17,505,1,2,1,233.53,234.25,10,100,1,1,233.5,234.41,100,500,1,1,233.45,234.43,15,105,1,2,AAPL,0.0,0.0,0.0,
2024-10-21 12:27:04.677802802+00:00,2024-10-21T12:27:04.677969002Z,10,2,38,A,B,3,233.77,400,130,166200,13168438,233.86,233.95,195,121,2,1,233.81,233.97,2,7,2,1,233.8,234.0,105,17,2,2,233.77,234.04,400,400,1,1,233.7,234.1,1200,100,1,1,233.66,234.13,1,400,1,1,233.58,234.17,505,1,2,1,233.53,234.25,10,100,1,1,233.5,234.41,100,500,1,1,233.45,234.43,15,105,1,2,AAPL,0.0,0.0,0.0,
2024-10-21 12:27:04.858186427+00:00,2024-10-21T12:27:04.858352610Z,10,2,38,C,B,3,233.77,200,130,166183,13168809,233.86,233.95,195,121,2,1,233.81,233.97,2,7,2,1,233.8,234.0,105,17,2,2,233.77,234.04,200,400,1,1,233.7,234.1,1200,100,1,1,233.66,234.13,1,400,1,1,233.58,234.17,505,1,2,1,233.53,234.25,10,100,1,1,233.5,234.41,100,500,1,1,233.45,234.43,15,105,1,2,AAPL,0.0,-200.0,0.0,
2024-10-21 12:27:08.140184917+00:00,2024-10-21T12:27:08.140351417Z,10,2,38,A,B,0,233.86,100,130,166500,13171896,233.86,233.95,295,121,3,1,233.81,233.97,2,7,2,1,233.8,234.0,105,17,2,2,233.77,234.04,200,400,1,1,233.7,234.1,1200,100,1,1,233.66,234.13,1,400,1,1,233.58,234.17,505,1,2,1,233.53,234.25,10,100,1,1,233.5,234.41,100,500,1,1,233.45,234.43,15,105,1,2,AAPL,100.0,100.0,100.0,
2024-10-21 12:27:08.267237597+00:00,2024-10-21T12:27:08.267404175Z,10,2,38,A,A,2,233.99,200,130,166578,13172040,233.86,233.95,295,121,3,1,233.81,233.97,2,7,2,1,233.8,233.99,105,200,2,1,233.77,234.0,200,17,1,2,233.7,234.1,1200,100,1,1,233.66,234.13,1,400,1,1,233.58,234.17,505,1,2,1,233.53,234.25,10,100,1,1,233.5,234.41,100,500,1,1,233.45,234.43,15,105,1,2,AAPL,0.0,0.0,100.0,
2024-10-21 12:27:08.903847050+00:00,2024-10-21T12:27:08.904013328Z,10,2,38,A,B,3,233.77,200,130,166278,13172666,233.86,233.95,295,121,3,1,233.81,233.97,2,7,2,1,233.8,233.99,105,200,2,1,233.77,234.0,400,17,2,2,233.7,234.1,1200,100,1,1,233.66,234.13,1,400,1,1,233.58,234.17,505,1,2,1,233.53,234.25,10,100,1,1,233.5,234.41,100,500,1,1,233.45,234.43,15,105,1,2,AAPL,0.0,200.0,100.0,
2024-10-21 12:27:15.211023662+00:00,2024-10-21T12:27:15.211190007Z,10,2,38,C,A,1,233.97,7,130,166345,13177973,233.86,233.95,295,121,3,1,233.81,233.99,2,200,2,1,233.8,234.0,105,17,2,2,233.77,234.1,400,100,2,1,233.7,234.13,1200,400,1,1,233.66,234.17,1,1,1,1,233.58,234.25,505,100,2,1,233.53,234.41,10,500,1,1,233.5,234.43,100,105,1,2,233.45,234.5,15,63,1,4,AAPL,0.0,0.0,0.0,
2024-10-21 12:27:16.357185731+00:00,2024-10-21T12:27:16.357351976Z,10,2,38,C,A,0,233.95,121,130,166245,13178747,233.86,233.99,295,200,3,1,233.81,234.0,2,17,2,2,233.8,234.1,105,100,2,1,233.77,234.13,400,400,2,1,233.7,234.17,1200,1,1,1,233.66,234.25,1,100,1,1,233.58,234.41,505,500,2,1,233.53,234.43,10,105,1,2,233.5,234.5,100,63,1,4,233.45,234.59,15,60,1,1,AAPL,0.0,0.0,0.0,
2024-10-21 12:27:16.383880298+00:00,2024-10-21T12:27:16.384048756Z,10,2,38,T,N,0,233.87,50,0,168458,13178752,233.86,233.99,295,200,3,1,233.81,234.0,2,17,2,2,233.8,234.1,105,100,2,1,233.77,234.13,400,400,2,1,233.7,234.17,1200,1,1,1,233.66,234.25,1,100,1,1,233.58,234.41,505,500,2,1,233.53,234.43,10,105,1,2,233.5,234.5,100,63,1,4,233.45,234.59,15,60,1,1,AAPL,0.0,0.0,0.0,
2024-10-21 12:27:16.383880298+00:00,2024-10-21T12:27:16.384048756Z,10,2,38,T,N,0,233.87,71,130,168458,13178753,233.86,233.99,295,200,3,1,233.81,234.0,2,17,2,2,233.8,234.1,105,100,2,1,233.77,234.13,400,400,2,1,233.7,234.17,1200,1,1,1,233.66,234.25,1,100,1,1,233.58,234.41,505,500,2,1,233.53,234.43,10,105,1,2,233.5,234.5,100,63,1,4,233.45,234.59,15,60,1,1,AAPL,0.0,0.0,0.0,
2024-10-21 12:27:17.218233083+00:00,2024-10-21T12:27:17.218399628Z,10,2,38,A,A,0,233.98,7,130,166545,13179063,233.86,233.98,295,7,3,1,233.81,233.99,2,200,2,1,233.8,234.0,105,17,2,2,233.77,234.1,400,100,2,1,233.7,234.13,1200,400,1,1,233.66,234.17,1,1,1,1,233.58,234.25,505,100,2,1,233.53,234.41,10,500,1,1,233.5,234.43,100,105,1,2,233.45,234.5,15,63,1,4,AAPL,0.0,0.0,0.0,
2024-10-21 12:27:21.555991612+00:00,2024-10-21T12:27:21.556157771Z,10,2,38,C,B,3,233.77,200,130,166159,13183172,233.86,233.98,295,7,3,1,233.81,233.99,2,200,2,1,233.8,234.0,105,17,2,2,233.77,234.1,200,100,1,1,233.7,234.13,1200,400,1,1,233.66,234.17,1,1,1,1,233.58,234.25,505,100,2,1,233.53,234.41,10,500,1,1,233.5,234.43,100,105,1,2,233.45,234.5,15,63,1,4,AAPL,0.0,-200.0,0.0,
2024-10-21 12:27:21.556005910+00:00,2024-10-21T12:27:21.556172659Z,10,2,38,A,B,1,233.81,200,130,166749,13183173,233.86,233.98,295,7,3,1,233.81,233.99,202,200,3,1,233.8,234.0,105,17,2,2,233.7,234.1,1200,100,1,1,233.66,234.13,1,400,1,1,233.58,234.17,505,1,2,1,233.53,234.25,10,100,1,1,233.5,234.41,100,500,1,1,233.45,234.43,15,105,1,2,233.4,234.5,110,63,2,4,AAPL,0.0,200.0,0.0,
2024-10-21 12:27:21.983129451+00:00,2024-10-21T12:27:21.983295309Z,10,2,38,C,B,1,233.81,200,130,165858,13183374,233.86,233.98,295,7,3,1,233.81,233.99,2,200,2,1,233.8,234.0,105,17,2,2,233.7,234.1,1200,100,1,1,233.66,234.13,1,400,1,1,233.58,234.17,505,1,2,1,233.53,234.25,10,100,1,1,233.5,234.41,100,500,1,1,233.45,234.43,15,105,1,2,233.4,234.5,110,63,2,4,AAPL,0.0,-200.0,0.0,
2024-10-21 12:27:21.983142748+00:00,2024-10-21T12:27:21.983308878Z,10,2,38,A,B,3,233.77,400,130,166130,13183375,233.86,233.98,295,7,3,1,233.81,233.99,2,200,2,1,233.8,234.0,105,17,2,2,233.77,234.1,400,100,1,1,233.7,234.13,1200,400,1,1,233.66,234.17,1,1,1,1,233.58,234.25,505,100,2,1,233.53,234.41,10,500,1,1,233.5,234.43,100,105,1,2,233.45,234.5,15,63,1,4,AAPL,0.0,0.0,0.0,
2024-10-21 12:27:22.988903196+00:00,2024-10-21T12:27:22.989069356Z,10,2,38,C,A,0,233.98,7,130,166160,13184098,233.86,233.99,295,200,3,1,233.81,234.0,2,17,2,2,233.8,234.1,105,100,2,1,233.77,234.13,400,400,1,1,233.7,234.17,1200,1,1,1,233.66,234.25,1,100,1,1,233.58,234.41,505,500,2,1,233.53,234.43,10,105,1,2,233.5,234.5,100,63,1,4,233.45,234.59,15,60,1,1,AAPL,0.0,0.0,0.0,
2024-10-21 12:27:23.025707565+00:00,2024-10-21T12:27:23.025873698Z,10,2,38,C,B,3,233.77,400,130,166133,13184133,233.86,233.99,295,200,3,1,233.81,234.0,2,17,2,2,233.8,234.1,105,100,2,1,233.7,234.13,1200,400,1,1,233.66,234.17,1,1,1,1,233.58,234.25,505,100,2,1,233.53,234.41,10,500,1,1,233.5,234.43,100,105,1,2,233.45,234.5,15,63,1,4,233.4,234.59,110,60,2,1,AAPL,0.0,0.0,0.0,
2024-10-21 12:27:23.025720316+00:00,2024-10-21T12:27:23.025886464Z,10,2,38,A,B,3,233.74,200,130,166148,13184134,233.86,233.99,295,200,3,1,233.81,234.0,2,17,2,2,233.8,234.1,105,100,2,1,233.74,234.13,200,400,1,1,233.7,234.17,1200,1,1,1,233.66,234.25,1,100,1,1,233.58,234.41,505,500,2,1,233.53,234.43,10,105,1,2,233.5,234.5,100,63,1,4,233.45,234.59,15,60,1,1,AAPL,0.0,0.0,0.0,
2024-10-21 12:27:24.992239712+00:00,2024-10-21T12:27:24.992972792Z,10,2,38,A,A,0,233.99,7,130,733080,13186020,233.86,233.99,295,207,3,2,233.81,234.0,2,17,2,2,233.8,234.1,105,100,2,1,233.74,234.13,200,400,1,1,233.7,234.17,1200,1,1,1,233.66,234.25,1,100,1,1,233.58,234.41,505,500,2,1,233.53,234.43,10,105,1,2,233.5,234.5,100,63,1,4,233.45,234.59,15,60,1,1,AAPL,-7.0,-7.0,-7.0,
2024-10-21 12:27:25.038119028+00:00,2024-10-21T12:27:25.038852343Z,10,2,38,A,B,3,233.77,200,130,733315,13186052,233.86,233.99,295,207,3,2,233.81,234.0,2,17,2,2,233.8,234.1,105,100,2,1,233.77,234.13,200,400,1,1,233.7,234.17,1200,1,1,1,233.66,234.25,1,100,1,1,233.58,234.41,505,500,2,1,233.53,234.43,10,105,1,2,233.5,234.5,100,63,1,4,233.45,234.59,15,60,1,1,AAPL,0.0,0.0,-7.0,
2024-10-21 12:27:26.130738899+00:00,2024-10-21T12:27:26.131472457Z,10,2,38,A,B,3,233.77,200,130,733558,13186986,233.86,233.99,295,207,3,2,233.81,234.0,2,17,2,2,233.8,234.1,105,100,2,1,233.77,234.13,400,400,2,1,233.7,234.17,1200,1,1,1,233.66,234.25,1,100,1,1,233.58,234.41,505,500,2,1,233.53,234.43,10,105,1,2,233.5,234.5,100,63,1,4,233.45,234.59,15,60,1,1,AAPL,0.0,200.0,0.0,
2024-10-21 12:27:28.578403729+00:00,2024-10-21T12:27:28.579136710Z,10,2,38,C,A,0,233.99,7,130,732981,13188280,233.86,233.99,295,200,3,1,233.81,234.0,2,17,2,2,233.8,234.1,105,100,2,1,233.77,234.13,400,400,2,1,233.7,234.17,1200,1,1,1,233.66,234.25,1,100,1,1,233.58,234.41,505,500,2,1,233.53,234.43,10,105,1,2,233.5,234.5,100,63,1,4,233.45,234.59,15,60,1,1,AAPL,7.0,7.0,7.0,
2024-10-21 12:27:29.135563917+00:00,2024-10-21T12:27:29.136296936Z,10,2,38,C,A,0,233.99,200,130,733019,13188524,233.86,234.0,295,17,3,2,233.81,234.1,2,100,2,1,233.8,234.13,105,400,2,1,233.77,234.17,400,1,2,1,233.7,234.25,1200,100,1,1,233.66,234.41,1,500,1,1,233.58,234.43,505,105,2,2,233.53,234.5,10,63,1,4,233.5,234.59,100,60,1,1,233.45,234.75,15,1,1,1,AAPL,0.0,0.0,7.0,
2024-10-21 12:27:29.135580379+00:00,2024-10-21T12:27:29.136314635Z,10,2,38,A,A,1,234.05,400,130,734256,13188525,233.86,234.0,295,17,3,2,233.81,234.05,2,400,2,1,233.8,234.1,105,100,2,1,233.77,234.13,400,400,2,1,233.7,234.17,1200,1,1,1,233.66,234.25,1,100,1,1,233.58,234.41,505,500,2,1,233.53,234.43,10,105,1,2,233.5,234.5,100,63,1,4,233.45,234.59,15,60,1,1,AAPL,0.0,0.0,7.0,
2024-10-21 12:27:30.581609917+00:00,2024-10-21T12:27:30.582343028Z,10,2,38,A,A,6,234.41,7,130,733111,13189750,233.86,234.0,295,17,3,2,233.81,234.05,2,400,2,1,233.8,234.1,105,100,2,1,233.77,234.13,400,400,2,1,233.7,234.17,1200,1,1,1,233.66,234.25,1,100,1,1,233.58,234.41,505,507,2,2,233.53,234.43,10,105,1,2,233.5,234.5,100,63,1,4,233.45,234.59,15,60,1,1,AAPL,0.0,0.0,0.0,
2024-10-21 12:27:37.149186319+00:00,2024-10-21T12:27:37.149919392Z,10,2,38,C,B,3,233.77,200,130,733073,13194254,233.86,234.0,295,17,3,2,233.81,234.05,2,400,2,1,233.8,234.1,105,100,2,1,233.77,234.13,200,400,1,1,233.7,234.17,1200,1,1,1,233.66,234.25,1,100,1,1,233.58,234.41,505,507,2,2,233.53,234.43,10,105,1,2,233.5,234.5,100,63,1,4,233.45,234.59,15,60,1,1,AAPL,0.0,-200.0,0.0,
2024-10-21 12:27:37.149198552+00:00,2024-10-21T12:27:37.149931822Z,10,2,38,A,B,3,233.78,400,130,733270,13194255,233.86,234.0,295,17,3,2,233.81,234.05,2,400,2,1,233.8,234.1,105,100,2,1,233.78,234.13,400,400,1,1,233.7,234.17,1200,1,1,1,233.66,234.25,1,100,1,1,233.58,234.41,505,507,2,2,233.53,234.43,10,105,1,2,233.5,234.5,100,63,1,4,233.45,234.59,15,60,1,1,AAPL,0.0,0.0,0.0,
2024-10-21 12:27:37.281359883+00:00,2024-10-21T12:27:37.282093181Z,10,2,38,A,A,1,234.02,200,130,733298,13194447,233.86,234.0,295,17,3,2,233.81,234.02,2,200,2,1,233.8,234.1,105,100,2,1,233.78,234.13,400,400,1,1,233.7,234.17,1200,1,1,1,233.66,234.25,1,100,1,1,233.58,234.41,505,507,2,2,233.53,234.43,10,105,1,2,233.5,234.5,100,63,1,4,233.45,234.59,15,60,1,1,AAPL,0.0,0.0,0.0,
2024-10-21 12:27:37.731121489+00:00,2024-10-21T12:27:37.731855277Z,10,2,38,A,B,3,233.79,400,130,733788,13195199,233.86,234.0,295,17,3,2,233.81,234.02,2,200,2,1,233.8,234.1,105,100,2,1,233.79,234.13,400,400,1,1,233.7,234.17,1200,1,1,1,233.66,234.25,1,100,1,1,233.58,234.41,505,507,2,2,233.53,234.43,10,105,1,2,233.5,234.5,100,63,1,4,233.45,234.59,15,60,1,1,AAPL,0.0,0.0,0.0,
2024-10-21 12:27:37.763839849+00:00,2024-10-21T12:27:37.764573144Z,10,2,38,C,B,3,233.79,200,130,733295,13195270,233.86,234.0,295,17,3,2,233.81,234.02,2,200,2,1,233.8,234.1,105,100,2,1,233.79,234.13,200,400,1,1,233.7,234.17,1200,1,1,1,233.66,234.25,1,100,1,1,233.58,234.41,505,507,2,2,233.53,234.43,10,105,1,2,233.5,234.5,100,63,1,4,233.45,234.59,15,60,1,1,AAPL,0.0,-200.0,0.0,
2024-10-21 12:27:37.766952915+00:00,2024-10-21T12:27:37.767686766Z,10,2,38,A,A,1,234.02,200,130,733851,13195276,233.86,234.0,295,17,3,2,233.81,234.02,2,400,2,2,233.8,234.1,105,100,2,1,233.79,234.13,200,400,1,1,233.7,234.17,1200,1,1,1,233.66,234.25,1,100,1,1,233.58,234.41,505,507,2,2,233.53,234.43,10,105,1,2,233.5,234.5,100,63,1,4,233.45,234.59,15,60,1,1,AAPL,0.0,-200.0,0.0,
2024-10-21 12:27:39.525383410+00:00,2024-10-21T12:27:39.526116351Z,10,2,38,C,A,1,234.02,200,130,732941,13197083,233.86,234.0,295,17,3,2,233.81,234.02,2,200,2,1,233.8,234.1,105,100,2,1,233.79,234.13,200,400,1,1,233.7,234.17,1200,1,1,1,233.66,234.25,1,100,1,1,233.58,234.41,505,507,2,2,233.53,234.43,10,105,1,2,233.5,234.5,100,63,1,4,233.45,234.59,15,60,1,1,AAPL,0.0,200.0,0.0,
2024-10-21 12:27:39.525394818+00:00,2024-10-21T12:27:39.526127909Z,10,2,38,C,A,1,234.02,200,130,733091,13197084,233.86,234.0,295,17,3,2,233.81,234.1,2,100,2,1,233.8,234.13,105,400,2,1,233.79,234.17,200,1,1,1,233.7,234.25,1200,100,1,1,233.66,234.41,1,507,1,2,233.58,234.43,505,105,2,2,233.53,234.5,10,63,1,4,233.5,234.59,100,60,1,1,233.45,234.75,15,1,1,1,AAPL,0.0,0.0,0.0,
2024-10-21 12:27:39.526899044+00:00,2024-10-21T12:27:39.527631797Z,10,2,38,C,A,5,234.41,7,130,732753,13197088,233.86,234.0,295,17,3,2,233.81,234.1,2,100,2,1,233.8,234.13,105,400,2,1,233.79,234.17,200,1,1,1,233.7,234.25,1200,100,1,1,233.66,234.41,1,500,1,1,233.58,234.43,505,105,2,2,233.53,234.5,10,63,1,4,233.5,234.59,100,60,1,1,233.45,234.75,15,1,1,1,AAPL,0.0,0.0,0.0,
2024-10-21 12:27:39.592903496+00:00,2024-10-21T12:27:39.593636447Z,10,2,38,A,B,1,233.84,100,130,732951,13197554,233.86,234.0,295,17,3,2,233.84,234.1,100,100,1,1,233.81,234.13,2,400,2,1,233.8,234.17,105,1,2,1,233.79,234.25,200,100,1,1,233.7,234.41,1200,500,1,1,233.66,234.43,1,105,1,2,233.58,234.5,505,63,2,4,233.53,234.59,10,60,1,1,233.5,234.75,100,1,1,1,AAPL,0.0,0.0,0.0,
2024-10-21 12:27:39.593262886+00:00,2024-10-21T12:27:39.593996622Z,10,2,38,C,B,1,233.84,100,130,733736,13197558,233.86,234.0,295,17,3,2,233.81,234.1,2,100,2,1,233.8,234.13,105,400,2,1,233.79,234.17,200,1,1,1,233.7,234.25,1200,100,1,1,233.66,234.41,1,500,1,1,233.58,234.43,505,105,2,2,233.53,234.5,10,63,1,4,233.5,234.59,100,60,1,1,233.45,234.75,15,1,1,1,AAPL,0.0,0.0,0.0,
2024-10-21 12:27:39.711750527+00:00,2024-10-21T12:27:39.712483751Z,10,2,38,A,A,1,234.02,400,130,733224,13197970,233.86,234.0,295,17,3,2,233.81,234.02,2,400,2,1,233.8,234.1,105,100,2,1,233.79,234.13,200,400,1,1,233.7,234.17,1200,1,1,1,233.66,234.25,1,100,1,1,233.58,234.41,505,500,2,1,233.53,234.43,10,105,1,2,233.5,234.5,100,63,1,4,233.45,234.59,15,60,1,1,AAPL,0.0,0.0,0.0,
2024-10-21 12:27:40.731328339+00:00,2024-10-21T12:27:40.732061815Z,10,2,38,A,A,1,234.01,400,130,733476,13198996,233.86,234.0,295,17,3,2,233.81,234.01,2,400,2,1,233.8,234.1,105,100,2,1,233.79,234.13,200,400,1,1,233.7,234.17,1200,1,1,1,233.66,234.25,1,100,1,1,233.58,234.41,505,500,2,1,233.53,234.43,10,105,1,2,233.5,234.5,100,63,1,4,233.45,234.59,15,60,1,1,AAPL,0.0,0.0,0.0,
2024-10-21 12:27:40.757807867+00:00,2024-10-21T12:27:40.758541085Z,10,2,38,C,A,1,234.01,400,130,733218,13199068,233.86,234.0,295,17,3,2,233.81,234.1,2,100,2,1,233.8,234.13,105,400,2,1,233.79,234.17,200,1,1,1,233.7,234.25,1200,100,1,1,233.66,234.41,1,500,1,1,233.58,234.43,505,105,2,2,233.53,234.5,10,63,1,4,233.5,234.59,100,60,1,1,233.45,234.75,15,1,1,1,AAPL,0.0,0.0,0.0,
2024-10-21 12:27:40.757820402+00:00,2024-10-21T12:27:40.758553589Z,10,2,38,A,A,1,234.02,200,130,733187,13199069,233.86,234.0,295,17,3,2,233.81,234.02,2,200,2,1,233.8,234.1,105,100,2,1,233.79,234.13,200,400,1,1,233.7,234.17,1200,1,1,1,233.66,234.25,1,100,1,1,233.58,234.41,505,500,2,1,233.53,234.43,10,105,1,2,233.5,234.5,100,63,1,4,233.45,234.59,15,60,1,1,AAPL,0.0,0.0,0.0,
2024-10-21 12:27:41.105981707+00:00,2024-10-21T12:27:41.106714797Z,10,2,38,C,A,1,234.02,200,130,733090,13199310,233.86,234.0,295,17,3,2,233.81,234.1,2,100,2,1,233.8,234.13,105,400,2,1,233.79,234.17,200,1,1,1,233.7,234.25,1200,100,1,1,233.66,234.41,1,500,1,1,233.58,234.43,505,105,2,2,233.53,234.5,10,63,1,4,233.5,234.59,100,60,1,1,233.45,234.75,15,1,1,1,AAPL,0.0,0.0,0.0,
2024-10-21 12:27:41.175574942+00:00,2024-10-21T12:27:41.176308255Z,10,2,38,A,A,1,234.06,200,130,733313,13199399,233.86,234.0,295,17,3,2,233.81,234.06,2,200,2,1,233.8,234.1,105,100,2,1,233.79,234.13,200,400,1,1,233.7,234.17,1200,1,1,1,233.66,234.25,1,100,1,1,233.58,234.41,505,500,2,1,233.53,234.43,10,105,1,2,233.5,234.5,100,63,1,4,233.45,234.59,15,60,1,1,AAPL,0.0,0.0,0.0,
2024-10-21 12:27:41.222814573+00:00,2024-10-21T12:27:41.223548018Z,10,2,38,A,A,1,234.06,200,130,733445,13199432,233.86,234.0,295,17,3,2,233.81,234.06,2,400,2,2,233.8,234.1,105,100,2,1,233.79,234.13,200,400,1,1,233.7,234.17,1200,1,1,1,233.66,234.25,1,100,1,1,233.58,234.41,505,500,2,1,233.53,234.43,10,105,1,2,233.5,234.5,100,63,1,4,233.45,234.59,15,60,1,1,AAPL,0.0,-200.0,0.0,
2024-10-21 12:27:41.319854032+00:00,2024-10-21T12:27:41.320586998Z,10,2,38,C,A,1,234.06,200,130,732966,13199474,233.86,234.0,295,17,3,2,233.81,234.06,2,200,2,1,233.8,234.1,105,100,2,1,233.79,234.13,200,400,1,1,233.7,234.17,1200,1,1,1,233.66,234.25,1,100,1,1,233.58,234.41,505,500,2,1,233.53,234.43,10,105,1,2,233.5,234.5,100,63,1,4,233.45,234.59,15,60,1,1,AAPL,0.0,200.0,0.0,
2024-10-21 12:27:41.319866876+00:00,2024-10-21T12:27:41.320600607Z,10,2,38,A,A,1,234.04,200,130,733731,13199475,233.86,234.0,295,17,3,2,233.81,234.04,2,200,2,1,233.8,234.1,105,100,2,1,233.79,234.13,200,400,1,1,233.7,234.17,1200,1,1,1,233.66,234.25,1,100,1,1,233.58,234.41,505,500,2,1,233.53,234.43,10,105,1,2,233.5,234.5,100,63,1,4,233.45,234.59,15,60,1,1,AAPL,0.0,0.0,0.0,
2024-10-21 12:27:41.529517717+00:00,2024-10-21T12:27:41.530250934Z,10,2,38,A,A,6,234.38,7,130,733217,13199682,233.86,234.0,295,17,3,2,233.81,234.04,2,200,2,1,233.8,234.1,105,100,2,1,233.79,234.13,200,400,1,1,233.7,234.17,1200,1,1,1,233.66,234.25,1,100,1,1,233.58,234.38,505,7,2,1,233.53,234.41,10,500,1,1,233.5,234.43,100,105,1,2,233.45,234.5,15,63,1,4,AAPL,0.0,0.0,0.0,
2024-10-21 12:27:46.417280824+00:00,2024-10-21T12:27:46.418013842Z,10,2,38,C,B,3,233.79,200,130,733018,13203166,233.86,234.0,295,17,3,2,233.81,234.04,2,200,2,1,233.8,234.1,105,100,2,1,233.7,234.13,1200,400,1,1,233.66,234.17,1,1,1,1,233.58,234.25,505,100,2,1,233.53,234.38,10,7,1,1,233.5,234.41,100,500,1,1,233.45,234.43,15,105,1,2,233.4,234.5,110,63,2,4,AAPL,0.0,0.0,0.0,
2024-10-21 12:27:46.417292639+00:00,2024-10-21T12:27:46.418026002Z,10,2,38,A,B,3,233.77,400,130,733363,13203167,233.86,234.0,295,17,3,2,233.81,234.04,2,200,2,1,233.8,234.1,105,100,2,1,233.77,234.13,400,400,1,1,233.7,234.17,1200,1,1,1,233.66,234.25,1,100,1,1,233.58,234.38,505,7,2,1,233.53,234.41,10,500,1,1,233.5,234.43,100,105,1,2,233.45,234.5,15,63,1,4,AAPL,0.0,0.0,0.0,
2024-10-21 12:27:46.472297071+00:00,2024-10-21T12:27:46.473030357Z,10,2,38,A,A,1,234.03,200,130,733286,13203213,233.86,234.0,295,17,3,2,233.81,234.03,2,200,2,1,233.8,234.1,105,100,2,1,233.77,234.13,400,400,1,1,233.7,234.17,1200,1,1,1,233.66,234.25,1,100,1,1,233.58,234.38,505,7,2,1,233.53,234.41,10,500,1,1,233.5,234.43,100,105,1,2,233.45,234.5,15,63,1,4,AAPL,0.0,0.0,0.0,
2024-10-21 12:27:47.208717142+00:00,2024-10-21T12:27:47.209450267Z,10,2,38,C,A,1,234.03,200,130,733125,13204087,233.86,234.0,295,17,3,2,233.81,234.1,2,100,2,1,233.8,234.13,105,400,2,1,233.77,234.17,400,1,1,1,233.7,234.25,1200,100,1,1,233.66,234.38,1,7,1,1,233.58,234.41,505,500,2,1,233.53,234.43,10,105,1,2,233.5,234.5,100,63,1,4,233.45,234.59,15,60,1,1,AAPL,0.0,0.0,0.0,
2024-10-21 12:27:47.309406274+00:00,2024-10-21T12:27:47.310139513Z,10,2,38,A,A,1,234.03,200,130,733239,13204445,233.86,234.0,295,17,3,2,233.81,234.03,2,200,2,1,233.8,234.1,105,100,2,1,233.77,234.13,400,400,1,1,233.7,234.17,1200,1,1,1,233.66,234.25,1,100,1,1,233.58,234.38,505,7,2,1,233.53,234.41,10,500,1,1,233.5,234.43,100,105,1,2,233.45,234.5,15,63,1,4,AAPL,0.0,0.0,0.0,
2024-10-21 12:27:47.985298442+00:00,2024-10-21T12:27:47.985465401Z,10,2,38,A,B,3,233.78,400,130,166959,13205236,233.86,234.0,295,17,3,2,233.81,234.03,2,200,2,1,233.8,234.1,105,100,2,1,233.78,234.13,400,400,1,1,233.7,234.17,1200,1,1,1,233.66,234.25,1,100,1,1,233.58,234.38,505,7,2,1,233.53,234.41,10,500,1,1,233.5,234.43,100,105,1,2,233.45,234.5,15,63,1,4,AAPL,0.0,0.0,0.0,
2024-10-21 12:27:50.060705561+00:00,2024-10-21T12:27:50.060871934Z,10,2,38,C,A,1,234.03,200,130,166373,13206376,233.86,234.0,295,17,3,2,233.81,234.1,2,100,2,1,233.8,234.13,105,400,2,1,233.78,234.17,400,1,1,1,233.7,234.25,1200,100,1,1,233.66,234.38,1,7,1,1,233.58,234.41,505,500,2,1,233.53,234.43,10,105,1,2,233.5,234.5,100,63,1,4,233.45,234.59,15,60,1,1,AAPL,0.0,0.0,0.0,
2024-10-21 12:27:50.061424726+00:00,2024-10-21T12:27:50.061591231Z,10,2,38,A,B,0,233.87,4,130,166505,13206379,233.87,234.0,4,17,1,2,233.86,234.1,295,100,3,1,233.81,234.13,2,400,2,1,233.8,234.17,105,1,2,1,233.78,234.25,400,100,1,1,233.7,234.38,1200,7,1,1,233.66,234.41,1,500,1,1,233.58,234.43,505,105,2,2,233.53,234.5,10,63,1,4,233.5,234.59,100,60,1,1,AAPL,0.0,0.0,0.0,
2024-10-21 12:27:50.061724093+00:00,2024-10-21T12:27:50.061891362Z,10,2,38,A,B,0,233.87,100,128,167269,13206382,233.87,234.0,104,17,2,2,233.86,234.1,295,100,3,1,233.81,234.13,2,400,2,1,233.8,234.17,105,1,2,1,233.78,234.25,400,100,1,1,233.7,234.38,1200,7,1,1,233.66,234.41,1,500,1,1,233.58,234.43,505,105,2,2,233.53,234.5,10,63,1,4,233.5,234.59,100,60,1,1,AAPL,100.0,100.0,100.0,
2024-10-21 12:27:50.062117451+00:00,2024-10-21T12:27:50.062283396Z,10,2,38,C,B,0,233.87,100,130,165945,13206387,233.87,234.0,4,17,1,2,233.86,234.1,295,100,3,1,233.81,234.13,2,400,2,1,233.8,234.17,105,1,2,1,233.78,234.25,400,100,1,1,233.7,234.38,1200,7,1,1,233.66,234.41,1,500,1,1,233.58,234.43,505,105,2,2,233.53,234.5,10,63,1,4,233.5,234.59,100,60,1,1,AAPL,-100.0,-100.0,0.0,
2024-10-21 12:27:50.063092822+00:00,2024-10-21T12:27:50.063258837Z,10,2,38,C,A,5,234.38,7,130,166015,13206393,233.87,234.0,4,17,1,2,233.86,234.1,295,100,3,1,233.81,234.13,2,400,2,1,233.8,234.17,105,1,2,1,233.78,234.25,400,100,1,1,233.7,234.41,1200,500,1,1,233.66,234.43,1,105,1,2,233.58,234.5,505,63,2,4,233.53,234.59,10,60,1,1,233.5,234.75,100,1,1,1,AAPL,0.0,0.0,0.0,
2024-10-21 12:27:50.065517946+00:00,2024-10-21T12:27:50.065683975Z,10,2,38,C,B,0,233.87,4,130,166029,13206394,233.86,234.0,295,17,3,2,233.81,234.1,2,100,2,1,233.8,234.13,105,400,2,1,233.78,234.17,400,1,1,1,233.7,234.25,1200,100,1,1,233.66,234.41,1,500,1,1,233.58,234.43,505,105,2,2,233.53,234.5,10,63,1,4,233.5,234.59,100,60,1,1,233.45,234.75,15,1,1,1,AAPL,0.0,0.0,0.0,
2024-10-21 12:27:50.072608485+00:00,2024-10-21T12:27:50.072777187Z,10,2,38,T,N,0,233.92,250,0,168702,13206395,233.86,234.0,295,17,3,2,233.81,234.1,2,100,2,1,233.8,234.13,105,400,2,1,233.78,234.17,400,1,1,1,233.7,234.25,1200,100,1,1,233.66,234.41,1,500,1,1,233.58,234.43,505,105,2,2,233.53,234.5,10,63,1,4,233.5,234.59,100,60,1,1,233.45,234.75,15,1,1,1,AAPL,0.0,0.0,0.0,
2024-10-21 12:27:50.072608485+00:00,2024-10-21T12:27:50.072777187Z,10,2,38,T,N,0,233.87,73,130,168702,13206396,233.86,234.0,295,17,3,2,233.81,234.1,2,100,2,1,233.8,234.13,105,400,2,1,233.78,234.17,400,1,1,1,233.7,234.25,1200,100,1,1,233.66,234.41,1,500,1,1,233.58,234.43,505,105,2,2,233.53,234.5,10,63,1,4,233.5,234.59,100,60,1,1,233.45,234.75,15,1,1,1,AAPL,0.0,0.0,0.0,
2024-10-21 12:27:50.167395987+00:00,2024-10-21T12:27:50.167562575Z,10,2,38,A,A,1,234.06,200,130,166588,13206479,233.86,234.0,295,17,3,2,233.81,234.06,2,200,2,1,233.8,234.1,105,100,2,1,233.78,234.13,400,400,1,1,233.7,234.17,1200,1,1,1,233.66,234.25,1,100,1,1,233.58,234.41,505,500,2,1,233.53,234.43,10,105,1,2,233.5,234.5,100,63,1,4,233.45,234.59,15,60,1,1,AAPL,0.0,0.0,0.0,
2024-10-21 12:27:51.736205355+00:00,2024-10-21T12:27:51.736371710Z,10,2,38,A,A,1,234.06,200,130,166355,13207413,233.86,234.0,295,17,3,2,233.81,234.06,2,400,2,2,233.8,234.1,105,100,2,1,233.78,234.13,400,400,1,1,233.7,234.17,1200,1,1,1,233.66,234.25,1,100,1,1,233.58,234.41,505,500,2,1,233.53,234.43,10,105,1,2,233.5,234.5,100,63,1,4,233.45,234.59,15,60,1,1,AAPL,0.0,-200.0,0.0,
2024-10-21 12:27:51.790801843+00:00,2024-10-21T12:27:51.790967984Z,10,2,38,C,A,1,234.06,200,130,166141,13207602,233.86,234.0,295,17,3,2,233.81,234.06,2,200,2,1,233.8,234.1,105,100,2,1,233.78,234.13,400,400,1,1,233.7,234.17,1200,1,1,1,233.66,234.25,1,100,1,1,233.58,234.41,505,500,2,1,233.53,234.43,10,105,1,2,233.5,234.5,100,63,1,4,233.45,234.59,15,60,1,1,AAPL,0.0,200.0,0.0,
2024-10-21 12:27:51.790814229+00:00,2024-10-21T12:27:51.790980861Z,10,2,38,A,A,1,234.05,200,130,166632,13207603,233.86,234.0,295,17,3,2,233.81,234.05,2,200,2,1,233.8,234.1,105,100,2,1,233.78,234.13,400,400,1,1,233.7,234.17,1200,1,1,1,233.66,234.25,1,100,1,1,233.58,234.41,505,500,2,1,233.53,234.43,10,105,1,2,233.5,234.5,100,63,1,4,233.45,234.59,15,60,1,1,AAPL,0.0,0.0,0.0,
2024-10-21 12:27:52.065555514+00:00,2024-10-21T12:27:52.065722099Z,10,2,38,A,A,6,234.41,7,130,166585,13207879,233.86,234.0,295,17,3,2,233.81,234.05,2,200,2,1,233.8,234.1,105,100,2,1,233.78,234.13,400,400,1,1,233.7,234.17,1200,1,1,1,233.66,234.25,1,100,1,1,233.58,234.41,505,507,2,2,233.53,234.43,10,105,1,2,233.5,234.5,100,63,1,4,233.45,234.59,15,60,1,1,AAPL,0.0,0.0,0.0,
2024-10-21 12:27:52.393140055+00:00,2024-10-21T12:27:52.393306163Z,10,2,38,A,B,0,233.91,100,130,166108,13208151,233.91,234.0,100,17,1,2,233.86,234.05,295,200,3,1,233.81,234.1,2,100,2,1,233.8,234.13,105,400,2,1,233.78,234.17,400,1,1,1,233.7,234.25,1200,100,1,1,233.66,234.41,1,507,1,2,233.58,234.43,505,105,2,2,233.53,234.5,10,63,1,4,233.5,234.59,100,60,1,1,AAPL,0.0,0.0,0.0,
2024-10-21 12:27:52.393807534+00:00,2024-10-21T12:27:52.393974163Z,10,2,38,C,B,0,233.91,100,130,166629,13208153,233.86,234.0,295,17,3,2,233.81,234.05,2,200,2,1,233.8,234.1,105,100,2,1,233.78,234.13,400,400,1,1,233.7,234.17,1200,1,1,1,233.66,234.25,1,100,1,1,233.58,234.41,505,507,2,2,233.53,234.43,10,105,1,2,233.5,234.5,100,63,1,4,233.45,234.59,15,60,1,1,AAPL,0.0,0.0,0.0,
2024-10-21 12:27:53.196914522+00:00,2024-10-21T12:27:53.197081371Z,10,2,38,A,B,1,233.81,200,130,166849,13208530,233.86,234.0,295,17,3,2,233.81,234.05,202,200,3,1,233.8,234.1,105,100,2,1,233.7,234.13,1200,400,1,1,233.66,234.17,1,1,1,1,233.58,234.25,505,100,2,1,233.53,234.41,10,507,1,2,233.5,234.43,100,105,1,2,233.45,234.5,15,63,1,4,233.4,234.59,110,60,2,1,AAPL,0.0,200.0,0.0,
2024-10-21 12:27:55.777360755+00:00,2024-10-21T12:27:55.777527005Z,10,2,38,A,B,1,233.82,200,130,166250,13210010,233.86,234.0,295,17,3,2,233.82,234.05,200,200,1,1,233.81,234.1,2,100,2,1,233.8,234.13,105,400,2,1,233.7,234.17,1200,1,1,1,233.66,234.25,1,100,1,1,233.58,234.41,505,507,2,2,233.53,234.43,10,105,1,2,233.5,234.5,100,63,1,4,233.45,234.59,15,60,1,1,AAPL,0.0,0.0,0.0,
2024-10-21 12:27:57.069644133+00:00,2024-10-21T12:27:57.069810253Z,10,2,38,C,A,6,234.41,7,130,166120,13211098,233.86,234.0,295,17,3,2,233.82,234.05,200,200,1,1,233.81,234.1,2,100,2,1,233.8,234.13,105,400,2,1,233.7,234.17,1200,1,1,1,233.66,234.25,1,100,1,1,233.58,234.41,505,500,2,1,233.53,234.43,10,105,1,2,233.5,234.5,100,63,1,4,233.45,234.59,15,60,1,1,AAPL,0.0,0.0,0.0,
2024-10-21 12:27:59.074932933+00:00,2024-10-21T12:27:59.075099035Z,10,2,38,A,A,2,234.08,7,130,166102,13212016,233.86,234.0,295,17,3,2,233.82,234.05,200,200,1,1,233.81,234.08,2,7,2,1,233.8,234.1,105,100,2,1,233.7,234.13,1200,400,1,1,233.66,234.17,1,1,1,1,233.58,234.25,505,100,2,1,233.53,234.41,10,500,1,1,233.5,234.43,100,105,1,2,233.45,234.5,15,63,1,4,AAPL,0.0,0.0,0.0,
2024-10-21 12:28:13.140488443+00:00,2024-10-21T12:28:13.140654755Z,10,2,38,C,A,2,234.08,7,130,166312,13223358,233.86,234.0,295,17,3,2,233.82,234.05,200,200,1,1,233.81,234.1,2,100,2,1,233.8,234.13,105,400,2,1,233.7,234.17,1200,1,1,1,233.66,234.25,1,100,1,1,233.58,234.41,505,500,2,1,233.53,234.43,10,105,1,2,233.5,234.5,100,63,1,4,233.45,234.59,15,60,1,1,AAPL,0.0,0.0,0.0,
2024-10-21 12:28:13.787619066+00:00,2024-10-21T12:28:13.787785757Z,10,2,38,C,B,0,233.86,100,130,166691,13223694,233.86,234.0,195,17,2,2,233.82,234.05,200,200,1,1,233.81,234.1,2,100,2,1,233.8,234.13,105,400,2,1,233.7,234.17,1200,1,1,1,233.66,234.25,1,100,1,1,233.58,234.41,505,500,2,1,233.53,234.43,10,105,1,2,233.5,234.5,100,63,1,4,233.45,234.59,15,60,1,1,AAPL,-100.0,-100.0,-100.0,
2024-10-21 12:28:15.143399309+00:00,2024-10-21T12:28:15.143565718Z,10,2,38,A,A,2,234.07,7,130,166409,13224881,233.86,234.0,195,17,2,2,233.82,234.05,200,200,1,1,233.81,234.07,2,7,2,1,233.8,234.1,105,100,2,1,233.7,234.13,1200,400,1,1,233.66,234.17,1,1,1,1,233.58,234.25,505,100,2,1,233.53,234.41,10,500,1,1,233.5,234.43,100,105,1,2,233.45,234.5,15,63,1,4,AAPL,0.0,0.0,0.0,
2024-10-21 12:28:15.998512488+00:00,2024-10-21T12:28:15.998678832Z,10,2,38,A,A,1,234.05,200,130,166344,13225383,233.86,234.0,195,17,2,2,233.82,234.05,200,400,1,2,233.81,234.07,2,7,2,1,233.8,234.1,105,100,2,1,233.7,234.13,1200,400,1,1,233.66,234.17,1,1,1,1,233.58,234.25,505,100,2,1,233.53,234.41,10,500,1,1,233.5,234.43,100,105,1,2,233.45,234.5,15,63,1,4,AAPL,0.0,-200.0,0.0,
2024-10-21 12:28:16.004484708+00:00,2024-10-21T12:28:16.004651224Z,10,2,38,C,A,1,234.05,200,130,166516,13225389,233.86,234.0,195,17,2,2,233.82,234.05,200,200,1,1,233.81,234.07,2,7,2,1,233.8,234.1,105,100,2,1,233.7,234.13,1200,400,1,1,233.66,234.17,1,1,1,1,233.58,234.25,505,100,2,1,233.53,234.41,10,500,1,1,233.5,234.43,100,105,1,2,233.45,234.5,15,63,1,4,AAPL,0.0,200.0,0.0,
2024-10-21 12:28:16.009375121+00:00,2024-10-21T12:28:16.009541505Z,10,2,38,A,A,1,234.05,200,130,166384,13225390,233.86,234.0,195,17,2,2,233.82,234.05,200,400,1,2,233.81,234.07,2,7,2,1,233.8,234.1,105,100,2,1,233.7,234.13,1200,400,1,1,233.66,234.17,1,1,1,1,233.58,234.25,505,100,2,1,233.53,234.41,10,500,1,1,233.5,234.43,100,105,1,2,233.45,234.5,15,63,1,4,AAPL,0.0,-200.0,0.0,
2024-10-21 12:28:18.439793678+00:00,2024-10-21T12:28:18.439960157Z,10,2,38,C,B,1,233.82,200,130,166479,13226392,233.86,234.0,195,17,2,2,233.81,234.05,2,400,2,2,233.8,234.07,105,7,2,1,233.7,234.1,1200,100,1,1,233.66,234.13,1,400,1,1,233.58,234.17,505,1,2,1,233.53,234.25,10,100,1,1,233.5,234.41,100,500,1,1,233.45,234.43,15,105,1,2,233.4,234.5,110,63,2,4,AAPL,0.0,0.0,0.0,
2024-10-21 12:28:18.439806868+00:00,2024-10-21T12:28:18.439973348Z,10,2,38,A,B,3,233.77,400,130,166480,13226393,233.86,234.0,195,17,2,2,233.81,234.05,2,400,2,2,233.8,234.07,105,7,2,1,233.77,234.1,400,100,1,1,233.7,234.13,1200,400,1,1,233.66,234.17,1,1,1,1,233.58,234.25,505,100,2,1,233.53,234.41,10,500,1,1,233.5,234.43,100,105,1,2,233.45,234.5,15,63,1,4,AAPL,0.0,0.0,0.0,
2024-10-21 12:28:18.595532956+00:00,2024-10-21T12:28:18.595699607Z,10,2,38,A,B,3,233.78,400,130,166651,13226507,233.86,234.0,195,17,2,2,233.81,234.05,2,400,2,2,233.8,234.07,105,7,2,1,233.78,234.1,400,100,1,1,233.7,234.13,1200,400,1,1,233.66,234.17,1,1,1,1,233.58,234.25,505,100,2,1,233.53,234.41,10,500,1,1,233.5,234.43,100,105,1,2,233.45,234.5,15,63,1,4,AAPL,0.0,0.0,0.0,
2024-10-21 12:28:21.754579574+00:00,2024-10-21T12:28:21.754746040Z,10,2,38,C,A,1,234.05,200,130,166466,13230028,233.86,234.0,195,17,2,2,233.81,234.05,2,200,2,1,233.8,234.07,105,7,2,1,233.78,234.1,400,100,1,1,233.7,234.13,1200,400,1,1,233.66,234.17,1,1,1,1,233.58,234.25,505,100,2,1,233.53,234.41,10,500,1,1,233.5,234.43,100,105,1,2,233.45,234.5,15,63,1,4,AAPL,0.0,200.0,0.0,
2024-10-21 12:28:21.754589712+00:00,2024-10-21T12:28:21.754755709Z,10,2,38,C,A,1,234.05,200,130,165997,13230029,233.86,234.0,195,17,2,2,233.81,234.07,2,7,2,1,233.8,234.1,105,100,2,1,233.78,234.13,400,400,1,1,233.7,234.17,1200,1,1,1,233.66,234.25,1,100,1,1,233.58,234.41,505,500,2,1,233.53,234.43,10,105,1,2,233.5,234.5,100,63,1,4,233.45,234.59,15,60,1,1,AAPL,0.0,0.0,0.0,
2024-10-21 12:28:21.754600821+00:00,2024-10-21T12:28:21.754767171Z,10,2,38,A,A,1,234.07,400,130,166350,13230030,233.86,234.0,195,17,2,2,233.81,234.07,2,407,2,2,233.8,234.1,105,100,2,1,233.78,234.13,400,400,1,1,233.7,234.17,1200,1,1,1,233.66,234.25,1,100,1,1,233.58,234.41,505,500,2,1,233.53,234.43,10,105,1,2,233.5,234.5,100,63,1,4,233.45,234.59,15,60,1,1,AAPL,0.0,-400.0,0.0,
2024-10-21 12:28:21.805245495+00:00,2024-10-21T12:28:21.805412137Z,10,2,38,A,B,3,233.79,400,130,166642,13230137,233.86,234.0,195,17,2,2,233.81,234.07,2,407,2,2,233.8,234.1,105,100,2,1,233.79,234.13,400,400,1,1,233.7,234.17,1200,1,1,1,233.66,234.25,1,100,1,1,233.58,234.41,505,500,2,1,233.53,234.43,10,105,1,2,233.5,234.5,100,63,1,4,233.45,234.59,15,60,1,1,AAPL,0.0,0.0,0.0,
2024-10-21 12:28:21.865225042+00:00,2024-10-21T12:28:21.865391217Z,10,2,38,C,B,3,233.79,200,130,166175,13230295,233.86,234.0,195,17,2,2,233.81,234.07,2,407,2,2,233.8,234.1,105,100,2,1,233.79,234.13,200,400,1,1,233.7,234.17,1200,1,1,1,233.66,234.25,1,100,1,1,233.58,234.41,505,500,2,1,233.53,234.43,10,105,1,2,233.5,234.5,100,63,1,4,233.45,234.59,15,60,1,1,AAPL,0.0,-200.0,0.0,
2024-10-21 12:28:32.979122877+00:00,2024-10-21T12:28:32.979289251Z,10,2,38,A,B,2,233.8,200,130,166374,13238520,233.86,234.0,195,17,2,2,233.81,234.07,2,407,2,2,233.8,234.1,305,100,3,1,233.7,234.13,1200,400,1,1,233.66,234.17,1,1,1,1,233.58,234.25,505,100,2,1,233.53,234.41,10,500,1,1,233.5,234.43,100,105,1,2,233.45,234.5,15,63,1,4,233.4,234.59,110,60,2,1,AAPL,0.0,200.0,0.0,
2024-10-21 12:28:35.114709429+00:00,2024-10-21T12:28:35.114875495Z,10,2,38,C,B,2,233.8,200,130,166066,13241058,233.86,234.0,195,17,2,2,233.81,234.07,2,407,2,2,233.8,234.1,105,100,2,1,233.7,234.13,1200,400,1,1,233.66,234.17,1,1,1,1,233.58,234.25,505,100,2,1,233.53,234.41,10,500,1,1,233.5,234.43,100,105,1,2,233.45,234.5,15,63,1,4,233.4,234.59,110,60,2,1,AAPL,0.0,-200.0,0.0,
2024-10-21 12:28:35.114721686+00:00,2024-10-21T12:28:35.114888161Z,10,2,38,A,B,3,233.78,200,130,166475,13241059,233.86,234.0,195,17,2,2,233.81,234.07,2,407,2,2,233.8,234.1,105,100,2,1,233.78,234.13,200,400,1,1,233.7,234.17,1200,1,1,1,233.66,234.25,1,100,1,1,233.58,234.41,505,500,2,1,233.53,234.43,10,105,1,2,233.5,234.5,100,63,1,4,233.45,234.59,15,60,1,1,AAPL,0.0,0.0,0.0,
2024-10-21 12:28:35.212998331+00:00,2024-10-21T12:28:35.213164931Z,10,2,38,A,A,1,234.06,400,130,166600,13241339,233.86,234.0,195,17,2,2,233.81,234.06,2,400,2,1,233.8,234.07,105,7,2,1,233.78,234.1,200,100,1,1,233.7,234.13,1200,400,1,1,233.66,234.17,1,1,1,1,233.58,234.25,505,100,2,1,233.53,234.41,10,500,1,1,233.5,234.43,100,105,1,2,233.45,234.5,15,63,1,4,AAPL,0.0,0.0,0.0,
2024-10-21 12:28:35.345053997+00:00,2024-10-21T12:28:35.345220081Z,10,2,38,A,B,3,233.78,200,130,166084,13241459,233.86,234.0,195,17,2,2,233.81,234.06,2,400,2,1,233.8,234.07,105,7,2,1,233.78,234.1,400,100,2,1,233.7,234.13,1200,400,1,1,233.66,234.17,1,1,1,1,233.58,234.25,505,100,2,1,233.53,234.41,10,500,1,1,233.5,234.43,100,105,1,2,233.45,234.5,15,63,1,4,AAPL,0.0,200.0,0.0,
2024-10-21 12:28:42.162092040+00:00,2024-10-21T12:28:42.162258578Z,10,2,38,C,B,3,233.78,200,130,166538,13247773,233.86,234.0,195,17,2,2,233.81,234.06,2,400,2,1,233.8,234.07,105,7,2,1,233.78,234.1,200,100,1,1,233.7,234.13,1200,400,1,1,233.66,234.17,1,1,1,1,233.58,234.25,505,100,2,1,233.53,234.41,10,500,1,1,233.5,234.43,100,105,1,2,233.45,234.5,15,63,1,4,AAPL,0.0,-200.0,0.0,
2024-10-21 12:28:42.162105350+00:00,2024-10-21T12:28:42.162271836Z,10,2,38,A,B,1,233.82,200,130,166486,13247774,233.86,234.0,195,17,2,2,233.82,234.06,200,400,1,1,233.81,234.07,2,7,2,1,233.8,234.1,105,100,2,1,233.7,234.13,1200,400,1,1,233.66,234.17,1,1,1,1,233.58,234.25,505,100,2,1,233.53,234.41,10,500,1,1,233.5,234.43,100,105,1,2,233.45,234.5,15,63,1,4,AAPL,0.0,0.0,0.0,
2024-10-21 12:28:45.429284120+00:00,2024-10-21T12:28:45.429450324Z,10,2,38,C,B,1,233.82,200,130,166204,13250330,233.86,234.0,195,17,2,2,233.81,234.06,2,400,2,1,233.8,234.07,105,7,2,1,233.7,234.1,1200,100,1,1,233.66,234.13,1,400,1,1,233.58,234.17,505,1,2,1,233.53,234.25,10,100,1,1,233.5,234.41,100,500,1,1,233.45,234.43,15,105,1,2,233.4,234.5,110,63,2,4,AAPL,0.0,0.0,0.0,
2024-10-21 12:28:45.429297045+00:00,2024-10-21T12:28:45.429463288Z,10,2,38,A,B,3,233.78,400,130,166243,13250331,233.86,234.0,195,17,2,2,233.81,234.06,2,400,2,1,233.8,234.07,105,7,2,1,233.78,234.1,400,100,1,1,233.7,234.13,1200,400,1,1,233.66,234.17,1,1,1,1,233.58,234.25,505,100,2,1,233.53,234.41,10,500,1,1,233.5,234.43,100,105,1,2,233.45,234.5,15,63,1,4,AAPL,0.0,0.0,0.0,
2024-10-21 12:28:48.483119828+00:00,2024-10-21T12:28:48.483286864Z,10,2,38,A,B,1,233.82,200,130,167036,13252635,233.86,234.0,195,17,2,2,233.82,234.06,200,400,1,1,233.81,234.07,2,7,2,1,233.8,234.1,105,100,2,1,233.7,234.13,1200,400,1,1,233.66,234.17,1,1,1,1,233.58,234.25,505,100,2,1,233.53,234.41,10,500,1,1,233.5,234.43,100,105,1,2,233.45,234.5,15,63,1,4,AAPL,0.0,0.0,0.0,
2024-10-21 12:28:55.560815833+00:00,2024-10-21T12:28:55.560984753Z,10,2,38,T,A,0,233.86,10,0,168920,13258219,233.86,234.0,195,17,2,2,233.82,234.06,200,400,1,1,233.81,234.07,2,7,2,1,233.8,234.1,105,100,2,1,233.7,234.13,1200,400,1,1,233.66,234.17,1,1,1,1,233.58,234.25,505,100,2,1,233.53,234.41,10,500,1,1,233.5,234.43,100,105,1,2,233.45,234.5,15,63,1,4,AAPL,0.0,0.0,0.0,
2024-10-21 12:28:55.560817191+00:00,2024-10-21T12:28:55.560984753Z,10,2,38,A,N,0,233.9,100,130,167562,13258220,233.86,233.9,185,100,2,1,233.82,234.0,200,17,1,2,233.81,234.06,2,400,2,1,233.8,234.07,105,7,2,1,233.7,234.1,1200,100,1,1,233.66,234.13,1,400,1,1,233.58,234.17,505,1,2,1,233.53,234.25,10,100,1,1,233.5,234.41,100,500,1,1,233.45,234.43,15,105,1,2,AAPL,-10.0,-10.0,-10.0,
2024-10-21 12:28:55.560841422+00:00,2024-10-21T12:28:55.561007655Z,10,2,38,A,A,0,233.9,100,130,166233,13258221,233.86,233.9,185,200,2,2,233.82,234.0,200,17,1,2,233.81,234.06,2,400,2,1,233.8,234.07,105,7,2,1,233.7,234.1,1200,100,1,1,233.66,234.13,1,400,1,1,233.58,234.17,505,1,2,1,233.53,234.25,10,100,1,1,233.5,234.41,100,500,1,1,233.45,234.43,15,105,1,2,AAPL,-100.0,-100.0,-110.0,
2024-10-21 12:28:55.560892756+00:00,2024-10-21T12:28:55.561058773Z,10,2,38,C,B,1,233.82,200,130,166017,13258225,233.86,233.9,185,200,2,2,233.81,234.0,2,17,2,2,233.8,234.06,105,400,2,1,233.7,234.07,1200,7,1,1,233.66,234.1,1,100,1,1,233.58,234.13,505,400,2,1,233.53,234.17,10,1,1,1,233.5,234.25,100,100,1,1,233.45,234.41,15,500,1,1,233.4,234.43,110,105,2,2,AAPL,0.0,0.0,-110.0,
2024-10-21 12:28:55.561120579+00:00,2024-10-21T12:28:55.561286132Z,10,2,38,C,A,0,233.9,100,130,165553,13258227,233.86,233.9,185,100,2,1,233.81,234.0,2,17,2,2,233.8,234.06,105,400,2,1,233.7,234.07,1200,7,1,1,233.66,234.1,1,100,1,1,233.58,234.13,505,400,2,1,233.53,234.17,10,1,1,1,233.5,234.25,100,100,1,1,233.45,234.41,15,500,1,1,233.4,234.43,110,105,2,2,AAPL,100.0,100.0,-10.0,
2024-10-21 12:28:55.561195478+00:00,2024-10-21T12:28:55.561361290Z,10,2,38,C,A,0,233.9,100,130,165812,13258228,233.86,234.0,185,17,2,2,233.81,234.06,2,400,2,1,233.8,234.07,105,7,2,1,233.7,234.1,1200,100,1,1,233.66,234.13,1,400,1,1,233.58,234.17,505,1,2,1,233.53,234.25,10,100,1,1,233.5,234.41,100,500,1,1,233.45,234.43,15,105,1,2,233.4,234.5,110,63,2,4,AAPL,0.0,0.0,-10.0,
2024-10-21 12:28:55.562160475+00:00,2024-10-21T12:28:55.562326440Z,10,2,38,C,A,2,234.07,7,130,165965,13258230,233.86,234.0,185,17,2,2,233.81,234.06,2,400,2,1,233.8,234.1,105,100,2,1,233.7,234.13,1200,400,1,1,233.66,234.17,1,1,1,1,233.58,234.25,505,100,2,1,233.53,234.41,10,500,1,1,233.5,234.43,100,105,1,2,233.45,234.5,15,63,1,4,233.4,234.59,110,60,2,1,AAPL,0.0,0.0,-10.0,
2024-10-21 12:28:55.639691686+00:00,2024-10-21T12:28:55.639858396Z,10,2,38,A,B,3,233.72,400,130,166710,13258325,233.86,234.0,185,17,2,2,233.81,234.06,2,400,2,1,233.8,234.1,105,100,2,1,233.72,234.13,400,400,1,1,233.7,234.17,1200,1,1,1,233.66,234.25,1,100,1,1,233.58,234.41,505,500,2,1,233.53,234.43,10,105,1,2,233.5,234.5,100,63,1,4,233.45,234.59,15,60,1,1,AAPL,0.0,0.0,-10.0,
2024-10-21 12:28:55.964429174+00:00,2024-10-21T12:28:55.964596099Z,10,2,38,A,B,3,233.75,200,130,166925,13258541,233.86,234.0,185,17,2,2,233.81,234.06,2,400,2,1,233.8,234.1,105,100,2,1,233.75,234.13,200,400,1,1,233.7,234.17,1200,1,1,1,233.66,234.25,1,100,1,1,233.58,234.41,505,500,2,1,233.53,234.43,10,105,1,2,233.5,234.5,100,63,1,4,233.45,234.59,15,60,1,1,AAPL,0.0,0.0,-10.0,
2024-10-21 12:28:56.442607241+00:00,2024-10-21T12:28:56.442773675Z,10,2,38,A,A,1,234.05,400,130,166434,13258927,233.86,234.0,185,17,2,2,233.81,234.05,2,400,2,1,233.8,234.1,105,100,2,1,233.75,234.13,200,400,1,1,233.7,234.17,1200,1,1,1,233.66,234.25,1,100,1,1,233.58,234.41,505,500,2,1,233.53,234.43,10,105,1,2,233.5,234.5,100,63,1,4,233.45,234.59,15,60,1,1,AAPL,0.0,0.0,-10.0,
2024-10-21 12:28:57.565348157+00:00,2024-10-21T12:28:57.565514672Z,10,2,38,A,A,2,234.07,7,130,166515,13259953,233.86,234.0,185,17,2,2,233.81,234.05,2,400,2,1,233.8,234.07,105,7,2,1,233.75,234.1,200,100,1,1,233.7,234.13,1200,400,1,1,233.66,234.17,1,1,1,1,233.58,234.25,505,100,2,1,233.53,234.41,10,500,1,1,233.5,234.43,100,105,1,2,233.45,234.5,15,63,1,4,AAPL,0.0,0.0,0.0,
2024-10-21 12:28:57.830839869+00:00,2024-10-21T12:28:57.831005951Z,10,2,38,A,A,1,234.01,200,130,166082,13260122,233.86,234.0,185,17,2,2,233.81,234.01,2,200,2,1,233.8,234.07,105,7,2,1,233.75,234.1,200,100,1,1,233.7,234.13,1200,400,1,1,233.66,234.17,1,1,1,1,233.58,234.25,505,100,2,1,233.53,234.41,10,500,1,1,233.5,234.43,100,105,1,2,233.45,234.5,15,63,1,4,AAPL,0.0,0.0,0.0,
2024-10-21 12:28:57.890894861+00:00,2024-10-21T12:28:57.891061549Z,10,2,38,A,A,0,234.0,200,130,166688,13260139,233.86,234.0,185,217,2,3,233.81,234.07,2,7,2,1,233.8,234.1,105,100,2,1,233.75,234.13,200,400,1,1,233.7,234.17,1200,1,1,1,233.66,234.25,1,100,1,1,233.58,234.41,505,500,2,1,233.53,234.43,10,105,1,2,233.5,234.5,100,63,1,4,233.45,234.59,15,60,1,1,AAPL,-200.0,-200.0,-200.0,
2024-10-21 12:28:58.005959828+00:00,2024-10-21T12:28:58.006126423Z,10,2,38,A,A,0,233.99,200,130,166595,13260238,233.86,233.99,185,200,2,1,233.81,234.0,2,17,2,2,233.8,234.07,105,7,2,1,233.75,234.1,200,100,1,1,233.7,234.13,1200,400,1,1,233.66,234.17,1,1,1,1,233.58,234.25,505,100,2,1,233.53,234.41,10,500,1,1,233.5,234.43,100,105,1,2,233.45,234.5,15,63,1,4,AAPL,0.0,0.0,-200.0,
2024-10-21 12:28:58.694439582+00:00,2024-10-21T12:28:58.694606149Z,10,2,38,A,B,1,233.81,200,130,166567,13260587,233.86,233.99,185,200,2,1,233.81,234.0,202,17,3,2,233.8,234.07,105,7,2,1,233.7,234.1,1200,100,1,1,233.66,234.13,1,400,1,1,233.58,234.17,505,1,2,1,233.53,234.25,10,100,1,1,233.5,234.41,100,500,1,1,233.45,234.43,15,105,1,2,233.4,234.5,110,63,2,4,AAPL,0.0,200.0,-200.0,
2024-10-21 12:29:01.022123658+00:00,2024-10-21T12:29:01.022290262Z,10,2,38,C,B,1,233.81,200,130,166604,13262995,233.86,233.99,185,200,2,1,233.81,234.0,2,17,2,2,233.8,234.07,105,7,2,1,233.7,234.1,1200,100,1,1,233.66,234.13,1,400,1,1,233.58,234.17,505,1,2,1,233.53,234.25,10,100,1,1,233.5,234.41,100,500,1,1,233.45,234.43,15,105,1,2,233.4,234.5,110,63,2,4,AAPL,0.0,-200.0,0.0,
2024-10-21 12:29:01.022136915+00:00,2024-10-21T12:29:01.022303152Z,10,2,38,A,B,3,233.76,400,130,166237,13262996,233.86,233.99,185,200,2,1,233.81,234.0,2,17,2,2,233.8,234.07,105,7,2,1,233.76,234.1,400,100,1,1,233.7,234.13,1200,400,1,1,233.66,234.17,1,1,1,1,233.58,234.25,505,100,2,1,233.53,234.41,10,500,1,1,233.5,234.43,100,105,1,2,233.45,234.5,15,63,1,4,AAPL,0.0,0.0,0.0,
2024-10-21 12:29:01.158380499+00:00,2024-10-21T12:29:01.158549246Z,10,2,38,T,A,0,233.86,85,0,168747,13263131,233.86,233.99,185,200,2,1,233.81,234.0,2,17,2,2,233.8,234.07,105,7,2,1,233.76,234.1,400,100,1,1,233.7,234.13,1200,400,1,1,233.66,234.17,1,1,1,1,233.58,234.25,505,100,2,1,233.53,234.41,10,500,1,1,233.5,234.43,100,105,1,2,233.45,234.5,15,63,1,4,AAPL,0.0,0.0,0.0,
2024-10-21 12:29:01.158380499+00:00,2024-10-21T12:29:01.158549246Z,10,2,38,T,A,0,233.86,100,130,168747,13263132,233.86,233.99,100,200,1,1,233.81,234.0,2,17,2,2,233.8,234.07,105,7,2,1,233.76,234.1,400,100,1,1,233.7,234.13,1200,400,1,1,233.66,234.17,1,1,1,1,233.58,234.25,505,100,2,1,233.53,234.41,10,500,1,1,233.5,234.43,100,105,1,2,233.45,234.5,15,63,1,4,AAPL,-85.0,-85.0,-85.0,
2024-10-21 12:29:01.158380499+00:00,2024-10-21T12:29:01.158549246Z,10,2,38,C,B,0,233.86,100,130,168747,13263132,233.81,233.99,2,200,2,1,233.8,234.0,105,17,2,2,233.76,234.07,400,7,1,1,233.7,234.1,1200,100,1,1,233.66,234.13,1,400,1,1,233.58,234.17,505,1,2,1,233.53,234.25,10,100,1,1,233.5,234.41,100,500,1,1,233.45,234.43,15,105,1,2,233.4,234.5,110,63,2,4,AAPL,0.0,0.0,-85.0,
2024-10-21 12:29:01.158396024+00:00,2024-10-21T12:29:01.158567848Z,10,2,38,A,B,0,233.86,100,128,171824,13263141,233.86,233.99,100,200,1,1,233.81,234.0,2,17,2,2,233.8,234.07,105,7,2,1,233.76,234.1,400,100,1,1,233.7,234.13,1200,400,1,1,233.66,234.17,1,1,1,1,233.58,234.25,505,100,2,1,233.53,234.41,10,500,1,1,233.5,234.43,100,105,1,2,233.45,234.5,15,63,1,4,AAPL,0.0,0.0,-85.0,
2024-10-21 12:29:01.158404180+00:00,2024-10-21T12:29:01.158571366Z,10,2,38,A,A,0,233.92,100,130,167186,13263148,233.86,233.92,100,100,1,1,233.81,233.99,2,200,2,1,233.8,234.0,105,17,2,2,233.76,234.07,400,7,1,1,233.7,234.1,1200,100,1,1,233.66,234.13,1,400,1,1,233.58,234.17,505,1,2,1,233.53,234.25,10,100,1,1,233.5,234.41,100,500,1,1,233.45,234.43,15,105,1,2,AAPL,0.0,0.0,-85.0,
2024-10-21 12:29:01.158408745+00:00,2024-10-21T12:29:01.158576809Z,10,2,38,A,A,1,233.96,100,128,168064,13263151,233.86,233.92,100,100,1,1,233.81,233.93,2,130,2,1,233.8,233.96,105,100,2,1,233.76,233.99,400,200,1,1,233.7,234.0,1200,17,1,2,233.66,234.07,1,7,1,1,233.58,234.1,505,100,2,1,233.53,234.13,10,400,1,1,233.5,234.17,100,1,1,1,233.45,234.25,15,100,1,1,AAPL,0.0,0.0,-85.0,
2024-10-21 12:29:01.158418184+00:00,2024-10-21T12:29:01.158585584Z,10,2,38,A,A,0,233.92,100,128,167400,13263156,233.86,233.92,100,200,1,2,233.81,233.93,2,130,2,1,233.8,233.96,105,100,2,1,233.76,233.99,400,200,1,1,233.7,234.0,1200,17,1,2,233.66,234.07,1,7,1,1,233.58,234.1,505,100,2,1,233.53,234.13,10,400,1,1,233.5,234.17,100,1,1,1,233.45,234.25,15,100,1,1,AAPL,-100.0,-100.0,-185.0,
2024-10-21 12:29:01.158419809+00:00,2024-10-21T12:29:01.158586865Z,10,2,38,A,A,2,233.96,100,130,167056,13263158,233.86,233.92,100,200,1,2,233.81,233.93,2,130,2,1,233.8,233.96,105,200,2,2,233.76,233.99,400,200,1,1,233.7,234.0,1200,17,1,2,233.66,234.07,1,7,1,1,233.58,234.1,505,100,2,1,233.53,234.13,10,400,1,1,233.5,234.17,100,1,1,1,233.45,234.25,15,100,1,1,AAPL,0.0,-100.0,-185.0,
2024-10-21 12:29:01.158423515+00:00,2024-10-21T12:29:01.158590064Z,10,2,38,A,A,1,233.93,26,130,166549,13263160,233.86,233.92,100,200,1,2,233.81,233.93,2,156,2,2,233.8,233.96,105,200,2,2,233.76,233.99,400,200,1,1,233.7,234.0,1200,17,1,2,233.66,234.07,1,7,1,1,233.58,234.1,505,100,2,1,233.53,234.13,10,400,1,1,233.5,234.17,100,1,1,1,233.45,234.25,15,100,1,1,AAPL,0.0,-26.0,-185.0,
2024-10-21 12:29:01.158424717+00:00,2024-10-21T12:29:01.158592348Z,10,2,38,T,A,0,233.86,100,0,167631,13263161,233.86,233.92,100,200,1,2,233.81,233.93,2,156,2,2,233.8,233.96,105,200,2,2,233.76,233.99,400,200,1,1,233.7,234.0,1200,17,1,2,233.66,234.07,1,7,1,1,233.58,234.1,505,100,2,1,233.53,234.13,10,400,1,1,233.5,234.17,100,1,1,1,233.45,234.25,15,100,1,1,AAPL,0.0,0.0,-185.0,
2024-10-21 12:29:01.158424717+00:00,2024-10-21T12:29:01.158592348Z,10,2,38,T,N,0,233.86,150,130,167631,13263162,233.81,233.92,2,200,2,2,233.8,233.93,105,156,2,2,233.76,233.96,400,200,1,2,233.7,233.99,1200,200,1,1,233.66,234.0,1,17,1,2,233.58,234.07,505,7,2,1,233.53,234.1,10,100,1,1,233.5,234.13,100,400,1,1,233.45,234.17,15,1,1,1,233.4,234.25,110,100,2,1,AAPL,0.0,0.0,-185.0,
2024-10-21 12:29:01.158426997+00:00,2024-10-21T12:29:01.158594194Z,10,2,38,T,N,0,233.86,50,0,167197,13263163,233.81,233.92,2,200,2,2,233.8,233.93,105,156,2,2,233.76,233.96,400,200,1,2,233.7,233.99,1200,200,1,1,233.66,234.0,1,17,1,2,233.58,234.07,505,7,2,1,233.53,234.1,10,100,1,1,233.5,234.13,100,400,1,1,233.45,234.17,15,1,1,1,233.4,234.25,110,100,2,1,AAPL,0.0,0.0,-185.0,
2024-10-21 12:29:01.158427442+00:00,2024-10-21T12:29:01.158594194Z,10,2,38,C,A,1,233.93,130,130,166752,13263164,233.81,233.92,2,200,2,2,233.8,233.93,105,26,2,1,233.76,233.96,400,200,1,2,233.7,233.99,1200,200,1,1,233.66,234.0,1,17,1,2,233.58,234.07,505,7,2,1,233.53,234.1,10,100,1,1,233.5,234.13,100,400,1,1,233.45,234.17,15,1,1,1,233.4,234.25,110,100,2,1,AAPL,0.0,130.0,-185.0,
2024-10-21 12:29:01.158431288+00:00,2024-10-21T12:29:01.158598557Z,10,2,38,A,A,2,233.96,100,130,167269,13263165,233.81,233.92,2,200,2,2,233.8,233.93,105,26,2,1,233.76,233.96,400,300,1,3,233.7,233.99,1200,200,1,1,233.66,234.0,1,17,1,2,233.58,234.07,505,7,2,1,233.53,234.1,10,100,1,1,233.5,234.13,100,400,1,1,233.45,234.17,15,1,1,1,233.4,234.25,110,100,2,1,AAPL,0.0,-100.0,-185.0,
2024-10-21 12:29:01.158434916+00:00,2024-10-21T12:29:01.158601250Z,10,2,38,A,B,0,233.86,100,130,166334,13263166,233.86,233.92,100,200,1,2,233.81,233.93,2,26,2,1,233.8,233.96,105,300,2,3,233.76,233.99,400,200,1,1,233.7,234.0,1200,17,1,2,233.66,234.07,1,7,1,1,233.58,234.1,505,100,2,1,233.53,234.13,10,400,1,1,233.5,234.17,100,1,1,1,233.45,234.25,15,100,1,1,AAPL,0.0,0.0,-185.0,
2024-10-21 12:29:01.158437825+00:00,2024-10-21T12:29:01.158603851Z,10,2,38,A,A,3,233.97,26,130,166026,13263167,233.86,233.92,100,200,1,2,233.81,233.93,2,26,2,1,233.8,233.96,105,300,2,3,233.76,233.97,400,26,1,1,233.7,233.99,1200,200,1,1,233.66,234.0,1,17,1,2,233.58,234.07,505,7,2,1,233.53,234.1,10,100,1,1,233.5,234.13,100,400,1,1,233.45,234.17,15,1,1,1,AAPL,0.0,0.0,-185.0,
2024-10-21 12:29:01.158453404+00:00,2024-10-21T12:29:01.158622043Z,10,2,38,C,B,3,233.76,400,130,168639,13263171,233.86,233.92,100,200,1,2,233.81,233.93,2,26,2,1,233.8,233.96,105,300,2,3,233.7,233.97,1200,26,1,1,233.66,233.99,1,200,1,1,233.58,234.0,505,17,2,2,233.53,234.07,10,7,1,1,233.5,234.1,100,100,1,1,233.45,234.13,15,400,1,1,233.4,234.17,110,1,2,1,AAPL,0.0,0.0,-185.0,
2024-10-21 12:29:01.158458726+00:00,2024-10-21T12:29:01.158626083Z,10,2,38,C,A,0,233.92,100,128,167357,13263172,233.86,233.92,100,100,1,1,233.81,233.93,2,26,2,1,233.8,233.96,105,300,2,3,233.7,233.97,1200,26,1,1,233.66,233.99,1,200,1,1,233.58,234.0,505,17,2,2,233.53,234.07,10,7,1,1,233.5,234.1,100,100,1,1,233.45,234.13,15,400,1,1,233.4,234.17,110,1,2,1,AAPL,100.0,100.0,-85.0,
2024-10-21 12:29:01.158475713+00:00,2024-10-21T12:29:01.158642773Z,10,2,38,C,A,0,233.92,100,128,167060,13263180,233.86,233.93,100,26,1,1,233.81,233.96,2,300,2,3,233.8,233.97,105,26,2,1,233.7,233.99,1200,200,1,1,233.66,234.0,1,17,1,2,233.58,234.07,505,7,2,1,233.53,234.1,10,100,1,1,233.5,234.13,100,400,1,1,233.45,234.17,15,1,1,1,233.4,234.25,110,100,2,1,AAPL,0.0,0.0,-85.0,
2024-10-21 12:29:01.158485485+00:00,2024-10-21T12:29:01.158651784Z,10,2,38,A,A,0,233.91,26,130,166299,13263183,233.86,233.91,100,26,1,1,233.81,233.93,2,26,2,1,233.8,233.96,105,300,2,3,233.7,233.97,1200,26,1,1,233.66,233.99,1,200,1,1,233.58,234.0,505,17,2,2,233.53,234.07,10,7,1,1,233.5,234.1,100,100,1,1,233.45,234.13,15,400,1,1,233.4,234.17,110,1,2,1,AAPL,0.0,0.0,-85.0,
2024-10-21 12:29:01.158498852+00:00,2024-10-21T12:29:01.158666241Z,10,2,38,T,A,0,233.86,50,128,167389,13263184,233.86,233.91,100,26,1,1,233.81,233.93,2,26,2,1,233.8,233.96,105,300,2,3,233.7,233.97,1200,26,1,1,233.66,233.99,1,200,1,1,233.58,234.0,505,17,2,2,233.53,234.07,10,7,1,1,233.5,234.1,100,100,1,1,233.45,234.13,15,400,1,1,233.4,234.17,110,1,2,1,AAPL,0.0,0.0,-85.0,
2024-10-21 12:29:01.158498852+00:00,2024-10-21T12:29:01.158666241Z,10,2,38,C,B,0,233.86,50,128,167389,13263184,233.86,233.91,50,26,1,1,233.81,233.93,2,26,2,1,233.8,233.96,105,300,2,3,233.7,233.97,1200,26,1,1,233.66,233.99,1,200,1,1,233.58,234.0,505,17,2,2,233.53,234.07,10,7,1,1,233.5,234.1,100,100,1,1,233.45,234.13,15,400,1,1,233.4,234.17,110,1,2,1,AAPL,-50.0,-50.0,-135.0,
2024-10-21 12:29:01.158508412+00:00,2024-10-21T12:29:01.158674864Z,10,2,38,A,B,0,233.86,100,130,166452,13263188,233.86,233.91,150,26,2,1,233.81,233.93,2,26,2,1,233.8,233.96,105,300,2,3,233.7,233.97,1200,26,1,1,233.66,233.99,1,200,1,1,233.58,234.0,505,17,2,2,233.53,234.07,10,7,1,1,233.5,234.1,100,100,1,1,233.45,234.13,15,400,1,1,233.4,234.17,110,1,2,1,AAPL,100.0,100.0,-35.0,
2024-10-21 12:29:01.158520941+00:00,2024-10-21T12:29:01.158688501Z,10,2,38,T,A,0,233.86,50,0,167560,13263189,233.86,233.91,150,26,2,1,233.81,233.93,2,26,2,1,233.8,233.96,105,300,2,3,233.7,233.97,1200,26,1,1,233.66,233.99,1,200,1,1,233.58,234.0,505,17,2,2,233.53,234.07,10,7,1,1,233.5,234.1,100,100,1,1,233.45,234.13,15,400,1,1,233.4,234.17,110,1,2,1,AAPL,0.0,0.0,-35.0,
2024-10-21 12:29:01.158520941+00:00,2024-10-21T12:29:01.158688501Z,10,2,38,T,A,0,233.86,50,130,167560,13263190,233.86,233.91,100,26,1,1,233.81,233.93,2,26,2,1,233.8,233.96,105,300,2,3,233.7,233.97,1200,26,1,1,233.66,233.99,1,200,1,1,233.58,234.0,505,17,2,2,233.53,234.07,10,7,1,1,233.5,234.1,100,100,1,1,233.45,234.13,15,400,1,1,233.4,234.17,110,1,2,1,AAPL,-50.0,-50.0,-85.0,
2024-10-21 12:29:01.158520941+00:00,2024-10-21T12:29:01.158688501Z,10,2,38,C,B,0,233.86,50,130,167560,13263190,233.86,233.91,50,26,1,1,233.81,233.93,2,26,2,1,233.8,233.96,105,300,2,3,233.7,233.97,1200,26,1,1,233.66,233.99,1,200,1,1,233.58,234.0,505,17,2,2,233.53,234.07,10,7,1,1,233.5,234.1,100,100,1,1,233.45,234.13,15,400,1,1,233.4,234.17,110,1,2,1,AAPL,-50.0,-50.0,-135.0,
2024-10-21 12:29:01.158530490+00:00,2024-10-21T12:29:01.158696696Z,10,2,38,C,A,2,233.96,100,130,166206,13263192,233.86,233.91,50,26,1,1,233.81,233.93,2,26,2,1,233.8,233.96,105,200,2,2,233.7,233.97,1200,26,1,1,233.66,233.99,1,200,1,1,233.58,234.0,505,17,2,2,233.53,234.07,10,7,1,1,233.5,234.1,100,100,1,1,233.45,234.13,15,400,1,1,233.4,234.17,110,1,2,1,AAPL,0.0,100.0,-135.0,
2024-10-21 12:29:01.158531815+00:00,2024-10-21T12:29:01.158698384Z,10,2,38,C,B,0,233.96,100,130,166569,13263194,233.86,233.91,150,26,2,1,233.81,233.93,2,26,2,1,233.8,233.96,105,100,2,1,233.7,233.97,1200,26,1,1,233.66,233.99,1,200,1,1,233.58,234.0,505,17,2,2,233.53,234.07,10,7,1,1,233.5,234.1,100,100,1,1,233.45,234.13,15,400,1,1,233.4,234.17,110,1,2,1,AAPL,100.0,200.0,-35.0,
2024-10-21 12:29:01.158554739+00:00,2024-10-21T12:29:01.158723924Z,10,2,38,T,A,0,233.86,50,128,169185,13263197,233.86,233.91,150,26,2,1,233.81,233.93,2,26,2,1,233.8,233.96,105,100,2,1,233.7,233.97,1200,26,1,1,233.66,233.99,1,200,1,1,233.58,234.0,505,17,2,2,233.53,234.07,10,7,1,1,233.5,234.1,100,100,1,1,233.45,234.13,15,400,1,1,233.4,234.17,110,1,2,1,AAPL,0.0,0.0,-35.0,
2024-10-21 12:29:01.158554739+00:00,2024-10-21T12:29:01.158723924Z,10,2,38,C,B,0,233.86,50,128,169185,13263197,233.86,233.91,100,26,1,1,233.81,233.93,2,26,2,1,233.8,233.96,105,100,2,1,233.7,233.97,1200,26,1,1,233.66,233.99,1,200,1,1,233.58,234.0,505,17,2,2,233.53,234.07,10,7,1,1,233.5,234.1,100,100,1,1,233.45,234.13,15,400,1,1,233.4,234.17,110,1,2,1,AAPL,-50.0,-50.0,-85.0,
2024-10-21 12:29:01.158835732+00:00,2024-10-21T12:29:01.159002676Z,10,2,38,C,A,2,233.96,100,130,166944,13263231,233.86,233.91,100,26,1,1,233.81,233.93,2,26,2,1,233.8,233.97,105,26,2,1,233.7,233.99,1200,200,1,1,233.66,234.0,1,17,1,2,233.58,234.07,505,7,2,1,233.53,234.1,10,100,1,1,233.5,234.13,100,400,1,1,233.45,234.17,15,1,1,1,233.4,234.25,110,100,2,1,AAPL,0.0,0.0,-85.0,
2024-10-21 12:29:01.260812083+00:00,2024-10-21T12:29:01.260977964Z,10,2,38,C,A,2,233.97,26,130,165881,13263664,233.86,233.91,100,26,1,1,233.81,233.93,2,26,2,1,233.8,233.99,105,200,2,1,233.7,234.0,1200,17,1,2,233.66,234.07,1,7,1,1,233.58,234.1,505,100,2,1,233.53,234.13,10,400,1,1,233.5,234.17,100,1,1,1,233.45,234.25,15,100,1,1,233.4,234.41,110,500,2,1,AAPL,0.0,0.0,-85.0,
2024-10-21 12:29:01.260820985+00:00,2024-10-21T12:29:01.260986860Z,10,2,38,C,A,0,233.91,26,130,165875,13263665,233.86,233.93,100,26,1,1,233.81,233.99,2,200,2,1,233.8,234.0,105,17,2,2,233.7,234.07,1200,7,1,1,233.66,234.1,1,100,1,1,233.58,234.13,505,400,2,1,233.53,234.17,10,1,1,1,233.5,234.25,100,100,1,1,233.45,234.41,15,500,1,1,233.4,234.43,110,105,2,2,AAPL,0.0,0.0,-85.0,
2024-10-21 12:29:01.260872777+00:00,2024-10-21T12:29:01.261039132Z,10,2,38,A,B,3,233.74,200,130,166355,13263667,233.86,233.93,100,26,1,1,233.81,233.99,2,200,2,1,233.8,234.0,105,17,2,2,233.74,234.07,200,7,1,1,233.7,234.1,1200,100,1,1,233.66,234.13,1,400,1,1,233.58,234.17,505,1,2,1,233.53,234.25,10,100,1,1,233.5,234.41,100,500,1,1,233.45,234.43,15,105,1,2,AAPL,0.0,0.0,-85.0,
2024-10-21 12:29:01.411037140+00:00,2024-10-21T12:29:01.411202852Z,10,2,38,C,A,0,233.93,26,130,165712,13264096,233.86,233.99,100,200,1,1,233.81,234.0,2,17,2,2,233.8,234.07,105,7,2,1,233.74,234.1,200,100,1,1,233.7,234.13,1200,400,1,1,233.66,234.17,1,1,1,1,233.58,234.25,505,100,2,1,233.53,234.41,10,500,1,1,233.5,234.43,100,105,1,2,233.45,234.5,15,63,1,4,AAPL,0.0,0.0,-85.0,
2024-10-21 12:29:01.477138444+00:00,2024-10-21T12:29:01.477305998Z,10,2,38,T,A,0,233.86,50,130,167554,13264991,233.86,233.99,100,200,1,1,233.81,234.0,2,17,2,2,233.8,234.07,105,7,2,1,233.74,234.1,200,100,1,1,233.7,234.13,1200,400,1,1,233.66,234.17,1,1,1,1,233.58,234.25,505,100,2,1,233.53,234.41,10,500,1,1,233.5,234.43,100,105,1,2,233.45,234.5,15,63,1,4,AAPL,0.0,0.0,-85.0,
2024-10-21 12:29:01.477138444+00:00,2024-10-21T12:29:01.477305998Z,10,2,38,C,B,0,233.86,50,130,167554,13264991,233.86,233.99,50,200,1,1,233.81,234.0,2,17,2,2,233.8,234.07,105,7,2,1,233.74,234.1,200,100,1,1,233.7,234.13,1200,400,1,1,233.66,234.17,1,1,1,1,233.58,234.25,505,100,2,1,233.53,234.41,10,500,1,1,233.5,234.43,100,105,1,2,233.45,234.5,15,63,1,4,AAPL,-50.0,-50.0,-135.0,
2024-10-21 12:29:01.477149422+00:00,2024-10-21T12:29:01.477315667Z,10,2,38,A,B,0,233.86,100,130,166245,13264992,233.86,233.99,150,200,2,1,233.81,234.0,2,17,2,2,233.8,234.07,105,7,2,1,233.74,234.1,200,100,1,1,233.7,234.13,1200,400,1,1,233.66,234.17,1,1,1,1,233.58,234.25,505,100,2,1,233.53,234.41,10,500,1,1,233.5,234.43,100,105,1,2,233.45,234.5,15,63,1,4,AAPL,100.0,100.0,-35.0,
2024-10-21 12:29:01.477199123+00:00,2024-10-21T12:29:01.477365108Z,10,2,38,C,B,3,233.74,200,130,165985,13264994,233.86,233.99,150,200,2,1,233.81,234.0,2,17,2,2,233.8,234.07,105,7,2,1,233.7,234.1,1200,100,1,1,233.66,234.13,1,400,1,1,233.58,234.17,505,1,2,1,233.53,234.25,10,100,1,1,233.5,234.41,100,500,1,1,233.45,234.43,15,105,1,2,233.4,234.5,110,63,2,4,AAPL,0.0,0.0,-35.0,
2024-10-21 12:29:01.541027344+00:00,2024-10-21T12:29:01.541193716Z,10,2,38,A,B,4,233.66,400,130,166372,13265322,233.86,233.99,150,200,2,1,233.81,234.0,2,17,2,2,233.8,234.07,105,7,2,1,233.7,234.1,1200,100,1,1,233.66,234.13,401,400,2,1,233.58,234.17,505,1,2,1,233.53,234.25,10,100,1,1,233.5,234.41,100,500,1,1,233.45,234.43,15,105,1,2,233.4,234.5,110,63,2,4,AAPL,0.0,400.0,-35.0,
2024-10-21 12:29:01.544694740+00:00,2024-10-21T12:29:01.544861244Z,10,2,38,A,A,0,233.99,200,130,166504,13265329,233.86,233.99,150,400,2,2,233.81,234.0,2,17,2,2,233.8,234.07,105,7,2,1,233.7,234.1,1200,100,1,1,233.66,234.13,401,400,2,1,233.58,234.17,505,1,2,1,233.53,234.25,10,100,1,1,233.5,234.41,100,500,1,1,233.45,234.43,15,105,1,2,233.4,234.5,110,63,2,4,AAPL,-200.0,-200.0,-235.0,
2024-10-21 12:29:01.602571884+00:00,2024-10-21T12:29:01.602737737Z,10,2,38,C,A,0,233.99,200,130,165853,13265457,233.86,233.99,150,200,2,1,233.81,234.0,2,17,2,2,233.8,234.07,105,7,2,1,233.7,234.1,1200,100,1,1,233.66,234.13,401,400,2,1,233.58,234.17,505,1,2,1,233.53,234.25,10,100,1,1,233.5,234.41,100,500,1,1,233.45,234.43,15,105,1,2,233.4,234.5,110,63,2,4,AAPL,200.0,200.0,-35.0,
2024-10-21 12:29:01.602608635+00:00,2024-10-21T12:29:01.602775080Z,10,2,38,A,A,0,233.94,400,130,166445,13265458,233.86,233.94,150,400,2,1,233.81,234.0,2,17,2,2,233.8,234.07,105,7,2,1,233.7,234.1,1200,100,1,1,233.66,234.13,401,400,2,1,233.58,234.17,505,1,2,1,233.53,234.25,10,100,1,1,233.5,234.41,100,500,1,1,233.45,234.43,15,105,1,2,233.4,234.5,110,63,2,4,AAPL,0.0,0.0,-35.0,
2024-10-21 12:29:01.646117074+00:00,2024-10-21T12:29:01.646283514Z,10,2,38,C,A,0,233.94,400,130,166440,13265552,233.86,234.0,150,17,2,2,233.81,234.07,2,7,2,1,233.8,234.1,105,100,2,1,233.7,234.13,1200,400,1,1,233.66,234.17,401,1,2,1,233.58,234.25,505,100,2,1,233.53,234.41,10,500,1,1,233.5,234.43,100,105,1,2,233.45,234.5,15,63,1,4,233.4,234.59,110,60,2,1,AAPL,0.0,0.0,-35.0,
2024-10-21 12:29:01.646130641+00:00,2024-10-21T12:29:01.646296993Z,10,2,38,A,A,0,233.95,200,130,166352,13265553,233.86,233.95,150,200,2,1,233.81,234.0,2,17,2,2,233.8,234.07,105,7,2,1,233.7,234.1,1200,100,1,1,233.66,234.13,401,400,2,1,233.58,234.17,505,1,2,1,233.53,234.25,10,100,1,1,233.5,234.41,100,500,1,1,233.45,234.43,15,105,1,2,233.4,234.5,110,63,2,4,AAPL,0.0,0.0,-35.0,
2024-10-21 12:29:01.700637009+00:00,2024-10-21T12:29:01.700803405Z,10,2,38,A,B,3,233.71,200,130,166396,13265636,233.86,233.95,150,200,2,1,233.81,234.0,2,17,2,2,233.8,234.07,105,7,2,1,233.71,234.1,200,100,1,1,233.7,234.13,1200,400,1,1,233.66,234.17,1,1,1,1,233.58,234.25,505,100,2,1,233.53,234.41,10,500,1,1,233.5,234.43,100,105,1,2,233.45,234.5,15,63,1,4,AAPL,0.0,0.0,-35.0,
2024-10-21 12:29:01.702431410+00:00,2024-10-21T12:29:01.702597558Z,10,2,38,C,A,0,233.95,200,130,166148,13265638,233.86,234.0,150,17,2,2,233.81,234.07,2,7,2,1,233.8,234.1,105,100,2,1,233.71,234.13,200,400,1,1,233.7,234.17,1200,1,1,1,233.66,234.25,1,100,1,1,233.58,234.41,505,500,2,1,233.53,234.43,10,105,1,2,233.5,234.5,100,63,1,4,233.45,234.59,15,60,1,1,AAPL,0.0,0.0,-35.0,
2024-10-21 12:29:01.702443831+00:00,2024-10-21T12:29:01.702610835Z,10,2,38,A,A,0,233.99,200,130,167004,13265639,233.86,233.99,150,200,2,1,233.81,234.0,2,17,2,2,233.8,234.07,105,7,2,1,233.71,234.1,200,100,1,1,233.7,234.13,1200,400,1,1,233.66,234.17,1,1,1,1,233.58,234.25,505,100,2,1,233.53,234.41,10,500,1,1,233.5,234.43,100,105,1,2,233.45,234.5,15,63,1,4,AAPL,0.0,0.0,-35.0,
2024-10-21 12:29:01.828859341+00:00,2024-10-21T12:29:01.829025695Z,10,2,38,A,B,3,233.71,200,130,166354,13265781,233.86,233.99,150,200,2,1,233.81,234.0,2,17,2,2,233.8,234.07,105,7,2,1,233.71,234.1,400,100,2,1,233.7,234.13,1200,400,1,1,233.66,234.17,1,1,1,1,233.58,234.25,505,100,2,1,233.53,234.41,10,500,1,1,233.5,234.43,100,105,1,2,233.45,234.5,15,63,1,4,AAPL,0.0,200.0,-35.0,
2024-10-21 12:29:01.883788028+00:00,2024-10-21T12:29:01.883954105Z,10,2,38,C,B,3,233.71,200,130,166077,13265824,233.86,233.99,150,200,2,1,233.81,234.0,2,17,2,2,233.8,234.07,105,7,2,1,233.71,234.1,200,100,1,1,233.7,234.13,1200,400,1,1,233.66,234.17,1,1,1,1,233.58,234.25,505,100,2,1,233.53,234.41,10,500,1,1,233.5,234.43,100,105,1,2,233.45,234.5,15,63,1,4,AAPL,0.0,-200.0,-35.0,
2024-10-21 12:29:01.883801296+00:00,2024-10-21T12:29:01.883967618Z,10,2,38,A,B,3,233.76,400,130,166322,13265825,233.86,233.99,150,200,2,1,233.81,234.0,2,17,2,2,233.8,234.07,105,7,2,1,233.76,234.1,400,100,1,1,233.7,234.13,1200,400,1,1,233.66,234.17,1,1,1,1,233.58,234.25,505,100,2,1,233.53,234.41,10,500,1,1,233.5,234.43,100,105,1,2,233.45,234.5,15,63,1,4,AAPL,0.0,0.0,-35.0,
2024-10-21 12:29:04.074375510+00:00,2024-10-21T12:29:04.074542032Z,10,2,38,A,B,1,233.81,200,130,166522,13268362,233.86,233.99,150,200,2,1,233.81,234.0,202,17,3,2,233.8,234.07,105,7,2,1,233.7,234.1,1200,100,1,1,233.66,234.13,1,400,1,1,233.58,234.17,505,1,2,1,233.53,234.25,10,100,1,1,233.5,234.41,100,500,1,1,233.45,234.43,15,105,1,2,233.4,234.5,110,63,2,4,AAPL,0.0,200.0,0.0,
2024-10-21 12:29:04.429500359+00:00,2024-10-21T12:29:04.429667694Z,10,2,38,T,A,0,233.86,3,130,167335,13268523,233.86,233.99,150,200,2,1,233.81,234.0,202,17,3,2,233.8,234.07,105,7,2,1,233.7,234.1,1200,100,1,1,233.66,234.13,1,400,1,1,233.58,234.17,505,1,2,1,233.53,234.25,10,100,1,1,233.5,234.41,100,500,1,1,233.45,234.43,15,105,1,2,233.4,234.5,110,63,2,4,AAPL,0.0,0.0,0.0,
2024-10-21 12:29:04.429500359+00:00,2024-10-21T12:29:04.429667694Z,10,2,38,C,B,0,233.86,3,130,167335,13268523,233.86,233.99,147,200,2,1,233.81,234.0,202,17,3,2,233.8,234.07,105,7,2,1,233.7,234.1,1200,100,1,1,233.66,234.13,1,400,1,1,233.58,234.17,505,1,2,1,233.53,234.25,10,100,1,1,233.5,234.41,100,500,1,1,233.45,234.43,15,105,1,2,233.4,234.5,110,63,2,4,AAPL,-3.0,-3.0,-3.0,
2024-10-21 12:29:04.493551721+00:00,2024-10-21T12:29:04.493717825Z,10,2,38,C,B,1,233.81,200,130,166104,13268610,233.86,233.99,147,200,2,1,233.81,234.0,2,17,2,2,233.8,234.07,105,7,2,1,233.7,234.1,1200,100,1,1,233.66,234.13,1,400,1,1,233.58,234.17,505,1,2,1,233.53,234.25,10,100,1,1,233.5,234.41,100,500,1,1,233.45,234.43,15,105,1,2,233.4,234.5,110,63,2,4,AAPL,0.0,-200.0,-3.0,
2024-10-21 12:29:04.493564498+00:00,2024-10-21T12:29:04.493730953Z,10,2,38,A,B,3,233.78,200,130,166455,13268611,233.86,233.99,147,200,2,1,233.81,234.0,2,17,2,2,233.8,234.07,105,7,2,1,233.78,234.1,200,100,1,1,233.7,234.13,1200,400,1,1,233.66,234.17,1,1,1,1,233.58,234.25,505,100,2,1,233.53,234.41,10,500,1,1,233.5,234.43,100,105,1,2,233.45,234.5,15,63,1,4,AAPL,0.0,0.0,-3.0,
2024-10-21 12:29:04.660423222+00:00,2024-10-21T12:29:04.660589203Z,10,2,38,C,B,3,233.78,200,130,165981,13268807,233.86,233.99,147,200,2,1,233.81,234.0,2,17,2,2,233.8,234.07,105,7,2,1,233.7,234.1,1200,100,1,1,233.66,234.13,1,400,1,1,233.58,234.17,505,1,2,1,233.53,234.25,10,100,1,1,233.5,234.41,100,500,1,1,233.45,234.43,15,105,1,2,233.4,234.5,110,63,2,4,AAPL,0.0,0.0,-3.0,
2024-10-21 12:29:04.660436269+00:00,2024-10-21T12:29:04.660602729Z,10,2,38,A,B,4,233.66,400,130,166460,13268808,233.86,233.99,147,200,2,1,233.81,234.0,2,17,2,2,233.8,234.07,105,7,2,1,233.7,234.1,1200,100,1,1,233.66,234.13,401,400,2,1,233.58,234.17,505,1,2,1,233.53,234.25,10,100,1,1,233.5,234.41,100,500,1,1,233.45,234.43,15,105,1,2,233.4,234.5,110,63,2,4,AAPL,0.0,400.0,-3.0,
2024-10-21 12:29:04.679139876+00:00,2024-10-21T12:29:04.679306243Z,10,2,38,A,A,0,233.99,200,130,166367,13268819,233.86,233.99,147,400,2,2,233.81,234.0,2,17,2,2,233.8,234.07,105,7,2,1,233.7,234.1,1200,100,1,1,233.66,234.13,401,400,2,1,233.58,234.17,505,1,2,1,233.53,234.25,10,100,1,1,233.5,234.41,100,500,1,1,233.45,234.43,15,105,1,2,233.4,234.5,110,63,2,4,AAPL,-200.0,-200.0,-203.0,
2024-10-21 12:29:04.736790546+00:00,2024-10-21T12:29:04.736956452Z,10,2,38,C,A,0,233.99,200,130,165906,13268859,233.86,233.99,147,200,2,1,233.81,234.0,2,17,2,2,233.8,234.07,105,7,2,1,233.7,234.1,1200,100,1,1,233.66,234.13,401,400,2,1,233.58,234.17,505,1,2,1,233.53,234.25,10,100,1,1,233.5,234.41,100,500,1,1,233.45,234.43,15,105,1,2,233.4,234.5,110,63,2,4,AAPL,200.0,200.0,-3.0,
2024-10-21 12:29:04.736803679+00:00,2024-10-21T12:29:04.736969863Z,10,2,38,A,A,0,233.94,200,130,166184,13268860,233.86,233.94,147,200,2,1,233.81,234.0,2,17,2,2,233.8,234.07,105,7,2,1,233.7,234.1,1200,100,1,1,233.66,234.13,401,400,2,1,233.58,234.17,505,1,2,1,233.53,234.25,10,100,1,1,233.5,234.41,100,500,1,1,233.45,234.43,15,105,1,2,233.4,234.5,110,63,2,4,AAPL,0.0,0.0,-3.0,
2024-10-21 12:29:04.942410445+00:00,2024-10-21T12:29:04.942576593Z,10,2,38,C,A,0,233.94,200,130,166148,13269072,233.86,234.0,147,17,2,2,233.81,234.07,2,7,2,1,233.8,234.1,105,100,2,1,233.7,234.13,1200,400,1,1,233.66,234.17,401,1,2,1,233.58,234.25,505,100,2,1,233.53,234.41,10,500,1,1,233.5,234.43,100,105,1,2,233.45,234.5,15,63,1,4,233.4,234.59,110,60,2,1,AAPL,0.0,0.0,-3.0,
2024-10-21 12:29:04.942423141+00:00,2024-10-21T12:29:04.942589417Z,10,2,38,A,A,0,233.99,200,130,166276,13269073,233.86,233.99,147,200,2,1,233.81,234.0,2,17,2,2,233.8,234.07,105,7,2,1,233.7,234.1,1200,100,1,1,233.66,234.13,401,400,2,1,233.58,234.17,505,1,2,1,233.53,234.25,10,100,1,1,233.5,234.41,100,500,1,1,233.45,234.43,15,105,1,2,233.4,234.5,110,63,2,4,AAPL,0.0,0.0,-3.0,
2024-10-21 12:29:04.996963888+00:00,2024-10-21T12:29:04.997130813Z,10,2,38,A,B,3,233.76,400,130,166925,13269127,233.86,233.99,147,200,2,1,233.81,234.0,2,17,2,2,233.8,234.07,105,7,2,1,233.76,234.1,400,100,1,1,233.7,234.13,1200,400,1,1,233.66,234.17,1,1,1,1,233.58,234.25,505,100,2,1,233.53,234.41,10,500,1,1,233.5,234.43,100,105,1,2,233.45,234.5,15,63,1,4,AAPL,0.0,0.0,-3.0,
2024-10-21 12:29:07.476155585+00:00,2024-10-21T12:29:07.476323268Z,10,2,38,T,A,0,233.86,30,130,167683,13271447,233.86,233.99,147,200,2,1,233.81,234.0,2,17,2,2,233.8,234.07,105,7,2,1,233.76,234.1,400,100,1,1,233.7,234.13,1200,400,1,1,233.66,234.17,1,1,1,1,233.58,234.25,505,100,2,1,233.53,234.41,10,500,1,1,233.5,234.43,100,105,1,2,233.45,234.5,15,63,1,4,AAPL,0.0,0.0,0.0,
2024-10-21 12:29:07.476155585+00:00,2024-10-21T12:29:07.476323268Z,10,2,38,C,B,0,233.86,30,130,167683,13271447,233.86,233.99,117,200,2,1,233.81,234.0,2,17,2,2,233.8,234.07,105,7,2,1,233.76,234.1,400,100,1,1,233.7,234.13,1200,400,1,1,233.66,234.17,1,1,1,1,233.58,234.25,505,100,2,1,233.53,234.41,10,500,1,1,233.5,234.43,100,105,1,2,233.45,234.5,15,63,1,4,AAPL,-30.0,-30.0,-30.0,
2024-10-21 12:29:07.543812287+00:00,2024-10-21T12:29:07.543978531Z,10,2,38,C,B,3,233.76,400,130,166244,13271500,233.86,233.99,117,200,2,1,233.81,234.0,2,17,2,2,233.8,234.07,105,7,2,1,233.7,234.1,1200,100,1,1,233.66,234.13,1,400,1,1,233.58,234.17,505,1,2,1,233.53,234.25,10,100,1,1,233.5,234.41,100,500,1,1,233.45,234.43,15,105,1,2,233.4,234.5,110,63,2,4,AAPL,0.0,0.0,-30.0,
2024-10-21 12:29:07.572921012+00:00,2024-10-21T12:29:07.573087456Z,10,2,38,C,A,2,234.07,7,130,166444,13271562,233.86,233.99,117,200,2,1,233.81,234.0,2,17,2,2,233.8,234.1,105,100,2,1,233.7,234.13,1200,400,1,1,233.66,234.17,1,1,1,1,233.58,234.25,505,100,2,1,233.53,234.41,10,500,1,1,233.5,234.43,100,105,1,2,233.45,234.5,15,63,1,4,233.4,234.59,110,60,2,1,AAPL,0.0,0.0,-30.0,
2024-10-21 12:29:07.582875842+00:00,2024-10-21T12:29:07.583042273Z,10,2,38,A,B,3,233.74,200,130,166431,13271567,233.86,233.99,117,200,2,1,233.81,234.0,2,17,2,2,233.8,234.1,105,100,2,1,233.74,234.13,200,400,1,1,233.7,234.17,1200,1,1,1,233.66,234.25,1,100,1,1,233.58,234.41,505,500,2,1,233.53,234.43,10,105,1,2,233.5,234.5,100,63,1,4,233.45,234.59,15,60,1,1,AAPL,0.0,0.0,-30.0,
2024-10-21 12:29:07.714932040+00:00,2024-10-21T12:29:07.715099060Z,10,2,38,A,B,3,233.76,200,130,167020,13271618,233.86,233.99,117,200,2,1,233.81,234.0,2,17,2,2,233.8,234.1,105,100,2,1,233.76,234.13,200,400,1,1,233.7,234.17,1200,1,1,1,233.66,234.25,1,100,1,1,233.58,234.41,505,500,2,1,233.53,234.43,10,105,1,2,233.5,234.5,100,63,1,4,233.45,234.59,15,60,1,1,AAPL,0.0,0.0,-30.0,
2024-10-21 12:29:08.288226889+00:00,2024-10-21T12:29:08.288393145Z,10,2,38,A,B,3,233.77,200,130,166256,13272141,233.86,233.99,117,200,2,1,233.81,234.0,2,17,2,2,233.8,234.1,105,100,2,1,233.77,234.13,200,400,1,1,233.7,234.17,1200,1,1,1,233.66,234.25,1,100,1,1,233.58,234.41,505,500,2,1,233.53,234.43,10,105,1,2,233.5,234.5,100,63,1,4,233.45,234.59,15,60,1,1,AAPL,0.0,0.0,-30.0,
2024-10-21 12:29:08.936973408+00:00,2024-10-21T12:29:08.937139462Z,10,2,38,C,A,0,233.99,200,130,166054,13272432,233.86,234.0,117,17,2,2,233.81,234.1,2,100,2,1,233.8,234.13,105,400,2,1,233.77,234.17,200,1,1,1,233.7,234.25,1200,100,1,1,233.66,234.41,1,500,1,1,233.58,234.43,505,105,2,2,233.53,234.5,10,63,1,4,233.5,234.59,100,60,1,1,233.45,234.75,15,1,1,1,AAPL,0.0,0.0,0.0,
2024-10-21 12:29:08.936985355+00:00,2024-10-21T12:29:08.937151622Z,10,2,38,A,A,1,234.01,200,130,166267,13272433,233.86,234.0,117,17,2,2,233.81,234.01,2,200,2,1,233.8,234.1,105,100,2,1,233.77,234.13,200,400,1,1,233.7,234.17,1200,1,1,1,233.66,234.25,1,100,1,1,233.58,234.41,505,500,2,1,233.53,234.43,10,105,1,2,233.5,234.5,100,63,1,4,233.45,234.59,15,60,1,1,AAPL,0.0,0.0,0.0,
2024-10-21 12:29:08.991905949+00:00,2024-10-21T12:29:08.992072347Z,10,2,38,A,B,3,233.78,200,130,166398,13272483,233.86,234.0,117,17,2,2,233.81,234.01,2,200,2,1,233.8,234.1,105,100,2,1,233.78,234.13,200,400,1,1,233.7,234.17,1200,1,1,1,233.66,234.25,1,100,1,1,233.58,234.41,505,500,2,1,233.53,234.43,10,105,1,2,233.5,234.5,100,63,1,4,233.45,234.59,15,60,1,1,AAPL,0.0,0.0,0.0,
2024-10-21 12:29:09.054055599+00:00,2024-10-21T12:29:09.054222160Z,10,2,38,A,A,0,234.0,200,130,166561,13272549,233.86,234.0,117,217,2,3,233.81,234.1,2,100,2,1,233.8,234.13,105,400,2,1,233.78,234.17,200,1,1,1,233.7,234.25,1200,100,1,1,233.66,234.41,1,500,1,1,233.58,234.43,505,105,2,2,233.53,234.5,10,63,1,4,233.5,234.59,100,60,1,1,233.45,234.75,15,1,1,1,AAPL,-200.0,-200.0,-200.0,
2024-10-21 12:29:09.096609749+00:00,2024-10-21T12:29:09.096780188Z,10,2,38,T,A,0,233.86,17,0,170439,13272571,233.86,234.0,117,217,2,3,233.81,234.1,2,100,2,1,233.8,234.13,105,400,2,1,233.78,234.17,200,1,1,1,233.7,234.25,1200,100,1,1,233.66,234.41,1,500,1,1,233.58,234.43,505,105,2,2,233.53,234.5,10,63,1,4,233.5,234.59,100,60,1,1,233.45,234.75,15,1,1,1,AAPL,0.0,0.0,-200.0,
2024-10-21 12:29:09.096609749+00:00,2024-10-21T12:29:09.096780188Z,10,2,38,T,A,0,233.86,100,0,170439,13272572,233.86,234.0,100,217,1,3,233.81,234.1,2,100,2,1,233.8,234.13,105,400,2,1,233.78,234.17,200,1,1,1,233.7,234.25,1200,100,1,1,233.66,234.41,1,500,1,1,233.58,234.43,505,105,2,2,233.53,234.5,10,63,1,4,233.5,234.59,100,60,1,1,233.45,234.75,15,1,1,1,AAPL,-17.0,-17.0,-217.0,
2024-10-21 12:29:09.096609749+00:00,2024-10-21T12:29:09.096780188Z,10,2,38,T,N,0,233.86,683,130,170439,13272573,233.81,234.0,2,217,2,3,233.8,234.1,105,100,2,1,233.78,234.13,200,400,1,1,233.7,234.17,1200,1,1,1,233.66,234.25,1,100,1,1,233.58,234.41,505,500,2,1,233.53,234.43,10,105,1,2,233.5,234.5,100,63,1,4,233.45,234.59,15,60,1,1,233.4,234.75,110,1,2,1,AAPL,0.0,0.0,-217.0,
2024-10-21 12:29:09.096622742+00:00,2024-10-21T12:29:09.096791448Z,10,2,38,A,B,0,233.86,100,130,168706,13272574,233.86,234.0,100,217,1,3,233.81,234.1,2,100,2,1,233.8,234.13,105,400,2,1,233.78,234.17,200,1,1,1,233.7,234.25,1200,100,1,1,233.66,234.41,1,500,1,1,233.58,234.43,505,105,2,2,233.53,234.5,10,63,1,4,233.5,234.59,100,60,1,1,233.45,234.75,15,1,1,1,AAPL,0.0,0.0,-217.0,
2024-10-21 12:29:09.096634813+00:00,2024-10-21T12:29:09.096803407Z,10,2,38,A,A,0,233.92,100,130,168594,13272575,233.86,233.92,100,100,1,1,233.81,234.0,2,217,2,3,233.8,234.1,105,100,2,1,233.78,234.13,200,400,1,1,233.7,234.17,1200,1,1,1,233.66,234.25,1,100,1,1,233.58,234.41,505,500,2,1,233.53,234.43,10,105,1,2,233.5,234.5,100,63,1,4,233.45,234.59,15,60,1,1,AAPL,0.0,0.0,-217.0,
2024-10-21 12:29:09.096639241+00:00,2024-10-21T12:29:09.096806296Z,10,2,38,A,A,1,233.93,135,130,167055,13272576,233.86,233.92,100,100,1,1,233.81,233.93,2,135,2,1,233.8,234.0,105,217,2,3,233.78,234.1,200,100,1,1,233.7,234.13,1200,400,1,1,233.66,234.17,1,1,1,1,233.58,234.25,505,100,2,1,233.53,234.41,10,500,1,1,233.5,234.43,100,105,1,2,233.45,234.5,15,63,1,4,AAPL,0.0,0.0,-217.0,
2024-10-21 12:29:09.096640225+00:00,2024-10-21T12:29:09.096808055Z,10,2,38,A,A,2,233.97,100,130,167830,13272577,233.86,233.92,100,100,1,1,233.81,233.93,2,135,2,1,233.8,233.97,105,100,2,1,233.78,234.0,200,217,1,3,233.7,234.1,1200,100,1,1,233.66,234.13,1,400,1,1,233.58,234.17,505,1,2,1,233.53,234.25,10,100,1,1,233.5,234.41,100,500,1,1,233.45,234.43,15,105,1,2,AAPL,0.0,0.0,-217.0,
2024-10-21 12:29:09.096649377+00:00,2024-10-21T12:29:09.096815657Z,10,2,38,A,A,2,233.97,100,130,166280,13272579,233.86,233.92,100,100,1,1,233.81,233.93,2,135,2,1,233.8,233.97,105,300,2,3,233.78,234.0,200,217,1,3,233.7,234.1,1200,100,1,1,233.66,234.13,1,400,1,1,233.58,234.17,505,1,2,1,233.53,234.25,10,100,1,1,233.5,234.41,100,500,1,1,233.45,234.43,15,105,1,2,AAPL,0.0,-200.0,-217.0,
2024-10-21 12:29:09.096651465+00:00,2024-10-21T12:29:09.096817407Z,10,2,38,C,A,1,233.93,135,130,165942,13272580,233.86,233.92,100,100,1,1,233.81,233.97,2,300,2,3,233.8,234.0,105,217,2,3,233.78,234.1,200,100,1,1,233.7,234.13,1200,400,1,1,233.66,234.17,1,1,1,1,233.58,234.25,505,100,2,1,233.53,234.41,10,500,1,1,233.5,234.43,100,105,1,2,233.45,234.5,15,63,1,4,AAPL,0.0,0.0,-217.0,
2024-10-21 12:29:09.096659107+00:00,2024-10-21T12:29:09.096825400Z,10,2,38,A,A,1,233.93,27,130,166293,13272581,233.86,233.92,100,100,1,1,233.81,233.93,2,27,2,1,233.8,233.97,105,300,2,3,233.78,234.0,200,217,1,3,233.7,234.1,1200,100,1,1,233.66,234.13,1,400,1,1,233.58,234.17,505,1,2,1,233.53,234.25,10,100,1,1,233.5,234.41,100,500,1,1,233.45,234.43,15,105,1,2,AAPL,0.0,0.0,-217.0,
2024-10-21 12:29:09.096672869+00:00,2024-10-21T12:29:09.096839118Z,10,2,38,A,A,3,233.98,27,130,166249,13272582,233.86,233.92,100,100,1,1,233.81,233.93,2,27,2,1,233.8,233.97,105,300,2,3,233.78,233.98,200,27,1,1,233.7,234.0,1200,217,1,3,233.66,234.1,1,100,1,1,233.58,234.13,505,400,2,1,233.53,234.17,10,1,1,1,233.5,234.25,100,100,1,1,233.45,234.41,15,500,1,1,AAPL,0.0,0.0,-217.0,
2024-10-21 12:29:09.096683301+00:00,2024-10-21T12:29:09.096849122Z,10,2,38,C,A,0,233.92,100,130,165821,13272583,233.86,233.93,100,27,1,1,233.81,233.97,2,300,2,3,233.8,233.98,105,27,2,1,233.78,234.0,200,217,1,3,233.7,234.1,1200,100,1,1,233.66,234.13,1,400,1,1,233.58,234.17,505,1,2,1,233.53,234.25,10,100,1,1,233.5,234.41,100,500,1,1,233.45,234.43,15,105,1,2,AAPL,0.0,0.0,-217.0,
2024-10-21 12:29:09.096693428+00:00,2024-10-21T12:29:09.096859383Z,10,2,38,C,B,3,233.78,200,130,165955,13272584,233.86,233.93,100,27,1,1,233.81,233.97,2,300,2,3,233.8,233.98,105,27,2,1,233.7,234.0,1200,217,1,3,233.66,234.1,1,100,1,1,233.58,234.13,505,400,2,1,233.53,234.17,10,1,1,1,233.5,234.25,100,100,1,1,233.45,234.41,15,500,1,1,233.4,234.43,110,105,2,2,AAPL,0.0,0.0,-217.0,
2024-10-21 12:29:09.096705312+00:00,2024-10-21T12:29:09.096872549Z,10,2,38,C,A,1,233.97,100,130,167237,13272586,233.86,233.93,100,27,1,1,233.81,233.97,2,200,2,2,233.8,233.98,105,27,2,1,233.7,234.0,1200,217,1,3,233.66,234.1,1,100,1,1,233.58,234.13,505,400,2,1,233.53,234.17,10,1,1,1,233.5,234.25,100,100,1,1,233.45,234.41,15,500,1,1,233.4,234.43,110,105,2,2,AAPL,0.0,100.0,-217.0,
2024-10-21 12:29:09.096706998+00:00,2024-10-21T12:29:09.096873527Z,10,2,38,C,A,1,233.97,100,130,166529,13272587,233.86,233.93,100,27,1,1,233.81,233.97,2,100,2,1,233.8,233.98,105,27,2,1,233.7,234.0,1200,217,1,3,233.66,234.1,1,100,1,1,233.58,234.13,505,400,2,1,233.53,234.17,10,1,1,1,233.5,234.25,100,100,1,1,233.45,234.41,15,500,1,1,233.4,234.43,110,105,2,2,AAPL,0.0,100.0,-217.0,
2024-10-21 12:29:09.097036830+00:00,2024-10-21T12:29:09.097202819Z,10,2,38,C,A,1,233.97,100,130,165989,13272589,233.86,233.93,100,27,1,1,233.81,233.98,2,27,2,1,233.8,234.0,105,217,2,3,233.7,234.1,1200,100,1,1,233.66,234.13,1,400,1,1,233.58,234.17,505,1,2,1,233.53,234.25,10,100,1,1,233.5,234.41,100,500,1,1,233.45,234.43,15,105,1,2,233.4,234.5,110,63,2,4,AAPL,0.0,0.0,-217.0,
2024-10-21 12:29:09.197808423+00:00,2024-10-21T12:29:09.197974288Z,10,2,38,C,A,1,233.98,27,130,165865,13272635,233.86,233.93,100,27,1,1,233.81,234.0,2,217,2,3,233.8,234.1,105,100,2,1,233.7,234.13,1200,400,1,1,233.66,234.17,1,1,1,1,233.58,234.25,505,100,2,1,233.53,234.41,10,500,1,1,233.5,234.43,100,105,1,2,233.45,234.5,15,63,1,4,233.4,234.59,110,60,2,1,AAPL,0.0,0.0,-217.0,
2024-10-21 12:29:09.197865189+00:00,2024-10-21T12:29:09.198031378Z,10,2,38,A,B,3,233.77,200,130,166189,13272636,233.86,233.93,100,27,1,1,233.81,234.0,2,217,2,3,233.8,234.1,105,100,2,1,233.77,234.13,200,400,1,1,233.7,234.17,1200,1,1,1,233.66,234.25,1,100,1,1,233.58,234.41,505,500,2,1,233.53,234.43,10,105,1,2,233.5,234.5,100,63,1,4,233.45,234.59,15,60,1,1,AAPL,0.0,0.0,-217.0,
2024-10-21 12:29:09.349517861+00:00,2024-10-21T12:29:09.349683778Z,10,2,38,C,A,0,233.93,27,130,165917,13272742,233.86,234.0,100,217,1,3,233.81,234.1,2,100,2,1,233.8,234.13,105,400,2,1,233.77,234.17,200,1,1,1,233.7,234.25,1200,100,1,1,233.66,234.41,1,500,1,1,233.58,234.43,505,105,2,2,233.53,234.5,10,63,1,4,233.5,234.59,100,60,1,1,233.45,234.75,15,1,1,1,AAPL,0.0,0.0,-217.0,
2024-10-21 12:29:09.575899057+00:00,2024-10-21T12:29:09.576065628Z,10,2,38,A,A,0,233.97,7,130,166571,13272947,233.86,233.97,100,7,1,1,233.81,234.0,2,217,2,3,233.8,234.1,105,100,2,1,233.77,234.13,200,400,1,1,233.7,234.17,1200,1,1,1,233.66,234.25,1,100,1,1,233.58,234.41,505,500,2,1,233.53,234.43,10,105,1,2,233.5,234.5,100,63,1,4,233.45,234.59,15,60,1,1,AAPL,0.0,0.0,-217.0,
2024-10-21 12:29:11.490444580+00:00,2024-10-21T12:29:11.490610915Z,10,2,38,A,B,3,233.78,200,130,166335,13273947,233.86,233.97,100,7,1,1,233.81,234.0,2,217,2,3,233.8,234.1,105,100,2,1,233.78,234.13,200,400,1,1,233.7,234.17,1200,1,1,1,233.66,234.25,1,100,1,1,233.58,234.41,505,500,2,1,233.53,234.43,10,105,1,2,233.5,234.5,100,63,1,4,233.45,234.59,15,60,1,1,AAPL,0.0,0.0,0.0,
2024-10-21 12:29:12.051081325+00:00,2024-10-21T12:29:12.051247514Z,10,2,38,C,A,1,234.0,200,130,166189,13274358,233.86,233.97,100,7,1,1,233.81,234.0,2,17,2,2,233.8,234.1,105,100,2,1,233.78,234.13,200,400,1,1,233.7,234.17,1200,1,1,1,233.66,234.25,1,100,1,1,233.58,234.41,505,500,2,1,233.53,234.43,10,105,1,2,233.5,234.5,100,63,1,4,233.45,234.59,15,60,1,1,AAPL,0.0,200.0,0.0,
2024-10-21 12:29:12.051094374+00:00,2024-10-21T12:29:12.051260608Z,10,2,38,A,A,2,234.02,200,130,166234,13274359,233.86,233.97,100,7,1,1,233.81,234.0,2,17,2,2,233.8,234.02,105,200,2,1,233.78,234.1,200,100,1,1,233.7,234.13,1200,400,1,1,233.66,234.17,1,1,1,1,233.58,234.25,505,100,2,1,233.53,234.41,10,500,1,1,233.5,234.43,100,105,1,2,233.45,234.5,15,63,1,4,AAPL,0.0,0.0,0.0,
2024-10-21 12:29:12.054384594+00:00,2024-10-21T12:29:12.054550814Z,10,2,38,C,A,2,234.02,200,130,166220,13274363,233.86,233.97,100,7,1,1,233.81,234.0,2,17,2,2,233.8,234.1,105,100,2,1,233.78,234.13,200,400,1,1,233.7,234.17,1200,1,1,1,233.66,234.25,1,100,1,1,233.58,234.41,505,500,2,1,233.53,234.43,10,105,1,2,233.5,234.5,100,63,1,4,233.45,234.59,15,60,1,1,AAPL,0.0,0.0,0.0,
2024-10-21 12:29:12.054397299+00:00,2024-10-21T12:29:12.054563570Z,10,2,38,A,A,2,234.06,200,130,166271,13274364,233.86,233.97,100,7,1,1,233.81,234.0,2,17,2,2,233.8,234.06,105,200,2,1,233.78,234.1,200,100,1,1,233.7,234.13,1200,400,1,1,233.66,234.17,1,1,1,1,233.58,234.25,505,100,2,1,233.53,234.41,10,500,1,1,233.5,234.43,100,105,1,2,233.45,234.5,15,63,1,4,AAPL,0.0,0.0,0.0,
2024-10-21 12:29:12.061278295+00:00,2024-10-21T12:29:12.061445338Z,10,2,38,A,A,2,234.06,200,130,167043,13274376,233.86,233.97,100,7,1,1,233.81,234.0,2,17,2,2,233.8,234.06,105,400,2,2,233.78,234.1,200,100,1,1,233.7,234.13,1200,400,1,1,233.66,234.17,1,1,1,1,233.58,234.25,505,100,2,1,233.53,234.41,10,500,1,1,233.5,234.43,100,105,1,2,233.45,234.5,15,63,1,4,AAPL,0.0,-200.0,0.0,
2024-10-21 12:29:12.188742107+00:00,2024-10-21T12:29:12.188908222Z,10,2,38,A,B,3,233.78,200,130,166115,13274537,233.86,233.97,100,7,1,1,233.81,234.0,2,17,2,2,233.8,234.06,105,400,2,2,233.78,234.1,400,100,2,1,233.7,234.13,1200,400,1,1,233.66,234.17,1,1,1,1,233.58,234.25,505,100,2,1,233.53,234.41,10,500,1,1,233.5,234.43,100,105,1,2,233.45,234.5,15,63,1,4,AAPL,0.0,200.0,0.0,
2024-10-21 12:29:14.061139742+00:00,2024-10-21T12:29:14.061306232Z,10,2,38,C,A,0,233.97,7,130,166490,13276931,233.86,234.0,100,17,1,2,233.81,234.06,2,400,2,2,233.8,234.1,105,100,2,1,233.78,234.13,400,400,2,1,233.7,234.17,1200,1,1,1,233.66,234.25,1,100,1,1,233.58,234.41,505,500,2,1,233.53,234.43,10,105,1,2,233.5,234.5,100,63,1,4,233.45,234.59,15,60,1,1,AAPL,0.0,0.0,0.0,
2024-10-21 12:29:16.067040933+00:00,2024-10-21T12:29:16.067207511Z,10,2,38,A,A,2,234.07,7,130,166578,13278868,233.86,234.0,100,17,1,2,233.81,234.06,2,400,2,2,233.8,234.07,105,7,2,1,233.78,234.1,400,100,2,1,233.7,234.13,1200,400,1,1,233.66,234.17,1,1,1,1,233.58,234.25,505,100,2,1,233.53,234.41,10,500,1,1,233.5,234.43,100,105,1,2,233.45,234.5,15,63,1,4,AAPL,0.0,0.0,0.0,
2024-10-21 12:29:26.242855402+00:00,2024-10-21T12:29:26.243021844Z,10,2,38,C,B,3,233.78,200,130,166442,13287675,233.86,234.0,100,17,1,2,233.81,234.06,2,400,2,2,233.8,234.07,105,7,2,1,233.78,234.1,200,100,1,1,233.7,234.13,1200,400,1,1,233.66,234.17,1,1,1,1,233.58,234.25,505,100,2,1,233.53,234.41,10,500,1,1,233.5,234.43,100,105,1,2,233.45,234.5,15,63,1,4,AAPL,0.0,-200.0,0.0,
2024-10-21 12:29:26.242868183+00:00,2024-10-21T12:29:26.243034702Z,10,2,38,A,B,3,233.79,400,130,166519,13287676,233.86,234.0,100,17,1,2,233.81,234.06,2,400,2,2,233.8,234.07,105,7,2,1,233.79,234.1,400,100,1,1,233.7,234.13,1200,400,1,1,233.66,234.17,1,1,1,1,233.58,234.25,505,100,2,1,233.53,234.41,10,500,1,1,233.5,234.43,100,105,1,2,233.45,234.5,15,63,1,4,AAPL,0.0,0.0,0.0,
2024-10-21 12:29:26.365233464+00:00,2024-10-21T12:29:26.365400353Z,10,2,38,C,B,3,233.79,200,130,166889,13287960,233.86,234.0,100,17,1,2,233.81,234.06,2,400,2,2,233.8,234.07,105,7,2,1,233.79,234.1,200,100,1,1,233.7,234.13,1200,400,1,1,233.66,234.17,1,1,1,1,233.58,234.25,505,100,2,1,233.53,234.41,10,500,1,1,233.5,234.43,100,105,1,2,233.45,234.5,15,63,1,4,AAPL,0.0,-200.0,0.0,
2024-10-21 12:29:49.448744098+00:00,2024-10-21T12:29:49.448914487Z,10,2,38,T,N,0,233.87,500,0,170389,13303883,233.86,234.0,100,17,1,2,233.81,234.06,2,400,2,2,233.8,234.07,105,7,2,1,233.79,234.1,200,100,1,1,233.7,234.13,1200,400,1,1,233.66,234.17,1,1,1,1,233.58,234.25,505,100,2,1,233.53,234.41,10,500,1,1,233.5,234.43,100,105,1,2,233.45,234.5,15,63,1,4,AAPL,0.0,0.0,0.0,
2024-10-21 12:29:49.448744098+00:00,2024-10-21T12:29:49.448914487Z,10,2,38,T,N,0,233.87,50,0,170389,13303884,233.86,234.0,100,17,1,2,233.81,234.06,2,400,2,2,233.8,234.07,105,7,2,1,233.79,234.1,200,100,1,1,233.7,234.13,1200,400,1,1,233.66,234.17,1,1,1,1,233.58,234.25,505,100,2,1,233.53,234.41,10,500,1,1,233.5,234.43,100,105,1,2,233.45,234.5,15,63,1,4,AAPL,0.0,0.0,0.0,
2024-10-21 12:29:49.448744098+00:00,2024-10-21T12:29:49.448914487Z,10,2,38,T,N,0,233.87,100,130,170389,13303885,233.86,234.0,100,17,1,2,233.81,234.06,2,400,2,2,233.8,234.07,105,7,2,1,233.79,234.1,200,100,1,1,233.7,234.13,1200,400,1,1,233.66,234.17,1,1,1,1,233.58,234.25,505,100,2,1,233.53,234.41,10,500,1,1,233.5,234.43,100,105,1,2,233.45,234.5,15,63,1,4,AAPL,0.0,0.0,0.0,
2024-10-21 12:29:49.450300162+00:00,2024-10-21T12:29:49.450467509Z,10,2,38,T,A,0,233.86,100,130,167347,13303886,233.86,234.0,100,17,1,2,233.81,234.06,2,400,2,2,233.8,234.07,105,7,2,1,233.79,234.1,200,100,1,1,233.7,234.13,1200,400,1,1,233.66,234.17,1,1,1,1,233.58,234.25,505,100,2,1,233.53,234.41,10,500,1,1,233.5,234.43,100,105,1,2,233.45,234.5,15,63,1,4,AAPL,0.0,0.0,0.0,
2024-10-21 12:29:49.450300162+00:00,2024-10-21T12:29:49.450467509Z,10,2,38,C,B,0,233.86,100,130,167347,13303886,233.81,234.0,2,17,2,2,233.8,234.06,105,400,2,2,233.79,234.07,200,7,1,1,233.7,234.1,1200,100,1,1,233.66,234.13,1,400,1,1,233.58,234.17,505,1,2,1,233.53,234.25,10,100,1,1,233.5,234.41,100,500,1,1,233.45,234.43,15,105,1,2,233.4,234.5,110,63,2,4,AAPL,0.0,0.0,0.0,
2024-10-21 12:29:49.450311621+00:00,2024-10-21T12:29:49.450478735Z,10,2,38,A,B,0,233.86,100,130,167114,13303887,233.86,234.0,100,17,1,2,233.81,234.06,2,400,2,2,233.8,234.07,105,7,2,1,233.79,234.1,200,100,1,1,233.7,234.13,1200,400,1,1,233.66,234.17,1,1,1,1,233.58,234.25,505,100,2,1,233.53,234.41,10,500,1,1,233.5,234.43,100,105,1,2,233.45,234.5,15,63,1,4,AAPL,0.0,0.0,0.0,
2024-10-21 12:29:49.450314673+00:00,2024-10-21T12:29:49.450482704Z,10,2,38,T,A,0,233.86,100,0,168031,13303888,233.86,234.0,100,17,1,2,233.81,234.06,2,400,2,2,233.8,234.07,105,7,2,1,233.79,234.1,200,100,1,1,233.7,234.13,1200,400,1,1,233.66,234.17,1,1,1,1,233.58,234.25,505,100,2,1,233.53,234.41,10,500,1,1,233.5,234.43,100,105,1,2,233.45,234.5,15,63,1,4,AAPL,0.0,0.0,0.0,
2024-10-21 12:29:49.450314673+00:00,2024-10-21T12:29:49.450482704Z,10,2,38,T,N,0,233.86,17,130,168031,13303889,233.81,234.0,2,17,2,2,233.8,234.06,105,400,2,2,233.79,234.07,200,7,1,1,233.7,234.1,1200,100,1,1,233.66,234.13,1,400,1,1,233.58,234.17,505,1,2,1,233.53,234.25,10,100,1,1,233.5,234.41,100,500,1,1,233.45,234.43,15,105,1,2,233.4,234.5,110,63,2,4,AAPL,0.0,0.0,0.0,
2024-10-21 12:29:49.450321900+00:00,2024-10-21T12:29:49.450488087Z,10,2,38,A,A,0,233.92,100,130,166187,13303890,233.81,233.92,2,100,2,1,233.8,234.0,105,17,2,2,233.79,234.06,200,400,1,2,233.7,234.07,1200,7,1,1,233.66,234.1,1,100,1,1,233.58,234.13,505,400,2,1,233.53,234.17,10,1,1,1,233.5,234.25,100,100,1,1,233.45,234.41,15,500,1,1,233.4,234.43,110,105,2,2,AAPL,0.0,0.0,0.0,
2024-10-21 12:29:49.450325841+00:00,2024-10-21T12:29:49.450494597Z,10,2,38,A,A,1,233.93,54,130,168756,13303892,233.81,233.92,2,100,2,1,233.8,233.93,105,54,2,1,233.79,233.97,200,100,1,1,233.7,234.0,1200,17,1,2,233.66,234.06,1,400,1,2,233.58,234.07,505,7,2,1,233.53,234.1,10,100,1,1,233.5,234.13,100,400,1,1,233.45,234.17,15,1,1,1,233.4,234.25,110,100,2,1,AAPL,0.0,0.0,0.0,
2024-10-21 12:29:49.450334304+00:00,2024-10-21T12:29:49.450500673Z,10,2,38,A,A,2,233.97,100,130,166369,13303894,233.81,233.92,2,100,2,1,233.8,233.93,105,54,2,1,233.79,233.97,200,300,1,3,233.7,234.0,1200,17,1,2,233.66,234.06,1,400,1,2,233.58,234.07,505,7,2,1,233.53,234.1,10,100,1,1,233.5,234.13,100,400,1,1,233.45,234.17,15,1,1,1,233.4,234.25,110,100,2,1,AAPL,0.0,-200.0,0.0,
2024-10-21 12:29:49.450337787+00:00,2024-10-21T12:29:49.450503676Z,10,2,38,A,A,1,233.93,19,130,165889,13303895,233.81,233.92,2,100,2,1,233.8,233.93,105,73,2,2,233.79,233.97,200,300,1,3,233.7,234.0,1200,17,1,2,233.66,234.06,1,400,1,2,233.58,234.07,505,7,2,1,233.53,234.1,10,100,1,1,233.5,234.13,100,400,1,1,233.45,234.17,15,1,1,1,233.4,234.25,110,100,2,1,AAPL,0.0,-19.0,0.0,
2024-10-21 12:29:49.450341436+00:00,2024-10-21T12:29:49.450507723Z,10,2,38,C,A,1,233.93,54,130,166287,13303896,233.81,233.92,2,100,2,1,233.8,233.93,105,19,2,1,233.79,233.97,200,300,1,3,233.7,234.0,1200,17,1,2,233.66,234.06,1,400,1,2,233.58,234.07,505,7,2,1,233.53,234.1,10,100,1,1,233.5,234.13,100,400,1,1,233.45,234.17,15,1,1,1,233.4,234.25,110,100,2,1,AAPL,0.0,54.0,0.0,
2024-10-21 12:29:49.450344611+00:00,2024-10-21T12:29:49.450510407Z,10,2,38,C,A,0,233.92,100,130,165796,13303897,233.81,233.93,2,19,2,1,233.8,233.97,105,300,2,3,233.79,234.0,200,17,1,2,233.7,234.06,1200,400,1,2,233.66,234.07,1,7,1,1,233.58,234.1,505,100,2,1,233.53,234.13,10,400,1,1,233.5,234.17,100,1,1,1,233.45,234.25,15,100,1,1,233.4,234.41,110,500,2,1,AAPL,0.0,0.0,0.0,
2024-10-21 12:29:49.450349606+00:00,2024-10-21T12:29:49.450516082Z,10,2,38,A,A,2,233.98,19,130,166476,13303898,233.81,233.93,2,19,2,1,233.8,233.97,105,300,2,3,233.79,233.98,200,19,1,1,233.7,234.0,1200,17,1,2,233.66,234.06,1,400,1,2,233.58,234.07,505,7,2,1,233.53,234.1,10,100,1,1,233.5,234.13,100,400,1,1,233.45,234.17,15,1,1,1,233.4,234.25,110,100,2,1,AAPL,0.0,0.0,0.0,
2024-10-21 12:29:49.450351627+00:00,2024-10-21T12:29:49.450517345Z,10,2,38,C,A,1,233.97,100,130,165718,13303899,233.81,233.93,2,19,2,1,233.8,233.97,105,200,2,2,233.79,233.98,200,19,1,1,233.7,234.0,1200,17,1,2,233.66,234.06,1,400,1,2,233.58,234.07,505,7,2,1,233.53,234.1,10,100,1,1,233.5,234.13,100,400,1,1,233.45,234.17,15,1,1,1,233.4,234.25,110,100,2,1,AAPL,0.0,100.0,0.0,
2024-10-21 12:29:49.450355047+00:00,2024-10-21T12:29:49.450521006Z,10,2,38,C,A,1,233.97,100,130,165959,13303900,233.81,233.93,2,19,2,1,233.8,233.97,105,100,2,1,233.79,233.98,200,19,1,1,233.7,234.0,1200,17,1,2,233.66,234.06,1,400,1,2,233.58,234.07,505,7,2,1,233.53,234.1,10,100,1,1,233.5,234.13,100,400,1,1,233.45,234.17,15,1,1,1,233.4,234.25,110,100,2,1,AAPL,0.0,100.0,0.0,
2024-10-21 12:29:49.450394230+00:00,2024-10-21T12:29:49.450560627Z,10,2,38,C,B,2,233.79,200,130,166397,13303902,233.81,233.93,2,19,2,1,233.8,233.97,105,100,2,1,233.7,233.98,1200,19,1,1,233.66,234.0,1,17,1,2,233.58,234.06,505,400,2,2,233.53,234.07,10,7,1,1,233.5,234.1,100,100,1,1,233.45,234.13,15,400,1,1,233.4,234.17,110,1,2,1,233.39,234.25,10,100,1,1,AAPL,0.0,0.0,0.0,
2024-10-21 12:29:49.450652186+00:00,2024-10-21T12:29:49.450818190Z,10,2,38,C,A,1,233.97,100,130,166004,13303903,233.81,233.93,2,19,2,1,233.8,233.98,105,19,2,1,233.7,234.0,1200,17,1,2,233.66,234.06,1,400,1,2,233.58,234.07,505,7,2,1,233.53,234.1,10,100,1,1,233.5,234.13,100,400,1,1,233.45,234.17,15,1,1,1,233.4,234.25,110,100,2,1,233.39,234.41,10,500,1,1,AAPL,0.0,0.0,0.0,
2024-10-21 12:29:49.452270874+00:00,2024-10-21T12:29:49.452437450Z,10,2,38,C,A,4,234.07,7,130,166576,13303906,233.81,233.93,2,19,2,1,233.8,233.98,105,19,2,1,233.7,234.0,1200,17,1,2,233.66,234.06,1,400,1,2,233.58,234.1,505,100,2,1,233.53,234.13,10,400,1,1,233.5,234.17,100,1,1,1,233.45,234.25,15,100,1,1,233.4,234.41,110,500,2,1,233.39,234.43,10,105,1,2,AAPL,0.0,0.0,0.0,
2024-10-21 12:29:49.553764632+00:00,2024-10-21T12:29:49.553930519Z,10,2,38,C,A,1,233.98,19,130,165887,13304055,233.81,233.93,2,19,2,1,233.8,234.0,105,17,2,2,233.7,234.06,1200,400,1,2,233.66,234.1,1,100,1,1,233.58,234.13,505,400,2,1,233.53,234.17,10,1,1,1,233.5,234.25,100,100,1,1,233.45,234.41,15,500,1,1,233.4,234.43,110,105,2,2,233.39,234.5,10,63,1,4,AAPL,0.0,0.0,0.0,
2024-10-21 12:29:49.553823391+00:00,2024-10-21T12:29:49.553989527Z,10,2,38,A,B,2,233.79,200,130,166136,13304056,233.81,233.93,2,19,2,1,233.8,234.0,105,17,2,2,233.79,234.06,200,400,1,2,233.7,234.1,1200,100,1,1,233.66,234.13,1,400,1,1,233.58,234.17,505,1,2,1,233.53,234.25,10,100,1,1,233.5,234.41,100,500,1,1,233.45,234.43,15,105,1,2,233.4,234.5,110,63,2,4,AAPL,0.0,0.0,0.0,
2024-10-21 12:29:49.703766083+00:00,2024-10-21T12:29:49.703932459Z,10,2,38,C,A,0,233.93,19,130,166376,13304148,233.81,234.0,2,17,2,2,233.8,234.06,105,400,2,2,233.79,234.1,200,100,1,1,233.7,234.13,1200,400,1,1,233.66,234.17,1,1,1,1,233.58,234.25,505,100,2,1,233.53,234.41,10,500,1,1,233.5,234.43,100,105,1,2,233.45,234.5,15,63,1,4,233.4,234.59,110,60,2,1,AAPL,0.0,0.0,0.0,
2024-10-21 12:29:50.524022649+00:00,2024-10-21T12:29:50.524188835Z,10,2,38,C,B,2,233.79,200,130,166186,13304862,233.81,234.0,2,17,2,2,233.8,234.06,105,400,2,2,233.7,234.1,1200,100,1,1,233.66,234.13,1,400,1,1,233.58,234.17,505,1,2,1,233.53,234.25,10,100,1,1,233.5,234.41,100,500,1,1,233.45,234.43,15,105,1,2,233.4,234.5,110,63,2,4,233.39,234.59,10,60,1,1,AAPL,0.0,0.0,0.0,
2024-10-21 12:29:50.524034831+00:00,2024-10-21T12:29:50.524201597Z,10,2,38,A,B,2,233.78,200,130,166766,13304863,233.81,234.0,2,17,2,2,233.8,234.06,105,400,2,2,233.78,234.1,200,100,1,1,233.7,234.13,1200,400,1,1,233.66,234.17,1,1,1,1,233.58,234.25,505,100,2,1,233.53,234.41,10,500,1,1,233.5,234.43,100,105,1,2,233.45,234.5,15,63,1,4,233.4,234.59,110,60,2,1,AAPL,0.0,0.0,0.0,
2024-10-21 12:29:51.461550015+00:00,2024-10-21T12:29:51.461716502Z,10,2,38,A,A,0,233.97,7,130,166487,13307787,233.81,233.97,2,7,2,1,233.8,234.0,105,17,2,2,233.78,234.06,200,400,1,2,233.7,234.1,1200,100,1,1,233.66,234.13,1,400,1,1,233.58,234.17,505,1,2,1,233.53,234.25,10,100,1,1,233.5,234.41,100,500,1,1,233.45,234.43,15,105,1,2,233.4,234.5,110,63,2,4,AAPL,0.0,0.0,0.0,
2024-10-21 12:29:54.581050838+00:00,2024-10-21T12:29:54.581217052Z,10,2,38,C,A,2,234.06,200,130,166214,13309491,233.81,233.97,2,7,2,1,233.8,234.0,105,17,2,2,233.78,234.06,200,200,1,1,233.7,234.1,1200,100,1,1,233.66,234.13,1,400,1,1,233.58,234.17,505,1,2,1,233.53,234.25,10,100,1,1,233.5,234.41,100,500,1,1,233.45,234.43,15,105,1,2,233.4,234.5,110,63,2,4,AAPL,0.0,200.0,0.0,
2024-10-21 12:29:54.581064740+00:00,2024-10-21T12:29:54.581231517Z,10,2,38,A,A,2,234.02,400,130,166777,13309492,233.81,233.97,2,7,2,1,233.8,234.0,105,17,2,2,233.78,234.02,200,400,1,1,233.7,234.1,1200,100,1,1,233.66,234.13,1,400,1,1,233.58,234.17,505,1,2,1,233.53,234.25,10,100,1,1,233.5,234.41,100,500,1,1,233.45,234.43,15,105,1,2,233.4,234.5,110,63,2,4,AAPL,0.0,0.0,0.0,
2024-10-21 12:29:54.639369336+00:00,2024-10-21T12:29:54.639536184Z,10,2,38,A,A,1,233.98,200,130,166848,13309521,233.81,233.97,2,7,2,1,233.8,233.98,105,200,2,1,233.78,234.0,200,17,1,2,233.7,234.1,1200,100,1,1,233.66,234.13,1,400,1,1,233.58,234.17,505,1,2,1,233.53,234.25,10,100,1,1,233.5,234.41,100,500,1,1,233.45,234.43,15,105,1,2,233.4,234.5,110,63,2,4,AAPL,0.0,0.0,0.0,
2024-10-21 12:29:55.410313755+00:00,2024-10-21T12:29:55.410480455Z,10,2,38,A,A,0,233.96,200,130,166700,13310140,233.81,233.96,2,200,2,1,233.8,233.97,105,7,2,1,233.78,234.0,200,17,1,2,233.7,234.1,1200,100,1,1,233.66,234.13,1,400,1,1,233.58,234.17,505,1,2,1,233.53,234.25,10,100,1,1,233.5,234.41,100,500,1,1,233.45,234.43,15,105,1,2,233.4,234.5,110,63,2,4,AAPL,0.0,0.0,0.0,
2024-10-21 12:30:01.594370016+00:00,2024-10-21T12:30:01.594536029Z,10,2,38,C,B,2,233.78,200,130,166013,13329349,233.81,233.96,2,200,2,1,233.8,233.97,105,7,2,1,233.7,234.0,1200,17,1,2,233.66,234.1,1,100,1,1,233.58,234.13,505,400,2,1,233.53,234.17,10,1,1,1,233.5,234.25,100,100,1,1,233.45,234.41,15,500,1,1,233.4,234.43,110,105,2,2,233.39,234.5,10,63,1,4,AAPL,0.0,0.0,0.0,
2024-10-21 12:30:01.675073949+00:00,2024-10-21T12:30:01.675240968Z,10,2,38,A,B,2,233.77,200,130,167019,13329475,233.81,233.96,2,200,2,1,233.8,233.97,105,7,2,1,233.77,234.0,200,17,1,2,233.7,234.1,1200,100,1,1,233.66,234.13,1,400,1,1,233.58,234.17,505,1,2,1,233.53,234.25,10,100,1,1,233.5,234.41,100,500,1,1,233.45,234.43,15,105,1,2,233.4,234.5,110,63,2,4,AAPL,0.0,0.0,0.0,
2024-10-21 12:30:01.702282387+00:00,2024-10-21T12:30:01.702448731Z,10,2,38,C,B,2,233.77,200,130,166344,13329489,233.81,233.96,2,200,2,1,233.8,233.97,105,7,2,1,233.7,234.0,1200,17,1,2,233.66,234.1,1,100,1,1,233.58,234.13,505,400,2,1,233.53,234.17,10,1,1,1,233.5,234.25,100,100,1,1,233.45,234.41,15,500,1,1,233.4,234.43,110,105,2,2,233.39,234.5,10,63,1,4,AAPL,0.0,0.0,0.0,
2024-10-21 12:30:01.702295886+00:00,2024-10-21T12:30:01.702462409Z,10,2,38,A,B,2,233.73,400,130,166523,13329490,233.81,233.96,2,200,2,1,233.8,233.97,105,7,2,1,233.73,234.0,400,17,1,2,233.7,234.1,1200,100,1,1,233.66,234.13,1,400,1,1,233.58,234.17,505,1,2,1,233.53,234.25,10,100,1,1,233.5,234.41,100,500,1,1,233.45,234.43,15,105,1,2,233.4,234.5,110,63,2,4,AAPL,0.0,0.0,0.0,
2024-10-21 12:30:01.702628858+00:00,2024-10-21T12:30:01.702795294Z,10,2,38,A,A,0,233.96,200,130,166436,13329491,233.81,233.96,2,400,2,2,233.8,233.97,105,7,2,1,233.73,234.0,400,17,1,2,233.7,234.1,1200,100,1,1,233.66,234.13,1,400,1,1,233.58,234.17,505,1,2,1,233.53,234.25,10,100,1,1,233.5,234.41,100,500,1,1,233.45,234.43,15,105,1,2,233.4,234.5,110,63,2,4,AAPL,-200.0,-200.0,-200.0,
2024-10-21 12:30:09.716255586+00:00,2024-10-21T12:30:09.716422273Z,10,2,38,A,B,2,233.77,200,130,166687,13350054,233.81,233.96,2,400,2,2,233.8,233.97,105,7,2,1,233.77,234.0,200,17,1,2,233.7,234.1,1200,100,1,1,233.66,234.13,1,400,1,1,233.58,234.17,505,1,2,1,233.53,234.25,10,100,1,1,233.5,234.41,100,500,1,1,233.45,234.43,15,105,1,2,233.4,234.5,110,63,2,4,AAPL,0.0,0.0,0.0,
2024-10-21 12:30:10.321520576+00:00,2024-10-21T12:30:10.321686875Z,10,2,38,A,B,2,233.78,200,130,166299,13350463,233.81,233.96,2,400,2,2,233.8,233.97,105,7,2,1,233.78,234.0,200,17,1,2,233.7,234.1,1200,100,1,1,233.66,234.13,1,400,1,1,233.58,234.17,505,1,2,1,233.53,234.25,10,100,1,1,233.5,234.41,100,500,1,1,233.45,234.43,15,105,1,2,233.4,234.5,110,63,2,4,AAPL,0.0,0.0,0.0,
2024-10-21 12:30:10.800024827+00:00,2024-10-21T12:30:10.800190917Z,10,2,38,A,A,0,233.88,2,130,166090,13351078,233.81,233.88,2,2,2,1,233.8,233.96,105,400,2,2,233.78,233.97,200,7,1,1,233.7,234.0,1200,17,1,2,233.66,234.1,1,100,1,1,233.58,234.13,505,400,2,1,233.53,234.17,10,1,1,1,233.5,234.25,100,100,1,1,233.45,234.41,15,500,1,1,233.4,234.43,110,105,2,2,AAPL,0.0,0.0,0.0,
2024-10-21 12:30:10.800051476+00:00,2024-10-21T12:30:10.800218508Z,10,2,38,C,B,2,233.78,200,130,167032,13351080,233.81,233.88,2,2,2,1,233.8,233.96,105,400,2,2,233.7,233.97,1200,7,1,1,233.66,234.0,1,17,1,2,233.58,234.1,505,100,2,1,233.53,234.13,10,400,1,1,233.5,234.17,100,1,1,1,233.45,234.25,15,100,1,1,233.4,234.41,110,500,2,1,233.39,234.43,10,105,1,2,AAPL,0.0,0.0,0.0,
2024-10-21 12:30:10.801218083+00:00,2024-10-21T12:30:10.801387277Z,10,2,38,T,A,0,233.81,1,0,169194,13351086,233.81,233.88,2,2,2,1,233.8,233.96,105,400,2,2,233.7,233.97,1200,7,1,1,233.66,234.0,1,17,1,2,233.58,234.1,505,100,2,1,233.53,234.13,10,400,1,1,233.5,234.17,100,1,1,1,233.45,234.25,15,100,1,1,233.4,234.41,110,500,2,1,233.39,234.43,10,105,1,2,AAPL,0.0,0.0,0.0,
2024-10-21 12:30:10.801218083+00:00,2024-10-21T12:30:10.801387277Z,10,2,38,T,A,0,233.81,1,130,169194,13351087,233.81,233.88,1,2,1,1,233.8,233.96,105,400,2,2,233.7,233.97,1200,7,1,1,233.66,234.0,1,17,1,2,233.58,234.1,505,100,2,1,233.53,234.13,10,400,1,1,233.5,234.17,100,1,1,1,233.45,234.25,15,100,1,1,233.4,234.41,110,500,2,1,233.39,234.43,10,105,1,2,AAPL,-1.0,-1.0,-1.0,
2024-10-21 12:30:10.801218083+00:00,2024-10-21T12:30:10.801387277Z,10,2,38,C,B,0,233.81,1,130,169194,13351087,233.8,233.88,105,2,2,1,233.7,233.96,1200,400,1,2,233.66,233.97,1,7,1,1,233.58,234.0,505,17,2,2,233.53,234.1,10,100,1,1,233.5,234.13,100,400,1,1,233.45,234.17,15,1,1,1,233.4,234.25,110,100,2,1,233.39,234.41,10,500,1,1,233.31,234.43,110,105,2,2,AAPL,0.0,0.0,-1.0,
2024-10-21 12:30:10.801242022+00:00,2024-10-21T12:30:10.801408166Z,10,2,38,A,A,0,233.86,100,130,166144,13351089,233.8,233.86,105,100,2,1,233.7,233.88,1200,2,1,1,233.66,233.96,1,400,1,2,233.58,233.97,505,7,2,1,233.53,234.0,10,17,1,2,233.5,234.1,100,100,1,1,233.45,234.13,15,400,1,1,233.4,234.17,110,1,2,1,233.39,234.25,10,100,1,1,233.31,234.41,110,500,2,1,AAPL,0.0,0.0,-1.0,
2024-10-21 12:30:10.801249125+00:00,2024-10-21T12:30:10.801415386Z,10,2,38,A,A,0,233.85,14,130,166261,13351090,233.8,233.85,105,14,2,1,233.7,233.86,1200,100,1,1,233.66,233.88,1,2,1,1,233.58,233.96,505,400,2,2,233.53,233.97,10,7,1,1,233.5,234.0,100,17,1,2,233.45,234.1,15,100,1,1,233.4,234.13,110,400,2,1,233.39,234.17,10,1,1,1,233.31,234.25,110,100,2,1,AAPL,0.0,0.0,-1.0,
2024-10-21 12:30:10.801255194+00:00,2024-10-21T12:30:10.801421493Z,10,2,38,A,A,1,233.86,100,130,166299,13351091,233.8,233.85,105,14,2,1,233.7,233.86,1200,200,1,2,233.66,233.88,1,2,1,1,233.58,233.96,505,400,2,2,233.53,233.97,10,7,1,1,233.5,234.0,100,17,1,2,233.45,234.1,15,100,1,1,233.4,234.13,110,400,2,1,233.39,234.17,10,1,1,1,233.31,234.25,110,100,2,1,AAPL,0.0,-100.0,-1.0,
2024-10-21 12:30:10.801256016+00:00,2024-10-21T12:30:10.801423606Z,10,2,38,A,A,2,233.87,21,130,167590,13351092,233.8,233.85,105,14,2,1,233.7,233.86,1200,200,1,2,233.66,233.87,1,21,1,1,233.58,233.88,505,2,2,1,233.53,233.96,10,400,1,2,233.5,233.97,100,7,1,1,233.45,234.0,15,17,1,2,233.4,234.1,110,100,2,1,233.39,234.13,10,400,1,1,233.31,234.17,110,1,2,1,AAPL,0.0,0.0,-1.0,
2024-10-21 12:30:10.801285169+00:00,2024-10-21T12:30:10.801453006Z,10,2,38,C,A,1,233.86,100,130,167837,13351093,233.8,233.85,105,14,2,1,233.7,233.86,1200,100,1,1,233.66,233.87,1,21,1,1,233.58,233.88,505,2,2,1,233.53,233.96,10,400,1,2,233.5,233.97,100,7,1,1,233.45,234.0,15,17,1,2,233.4,234.1,110,100,2,1,233.39,234.13,10,400,1,1,233.31,234.17,110,1,2,1,AAPL,0.0,100.0,-1.0,
2024-10-21 12:30:10.801293865+00:00,2024-10-21T12:30:10.801459804Z,10,2,38,C,A,1,233.86,100,130,165939,13351094,233.8,233.85,105,14,2,1,233.7,233.87,1200,21,1,1,233.66,233.88,1,2,1,1,233.58,233.96,505,400,2,2,233.53,233.97,10,7,1,1,233.5,234.0,100,17,1,2,233.45,234.1,15,100,1,1,233.4,234.13,110,400,2,1,233.39,234.17,10,1,1,1,233.31,234.25,110,100,2,1,AAPL,0.0,0.0,-1.0,
2024-10-21 12:30:10.801518640+00:00,2024-10-21T12:30:10.801684920Z,10,2,38,A,A,3,233.89,100,130,166280,13351095,233.8,233.85,105,14,2,1,233.7,233.87,1200,21,1,1,233.66,233.88,1,2,1,1,233.58,233.89,505,100,2,1,233.53,233.96,10,400,1,2,233.5,233.97,100,7,1,1,233.45,234.0,15,17,1,2,233.4,234.1,110,100,2,1,233.39,234.13,10,400,1,1,233.31,234.17,110,1,2,1,AAPL,0.0,0.0,-1.0,
2024-10-21 12:30:10.801839030+00:00,2024-10-21T12:30:10.802005192Z,10,2,38,A,A,0,233.83,4,130,166162,13351096,233.8,233.83,105,4,2,1,233.7,233.85,1200,14,1,1,233.66,233.87,1,21,1,1,233.58,233.88,505,2,2,1,233.53,233.89,10,100,1,1,233.5,233.96,100,400,1,2,233.45,233.97,15,7,1,1,233.4,234.0,110,17,2,2,233.39,234.1,10,100,1,1,233.31,234.13,110,400,2,1,AAPL,0.0,0.0,-1.0,
2024-10-21 12:30:10.801849830+00:00,2024-10-21T12:30:10.802018507Z,10,2,38,T,A,0,233.8,5,0,168677,13351097,233.8,233.83,105,4,2,1,233.7,233.85,1200,14,1,1,233.66,233.87,1,21,1,1,233.58,233.88,505,2,2,1,233.53,233.89,10,100,1,1,233.5,233.96,100,400,1,2,233.45,233.97,15,7,1,1,233.4,234.0,110,17,2,2,233.39,234.1,10,100,1,1,233.31,234.13,110,400,2,1,AAPL,0.0,0.0,-1.0,
2024-10-21 12:30:10.801849830+00:00,2024-10-21T12:30:10.802018507Z,10,2,38,T,A,0,233.8,100,130,168677,13351098,233.8,233.83,100,4,1,1,233.7,233.85,1200,14,1,1,233.66,233.87,1,21,1,1,233.58,233.88,505,2,2,1,233.53,233.89,10,100,1,1,233.5,233.96,100,400,1,2,233.45,233.97,15,7,1,1,233.4,234.0,110,17,2,2,233.39,234.1,10,100,1,1,233.31,234.13,110,400,2,1,AAPL,-5.0,-5.0,-6.0,
2024-10-21 12:30:10.801849830+00:00,2024-10-21T12:30:10.802018507Z,10,2,38,C,B,0,233.8,100,130,168677,13351098,233.7,233.83,1200,4,1,1,233.66,233.85,1,14,1,1,233.58,233.87,505,21,2,1,233.53,233.88,10,2,1,1,233.5,233.89,100,100,1,1,233.45,233.96,15,400,1,2,233.4,233.97,110,7,2,1,233.39,234.0,10,17,1,2,233.31,234.1,110,100,2,1,233.3,234.13,100,400,1,1,AAPL,0.0,0.0,-6.0,
2024-10-21 12:30:10.801875239+00:00,2024-10-21T12:30:10.802042064Z,10,2,38,A,A,0,233.82,100,130,166825,13351100,233.7,233.82,1200,200,1,2,233.66,233.83,1,4,1,1,233.58,233.85,505,14,2,1,233.53,233.87,10,21,1,1,233.5,233.88,100,2,1,1,233.45,233.89,15,100,1,1,233.4,233.96,110,400,2,2,233.39,233.97,10,7,1,1,233.31,234.0,110,17,2,2,233.3,234.1,100,100,1,1,AAPL,0.0,0.0,-6.0,
2024-10-21 12:30:10.801885691+00:00,2024-10-21T12:30:10.802051826Z,10,2,38,A,A,0,233.82,100,130,166135,13351101,233.7,233.82,1200,300,1,3,233.66,233.83,1,4,1,1,233.58,233.85,505,14,2,1,233.53,233.87,10,21,1,1,233.5,233.88,100,2,1,1,233.45,233.89,15,100,1,1,233.4,233.96,110,400,2,2,233.39,233.97,10,7,1,1,233.31,234.0,110,17,2,2,233.3,234.1,100,100,1,1,AAPL,-100.0,-100.0,-106.0,
2024-10-21 12:30:10.801887002+00:00,2024-10-21T12:30:10.802056341Z,10,2,38,A,A,0,233.82,100,130,169339,13351102,233.7,233.82,1200,400,1,4,233.66,233.83,1,4,1,1,233.58,233.85,505,14,2,1,233.53,233.87,10,21,1,1,233.5,233.88,100,2,1,1,233.45,233.89,15,100,1,1,233.4,233.96,110,400,2,2,233.39,233.97,10,7,1,1,233.31,234.0,110,17,2,2,233.3,234.1,100,100,1,1,AAPL,-100.0,-100.0,-206.0,
2024-10-21 12:30:10.801896921+00:00,2024-10-21T12:30:10.802062956Z,10,2,38,C,A,0,233.82,100,130,166035,13351103,233.7,233.82,1200,300,1,3,233.66,233.83,1,4,1,1,233.58,233.85,505,14,2,1,233.53,233.87,10,21,1,1,233.5,233.88,100,2,1,1,233.45,233.89,15,100,1,1,233.4,233.96,110,400,2,2,233.39,233.97,10,7,1,1,233.31,234.0,110,17,2,2,233.3,234.1,100,100,1,1,AAPL,100.0,100.0,-106.0,
2024-10-21 12:30:10.801910649+00:00,2024-10-21T12:30:10.802076696Z,10,2,38,C,A,5,233.89,100,130,166047,13351104,233.7,233.82,1200,300,1,3,233.66,233.83,1,4,1,1,233.58,233.85,505,14,2,1,233.53,233.87,10,21,1,1,233.5,233.88,100,2,1,1,233.45,233.96,15,400,1,2,233.4,233.97,110,7,2,1,233.39,234.0,10,17,1,2,233.31,234.1,110,100,2,1,233.3,234.13,100,400,1,1,AAPL,0.0,0.0,-106.0,
2024-10-21 12:30:10.801912958+00:00,2024-10-21T12:30:10.802078886Z,10,2,38,C,A,0,233.82,100,130,165928,13351105,233.7,233.82,1200,200,1,2,233.66,233.83,1,4,1,1,233.58,233.85,505,14,2,1,233.53,233.87,10,21,1,1,233.5,233.88,100,2,1,1,233.45,233.96,15,400,1,2,233.4,233.97,110,7,2,1,233.39,234.0,10,17,1,2,233.31,234.1,110,100,2,1,233.3,234.13,100,400,1,1,AAPL,100.0,100.0,-6.0,
2024-10-21 12:30:10.801948090+00:00,2024-10-21T12:30:10.802114011Z,10,2,38,C,A,0,233.82,100,130,165921,13351106,233.7,233.82,1200,100,1,1,233.66,233.83,1,4,1,1,233.58,233.85,505,14,2,1,233.53,233.87,10,21,1,1,233.5,233.88,100,2,1,1,233.45,233.96,15,400,1,2,233.4,233.97,110,7,2,1,233.39,234.0,10,17,1,2,233.31,234.1,110,100,2,1,233.3,234.13,100,400,1,1,AAPL,100.0,100.0,94.0,
2024-10-21 12:30:10.802147907+00:00,2024-10-21T12:30:10.802313903Z,10,2,38,C,A,0,233.82,100,130,165996,13351107,233.7,233.83,1200,4,1,1,233.66,233.85,1,14,1,1,233.58,233.87,505,21,2,1,233.53,233.88,10,2,1,1,233.5,233.96,100,400,1,2,233.45,233.97,15,7,1,1,233.4,234.0,110,17,2,2,233.39,234.1,10,100,1,1,233.31,234.13,110,400,2,1,233.3,234.17,100,1,1,1,AAPL,0.0,0.0,94.0,
2024-10-21 12:30:10.802168655+00:00,2024-10-21T12:30:10.802335407Z,10,2,38,C,A,1,233.85,14,130,166752,13351108,233.7,233.83,1200,4,1,1,233.66,233.87,1,21,1,1,233.58,233.88,505,2,2,1,233.53,233.96,10,400,1,2,233.5,233.97,100,7,1,1,233.45,234.0,15,17,1,2,233.4,234.1,110,100,2,1,233.39,234.13,10,400,1,1,233.31,234.17,110,1,2,1,233.3,234.25,100,100,1,1,AAPL,0.0,0.0,94.0,
2024-10-21 12:30:10.803071076+00:00,2024-10-21T12:30:10.803237363Z,10,2,38,C,A,4,233.97,7,130,166287,13351112,233.7,233.83,1200,4,1,1,233.66,233.87,1,21,1,1,233.58,233.88,505,2,2,1,233.53,233.96,10,400,1,2,233.5,234.0,100,17,1,2,233.45,234.1,15,100,1,1,233.4,234.13,110,400,2,1,233.39,234.17,10,1,1,1,233.31,234.25,110,100,2,1,233.3,234.41,100,500,1,1,AAPL,0.0,0.0,94.0,
2024-10-21 12:30:10.804124159+00:00,2024-10-21T12:30:10.804290650Z,10,2,38,C,A,2,233.88,2,130,166491,13351118,233.7,233.83,1200,4,1,1,233.66,233.87,1,21,1,1,233.58,233.96,505,400,2,2,233.53,234.0,10,17,1,2,233.5,234.1,100,100,1,1,233.45,234.13,15,400,1,1,233.4,234.17,110,1,2,1,233.39,234.25,10,100,1,1,233.31,234.41,110,500,2,1,233.3,234.43,100,105,1,2,AAPL,0.0,0.0,94.0,
2024-10-21 12:30:10.805929875+00:00,2024-10-21T12:30:10.806095967Z,10,2,38,C,A,0,233.83,4,130,166092,13351123,233.7,233.87,1200,21,1,1,233.66,233.96,1,400,1,2,233.58,234.0,505,17,2,2,233.53,234.1,10,100,1,1,233.5,234.13,100,400,1,1,233.45,234.17,15,1,1,1,233.4,234.25,110,100,2,1,233.39,234.41,10,500,1,1,233.31,234.43,110,105,2,2,233.3,234.5,100,63,1,4,AAPL,0.0,0.0,94.0,
2024-10-21 12:30:10.872155138+00:00,2024-10-21T12:30:10.872321876Z,10,2,38,A,B,2,233.62,200,130,166738,13351674,233.7,233.87,1200,21,1,1,233.66,233.96,1,400,1,2,233.62,234.0,200,17,1,2,233.58,234.1,505,100,2,1,233.53,234.13,10,400,1,1,233.5,234.17,100,1,1,1,233.45,234.25,15,100,1,1,233.4,234.41,110,500,2,1,233.39,234.43,10,105,1,2,233.31,234.5,110,63,2,4,AAPL,0.0,0.0,94.0,
2024-10-21 12:30:10.897934717+00:00,2024-10-21T12:30:10.898101085Z,10,2,38,A,B,2,233.62,200,130,166368,13351708,233.7,233.87,1200,21,1,1,233.66,233.96,1,400,1,2,233.62,234.0,400,17,2,2,233.58,234.1,505,100,2,1,233.53,234.13,10,400,1,1,233.5,234.17,100,1,1,1,233.45,234.25,15,100,1,1,233.4,234.41,110,500,2,1,233.39,234.43,10,105,1,2,233.31,234.5,110,63,2,4,AAPL,0.0,200.0,94.0,
2024-10-21 12:30:10.903766597+00:00,2024-10-21T12:30:10.903932828Z,10,2,38,C,A,0,233.87,21,130,166231,13351712,233.7,233.96,1200,400,1,2,233.66,234.0,1,17,1,2,233.62,234.1,400,100,2,1,233.58,234.13,505,400,2,1,233.53,234.17,10,1,1,1,233.5,234.25,100,100,1,1,233.45,234.41,15,500,1,1,233.4,234.43,110,105,2,2,233.39,234.5,10,63,1,4,233.31,234.59,110,60,2,1,AAPL,0.0,0.0,94.0,
2024-10-21 12:30:10.925970633+00:00,2024-10-21T12:30:10.926143379Z,10,2,38,A,A,0,233.91,400,130,172746,13351770,233.7,233.91,1200,400,1,1,233.66,234.0,1,17,1,2,233.62,234.1,400,100,2,1,233.58,234.13,505,400,2,1,233.53,234.17,10,1,1,1,233.5,234.25,100,100,1,1,233.45,234.41,15,500,1,1,233.4,234.43,110,105,2,2,233.39,234.5,10,63,1,4,233.31,234.59,110,60,2,1,AAPL,0.0,0.0,94.0,
2024-10-21 12:30:11.987463739+00:00,2024-10-21T12:30:11.987630030Z,10,2,38,C,B,2,233.62,200,130,166291,13353675,233.7,233.91,1200,400,1,1,233.66,234.0,1,17,1,2,233.62,234.1,200,100,1,1,233.58,234.13,505,400,2,1,233.53,234.17,10,1,1,1,233.5,234.25,100,100,1,1,233.45,234.41,15,500,1,1,233.4,234.43,110,105,2,2,233.39,234.5,10,63,1,4,233.31,234.59,110,60,2,1,AAPL,0.0,-200.0,0.0,
2024-10-21 12:30:11.987474545+00:00,2024-10-21T12:30:11.987640828Z,10,2,38,C,B,2,233.62,200,130,166283,13353676,233.7,233.91,1200,400,1,1,233.66,234.0,1,17,1,2,233.58,234.1,505,100,2,1,233.53,234.13,10,400,1,1,233.5,234.17,100,1,1,1,233.45,234.25,15,100,1,1,233.4,234.41,110,500,2,1,233.39,234.43,10,105,1,2,233.31,234.5,110,63,2,4,233.3,234.59,100,60,1,1,AAPL,0.0,0.0,0.0,
2024-10-21 12:30:11.987486150+00:00,2024-10-21T12:30:11.987652703Z,10,2,38,A,B,2,233.6,200,130,166553,13353677,233.7,233.91,1200,400,1,1,233.66,234.0,1,17,1,2,233.6,234.1,200,100,1,1,233.58,234.13,505,400,2,1,233.53,234.17,10,1,1,1,233.5,234.25,100,100,1,1,233.45,234.41,15,500,1,1,233.4,234.43,110,105,2,2,233.39,234.5,10,63,1,4,233.31,234.59,110,60,2,1,AAPL,0.0,0.0,0.0,
2024-10-21 12:30:12.806183466+00:00,2024-10-21T12:30:12.806349843Z,10,2,38,A,A,1,233.97,7,130,166377,13354393,233.7,233.91,1200,400,1,1,233.66,233.97,1,7,1,1,233.6,234.0,200,17,1,2,233.58,234.1,505,100,2,1,233.53,234.13,10,400,1,1,233.5,234.17,100,1,1,1,233.45,234.25,15,100,1,1,233.4,234.41,110,500,2,1,233.39,234.43,10,105,1,2,233.31,234.5,110,63,2,4,AAPL,0.0,0.0,0.0,
2024-10-21 12:30:13.320141102+00:00,2024-10-21T12:30:13.320307781Z,10,2,38,A,B,2,233.61,200,130,166679,13354988,233.7,233.91,1200,400,1,1,233.66,233.97,1,7,1,1,233.61,234.0,200,17,1,2,233.58,234.1,505,100,2,1,233.53,234.13,10,400,1,1,233.5,234.17,100,1,1,1,233.45,234.25,15,100,1,1,233.4,234.41,110,500,2,1,233.39,234.43,10,105,1,2,233.31,234.5,110,63,2,4,AAPL,0.0,0.0,0.0,
2024-10-21 12:30:13.926860673+00:00,2024-10-21T12:30:13.927027211Z,10,2,38,A,B,1,233.68,200,130,166538,13356286,233.7,233.91,1200,400,1,1,233.68,233.97,200,7,1,1,233.66,234.0,1,17,1,2,233.58,234.1,505,100,2,1,233.53,234.13,10,400,1,1,233.5,234.17,100,1,1,1,233.45,234.25,15,100,1,1,233.4,234.41,110,500,2,1,233.39,234.43,10,105,1,2,233.31,234.5,110,63,2,4,AAPL,0.0,0.0,0.0,
2024-10-21 12:30:33.768570061+00:00,2024-10-21T12:30:33.768736428Z,10,2,38,C,B,1,233.68,200,130,166367,13375759,233.7,233.91,1200,400,1,1,233.66,233.97,1,7,1,1,233.58,234.0,505,17,2,2,233.53,234.1,10,100,1,1,233.5,234.13,100,400,1,1,233.45,234.17,15,1,1,1,233.4,234.25,110,100,2,1,233.39,234.41,10,500,1,1,233.31,234.43,110,105,2,2,233.3,234.5,100,63,1,4,AAPL,0.0,0.0,0.0,
2024-10-21 12:30:33.768615671+00:00,2024-10-21T12:30:33.768783306Z,10,2,38,A,A,0,233.86,2,130,167635,13375763,233.7,233.86,1200,2,1,1,233.66,233.91,1,400,1,1,233.58,233.97,505,7,2,1,233.53,234.0,10,17,1,2,233.5,234.1,100,100,1,1,233.45,234.13,15,400,1,1,233.4,234.17,110,1,2,1,233.39,234.25,10,100,1,1,233.31,234.41,110,500,2,1,233.3,234.43,100,105,1,2,AAPL,0.0,0.0,0.0,
2024-10-21 12:30:33.772724890+00:00,2024-10-21T12:30:33.772891039Z,10,2,38,C,A,0,233.86,2,130,166149,13375767,233.7,233.91,1200,400,1,1,233.66,233.97,1,7,1,1,233.58,234.0,505,17,2,2,233.53,234.1,10,100,1,1,233.5,234.13,100,400,1,1,233.45,234.17,15,1,1,1,233.4,234.25,110,100,2,1,233.39,234.41,10,500,1,1,233.31,234.43,110,105,2,2,233.3,234.5,100,63,1,4,AAPL,0.0,0.0,0.0,
2024-10-21 12:30:33.841886930+00:00,2024-10-21T12:30:33.842053425Z,10,2,38,A,B,3,233.53,400,130,166495,13375851,233.7,233.91,1200,400,1,1,233.66,233.97,1,7,1,1,233.58,234.0,505,17,2,2,233.53,234.1,410,100,2,1,233.5,234.13,100,400,1,1,233.45,234.17,15,1,1,1,233.4,234.25,110,100,2,1,233.39,234.41,10,500,1,1,233.31,234.43,110,105,2,2,233.3,234.5,100,63,1,4,AAPL,0.0,400.0,0.0,
2024-10-21 12:30:33.993763813+00:00,2024-10-21T12:30:33.993930780Z,10,2,38,A,B,3,233.57,200,130,166967,13375889,233.7,233.91,1200,400,1,1,233.66,233.97,1,7,1,1,233.58,234.0,505,17,2,2,233.57,234.1,200,100,1,1,233.53,234.13,10,400,1,1,233.5,234.17,100,1,1,1,233.45,234.25,15,100,1,1,233.4,234.41,110,500,2,1,233.39,234.43,10,105,1,2,233.31,234.5,110,63,2,4,AAPL,0.0,0.0,0.0,
2024-10-21 12:30:34.613890939+00:00,2024-10-21T12:30:34.614057394Z,10,2,38,A,B,3,233.57,200,130,166455,13376208,233.7,233.91,1200,400,1,1,233.66,233.97,1,7,1,1,233.58,234.0,505,17,2,2,233.57,234.1,400,100,2,1,233.53,234.13,10,400,1,1,233.5,234.17,100,1,1,1,233.45,234.25,15,100,1,1,233.4,234.41,110,500,2,1,233.39,234.43,10,105,1,2,233.31,234.5,110,63,2,4,AAPL,0.0,200.0,0.0,
2024-10-21 12:30:34.668094071+00:00,2024-10-21T12:30:34.668260203Z,10,2,38,C,B,3,233.57,200,130,166132,13376228,233.7,233.91,1200,400,1,1,233.66,233.97,1,7,1,1,233.58,234.0,505,17,2,2,233.57,234.1,200,100,1,1,233.53,234.13,10,400,1,1,233.5,234.17,100,1,1,1,233.45,234.25,15,100,1,1,233.4,234.41,110,500,2,1,233.39,234.43,10,105,1,2,233.31,234.5,110,63,2,4,AAPL,0.0,-200.0,0.0,
2024-10-21 12:30:34.668106643+00:00,2024-10-21T12:30:34.668273099Z,10,2,38,A,B,2,233.61,200,130,166456,13376229,233.7,233.91,1200,400,1,1,233.66,233.97,1,7,1,1,233.61,234.0,200,17,1,2,233.58,234.1,505,100,2,1,233.53,234.13,10,400,1,1,233.5,234.17,100,1,1,1,233.45,234.25,15,100,1,1,233.4,234.41,110,500,2,1,233.39,234.43,10,105,1,2,233.31,234.5,110,63,2,4,AAPL,0.0,0.0,0.0,
2024-10-21 12:30:35.853859462+00:00,2024-10-21T12:30:35.854025768Z,10,2,38,C,A,1,233.97,7,130,166306,13377241,233.7,233.91,1200,400,1,1,233.66,234.0,1,17,1,2,233.61,234.1,200,100,1,1,233.58,234.13,505,400,2,1,233.53,234.17,10,1,1,1,233.5,234.25,100,100,1,1,233.45,234.41,15,500,1,1,233.4,234.43,110,105,2,2,233.39,234.5,10,63,1,4,233.31,234.59,110,60,2,1,AAPL,0.0,0.0,0.0,
2024-10-21 12:30:36.897088633+00:00,2024-10-21T12:30:36.897254958Z,10,2,38,A,B,2,233.63,200,130,166325,13378495,233.7,233.91,1200,400,1,1,233.66,234.0,1,17,1,2,233.63,234.1,200,100,1,1,233.58,234.13,505,400,2,1,233.53,234.17,10,1,1,1,233.5,234.25,100,100,1,1,233.45,234.41,15,500,1,1,233.4,234.43,110,105,2,2,233.39,234.5,10,63,1,4,233.31,234.59,110,60,2,1,AAPL,0.0,0.0,0.0,
2024-10-21 12:30:37.857289497+00:00,2024-10-21T12:30:37.857455846Z,10,2,38,A,A,0,233.91,7,130,166349,13379698,233.7,233.91,1200,407,1,2,233.66,234.0,1,17,1,2,233.63,234.1,200,100,1,1,233.58,234.13,505,400,2,1,233.53,234.17,10,1,1,1,233.5,234.25,100,100,1,1,233.45,234.41,15,500,1,1,233.4,234.43,110,105,2,2,233.39,234.5,10,63,1,4,233.31,234.59,110,60,2,1,AAPL,-7.0,-7.0,-7.0,
2024-10-21 12:30:37.932904919+00:00,2024-10-21T12:30:37.933071217Z,10,2,38,C,A,0,233.91,400,130,166298,13379830,233.7,233.91,1200,7,1,1,233.66,234.0,1,17,1,2,233.63,234.1,200,100,1,1,233.58,234.13,505,400,2,1,233.53,234.17,10,1,1,1,233.5,234.25,100,100,1,1,233.45,234.41,15,500,1,1,233.4,234.43,110,105,2,2,233.39,234.5,10,63,1,4,233.31,234.59,110,60,2,1,AAPL,400.0,400.0,393.0,
2024-10-21 12:30:37.932917819+00:00,2024-10-21T12:30:37.933084228Z,10,2,38,A,A,1,233.93,200,130,166409,13379831,233.7,233.91,1200,7,1,1,233.66,233.93,1,200,1,1,233.63,234.0,200,17,1,2,233.58,234.1,505,100,2,1,233.53,234.13,10,400,1,1,233.5,234.17,100,1,1,1,233.45,234.25,15,100,1,1,233.4,234.41,110,500,2,1,233.39,234.43,10,105,1,2,233.31,234.5,110,63,2,4,AAPL,0.0,0.0,393.0,
2024-10-21 12:30:40.401633392+00:00,2024-10-21T12:30:40.401799790Z,10,2,38,A,B,2,233.64,200,130,166398,13382028,233.7,233.91,1200,7,1,1,233.66,233.93,1,200,1,1,233.64,234.0,200,17,1,2,233.58,234.1,505,100,2,1,233.53,234.13,10,400,1,1,233.5,234.17,100,1,1,1,233.45,234.25,15,100,1,1,233.4,234.41,110,500,2,1,233.39,234.43,10,105,1,2,233.31,234.5,110,63,2,4,AAPL,0.0,0.0,0.0,
2024-10-21 12:30:40.472627145+00:00,2024-10-21T12:30:40.472793565Z,10,2,38,A,A,1,233.93,200,130,166420,13382215,233.7,233.91,1200,7,1,1,233.66,233.93,1,400,1,2,233.64,234.0,200,17,1,2,233.58,234.1,505,100,2,1,233.53,234.13,10,400,1,1,233.5,234.17,100,1,1,1,233.45,234.25,15,100,1,1,233.4,234.41,110,500,2,1,233.39,234.43,10,105,1,2,233.31,234.5,110,63,2,4,AAPL,0.0,-200.0,0.0,
2024-10-21 12:30:40.523757097+00:00,2024-10-21T12:30:40.523923090Z,10,2,38,C,A,1,233.93,200,130,165993,13382285,233.7,233.91,1200,7,1,1,233.66,233.93,1,200,1,1,233.64,234.0,200,17,1,2,233.58,234.1,505,100,2,1,233.53,234.13,10,400,1,1,233.5,234.17,100,1,1,1,233.45,234.25,15,100,1,1,233.4,234.41,110,500,2,1,233.39,234.43,10,105,1,2,233.31,234.5,110,63,2,4,AAPL,0.0,200.0,0.0,
2024-10-21 12:30:40.523770024+00:00,2024-10-21T12:30:40.523936566Z,10,2,38,A,A,0,233.87,200,130,166542,13382286,233.7,233.87,1200,200,1,1,233.66,233.91,1,7,1,1,233.64,234.0,200,17,1,2,233.58,234.1,505,100,2,1,233.53,234.13,10,400,1,1,233.5,234.17,100,1,1,1,233.45,234.25,15,100,1,1,233.4,234.41,110,500,2,1,233.39,234.43,10,105,1,2,233.31,234.5,110,63,2,4,AAPL,0.0,0.0,0.0,
2024-10-21 12:30:40.959299618+00:00,2024-10-21T12:30:40.959465649Z,10,2,38,C,A,0,233.87,200,130,166031,13382848,233.7,233.91,1200,7,1,1,233.66,234.0,1,17,1,2,233.64,234.1,200,100,1,1,233.58,234.13,505,400,2,1,233.53,234.17,10,1,1,1,233.5,234.25,100,100,1,1,233.45,234.41,15,500,1,1,233.4,234.43,110,105,2,2,233.39,234.5,10,63,1,4,233.31,234.59,110,60,2,1,AAPL,0.0,0.0,0.0,
2024-10-21 12:30:40.959311816+00:00,2024-10-21T12:30:40.959478166Z,10,2,38,A,A,1,234.0,200,130,166350,13382849,233.7,233.91,1200,7,1,1,233.66,234.0,1,217,1,3,233.64,234.1,200,100,1,1,233.58,234.13,505,400,2,1,233.53,234.17,10,1,1,1,233.5,234.25,100,100,1,1,233.45,234.41,15,500,1,1,233.4,234.43,110,105,2,2,233.39,234.5,10,63,1,4,233.31,234.59,110,60,2,1,AAPL,0.0,-200.0,0.0,
2024-10-21 12:30:40.959659070+00:00,2024-10-21T12:30:40.959825223Z,10,2,38,A,A,1,234.0,200,130,166153,13382851,233.7,233.91,1200,7,1,1,233.66,234.0,1,417,1,4,233.64,234.1,200,100,1,1,233.58,234.13,505,400,2,1,233.53,234.17,10,1,1,1,233.5,234.25,100,100,1,1,233.45,234.41,15,500,1,1,233.4,234.43,110,105,2,2,233.39,234.5,10,63,1,4,233.31,234.59,110,60,2,1,AAPL,0.0,-200.0,0.0,
2024-10-21 12:30:41.011299851+00:00,2024-10-21T12:30:41.011466621Z,10,2,38,C,A,1,234.0,200,130,166770,13382912,233.7,233.91,1200,7,1,1,233.66,234.0,1,217,1,3,233.64,234.1,200,100,1,1,233.58,234.13,505,400,2,1,233.53,234.17,10,1,1,1,233.5,234.25,100,100,1,1,233.45,234.41,15,500,1,1,233.4,234.43,110,105,2,2,233.39,234.5,10,63,1,4,233.31,234.59,110,60,2,1,AAPL,0.0,200.0,0.0,
2024-10-21 12:30:41.011312427+00:00,2024-10-21T12:30:41.011478729Z,10,2,38,A,A,1,233.93,400,130,166302,13382913,233.7,233.91,1200,7,1,1,233.66,233.93,1,400,1,1,233.64,234.0,200,17,1,2,233.58,234.1,505,100,2,1,233.53,234.13,10,400,1,1,233.5,234.17,100,1,1,1,233.45,234.25,15,100,1,1,233.4,234.41,110,500,2,1,233.39,234.43,10,105,1,2,233.31,234.5,110,63,2,4,AAPL,0.0,0.0,0.0,
2024-10-21 12:30:42.852800519+00:00,2024-10-21T12:30:42.852966987Z,10,2,38,A,B,2,233.65,200,130,166468,13385315,233.7,233.91,1200,7,1,1,233.66,233.93,1,400,1,1,233.65,234.0,200,17,1,2,233.58,234.1,505,100,2,1,233.53,234.13,10,400,1,1,233.5,234.17,100,1,1,1,233.45,234.25,15,100,1,1,233.4,234.41,110,500,2,1,233.39,234.43,10,105,1,2,233.31,234.5,110,63,2,4,AAPL,0.0,0.0,0.0,
2024-10-21 12:30:42.911106065+00:00,2024-10-21T12:30:42.911272136Z,10,2,38,C,B,2,233.65,200,130,166071,13385545,233.7,233.91,1200,7,1,1,233.66,233.93,1,400,1,1,233.58,234.0,505,17,2,2,233.53,234.1,10,100,1,1,233.5,234.13,100,400,1,1,233.45,234.17,15,1,1,1,233.4,234.25,110,100,2,1,233.39,234.41,10,500,1,1,233.31,234.43,110,105,2,2,233.3,234.5,100,63,1,4,AAPL,0.0,0.0,0.0,
2024-10-21 12:30:42.911118704+00:00,2024-10-21T12:30:42.911285351Z,10,2,38,A,B,2,233.63,200,130,166647,13385546,233.7,233.91,1200,7,1,1,233.66,233.93,1,400,1,1,233.63,234.0,200,17,1,2,233.58,234.1,505,100,2,1,233.53,234.13,10,400,1,1,233.5,234.17,100,1,1,1,233.45,234.25,15,100,1,1,233.4,234.41,110,500,2,1,233.39,234.43,10,105,1,2,233.31,234.5,110,63,2,4,AAPL,0.0,0.0,0.0,
2024-10-21 12:30:43.077759194+00:00,2024-10-21T12:30:43.077926603Z,10,2,38,A,A,0,233.81,100,130,167409,13386086,233.7,233.81,1200,100,1,1,233.66,233.91,1,7,1,1,233.63,233.93,200,400,1,1,233.58,234.0,505,17,2,2,233.53,234.1,10,100,1,1,233.5,234.13,100,400,1,1,233.45,234.17,15,1,1,1,233.4,234.25,110,100,2,1,233.39,234.41,10,500,1,1,233.31,234.43,110,105,2,2,AAPL,0.0,0.0,0.0,
2024-10-21 12:30:43.077845659+00:00,2024-10-21T12:30:43.078011775Z,10,2,38,A,A,0,233.79,2,130,166116,13386087,233.7,233.79,1200,2,1,1,233.66,233.81,1,100,1,1,233.63,233.91,200,7,1,1,233.58,233.93,505,400,2,1,233.53,234.0,10,17,1,2,233.5,234.1,100,100,1,1,233.45,234.13,15,400,1,1,233.4,234.17,110,1,2,1,233.39,234.25,10,100,1,1,233.31,234.41,110,500,2,1,AAPL,0.0,0.0,0.0,
2024-10-21 12:30:43.077853974+00:00,2024-10-21T12:30:43.078020128Z,10,2,38,A,A,2,233.82,27,130,166154,13386088,233.7,233.79,1200,2,1,1,233.66,233.81,1,100,1,1,233.63,233.82,200,27,1,1,233.58,233.91,505,7,2,1,233.53,233.93,10,400,1,1,233.5,234.0,100,17,1,2,233.45,234.1,15,100,1,1,233.4,234.13,110,400,2,1,233.39,234.17,10,1,1,1,233.31,234.25,110,100,2,1,AAPL,0.0,0.0,0.0,
2024-10-21 12:30:43.077880864+00:00,2024-10-21T12:30:43.078046807Z,10,2,38,C,B,2,233.63,200,130,165943,13386089,233.7,233.79,1200,2,1,1,233.66,233.81,1,100,1,1,233.58,233.82,505,27,2,1,233.53,233.91,10,7,1,1,233.5,233.93,100,400,1,1,233.45,234.0,15,17,1,2,233.4,234.1,110,100,2,1,233.39,234.13,10,400,1,1,233.31,234.17,110,1,2,1,233.3,234.25,100,100,1,1,AAPL,0.0,0.0,0.0,
2024-10-21 12:30:43.078169970+00:00,2024-10-21T12:30:43.078335932Z,10,2,38,C,A,1,233.81,100,130,165962,13386090,233.7,233.79,1200,2,1,1,233.66,233.82,1,27,1,1,233.58,233.91,505,7,2,1,233.53,233.93,10,400,1,1,233.5,234.0,100,17,1,2,233.45,234.1,15,100,1,1,233.4,234.13,110,400,2,1,233.39,234.17,10,1,1,1,233.31,234.25,110,100,2,1,233.3,234.41,100,500,1,1,AAPL,0.0,0.0,0.0,
2024-10-21 12:30:43.081947674+00:00,2024-10-21T12:30:43.082113679Z,10,2,38,C,A,1,233.82,27,130,166005,13386104,233.7,233.79,1200,2,1,1,233.66,233.91,1,7,1,1,233.58,233.93,505,400,2,1,233.53,234.0,10,17,1,2,233.5,234.1,100,100,1,1,233.45,234.13,15,400,1,1,233.4,234.17,110,1,2,1,233.39,234.25,10,100,1,1,233.31,234.41,110,500,2,1,233.3,234.43,100,105,1,2,AAPL,0.0,0.0,0.0,
2024-10-21 12:30:43.081952786+00:00,2024-10-21T12:30:43.082118638Z,10,2,38,C,A,0,233.79,2,130,165852,13386105,233.7,233.91,1200,7,1,1,233.66,233.93,1,400,1,1,233.58,234.0,505,17,2,2,233.53,234.1,10,100,1,1,233.5,234.13,100,400,1,1,233.45,234.17,15,1,1,1,233.4,234.25,110,100,2,1,233.39,234.41,10,500,1,1,233.31,234.43,110,105,2,2,233.3,234.5,100,63,1,4,AAPL,0.0,0.0,0.0,
2024-10-21 12:30:43.145229452+00:00,2024-10-21T12:30:43.145395752Z,10,2,38,A,B,2,233.6,400,130,166300,13386208,233.7,233.91,1200,7,1,1,233.66,233.93,1,400,1,1,233.6,234.0,400,17,1,2,233.58,234.1,505,100,2,1,233.53,234.13,10,400,1,1,233.5,234.17,100,1,1,1,233.45,234.25,15,100,1,1,233.4,234.41,110,500,2,1,233.39,234.43,10,105,1,2,233.31,234.5,110,63,2,4,AAPL,0.0,0.0,0.0,
2024-10-21 12:30:51.064507066+00:00,2024-10-21T12:30:51.064674265Z,10,2,38,A,A,0,233.9,200,130,167199,13392451,233.7,233.9,1200,200,1,1,233.66,233.91,1,7,1,1,233.6,234.0,400,17,1,2,233.58,234.1,505,100,2,1,233.53,234.13,10,400,1,1,233.5,234.17,100,1,1,1,233.45,234.25,15,100,1,1,233.4,234.41,110,500,2,1,233.39,234.43,10,105,1,2,233.31,234.5,110,63,2,4,AAPL,0.0,0.0,0.0,
2024-10-21 12:30:51.126612912+00:00,2024-10-21T12:30:51.126805554Z,10,2,38,C,A,1,233.91,7,130,192642,13392493,233.7,233.9,1200,200,1,1,233.66,234.0,1,17,1,2,233.6,234.1,400,100,1,1,233.58,234.13,505,400,2,1,233.53,234.17,10,1,1,1,233.5,234.25,100,100,1,1,233.45,234.41,15,500,1,1,233.4,234.43,110,105,2,2,233.39,234.5,10,63,1,4,233.31,234.59,110,60,2,1,AAPL,0.0,0.0,0.0,
2024-10-21 12:30:53.132658845+00:00,2024-10-21T12:30:53.132825110Z,10,2,38,A,A,0,233.89,7,130,166265,13394395,233.7,233.89,1200,7,1,1,233.66,233.9,1,200,1,1,233.6,234.0,400,17,1,2,233.58,234.1,505,100,2,1,233.53,234.13,10,400,1,1,233.5,234.17,100,1,1,1,233.45,234.25,15,100,1,1,233.4,234.41,110,500,2,1,233.39,234.43,10,105,1,2,233.31,234.5,110,63,2,4,AAPL,0.0,0.0,0.0,
2024-10-21 12:30:53.158946223+00:00,2024-10-21T12:30:53.159112566Z,10,2,38,C,A,1,233.9,200,130,166343,13394422,233.7,233.89,1200,7,1,1,233.66,234.0,1,17,1,2,233.6,234.1,400,100,1,1,233.58,234.13,505,400,2,1,233.53,234.17,10,1,1,1,233.5,234.25,100,100,1,1,233.45,234.41,15,500,1,1,233.4,234.43,110,105,2,2,233.39,234.5,10,63,1,4,233.31,234.59,110,60,2,1,AAPL,0.0,0.0,0.0,
2024-10-21 12:30:53.158960124+00:00,2024-10-21T12:30:53.159126656Z,10,2,38,A,A,1,233.94,400,130,166532,13394423,233.7,233.89,1200,7,1,1,233.66,233.94,1,400,1,1,233.6,234.0,400,17,1,2,233.58,234.1,505,100,2,1,233.53,234.13,10,400,1,1,233.5,234.17,100,1,1,1,233.45,234.25,15,100,1,1,233.4,234.41,110,500,2,1,233.39,234.43,10,105,1,2,233.31,234.5,110,63,2,4,AAPL,0.0,0.0,0.0,
2024-10-21 12:30:54.724993656+00:00,2024-10-21T12:30:54.725160534Z,10,2,38,A,B,2,233.61,400,130,166878,13395667,233.7,233.89,1200,7,1,1,233.66,233.94,1,400,1,1,233.61,234.0,400,17,1,2,233.58,234.1,505,100,2,1,233.53,234.13,10,400,1,1,233.5,234.17,100,1,1,1,233.45,234.25,15,100,1,1,233.4,234.41,110,500,2,1,233.39,234.43,10,105,1,2,233.31,234.5,110,63,2,4,AAPL,0.0,0.0,0.0,
2024-10-21 12:30:57.249970057+00:00,2024-10-21T12:30:57.250136599Z,10,2,38,A,A,1,233.91,200,130,166542,13398703,233.7,233.89,1200,7,1,1,233.66,233.91,1,200,1,1,233.61,234.0,400,17,1,2,233.58,234.1,505,100,2,1,233.53,234.13,10,400,1,1,233.5,234.17,100,1,1,1,233.45,234.25,15,100,1,1,233.4,234.41,110,500,2,1,233.39,234.43,10,105,1,2,233.31,234.5,110,63,2,4,AAPL,0.0,0.0,0.0,
2024-10-21 12:30:59.735648884+00:00,2024-10-21T12:30:59.735815684Z,10,2,38,A,A,1,233.9,200,130,166800,13401350,233.7,233.89,1200,7,1,1,233.66,233.9,1,200,1,1,233.61,234.0,400,17,1,2,233.58,234.1,505,100,2,1,233.53,234.13,10,400,1,1,233.5,234.17,100,1,1,1,233.45,234.25,15,100,1,1,233.4,234.41,110,500,2,1,233.39,234.43,10,105,1,2,233.31,234.5,110,63,2,4,AAPL,0.0,0.0,0.0,
2024-10-21 12:31:00.041878233+00:00,2024-10-21T12:31:00.042044822Z,10,2,38,A,A,0,233.88,200,130,166589,13402076,233.7,233.88,1200,200,1,1,233.66,233.89,1,7,1,1,233.61,234.0,400,17,1,2,233.58,234.1,505,100,2,1,233.53,234.13,10,400,1,1,233.5,234.17,100,1,1,1,233.45,234.25,15,100,1,1,233.4,234.41,110,500,2,1,233.39,234.43,10,105,1,2,233.31,234.5,110,63,2,4,AAPL,0.0,0.0,0.0,
2024-10-21 12:31:00.098753103+00:00,2024-10-21T12:31:00.098919227Z,10,2,38,C,A,1,233.89,7,130,166124,13402444,233.7,233.88,1200,200,1,1,233.66,234.0,1,17,1,2,233.61,234.1,400,100,1,1,233.58,234.13,505,400,2,1,233.53,234.17,10,1,1,1,233.5,234.25,100,100,1,1,233.45,234.41,15,500,1,1,233.4,234.43,110,105,2,2,233.39,234.5,10,63,1,4,233.31,234.59,110,60,2,1,AAPL,0.0,0.0,0.0,
2024-10-21 12:31:00.156687698+00:00,2024-10-21T12:31:00.156853823Z,10,2,38,C,A,0,233.88,200,130,166125,13402657,233.7,234.0,1200,17,1,2,233.66,234.1,1,100,1,1,233.61,234.13,400,400,1,1,233.58,234.17,505,1,2,1,233.53,234.25,10,100,1,1,233.5,234.41,100,500,1,1,233.45,234.43,15,105,1,2,233.4,234.5,110,63,2,4,233.39,234.59,10,60,1,1,233.31,234.75,110,1,2,1,AAPL,0.0,0.0,0.0,
2024-10-21 12:31:00.156700602+00:00,2024-10-21T12:31:00.156866735Z,10,2,38,A,A,0,233.9,200,130,166133,13402658,233.7,233.9,1200,200,1,1,233.66,234.0,1,17,1,2,233.61,234.1,400,100,1,1,233.58,234.13,505,400,2,1,233.53,234.17,10,1,1,1,233.5,234.25,100,100,1,1,233.45,234.41,15,500,1,1,233.4,234.43,110,105,2,2,233.39,234.5,10,63,1,4,233.31,234.59,110,60,2,1,AAPL,0.0,0.0,0.0,
2024-10-21 12:31:00.172626181+00:00,2024-10-21T12:31:00.172792189Z,10,2,38,C,A,0,233.9,200,130,166008,13402690,233.7,234.0,1200,17,1,2,233.66,234.1,1,100,1,1,233.61,234.13,400,400,1,1,233.58,234.17,505,1,2,1,233.53,234.25,10,100,1,1,233.5,234.41,100,500,1,1,233.45,234.43,15,105,1,2,233.4,234.5,110,63,2,4,233.39,234.59,10,60,1,1,233.31,234.75,110,1,2,1,AAPL,0.0,0.0,0.0,
2024-10-21 12:31:00.172638682+00:00,2024-10-21T12:31:00.172805116Z,10,2,38,A,A,0,233.94,400,130,166434,13402691,233.7,233.94,1200,400,1,1,233.66,234.0,1,17,1,2,233.61,234.1,400,100,1,1,233.58,234.13,505,400,2,1,233.53,234.17,10,1,1,1,233.5,234.25,100,100,1,1,233.45,234.41,15,500,1,1,233.4,234.43,110,105,2,2,233.39,234.5,10,63,1,4,233.31,234.59,110,60,2,1,AAPL,0.0,0.0,0.0,
2024-10-21 12:31:00.400232797+00:00,2024-10-21T12:31:00.400399117Z,10,2,38,A,A,0,233.92,200,130,166320,13403529,233.7,233.92,1200,200,1,1,233.66,234.0,1,17,1,2,233.61,234.1,400,100,1,1,233.58,234.13,505,400,2,1,233.53,234.17,10,1,1,1,233.5,234.25,100,100,1,1,233.45,234.41,15,500,1,1,233.4,234.43,110,105,2,2,233.39,234.5,10,63,1,4,233.31,234.59,110,60,2,1,AAPL,0.0,0.0,0.0,
2024-10-21 12:31:00.880934995+00:00,2024-10-21T12:31:00.881101502Z,10,2,38,C,A,0,233.92,200,130,166507,13404357,233.7,234.0,1200,17,1,2,233.66,234.1,1,100,1,1,233.61,234.13,400,400,1,1,233.58,234.17,505,1,2,1,233.53,234.25,10,100,1,1,233.5,234.41,100,500,1,1,233.45,234.43,15,105,1,2,233.4,234.5,110,63,2,4,233.39,234.59,10,60,1,1,233.31,234.75,110,1,2,1,AAPL,0.0,0.0,0.0,
2024-10-21 12:31:00.880948262+00:00,2024-10-21T12:31:00.881114450Z,10,2,38,A,A,0,233.94,400,130,166188,13404358,233.7,233.94,1200,400,1,1,233.66,234.0,1,17,1,2,233.61,234.1,400,100,1,1,233.58,234.13,505,400,2,1,233.53,234.17,10,1,1,1,233.5,234.25,100,100,1,1,233.45,234.41,15,500,1,1,233.4,234.43,110,105,2,2,233.39,234.5,10,63,1,4,233.31,234.59,110,60,2,1,AAPL,0.0,0.0,0.0,
2024-10-21 12:31:01.118555295+00:00,2024-10-21T12:31:01.118721679Z,10,2,38,A,A,0,233.93,200,130,166384,13404633,233.7,233.93,1200,200,1,1,233.66,234.0,1,17,1,2,233.61,234.1,400,100,1,1,233.58,234.13,505,400,2,1,233.53,234.17,10,1,1,1,233.5,234.25,100,100,1,1,233.45,234.41,15,500,1,1,233.4,234.43,110,105,2,2,233.39,234.5,10,63,1,4,233.31,234.59,110,60,2,1,AAPL,0.0,0.0,0.0,
2024-10-21 12:31:01.146597464+00:00,2024-10-21T12:31:01.146763916Z,10,2,38,A,A,0,233.9,200,130,166452,13404693,233.7,233.9,1200,200,1,1,233.66,234.0,1,17,1,2,233.61,234.1,400,100,1,1,233.58,234.13,505,400,2,1,233.53,234.17,10,1,1,1,233.5,234.25,100,100,1,1,233.45,234.41,15,500,1,1,233.4,234.43,110,105,2,2,233.39,234.5,10,63,1,4,233.31,234.59,110,60,2,1,AAPL,0.0,0.0,0.0,
2024-10-21 12:31:01.698782682+00:00,2024-10-21T12:31:01.698949935Z,10,2,38,A,B,0,233.76,10,130,167253,13405476,233.76,233.9,10,200,1,1,233.7,234.0,1200,17,1,2,233.66,234.1,1,100,1,1,233.61,234.13,400,400,1,1,233.58,234.17,505,1,2,1,233.53,234.25,10,100,1,1,233.5,234.41,100,500,1,1,233.45,234.43,15,105,1,2,233.4,234.5,110,63,2,4,233.39,234.59,10,60,1,1,AAPL,0.0,0.0,0.0,
2024-10-21 12:31:02.104600327+00:00,2024-10-21T12:31:02.104766747Z,10,2,38,A,A,0,233.89,7,130,166420,13405925,233.76,233.89,10,7,1,1,233.7,233.9,1200,200,1,1,233.66,234.0,1,17,1,2,233.61,234.1,400,100,1,1,233.58,234.13,505,400,2,1,233.53,234.17,10,1,1,1,233.5,234.25,100,100,1,1,233.45,234.41,15,500,1,1,233.4,234.43,110,105,2,2,233.39,234.5,10,63,1,4,AAPL,0.0,0.0,0.0,
2024-10-21 12:31:02.286559844+00:00,2024-10-21T12:31:02.286726124Z,10,2,38,C,A,1,233.9,200,130,166280,13406135,233.76,233.89,10,7,1,1,233.7,234.0,1200,17,1,2,233.66,234.1,1,100,1,1,233.61,234.13,400,400,1,1,233.58,234.17,505,1,2,1,233.53,234.25,10,100,1,1,233.5,234.41,100,500,1,1,233.45,234.43,15,105,1,2,233.4,234.5,110,63,2,4,233.39,234.59,10,60,1,1,AAPL,0.0,0.0,0.0,
2024-10-21 12:31:02.286572345+00:00,2024-10-21T12:31:02.286738616Z,10,2,38,A,A,1,233.92,200,130,166271,13406136,233.76,233.89,10,7,1,1,233.7,233.92,1200,200,1,1,233.66,234.0,1,17,1,2,233.61,234.1,400,100,1,1,233.58,234.13,505,400,2,1,233.53,234.17,10,1,1,1,233.5,234.25,100,100,1,1,233.45,234.41,15,500,1,1,233.4,234.43,110,105,2,2,233.39,234.5,10,63,1,4,AAPL,0.0,0.0,0.0,
2024-10-21 12:31:02.297066314+00:00,2024-10-21T12:31:02.297232093Z,10,2,38,C,A,1,233.92,200,130,165779,13406143,233.76,233.89,10,7,1,1,233.7,234.0,1200,17,1,2,233.66,234.1,1,100,1,1,233.61,234.13,400,400,1,1,233.58,234.17,505,1,2,1,233.53,234.25,10,100,1,1,233.5,234.41,100,500,1,1,233.45,234.43,15,105,1,2,233.4,234.5,110,63,2,4,233.39,234.59,10,60,1,1,AAPL,0.0,0.0,0.0,
2024-10-21 12:31:02.297079450+00:00,2024-10-21T12:31:02.297245858Z,10,2,38,A,A,1,233.94,400,130,166408,13406144,233.76,233.89,10,7,1,1,233.7,233.94,1200,400,1,1,233.66,234.0,1,17,1,2,233.61,234.1,400,100,1,1,233.58,234.13,505,400,2,1,233.53,234.17,10,1,1,1,233.5,234.25,100,100,1,1,233.45,234.41,15,500,1,1,233.4,234.43,110,105,2,2,233.39,234.5,10,63,1,4,AAPL,0.0,0.0,0.0,
2024-10-21 12:31:02.320854035+00:00,2024-10-21T12:31:02.321020744Z,10,2,38,A,B,3,233.65,200,130,166709,13406162,233.76,233.89,10,7,1,1,233.7,233.94,1200,400,1,1,233.66,234.0,1,17,1,2,233.65,234.1,200,100,1,1,233.58,234.13,505,400,2,1,233.53,234.17,10,1,1,1,233.5,234.25,100,100,1,1,233.45,234.41,15,500,1,1,233.4,234.43,110,105,2,2,233.39,234.5,10,63,1,4,AAPL,0.0,0.0,0.0,
2024-10-21 12:31:03.261814629+00:00,2024-10-21T12:31:03.262141913Z,10,2,38,A,B,3,233.65,200,130,327284,13406966,233.76,233.89,10,7,1,1,233.7,233.94,1200,400,1,1,233.66,234.0,1,17,1,2,233.65,234.1,400,100,2,1,233.58,234.13,505,400,2,1,233.53,234.17,10,1,1,1,233.5,234.25,100,100,1,1,233.45,234.41,15,500,1,1,233.4,234.43,110,105,2,2,233.39,234.5,10,63,1,4,AAPL,0.0,200.0,0.0,
2024-10-21 12:31:03.312554281+00:00,2024-10-21T12:31:03.314769469Z,10,2,38,A,B,2,233.68,200,130,2215188,13407030,233.76,233.89,10,7,1,1,233.7,233.94,1200,400,1,1,233.68,234.0,200,17,1,2,233.66,234.1,1,100,1,1,233.58,234.13,505,400,2,1,233.53,234.17,10,1,1,1,233.5,234.25,100,100,1,1,233.45,234.41,15,500,1,1,233.4,234.43,110,105,2,2,233.39,234.5,10,63,1,4,AAPL,0.0,0.0,0.0,
2024-10-21 12:31:05.971386477+00:00,2024-10-21T12:31:05.971552774Z,10,2,38,A,A,1,233.93,400,130,166297,13409309,233.76,233.89,10,7,1,1,233.7,233.93,1200,400,1,1,233.68,234.0,200,17,1,2,233.66,234.1,1,100,1,1,233.58,234.13,505,400,2,1,233.53,234.17,10,1,1,1,233.5,234.25,100,100,1,1,233.45,234.41,15,500,1,1,233.4,234.43,110,105,2,2,233.39,234.5,10,63,1,4,AAPL,0.0,0.0,0.0,
2024-10-21 12:31:10.467431005+00:00,2024-10-21T12:31:10.467597154Z,10,2,38,A,A,0,233.81,55,130,166149,13412654,233.76,233.81,10,55,1,1,233.7,233.89,1200,7,1,1,233.68,233.93,200,400,1,1,233.66,234.0,1,17,1,2,233.58,234.1,505,100,2,1,233.53,234.13,10,400,1,1,233.5,234.17,100,1,1,1,233.45,234.25,15,100,1,1,233.4,234.41,110,500,2,1,233.39,234.43,10,105,1,2,AAPL,0.0,0.0,0.0,
2024-10-21 12:31:10.467497398+00:00,2024-10-21T12:31:10.467664679Z,10,2,38,T,A,0,233.76,10,130,167281,13412655,233.76,233.81,10,55,1,1,233.7,233.89,1200,7,1,1,233.68,233.93,200,400,1,1,233.66,234.0,1,17,1,2,233.58,234.1,505,100,2,1,233.53,234.13,10,400,1,1,233.5,234.17,100,1,1,1,233.45,234.25,15,100,1,1,233.4,234.41,110,500,2,1,233.39,234.43,10,105,1,2,AAPL,0.0,0.0,0.0,
2024-10-21 12:31:10.467497398+00:00,2024-10-21T12:31:10.467664679Z,10,2,38,C,B,0,233.76,10,130,167281,13412655,233.7,233.81,1200,55,1,1,233.68,233.89,200,7,1,1,233.66,233.93,1,400,1,1,233.58,234.0,505,17,2,2,233.53,234.1,10,100,1,1,233.5,234.13,100,400,1,1,233.45,234.17,15,1,1,1,233.4,234.25,110,100,2,1,233.39,234.41,10,500,1,1,233.31,234.43,110,105,2,2,AAPL,0.0,0.0,0.0,
2024-10-21 12:31:10.467519660+00:00,2024-10-21T12:31:10.467686549Z,10,2,38,A,A,0,233.8,100,130,166889,13412656,233.7,233.8,1200,100,1,1,233.68,233.81,200,55,1,1,233.66,233.89,1,7,1,1,233.58,233.93,505,400,2,1,233.53,234.0,10,17,1,2,233.5,234.1,100,100,1,1,233.45,234.13,15,400,1,1,233.4,234.17,110,1,2,1,233.39,234.25,10,100,1,1,233.31,234.41,110,500,2,1,AAPL,0.0,0.0,0.0,
2024-10-21 12:31:10.467521772+00:00,2024-10-21T12:31:10.467688659Z,10,2,38,A,A,0,233.79,7,130,166887,13412657,233.7,233.79,1200,7,1,1,233.68,233.8,200,100,1,1,233.66,233.81,1,55,1,1,233.58,233.89,505,7,2,1,233.53,233.93,10,400,1,1,233.5,234.0,100,17,1,2,233.45,234.1,15,100,1,1,233.4,234.13,110,400,2,1,233.39,234.17,10,1,1,1,233.31,234.25,110,100,2,1,AAPL,0.0,0.0,0.0,
2024-10-21 12:31:10.467536010+00:00,2024-10-21T12:31:10.467702771Z,10,2,38,A,A,1,233.8,77,130,166761,13412661,233.7,233.79,1200,7,1,1,233.68,233.8,200,177,1,2,233.66,233.81,1,55,1,1,233.58,233.89,505,7,2,1,233.53,233.93,10,400,1,1,233.5,234.0,100,17,1,2,233.45,234.1,15,100,1,1,233.4,234.13,110,400,2,1,233.39,234.17,10,1,1,1,233.31,234.25,110,100,2,1,AAPL,0.0,-77.0,0.0,
2024-10-21 12:31:10.467551632+00:00,2024-10-21T12:31:10.467720432Z,10,2,38,C,A,1,233.8,100,130,168800,13412662,233.7,233.79,1200,7,1,1,233.68,233.8,200,77,1,1,233.66,233.81,1,55,1,1,233.58,233.89,505,7,2,1,233.53,233.93,10,400,1,1,233.5,234.0,100,17,1,2,233.45,234.1,15,100,1,1,233.4,234.13,110,400,2,1,233.39,234.17,10,1,1,1,233.31,234.25,110,100,2,1,AAPL,0.0,100.0,0.0,
