ts_event,ts_recv,rtype,publisher_id,instrument_id,action,side,depth,price,size,flags,ts_in_delta,sequence,bid_px_00,ask_px_00,bid_sz_00,ask_sz_00,bid_ct_00,ask_ct_00,bid_px_01,ask_px_01,bid_sz_01,ask_sz_01,bid_ct_01,ask_ct_01,bid_px_02,ask_px_02,bid_sz_02,ask_sz_02,bid_ct_02,ask_ct_02,bid_px_03,ask_px_03,bid_sz_03,ask_sz_03,bid_ct_03,ask_ct_03,bid_px_04,ask_px_04,bid_sz_04,ask_sz_04,bid_ct_04,ask_ct_04,bid_px_05,ask_px_05,bid_sz_05,ask_sz_05,bid_ct_05,ask_ct_05,bid_px_06,ask_px_06,bid_sz_06,ask_sz_06,bid_ct_06,ask_ct_06,bid_px_07,ask_px_07,bid_sz_07,ask_sz_07,bid_ct_07,ask_ct_07,bid_px_08,ask_px_08,bid_sz_08,ask_sz_08,bid_ct_08,ask_ct_08,bid_px_09,ask_px_09,bid_sz_09,ask_sz_09,bid_ct_09,ask_ct_09,symbol,best_level_ofi,multi_level_ofi,integrated_ofi_1s,cross_asset_ofi
2024-10-21 12:02:48.883865862+00:00,2024-10-21T12:02:48.884031773Z,10,2,38,C,B,2,233.51,400,130,165911,11809083,233.58,233.78,500,150,1,2,233.53,233.79,10,400,1,2,233.45,233.8,15,25,1,1,233.43,233.86,29,29,1,1,233.4,233.94,110,200,2,1,233.39,233.98,10,44,1,3,233.31,234.0,110,154,2,7,233.3,234.13,100,400,1,1,233.25,234.17,55,1,2,1,233.24,234.41,1,600,1,2,AAPL,0.0,0.0,0.0,
2024-10-21 12:02:48.883880917+00:00,2024-10-21T12:02:48.884046853Z,10,2,38,A,B,2,233.48,200,130,165936,11809084,233.58,233.78,500,150,1,2,233.53,233.79,10,400,1,2,233.48,233.8,200,25,1,1,233.45,233.86,15,29,1,1,233.43,233.94,29,200,1,1,233.4,233.98,110,44,2,3,233.39,234.0,10,154,1,7,233.31,234.13,110,400,2,1,233.3,234.17,100,1,1,1,233.25,234.41,55,600,2,2,AAPL,0.0,0.0,0.0,
2024-10-21 12:02:49.759332649+00:00,2024-10-21T12:02:49.759499338Z,10,2,38,A,B,2,233.51,200,130,166689,11810239,233.58,233.78,500,150,1,2,233.53,233.79,10,400,1,2,233.51,233.8,200,25,1,1,233.45,233.86,15,29,1,1,233.43,233.94,29,200,1,1,233.4,233.98,110,44,2,3,233.39,234.0,10,154,1,7,233.31,234.13,110,400,2,1,233.3,234.17,100,1,1,1,233.25,234.41,55,600,2,2,AAPL,0.0,0.0,0.0,
2024-10-21 12:02:54.518612296+00:00,2024-10-21T12:02:54.518778131Z,10,2,38,C,A,1,233.79,200,130,165835,11814397,233.58,233.78,500,150,1,2,233.53,233.79,10,200,1,1,233.51,233.8,200,25,1,1,233.45,233.86,15,29,1,1,233.43,233.94,29,200,1,1,233.4,233.98,110,44,2,3,233.39,234.0,10,154,1,7,233.31,234.13,110,400,2,1,233.3,234.17,100,1,1,1,233.25,234.41,55,600,2,2,AAPL,0.0,200.0,0.0,
2024-10-21 12:02:54.518624596+00:00,2024-10-21T12:02:54.518790915Z,10,2,38,A,A,0,233.78,400,130,166319,11814398,233.58,233.78,500,550,1,3,233.53,233.8,10,25,1,1,233.51,233.86,200,29,1,1,233.45,233.94,15,200,1,1,233.43,233.98,29,44,1,3,233.4,234.0,110,154,2,7,233.39,234.13,10,400,1,1,233.31,234.17,110,1,2,1,233.3,234.41,100,600,1,2,233.25,234.43,55,5,2,1,AAPL,-400.0,-400.0,-400.0,
2024-10-21 12:02:54.523940080+00:00,2024-10-21T12:02:54.524106300Z,10,2,38,A,A,2,233.85,26,130,166220,11814473,233.58,233.78,500,550,1,3,233.53,233.8,10,25,1,1,233.51,233.85,200,26,1,1,233.45,233.86,15,29,1,1,233.43,233.94,29,200,1,1,233.4,233.98,110,44,2,3,233.39,234.0,10,154,1,7,233.31,234.13,110,400,2,1,233.3,234.17,100,1,1,1,233.25,234.41,55,600,2,2,AAPL,0.0,0.0,-400.0,
2024-10-21 12:02:54.524017462+00:00,2024-10-21T12:02:54.524183296Z,10,2,38,C,A,3,233.86,29,130,165834,11814475,233.58,233.78,500,550,1,3,233.53,233.8,10,25,1,1,233.51,233.85,200,26,1,1,233.45,233.94,15,200,1,1,233.43,233.98,29,44,1,3,233.4,234.0,110,154,2,7,233.39,234.13,10,400,1,1,233.31,234.17,110,1,2,1,233.3,234.41,100,600,1,2,233.25,234.43,55,5,2,1,AAPL,0.0,0.0,-400.0,
2024-10-21 12:02:56.706628033+00:00,2024-10-21T12:02:56.706794368Z,10,2,38,C,B,2,233.51,200,130,166335,11816088,233.58,233.78,500,550,1,3,233.53,233.8,10,25,1,1,233.45,233.85,15,26,1,1,233.43,233.94,29,200,1,1,233.4,233.98,110,44,2,3,233.39,234.0,10,154,1,7,233.31,234.13,110,400,2,1,233.3,234.17,100,1,1,1,233.25,234.41,55,600,2,2,233.24,234.43,1,5,1,1,AAPL,0.0,0.0,0.0,
2024-10-21 12:02:56.706639645+00:00,2024-10-21T12:02:56.706805799Z,10,2,38,A,B,2,233.49,200,130,166154,11816089,233.58,233.78,500,550,1,3,233.53,233.8,10,25,1,1,233.49,233.85,200,26,1,1,233.45,233.94,15,200,1,1,233.43,233.98,29,44,1,3,233.4,234.0,110,154,2,7,233.39,234.13,10,400,1,1,233.31,234.17,110,1,2,1,233.3,234.41,100,600,1,2,233.25,234.43,55,5,2,1,AAPL,0.0,0.0,0.0,
2024-10-21 12:02:56.761416724+00:00,2024-10-21T12:02:56.761583278Z,10,2,38,A,A,0,233.77,200,130,166554,11816211,233.58,233.77,500,200,1,1,233.53,233.78,10,150,1,2,233.49,233.8,200,25,1,1,233.45,233.85,15,26,1,1,233.43,233.94,29,200,1,1,233.4,233.98,110,44,2,3,233.39,234.0,10,154,1,7,233.31,234.13,110,400,2,1,233.3,234.17,100,1,1,1,233.25,234.41,55,600,2,2,AAPL,0.0,0.0,0.0,
2024-10-21 12:02:56.763029737+00:00,2024-10-21T12:02:56.763195832Z,10,2,38,A,B,2,233.49,200,130,166095,11816232,233.58,233.77,500,200,1,1,233.53,233.78,10,150,1,2,233.49,233.8,400,25,2,1,233.45,233.85,15,26,1,1,233.43,233.94,29,200,1,1,233.4,233.98,110,44,2,3,233.39,234.0,10,154,1,7,233.31,234.13,110,400,2,1,233.3,234.17,100,1,1,1,233.25,234.41,55,600,2,2,AAPL,0.0,200.0,0.0,
2024-10-21 12:02:56.828592562+00:00,2024-10-21T12:02:56.828759239Z,10,2,38,A,A,3,233.84,29,130,166677,11816538,233.58,233.77,500,200,1,1,233.53,233.78,10,150,1,2,233.49,233.8,400,25,2,1,233.45,233.84,15,29,1,1,233.43,233.85,29,26,1,1,233.4,233.94,110,200,2,1,233.39,233.98,10,44,1,3,233.31,234.0,110,154,2,7,233.3,234.13,100,400,1,1,233.25,234.17,55,1,2,1,AAPL,0.0,0.0,0.0,
2024-10-21 12:02:56.828630121+00:00,2024-10-21T12:02:56.828796257Z,10,2,38,C,A,4,233.85,26,130,166136,11816539,233.58,233.77,500,200,1,1,233.53,233.78,10,150,1,2,233.49,233.8,400,25,2,1,233.45,233.84,15,29,1,1,233.43,233.94,29,200,1,1,233.4,233.98,110,44,2,3,233.39,234.0,10,154,1,7,233.31,234.13,110,400,2,1,233.3,234.17,100,1,1,1,233.25,234.41,55,600,2,2,AAPL,0.0,0.0,0.0,
2024-10-21 12:02:58.875085988+00:00,2024-10-21T12:02:58.875252013Z,10,2,38,C,B,2,233.49,200,130,166025,11818220,233.58,233.77,500,200,1,1,233.53,233.78,10,150,1,2,233.49,233.8,200,25,1,1,233.45,233.84,15,29,1,1,233.43,233.94,29,200,1,1,233.4,233.98,110,44,2,3,233.39,234.0,10,154,1,7,233.31,234.13,110,400,2,1,233.3,234.17,100,1,1,1,233.25,234.41,55,600,2,2,AAPL,0.0,-200.0,0.0,
2024-10-21 12:02:58.875097976+00:00,2024-10-21T12:02:58.875264160Z,10,2,38,A,B,2,233.5,400,130,166184,11818221,233.58,233.77,500,200,1,1,233.53,233.78,10,150,1,2,233.5,233.8,400,25,1,1,233.45,233.84,15,29,1,1,233.43,233.94,29,200,1,1,233.4,233.98,110,44,2,3,233.39,234.0,10,154,1,7,233.31,234.13,110,400,2,1,233.3,234.17,100,1,1,1,233.25,234.41,55,600,2,2,AAPL,0.0,0.0,0.0,
2024-10-21 12:02:59.629692844+00:00,2024-10-21T12:02:59.629858436Z,10,2,38,C,B,2,233.5,400,130,165592,11818945,233.58,233.77,500,200,1,1,233.53,233.78,10,150,1,2,233.45,233.8,15,25,1,1,233.43,233.84,29,29,1,1,233.4,233.94,110,200,2,1,233.39,233.98,10,44,1,3,233.31,234.0,110,154,2,7,233.3,234.13,100,400,1,1,233.25,234.17,55,1,2,1,233.24,234.41,1,600,1,2,AAPL,0.0,0.0,0.0,
2024-10-21 12:02:59.629704420+00:00,2024-10-21T12:02:59.629870364Z,10,2,38,A,B,2,233.49,400,130,165944,11818946,233.58,233.77,500,200,1,1,233.53,233.78,10,150,1,2,233.49,233.8,400,25,1,1,233.45,233.84,15,29,1,1,233.43,233.94,29,200,1,1,233.4,233.98,110,44,2,3,233.39,234.0,10,154,1,7,233.31,234.13,110,400,2,1,233.3,234.17,100,1,1,1,233.25,234.41,55,600,2,2,AAPL,0.0,0.0,0.0,
2024-10-21 12:03:04.465116162+00:00,2024-10-21T12:03:04.465282370Z,10,2,38,A,B,2,233.5,400,130,166208,11824666,233.58,233.77,500,200,1,1,233.53,233.78,10,150,1,2,233.5,233.8,400,25,1,1,233.45,233.84,15,29,1,1,233.43,233.94,29,200,1,1,233.4,233.98,110,44,2,3,233.39,234.0,10,154,1,7,233.31,234.13,110,400,2,1,233.3,234.17,100,1,1,1,233.25,234.41,55,600,2,2,AAPL,0.0,0.0,0.0,
2024-10-21 12:03:23.013257512+00:00,2024-10-21T12:03:23.013424282Z,10,2,38,C,B,2,233.5,400,130,166770,11850697,233.58,233.77,500,200,1,1,233.53,233.78,10,150,1,2,233.45,233.8,15,25,1,1,233.43,233.84,29,29,1,1,233.4,233.94,110,200,2,1,233.39,233.98,10,44,1,3,233.31,234.0,110,154,2,7,233.3,234.13,100,400,1,1,233.25,234.17,55,1,2,1,233.24,234.41,1,600,1,2,AAPL,0.0,0.0,0.0,
2024-10-21 12:03:23.013270046+00:00,2024-10-21T12:03:23.013436299Z,10,2,38,A,B,2,233.48,400,130,166253,11850699,233.58,233.77,500,200,1,1,233.53,233.78,10,150,1,2,233.48,233.8,400,25,1,1,233.45,233.84,15,29,1,1,233.43,233.94,29,200,1,1,233.4,233.98,110,44,2,3,233.39,234.0,10,154,1,7,233.31,234.13,110,400,2,1,233.3,234.17,100,1,1,1,233.25,234.41,55,600,2,2,AAPL,0.0,0.0,0.0,
2024-10-21 12:03:36.462240600+00:00,2024-10-21T12:03:36.462407761Z,10,2,38,A,A,0,233.76,200,130,167161,11869933,233.58,233.76,500,200,1,1,233.53,233.78,10,150,1,2,233.48,233.8,400,25,1,1,233.45,233.84,15,29,1,1,233.43,233.94,29,200,1,1,233.4,233.98,110,44,2,3,233.39,234.0,10,154,1,7,233.31,234.13,110,400,2,1,233.3,234.17,100,1,1,1,233.25,234.41,55,600,2,2,AAPL,0.0,0.0,0.0,
2024-10-21 12:03:36.477257436+00:00,2024-10-21T12:03:36.477423785Z,10,2,38,A,B,5,233.4,28,130,166349,11870139,233.58,233.76,500,200,1,1,233.53,233.78,10,150,1,2,233.48,233.8,400,25,1,1,233.45,233.84,15,29,1,1,233.43,233.94,29,200,1,1,233.4,233.98,138,44,3,3,233.39,234.0,10,154,1,7,233.31,234.13,110,400,2,1,233.3,234.17,100,1,1,1,233.25,234.41,55,600,2,2,AAPL,0.0,0.0,0.0,
2024-10-21 12:03:36.477483536+00:00,2024-10-21T12:03:36.477651445Z,10,2,38,C,B,4,233.43,29,130,167909,11870145,233.58,233.76,500,200,1,1,233.53,233.78,10,150,1,2,233.48,233.8,400,25,1,1,233.45,233.84,15,29,1,1,233.4,233.94,138,200,3,1,233.39,233.98,10,44,1,3,233.31,234.0,110,154,2,7,233.3,234.13,100,400,1,1,233.25,234.17,55,1,2,1,233.24,234.41,1,600,1,2,AAPL,0.0,0.0,0.0,
2024-10-21 12:03:36.477526397+00:00,2024-10-21T12:03:36.477692453Z,10,2,38,C,A,3,233.84,29,130,166056,11870147,233.58,233.76,500,200,1,1,233.53,233.78,10,150,1,2,233.48,233.8,400,25,1,1,233.45,233.94,15,200,1,1,233.4,233.98,138,44,3,3,233.39,234.0,10,154,1,7,233.31,234.13,110,400,2,1,233.3,234.17,100,1,1,1,233.25,234.41,55,600,2,2,233.24,234.43,1,5,1,1,AAPL,0.0,0.0,0.0,
2024-10-21 12:03:36.477570977+00:00,2024-10-21T12:03:36.477737613Z,10,2,38,A,A,3,233.83,27,130,166636,11870149,233.58,233.76,500,200,1,1,233.53,233.78,10,150,1,2,233.48,233.8,400,25,1,1,233.45,233.83,15,27,1,1,233.4,233.94,138,200,3,1,233.39,233.98,10,44,1,3,233.31,234.0,110,154,2,7,233.3,234.13,100,400,1,1,233.25,234.17,55,1,2,1,233.24,234.41,1,600,1,2,AAPL,0.0,0.0,0.0,
2024-10-21 12:03:37.922916443+00:00,2024-10-21T12:03:37.923082663Z,10,2,38,C,A,3,233.83,27,130,166220,11873649,233.58,233.76,500,200,1,1,233.53,233.78,10,150,1,2,233.48,233.8,400,25,1,1,233.45,233.94,15,200,1,1,233.4,233.98,138,44,3,3,233.39,234.0,10,154,1,7,233.31,234.13,110,400,2,1,233.3,234.17,100,1,1,1,233.25,234.41,55,600,2,2,233.24,234.43,1,5,1,1,AAPL,0.0,0.0,0.0,
2024-10-21 12:03:37.922990125+00:00,2024-10-21T12:03:37.923156406Z,10,2,38,A,A,3,233.82,27,130,166281,11873650,233.58,233.76,500,200,1,1,233.53,233.78,10,150,1,2,233.48,233.8,400,25,1,1,233.45,233.82,15,27,1,1,233.4,233.94,138,200,3,1,233.39,233.98,10,44,1,3,233.31,234.0,110,154,2,7,233.3,234.13,100,400,1,1,233.25,234.17,55,1,2,1,233.24,234.41,1,600,1,2,AAPL,0.0,0.0,0.0,
2024-10-21 12:03:38.391113474+00:00,2024-10-21T12:03:38.391279949Z,10,2,38,A,B,0,233.66,1,130,166475,11873925,233.66,233.76,1,200,1,1,233.58,233.78,500,150,1,2,233.53,233.8,10,25,1,1,233.48,233.82,400,27,1,1,233.45,233.94,15,200,1,1,233.4,233.98,138,44,3,3,233.39,234.0,10,154,1,7,233.31,234.13,110,400,2,1,233.3,234.17,100,1,1,1,233.25,234.41,55,600,2,2,AAPL,0.0,0.0,0.0,
2024-10-21 12:03:38.520085682+00:00,2024-10-21T12:03:38.520252527Z,10,2,38,A,B,5,233.41,27,130,166845,11874245,233.66,233.76,1,200,1,1,233.58,233.78,500,150,1,2,233.53,233.8,10,25,1,1,233.48,233.82,400,27,1,1,233.45,233.94,15,200,1,1,233.41,233.98,27,44,1,3,233.4,234.0,138,154,3,7,233.39,234.13,10,400,1,1,233.31,234.17,110,1,2,1,233.3,234.41,100,600,1,2,AAPL,0.0,0.0,0.0,
2024-10-21 12:03:38.520115737+00:00,2024-10-21T12:03:38.520281859Z,10,2,38,C,B,6,233.4,28,130,166122,11874246,233.66,233.76,1,200,1,1,233.58,233.78,500,150,1,2,233.53,233.8,10,25,1,1,233.48,233.82,400,27,1,1,233.45,233.94,15,200,1,1,233.41,233.98,27,44,1,3,233.4,234.0,110,154,2,7,233.39,234.13,10,400,1,1,233.31,234.17,110,1,2,1,233.3,234.41,100,600,1,2,AAPL,0.0,0.0,0.0,
2024-10-21 12:03:55.424131689+00:00,2024-10-21T12:03:55.424297621Z,10,2,38,C,B,5,233.41,27,130,165932,11897535,233.66,233.76,1,200,1,1,233.58,233.78,500,150,1,2,233.53,233.8,10,25,1,1,233.48,233.82,400,27,1,1,233.45,233.94,15,200,1,1,233.4,233.98,110,44,2,3,233.39,234.0,10,154,1,7,233.31,234.13,110,400,2,1,233.3,234.17,100,1,1,1,233.25,234.41,55,600,2,2,AAPL,0.0,0.0,0.0,
2024-10-21 12:03:55.424188038+00:00,2024-10-21T12:03:55.424354377Z,10,2,38,A,B,5,233.42,30,130,166339,11897536,233.66,233.76,1,200,1,1,233.58,233.78,500,150,1,2,233.53,233.8,10,25,1,1,233.48,233.82,400,27,1,1,233.45,233.94,15,200,1,1,233.42,233.98,30,44,1,3,233.4,234.0,110,154,2,7,233.39,234.13,10,400,1,1,233.31,234.17,110,1,2,1,233.3,234.41,100,600,1,2,AAPL,0.0,0.0,0.0,
2024-10-21 12:03:55.618218602+00:00,2024-10-21T12:03:55.618384707Z,10,2,38,C,A,0,233.76,200,130,166105,11897697,233.66,233.78,1,150,1,2,233.58,233.8,500,25,1,1,233.53,233.82,10,27,1,1,233.48,233.94,400,200,1,1,233.45,233.98,15,44,1,3,233.42,234.0,30,154,1,7,233.4,234.13,110,400,2,1,233.39,234.17,10,1,1,1,233.31,234.41,110,600,2,2,233.3,234.43,100,5,1,1,AAPL,0.0,0.0,0.0,
2024-10-21 12:03:55.618231402+00:00,2024-10-21T12:03:55.618397628Z,10,2,38,A,A,0,233.78,200,130,166226,11897698,233.66,233.78,1,350,1,3,233.58,233.8,500,25,1,1,233.53,233.82,10,27,1,1,233.48,233.94,400,200,1,1,233.45,233.98,15,44,1,3,233.42,234.0,30,154,1,7,233.4,234.13,110,400,2,1,233.39,234.17,10,1,1,1,233.31,234.41,110,600,2,2,233.3,234.43,100,5,1,1,AAPL,-200.0,-200.0,-200.0,
2024-10-21 12:03:55.674377683+00:00,2024-10-21T12:03:55.674543945Z,10,2,38,A,B,3,233.49,400,130,166262,11897798,233.66,233.78,1,350,1,3,233.58,233.8,500,25,1,1,233.53,233.82,10,27,1,1,233.49,233.94,400,200,1,1,233.45,233.98,15,44,1,3,233.42,234.0,30,154,1,7,233.4,234.13,110,400,2,1,233.39,234.17,10,1,1,1,233.31,234.41,110,600,2,2,233.3,234.43,100,5,1,1,AAPL,0.0,0.0,-200.0,
2024-10-21 12:03:55.688445687+00:00,2024-10-21T12:03:55.688611614Z,10,2,38,C,A,2,233.82,27,130,165927,11897840,233.66,233.78,1,350,1,3,233.58,233.8,500,25,1,1,233.53,233.94,10,200,1,1,233.49,233.98,400,44,1,3,233.45,234.0,15,154,1,7,233.42,234.13,30,400,1,1,233.4,234.17,110,1,2,1,233.39,234.41,10,600,1,2,233.31,234.43,110,5,2,1,233.3,234.5,100,63,1,4,AAPL,0.0,0.0,-200.0,
2024-10-21 12:03:55.688489469+00:00,2024-10-21T12:03:55.688655741Z,10,2,38,A,A,2,233.85,27,130,166272,11897841,233.66,233.78,1,350,1,3,233.58,233.8,500,25,1,1,233.53,233.85,10,27,1,1,233.49,233.94,400,200,1,1,233.45,233.98,15,44,1,3,233.42,234.0,30,154,1,7,233.4,234.13,110,400,2,1,233.39,234.17,10,1,1,1,233.31,234.41,110,600,2,2,233.3,234.43,100,5,1,1,AAPL,0.0,0.0,-200.0,
2024-10-21 12:03:55.728447009+00:00,2024-10-21T12:03:55.728613443Z,10,2,38,A,A,0,233.77,200,130,166434,11897883,233.66,233.77,1,200,1,1,233.58,233.78,500,150,1,2,233.53,233.8,10,25,1,1,233.49,233.85,400,27,1,1,233.45,233.94,15,200,1,1,233.42,233.98,30,44,1,3,233.4,234.0,110,154,2,7,233.39,234.13,10,400,1,1,233.31,234.17,110,1,2,1,233.3,234.41,100,600,1,2,AAPL,0.0,0.0,-200.0,
2024-10-21 12:03:56.332225034+00:00,2024-10-21T12:03:56.332391241Z,10,2,38,C,B,5,233.42,30,130,166207,11898284,233.66,233.77,1,200,1,1,233.58,233.78,500,150,1,2,233.53,233.8,10,25,1,1,233.49,233.85,400,27,1,1,233.45,233.94,15,200,1,1,233.4,233.98,110,44,2,3,233.39,234.0,10,154,1,7,233.31,234.13,110,400,2,1,233.3,234.17,100,1,1,1,233.25,234.41,55,600,2,2,AAPL,0.0,0.0,-200.0,
2024-10-21 12:03:56.332253646+00:00,2024-10-21T12:03:56.332419452Z,10,2,38,C,A,3,233.85,27,130,165806,11898285,233.66,233.77,1,200,1,1,233.58,233.78,500,150,1,2,233.53,233.8,10,25,1,1,233.49,233.94,400,200,1,1,233.45,233.98,15,44,1,3,233.4,234.0,110,154,2,7,233.39,234.13,10,400,1,1,233.31,234.17,110,1,2,1,233.3,234.41,100,600,1,2,233.25,234.43,55,5,2,1,AAPL,0.0,0.0,-200.0,
2024-10-21 12:03:56.332311467+00:00,2024-10-21T12:03:56.332477635Z,10,2,38,A,A,3,233.84,27,130,166168,11898286,233.66,233.77,1,200,1,1,233.58,233.78,500,150,1,2,233.53,233.8,10,25,1,1,233.49,233.84,400,27,1,1,233.45,233.94,15,200,1,1,233.4,233.98,110,44,2,3,233.39,234.0,10,154,1,7,233.31,234.13,110,400,2,1,233.3,234.17,100,1,1,1,233.25,234.41,55,600,2,2,AAPL,0.0,0.0,-200.0,
2024-10-21 12:03:56.332342495+00:00,2024-10-21T12:03:56.332508686Z,10,2,38,A,B,4,233.47,30,130,166191,11898287,233.66,233.77,1,200,1,1,233.58,233.78,500,150,1,2,233.53,233.8,10,25,1,1,233.49,233.84,400,27,1,1,233.47,233.94,30,200,1,1,233.45,233.98,15,44,1,3,233.4,234.0,110,154,2,7,233.39,234.13,10,400,1,1,233.31,234.17,110,1,2,1,233.3,234.41,100,600,1,2,AAPL,0.0,0.0,-200.0,
2024-10-21 12:03:56.388992803+00:00,2024-10-21T12:03:56.389159167Z,10,2,38,A,B,2,233.57,200,130,166364,11898316,233.66,233.77,1,200,1,1,233.58,233.78,500,150,1,2,233.57,233.8,200,25,1,1,233.53,233.84,10,27,1,1,233.47,233.94,30,200,1,1,233.45,233.98,15,44,1,3,233.4,234.0,110,154,2,7,233.39,234.13,10,400,1,1,233.31,234.17,110,1,2,1,233.3,234.41,100,600,1,2,AAPL,0.0,0.0,-200.0,
2024-10-21 12:03:56.896105724+00:00,2024-10-21T12:03:56.896271800Z,10,2,38,C,B,4,233.47,30,130,166076,11898637,233.66,233.77,1,200,1,1,233.58,233.78,500,150,1,2,233.57,233.8,200,25,1,1,233.53,233.84,10,27,1,1,233.45,233.94,15,200,1,1,233.4,233.98,110,44,2,3,233.39,234.0,10,154,1,7,233.31,234.13,110,400,2,1,233.3,234.17,100,1,1,1,233.25,234.41,55,600,2,2,AAPL,0.0,0.0,0.0,
2024-10-21 12:03:56.896208906+00:00,2024-10-21T12:03:56.896375276Z,10,2,38,A,B,4,233.52,28,130,166370,11898638,233.66,233.77,1,200,1,1,233.58,233.78,500,150,1,2,233.57,233.8,200,25,1,1,233.53,233.84,10,27,1,1,233.52,233.94,28,200,1,1,233.45,233.98,15,44,1,3,233.4,234.0,110,154,2,7,233.39,234.13,10,400,1,1,233.31,234.17,110,1,2,1,233.3,234.41,100,600,1,2,AAPL,0.0,0.0,0.0,
2024-10-21 12:04:00.333416396+00:00,2024-10-21T12:04:00.333582745Z,10,2,38,A,B,1,233.58,200,130,166349,11905464,233.66,233.77,1,200,1,1,233.58,233.78,700,150,2,2,233.53,233.8,10,25,1,1,233.52,233.84,28,27,1,1,233.45,233.94,15,200,1,1,233.4,233.98,110,44,2,3,233.39,234.0,10,154,1,7,233.31,234.13,110,400,2,1,233.3,234.17,100,1,1,1,233.25,234.41,55,600,2,2,AAPL,0.0,200.0,0.0,
2024-10-21 12:04:00.453606564+00:00,2024-10-21T12:04:00.453772968Z,10,2,38,A,B,2,233.53,27,130,166404,11905750,233.66,233.77,1,200,1,1,233.58,233.78,700,150,2,2,233.53,233.8,37,25,2,1,233.52,233.84,28,27,1,1,233.45,233.94,15,200,1,1,233.4,233.98,110,44,2,3,233.39,234.0,10,154,1,7,233.31,234.13,110,400,2,1,233.3,234.17,100,1,1,1,233.25,234.41,55,600,2,2,AAPL,0.0,27.0,0.0,
2024-10-21 12:04:00.453632315+00:00,2024-10-21T12:04:00.453798276Z,10,2,38,C,B,3,233.52,28,130,165961,11905751,233.66,233.77,1,200,1,1,233.58,233.78,700,150,2,2,233.53,233.8,37,25,2,1,233.45,233.84,15,27,1,1,233.4,233.94,110,200,2,1,233.39,233.98,10,44,1,3,233.31,234.0,110,154,2,7,233.3,234.13,100,400,1,1,233.25,234.17,55,1,2,1,233.24,234.41,1,600,1,2,AAPL,0.0,0.0,0.0,
2024-10-21 12:04:01.301464181+00:00,2024-10-21T12:04:01.301630237Z,10,2,38,A,B,1,233.65,18,130,166056,11906476,233.66,233.77,1,200,1,1,233.65,233.78,18,150,1,2,233.58,233.8,700,25,2,1,233.53,233.84,37,27,2,1,233.45,233.94,15,200,1,1,233.4,233.98,110,44,2,3,233.39,234.0,10,154,1,7,233.31,234.13,110,400,2,1,233.3,234.17,100,1,1,1,233.25,234.41,55,600,2,2,AAPL,0.0,0.0,0.0,
2024-10-21 12:04:01.372206492+00:00,2024-10-21T12:04:01.372372505Z,10,2,38,C,B,2,233.58,200,130,166013,11906511,233.66,233.77,1,200,1,1,233.65,233.78,18,150,1,2,233.58,233.8,500,25,1,1,233.53,233.84,37,27,2,1,233.45,233.94,15,200,1,1,233.4,233.98,110,44,2,3,233.39,234.0,10,154,1,7,233.31,234.13,110,400,2,1,233.3,234.17,100,1,1,1,233.25,234.41,55,600,2,2,AAPL,0.0,-200.0,0.0,
2024-10-21 12:04:01.372219216+00:00,2024-10-21T12:04:01.372385835Z,10,2,38,A,B,3,233.55,400,130,166619,11906512,233.66,233.77,1,200,1,1,233.65,233.78,18,150,1,2,233.58,233.8,500,25,1,1,233.55,233.84,400,27,1,1,233.53,233.94,37,200,2,1,233.45,233.98,15,44,1,3,233.4,234.0,110,154,2,7,233.39,234.13,10,400,1,1,233.31,234.17,110,1,2,1,233.3,234.41,100,600,1,2,AAPL,0.0,0.0,0.0,
2024-10-21 12:04:01.372796891+00:00,2024-10-21T12:04:01.372962808Z,10,2,38,C,B,4,233.53,27,130,165917,11906513,233.66,233.77,1,200,1,1,233.65,233.78,18,150,1,2,233.58,233.8,500,25,1,1,233.55,233.84,400,27,1,1,233.53,233.94,10,200,1,1,233.45,233.98,15,44,1,3,233.4,234.0,110,154,2,7,233.39,234.13,10,400,1,1,233.31,234.17,110,1,2,1,233.3,234.41,100,600,1,2,AAPL,0.0,-27.0,0.0,
2024-10-21 12:04:01.644457609+00:00,2024-10-21T12:04:01.644624077Z,10,2,38,A,B,2,233.58,200,130,166468,11906692,233.66,233.77,1,200,1,1,233.65,233.78,18,150,1,2,233.58,233.8,700,25,2,1,233.53,233.84,10,27,1,1,233.45,233.94,15,200,1,1,233.4,233.98,110,44,2,3,233.39,234.0,10,154,1,7,233.31,234.13,110,400,2,1,233.3,234.17,100,1,1,1,233.25,234.41,55,600,2,2,AAPL,0.0,200.0,0.0,
2024-10-21 12:04:05.632550110+00:00,2024-10-21T12:04:05.632716292Z,10,2,38,A,B,3,233.53,26,130,166182,11911165,233.66,233.77,1,200,1,1,233.65,233.78,18,150,1,2,233.58,233.8,700,25,2,1,233.53,233.84,36,27,2,1,233.45,233.94,15,200,1,1,233.4,233.98,110,44,2,3,233.39,234.0,10,154,1,7,233.31,234.13,110,400,2,1,233.3,234.17,100,1,1,1,233.25,234.41,55,600,2,2,AAPL,0.0,26.0,0.0,
2024-10-21 12:04:12.155049282+00:00,2024-10-21T12:04:12.155215428Z,10,2,38,C,A,0,233.77,200,130,166146,11915766,233.66,233.78,1,150,1,2,233.65,233.8,18,25,1,1,233.58,233.84,700,27,2,1,233.53,233.94,36,200,2,1,233.45,233.98,15,44,1,3,233.4,234.0,110,154,2,7,233.39,234.13,10,400,1,1,233.31,234.17,110,1,2,1,233.3,234.41,100,600,1,2,233.25,234.43,55,5,2,1,AAPL,0.0,0.0,0.0,
2024-10-21 12:04:12.156256239+00:00,2024-10-21T12:04:12.156423591Z,10,2,38,T,N,0,233.72,38,130,167352,11915773,233.66,233.78,1,150,1,2,233.65,233.8,18,25,1,1,233.58,233.84,700,27,2,1,233.53,233.94,36,200,2,1,233.45,233.98,15,44,1,3,233.4,234.0,110,154,2,7,233.39,234.13,10,400,1,1,233.31,234.17,110,1,2,1,233.3,234.41,100,600,1,2,233.25,234.43,55,5,2,1,AAPL,0.0,0.0,0.0,
2024-10-21 12:04:12.260774944+00:00,2024-10-21T12:04:12.260942337Z,10,2,38,A,A,2,233.82,200,130,167393,11915806,233.66,233.78,1,150,1,2,233.65,233.8,18,25,1,1,233.58,233.82,700,200,2,1,233.53,233.84,36,27,2,1,233.45,233.94,15,200,1,1,233.4,233.98,110,44,2,3,233.39,234.0,10,154,1,7,233.31,234.13,110,400,2,1,233.3,234.17,100,1,1,1,233.25,234.41,55,600,2,2,AAPL,0.0,0.0,0.0,
2024-10-21 12:04:16.430845992+00:00,2024-10-21T12:04:16.431012384Z,10,2,38,A,A,2,233.82,200,130,166392,11920715,233.66,233.78,1,150,1,2,233.65,233.8,18,25,1,1,233.58,233.82,700,400,2,2,233.53,233.84,36,27,2,1,233.45,233.94,15,200,1,1,233.4,233.98,110,44,2,3,233.39,234.0,10,154,1,7,233.31,234.13,110,400,2,1,233.3,234.17,100,1,1,1,233.25,234.41,55,600,2,2,AAPL,0.0,-200.0,0.0,
2024-10-21 12:04:16.499853888+00:00,2024-10-21T12:04:16.500019710Z,10,2,38,C,B,2,233.58,200,130,165822,11920772,233.66,233.78,1,150,1,2,233.65,233.8,18,25,1,1,233.58,233.82,500,400,1,2,233.53,233.84,36,27,2,1,233.45,233.94,15,200,1,1,233.4,233.98,110,44,2,3,233.39,234.0,10,154,1,7,233.31,234.13,110,400,2,1,233.3,234.17,100,1,1,1,233.25,234.41,55,600,2,2,AAPL,0.0,-200.0,0.0,
2024-10-21 12:04:16.509417925+00:00,2024-10-21T12:04:16.509584729Z,10,2,38,A,B,3,233.57,200,130,166804,11920777,233.66,233.78,1,150,1,2,233.65,233.8,18,25,1,1,233.58,233.82,500,400,1,2,233.57,233.84,200,27,1,1,233.53,233.94,36,200,2,1,233.45,233.98,15,44,1,3,233.4,234.0,110,154,2,7,233.39,234.13,10,400,1,1,233.31,234.17,110,1,2,1,233.3,234.41,100,600,1,2,AAPL,0.0,0.0,0.0,
2024-10-21 12:04:19.069602567+00:00,2024-10-21T12:04:19.069768586Z,10,2,38,C,B,3,233.57,200,130,166019,11924539,233.66,233.78,1,150,1,2,233.65,233.8,18,25,1,1,233.58,233.82,500,400,1,2,233.53,233.84,36,27,2,1,233.45,233.94,15,200,1,1,233.4,233.98,110,44,2,3,233.39,234.0,10,154,1,7,233.31,234.13,110,400,2,1,233.3,234.17,100,1,1,1,233.25,234.41,55,600,2,2,AAPL,0.0,0.0,0.0,
2024-10-21 12:04:19.069614798+00:00,2024-10-21T12:04:19.069781475Z,10,2,38,A,B,3,233.54,400,130,166677,11924540,233.66,233.78,1,150,1,2,233.65,233.8,18,25,1,1,233.58,233.82,500,400,1,2,233.54,233.84,400,27,1,1,233.53,233.94,36,200,2,1,233.45,233.98,15,44,1,3,233.4,234.0,110,154,2,7,233.39,234.13,10,400,1,1,233.31,234.17,110,1,2,1,233.3,234.41,100,600,1,2,AAPL,0.0,0.0,0.0,
2024-10-21 12:04:19.070597243+00:00,2024-10-21T12:04:19.070763821Z,10,2,38,C,B,4,233.53,26,130,166578,11924541,233.66,233.78,1,150,1,2,233.65,233.8,18,25,1,1,233.58,233.82,500,400,1,2,233.54,233.84,400,27,1,1,233.53,233.94,10,200,1,1,233.45,233.98,15,44,1,3,233.4,234.0,110,154,2,7,233.39,234.13,10,400,1,1,233.31,234.17,110,1,2,1,233.3,234.41,100,600,1,2,AAPL,0.0,-26.0,0.0,
2024-10-21 12:04:19.070641181+00:00,2024-10-21T12:04:19.070807458Z,10,2,38,A,B,5,233.47,28,130,166277,11924542,233.66,233.78,1,150,1,2,233.65,233.8,18,25,1,1,233.58,233.82,500,400,1,2,233.54,233.84,400,27,1,1,233.53,233.94,10,200,1,1,233.47,233.98,28,44,1,3,233.45,234.0,15,154,1,7,233.4,234.13,110,400,2,1,233.39,234.17,10,1,1,1,233.31,234.41,110,600,2,2,AAPL,0.0,0.0,0.0,
2024-10-21 12:04:19.474987580+00:00,2024-10-21T12:04:19.475154065Z,10,2,38,A,B,3,233.57,200,130,166485,11924892,233.66,233.78,1,150,1,2,233.65,233.8,18,25,1,1,233.58,233.82,500,400,1,2,233.57,233.84,200,27,1,1,233.53,233.94,10,200,1,1,233.47,233.98,28,44,1,3,233.45,234.0,15,154,1,7,233.4,234.13,110,400,2,1,233.39,234.17,10,1,1,1,233.31,234.41,110,600,2,2,AAPL,0.0,0.0,0.0,
2024-10-21 12:04:19.884911653+00:00,2024-10-21T12:04:19.885077953Z,10,2,38,C,B,5,233.47,28,130,166300,11925176,233.66,233.78,1,150,1,2,233.65,233.8,18,25,1,1,233.58,233.82,500,400,1,2,233.57,233.84,200,27,1,1,233.53,233.94,10,200,1,1,233.45,233.98,15,44,1,3,233.4,234.0,110,154,2,7,233.39,234.13,10,400,1,1,233.31,234.17,110,1,2,1,233.3,234.41,100,600,1,2,AAPL,0.0,0.0,0.0,
2024-10-21 12:04:19.885049397+00:00,2024-10-21T12:04:19.885215852Z,10,2,38,A,B,5,233.52,29,130,166455,11925177,233.66,233.78,1,150,1,2,233.65,233.8,18,25,1,1,233.58,233.82,500,400,1,2,233.57,233.84,200,27,1,1,233.53,233.94,10,200,1,1,233.52,233.98,29,44,1,3,233.45,234.0,15,154,1,7,233.4,234.13,110,400,2,1,233.39,234.17,10,1,1,1,233.31,234.41,110,600,2,2,AAPL,0.0,0.0,0.0,
2024-10-21 12:04:26.481060587+00:00,2024-10-21T12:04:26.481227392Z,10,2,38,C,B,3,233.57,200,130,166805,11934662,233.66,233.78,1,150,1,2,233.65,233.8,18,25,1,1,233.58,233.82,500,400,1,2,233.53,233.84,10,27,1,1,233.52,233.94,29,200,1,1,233.45,233.98,15,44,1,3,233.4,234.0,110,154,2,7,233.39,234.13,10,400,1,1,233.31,234.17,110,1,2,1,233.3,234.41,100,600,1,2,AAPL,0.0,0.0,0.0,
2024-10-21 12:04:26.481072450+00:00,2024-10-21T12:04:26.481239121Z,10,2,38,A,B,3,233.56,200,130,166671,11934663,233.66,233.78,1,150,1,2,233.65,233.8,18,25,1,1,233.58,233.82,500,400,1,2,233.56,233.84,200,27,1,1,233.53,233.94,10,200,1,1,233.52,233.98,29,44,1,3,233.45,234.0,15,154,1,7,233.4,234.13,110,400,2,1,233.39,234.17,10,1,1,1,233.31,234.41,110,600,2,2,AAPL,0.0,0.0,0.0,
2024-10-21 12:04:26.535918353+00:00,2024-10-21T12:04:26.536084575Z,10,2,38,C,A,2,233.82,200,130,166222,11934785,233.66,233.78,1,150,1,2,233.65,233.8,18,25,1,1,233.58,233.82,500,200,1,1,233.56,233.84,200,27,1,1,233.53,233.94,10,200,1,1,233.52,233.98,29,44,1,3,233.45,234.0,15,154,1,7,233.4,234.13,110,400,2,1,233.39,234.17,10,1,1,1,233.31,234.41,110,600,2,2,AAPL,0.0,200.0,0.0,
2024-10-21 12:04:26.535930308+00:00,2024-10-21T12:04:26.536096505Z,10,2,38,A,A,2,233.81,400,130,166197,11934786,233.66,233.78,1,150,1,2,233.65,233.8,18,25,1,1,233.58,233.81,500,400,1,1,233.56,233.84,200,27,1,1,233.53,233.94,10,200,1,1,233.52,233.98,29,44,1,3,233.45,234.0,15,154,1,7,233.4,234.13,110,400,2,1,233.39,234.17,10,1,1,1,233.31,234.41,110,600,2,2,AAPL,0.0,0.0,0.0,
2024-10-21 12:04:26.555072803+00:00,2024-10-21T12:04:26.555239082Z,10,2,38,C,A,3,233.84,27,130,166279,11935024,233.66,233.78,1,150,1,2,233.65,233.8,18,25,1,1,233.58,233.81,500,400,1,1,233.56,233.94,200,200,1,1,233.53,233.98,10,44,1,3,233.52,234.0,29,154,1,7,233.45,234.13,15,400,1,1,233.4,234.17,110,1,2,1,233.39,234.41,10,600,1,2,233.31,234.43,110,5,2,1,AAPL,0.0,0.0,0.0,
2024-10-21 12:04:26.555132343+00:00,2024-10-21T12:04:26.555299312Z,10,2,38,A,A,3,233.83,30,130,166969,11935025,233.66,233.78,1,150,1,2,233.65,233.8,18,25,1,1,233.58,233.81,500,400,1,1,233.56,233.83,200,30,1,1,233.53,233.94,10,200,1,1,233.52,233.98,29,44,1,3,233.45,234.0,15,154,1,7,233.4,234.13,110,400,2,1,233.39,234.17,10,1,1,1,233.31,234.41,110,600,2,2,AAPL,0.0,0.0,0.0,
2024-10-21 12:04:26.566152901+00:00,2024-10-21T12:04:26.566319697Z,10,2,38,A,B,3,233.56,200,130,166796,11935064,233.66,233.78,1,150,1,2,233.65,233.8,18,25,1,1,233.58,233.81,500,400,1,1,233.56,233.83,400,30,2,1,233.53,233.94,10,200,1,1,233.52,233.98,29,44,1,3,233.45,234.0,15,154,1,7,233.4,234.13,110,400,2,1,233.39,234.17,10,1,1,1,233.31,234.41,110,600,2,2,AAPL,0.0,200.0,0.0,
2024-10-21 12:04:26.621148067+00:00,2024-10-21T12:04:26.621314387Z,10,2,38,C,B,3,233.56,200,130,166320,11935247,233.66,233.78,1,150,1,2,233.65,233.8,18,25,1,1,233.58,233.81,500,400,1,1,233.56,233.83,200,30,1,1,233.53,233.94,10,200,1,1,233.52,233.98,29,44,1,3,233.45,234.0,15,154,1,7,233.4,234.13,110,400,2,1,233.39,234.17,10,1,1,1,233.31,234.41,110,600,2,2,AAPL,0.0,-200.0,0.0,
2024-10-21 12:04:26.621160396+00:00,2024-10-21T12:04:26.621327019Z,10,2,38,A,B,2,233.58,400,130,166623,11935248,233.66,233.78,1,150,1,2,233.65,233.8,18,25,1,1,233.58,233.81,900,400,2,1,233.53,233.83,10,30,1,1,233.52,233.94,29,200,1,1,233.45,233.98,15,44,1,3,233.4,234.0,110,154,2,7,233.39,234.13,10,400,1,1,233.31,234.17,110,1,2,1,233.3,234.41,100,600,1,2,AAPL,0.0,400.0,0.0,
2024-10-21 12:04:27.723319849+00:00,2024-10-21T12:04:27.723486293Z,10,2,38,A,B,2,233.59,400,130,166444,11936720,233.66,233.78,1,150,1,2,233.65,233.8,18,25,1,1,233.59,233.81,400,400,1,1,233.58,233.83,500,30,1,1,233.53,233.94,10,200,1,1,233.52,233.98,29,44,1,3,233.45,234.0,15,154,1,7,233.4,234.13,110,400,2,1,233.39,234.17,10,1,1,1,233.31,234.41,110,600,2,2,AAPL,0.0,0.0,0.0,
2024-10-21 12:04:27.735053874+00:00,2024-10-21T12:04:27.735219832Z,10,2,38,C,B,2,233.59,400,130,165958,11936743,233.66,233.78,1,150,1,2,233.65,233.8,18,25,1,1,233.58,233.81,500,400,1,1,233.53,233.83,10,30,1,1,233.52,233.94,29,200,1,1,233.45,233.98,15,44,1,3,233.4,234.0,110,154,2,7,233.39,234.13,10,400,1,1,233.31,234.17,110,1,2,1,233.3,234.41,100,600,1,2,AAPL,0.0,0.0,0.0,
2024-10-21 12:04:27.735066380+00:00,2024-10-21T12:04:27.735232654Z,10,2,38,A,B,3,233.57,200,130,166274,11936744,233.66,233.78,1,150,1,2,233.65,233.8,18,25,1,1,233.58,233.81,500,400,1,1,233.57,233.83,200,30,1,1,233.53,233.94,10,200,1,1,233.52,233.98,29,44,1,3,233.45,234.0,15,154,1,7,233.4,234.13,110,400,2,1,233.39,234.17,10,1,1,1,233.31,234.41,110,600,2,2,AAPL,0.0,0.0,0.0,
2024-10-21 12:04:40.612532228+00:00,2024-10-21T12:04:40.612698742Z,10,2,38,A,A,8,234.15,50,130,166514,11955462,233.66,233.78,1,150,1,2,233.65,233.8,18,25,1,1,233.58,233.81,500,400,1,1,233.57,233.83,200,30,1,1,233.53,233.94,10,200,1,1,233.52,233.98,29,44,1,3,233.45,234.0,15,154,1,7,233.4,234.13,110,400,2,1,233.39,234.15,10,50,1,1,233.31,234.17,110,1,2,1,AAPL,0.0,0.0,0.0,
2024-10-21 12:04:47.058697813+00:00,2024-10-21T12:04:47.058864380Z,10,2,38,A,A,0,233.72,3,130,166567,11962920,233.66,233.72,1,3,1,1,233.65,233.78,18,150,1,2,233.58,233.8,500,25,1,1,233.57,233.81,200,400,1,1,233.53,233.83,10,30,1,1,233.52,233.94,29,200,1,1,233.45,233.98,15,44,1,3,233.4,234.0,110,154,2,7,233.39,234.13,10,400,1,1,233.31,234.15,110,50,2,1,AAPL,0.0,0.0,0.0,
2024-10-21 12:04:51.210492220+00:00,2024-10-21T12:04:51.210658197Z,10,2,38,C,A,3,233.81,400,130,165977,11968430,233.66,233.72,1,3,1,1,233.65,233.78,18,150,1,2,233.58,233.8,500,25,1,1,233.57,233.83,200,30,1,1,233.53,233.94,10,200,1,1,233.52,233.98,29,44,1,3,233.45,234.0,15,154,1,7,233.4,234.13,110,400,2,1,233.39,234.15,10,50,1,1,233.31,234.17,110,1,2,1,AAPL,0.0,0.0,0.0,
2024-10-21 12:04:51.210504256+00:00,2024-10-21T12:04:51.210670708Z,10,2,38,A,A,3,233.83,400,130,166452,11968431,233.66,233.72,1,3,1,1,233.65,233.78,18,150,1,2,233.58,233.8,500,25,1,1,233.57,233.83,200,430,1,2,233.53,233.94,10,200,1,1,233.52,233.98,29,44,1,3,233.45,234.0,15,154,1,7,233.4,234.13,110,400,2,1,233.39,234.15,10,50,1,1,233.31,234.17,110,1,2,1,AAPL,0.0,-400.0,0.0,
2024-10-21 12:04:51.271373633+00:00,2024-10-21T12:04:51.271539805Z,10,2,38,C,B,5,233.52,29,130,166172,11968508,233.66,233.72,1,3,1,1,233.65,233.78,18,150,1,2,233.58,233.8,500,25,1,1,233.57,233.83,200,430,1,2,233.53,233.94,10,200,1,1,233.45,233.98,15,44,1,3,233.4,234.0,110,154,2,7,233.39,234.13,10,400,1,1,233.31,234.15,110,50,2,1,233.3,234.17,100,1,1,1,AAPL,0.0,0.0,0.0,
2024-10-21 12:04:51.271438407+00:00,2024-10-21T12:04:51.271604678Z,10,2,38,A,B,4,233.53,27,130,166271,11968509,233.66,233.72,1,3,1,1,233.65,233.78,18,150,1,2,233.58,233.8,500,25,1,1,233.57,233.83,200,430,1,2,233.53,233.94,37,200,2,1,233.45,233.98,15,44,1,3,233.4,234.0,110,154,2,7,233.39,234.13,10,400,1,1,233.31,234.15,110,50,2,1,233.3,234.17,100,1,1,1,AAPL,0.0,27.0,0.0,
2024-10-21 12:04:51.271510236+00:00,2024-10-21T12:04:51.271676560Z,10,2,38,A,A,3,233.82,200,130,166324,11968510,233.66,233.72,1,3,1,1,233.65,233.78,18,150,1,2,233.58,233.8,500,25,1,1,233.57,233.82,200,200,1,1,233.53,233.83,37,30,2,1,233.45,233.94,15,200,1,1,233.4,233.98,110,44,2,3,233.39,234.0,10,154,1,7,233.31,234.13,110,400,2,1,233.3,234.15,100,50,1,1,AAPL,0.0,0.0,0.0,
2024-10-21 12:04:51.316443773+00:00,2024-10-21T12:04:51.316610309Z,10,2,38,A,A,3,233.82,200,130,166536,11968577,233.66,233.72,1,3,1,1,233.65,233.78,18,150,1,2,233.58,233.8,500,25,1,1,233.57,233.82,200,400,1,2,233.53,233.83,37,30,2,1,233.45,233.94,15,200,1,1,233.4,233.98,110,44,2,3,233.39,234.0,10,154,1,7,233.31,234.13,110,400,2,1,233.3,234.15,100,50,1,1,AAPL,0.0,-200.0,0.0,
2024-10-21 12:04:54.735741554+00:00,2024-10-21T12:04:54.735907876Z,10,2,38,A,B,2,233.58,5,130,166322,11972208,233.66,233.72,1,3,1,1,233.65,233.78,18,150,1,2,233.58,233.8,505,25,2,1,233.57,233.82,200,400,1,2,233.53,233.83,37,30,2,1,233.45,233.94,15,200,1,1,233.4,233.98,110,44,2,3,233.39,234.0,10,154,1,7,233.31,234.13,110,400,2,1,233.3,234.15,100,50,1,1,AAPL,0.0,5.0,0.0,
2024-10-21 12:05:01.936493423+00:00,2024-10-21T12:05:01.936659665Z,10,2,38,C,A,3,233.82,200,130,166242,11982930,233.66,233.72,1,3,1,1,233.65,233.78,18,150,1,2,233.58,233.8,505,25,2,1,233.57,233.82,200,200,1,1,233.53,233.83,37,30,2,1,233.45,233.94,15,200,1,1,233.4,233.98,110,44,2,3,233.39,234.0,10,154,1,7,233.31,234.13,110,400,2,1,233.3,234.15,100,50,1,1,AAPL,0.0,200.0,0.0,
2024-10-21 12:05:01.936505877+00:00,2024-10-21T12:05:01.936672067Z,10,2,38,A,A,1,233.77,200,130,166190,11982931,233.66,233.72,1,3,1,1,233.65,233.77,18,200,1,1,233.58,233.78,505,150,2,2,233.57,233.8,200,25,1,1,233.53,233.83,37,30,2,1,233.45,233.94,15,200,1,1,233.4,233.98,110,44,2,3,233.39,234.0,10,154,1,7,233.31,234.13,110,400,2,1,233.3,234.15,100,50,1,1,AAPL,0.0,0.0,0.0,
2024-10-21 12:05:05.090737406+00:00,2024-10-21T12:05:05.090904204Z,10,2,38,C,A,9,234.15,50,130,166798,11987492,233.66,233.72,1,3,1,1,233.65,233.77,18,200,1,1,233.58,233.78,505,150,2,2,233.57,233.8,200,25,1,1,233.53,233.83,37,30,2,1,233.45,233.94,15,200,1,1,233.4,233.98,110,44,2,3,233.39,234.0,10,154,1,7,233.31,234.13,110,400,2,1,233.3,234.17,100,1,1,1,AAPL,0.0,0.0,0.0,
2024-10-21 12:05:15.858212657+00:00,2024-10-21T12:05:15.858379034Z,10,2,38,C,A,1,233.77,200,130,166377,12002579,233.66,233.72,1,3,1,1,233.65,233.78,18,150,1,2,233.58,233.8,505,25,2,1,233.57,233.83,200,30,1,1,233.53,233.94,37,200,2,1,233.45,233.98,15,44,1,3,233.4,234.0,110,154,2,7,233.39,234.13,10,400,1,1,233.31,234.17,110,1,2,1,233.3,234.25,100,50,1,1,AAPL,0.0,0.0,0.0,
2024-10-21 12:05:15.858226719+00:00,2024-10-21T12:05:15.858393121Z,10,2,38,A,A,3,233.82,200,130,166402,12002580,233.66,233.72,1,3,1,1,233.65,233.78,18,150,1,2,233.58,233.8,505,25,2,1,233.57,233.82,200,200,1,1,233.53,233.83,37,30,2,1,233.45,233.94,15,200,1,1,233.4,233.98,110,44,2,3,233.39,234.0,10,154,1,7,233.31,234.13,110,400,2,1,233.3,234.17,100,1,1,1,AAPL,0.0,0.0,0.0,
2024-10-21 12:05:18.858600266+00:00,2024-10-21T12:05:18.858766649Z,10,2,38,A,A,3,233.82,200,130,166383,12004906,233.66,233.72,1,3,1,1,233.65,233.78,18,150,1,2,233.58,233.8,505,25,2,1,233.57,233.82,200,400,1,2,233.53,233.83,37,30,2,1,233.45,233.94,15,200,1,1,233.4,233.98,110,44,2,3,233.39,234.0,10,154,1,7,233.31,234.13,110,400,2,1,233.3,234.17,100,1,1,1,AAPL,0.0,-200.0,0.0,
2024-10-21 12:05:27.769244591+00:00,2024-10-21T12:05:27.769411797Z,10,2,38,T,B,0,233.72,3,130,167206,12010755,233.66,233.72,1,3,1,1,233.65,233.78,18,150,1,2,233.58,233.8,505,25,2,1,233.57,233.82,200,400,1,2,233.53,233.83,37,30,2,1,233.45,233.94,15,200,1,1,233.4,233.98,110,44,2,3,233.39,234.0,10,154,1,7,233.31,234.13,110,400,2,1,233.3,234.17,100,1,1,1,AAPL,0.0,0.0,0.0,
2024-10-21 12:05:27.769244591+00:00,2024-10-21T12:05:27.769411797Z,10,2,38,C,A,0,233.72,3,130,167206,12010755,233.66,233.78,1,150,1,2,233.65,233.8,18,25,1,1,233.58,233.82,505,400,2,2,233.57,233.83,200,30,1,1,233.53,233.94,37,200,2,1,233.45,233.98,15,44,1,3,233.4,234.0,110,154,2,7,233.39,234.13,10,400,1,1,233.31,234.17,110,1,2,1,233.3,234.25,100,50,1,1,AAPL,0.0,0.0,0.0,
2024-10-21 12:05:27.769266569+00:00,2024-10-21T12:05:27.769433447Z,10,2,38,A,B,0,233.68,100,130,166878,12010756,233.68,233.78,100,150,1,2,233.66,233.8,1,25,1,1,233.65,233.82,18,400,1,2,233.58,233.83,505,30,2,1,233.57,233.94,200,200,1,1,233.53,233.98,37,44,2,3,233.45,234.0,15,154,1,7,233.4,234.13,110,400,2,1,233.39,234.17,10,1,1,1,233.31,234.25,110,50,2,1,AAPL,0.0,0.0,0.0,
2024-10-21 12:05:27.769279547+00:00,2024-10-21T12:05:27.769446609Z,10,2,38,A,B,0,233.68,100,130,167062,12010757,233.68,233.78,200,150,2,2,233.66,233.8,1,25,1,1,233.65,233.82,18,400,1,2,233.58,233.83,505,30,2,1,233.57,233.94,200,200,1,1,233.53,233.98,37,44,2,3,233.45,234.0,15,154,1,7,233.4,234.13,110,400,2,1,233.39,234.17,10,1,1,1,233.31,234.25,110,50,2,1,AAPL,100.0,100.0,100.0,
2024-10-21 12:05:27.769282701+00:00,2024-10-21T12:05:27.769448769Z,10,2,38,A,B,1,233.67,13,130,166068,12010758,233.68,233.78,200,150,2,2,233.67,233.8,13,25,1,1,233.66,233.82,1,400,1,2,233.65,233.83,18,30,1,1,233.58,233.94,505,200,2,1,233.57,233.98,200,44,1,3,233.53,234.0,37,154,2,7,233.45,234.13,15,400,1,1,233.4,234.17,110,1,2,1,233.39,234.25,10,50,1,1,AAPL,0.0,0.0,100.0,
2024-10-21 12:05:27.769319506+00:00,2024-10-21T12:05:27.769485951Z,10,2,38,C,B,0,233.68,100,130,166445,12010760,233.68,233.78,100,150,1,2,233.67,233.8,13,25,1,1,233.66,233.82,1,400,1,2,233.65,233.83,18,30,1,1,233.58,233.94,505,200,2,1,233.57,233.98,200,44,1,3,233.53,234.0,37,154,2,7,233.45,234.13,15,400,1,1,233.4,234.17,110,1,2,1,233.39,234.25,10,50,1,1,AAPL,-100.0,-100.0,0.0,
2024-10-21 12:05:27.769383987+00:00,2024-10-21T12:05:27.769550286Z,10,2,38,C,B,0,233.68,100,130,166299,12010767,233.67,233.78,13,150,1,2,233.66,233.8,1,25,1,1,233.65,233.82,18,400,1,2,233.58,233.83,505,30,2,1,233.57,233.94,200,200,1,1,233.53,233.98,37,44,2,3,233.45,234.0,15,154,1,7,233.4,234.13,110,400,2,1,233.39,234.17,10,1,1,1,233.31,234.25,110,50,2,1,AAPL,0.0,0.0,0.0,
2024-10-21 12:05:27.870580890+00:00,2024-10-21T12:05:27.870746889Z,10,2,38,C,B,0,233.67,13,130,165999,12010841,233.66,233.78,1,150,1,2,233.65,233.8,18,25,1,1,233.58,233.82,505,400,2,2,233.57,233.83,200,30,1,1,233.53,233.94,37,200,2,1,233.45,233.98,15,44,1,3,233.4,234.0,110,154,2,7,233.39,234.13,10,400,1,1,233.31,234.17,110,1,2,1,233.3,234.25,100,50,1,1,AAPL,0.0,0.0,0.0,
2024-10-21 12:05:30.107740673+00:00,2024-10-21T12:05:30.107907731Z,10,2,38,A,B,0,233.7,1200,130,167058,12012202,233.7,233.78,1200,150,1,2,233.66,233.8,1,25,1,1,233.65,233.82,18,400,1,2,233.58,233.83,505,30,2,1,233.57,233.94,200,200,1,1,233.53,233.98,37,44,2,3,233.45,234.0,15,154,1,7,233.4,234.13,110,400,2,1,233.39,234.17,10,1,1,1,233.31,234.25,110,50,2,1,AAPL,0.0,0.0,0.0,
2024-10-21 12:05:35.113109625+00:00,2024-10-21T12:05:35.113275906Z,10,2,38,C,B,4,233.57,200,130,166281,12015205,233.7,233.78,1200,150,1,2,233.66,233.8,1,25,1,1,233.65,233.82,18,400,1,2,233.58,233.83,505,30,2,1,233.53,233.94,37,200,2,1,233.45,233.98,15,44,1,3,233.4,234.0,110,154,2,7,233.39,234.13,10,400,1,1,233.31,234.17,110,1,2,1,233.3,234.25,100,50,1,1,AAPL,0.0,0.0,0.0,
2024-10-21 12:05:35.113122799+00:00,2024-10-21T12:05:35.113289385Z,10,2,38,A,B,5,233.52,400,130,166586,12015206,233.7,233.78,1200,150,1,2,233.66,233.8,1,25,1,1,233.65,233.82,18,400,1,2,233.58,233.83,505,30,2,1,233.53,233.94,37,200,2,1,233.52,233.98,400,44,1,3,233.45,234.0,15,154,1,7,233.4,234.13,110,400,2,1,233.39,234.17,10,1,1,1,233.31,234.25,110,50,2,1,AAPL,0.0,0.0,0.0,
2024-10-21 12:05:40.025196163+00:00,2024-10-21T12:05:40.025362817Z,10,2,38,C,A,2,233.82,200,130,166654,12018306,233.7,233.78,1200,150,1,2,233.66,233.8,1,25,1,1,233.65,233.82,18,200,1,1,233.58,233.83,505,30,2,1,233.53,233.94,37,200,2,1,233.52,233.98,400,44,1,3,233.45,234.0,15,154,1,7,233.4,234.13,110,400,2,1,233.39,234.17,10,1,1,1,233.31,234.25,110,50,2,1,AAPL,0.0,200.0,0.0,
2024-10-21 12:05:40.028003470+00:00,2024-10-21T12:05:40.028175209Z,10,2,38,T,B,0,233.78,50,0,171739,12018310,233.7,233.78,1200,150,1,2,233.66,233.8,1,25,1,1,233.65,233.82,18,200,1,1,233.58,233.83,505,30,2,1,233.53,233.94,37,200,2,1,233.52,233.98,400,44,1,3,233.45,234.0,15,154,1,7,233.4,234.13,110,400,2,1,233.39,234.17,10,1,1,1,233.31,234.25,110,50,2,1,AAPL,0.0,0.0,0.0,
2024-10-21 12:05:40.028003470+00:00,2024-10-21T12:05:40.028175209Z,10,2,38,T,B,0,233.78,100,0,171739,12018311,233.7,233.78,1200,100,1,1,233.66,233.8,1,25,1,1,233.65,233.82,18,200,1,1,233.58,233.83,505,30,2,1,233.53,233.94,37,200,2,1,233.52,233.98,400,44,1,3,233.45,234.0,15,154,1,7,233.4,234.13,110,400,2,1,233.39,234.17,10,1,1,1,233.31,234.25,110,50,2,1,AAPL,50.0,50.0,50.0,
2024-10-21 12:05:40.028006695+00:00,2024-10-21T12:05:40.028175209Z,10,2,38,C,N,0,233.82,200,130,168514,12018313,233.78,233.8,256,25,1,1,233.7,233.83,1200,30,1,1,233.66,233.94,1,200,1,1,233.65,233.98,18,44,1,3,233.58,234.0,505,154,2,7,233.53,234.13,37,400,2,1,233.52,234.17,400,1,1,1,233.45,234.25,15,50,1,1,233.4,234.41,110,600,2,2,233.39,234.43,10,5,1,1,AAPL,0.0,0.0,50.0,
2024-10-21 12:05:40.028030027+00:00,2024-10-21T12:05:40.028197600Z,10,2,38,A,B,1,233.74,100,130,167573,12018314,233.78,233.8,256,25,1,1,233.74,233.83,100,30,1,1,233.7,233.94,1200,200,1,1,233.66,233.98,1,44,1,3,233.65,234.0,18,154,1,7,233.58,234.13,505,400,2,1,233.53,234.17,37,1,2,1,233.52,234.25,400,50,1,1,233.45,234.41,15,600,1,2,233.4,234.43,110,5,2,1,AAPL,0.0,0.0,50.0,
2024-10-21 12:05:40.028032659+00:00,2024-10-21T12:05:40.028200070Z,10,2,38,A,B,2,233.72,100,130,167411,12018315,233.78,233.8,256,25,1,1,233.74,233.83,100,30,1,1,233.72,233.94,100,200,1,1,233.7,233.98,1200,44,1,3,233.66,234.0,1,154,1,7,233.65,234.13,18,400,1,1,233.58,234.17,505,1,2,1,233.53,234.25,37,50,2,1,233.52,234.41,400,600,1,2,233.45,234.43,15,5,1,1,AAPL,0.0,0.0,50.0,
2024-10-21 12:05:40.028041901+00:00,2024-10-21T12:05:40.028209847Z,10,2,38,A,B,2,233.72,100,128,167946,12018316,233.78,233.8,256,25,1,1,233.74,233.83,100,30,1,1,233.72,233.94,200,200,2,1,233.7,233.98,1200,44,1,3,233.66,234.0,1,154,1,7,233.65,234.13,18,400,1,1,233.58,234.17,505,1,2,1,233.53,234.25,37,50,2,1,233.52,234.41,400,600,1,2,233.45,234.43,15,5,1,1,AAPL,0.0,100.0,50.0,
2024-10-21 12:05:40.028043931+00:00,2024-10-21T12:05:40.028210843Z,10,2,38,A,B,1,233.74,100,130,166912,12018318,233.78,233.8,256,25,1,1,233.74,233.83,200,30,2,1,233.72,233.94,200,200,2,1,233.7,233.98,1200,44,1,3,233.66,234.0,1,154,1,7,233.65,234.13,18,400,1,1,233.58,234.17,505,1,2,1,233.53,234.25,37,50,2,1,233.52,234.41,400,600,1,2,233.45,234.43,15,5,1,1,AAPL,0.0,100.0,50.0,
2024-10-21 12:05:40.028048443+00:00,2024-10-21T12:05:40.028215296Z,10,2,38,A,B,1,233.74,32,130,166853,12018319,233.78,233.8,256,25,1,1,233.74,233.83,232,30,3,1,233.72,233.94,200,200,2,1,233.7,233.98,1200,44,1,3,233.66,234.0,1,154,1,7,233.65,234.13,18,400,1,1,233.58,234.17,505,1,2,1,233.53,234.25,37,50,2,1,233.52,234.41,400,600,1,2,233.45,234.43,15,5,1,1,AAPL,0.0,32.0,50.0,
2024-10-21 12:05:40.028054971+00:00,2024-10-21T12:05:40.028222153Z,10,2,38,A,B,2,233.72,100,128,167182,12018320,233.78,233.8,256,25,1,1,233.74,233.83,232,30,3,1,233.72,233.94,300,200,3,1,233.7,233.98,1200,44,1,3,233.66,234.0,1,154,1,7,233.65,234.13,18,400,1,1,233.58,234.17,505,1,2,1,233.53,234.25,37,50,2,1,233.52,234.41,400,600,1,2,233.45,234.43,15,5,1,1,AAPL,0.0,100.0,50.0,
2024-10-21 12:05:40.028063174+00:00,2024-10-21T12:05:40.028229221Z,10,2,38,A,B,3,233.71,32,130,166047,12018322,233.78,233.8,256,25,1,1,233.74,233.83,232,30,3,1,233.72,233.94,300,200,3,1,233.71,233.98,32,44,1,3,233.7,234.0,1200,154,1,7,233.66,234.13,1,400,1,1,233.65,234.17,18,1,1,1,233.58,234.25,505,50,2,1,233.53,234.41,37,600,2,2,233.52,234.43,400,5,1,1,AAPL,0.0,0.0,50.0,
2024-10-21 12:05:40.028066207+00:00,2024-10-21T12:05:40.028232731Z,10,2,38,C,B,1,233.74,100,130,166524,12018323,233.78,233.8,256,25,1,1,233.74,233.83,132,30,2,1,233.72,233.94,300,200,3,1,233.71,233.98,32,44,1,3,233.7,234.0,1200,154,1,7,233.66,234.13,1,400,1,1,233.65,234.17,18,1,1,1,233.58,234.25,505,50,2,1,233.53,234.41,37,600,2,2,233.52,234.43,400,5,1,1,AAPL,0.0,-100.0,50.0,
2024-10-21 12:05:40.028077104+00:00,2024-10-21T12:05:40.028243957Z,10,2,38,C,B,1,233.74,100,130,166853,12018324,233.78,233.8,256,25,1,1,233.74,233.83,32,30,1,1,233.72,233.94,300,200,3,1,233.71,233.98,32,44,1,3,233.7,234.0,1200,154,1,7,233.66,234.13,1,400,1,1,233.65,234.17,18,1,1,1,233.58,234.25,505,50,2,1,233.53,234.41,37,600,2,2,233.52,234.43,400,5,1,1,AAPL,0.0,-100.0,50.0,
2024-10-21 12:05:40.028094970+00:00,2024-10-21T12:05:40.028264359Z,10,2,38,T,B,0,233.8,25,130,169389,12018325,233.78,233.8,256,25,1,1,233.74,233.83,32,30,1,1,233.72,233.94,300,200,3,1,233.71,233.98,32,44,1,3,233.7,234.0,1200,154,1,7,233.66,234.13,1,400,1,1,233.65,234.17,18,1,1,1,233.58,234.25,505,50,2,1,233.53,234.41,37,600,2,2,233.52,234.43,400,5,1,1,AAPL,0.0,0.0,50.0,
2024-10-21 12:05:40.028094970+00:00,2024-10-21T12:05:40.028264359Z,10,2,38,C,A,0,233.8,25,130,169389,12018325,233.78,233.83,256,30,1,1,233.74,233.94,32,200,1,1,233.72,233.98,300,44,3,3,233.71,234.0,32,154,1,7,233.7,234.13,1200,400,1,1,233.66,234.17,1,1,1,1,233.65,234.25,18,50,1,1,233.58,234.41,505,600,2,2,233.53,234.43,37,5,2,1,233.52,234.5,400,63,1,4,AAPL,0.0,0.0,50.0,
2024-10-21 12:05:40.028097758+00:00,2024-10-21T12:05:40.028266286Z,10,2,38,A,B,4,233.7,100,130,168528,12018326,233.78,233.83,256,30,1,1,233.74,233.94,32,200,1,1,233.72,233.98,300,44,3,3,233.71,234.0,32,154,1,7,233.7,234.13,1300,400,2,1,233.66,234.17,1,1,1,1,233.65,234.25,18,50,1,1,233.58,234.41,505,600,2,2,233.53,234.43,37,5,2,1,233.52,234.5,400,63,1,4,AAPL,0.0,100.0,50.0,
2024-10-21 12:05:40.028115361+00:00,2024-10-21T12:05:40.028281310Z,10,2,38,A,B,0,233.79,100,130,165949,12018327,233.79,233.83,100,30,1,1,233.78,233.94,256,200,1,1,233.74,233.98,32,44,1,3,233.72,234.0,300,154,3,7,233.71,234.13,32,400,1,1,233.7,234.17,1300,1,2,1,233.66,234.25,1,50,1,1,233.65,234.41,18,600,1,2,233.58,234.43,505,5,2,1,233.53,234.5,37,63,2,4,AAPL,0.0,0.0,50.0,
2024-10-21 12:05:40.028121192+00:00,2024-10-21T12:05:40.028288152Z,10,2,38,A,B,5,233.7,100,128,166960,12018328,233.79,233.83,100,30,1,1,233.78,233.94,256,200,1,1,233.74,233.98,32,44,1,3,233.72,234.0,300,154,3,7,233.71,234.13,32,400,1,1,233.7,234.17,1400,1,3,1,233.66,234.25,1,50,1,1,233.65,234.41,18,600,1,2,233.58,234.43,505,5,2,1,233.53,234.5,37,63,2,4,AAPL,0.0,0.0,50.0,
2024-10-21 12:05:40.028128644+00:00,2024-10-21T12:05:40.028294528Z,10,2,38,C,B,3,233.72,100,130,165884,12018330,233.79,233.83,100,30,1,1,233.78,233.94,256,200,1,1,233.74,233.98,32,44,1,3,233.72,234.0,200,154,2,7,233.71,234.13,32,400,1,1,233.7,234.17,1400,1,3,1,233.66,234.25,1,50,1,1,233.65,234.41,18,600,1,2,233.58,234.43,505,5,2,1,233.53,234.5,37,63,2,4,AAPL,0.0,-100.0,50.0,
2024-10-21 12:05:40.028156649+00:00,2024-10-21T12:05:40.028323326Z,10,2,38,C,B,3,233.72,100,130,166677,12018331,233.79,233.83,100,30,1,1,233.78,233.94,256,200,1,1,233.74,233.98,32,44,1,3,233.72,234.0,100,154,1,7,233.71,234.13,32,400,1,1,233.7,234.17,1400,1,3,1,233.66,234.25,1,50,1,1,233.65,234.41,18,600,1,2,233.58,234.43,505,5,2,1,233.53,234.5,37,63,2,4,AAPL,0.0,-100.0,50.0,
2024-10-21 12:05:40.028365786+00:00,2024-10-21T12:05:40.028531746Z,10,2,38,C,B,0,233.79,100,130,165960,12018340,233.78,233.83,256,30,1,1,233.74,233.94,32,200,1,1,233.72,233.98,100,44,1,3,233.71,234.0,32,154,1,7,233.7,234.13,1400,400,3,1,233.66,234.17,1,1,1,1,233.65,234.25,18,50,1,1,233.58,234.41,505,600,2,2,233.53,234.43,37,5,2,1,233.52,234.5,400,63,1,4,AAPL,0.0,0.0,50.0,
2024-10-21 12:05:40.028429209+00:00,2024-10-21T12:05:40.028595126Z,10,2,38,C,B,2,233.72,100,130,165917,12018342,233.78,233.83,256,30,1,1,233.74,233.94,32,200,1,1,233.71,233.98,32,44,1,3,233.7,234.0,1400,154,3,7,233.66,234.13,1,400,1,1,233.65,234.17,18,1,1,1,233.58,234.25,505,50,2,1,233.53,234.41,37,600,2,2,233.52,234.43,400,5,1,1,233.45,234.5,15,63,1,4,AAPL,0.0,0.0,50.0,
2024-10-21 12:05:40.028485091+00:00,2024-10-21T12:05:40.028651521Z,10,2,38,C,B,3,233.7,100,130,166430,12018343,233.78,233.83,256,30,1,1,233.74,233.94,32,200,1,1,233.71,233.98,32,44,1,3,233.7,234.0,1300,154,2,7,233.66,234.13,1,400,1,1,233.65,234.17,18,1,1,1,233.58,234.25,505,50,2,1,233.53,234.41,37,600,2,2,233.52,234.43,400,5,1,1,233.45,234.5,15,63,1,4,AAPL,0.0,-100.0,50.0,
2024-10-21 12:05:40.028584035+00:00,2024-10-21T12:05:40.028749890Z,10,2,38,C,B,3,233.7,100,130,165855,12018344,233.78,233.83,256,30,1,1,233.74,233.94,32,200,1,1,233.71,233.98,32,44,1,3,233.7,234.0,1200,154,1,7,233.66,234.13,1,400,1,1,233.65,234.17,18,1,1,1,233.58,234.25,505,50,2,1,233.53,234.41,37,600,2,2,233.52,234.43,400,5,1,1,233.45,234.5,15,63,1,4,AAPL,0.0,-100.0,50.0,
2024-10-21 12:05:40.055564914+00:00,2024-10-21T12:05:40.055731072Z,10,2,38,C,B,0,233.78,256,130,166158,12018442,233.74,233.83,32,30,1,1,233.71,233.94,32,200,1,1,233.7,233.98,1200,44,1,3,233.66,234.0,1,154,1,7,233.65,234.13,18,400,1,1,233.58,234.17,505,1,2,1,233.53,234.25,37,50,2,1,233.52,234.41,400,600,1,2,233.45,234.43,15,5,1,1,233.4,234.5,110,63,2,4,AAPL,0.0,0.0,50.0,
2024-10-21 12:05:40.071027333+00:00,2024-10-21T12:05:40.071193978Z,10,2,38,A,B,0,233.78,326,130,166645,12018463,233.78,233.83,326,30,1,1,233.74,233.94,32,200,1,1,233.71,233.98,32,44,1,3,233.7,234.0,1200,154,1,7,233.66,234.13,1,400,1,1,233.65,234.17,18,1,1,1,233.58,234.25,505,50,2,1,233.53,234.41,37,600,2,2,233.52,234.43,400,5,1,1,233.45,234.5,15,63,1,4,AAPL,0.0,0.0,50.0,
2024-10-21 12:05:40.096302346+00:00,2024-10-21T12:05:40.096468671Z,10,2,38,C,A,0,233.83,30,130,166325,12018476,233.78,233.94,326,200,1,1,233.74,233.98,32,44,1,3,233.71,234.0,32,154,1,7,233.7,234.13,1200,400,1,1,233.66,234.17,1,1,1,1,233.65,234.25,18,50,1,1,233.58,234.41,505,600,2,2,233.53,234.43,37,5,2,1,233.52,234.5,400,63,1,4,233.45,234.75,15,1,1,1,AAPL,0.0,0.0,50.0,
2024-10-21 12:05:40.096345392+00:00,2024-10-21T12:05:40.096512056Z,10,2,38,A,A,0,233.89,28,130,166664,12018477,233.78,233.89,326,28,1,1,233.74,233.94,32,200,1,1,233.71,233.98,32,44,1,3,233.7,234.0,1200,154,1,7,233.66,234.13,1,400,1,1,233.65,234.17,18,1,1,1,233.58,234.25,505,50,2,1,233.53,234.41,37,600,2,2,233.52,234.43,400,5,1,1,233.45,234.5,15,63,1,4,AAPL,0.0,0.0,50.0,
2024-10-21 12:05:40.133764520+00:00,2024-10-21T12:05:40.133930729Z,10,2,38,C,B,2,233.71,32,130,166209,12018494,233.78,233.89,326,28,1,1,233.74,233.94,32,200,1,1,233.7,233.98,1200,44,1,3,233.66,234.0,1,154,1,7,233.65,234.13,18,400,1,1,233.58,234.17,505,1,2,1,233.53,234.25,37,50,2,1,233.52,234.41,400,600,1,2,233.45,234.43,15,5,1,1,233.4,234.5,110,63,2,4,AAPL,0.0,0.0,50.0,
2024-10-21 12:05:40.147760543+00:00,2024-10-21T12:05:40.147927019Z,10,2,38,A,B,5,233.58,400,130,166476,12018505,233.78,233.89,326,28,1,1,233.74,233.94,32,200,1,1,233.7,233.98,1200,44,1,3,233.66,234.0,1,154,1,7,233.65,234.13,18,400,1,1,233.58,234.17,905,1,3,1,233.53,234.25,37,50,2,1,233.45,234.41,15,600,1,2,233.4,234.43,110,5,2,1,233.39,234.5,10,63,1,4,AAPL,0.0,0.0,50.0,
2024-10-21 12:05:40.167062454+00:00,2024-10-21T12:05:40.167228800Z,10,2,38,A,A,0,233.88,200,130,166346,12018509,233.78,233.88,326,200,1,1,233.74,233.89,32,28,1,1,233.7,233.94,1200,200,1,1,233.66,233.98,1,44,1,3,233.65,234.0,18,154,1,7,233.58,234.13,905,400,3,1,233.53,234.17,37,1,2,1,233.45,234.25,15,50,1,1,233.4,234.41,110,600,2,2,233.39,234.43,10,5,1,1,AAPL,0.0,0.0,50.0,
2024-10-21 12:05:40.279040532+00:00,2024-10-21T12:05:40.279206575Z,10,2,38,C,B,1,233.74,32,130,166043,12018540,233.78,233.88,326,200,1,1,233.7,233.89,1200,28,1,1,233.66,233.94,1,200,1,1,233.65,233.98,18,44,1,3,233.58,234.0,905,154,3,7,233.53,234.13,37,400,2,1,233.45,234.17,15,1,1,1,233.4,234.25,110,50,2,1,233.39,234.41,10,600,1,2,233.31,234.43,110,5,2,1,AAPL,0.0,0.0,50.0,
2024-10-21 12:05:40.371306716+00:00,2024-10-21T12:05:40.371473684Z,10,2,38,A,B,4,233.59,400,130,166968,12018572,233.78,233.88,326,200,1,1,233.7,233.89,1200,28,1,1,233.66,233.94,1,200,1,1,233.65,233.98,18,44,1,3,233.59,234.0,400,154,1,7,233.58,234.13,505,400,2,1,233.53,234.17,37,1,2,1,233.45,234.25,15,50,1,1,233.4,234.41,110,600,2,2,233.39,234.43,10,5,1,1,AAPL,0.0,0.0,50.0,
2024-10-21 12:05:40.371534341+00:00,2024-10-21T12:05:40.371700587Z,10,2,38,C,A,0,233.88,200,130,166246,12018573,233.78,233.89,326,28,1,1,233.7,233.94,1200,200,1,1,233.66,233.98,1,44,1,3,233.65,234.0,18,154,1,7,233.59,234.13,400,400,1,1,233.58,234.17,505,1,2,1,233.53,234.25,37,50,2,1,233.45,234.41,15,600,1,2,233.4,234.43,110,5,2,1,233.39,234.5,10,63,1,4,AAPL,0.0,0.0,50.0,
2024-10-21 12:05:40.371545573+00:00,2024-10-21T12:05:40.371712816Z,10,2,38,A,A,1,233.92,200,130,167243,12018574,233.78,233.89,326,28,1,1,233.7,233.92,1200,200,1,1,233.66,233.94,1,200,1,1,233.65,233.98,18,44,1,3,233.59,234.0,400,154,1,7,233.58,234.13,505,400,2,1,233.53,234.17,37,1,2,1,233.45,234.25,15,50,1,1,233.4,234.41,110,600,2,2,233.39,234.43,10,5,1,1,AAPL,0.0,0.0,50.0,
2024-10-21 12:05:40.371797762+00:00,2024-10-21T12:05:40.371963906Z,10,2,38,A,B,5,233.58,27,130,166144,12018575,233.78,233.89,326,28,1,1,233.7,233.92,1200,200,1,1,233.66,233.94,1,200,1,1,233.65,233.98,18,44,1,3,233.59,234.0,400,154,1,7,233.58,234.13,532,400,3,1,233.53,234.17,37,1,2,1,233.45,234.25,15,50,1,1,233.4,234.41,110,600,2,2,233.39,234.43,10,5,1,1,AAPL,0.0,0.0,50.0,
2024-10-21 12:05:40.371831552+00:00,2024-10-21T12:05:40.371997976Z,10,2,38,C,B,6,233.53,27,130,166424,12018576,233.78,233.89,326,28,1,1,233.7,233.92,1200,200,1,1,233.66,233.94,1,200,1,1,233.65,233.98,18,44,1,3,233.59,234.0,400,154,1,7,233.58,234.13,532,400,3,1,233.53,234.17,10,1,1,1,233.45,234.25,15,50,1,1,233.4,234.41,110,600,2,2,233.39,234.43,10,5,1,1,AAPL,0.0,0.0,50.0,
2024-10-21 12:05:40.422122396+00:00,2024-10-21T12:05:40.422288699Z,10,2,38,A,B,2,233.68,200,130,166303,12018592,233.78,233.89,326,28,1,1,233.7,233.92,1200,200,1,1,233.68,233.94,200,200,1,1,233.66,233.98,1,44,1,3,233.65,234.0,18,154,1,7,233.58,234.13,532,400,3,1,233.53,234.17,10,1,1,1,233.45,234.25,15,50,1,1,233.4,234.41,110,600,2,2,233.39,234.43,10,5,1,1,AAPL,0.0,0.0,50.0,
2024-10-21 12:05:41.922932814+00:00,2024-10-21T12:05:41.923099064Z,10,2,38,C,B,5,233.58,27,130,166250,12019448,233.78,233.89,326,28,1,1,233.7,233.92,1200,200,1,1,233.68,233.94,200,200,1,1,233.66,233.98,1,44,1,3,233.65,234.0,18,154,1,7,233.58,234.13,505,400,2,1,233.53,234.17,10,1,1,1,233.45,234.25,15,50,1,1,233.4,234.41,110,600,2,2,233.39,234.43,10,5,1,1,AAPL,0.0,0.0,0.0,
2024-10-21 12:05:41.923000912+00:00,2024-10-21T12:05:41.923167380Z,10,2,38,A,B,5,233.63,28,130,166468,12019449,233.78,233.89,326,28,1,1,233.7,233.92,1200,200,1,1,233.68,233.94,200,200,1,1,233.66,233.98,1,44,1,3,233.65,234.0,18,154,1,7,233.63,234.13,28,400,1,1,233.58,234.17,505,1,2,1,233.53,234.25,10,50,1,1,233.45,234.41,15,600,1,2,233.4,234.43,110,5,2,1,AAPL,0.0,0.0,0.0,
2024-10-21 12:05:41.948630132+00:00,2024-10-21T12:05:41.948798033Z,10,2,38,T,N,0,233.79,162,130,167901,12019456,233.78,233.89,326,28,1,1,233.7,233.92,1200,200,1,1,233.68,233.94,200,200,1,1,233.66,233.98,1,44,1,3,233.65,234.0,18,154,1,7,233.63,234.13,28,400,1,1,233.58,234.17,505,1,2,1,233.53,234.25,10,50,1,1,233.45,234.41,15,600,1,2,233.4,234.43,110,5,2,1,AAPL,0.0,0.0,0.0,
2024-10-21 12:05:41.951962933+00:00,2024-10-21T12:05:41.952129039Z,10,2,38,C,B,2,233.68,200,130,166106,12019457,233.78,233.89,326,28,1,1,233.7,233.92,1200,200,1,1,233.66,233.94,1,200,1,1,233.65,233.98,18,44,1,3,233.63,234.0,28,154,1,7,233.58,234.13,505,400,2,1,233.53,234.17,10,1,1,1,233.45,234.25,15,50,1,1,233.4,234.41,110,600,2,2,233.39,234.43,10,5,1,1,AAPL,0.0,0.0,0.0,
2024-10-21 12:05:41.951975929+00:00,2024-10-21T12:05:41.952142239Z,10,2,38,A,B,3,233.65,400,130,166310,12019458,233.78,233.89,326,28,1,1,233.7,233.92,1200,200,1,1,233.66,233.94,1,200,1,1,233.65,233.98,418,44,2,3,233.63,234.0,28,154,1,7,233.58,234.13,505,400,2,1,233.53,234.17,10,1,1,1,233.45,234.25,15,50,1,1,233.4,234.41,110,600,2,2,233.39,234.43,10,5,1,1,AAPL,0.0,400.0,0.0,
2024-10-21 12:05:41.952567424+00:00,2024-10-21T12:05:41.952733597Z,10,2,38,C,A,0,233.89,28,130,166173,12019459,233.78,233.92,326,200,1,1,233.7,233.94,1200,200,1,1,233.66,233.98,1,44,1,3,233.65,234.0,418,154,2,7,233.63,234.13,28,400,1,1,233.58,234.17,505,1,2,1,233.53,234.25,10,50,1,1,233.45,234.41,15,600,1,2,233.4,234.43,110,5,2,1,233.39,234.5,10,63,1,4,AAPL,0.0,0.0,0.0,
2024-10-21 12:05:41.952619801+00:00,2024-10-21T12:05:41.952786117Z,10,2,38,A,A,2,233.95,29,130,166316,12019460,233.78,233.92,326,200,1,1,233.7,233.94,1200,200,1,1,233.66,233.95,1,29,1,1,233.65,233.98,418,44,2,3,233.63,234.0,28,154,1,7,233.58,234.13,505,400,2,1,233.53,234.17,10,1,1,1,233.45,234.25,15,50,1,1,233.4,234.41,110,600,2,2,233.39,234.43,10,5,1,1,AAPL,0.0,0.0,0.0,
2024-10-21 12:05:43.153724103+00:00,2024-10-21T12:05:43.153890594Z,10,2,38,A,B,2,233.69,200,130,166491,12020040,233.78,233.92,326,200,1,1,233.7,233.94,1200,200,1,1,233.69,233.95,200,29,1,1,233.66,233.98,1,44,1,3,233.65,234.0,18,154,1,7,233.63,234.13,28,400,1,1,233.58,234.17,505,1,2,1,233.53,234.25,10,50,1,1,233.45,234.41,15,600,1,2,233.4,234.43,110,5,2,1,AAPL,0.0,0.0,0.0,
2024-10-21 12:05:43.258685033+00:00,2024-10-21T12:05:43.258851703Z,10,2,38,T,A,0,233.78,250,130,166670,12020063,233.78,233.92,326,200,1,1,233.7,233.94,1200,200,1,1,233.69,233.95,200,29,1,1,233.66,233.98,1,44,1,3,233.65,234.0,18,154,1,7,233.63,234.13,28,400,1,1,233.58,234.17,505,1,2,1,233.53,234.25,10,50,1,1,233.45,234.41,15,600,1,2,233.4,234.43,110,5,2,1,AAPL,0.0,0.0,0.0,
2024-10-21 12:05:43.258685033+00:00,2024-10-21T12:05:43.258851703Z,10,2,38,C,B,0,233.78,250,130,166670,12020063,233.78,233.92,76,200,1,1,233.7,233.94,1200,200,1,1,233.69,233.95,200,29,1,1,233.66,233.98,1,44,1,3,233.65,234.0,18,154,1,7,233.63,234.13,28,400,1,1,233.58,234.17,505,1,2,1,233.53,234.25,10,50,1,1,233.45,234.41,15,600,1,2,233.4,234.43,110,5,2,1,AAPL,-250.0,-250.0,-250.0,
2024-10-21 12:05:43.258755715+00:00,2024-10-21T12:05:43.258921916Z,10,2,38,C,B,2,233.69,200,130,166201,12020064,233.78,233.92,76,200,1,1,233.7,233.94,1200,200,1,1,233.66,233.95,1,29,1,1,233.65,233.98,18,44,1,3,233.63,234.0,28,154,1,7,233.58,234.13,505,400,2,1,233.53,234.17,10,1,1,1,233.45,234.25,15,50,1,1,233.4,234.41,110,600,2,2,233.39,234.43,10,5,1,1,AAPL,0.0,0.0,-250.0,
2024-10-21 12:05:43.337323654+00:00,2024-10-21T12:05:43.337489880Z,10,2,38,A,B,5,233.59,200,130,166226,12020098,233.78,233.92,76,200,1,1,233.7,233.94,1200,200,1,1,233.66,233.95,1,29,1,1,233.65,233.98,18,44,1,3,233.63,234.0,28,154,1,7,233.59,234.13,200,400,1,1,233.58,234.17,505,1,2,1,233.53,234.25,10,50,1,1,233.45,234.41,15,600,1,2,233.4,234.43,110,5,2,1,AAPL,0.0,0.0,-250.0,
2024-10-21 12:05:43.337453873+00:00,2024-10-21T12:05:43.337620382Z,10,2,38,A,A,0,233.92,200,130,166509,12020100,233.78,233.92,76,400,1,2,233.7,233.94,1200,200,1,1,233.66,233.95,1,29,1,1,233.65,233.98,18,44,1,3,233.63,234.0,28,154,1,7,233.59,234.13,200,400,1,1,233.58,234.17,505,1,2,1,233.53,234.25,10,50,1,1,233.45,234.41,15,600,1,2,233.4,234.43,110,5,2,1,AAPL,-200.0,-200.0,-450.0,
2024-10-21 12:05:43.337912322+00:00,2024-10-21T12:05:43.338078299Z,10,2,38,C,B,4,233.63,28,130,165977,12020101,233.78,233.92,76,400,1,2,233.7,233.94,1200,200,1,1,233.66,233.95,1,29,1,1,233.65,233.98,18,44,1,3,233.59,234.0,200,154,1,7,233.58,234.13,505,400,2,1,233.53,234.17,10,1,1,1,233.45,234.25,15,50,1,1,233.4,234.41,110,600,2,2,233.39,234.43,10,5,1,1,AAPL,0.0,0.0,-450.0,
2024-10-21 12:05:43.337965586+00:00,2024-10-21T12:05:43.338131765Z,10,2,38,A,B,7,233.52,26,130,166179,12020102,233.78,233.92,76,400,1,2,233.7,233.94,1200,200,1,1,233.66,233.95,1,29,1,1,233.65,233.98,18,44,1,3,233.59,234.0,200,154,1,7,233.58,234.13,505,400,2,1,233.53,234.17,10,1,1,1,233.52,234.25,26,50,1,1,233.45,234.41,15,600,1,2,233.4,234.43,110,5,2,1,AAPL,0.0,0.0,-450.0,
2024-10-21 12:05:43.365778374+00:00,2024-10-21T12:05:43.365944776Z,10,2,38,A,B,4,233.59,200,130,166402,12020108,233.78,233.92,76,400,1,2,233.7,233.94,1200,200,1,1,233.66,233.95,1,29,1,1,233.65,233.98,18,44,1,3,233.59,234.0,400,154,2,7,233.58,234.13,505,400,2,1,233.53,234.17,10,1,1,1,233.52,234.25,26,50,1,1,233.45,234.41,15,600,1,2,233.4,234.43,110,5,2,1,AAPL,0.0,200.0,-450.0,
2024-10-21 12:05:43.393790686+00:00,2024-10-21T12:05:43.393956628Z,10,2,38,C,A,0,233.92,200,130,165942,12020113,233.78,233.92,76,200,1,1,233.7,233.94,1200,200,1,1,233.66,233.95,1,29,1,1,233.65,233.98,18,44,1,3,233.59,234.0,400,154,2,7,233.58,234.13,505,400,2,1,233.53,234.17,10,1,1,1,233.52,234.25,26,50,1,1,233.45,234.41,15,600,1,2,233.4,234.43,110,5,2,1,AAPL,200.0,200.0,-250.0,
2024-10-21 12:05:43.393803680+00:00,2024-10-21T12:05:43.393969995Z,10,2,38,A,A,0,233.88,200,130,166315,12020114,233.78,233.88,76,200,1,1,233.7,233.94,1200,200,1,1,233.66,233.95,1,29,1,1,233.65,233.98,18,44,1,3,233.59,234.0,400,154,2,7,233.58,234.13,505,400,2,1,233.53,234.17,10,1,1,1,233.52,234.25,26,50,1,1,233.45,234.41,15,600,1,2,233.4,234.43,110,5,2,1,AAPL,0.0,0.0,-250.0,
2024-10-21 12:05:43.596064460+00:00,2024-10-21T12:05:43.596230510Z,10,2,38,C,B,4,233.59,200,130,166050,12020213,233.78,233.88,76,200,1,1,233.7,233.94,1200,200,1,1,233.66,233.95,1,29,1,1,233.65,233.98,18,44,1,3,233.59,234.0,200,154,1,7,233.58,234.13,505,400,2,1,233.53,234.17,10,1,1,1,233.52,234.25,26,50,1,1,233.45,234.41,15,600,1,2,233.4,234.43,110,5,2,1,AAPL,0.0,-200.0,-250.0,
2024-10-21 12:05:43.596076460+00:00,2024-10-21T12:05:43.596242797Z,10,2,38,A,B,3,233.65,400,130,166337,12020214,233.78,233.88,76,200,1,1,233.7,233.94,1200,200,1,1,233.66,233.95,1,29,1,1,233.65,233.98,418,44,2,3,233.58,234.0,505,154,2,7,233.53,234.13,10,400,1,1,233.52,234.17,26,1,1,1,233.45,234.25,15,50,1,1,233.4,234.41,110,600,2,2,233.39,234.43,10,5,1,1,AAPL,0.0,400.0,-250.0,
2024-10-21 12:05:45.922885872+00:00,2024-10-21T12:05:45.923051933Z,10,2,38,C,B,6,233.52,26,130,166061,12021802,233.78,233.88,76,200,1,1,233.7,233.94,1200,200,1,1,233.66,233.95,1,29,1,1,233.65,233.98,418,44,2,3,233.58,234.0,505,154,2,7,233.53,234.13,10,400,1,1,233.45,234.17,15,1,1,1,233.4,234.25,110,50,2,1,233.39,234.41,10,600,1,2,233.31,234.43,110,5,2,1,AAPL,0.0,0.0,0.0,
2024-10-21 12:05:45.923016443+00:00,2024-10-21T12:05:45.923182693Z,10,2,38,A,B,4,233.58,29,130,166250,12021803,233.78,233.88,76,200,1,1,233.7,233.94,1200,200,1,1,233.66,233.95,1,29,1,1,233.65,233.98,418,44,2,3,233.58,234.0,534,154,3,7,233.53,234.13,10,400,1,1,233.45,234.17,15,1,1,1,233.4,234.25,110,50,2,1,233.39,234.41,10,600,1,2,233.31,234.43,110,5,2,1,AAPL,0.0,29.0,0.0,
2024-10-21 12:05:46.352758108+00:00,2024-10-21T12:05:46.352924753Z,10,2,38,A,B,1,233.76,100,130,166645,12022103,233.78,233.88,76,200,1,1,233.76,233.94,100,200,1,1,233.7,233.95,1200,29,1,1,233.66,233.98,1,44,1,3,233.65,234.0,418,154,2,7,233.58,234.13,534,400,3,1,233.53,234.17,10,1,1,1,233.45,234.25,15,50,1,1,233.4,234.41,110,600,2,2,233.39,234.43,10,5,1,1,AAPL,0.0,0.0,0.0,
2024-10-21 12:05:46.952418271+00:00,2024-10-21T12:05:46.952584387Z,10,2,38,C,A,0,233.88,200,130,166116,12022312,233.78,233.94,76,200,1,1,233.76,233.95,100,29,1,1,233.7,233.98,1200,44,1,3,233.66,234.0,1,154,1,7,233.65,234.13,418,400,2,1,233.58,234.17,534,1,3,1,233.53,234.25,10,50,1,1,233.45,234.41,15,600,1,2,233.4,234.43,110,5,2,1,233.39,234.5,10,63,1,4,AAPL,0.0,0.0,0.0,
2024-10-21 12:05:46.952433308+00:00,2024-10-21T12:05:46.952599898Z,10,2,38,A,A,0,233.93,400,130,166590,12022313,233.78,233.93,76,400,1,1,233.76,233.94,100,200,1,1,233.7,233.95,1200,29,1,1,233.66,233.98,1,44,1,3,233.65,234.0,418,154,2,7,233.58,234.13,534,400,3,1,233.53,234.17,10,1,1,1,233.45,234.25,15,50,1,1,233.4,234.41,110,600,2,2,233.39,234.43,10,5,1,1,AAPL,0.0,0.0,0.0,
2024-10-21 12:05:47.007021590+00:00,2024-10-21T12:05:47.007188854Z,10,2,38,A,B,3,233.68,200,130,167264,12022361,233.78,233.93,76,400,1,1,233.76,233.94,100,200,1,1,233.7,233.95,1200,29,1,1,233.68,233.98,200,44,1,3,233.66,234.0,1,154,1,7,233.65,234.13,18,400,1,1,233.58,234.17,534,1,3,1,233.53,234.25,10,50,1,1,233.45,234.41,15,600,1,2,233.4,234.43,110,5,2,1,AAPL,0.0,0.0,0.0,
2024-10-21 12:05:48.195531738+00:00,2024-10-21T12:05:48.195697508Z,10,2,38,C,A,0,233.93,400,130,165770,12023323,233.78,233.94,76,200,1,1,233.76,233.95,100,29,1,1,233.7,233.98,1200,44,1,3,233.68,234.0,200,154,1,7,233.66,234.13,1,400,1,1,233.65,234.17,18,1,1,1,233.58,234.25,534,50,3,1,233.53,234.41,10,600,1,2,233.45,234.43,15,5,1,1,233.4,234.5,110,63,2,4,AAPL,0.0,0.0,0.0,
2024-10-21 12:05:48.195615637+00:00,2024-10-21T12:05:48.195783198Z,10,2,38,T,A,0,233.78,76,0,167561,12023325,233.78,233.94,76,200,1,1,233.76,233.95,100,29,1,1,233.7,233.98,1200,44,1,3,233.68,234.0,200,154,1,7,233.66,234.13,1,400,1,1,233.65,234.17,18,1,1,1,233.58,234.25,534,50,3,1,233.53,234.41,10,600,1,2,233.45,234.43,15,5,1,1,233.4,234.5,110,63,2,4,AAPL,0.0,0.0,0.0,
2024-10-21 12:05:48.195615637+00:00,2024-10-21T12:05:48.195783198Z,10,2,38,T,A,0,233.76,100,130,167561,12023326,233.76,233.94,100,200,1,1,233.7,233.95,1200,29,1,1,233.68,233.98,200,44,1,3,233.66,234.0,1,154,1,7,233.65,234.13,18,400,1,1,233.58,234.17,534,1,3,1,233.53,234.25,10,50,1,1,233.45,234.41,15,600,1,2,233.4,234.43,110,5,2,1,233.39,234.5,10,63,1,4,AAPL,0.0,0.0,0.0,
2024-10-21 12:05:48.195615637+00:00,2024-10-21T12:05:48.195783198Z,10,2,38,C,B,0,233.76,100,130,167561,12023326,233.7,233.94,1200,200,1,1,233.68,233.95,200,29,1,1,233.66,233.98,1,44,1,3,233.65,234.0,18,154,1,7,233.58,234.13,534,400,3,1,233.53,234.17,10,1,1,1,233.45,234.25,15,50,1,1,233.4,234.41,110,600,2,2,233.39,234.43,10,5,1,1,233.31,234.5,110,63,2,4,AAPL,0.0,0.0,0.0,
2024-10-21 12:05:48.195638794+00:00,2024-10-21T12:05:48.195805043Z,10,2,38,A,A,0,233.85,100,130,166249,12023327,233.7,233.85,1200,100,1,1,233.68,233.94,200,200,1,1,233.66,233.95,1,29,1,1,233.65,233.98,18,44,1,3,233.58,234.0,534,154,3,7,233.53,234.13,10,400,1,1,233.45,234.17,15,1,1,1,233.4,234.25,110,50,2,1,233.39,234.41,10,600,1,2,233.31,234.43,110,5,2,1,AAPL,0.0,0.0,0.0,
2024-10-21 12:05:48.195643749+00:00,2024-10-21T12:05:48.195809855Z,10,2,38,A,A,1,233.9,100,130,166106,12023328,233.7,233.85,1200,100,1,1,233.68,233.9,200,100,1,1,233.66,233.94,1,200,1,1,233.65,233.95,18,29,1,1,233.58,233.98,534,44,3,3,233.53,234.0,10,154,1,7,233.45,234.13,15,400,1,1,233.4,234.17,110,1,2,1,233.39,234.25,10,50,1,1,233.31,234.41,110,600,2,2,AAPL,0.0,0.0,0.0,
2024-10-21 12:05:48.195651625+00:00,2024-10-21T12:05:48.195817817Z,10,2,38,A,A,2,233.91,100,130,166192,12023329,233.7,233.85,1200,100,1,1,233.68,233.9,200,100,1,1,233.66,233.91,1,100,1,1,233.65,233.94,18,200,1,1,233.58,233.95,534,29,3,1,233.53,233.98,10,44,1,3,233.45,234.0,15,154,1,7,233.4,234.13,110,400,2,1,233.39,234.17,10,1,1,1,233.31,234.25,110,50,2,1,AAPL,0.0,0.0,0.0,
2024-10-21 12:05:48.195652834+00:00,2024-10-21T12:05:48.195819428Z,10,2,38,A,A,0,233.85,33,130,166594,12023331,233.7,233.85,1200,133,1,2,233.68,233.9,200,200,1,2,233.66,233.91,1,100,1,1,233.65,233.94,18,200,1,1,233.58,233.95,534,29,3,1,233.53,233.98,10,44,1,3,233.45,234.0,15,154,1,7,233.4,234.13,110,400,2,1,233.39,234.17,10,1,1,1,233.31,234.25,110,50,2,1,AAPL,-33.0,-133.0,-33.0,
2024-10-21 12:05:48.195667975+00:00,2024-10-21T12:05:48.195835783Z,10,2,38,A,A,0,233.91,33,130,167808,12023333,233.7,233.84,1200,100,1,1,233.68,233.85,200,133,1,2,233.66,233.9,1,200,1,2,233.65,233.91,18,133,1,2,233.58,233.94,534,200,3,1,233.53,233.95,10,29,1,1,233.45,233.98,15,44,1,3,233.4,234.0,110,154,2,7,233.39,234.13,10,400,1,1,233.31,234.17,110,1,2,1,AAPL,0.0,0.0,-33.0,
2024-10-21 12:05:48.195671113+00:00,2024-10-21T12:05:48.195836860Z,10,2,38,C,B,1,233.68,200,130,165747,12023334,233.7,233.84,1200,100,1,1,233.66,233.85,1,133,1,2,233.65,233.9,18,200,1,2,233.58,233.91,534,133,3,2,233.53,233.94,10,200,1,1,233.45,233.95,15,29,1,1,233.4,233.98,110,44,2,3,233.39,234.0,10,154,1,7,233.31,234.13,110,400,2,1,233.3,234.17,100,1,1,1,AAPL,0.0,0.0,-33.0,
2024-10-21 12:05:48.195675914+00:00,2024-10-21T12:05:48.195841831Z,10,2,38,A,A,3,233.91,100,130,165917,12023335,233.7,233.84,1200,100,1,1,233.66,233.85,1,133,1,2,233.65,233.9,18,200,1,2,233.58,233.91,534,233,3,3,233.53,233.94,10,200,1,1,233.45,233.95,15,29,1,1,233.4,233.98,110,44,2,3,233.39,234.0,10,154,1,7,233.31,234.13,110,400,2,1,233.3,234.17,100,1,1,1,AAPL,0.0,-100.0,-33.0,
2024-10-21 12:05:48.195679038+00:00,2024-10-21T12:05:48.195845200Z,10,2,38,A,A,2,233.9,100,130,166162,12023336,233.7,233.84,1200,100,1,1,233.66,233.85,1,133,1,2,233.65,233.9,18,300,1,3,233.58,233.91,534,233,3,3,233.53,233.94,10,200,1,1,233.45,233.95,15,29,1,1,233.4,233.98,110,44,2,3,233.39,234.0,10,154,1,7,233.31,234.13,110,400,2,1,233.3,234.17,100,1,1,1,AAPL,0.0,-100.0,-33.0,
2024-10-21 12:05:48.195690635+00:00,2024-10-21T12:05:48.195856309Z,10,2,38,C,A,1,233.85,100,130,165674,12023338,233.7,233.84,1200,100,1,1,233.66,233.85,1,33,1,1,233.65,233.9,18,300,1,3,233.58,233.91,534,233,3,3,233.53,233.94,10,200,1,1,233.45,233.95,15,29,1,1,233.4,233.98,110,44,2,3,233.39,234.0,10,154,1,7,233.31,234.13,110,400,2,1,233.3,234.17,100,1,1,1,AAPL,0.0,100.0,-33.0,
2024-10-21 12:05:48.195701993+00:00,2024-10-21T12:05:48.195867603Z,10,2,38,C,A,2,233.9,100,130,165610,12023340,233.7,233.84,1200,100,1,1,233.66,233.85,1,33,1,1,233.65,233.9,18,200,1,2,233.58,233.91,534,233,3,3,233.53,233.94,10,200,1,1,233.45,233.95,15,29,1,1,233.4,233.98,110,44,2,3,233.39,234.0,10,154,1,7,233.31,234.13,110,400,2,1,233.3,234.17,100,1,1,1,AAPL,0.0,100.0,-33.0,
2024-10-21 12:05:48.195706051+00:00,2024-10-21T12:05:48.195872903Z,10,2,38,C,A,3,233.91,100,130,166852,12023341,233.7,233.84,1200,100,1,1,233.66,233.85,1,33,1,1,233.65,233.9,18,200,1,2,233.58,233.91,534,133,3,2,233.53,233.94,10,200,1,1,233.45,233.95,15,29,1,1,233.4,233.98,110,44,2,3,233.39,234.0,10,154,1,7,233.31,234.13,110,400,2,1,233.3,234.17,100,1,1,1,AAPL,0.0,100.0,-33.0,
2024-10-21 12:05:48.195771617+00:00,2024-10-21T12:05:48.195937493Z,10,2,38,C,A,3,233.91,100,130,165876,12023342,233.7,233.84,1200,100,1,1,233.66,233.85,1,33,1,1,233.65,233.9,18,200,1,2,233.58,233.91,534,33,3,1,233.53,233.94,10,200,1,1,233.45,233.95,15,29,1,1,233.4,233.98,110,44,2,3,233.39,234.0,10,154,1,7,233.31,234.13,110,400,2,1,233.3,234.17,100,1,1,1,AAPL,0.0,100.0,-33.0,
2024-10-21 12:05:48.195800135+00:00,2024-10-21T12:05:48.195966195Z,10,2,38,C,A,0,233.84,100,130,166060,12023344,233.7,233.85,1200,33,1,1,233.66,233.9,1,200,1,2,233.65,233.91,18,33,1,1,233.58,233.94,534,200,3,1,233.53,233.95,10,29,1,1,233.45,233.98,15,44,1,3,233.4,234.0,110,154,2,7,233.39,234.13,10,400,1,1,233.31,234.17,110,1,2,1,233.3,234.25,100,50,1,1,AAPL,0.0,0.0,-33.0,
2024-10-21 12:05:48.195848770+00:00,2024-10-21T12:05:48.196014405Z,10,2,38,C,A,1,233.9,100,130,165635,12023346,233.7,233.85,1200,33,1,1,233.66,233.9,1,100,1,1,233.65,233.91,18,33,1,1,233.58,233.94,534,200,3,1,233.53,233.95,10,29,1,1,233.45,233.98,15,44,1,3,233.4,234.0,110,154,2,7,233.39,234.13,10,400,1,1,233.31,234.17,110,1,2,1,233.3,234.25,100,50,1,1,AAPL,0.0,100.0,-33.0,
2024-10-21 12:05:48.195954138+00:00,2024-10-21T12:05:48.196120006Z,10,2,38,C,A,1,233.9,100,130,165868,12023347,233.7,233.85,1200,33,1,1,233.66,233.91,1,33,1,1,233.65,233.94,18,200,1,1,233.58,233.95,534,29,3,1,233.53,233.98,10,44,1,3,233.45,234.0,15,154,1,7,233.4,234.13,110,400,2,1,233.39,234.17,10,1,1,1,233.31,234.25,110,50,2,1,233.3,234.41,100,600,1,2,AAPL,0.0,0.0,-33.0,
2024-10-21 12:05:48.259822838+00:00,2024-10-21T12:05:48.259989271Z,10,2,38,A,B,3,233.59,400,130,166433,12023416,233.7,233.85,1200,33,1,1,233.66,233.91,1,33,1,1,233.65,233.94,18,200,1,1,233.59,233.95,400,29,1,1,233.58,233.98,534,44,3,3,233.53,234.0,10,154,1,7,233.45,234.13,15,400,1,1,233.4,234.17,110,1,2,1,233.39,234.25,10,50,1,1,233.31,234.41,110,600,2,2,AAPL,0.0,0.0,-33.0,
2024-10-21 12:05:48.263346529+00:00,2024-10-21T12:05:48.263512682Z,10,2,38,C,B,4,233.58,29,130,166153,12023419,233.7,233.85,1200,33,1,1,233.66,233.91,1,33,1,1,233.65,233.94,18,200,1,1,233.59,233.95,400,29,1,1,233.58,233.98,505,44,2,3,233.53,234.0,10,154,1,7,233.45,234.13,15,400,1,1,233.4,234.17,110,1,2,1,233.39,234.25,10,50,1,1,233.31,234.41,110,600,2,2,AAPL,0.0,-29.0,-33.0,
2024-10-21 12:05:48.297202075+00:00,2024-10-21T12:05:48.297368202Z,10,2,38,A,A,2,233.93,400,130,166127,12023433,233.7,233.85,1200,33,1,1,233.66,233.91,1,33,1,1,233.65,233.93,18,400,1,1,233.59,233.94,400,200,1,1,233.58,233.95,505,29,2,1,233.53,233.98,10,44,1,3,233.45,234.0,15,154,1,7,233.4,234.13,110,400,2,1,233.39,234.17,10,1,1,1,233.31,234.25,110,50,2,1,AAPL,0.0,0.0,-33.0,
2024-10-21 12:05:48.297231678+00:00,2024-10-21T12:05:48.297397398Z,10,2,38,C,A,1,233.91,33,130,165720,12023434,233.7,233.85,1200,33,1,1,233.66,233.93,1,400,1,1,233.65,233.94,18,200,1,1,233.59,233.95,400,29,1,1,233.58,233.98,505,44,2,3,233.53,234.0,10,154,1,7,233.45,234.13,15,400,1,1,233.4,234.17,110,1,2,1,233.39,234.25,10,50,1,1,233.31,234.41,110,600,2,2,AAPL,0.0,0.0,-33.0,
2024-10-21 12:05:48.313231819+00:00,2024-10-21T12:05:48.313398298Z,10,2,38,A,A,1,233.88,200,130,166479,12023436,233.7,233.85,1200,33,1,1,233.66,233.88,1,200,1,1,233.65,233.94,18,200,1,1,233.59,233.95,400,29,1,1,233.58,233.98,505,44,2,3,233.53,234.0,10,154,1,7,233.45,234.13,15,400,1,1,233.4,234.17,110,1,2,1,233.39,234.25,10,50,1,1,233.31,234.41,110,600,2,2,AAPL,0.0,0.0,-33.0,
2024-10-21 12:05:48.453765847+00:00,2024-10-21T12:05:48.453931984Z,10,2,38,C,A,0,233.85,33,130,166137,12023463,233.7,233.88,1200,200,1,1,233.66,233.94,1,200,1,1,233.65,233.95,18,29,1,1,233.59,233.98,400,44,1,3,233.58,234.0,505,154,2,7,233.53,234.13,10,400,1,1,233.45,234.17,15,1,1,1,233.4,234.25,110,50,2,1,233.39,234.41,10,600,1,2,233.31,234.43,110,5,2,1,AAPL,0.0,0.0,-33.0,
2024-10-21 12:05:48.461428130+00:00,2024-10-21T12:05:48.461595380Z,10,2,38,A,A,0,233.88,200,130,167250,12023464,233.7,233.88,1200,400,1,2,233.66,233.94,1,200,1,1,233.65,233.95,18,29,1,1,233.59,233.98,400,44,1,3,233.58,234.0,505,154,2,7,233.53,234.13,10,400,1,1,233.45,234.17,15,1,1,1,233.4,234.25,110,50,2,1,233.39,234.41,10,600,1,2,233.31,234.43,110,5,2,1,AAPL,-200.0,-200.0,-233.0,
2024-10-21 12:05:48.825644162+00:00,2024-10-21T12:05:48.825810960Z,10,2,38,A,B,3,233.62,200,130,166798,12023548,233.7,233.88,1200,400,1,2,233.66,233.94,1,200,1,1,233.65,233.95,18,29,1,1,233.62,233.98,200,44,1,3,233.58,234.0,505,154,2,7,233.53,234.13,10,400,1,1,233.45,234.17,15,1,1,1,233.4,234.25,110,50,2,1,233.39,234.41,10,600,1,2,233.31,234.43,110,5,2,1,AAPL,0.0,0.0,-233.0,
2024-10-21 12:05:49.592099813+00:00,2024-10-21T12:05:49.592266377Z,10,2,38,A,B,2,233.65,200,130,166564,12023911,233.7,233.88,1200,400,1,2,233.66,233.94,1,200,1,1,233.65,233.95,218,29,2,1,233.58,233.98,505,44,2,3,233.53,234.0,10,154,1,7,233.45,234.13,15,400,1,1,233.4,234.17,110,1,2,1,233.39,234.25,10,50,1,1,233.31,234.41,110,600,2,2,233.3,234.43,100,5,1,1,AAPL,0.0,200.0,0.0,
2024-10-21 12:05:52.517180690+00:00,2024-10-21T12:05:52.517347120Z,10,2,38,A,B,4,233.57,29,130,166430,12025554,233.7,233.88,1200,400,1,2,233.66,233.94,1,200,1,1,233.65,233.95,218,29,2,1,233.58,233.98,505,44,2,3,233.57,234.0,29,154,1,7,233.53,234.13,10,400,1,1,233.45,234.17,15,1,1,1,233.4,234.25,110,50,2,1,233.39,234.41,10,600,1,2,233.31,234.43,110,5,2,1,AAPL,0.0,0.0,0.0,
2024-10-21 12:05:55.930110286+00:00,2024-10-21T12:05:55.930276631Z,10,2,38,C,B,2,233.65,18,130,166345,12028586,233.7,233.88,1200,400,1,2,233.66,233.94,1,200,1,1,233.65,233.95,200,29,1,1,233.58,233.98,505,44,2,3,233.57,234.0,29,154,1,7,233.53,234.13,10,400,1,1,233.45,234.17,15,1,1,1,233.4,234.25,110,50,2,1,233.39,234.41,10,600,1,2,233.31,234.43,110,5,2,1,AAPL,0.0,-18.0,0.0,
2024-10-21 12:05:57.922929284+00:00,2024-10-21T12:05:57.923095285Z,10,2,38,C,B,4,233.57,29,130,166001,12029987,233.7,233.88,1200,400,1,2,233.66,233.94,1,200,1,1,233.65,233.95,200,29,1,1,233.58,233.98,505,44,2,3,233.53,234.0,10,154,1,7,233.45,234.13,15,400,1,1,233.4,234.17,110,1,2,1,233.39,234.25,10,50,1,1,233.31,234.41,110,600,2,2,233.3,234.43,100,5,1,1,AAPL,0.0,0.0,0.0,
2024-10-21 12:05:57.923066098+00:00,2024-10-21T12:05:57.923232470Z,10,2,38,A,B,3,233.58,30,130,166372,12029988,233.7,233.88,1200,400,1,2,233.66,233.94,1,200,1,1,233.65,233.95,200,29,1,1,233.58,233.98,535,44,3,3,233.53,234.0,10,154,1,7,233.45,234.13,15,400,1,1,233.4,234.17,110,1,2,1,233.39,234.25,10,50,1,1,233.31,234.41,110,600,2,2,233.3,234.43,100,5,1,1,AAPL,0.0,30.0,0.0,
2024-10-21 12:06:05.427139071+00:00,2024-10-21T12:06:05.427305884Z,10,2,38,A,A,0,233.8,5,130,166813,12035523,233.7,233.8,1200,5,1,1,233.66,233.88,1,400,1,2,233.65,233.94,200,200,1,1,233.58,233.95,535,29,3,1,233.53,233.98,10,44,1,3,233.45,234.0,15,154,1,7,233.4,234.13,110,400,2,1,233.39,234.17,10,1,1,1,233.31,234.25,110,50,2,1,233.3,234.41,100,600,1,2,AAPL,0.0,0.0,0.0,
2024-10-21 12:06:06.690796307+00:00,2024-10-21T12:06:06.690962423Z,10,2,38,C,A,1,233.88,200,130,166116,12036944,233.7,233.8,1200,5,1,1,233.66,233.88,1,200,1,1,233.65,233.94,200,200,1,1,233.58,233.95,535,29,3,1,233.53,233.98,10,44,1,3,233.45,234.0,15,154,1,7,233.4,234.13,110,400,2,1,233.39,234.17,10,1,1,1,233.31,234.25,110,50,2,1,233.3,234.41,100,600,1,2,AAPL,0.0,200.0,0.0,
2024-10-21 12:06:06.690808686+00:00,2024-10-21T12:06:06.690975076Z,10,2,38,A,A,1,233.87,200,130,166390,12036945,233.7,233.8,1200,5,1,1,233.66,233.87,1,200,1,1,233.65,233.94,200,200,1,1,233.58,233.95,535,29,3,1,233.53,233.98,10,44,1,3,233.45,234.0,15,154,1,7,233.4,234.13,110,400,2,1,233.39,234.17,10,1,1,1,233.31,234.25,110,50,2,1,233.3,234.41,100,600,1,2,AAPL,0.0,0.0,0.0,
2024-10-21 12:06:06.701910843+00:00,2024-10-21T12:06:06.702077630Z,10,2,38,C,A,3,233.95,29,130,166787,12037042,233.7,233.8,1200,5,1,1,233.66,233.87,1,200,1,1,233.65,233.94,200,200,1,1,233.58,233.98,535,44,3,3,233.53,234.0,10,154,1,7,233.45,234.13,15,400,1,1,233.4,234.17,110,1,2,1,233.39,234.25,10,50,1,1,233.31,234.41,110,600,2,2,233.3,234.43,100,5,1,1,AAPL,0.0,0.0,0.0,
2024-10-21 12:06:06.701967763+00:00,2024-10-21T12:06:06.702133954Z,10,2,38,A,A,2,233.94,26,130,166191,12037043,233.7,233.8,1200,5,1,1,233.66,233.87,1,200,1,1,233.65,233.94,200,226,1,2,233.58,233.98,535,44,3,3,233.53,234.0,10,154,1,7,233.45,234.13,15,400,1,1,233.4,234.17,110,1,2,1,233.39,234.25,10,50,1,1,233.31,234.41,110,600,2,2,233.3,234.43,100,5,1,1,AAPL,0.0,-26.0,0.0,
2024-10-21 12:06:06.737555073+00:00,2024-10-21T12:06:06.737721359Z,10,2,38,C,B,2,233.65,200,130,166286,12037240,233.7,233.8,1200,5,1,1,233.66,233.87,1,200,1,1,233.58,233.94,535,226,3,2,233.53,233.98,10,44,1,3,233.45,234.0,15,154,1,7,233.4,234.13,110,400,2,1,233.39,234.17,10,1,1,1,233.31,234.25,110,50,2,1,233.3,234.41,100,600,1,2,233.25,234.43,55,5,2,1,AAPL,0.0,0.0,0.0,
2024-10-21 12:06:06.737568257+00:00,2024-10-21T12:06:06.737734292Z,10,2,38,A,B,2,233.63,200,130,166035,12037241,233.7,233.8,1200,5,1,1,233.66,233.87,1,200,1,1,233.63,233.94,200,226,1,2,233.58,233.98,535,44,3,3,233.53,234.0,10,154,1,7,233.45,234.13,15,400,1,1,233.4,234.17,110,1,2,1,233.39,234.25,10,50,1,1,233.31,234.41,110,600,2,2,233.3,234.43,100,5,1,1,AAPL,0.0,0.0,0.0,
2024-10-21 12:06:06.784651971+00:00,2024-10-21T12:06:06.784818334Z,10,2,38,A,B,2,233.63,200,130,166363,12037447,233.7,233.8,1200,5,1,1,233.66,233.87,1,200,1,1,233.63,233.94,400,226,2,2,233.58,233.98,535,44,3,3,233.53,234.0,10,154,1,7,233.45,234.13,15,400,1,1,233.4,234.17,110,1,2,1,233.39,234.25,10,50,1,1,233.31,234.41,110,600,2,2,233.3,234.43,100,5,1,1,AAPL,0.0,200.0,0.0,
2024-10-21 12:06:06.795491217+00:00,2024-10-21T12:06:06.795657010Z,10,2,38,C,B,2,233.63,200,130,165793,12037500,233.7,233.8,1200,5,1,1,233.66,233.87,1,200,1,1,233.63,233.94,200,226,1,2,233.58,233.98,535,44,3,3,233.53,234.0,10,154,1,7,233.45,234.13,15,400,1,1,233.4,234.17,110,1,2,1,233.39,234.25,10,50,1,1,233.31,234.41,110,600,2,2,233.3,234.43,100,5,1,1,AAPL,0.0,-200.0,0.0,
2024-10-21 12:06:06.795502438+00:00,2024-10-21T12:06:06.795669136Z,10,2,38,A,B,2,233.64,200,130,166698,12037501,233.7,233.8,1200,5,1,1,233.66,233.87,1,200,1,1,233.64,233.94,200,226,1,2,233.58,233.98,535,44,3,3,233.53,234.0,10,154,1,7,233.45,234.13,15,400,1,1,233.4,234.17,110,1,2,1,233.39,234.25,10,50,1,1,233.31,234.41,110,600,2,2,233.3,234.43,100,5,1,1,AAPL,0.0,0.0,0.0,
2024-10-21 12:06:07.734697882+00:00,2024-10-21T12:06:07.734864255Z,10,2,38,A,B,0,233.74,100,130,166373,12038529,233.74,233.8,100,5,1,1,233.7,233.87,1200,200,1,1,233.66,233.94,1,226,1,2,233.64,233.98,200,44,1,3,233.58,234.0,535,154,3,7,233.53,234.13,10,400,1,1,233.45,234.17,15,1,1,1,233.4,234.25,110,50,2,1,233.39,234.41,10,600,1,2,233.31,234.43,110,5,2,1,AAPL,0.0,0.0,0.0,
2024-10-21 12:06:07.735102284+00:00,2024-10-21T12:06:07.735268195Z,10,2,38,C,B,0,233.74,100,130,165911,12038532,233.7,233.8,1200,5,1,1,233.66,233.87,1,200,1,1,233.64,233.94,200,226,1,2,233.58,233.98,535,44,3,3,233.53,234.0,10,154,1,7,233.45,234.13,15,400,1,1,233.4,234.17,110,1,2,1,233.39,234.25,10,50,1,1,233.31,234.41,110,600,2,2,233.3,234.43,100,5,1,1,AAPL,0.0,0.0,0.0,
2024-10-21 12:06:07.797318931+00:00,2024-10-21T12:06:07.797485159Z,10,2,38,C,A,2,233.94,26,130,166228,12038578,233.7,233.8,1200,5,1,1,233.66,233.87,1,200,1,1,233.64,233.94,200,200,1,1,233.58,233.98,535,44,3,3,233.53,234.0,10,154,1,7,233.45,234.13,15,400,1,1,233.4,234.17,110,1,2,1,233.39,234.25,10,50,1,1,233.31,234.41,110,600,2,2,233.3,234.43,100,5,1,1,AAPL,0.0,26.0,0.0,
2024-10-21 12:06:07.797428592+00:00,2024-10-21T12:06:07.797594793Z,10,2,38,A,A,2,233.93,29,130,166201,12038579,233.7,233.8,1200,5,1,1,233.66,233.87,1,200,1,1,233.64,233.93,200,29,1,1,233.58,233.94,535,200,3,1,233.53,233.98,10,44,1,3,233.45,234.0,15,154,1,7,233.4,234.13,110,400,2,1,233.39,234.17,10,1,1,1,233.31,234.25,110,50,2,1,233.3,234.41,100,600,1,2,AAPL,0.0,0.0,0.0,
2024-10-21 12:06:07.802356464+00:00,2024-10-21T12:06:07.802522549Z,10,2,38,C,A,1,233.87,200,130,166085,12038584,233.7,233.8,1200,5,1,1,233.66,233.93,1,29,1,1,233.64,233.94,200,200,1,1,233.58,233.98,535,44,3,3,233.53,234.0,10,154,1,7,233.45,234.13,15,400,1,1,233.4,234.17,110,1,2,1,233.39,234.25,10,50,1,1,233.31,234.41,110,600,2,2,233.3,234.43,100,5,1,1,AAPL,0.0,0.0,0.0,
2024-10-21 12:06:07.802368533+00:00,2024-10-21T12:06:07.802534762Z,10,2,38,A,A,1,233.92,200,130,166229,12038585,233.7,233.8,1200,5,1,1,233.66,233.92,1,200,1,1,233.64,233.93,200,29,1,1,233.58,233.94,535,200,3,1,233.53,233.98,10,44,1,3,233.45,234.0,15,154,1,7,233.4,234.13,110,400,2,1,233.39,234.17,10,1,1,1,233.31,234.25,110,50,2,1,233.3,234.41,100,600,1,2,AAPL,0.0,0.0,0.0,
2024-10-21 12:06:07.805948070+00:00,2024-10-21T12:06:07.806114373Z,10,2,38,A,B,2,233.64,200,130,166303,12038589,233.7,233.8,1200,5,1,1,233.66,233.92,1,200,1,1,233.64,233.93,400,29,2,1,233.58,233.94,535,200,3,1,233.53,233.98,10,44,1,3,233.45,234.0,15,154,1,7,233.4,234.13,110,400,2,1,233.39,234.17,10,1,1,1,233.31,234.25,110,50,2,1,233.3,234.41,100,600,1,2,AAPL,0.0,200.0,0.0,
2024-10-21 12:06:07.846428844+00:00,2024-10-21T12:06:07.846595428Z,10,2,38,A,A,1,233.92,200,130,166584,12038617,233.7,233.8,1200,5,1,1,233.66,233.92,1,400,1,2,233.64,233.93,400,29,2,1,233.58,233.94,535,200,3,1,233.53,233.98,10,44,1,3,233.45,234.0,15,154,1,7,233.4,234.13,110,400,2,1,233.39,234.17,10,1,1,1,233.31,234.25,110,50,2,1,233.3,234.41,100,600,1,2,AAPL,0.0,-200.0,0.0,
2024-10-21 12:06:07.848909781+00:00,2024-10-21T12:06:07.849075752Z,10,2,38,C,B,2,233.64,200,130,165971,12038620,233.7,233.8,1200,5,1,1,233.66,233.92,1,400,1,2,233.64,233.93,200,29,1,1,233.58,233.94,535,200,3,1,233.53,233.98,10,44,1,3,233.45,234.0,15,154,1,7,233.4,234.13,110,400,2,1,233.39,234.17,10,1,1,1,233.31,234.25,110,50,2,1,233.3,234.41,100,600,1,2,AAPL,0.0,-200.0,0.0,
2024-10-21 12:06:07.896522805+00:00,2024-10-21T12:06:07.896688660Z,10,2,38,C,A,1,233.92,200,130,165855,12038640,233.7,233.8,1200,5,1,1,233.66,233.92,1,200,1,1,233.64,233.93,200,29,1,1,233.58,233.94,535,200,3,1,233.53,233.98,10,44,1,3,233.45,234.0,15,154,1,7,233.4,234.13,110,400,2,1,233.39,234.17,10,1,1,1,233.31,234.25,110,50,2,1,233.3,234.41,100,600,1,2,AAPL,0.0,200.0,0.0,
2024-10-21 12:06:07.896534876+00:00,2024-10-21T12:06:07.896701378Z,10,2,38,A,A,1,233.89,200,130,166502,12038641,233.7,233.8,1200,5,1,1,233.66,233.89,1,200,1,1,233.64,233.93,200,29,1,1,233.58,233.94,535,200,3,1,233.53,233.98,10,44,1,3,233.45,234.0,15,154,1,7,233.4,234.13,110,400,2,1,233.39,234.17,10,1,1,1,233.31,234.25,110,50,2,1,233.3,234.41,100,600,1,2,AAPL,0.0,0.0,0.0,
2024-10-21 12:06:08.694025455+00:00,2024-10-21T12:06:08.694191792Z,10,2,38,A,A,1,233.88,200,130,166337,12039365,233.7,233.8,1200,5,1,1,233.66,233.88,1,200,1,1,233.64,233.93,200,29,1,1,233.58,233.94,535,200,3,1,233.53,233.98,10,44,1,3,233.45,234.0,15,154,1,7,233.4,234.13,110,400,2,1,233.39,234.17,10,1,1,1,233.31,234.25,110,50,2,1,233.3,234.41,100,600,1,2,AAPL,0.0,0.0,0.0,
2024-10-21 12:06:17.680964159+00:00,2024-10-21T12:06:17.681130355Z,10,2,38,C,B,3,233.58,30,130,166196,12045252,233.7,233.8,1200,5,1,1,233.66,233.88,1,200,1,1,233.64,233.93,200,29,1,1,233.58,233.94,505,200,2,1,233.53,233.98,10,44,1,3,233.45,234.0,15,154,1,7,233.4,234.13,110,400,2,1,233.39,234.17,10,1,1,1,233.31,234.25,110,50,2,1,233.3,234.41,100,600,1,2,AAPL,0.0,-30.0,0.0,
2024-10-21 12:06:17.681006872+00:00,2024-10-21T12:06:17.681173092Z,10,2,38,A,B,4,233.55,29,130,166220,12045253,233.7,233.8,1200,5,1,1,233.66,233.88,1,200,1,1,233.64,233.93,200,29,1,1,233.58,233.94,505,200,2,1,233.55,233.98,29,44,1,3,233.53,234.0,10,154,1,7,233.45,234.13,15,400,1,1,233.4,234.17,110,1,2,1,233.39,234.25,10,50,1,1,233.31,234.41,110,600,2,2,AAPL,0.0,0.0,0.0,
2024-10-21 12:06:17.696105981+00:00,2024-10-21T12:06:17.696271989Z,10,2,38,C,A,2,233.93,29,130,166008,12045305,233.7,233.8,1200,5,1,1,233.66,233.88,1,200,1,1,233.64,233.94,200,200,1,1,233.58,233.98,505,44,2,3,233.55,234.0,29,154,1,7,233.53,234.13,10,400,1,1,233.45,234.17,15,1,1,1,233.4,234.25,110,50,2,1,233.39,234.41,10,600,1,2,233.31,234.43,110,5,2,1,AAPL,0.0,0.0,0.0,
2024-10-21 12:06:18.819178890+00:00,2024-10-21T12:06:18.819345163Z,10,2,38,A,B,0,233.74,100,130,166273,12045986,233.74,233.8,100,5,1,1,233.7,233.88,1200,200,1,1,233.66,233.94,1,200,1,1,233.64,233.98,200,44,1,3,233.58,234.0,505,154,2,7,233.55,234.13,29,400,1,1,233.53,234.17,10,1,1,1,233.45,234.25,15,50,1,1,233.4,234.41,110,600,2,2,233.39,234.43,10,5,1,1,AAPL,0.0,0.0,0.0,
2024-10-21 12:06:18.819594049+00:00,2024-10-21T12:06:18.819759953Z,10,2,38,C,B,0,233.74,100,130,165904,12045987,233.7,233.8,1200,5,1,1,233.66,233.88,1,200,1,1,233.64,233.94,200,200,1,1,233.58,233.98,505,44,2,3,233.55,234.0,29,154,1,7,233.53,234.13,10,400,1,1,233.45,234.17,15,1,1,1,233.4,234.25,110,50,2,1,233.39,234.41,10,600,1,2,233.31,234.43,110,5,2,1,AAPL,0.0,0.0,0.0,
2024-10-21 12:06:18.820239929+00:00,2024-10-21T12:06:18.820405900Z,10,2,38,C,B,2,233.64,200,130,165971,12045988,233.7,233.8,1200,5,1,1,233.66,233.88,1,200,1,1,233.58,233.94,505,200,2,1,233.55,233.98,29,44,1,3,233.53,234.0,10,154,1,7,233.45,234.13,15,400,1,1,233.4,234.17,110,1,2,1,233.39,234.25,10,50,1,1,233.31,234.41,110,600,2,2,233.3,234.43,100,5,1,1,AAPL,0.0,0.0,0.0,
2024-10-21 12:06:18.821093344+00:00,2024-10-21T12:06:18.821259996Z,10,2,38,C,A,0,233.8,5,130,166652,12045989,233.7,233.88,1200,200,1,1,233.66,233.94,1,200,1,1,233.58,233.98,505,44,2,3,233.55,234.0,29,154,1,7,233.53,234.13,10,400,1,1,233.45,234.17,15,1,1,1,233.4,234.25,110,50,2,1,233.39,234.41,10,600,1,2,233.31,234.43,110,5,2,1,233.3,234.5,100,63,1,4,AAPL,0.0,0.0,0.0,
2024-10-21 12:06:18.873162917+00:00,2024-10-21T12:06:18.873329140Z,10,2,38,A,B,2,233.63,200,130,166223,12046004,233.7,233.88,1200,200,1,1,233.66,233.94,1,200,1,1,233.63,233.98,200,44,1,3,233.58,234.0,505,154,2,7,233.55,234.13,29,400,1,1,233.53,234.17,10,1,1,1,233.45,234.25,15,50,1,1,233.4,234.41,110,600,2,2,233.39,234.43,10,5,1,1,233.31,234.5,110,63,2,4,AAPL,0.0,0.0,0.0,
2024-10-21 12:06:18.892219598+00:00,2024-10-21T12:06:18.892386164Z,10,2,38,C,A,0,233.88,200,130,166566,12046028,233.7,233.94,1200,200,1,1,233.66,233.98,1,44,1,3,233.63,234.0,200,154,1,7,233.58,234.13,505,400,2,1,233.55,234.17,29,1,1,1,233.53,234.25,10,50,1,1,233.45,234.41,15,600,1,2,233.4,234.43,110,5,2,1,233.39,234.5,10,63,1,4,233.31,234.75,110,1,2,1,AAPL,0.0,0.0,0.0,
2024-10-21 12:06:18.892231335+00:00,2024-10-21T12:06:18.892397427Z,10,2,38,A,A,0,233.91,400,130,166092,12046029,233.7,233.91,1200,400,1,1,233.66,233.94,1,200,1,1,233.63,233.98,200,44,1,3,233.58,234.0,505,154,2,7,233.55,234.13,29,400,1,1,233.53,234.17,10,1,1,1,233.45,234.25,15,50,1,1,233.4,234.41,110,600,2,2,233.39,234.43,10,5,1,1,233.31,234.5,110,63,2,4,AAPL,0.0,0.0,0.0,
2024-10-21 12:06:18.892290341+00:00,2024-10-21T12:06:18.892456423Z,10,2,38,C,A,0,233.91,200,130,166082,12046031,233.7,233.91,1200,200,1,1,233.66,233.94,1,200,1,1,233.63,233.98,200,44,1,3,233.58,234.0,505,154,2,7,233.55,234.13,29,400,1,1,233.53,234.17,10,1,1,1,233.45,234.25,15,50,1,1,233.4,234.41,110,600,2,2,233.39,234.43,10,5,1,1,233.31,234.5,110,63,2,4,AAPL,200.0,200.0,200.0,
2024-10-21 12:06:19.678000980+00:00,2024-10-21T12:06:19.678167259Z,10,2,38,A,B,2,233.63,200,130,166279,12046958,233.7,233.91,1200,200,1,1,233.66,233.94,1,200,1,1,233.63,233.98,400,44,2,3,233.58,234.0,505,154,2,7,233.55,234.13,29,400,1,1,233.53,234.17,10,1,1,1,233.45,234.25,15,50,1,1,233.4,234.41,110,600,2,2,233.39,234.43,10,5,1,1,233.31,234.5,110,63,2,4,AAPL,0.0,200.0,200.0,
2024-10-21 12:06:19.696727473+00:00,2024-10-21T12:06:19.696893580Z,10,2,38,C,B,2,233.63,200,130,166107,12047035,233.7,233.91,1200,200,1,1,233.66,233.94,1,200,1,1,233.63,233.98,200,44,1,3,233.58,234.0,505,154,2,7,233.55,234.13,29,400,1,1,233.53,234.17,10,1,1,1,233.45,234.25,15,50,1,1,233.4,234.41,110,600,2,2,233.39,234.43,10,5,1,1,233.31,234.5,110,63,2,4,AAPL,0.0,-200.0,200.0,
2024-10-21 12:06:19.696738939+00:00,2024-10-21T12:06:19.696905409Z,10,2,38,A,B,2,233.64,400,130,166470,12047036,233.7,233.91,1200,200,1,1,233.66,233.94,1,200,1,1,233.64,233.98,400,44,1,3,233.58,234.0,505,154,2,7,233.55,234.13,29,400,1,1,233.53,234.17,10,1,1,1,233.45,234.25,15,50,1,1,233.4,234.41,110,600,2,2,233.39,234.43,10,5,1,1,233.31,234.5,110,63,2,4,AAPL,0.0,0.0,200.0,
2024-10-21 12:06:22.179031254+00:00,2024-10-21T12:06:22.179197708Z,10,2,38,C,B,2,233.64,200,130,166454,12050374,233.7,233.91,1200,200,1,1,233.66,233.94,1,200,1,1,233.64,233.98,200,44,1,3,233.58,234.0,505,154,2,7,233.55,234.13,29,400,1,1,233.53,234.17,10,1,1,1,233.45,234.25,15,50,1,1,233.4,234.41,110,600,2,2,233.39,234.43,10,5,1,1,233.31,234.5,110,63,2,4,AAPL,0.0,-200.0,0.0,
2024-10-21 12:06:29.265587376+00:00,2024-10-21T12:06:29.265753510Z,10,2,38,C,B,4,233.55,29,130,166134,12057133,233.7,233.91,1200,200,1,1,233.66,233.94,1,200,1,1,233.64,233.98,200,44,1,3,233.58,234.0,505,154,2,7,233.53,234.13,10,400,1,1,233.45,234.17,15,1,1,1,233.4,234.25,110,50,2,1,233.39,234.41,10,600,1,2,233.31,234.43,110,5,2,1,233.3,234.5,100,63,1,4,AAPL,0.0,0.0,0.0,
2024-10-21 12:06:29.265653484+00:00,2024-10-21T12:06:29.265819664Z,10,2,38,A,B,4,233.56,30,130,166180,12057134,233.7,233.91,1200,200,1,1,233.66,233.94,1,200,1,1,233.64,233.98,200,44,1,3,233.58,234.0,505,154,2,7,233.56,234.13,30,400,1,1,233.53,234.17,10,1,1,1,233.45,234.25,15,50,1,1,233.4,234.41,110,600,2,2,233.39,234.43,10,5,1,1,233.31,234.5,110,63,2,4,AAPL,0.0,0.0,0.0,
2024-10-21 12:06:29.265699161+00:00,2024-10-21T12:06:29.265865941Z,10,2,38,A,A,1,233.94,28,130,166780,12057136,233.7,233.91,1200,200,1,1,233.66,233.94,1,228,1,2,233.64,233.98,200,44,1,3,233.58,234.0,505,154,2,7,233.56,234.13,30,400,1,1,233.53,234.17,10,1,1,1,233.45,234.25,15,50,1,1,233.4,234.41,110,600,2,2,233.39,234.43,10,5,1,1,233.31,234.5,110,63,2,4,AAPL,0.0,-28.0,0.0,
2024-10-21 12:06:31.862439229+00:00,2024-10-21T12:06:31.862605353Z,10,2,38,C,B,4,233.56,30,130,166124,12059004,233.7,233.91,1200,200,1,1,233.66,233.94,1,228,1,2,233.64,233.98,200,44,1,3,233.58,234.0,505,154,2,7,233.53,234.13,10,400,1,1,233.45,234.17,15,1,1,1,233.4,234.25,110,50,2,1,233.39,234.41,10,600,1,2,233.31,234.43,110,5,2,1,233.3,234.5,100,63,1,4,AAPL,0.0,0.0,0.0,
2024-10-21 12:06:31.862509699+00:00,2024-10-21T12:06:31.862676130Z,10,2,38,A,B,4,233.57,27,130,166431,12059008,233.7,233.91,1200,200,1,1,233.66,233.94,1,228,1,2,233.64,233.98,200,44,1,3,233.58,234.0,505,154,2,7,233.57,234.13,27,400,1,1,233.53,234.17,10,1,1,1,233.45,234.25,15,50,1,1,233.4,234.41,110,600,2,2,233.39,234.43,10,5,1,1,233.31,234.5,110,63,2,4,AAPL,0.0,0.0,0.0,
2024-10-21 12:06:39.032886978+00:00,2024-10-21T12:06:39.033053296Z,10,2,38,C,A,0,233.91,200,130,166318,12066080,233.7,233.94,1200,228,1,2,233.66,233.98,1,44,1,3,233.64,234.0,200,154,1,7,233.58,234.13,505,400,2,1,233.57,234.17,27,1,1,1,233.53,234.25,10,50,1,1,233.45,234.41,15,600,1,2,233.4,234.43,110,5,2,1,233.39,234.5,10,63,1,4,233.31,234.75,110,1,2,1,AAPL,0.0,0.0,0.0,
2024-10-21 12:06:39.137156502+00:00,2024-10-21T12:06:39.137323341Z,10,2,38,A,A,0,233.92,200,130,166839,12066185,233.7,233.92,1200,200,1,1,233.66,233.94,1,228,1,2,233.64,233.98,200,44,1,3,233.58,234.0,505,154,2,7,233.57,234.13,27,400,1,1,233.53,234.17,10,1,1,1,233.45,234.25,15,50,1,1,233.4,234.41,110,600,2,2,233.39,234.43,10,5,1,1,233.31,234.5,110,63,2,4,AAPL,0.0,0.0,0.0,
2024-10-21 12:06:46.758024329+00:00,2024-10-21T12:06:46.758190934Z,10,2,38,A,B,2,233.64,200,130,166605,12071674,233.7,233.92,1200,200,1,1,233.66,233.94,1,228,1,2,233.64,233.98,400,44,2,3,233.58,234.0,505,154,2,7,233.57,234.13,27,400,1,1,233.53,234.17,10,1,1,1,233.45,234.25,15,50,1,1,233.4,234.41,110,600,2,2,233.39,234.43,10,5,1,1,233.31,234.5,110,63,2,4,AAPL,0.0,200.0,0.0,
2024-10-21 12:06:46.812855420+00:00,2024-10-21T12:06:46.813021764Z,10,2,38,C,B,2,233.64,200,130,166344,12071825,233.7,233.92,1200,200,1,1,233.66,233.94,1,228,1,2,233.64,233.98,200,44,1,3,233.58,234.0,505,154,2,7,233.57,234.13,27,400,1,1,233.53,234.17,10,1,1,1,233.45,234.25,15,50,1,1,233.4,234.41,110,600,2,2,233.39,234.43,10,5,1,1,233.31,234.5,110,63,2,4,AAPL,0.0,-200.0,0.0,
2024-10-21 12:06:46.812867723+00:00,2024-10-21T12:06:46.813033905Z,10,2,38,A,B,2,233.65,200,130,166182,12071826,233.7,233.92,1200,200,1,1,233.66,233.94,1,228,1,2,233.65,233.98,200,44,1,3,233.58,234.0,505,154,2,7,233.57,234.13,27,400,1,1,233.53,234.17,10,1,1,1,233.45,234.25,15,50,1,1,233.4,234.41,110,600,2,2,233.39,234.43,10,5,1,1,233.31,234.5,110,63,2,4,AAPL,0.0,0.0,0.0,
2024-10-21 12:06:46.863385247+00:00,2024-10-21T12:06:46.863551302Z,10,2,38,C,B,4,233.57,27,130,166055,12072246,233.7,233.92,1200,200,1,1,233.66,233.94,1,228,1,2,233.65,233.98,200,44,1,3,233.58,234.0,505,154,2,7,233.53,234.13,10,400,1,1,233.45,234.17,15,1,1,1,233.4,234.25,110,50,2,1,233.39,234.41,10,600,1,2,233.31,234.43,110,5,2,1,233.3,234.5,100,63,1,4,AAPL,0.0,0.0,0.0,
2024-10-21 12:06:46.888617346+00:00,2024-10-21T12:06:46.888783692Z,10,2,38,A,B,3,233.58,26,130,166346,12072288,233.7,233.92,1200,200,1,1,233.66,233.94,1,228,1,2,233.65,233.98,200,44,1,3,233.58,234.0,531,154,3,7,233.53,234.13,10,400,1,1,233.45,234.17,15,1,1,1,233.4,234.25,110,50,2,1,233.39,234.41,10,600,1,2,233.31,234.43,110,5,2,1,233.3,234.5,100,63,1,4,AAPL,0.0,26.0,0.0,
2024-10-21 12:06:48.285146479+00:00,2024-10-21T12:06:48.285314626Z,10,2,38,C,A,0,233.92,200,130,168147,12073283,233.7,233.94,1200,228,1,2,233.66,233.98,1,44,1,3,233.65,234.0,200,154,1,7,233.58,234.13,531,400,3,1,233.53,234.17,10,1,1,1,233.45,234.25,15,50,1,1,233.4,234.41,110,600,2,2,233.39,234.43,10,5,1,1,233.31,234.5,110,63,2,4,233.3,234.75,100,1,1,1,AAPL,0.0,0.0,0.0,
2024-10-21 12:06:48.317330539+00:00,2024-10-21T12:06:48.317496644Z,10,2,38,A,A,0,233.93,200,130,166105,12073312,233.7,233.93,1200,200,1,1,233.66,233.94,1,228,1,2,233.65,233.98,200,44,1,3,233.58,234.0,531,154,3,7,233.53,234.13,10,400,1,1,233.45,234.17,15,1,1,1,233.4,234.25,110,50,2,1,233.39,234.41,10,600,1,2,233.31,234.43,110,5,2,1,233.3,234.5,100,63,1,4,AAPL,0.0,0.0,0.0,
2024-10-21 12:06:48.791506901+00:00,2024-10-21T12:06:48.791673239Z,10,2,38,A,A,0,233.79,20,130,166338,12073929,233.7,233.79,1200,20,1,1,233.66,233.93,1,200,1,1,233.65,233.94,200,228,1,2,233.58,233.98,531,44,3,3,233.53,234.0,10,154,1,7,233.45,234.13,15,400,1,1,233.4,234.17,110,1,2,1,233.39,234.25,10,50,1,1,233.31,234.41,110,600,2,2,233.3,234.43,100,5,1,1,AAPL,0.0,0.0,0.0,
2024-10-21 12:06:48.791534978+00:00,2024-10-21T12:06:48.791702674Z,10,2,38,T,B,0,233.79,20,130,167696,12073930,233.7,233.79,1200,20,1,1,233.66,233.93,1,200,1,1,233.65,233.94,200,228,1,2,233.58,233.98,531,44,3,3,233.53,234.0,10,154,1,7,233.45,234.13,15,400,1,1,233.4,234.17,110,1,2,1,233.39,234.25,10,50,1,1,233.31,234.41,110,600,2,2,233.3,234.43,100,5,1,1,AAPL,0.0,0.0,0.0,
2024-10-21 12:06:48.791534978+00:00,2024-10-21T12:06:48.791702674Z,10,2,38,C,A,0,233.79,20,130,167696,12073930,233.7,233.93,1200,200,1,1,233.66,233.94,1,228,1,2,233.65,233.98,200,44,1,3,233.58,234.0,531,154,3,7,233.53,234.13,10,400,1,1,233.45,234.17,15,1,1,1,233.4,234.25,110,50,2,1,233.39,234.41,10,600,1,2,233.31,234.43,110,5,2,1,233.3,234.5,100,63,1,4,AAPL,0.0,0.0,0.0,
2024-10-21 12:06:48.791573564+00:00,2024-10-21T12:06:48.791739905Z,10,2,38,A,B,0,233.74,100,130,166341,12073931,233.74,233.93,100,200,1,1,233.7,233.94,1200,228,1,2,233.66,233.98,1,44,1,3,233.65,234.0,200,154,1,7,233.58,234.13,531,400,3,1,233.53,234.17,10,1,1,1,233.45,234.25,15,50,1,1,233.4,234.41,110,600,2,2,233.39,234.43,10,5,1,1,233.31,234.5,110,63,2,4,AAPL,0.0,0.0,0.0,
2024-10-21 12:06:48.791586310+00:00,2024-10-21T12:06:48.791752199Z,10,2,38,A,B,1,233.71,100,130,165889,12073932,233.74,233.93,100,200,1,1,233.71,233.94,100,228,1,2,233.7,233.98,1200,44,1,3,233.66,234.0,1,154,1,7,233.65,234.13,200,400,1,1,233.58,234.17,531,1,3,1,233.53,234.25,10,50,1,1,233.45,234.41,15,600,1,2,233.4,234.43,110,5,2,1,233.39,234.5,10,63,1,4,AAPL,0.0,0.0,0.0,
2024-10-21 12:06:48.893768793+00:00,2024-10-21T12:06:48.893935165Z,10,2,38,C,B,1,233.71,100,130,166372,12074008,233.74,233.93,100,200,1,1,233.7,233.94,1200,228,1,2,233.66,233.98,1,44,1,3,233.65,234.0,200,154,1,7,233.58,234.13,531,400,3,1,233.53,234.17,10,1,1,1,233.45,234.25,15,50,1,1,233.4,234.41,110,600,2,2,233.39,234.43,10,5,1,1,233.31,234.5,110,63,2,4,AAPL,0.0,0.0,0.0,
2024-10-21 12:06:49.043764990+00:00,2024-10-21T12:06:49.043931536Z,10,2,38,C,B,0,233.74,100,130,166546,12074117,233.7,233.93,1200,200,1,1,233.66,233.94,1,228,1,2,233.65,233.98,200,44,1,3,233.58,234.0,531,154,3,7,233.53,234.13,10,400,1,1,233.45,234.17,15,1,1,1,233.4,234.25,110,50,2,1,233.39,234.41,10,600,1,2,233.31,234.43,110,5,2,1,233.3,234.5,100,63,1,4,AAPL,0.0,0.0,0.0,
2024-10-21 12:06:49.574441885+00:00,2024-10-21T12:06:49.574608384Z,10,2,38,A,B,1,233.66,200,130,166499,12074442,233.7,233.93,1200,200,1,1,233.66,233.94,201,228,2,2,233.58,233.98,531,44,3,3,233.53,234.0,10,154,1,7,233.45,234.13,15,400,1,1,233.4,234.17,110,1,2,1,233.39,234.25,10,50,1,1,233.31,234.41,110,600,2,2,233.3,234.43,100,5,1,1,233.25,234.5,55,63,2,4,AAPL,0.0,200.0,0.0,
2024-10-21 12:06:51.353578115+00:00,2024-10-21T12:06:51.353744448Z,10,2,38,C,B,1,233.66,200,130,166333,12075742,233.7,233.93,1200,200,1,1,233.66,233.94,1,228,1,2,233.58,233.98,531,44,3,3,233.53,234.0,10,154,1,7,233.45,234.13,15,400,1,1,233.4,234.17,110,1,2,1,233.39,234.25,10,50,1,1,233.31,234.41,110,600,2,2,233.3,234.43,100,5,1,1,233.25,234.5,55,63,2,4,AAPL,0.0,-200.0,0.0,
2024-10-21 12:06:51.353591847+00:00,2024-10-21T12:06:51.353758889Z,10,2,38,A,B,2,233.64,200,130,167042,12075743,233.7,233.93,1200,200,1,1,233.66,233.94,1,228,1,2,233.64,233.98,200,44,1,3,233.58,234.0,531,154,3,7,233.53,234.13,10,400,1,1,233.45,234.17,15,1,1,1,233.4,234.25,110,50,2,1,233.39,234.41,10,600,1,2,233.31,234.43,110,5,2,1,233.3,234.5,100,63,1,4,AAPL,0.0,0.0,0.0,
2024-10-21 12:06:53.388459101+00:00,2024-10-21T12:06:53.388625485Z,10,2,38,A,B,2,233.65,200,130,166384,12077374,233.7,233.93,1200,200,1,1,233.66,233.94,1,228,1,2,233.65,233.98,200,44,1,3,233.58,234.0,531,154,3,7,233.53,234.13,10,400,1,1,233.45,234.17,15,1,1,1,233.4,234.25,110,50,2,1,233.39,234.41,10,600,1,2,233.31,234.43,110,5,2,1,233.3,234.5,100,63,1,4,AAPL,0.0,0.0,0.0,
2024-10-21 12:06:56.110160994+00:00,2024-10-21T12:06:56.110327183Z,10,2,38,A,B,0,233.8,100,130,166189,12079383,233.8,233.93,100,200,1,1,233.7,233.94,1200,228,1,2,233.66,233.98,1,44,1,3,233.65,234.0,200,154,1,7,233.58,234.13,531,400,3,1,233.53,234.17,10,1,1,1,233.45,234.25,15,50,1,1,233.4,234.41,110,600,2,2,233.39,234.43,10,5,1,1,233.31,234.5,110,63,2,4,AAPL,0.0,0.0,0.0,
2024-10-21 12:06:56.110195323+00:00,2024-10-21T12:06:56.110361628Z,10,2,38,C,A,0,233.93,200,130,166305,12079385,233.8,233.94,100,228,1,2,233.7,233.98,1200,44,1,3,233.66,234.0,1,154,1,7,233.65,234.13,200,400,1,1,233.58,234.17,531,1,3,1,233.53,234.25,10,50,1,1,233.45,234.41,15,600,1,2,233.4,234.43,110,5,2,1,233.39,234.5,10,63,1,4,233.31,234.75,110,1,2,1,AAPL,0.0,0.0,0.0,
2024-10-21 12:06:56.110459619+00:00,2024-10-21T12:06:56.110625865Z,10,2,38,C,B,0,233.8,100,130,166246,12079387,233.7,233.94,1200,228,1,2,233.66,233.98,1,44,1,3,233.65,234.0,200,154,1,7,233.58,234.13,531,400,3,1,233.53,234.17,10,1,1,1,233.45,234.25,15,50,1,1,233.4,234.41,110,600,2,2,233.39,234.43,10,5,1,1,233.31,234.5,110,63,2,4,233.3,234.75,100,1,1,1,AAPL,0.0,0.0,0.0,
2024-10-21 12:06:56.110506828+00:00,2024-10-21T12:06:56.110674106Z,10,2,38,A,A,0,233.94,200,130,167278,12079388,233.7,233.94,1200,428,1,3,233.66,233.98,1,44,1,3,233.65,234.0,200,154,1,7,233.58,234.13,531,400,3,1,233.53,234.17,10,1,1,1,233.45,234.25,15,50,1,1,233.4,234.41,110,600,2,2,233.39,234.43,10,5,1,1,233.31,234.5,110,63,2,4,233.3,234.75,100,1,1,1,AAPL,-200.0,-200.0,-200.0,
2024-10-21 12:06:56.200078370+00:00,2024-10-21T12:06:56.200245289Z,10,2,38,A,B,2,233.65,200,130,166919,12079603,233.7,233.94,1200,428,1,3,233.66,233.98,1,44,1,3,233.65,234.0,400,154,2,7,233.58,234.13,531,400,3,1,233.53,234.17,10,1,1,1,233.45,234.25,15,50,1,1,233.4,234.41,110,600,2,2,233.39,234.43,10,5,1,1,233.31,234.5,110,63,2,4,233.3,234.75,100,1,1,1,AAPL,0.0,200.0,-200.0,
2024-10-21 12:06:56.253414674+00:00,2024-10-21T12:06:56.253580648Z,10,2,38,C,B,2,233.65,200,130,165974,12079693,233.7,233.94,1200,428,1,3,233.66,233.98,1,44,1,3,233.65,234.0,200,154,1,7,233.58,234.13,531,400,3,1,233.53,234.17,10,1,1,1,233.45,234.25,15,50,1,1,233.4,234.41,110,600,2,2,233.39,234.43,10,5,1,1,233.31,234.5,110,63,2,4,233.3,234.75,100,1,1,1,AAPL,0.0,-200.0,-200.0,
2024-10-21 12:06:56.253426681+00:00,2024-10-21T12:06:56.253593165Z,10,2,38,A,B,1,233.66,400,130,166484,12079694,233.7,233.94,1200,428,1,3,233.66,233.98,401,44,2,3,233.58,234.0,531,154,3,7,233.53,234.13,10,400,1,1,233.45,234.17,15,1,1,1,233.4,234.25,110,50,2,1,233.39,234.41,10,600,1,2,233.31,234.43,110,5,2,1,233.3,234.5,100,63,1,4,233.25,234.75,55,1,2,1,AAPL,0.0,400.0,-200.0,
2024-10-21 12:06:56.253770667+00:00,2024-10-21T12:06:56.253936800Z,10,2,38,C,B,1,233.66,200,130,166133,12079695,233.7,233.94,1200,428,1,3,233.66,233.98,201,44,2,3,233.58,234.0,531,154,3,7,233.53,234.13,10,400,1,1,233.45,234.17,15,1,1,1,233.4,234.25,110,50,2,1,233.39,234.41,10,600,1,2,233.31,234.43,110,5,2,1,233.3,234.5,100,63,1,4,233.25,234.75,55,1,2,1,AAPL,0.0,-200.0,-200.0,
2024-10-21 12:06:56.253914719+00:00,2024-10-21T12:06:56.254080762Z,10,2,38,C,B,2,233.58,26,130,166043,12079696,233.7,233.94,1200,428,1,3,233.66,233.98,201,44,2,3,233.58,234.0,505,154,2,7,233.53,234.13,10,400,1,1,233.45,234.17,15,1,1,1,233.4,234.25,110,50,2,1,233.39,234.41,10,600,1,2,233.31,234.43,110,5,2,1,233.3,234.5,100,63,1,4,233.25,234.75,55,1,2,1,AAPL,0.0,-26.0,-200.0,
2024-10-21 12:06:56.254006802+00:00,2024-10-21T12:06:56.254173312Z,10,2,38,A,B,2,233.64,26,130,166510,12079697,233.7,233.94,1200,428,1,3,233.66,233.98,201,44,2,3,233.64,234.0,26,154,1,7,233.58,234.13,505,400,2,1,233.53,234.17,10,1,1,1,233.45,234.25,15,50,1,1,233.4,234.41,110,600,2,2,233.39,234.43,10,5,1,1,233.31,234.5,110,63,2,4,233.3,234.75,100,1,1,1,AAPL,0.0,0.0,-200.0,
2024-10-21 12:06:56.262048229+00:00,2024-10-21T12:06:56.262214424Z,10,2,38,C,B,1,233.66,200,130,166195,12079704,233.7,233.94,1200,428,1,3,233.66,233.98,1,44,1,3,233.64,234.0,26,154,1,7,233.58,234.13,505,400,2,1,233.53,234.17,10,1,1,1,233.45,234.25,15,50,1,1,233.4,234.41,110,600,2,2,233.39,234.43,10,5,1,1,233.31,234.5,110,63,2,4,233.3,234.75,100,1,1,1,AAPL,0.0,-200.0,-200.0,
2024-10-21 12:06:56.262061304+00:00,2024-10-21T12:06:56.262227751Z,10,2,38,A,B,3,233.61,400,130,166447,12079705,233.7,233.94,1200,428,1,3,233.66,233.98,1,44,1,3,233.64,234.0,26,154,1,7,233.61,234.13,400,400,1,1,233.58,234.17,505,1,2,1,233.53,234.25,10,50,1,1,233.45,234.41,15,600,1,2,233.4,234.43,110,5,2,1,233.39,234.5,10,63,1,4,233.31,234.75,110,1,2,1,AAPL,0.0,0.0,-200.0,
2024-10-21 12:06:56.280865568+00:00,2024-10-21T12:06:56.281031560Z,10,2,38,C,B,2,233.64,26,130,165992,12079723,233.7,233.94,1200,428,1,3,233.66,233.98,1,44,1,3,233.61,234.0,400,154,1,7,233.58,234.13,505,400,2,1,233.53,234.17,10,1,1,1,233.45,234.25,15,50,1,1,233.4,234.41,110,600,2,2,233.39,234.43,10,5,1,1,233.31,234.5,110,63,2,4,233.3,234.75,100,1,1,1,AAPL,0.0,0.0,-200.0,
2024-10-21 12:06:56.343913221+00:00,2024-10-21T12:06:56.344079966Z,10,2,38,A,B,1,233.66,200,130,166745,12079737,233.7,233.94,1200,428,1,3,233.66,233.98,201,44,2,3,233.58,234.0,505,154,2,7,233.53,234.13,10,400,1,1,233.45,234.17,15,1,1,1,233.4,234.25,110,50,2,1,233.39,234.41,10,600,1,2,233.31,234.43,110,5,2,1,233.3,234.5,100,63,1,4,233.25,234.75,55,1,2,1,AAPL,0.0,200.0,-200.0,
2024-10-21 12:06:57.181891624+00:00,2024-10-21T12:06:57.182057820Z,10,2,38,A,B,2,233.58,26,130,166196,12080361,233.7,233.94,1200,428,1,3,233.66,233.98,201,44,2,3,233.58,234.0,531,154,3,7,233.53,234.13,10,400,1,1,233.45,234.17,15,1,1,1,233.4,234.25,110,50,2,1,233.39,234.41,10,600,1,2,233.31,234.43,110,5,2,1,233.3,234.5,100,63,1,4,233.25,234.75,55,1,2,1,AAPL,0.0,26.0,0.0,
2024-10-21 12:06:59.253990761+00:00,2024-10-21T12:06:59.254157093Z,10,2,38,A,B,1,233.66,200,130,166332,12081445,233.7,233.94,1200,428,1,3,233.66,233.98,401,44,3,3,233.58,234.0,531,154,3,7,233.53,234.13,10,400,1,1,233.45,234.17,15,1,1,1,233.4,234.25,110,50,2,1,233.39,234.41,10,600,1,2,233.31,234.43,110,5,2,1,233.3,234.5,100,63,1,4,233.25,234.75,55,1,2,1,AAPL,0.0,200.0,0.0,
2024-10-21 12:06:59.254521031+00:00,2024-10-21T12:06:59.254687091Z,10,2,38,C,B,2,233.58,26,130,166060,12081446,233.7,233.94,1200,428,1,3,233.66,233.98,401,44,3,3,233.58,234.0,505,154,2,7,233.53,234.13,10,400,1,1,233.45,234.17,15,1,1,1,233.4,234.25,110,50,2,1,233.39,234.41,10,600,1,2,233.31,234.43,110,5,2,1,233.3,234.5,100,63,1,4,233.25,234.75,55,1,2,1,AAPL,0.0,-26.0,0.0,
2024-10-21 12:06:59.254578130+00:00,2024-10-21T12:06:59.254744498Z,10,2,38,A,B,2,233.64,29,130,166368,12081447,233.7,233.94,1200,428,1,3,233.66,233.98,401,44,3,3,233.64,234.0,29,154,1,7,233.58,234.13,505,400,2,1,233.53,234.17,10,1,1,1,233.45,234.25,15,50,1,1,233.4,234.41,110,600,2,2,233.39,234.43,10,5,1,1,233.31,234.5,110,63,2,4,233.3,234.75,100,1,1,1,AAPL,0.0,0.0,0.0,
2024-10-21 12:06:59.308464431+00:00,2024-10-21T12:06:59.308630752Z,10,2,38,C,B,1,233.66,200,130,166321,12081505,233.7,233.94,1200,428,1,3,233.66,233.98,201,44,2,3,233.64,234.0,29,154,1,7,233.58,234.13,505,400,2,1,233.53,234.17,10,1,1,1,233.45,234.25,15,50,1,1,233.4,234.41,110,600,2,2,233.39,234.43,10,5,1,1,233.31,234.5,110,63,2,4,233.3,234.75,100,1,1,1,AAPL,0.0,-200.0,0.0,
2024-10-21 12:06:59.308477350+00:00,2024-10-21T12:06:59.308644001Z,10,2,38,A,B,0,233.7,200,130,166651,12081506,233.7,233.94,1400,428,2,3,233.66,233.98,1,44,1,3,233.64,234.0,29,154,1,7,233.58,234.13,505,400,2,1,233.53,234.17,10,1,1,1,233.45,234.25,15,50,1,1,233.4,234.41,110,600,2,2,233.39,234.43,10,5,1,1,233.31,234.5,110,63,2,4,233.3,234.75,100,1,1,1,AAPL,200.0,0.0,200.0,
2024-10-21 12:07:03.723636278+00:00,2024-10-21T12:07:03.723802492Z,10,2,38,A,A,0,233.93,200,130,166214,12085903,233.7,233.93,1400,200,2,1,233.66,233.94,1,228,1,2,233.64,233.98,29,44,1,3,233.58,234.0,505,154,2,7,233.53,234.13,10,400,1,1,233.45,234.17,15,1,1,1,233.4,234.25,110,50,2,1,233.39,234.41,10,600,1,2,233.31,234.43,110,5,2,1,233.3,234.5,100,63,1,4,AAPL,0.0,0.0,0.0,
2024-10-21 12:07:06.239446409+00:00,2024-10-21T12:07:06.239612135Z,10,2,38,C,B,0,233.7,200,130,165726,12087785,233.7,233.93,1200,200,1,1,233.66,233.94,1,228,1,2,233.64,233.98,29,44,1,3,233.58,234.0,505,154,2,7,233.53,234.13,10,400,1,1,233.45,234.17,15,1,1,1,233.4,234.25,110,50,2,1,233.39,234.41,10,600,1,2,233.31,234.43,110,5,2,1,233.3,234.5,100,63,1,4,AAPL,-200.0,-200.0,-200.0,
2024-10-21 12:07:06.347474732+00:00,2024-10-21T12:07:06.347640980Z,10,2,38,A,B,0,233.7,200,130,166248,12087873,233.7,233.93,1400,200,2,1,233.66,233.94,1,228,1,2,233.64,233.98,29,44,1,3,233.58,234.0,505,154,2,7,233.53,234.13,10,400,1,1,233.45,234.17,15,1,1,1,233.4,234.25,110,50,2,1,233.39,234.41,10,600,1,2,233.31,234.43,110,5,2,1,233.3,234.5,100,63,1,4,AAPL,200.0,200.0,0.0,
2024-10-21 12:07:21.424028257+00:00,2024-10-21T12:07:21.424194481Z,10,2,38,C,A,0,233.93,200,130,166224,12101250,233.7,233.94,1400,228,2,2,233.66,233.98,1,44,1,3,233.64,234.0,29,154,1,7,233.58,234.13,505,400,2,1,233.53,234.17,10,1,1,1,233.45,234.25,15,50,1,1,233.4,234.41,110,600,2,2,233.39,234.43,10,5,1,1,233.31,234.5,110,63,2,4,233.3,234.75,100,1,1,1,AAPL,0.0,0.0,0.0,
2024-10-21 12:07:21.424041784+00:00,2024-10-21T12:07:21.424207907Z,10,2,38,A,A,1,233.95,200,130,166123,12101251,233.7,233.94,1400,228,2,2,233.66,233.95,1,200,1,1,233.64,233.98,29,44,1,3,233.58,234.0,505,154,2,7,233.53,234.13,10,400,1,1,233.45,234.17,15,1,1,1,233.4,234.25,110,50,2,1,233.39,234.41,10,600,1,2,233.31,234.43,110,5,2,1,233.3,234.5,100,63,1,4,AAPL,0.0,0.0,0.0,
2024-10-21 12:07:21.478349682+00:00,2024-10-21T12:07:21.478515734Z,10,2,38,A,B,0,233.71,200,130,166052,12101383,233.71,233.94,200,228,1,2,233.7,233.95,1200,200,1,1,233.66,233.98,1,44,1,3,233.64,234.0,29,154,1,7,233.58,234.13,505,400,2,1,233.53,234.17,10,1,1,1,233.45,234.25,15,50,1,1,233.4,234.41,110,600,2,2,233.39,234.43,10,5,1,1,233.31,234.5,110,63,2,4,AAPL,0.0,0.0,0.0,
2024-10-21 12:07:21.488058823+00:00,2024-10-21T12:07:21.488225088Z,10,2,38,C,B,3,233.64,29,130,166265,12101519,233.71,233.94,200,228,1,2,233.7,233.95,1200,200,1,1,233.66,233.98,1,44,1,3,233.58,234.0,505,154,2,7,233.53,234.13,10,400,1,1,233.45,234.17,15,1,1,1,233.4,234.25,110,50,2,1,233.39,234.41,10,600,1,2,233.31,234.43,110,5,2,1,233.3,234.5,100,63,1,4,AAPL,0.0,0.0,0.0,
2024-10-21 12:07:21.488100749+00:00,2024-10-21T12:07:21.488266872Z,10,2,38,A,B,3,233.65,26,130,166123,12101521,233.71,233.94,200,228,1,2,233.7,233.95,1200,200,1,1,233.66,233.98,1,44,1,3,233.65,234.0,26,154,1,7,233.58,234.13,505,400,2,1,233.53,234.17,10,1,1,1,233.45,234.25,15,50,1,1,233.4,234.41,110,600,2,2,233.39,234.43,10,5,1,1,233.31,234.5,110,63,2,4,AAPL,0.0,0.0,0.0,
2024-10-21 12:07:21.502492836+00:00,2024-10-21T12:07:21.502658985Z,10,2,38,C,A,0,233.94,28,130,166149,12101598,233.71,233.94,200,200,1,1,233.7,233.95,1200,200,1,1,233.66,233.98,1,44,1,3,233.65,234.0,26,154,1,7,233.58,234.13,505,400,2,1,233.53,234.17,10,1,1,1,233.45,234.25,15,50,1,1,233.4,234.41,110,600,2,2,233.39,234.43,10,5,1,1,233.31,234.5,110,63,2,4,AAPL,28.0,28.0,28.0,
2024-10-21 12:07:21.502548349+00:00,2024-10-21T12:07:21.502714841Z,10,2,38,A,A,2,233.97,26,130,166492,12101599,233.71,233.94,200,200,1,1,233.7,233.95,1200,200,1,1,233.66,233.97,1,26,1,1,233.65,233.98,26,44,1,3,233.58,234.0,505,154,2,7,233.53,234.13,10,400,1,1,233.45,234.17,15,1,1,1,233.4,234.25,110,50,2,1,233.39,234.41,10,600,1,2,233.31,234.43,110,5,2,1,AAPL,0.0,0.0,28.0,
2024-10-21 12:07:24.037331253+00:00,2024-10-21T12:07:24.037497828Z,10,2,38,A,A,0,233.94,200,130,166575,12104033,233.71,233.94,200,400,1,2,233.7,233.97,1200,26,1,1,233.66,233.98,1,44,1,3,233.65,234.0,26,154,1,7,233.58,234.13,505,400,2,1,233.53,234.17,10,1,1,1,233.45,234.25,15,50,1,1,233.4,234.41,110,600,2,2,233.39,234.43,10,5,1,1,233.31,234.5,110,63,2,4,AAPL,-200.0,-200.0,-200.0,
2024-10-21 12:07:24.051643239+00:00,2024-10-21T12:07:24.051809302Z,10,2,38,C,A,1,233.97,26,130,166063,12104141,233.71,233.94,200,400,1,2,233.7,233.98,1200,44,1,3,233.66,234.0,1,154,1,7,233.65,234.13,26,400,1,1,233.58,234.17,505,1,2,1,233.53,234.25,10,50,1,1,233.45,234.41,15,600,1,2,233.4,234.43,110,5,2,1,233.39,234.5,10,63,1,4,233.31,234.75,110,1,2,1,AAPL,0.0,0.0,-200.0,
2024-10-21 12:07:24.051685450+00:00,2024-10-21T12:07:24.051851741Z,10,2,38,A,A,1,233.96,26,130,166291,12104142,233.71,233.94,200,400,1,2,233.7,233.96,1200,26,1,1,233.66,233.98,1,44,1,3,233.65,234.0,26,154,1,7,233.58,234.13,505,400,2,1,233.53,234.17,10,1,1,1,233.45,234.25,15,50,1,1,233.4,234.41,110,600,2,2,233.39,234.43,10,5,1,1,233.31,234.5,110,63,2,4,AAPL,0.0,0.0,-200.0,
2024-10-21 12:07:31.492189570+00:00,2024-10-21T12:07:31.492356327Z,10,2,38,A,A,0,233.93,200,130,166757,12109685,233.71,233.93,200,200,1,1,233.7,233.94,1200,200,1,1,233.66,233.96,1,26,1,1,233.65,233.98,26,44,1,3,233.58,234.0,505,154,2,7,233.53,234.13,10,400,1,1,233.45,234.17,15,1,1,1,233.4,234.25,110,50,2,1,233.39,234.41,10,600,1,2,233.31,234.43,110,5,2,1,AAPL,0.0,0.0,0.0,
2024-10-21 12:07:31.505459563+00:00,2024-10-21T12:07:31.505625526Z,10,2,38,C,A,2,233.96,26,130,165963,12109738,233.71,233.93,200,200,1,1,233.7,233.94,1200,200,1,1,233.66,233.98,1,44,1,3,233.65,234.0,26,154,1,7,233.58,234.13,505,400,2,1,233.53,234.17,10,1,1,1,233.45,234.25,15,50,1,1,233.4,234.41,110,600,2,2,233.39,234.43,10,5,1,1,233.31,234.5,110,63,2,4,AAPL,0.0,0.0,0.0,
2024-10-21 12:07:31.506518669+00:00,2024-10-21T12:07:31.506685578Z,10,2,38,A,A,2,233.95,29,130,166909,12109739,233.71,233.93,200,200,1,1,233.7,233.94,1200,200,1,1,233.66,233.95,1,29,1,1,233.65,233.98,26,44,1,3,233.58,234.0,505,154,2,7,233.53,234.13,10,400,1,1,233.45,234.17,15,1,1,1,233.4,234.25,110,50,2,1,233.39,234.41,10,600,1,2,233.31,234.43,110,5,2,1,AAPL,0.0,0.0,0.0,
2024-10-21 12:07:32.030551990+00:00,2024-10-21T12:07:32.030718105Z,10,2,38,C,B,0,233.71,200,130,166115,12110208,233.7,233.93,1200,200,1,1,233.66,233.94,1,200,1,1,233.65,233.95,26,29,1,1,233.58,233.98,505,44,2,3,233.53,234.0,10,154,1,7,233.45,234.13,15,400,1,1,233.4,234.17,110,1,2,1,233.39,234.25,10,50,1,1,233.31,234.41,110,600,2,2,233.3,234.43,100,5,1,1,AAPL,0.0,0.0,0.0,
2024-10-21 12:07:32.030564032+00:00,2024-10-21T12:07:32.030730303Z,10,2,38,A,B,1,233.69,200,130,166271,12110209,233.7,233.93,1200,200,1,1,233.69,233.94,200,200,1,1,233.66,233.95,1,29,1,1,233.65,233.98,26,44,1,3,233.58,234.0,505,154,2,7,233.53,234.13,10,400,1,1,233.45,234.17,15,1,1,1,233.4,234.25,110,50,2,1,233.39,234.41,10,600,1,2,233.31,234.43,110,5,2,1,AAPL,0.0,0.0,0.0,
2024-10-21 12:07:33.189588145+00:00,2024-10-21T12:07:33.189754626Z,10,2,38,A,B,0,233.7,200,130,166481,12111500,233.7,233.93,1400,200,2,1,233.66,233.94,1,200,1,1,233.65,233.95,26,29,1,1,233.58,233.98,505,44,2,3,233.53,234.0,10,154,1,7,233.45,234.13,15,400,1,1,233.4,234.17,110,1,2,1,233.39,234.25,10,50,1,1,233.31,234.41,110,600,2,2,233.3,234.43,100,5,1,1,AAPL,200.0,200.0,200.0,
2024-10-21 12:07:34.413504555+00:00,2024-10-21T12:07:34.413671182Z,10,2,38,A,B,0,233.71,200,130,166627,12112520,233.71,233.93,200,200,1,1,233.7,233.94,1200,200,1,1,233.66,233.95,1,29,1,1,233.65,233.98,26,44,1,3,233.58,234.0,505,154,2,7,233.53,234.13,10,400,1,1,233.45,234.17,15,1,1,1,233.4,234.25,110,50,2,1,233.39,234.41,10,600,1,2,233.31,234.43,110,5,2,1,AAPL,0.0,0.0,0.0,
2024-10-21 12:07:51.491296294+00:00,2024-10-21T12:07:51.491464688Z,10,2,38,T,N,0,233.87,50,0,168394,12127009,233.71,233.93,200,200,1,1,233.7,233.94,1200,200,1,1,233.66,233.95,1,29,1,1,233.65,233.98,26,44,1,3,233.58,234.0,505,154,2,7,233.53,234.13,10,400,1,1,233.45,234.17,15,1,1,1,233.4,234.25,110,50,2,1,233.39,234.41,10,600,1,2,233.31,234.43,110,5,2,1,AAPL,0.0,0.0,0.0,
2024-10-21 12:07:51.491296294+00:00,2024-10-21T12:07:51.491464688Z,10,2,38,T,N,0,233.88,50,130,168394,12127010,233.71,233.93,200,200,1,1,233.7,233.94,1200,200,1,1,233.66,233.95,1,29,1,1,233.65,233.98,26,44,1,3,233.58,234.0,505,154,2,7,233.53,234.13,10,400,1,1,233.45,234.17,15,1,1,1,233.4,234.25,110,50,2,1,233.39,234.41,10,600,1,2,233.31,234.43,110,5,2,1,AAPL,0.0,0.0,0.0,
2024-10-21 12:07:51.493462211+00:00,2024-10-21T12:07:51.493630333Z,10,2,38,T,N,0,233.9,150,130,168122,12127014,233.71,233.93,200,200,1,1,233.7,233.94,1200,200,1,1,233.66,233.95,1,29,1,1,233.65,233.98,26,44,1,3,233.58,234.0,505,154,2,7,233.53,234.13,10,400,1,1,233.45,234.17,15,1,1,1,233.4,234.25,110,50,2,1,233.39,234.41,10,600,1,2,233.31,234.43,110,5,2,1,AAPL,0.0,0.0,0.0,
2024-10-21 12:07:51.493723176+00:00,2024-10-21T12:07:51.493889366Z,10,2,38,A,B,0,233.86,100,130,166190,12127015,233.86,233.93,100,200,1,1,233.71,233.94,200,200,1,1,233.7,233.95,1200,29,1,1,233.66,233.98,1,44,1,3,233.65,234.0,26,154,1,7,233.58,234.13,505,400,2,1,233.53,234.17,10,1,1,1,233.45,234.25,15,50,1,1,233.4,234.41,110,600,2,2,233.39,234.43,10,5,1,1,AAPL,0.0,0.0,0.0,
2024-10-21 12:07:51.493724386+00:00,2024-10-21T12:07:51.493891476Z,10,2,38,A,B,1,233.83,100,130,167090,12127016,233.86,233.93,100,200,1,1,233.83,233.94,100,200,1,1,233.71,233.95,200,29,1,1,233.7,233.98,1200,44,1,3,233.66,234.0,1,154,1,7,233.65,234.13,26,400,1,1,233.58,234.17,505,1,2,1,233.53,234.25,10,50,1,1,233.45,234.41,15,600,1,2,233.4,234.43,110,5,2,1,AAPL,0.0,0.0,0.0,
2024-10-21 12:07:51.493756947+00:00,2024-10-21T12:07:51.493922927Z,10,2,38,C,A,0,233.93,200,130,165980,12127018,233.86,233.94,100,200,1,1,233.83,233.95,100,29,1,1,233.71,233.98,200,44,1,3,233.7,234.0,1200,154,1,7,233.66,234.13,1,400,1,1,233.65,234.17,26,1,1,1,233.58,234.25,505,50,2,1,233.53,234.41,10,600,1,2,233.45,234.43,15,5,1,1,233.4,234.5,110,63,2,4,AAPL,0.0,0.0,0.0,
2024-10-21 12:07:51.494118408+00:00,2024-10-21T12:07:51.494284128Z,10,2,38,C,B,0,233.86,100,130,165720,12127025,233.83,233.94,100,200,1,1,233.71,233.95,200,29,1,1,233.7,233.98,1200,44,1,3,233.66,234.0,1,154,1,7,233.65,234.13,26,400,1,1,233.58,234.17,505,1,2,1,233.53,234.25,10,50,1,1,233.45,234.41,15,600,1,2,233.4,234.43,110,5,2,1,233.39,234.5,10,63,1,4,AAPL,0.0,0.0,0.0,
2024-10-21 12:07:51.502398180+00:00,2024-10-21T12:07:51.502564185Z,10,2,38,C,B,0,233.83,100,130,166005,12127032,233.71,233.94,200,200,1,1,233.7,233.95,1200,29,1,1,233.66,233.98,1,44,1,3,233.65,234.0,26,154,1,7,233.58,234.13,505,400,2,1,233.53,234.17,10,1,1,1,233.45,234.25,15,50,1,1,233.4,234.41,110,600,2,2,233.39,234.43,10,5,1,1,233.31,234.5,110,63,2,4,AAPL,0.0,0.0,0.0,
2024-10-21 12:07:51.568012126+00:00,2024-10-21T12:07:51.568178423Z,10,2,38,A,B,0,233.71,200,130,166297,12127155,233.71,233.94,400,200,2,1,233.7,233.95,1200,29,1,1,233.66,233.98,1,44,1,3,233.65,234.0,26,154,1,7,233.58,234.13,505,400,2,1,233.53,234.17,10,1,1,1,233.45,234.25,15,50,1,1,233.4,234.41,110,600,2,2,233.39,234.43,10,5,1,1,233.31,234.5,110,63,2,4,AAPL,200.0,200.0,200.0,
2024-10-21 12:07:51.600943259+00:00,2024-10-21T12:07:51.601109855Z,10,2,38,A,A,3,233.99,200,130,166596,12127168,233.71,233.94,400,200,2,1,233.7,233.95,1200,29,1,1,233.66,233.98,1,44,1,3,233.65,233.99,26,200,1,1,233.58,234.0,505,154,2,7,233.53,234.13,10,400,1,1,233.45,234.17,15,1,1,1,233.4,234.25,110,50,2,1,233.39,234.41,10,600,1,2,233.31,234.43,110,5,2,1,AAPL,0.0,0.0,200.0,
2024-10-21 12:07:51.615820733+00:00,2024-10-21T12:07:51.615987022Z,10,2,38,C,A,3,233.99,200,130,166289,12127177,233.71,233.94,400,200,2,1,233.7,233.95,1200,29,1,1,233.66,233.98,1,44,1,3,233.65,234.0,26,154,1,7,233.58,234.13,505,400,2,1,233.53,234.17,10,1,1,1,233.45,234.25,15,50,1,1,233.4,234.41,110,600,2,2,233.39,234.43,10,5,1,1,233.31,234.5,110,63,2,4,AAPL,0.0,0.0,200.0,
2024-10-21 12:07:51.619802962+00:00,2024-10-21T12:07:51.619969198Z,10,2,38,C,B,3,233.65,26,130,166236,12127178,233.71,233.94,400,200,2,1,233.7,233.95,1200,29,1,1,233.66,233.98,1,44,1,3,233.58,234.0,505,154,2,7,233.53,234.13,10,400,1,1,233.45,234.17,15,1,1,1,233.4,234.25,110,50,2,1,233.39,234.41,10,600,1,2,233.31,234.43,110,5,2,1,233.3,234.5,100,63,1,4,AAPL,0.0,0.0,200.0,
2024-10-21 12:07:51.619884656+00:00,2024-10-21T12:07:51.620051180Z,10,2,38,A,B,2,233.69,28,130,166524,12127179,233.71,233.94,400,200,2,1,233.7,233.95,1200,29,1,1,233.69,233.98,28,44,1,3,233.66,234.0,1,154,1,7,233.58,234.13,505,400,2,1,233.53,234.17,10,1,1,1,233.45,234.25,15,50,1,1,233.4,234.41,110,600,2,2,233.39,234.43,10,5,1,1,233.31,234.5,110,63,2,4,AAPL,0.0,0.0,200.0,
2024-10-21 12:07:51.619898253+00:00,2024-10-21T12:07:51.620064221Z,10,2,38,C,A,1,233.95,29,130,165968,12127180,233.71,233.94,400,200,2,1,233.7,233.98,1200,44,1,3,233.69,234.0,28,154,1,7,233.66,234.13,1,400,1,1,233.58,234.17,505,1,2,1,233.53,234.25,10,50,1,1,233.45,234.41,15,600,1,2,233.4,234.43,110,5,2,1,233.39,234.5,10,63,1,4,233.31,234.75,110,1,2,1,AAPL,0.0,0.0,200.0,
2024-10-21 12:07:51.619921024+00:00,2024-10-21T12:07:51.620087853Z,10,2,38,A,B,0,233.72,28,130,166829,12127181,233.72,233.94,28,200,1,1,233.71,233.98,400,44,2,3,233.7,234.0,1200,154,1,7,233.69,234.13,28,400,1,1,233.66,234.17,1,1,1,1,233.58,234.25,505,50,2,1,233.53,234.41,10,600,1,2,233.45,234.43,15,5,1,1,233.4,234.5,110,63,2,4,233.39,234.75,10,1,1,1,AAPL,0.0,0.0,200.0,
2024-10-21 12:07:51.619959682+00:00,2024-10-21T12:07:51.620126136Z,10,2,38,A,A,3,234.07,30,130,166454,12127184,233.72,233.94,28,200,1,1,233.71,233.98,400,44,2,3,233.7,234.0,1200,154,1,7,233.69,234.07,28,30,1,1,233.66,234.13,1,400,1,1,233.58,234.17,505,1,2,1,233.53,234.25,10,50,1,1,233.45,234.41,15,600,1,2,233.4,234.43,110,5,2,1,233.39,234.5,10,63,1,4,AAPL,0.0,0.0,200.0,
2024-10-21 12:07:51.628191317+00:00,2024-10-21T12:07:51.628357454Z,10,2,38,C,B,1,233.71,200,130,166137,12127189,233.72,233.94,28,200,1,1,233.71,233.98,200,44,1,3,233.7,234.0,1200,154,1,7,233.69,234.07,28,30,1,1,233.66,234.13,1,400,1,1,233.58,234.17,505,1,2,1,233.53,234.25,10,50,1,1,233.45,234.41,15,600,1,2,233.4,234.43,110,5,2,1,233.39,234.5,10,63,1,4,AAPL,0.0,-200.0,200.0,
2024-10-21 12:07:51.628201644+00:00,2024-10-21T12:07:51.628367420Z,10,2,38,C,B,1,233.71,200,130,165776,12127190,233.72,233.94,28,200,1,1,233.7,233.98,1200,44,1,3,233.69,234.0,28,154,1,7,233.66,234.07,1,30,1,1,233.58,234.13,505,400,2,1,233.53,234.17,10,1,1,1,233.45,234.25,15,50,1,1,233.4,234.41,110,600,2,2,233.39,234.43,10,5,1,1,233.31,234.5,110,63,2,4,AAPL,0.0,0.0,200.0,
2024-10-21 12:07:51.628212387+00:00,2024-10-21T12:07:51.628378547Z,10,2,38,A,B,3,233.67,200,130,166160,12127191,233.72,233.94,28,200,1,1,233.7,233.98,1200,44,1,3,233.69,234.0,28,154,1,7,233.67,234.07,200,30,1,1,233.66,234.13,1,400,1,1,233.58,234.17,505,1,2,1,233.53,234.25,10,50,1,1,233.45,234.41,15,600,1,2,233.4,234.43,110,5,2,1,233.39,234.5,10,63,1,4,AAPL,0.0,0.0,200.0,
2024-10-21 12:07:51.686536494+00:00,2024-10-21T12:07:51.686702996Z,10,2,38,A,A,2,234.0,200,130,166502,12127218,233.72,233.94,28,200,1,1,233.7,233.98,1200,44,1,3,233.69,234.0,28,354,1,8,233.67,234.07,200,30,1,1,233.66,234.13,1,400,1,1,233.58,234.17,505,1,2,1,233.53,234.25,10,50,1,1,233.45,234.41,15,600,1,2,233.4,234.43,110,5,2,1,233.39,234.5,10,63,1,4,AAPL,0.0,-200.0,200.0,
2024-10-21 12:07:51.794799198+00:00,2024-10-21T12:07:51.794965675Z,10,2,38,A,B,3,233.68,200,130,166477,12127318,233.72,233.94,28,200,1,1,233.7,233.98,1200,44,1,3,233.69,234.0,28,354,1,8,233.68,234.07,200,30,1,1,233.66,234.13,1,400,1,1,233.58,234.17,505,1,2,1,233.53,234.25,10,50,1,1,233.45,234.41,15,600,1,2,233.4,234.43,110,5,2,1,233.39,234.5,10,63,1,4,AAPL,0.0,0.0,200.0,
2024-10-21 12:07:51.814032926+00:00,2024-10-21T12:07:51.814199410Z,10,2,38,A,B,1,233.71,200,130,166484,12127371,233.72,233.94,28,200,1,1,233.71,233.98,200,44,1,3,233.7,234.0,1200,354,1,8,233.69,234.07,28,30,1,1,233.66,234.13,1,400,1,1,233.58,234.17,505,1,2,1,233.53,234.25,10,50,1,1,233.45,234.41,15,600,1,2,233.4,234.43,110,5,2,1,233.39,234.5,10,63,1,4,AAPL,0.0,0.0,200.0,
2024-10-21 12:07:52.076548886+00:00,2024-10-21T12:07:52.076717628Z,10,2,38,T,N,0,233.93,50,130,168742,12127534,233.72,233.94,28,200,1,1,233.71,233.98,200,44,1,3,233.7,234.0,1200,354,1,8,233.69,234.07,28,30,1,1,233.66,234.13,1,400,1,1,233.58,234.17,505,1,2,1,233.53,234.25,10,50,1,1,233.45,234.41,15,600,1,2,233.4,234.43,110,5,2,1,233.39,234.5,10,63,1,4,AAPL,0.0,0.0,200.0,
2024-10-21 12:07:52.076590310+00:00,2024-10-21T12:07:52.076756699Z,10,2,38,A,B,0,233.82,5,130,166389,12127535,233.82,233.94,5,200,1,1,233.72,233.98,28,44,1,3,233.71,234.0,200,354,1,8,233.7,234.07,1200,30,1,1,233.69,234.13,28,400,1,1,233.66,234.17,1,1,1,1,233.58,234.25,505,50,2,1,233.53,234.41,10,600,1,2,233.45,234.43,15,5,1,1,233.4,234.5,110,63,2,4,AAPL,0.0,0.0,200.0,
2024-10-21 12:07:52.083763088+00:00,2024-10-21T12:07:52.083929289Z,10,2,38,C,B,0,233.82,5,130,166201,12127537,233.72,233.94,28,200,1,1,233.71,233.98,200,44,1,3,233.7,234.0,1200,354,1,8,233.69,234.07,28,30,1,1,233.66,234.13,1,400,1,1,233.58,234.17,505,1,2,1,233.53,234.25,10,50,1,1,233.45,234.41,15,600,1,2,233.4,234.43,110,5,2,1,233.39,234.5,10,63,1,4,AAPL,0.0,0.0,200.0,
2024-10-21 12:07:52.139320651+00:00,2024-10-21T12:07:52.139486617Z,10,2,38,C,B,3,233.69,28,130,165966,12127647,233.72,233.94,28,200,1,1,233.71,233.98,200,44,1,3,233.7,234.0,1200,354,1,8,233.66,234.07,1,30,1,1,233.58,234.13,505,400,2,1,233.53,234.17,10,1,1,1,233.45,234.25,15,50,1,1,233.4,234.41,110,600,2,2,233.39,234.43,10,5,1,1,233.31,234.5,110,63,2,4,AAPL,0.0,0.0,200.0,
2024-10-21 12:07:52.139355221+00:00,2024-10-21T12:07:52.139521177Z,10,2,38,C,B,0,233.72,28,130,165956,12127648,233.71,233.94,200,200,1,1,233.7,233.98,1200,44,1,3,233.66,234.0,1,354,1,8,233.58,234.07,505,30,2,1,233.53,234.13,10,400,1,1,233.45,234.17,15,1,1,1,233.4,234.25,110,50,2,1,233.39,234.41,10,600,1,2,233.31,234.43,110,5,2,1,233.3,234.5,100,63,1,4,AAPL,0.0,0.0,200.0,
2024-10-21 12:07:52.139430957+00:00,2024-10-21T12:07:52.139597427Z,10,2,38,A,B,1,233.7,29,130,166470,12127649,233.71,233.94,200,200,1,1,233.7,233.98,1229,44,2,3,233.66,234.0,1,354,1,8,233.58,234.07,505,30,2,1,233.53,234.13,10,400,1,1,233.45,234.17,15,1,1,1,233.4,234.25,110,50,2,1,233.39,234.41,10,600,1,2,233.31,234.43,110,5,2,1,233.3,234.5,100,63,1,4,AAPL,0.0,29.0,200.0,
2024-10-21 12:07:52.330233710+00:00,2024-10-21T12:07:52.330401624Z,10,2,38,T,N,0,233.93,50,130,167914,12127818,233.71,233.94,200,200,1,1,233.7,233.98,1229,44,2,3,233.66,234.0,1,354,1,8,233.58,234.07,505,30,2,1,233.53,234.13,10,400,1,1,233.45,234.17,15,1,1,1,233.4,234.25,110,50,2,1,233.39,234.41,10,600,1,2,233.31,234.43,110,5,2,1,233.3,234.5,100,63,1,4,AAPL,0.0,0.0,200.0,
2024-10-21 12:07:52.330267041+00:00,2024-10-21T12:07:52.330433594Z,10,2,38,A,B,0,233.82,5,130,166553,12127819,233.82,233.94,5,200,1,1,233.71,233.98,200,44,1,3,233.7,234.0,1229,354,2,8,233.66,234.07,1,30,1,1,233.58,234.13,505,400,2,1,233.53,234.17,10,1,1,1,233.45,234.25,15,50,1,1,233.4,234.41,110,600,2,2,233.39,234.43,10,5,1,1,233.31,234.5,110,63,2,4,AAPL,0.0,0.0,200.0,
2024-10-21 12:07:52.333762726+00:00,2024-10-21T12:07:52.333928834Z,10,2,38,C,B,0,233.82,5,130,166108,12127822,233.71,233.94,200,200,1,1,233.7,233.98,1229,44,2,3,233.66,234.0,1,354,1,8,233.58,234.07,505,30,2,1,233.53,234.13,10,400,1,1,233.45,234.17,15,1,1,1,233.4,234.25,110,50,2,1,233.39,234.41,10,600,1,2,233.31,234.43,110,5,2,1,233.3,234.5,100,63,1,4,AAPL,0.0,0.0,200.0,
2024-10-21 12:07:53.654833970+00:00,2024-10-21T12:07:53.655001137Z,10,2,38,T,N,0,233.93,50,130,167167,12128538,233.71,233.94,200,200,1,1,233.7,233.98,1229,44,2,3,233.66,234.0,1,354,1,8,233.58,234.07,505,30,2,1,233.53,234.13,10,400,1,1,233.45,234.17,15,1,1,1,233.4,234.25,110,50,2,1,233.39,234.41,10,600,1,2,233.31,234.43,110,5,2,1,233.3,234.5,100,63,1,4,AAPL,0.0,0.0,0.0,
2024-10-21 12:07:53.654870612+00:00,2024-10-21T12:07:53.655037705Z,10,2,38,A,B,0,233.82,5,130,167093,12128540,233.82,233.94,5,200,1,1,233.71,233.98,200,44,1,3,233.7,234.0,1229,354,2,8,233.66,234.07,1,30,1,1,233.58,234.13,505,400,2,1,233.53,234.17,10,1,1,1,233.45,234.25,15,50,1,1,233.4,234.41,110,600,2,2,233.39,234.43,10,5,1,1,233.31,234.5,110,63,2,4,AAPL,0.0,0.0,0.0,
2024-10-21 12:07:53.663763591+00:00,2024-10-21T12:07:53.663929398Z,10,2,38,C,B,0,233.82,5,130,165807,12128556,233.71,233.94,200,200,1,1,233.7,233.98,1229,44,2,3,233.66,234.0,1,354,1,8,233.58,234.07,505,30,2,1,233.53,234.13,10,400,1,1,233.45,234.17,15,1,1,1,233.4,234.25,110,50,2,1,233.39,234.41,10,600,1,2,233.31,234.43,110,5,2,1,233.3,234.5,100,63,1,4,AAPL,0.0,0.0,0.0,
2024-10-21 12:07:54.619783229+00:00,2024-10-21T12:07:54.619949683Z,10,2,38,A,B,0,233.71,200,130,166454,12129129,233.71,233.94,400,200,2,1,233.7,233.98,1229,44,2,3,233.66,234.0,1,354,1,8,233.58,234.07,505,30,2,1,233.53,234.13,10,400,1,1,233.45,234.17,15,1,1,1,233.4,234.25,110,50,2,1,233.39,234.41,10,600,1,2,233.31,234.43,110,5,2,1,233.3,234.5,100,63,1,4,AAPL,200.0,200.0,200.0,
2024-10-21 12:07:54.619937567+00:00,2024-10-21T12:07:54.620103538Z,10,2,38,C,A,2,234.0,200,130,165971,12129132,233.71,233.94,400,200,2,1,233.7,233.98,1229,44,2,3,233.66,234.0,1,154,1,7,233.58,234.07,505,30,2,1,233.53,234.13,10,400,1,1,233.45,234.17,15,1,1,1,233.4,234.25,110,50,2,1,233.39,234.41,10,600,1,2,233.31,234.43,110,5,2,1,233.3,234.5,100,63,1,4,AAPL,0.0,200.0,200.0,
2024-10-21 12:07:54.619949131+00:00,2024-10-21T12:07:54.620115428Z,10,2,38,A,A,3,234.05,400,130,166297,12129133,233.71,233.94,400,200,2,1,233.7,233.98,1229,44,2,3,233.66,234.0,1,154,1,7,233.58,234.05,505,400,2,1,233.53,234.07,10,30,1,1,233.45,234.13,15,400,1,1,233.4,234.17,110,1,2,1,233.39,234.25,10,50,1,1,233.31,234.41,110,600,2,2,233.3,234.43,100,5,1,1,AAPL,0.0,0.0,200.0,
2024-10-21 12:07:54.620382308+00:00,2024-10-21T12:07:54.620548789Z,10,2,38,A,B,0,233.72,29,130,166481,12129141,233.72,233.94,29,200,1,1,233.71,233.98,400,44,2,3,233.7,234.0,1229,154,2,7,233.66,234.05,1,400,1,1,233.58,234.07,505,30,2,1,233.53,234.13,10,400,1,1,233.45,234.17,15,1,1,1,233.4,234.25,110,50,2,1,233.39,234.41,10,600,1,2,233.31,234.43,110,5,2,1,AAPL,0.0,0.0,200.0,
2024-10-21 12:07:54.620490674+00:00,2024-10-21T12:07:54.620656776Z,10,2,38,C,A,4,234.07,30,130,166102,12129142,233.72,233.94,29,200,1,1,233.71,233.98,400,44,2,3,233.7,234.0,1229,154,2,7,233.66,234.05,1,400,1,1,233.58,234.13,505,400,2,1,233.53,234.17,10,1,1,1,233.45,234.25,15,50,1,1,233.4,234.41,110,600,2,2,233.39,234.43,10,5,1,1,233.31,234.5,110,63,2,4,AAPL,0.0,0.0,200.0,
2024-10-21 12:07:54.620533693+00:00,2024-10-21T12:07:54.620699903Z,10,2,38,A,A,4,234.12,28,130,166210,12129143,233.72,233.94,29,200,1,1,233.71,233.98,400,44,2,3,233.7,234.0,1229,154,2,7,233.66,234.05,1,400,1,1,233.58,234.12,505,28,2,1,233.53,234.13,10,400,1,1,233.45,234.17,15,1,1,1,233.4,234.25,110,50,2,1,233.39,234.41,10,600,1,2,233.31,234.43,110,5,2,1,AAPL,0.0,0.0,200.0,
2024-10-21 12:07:54.677762815+00:00,2024-10-21T12:07:54.677928883Z,10,2,38,C,B,1,233.71,200,130,166068,12129187,233.72,233.94,29,200,1,1,233.71,233.98,200,44,1,3,233.7,234.0,1229,154,2,7,233.66,234.05,1,400,1,1,233.58,234.12,505,28,2,1,233.53,234.13,10,400,1,1,233.45,234.17,15,1,1,1,233.4,234.25,110,50,2,1,233.39,234.41,10,600,1,2,233.31,234.43,110,5,2,1,AAPL,0.0,-200.0,200.0,
2024-10-21 12:07:54.677774981+00:00,2024-10-21T12:07:54.677941254Z,10,2,38,A,B,0,233.8,200,130,166273,12129188,233.8,233.94,200,200,1,1,233.72,233.98,29,44,1,3,233.7,234.0,1229,154,2,7,233.66,234.05,1,400,1,1,233.58,234.12,505,28,2,1,233.53,234.13,10,400,1,1,233.45,234.17,15,1,1,1,233.4,234.25,110,50,2,1,233.39,234.41,10,600,1,2,233.31,234.43,110,5,2,1,AAPL,0.0,0.0,200.0,
2024-10-21 12:07:54.740560308+00:00,2024-10-21T12:07:54.740726585Z,10,2,38,C,B,1,233.72,29,130,166277,12129249,233.8,233.94,200,200,1,1,233.7,233.98,1229,44,2,3,233.66,234.0,1,154,1,7,233.58,234.05,505,400,2,1,233.53,234.12,10,28,1,1,233.45,234.13,15,400,1,1,233.4,234.17,110,1,2,1,233.39,234.25,10,50,1,1,233.31,234.41,110,600,2,2,233.3,234.43,100,5,1,1,AAPL,0.0,0.0,200.0,
2024-10-21 12:07:54.740591753+00:00,2024-10-21T12:07:54.740757905Z,10,2,38,C,B,1,233.7,29,130,166152,12129250,233.8,233.94,200,200,1,1,233.7,233.98,1200,44,1,3,233.66,234.0,1,154,1,7,233.58,234.05,505,400,2,1,233.53,234.12,10,28,1,1,233.45,234.13,15,400,1,1,233.4,234.17,110,1,2,1,233.39,234.25,10,50,1,1,233.31,234.41,110,600,2,2,233.3,234.43,100,5,1,1,AAPL,0.0,-29.0,200.0,
2024-10-21 12:07:54.740668620+00:00,2024-10-21T12:07:54.740834864Z,10,2,38,A,B,1,233.75,29,130,166244,12129251,233.8,233.94,200,200,1,1,233.75,233.98,29,44,1,3,233.7,234.0,1200,154,1,7,233.66,234.05,1,400,1,1,233.58,234.12,505,28,2,1,233.53,234.13,10,400,1,1,233.45,234.17,15,1,1,1,233.4,234.25,110,50,2,1,233.39,234.41,10,600,1,2,233.31,234.43,110,5,2,1,AAPL,0.0,0.0,200.0,
2024-10-21 12:07:57.005348310+00:00,2024-10-21T12:07:57.005517492Z,10,2,38,T,N,0,233.93,50,0,169182,12130684,233.8,233.94,200,200,1,1,233.75,233.98,29,44,1,3,233.7,234.0,1200,154,1,7,233.66,234.05,1,400,1,1,233.58,234.12,505,28,2,1,233.53,234.13,10,400,1,1,233.45,234.17,15,1,1,1,233.4,234.25,110,50,2,1,233.39,234.41,10,600,1,2,233.31,234.43,110,5,2,1,AAPL,0.0,0.0,0.0,
2024-10-21 12:07:57.005348926+00:00,2024-10-21T12:07:57.005517492Z,10,2,38,T,N,0,233.93,50,130,168566,12130685,233.8,233.94,200,200,1,1,233.75,233.98,29,44,1,3,233.7,234.0,1200,154,1,7,233.66,234.05,1,400,1,1,233.58,234.12,505,28,2,1,233.53,234.13,10,400,1,1,233.45,234.17,15,1,1,1,233.4,234.25,110,50,2,1,233.39,234.41,10,600,1,2,233.31,234.43,110,5,2,1,AAPL,0.0,0.0,0.0,
2024-10-21 12:07:57.005648252+00:00,2024-10-21T12:07:57.005814257Z,10,2,38,A,B,0,233.91,100,130,166005,12130686,233.91,233.94,100,200,1,1,233.8,233.98,200,44,1,3,233.75,234.0,29,154,1,7,233.7,234.05,1200,400,1,1,233.66,234.12,1,28,1,1,233.58,234.13,505,400,2,1,233.53,234.17,10,1,1,1,233.45,234.25,15,50,1,1,233.4,234.41,110,600,2,2,233.39,234.43,10,5,1,1,AAPL,0.0,0.0,0.0,
2024-10-21 12:07:57.006073356+00:00,2024-10-21T12:07:57.006239314Z,10,2,38,C,B,0,233.91,100,130,165958,12130687,233.8,233.94,200,200,1,1,233.75,233.98,29,44,1,3,233.7,234.0,1200,154,1,7,233.66,234.05,1,400,1,1,233.58,234.12,505,28,2,1,233.53,234.13,10,400,1,1,233.45,234.17,15,1,1,1,233.4,234.25,110,50,2,1,233.39,234.41,10,600,1,2,233.31,234.43,110,5,2,1,AAPL,0.0,0.0,0.0,
2024-10-21 12:07:57.069351091+00:00,2024-10-21T12:07:57.069517287Z,10,2,38,C,A,3,234.05,200,130,166196,12130710,233.8,233.94,200,200,1,1,233.75,233.98,29,44,1,3,233.7,234.0,1200,154,1,7,233.66,234.05,1,200,1,1,233.58,234.12,505,28,2,1,233.53,234.13,10,400,1,1,233.45,234.17,15,1,1,1,233.4,234.25,110,50,2,1,233.39,234.41,10,600,1,2,233.31,234.43,110,5,2,1,AAPL,0.0,200.0,0.0,
2024-10-21 12:07:57.258842550+00:00,2024-10-21T12:07:57.259009812Z,10,2,38,T,N,0,233.93,50,130,167262,12130840,233.8,233.94,200,200,1,1,233.75,233.98,29,44,1,3,233.7,234.0,1200,154,1,7,233.66,234.05,1,200,1,1,233.58,234.12,505,28,2,1,233.53,234.13,10,400,1,1,233.45,234.17,15,1,1,1,233.4,234.25,110,50,2,1,233.39,234.41,10,600,1,2,233.31,234.43,110,5,2,1,AAPL,0.0,0.0,0.0,
2024-10-21 12:07:58.008823092+00:00,2024-10-21T12:07:58.008991267Z,10,2,38,T,B,0,233.94,50,130,168175,12131171,233.8,233.94,200,200,1,1,233.75,233.98,29,44,1,3,233.7,234.0,1200,154,1,7,233.66,234.05,1,200,1,1,233.58,234.12,505,28,2,1,233.53,234.13,10,400,1,1,233.45,234.17,15,1,1,1,233.4,234.25,110,50,2,1,233.39,234.41,10,600,1,2,233.31,234.43,110,5,2,1,AAPL,0.0,0.0,0.0,
2024-10-21 12:07:58.008823092+00:00,2024-10-21T12:07:58.008991267Z,10,2,38,C,A,0,233.94,50,130,168175,12131171,233.8,233.94,200,150,1,1,233.75,233.98,29,44,1,3,233.7,234.0,1200,154,1,7,233.66,234.05,1,200,1,1,233.58,234.12,505,28,2,1,233.53,234.13,10,400,1,1,233.45,234.17,15,1,1,1,233.4,234.25,110,50,2,1,233.39,234.41,10,600,1,2,233.31,234.43,110,5,2,1,AAPL,50.0,50.0,50.0,
2024-10-21 12:07:58.008889077+00:00,2024-10-21T12:07:58.009054960Z,10,2,38,C,A,3,234.05,200,130,165883,12131172,233.8,233.94,200,150,1,1,233.75,233.98,29,44,1,3,233.7,234.0,1200,154,1,7,233.66,234.12,1,28,1,1,233.58,234.13,505,400,2,1,233.53,234.17,10,1,1,1,233.45,234.25,15,50,1,1,233.4,234.41,110,600,2,2,233.39,234.43,10,5,1,1,233.31,234.5,110,63,2,4,AAPL,0.0,0.0,50.0,
2024-10-21 12:07:58.036947209+00:00,2024-10-21T12:07:58.037113337Z,10,2,38,A,A,3,234.05,200,130,166128,12131183,233.8,233.94,200,150,1,1,233.75,233.98,29,44,1,3,233.7,234.0,1200,154,1,7,233.66,234.05,1,200,1,1,233.58,234.12,505,28,2,1,233.53,234.13,10,400,1,1,233.45,234.17,15,1,1,1,233.4,234.25,110,50,2,1,233.39,234.41,10,600,1,2,233.31,234.43,110,5,2,1,AAPL,0.0,0.0,50.0,
2024-10-21 12:07:58.162656656+00:00,2024-10-21T12:07:58.162823341Z,10,2,38,A,A,3,234.05,200,130,166685,12131260,233.8,233.94,200,150,1,1,233.75,233.98,29,44,1,3,233.7,234.0,1200,154,1,7,233.66,234.05,1,400,1,2,233.58,234.12,505,28,2,1,233.53,234.13,10,400,1,1,233.45,234.17,15,1,1,1,233.4,234.25,110,50,2,1,233.39,234.41,10,600,1,2,233.31,234.43,110,5,2,1,AAPL,0.0,-200.0,50.0,
2024-10-21 12:08:07.337716526+00:00,2024-10-21T12:08:07.337883263Z,10,2,38,A,B,0,233.81,200,130,166737,12137724,233.81,233.94,200,150,1,1,233.75,233.98,29,44,1,3,233.7,234.0,1200,154,1,7,233.66,234.05,1,400,1,2,233.58,234.12,505,28,2,1,233.53,234.13,10,400,1,1,233.45,234.17,15,1,1,1,233.4,234.25,110,50,2,1,233.39,234.41,10,600,1,2,233.31,234.43,110,5,2,1,AAPL,0.0,0.0,0.0,
2024-10-21 12:08:07.341475627+00:00,2024-10-21T12:08:07.341641992Z,10,2,38,A,B,1,233.76,29,130,166365,12137749,233.81,233.94,200,150,1,1,233.76,233.98,29,44,1,3,233.75,234.0,29,154,1,7,233.7,234.05,1200,400,1,2,233.66,234.12,1,28,1,1,233.58,234.13,505,400,2,1,233.53,234.17,10,1,1,1,233.45,234.25,15,50,1,1,233.4,234.41,110,600,2,2,233.39,234.43,10,5,1,1,AAPL,0.0,0.0,0.0,
2024-10-21 12:08:07.343053018+00:00,2024-10-21T12:08:07.343219276Z,10,2,38,C,B,2,233.75,29,130,166258,12137753,233.81,233.94,200,150,1,1,233.76,233.98,29,44,1,3,233.7,234.0,1200,154,1,7,233.66,234.05,1,400,1,2,233.58,234.12,505,28,2,1,233.53,234.13,10,400,1,1,233.45,234.17,15,1,1,1,233.4,234.25,110,50,2,1,233.39,234.41,10,600,1,2,233.31,234.43,110,5,2,1,AAPL,0.0,0.0,0.0,
2024-10-21 12:08:11.980882050+00:00,2024-10-21T12:08:11.981052333Z,10,2,38,T,N,0,233.93,44,0,170283,12141046,233.81,233.94,200,150,1,1,233.76,233.98,29,44,1,3,233.7,234.0,1200,154,1,7,233.66,234.05,1,400,1,2,233.58,234.12,505,28,2,1,233.53,234.13,10,400,1,1,233.45,234.17,15,1,1,1,233.4,234.25,110,50,2,1,233.39,234.41,10,600,1,2,233.31,234.43,110,5,2,1,AAPL,0.0,0.0,0.0,
2024-10-21 12:08:11.980882050+00:00,2024-10-21T12:08:11.981052333Z,10,2,38,T,B,0,233.94,56,130,170283,12141047,233.81,233.94,200,150,1,1,233.76,233.98,29,44,1,3,233.7,234.0,1200,154,1,7,233.66,234.05,1,400,1,2,233.58,234.12,505,28,2,1,233.53,234.13,10,400,1,1,233.45,234.17,15,1,1,1,233.4,234.25,110,50,2,1,233.39,234.41,10,600,1,2,233.31,234.43,110,5,2,1,AAPL,0.0,0.0,0.0,
2024-10-21 12:08:11.980882050+00:00,2024-10-21T12:08:11.981052333Z,10,2,38,C,A,0,233.94,56,130,170283,12141047,233.81,233.94,200,94,1,1,233.76,233.98,29,44,1,3,233.7,234.0,1200,154,1,7,233.66,234.05,1,400,1,2,233.58,234.12,505,28,2,1,233.53,234.13,10,400,1,1,233.45,234.17,15,1,1,1,233.4,234.25,110,50,2,1,233.39,234.41,10,600,1,2,233.31,234.43,110,5,2,1,AAPL,56.0,56.0,56.0,
2024-10-21 12:08:22.863309742+00:00,2024-10-21T12:08:22.863475945Z,10,2,38,C,B,0,233.81,200,130,166203,12147416,233.76,233.94,29,94,1,1,233.7,233.98,1200,44,1,3,233.66,234.0,1,154,1,7,233.58,234.05,505,400,2,2,233.53,234.12,10,28,1,1,233.45,234.13,15,400,1,1,233.4,234.17,110,1,2,1,233.39,234.25,10,50,1,1,233.31,234.41,110,600,2,2,233.3,234.43,100,5,1,1,AAPL,0.0,0.0,0.0,
2024-10-21 12:08:22.863323283+00:00,2024-10-21T12:08:22.863490039Z,10,2,38,A,B,1,233.73,400,130,166756,12147417,233.76,233.94,29,94,1,1,233.73,233.98,400,44,1,3,233.7,234.0,1200,154,1,7,233.66,234.05,1,400,1,2,233.58,234.12,505,28,2,1,233.53,234.13,10,400,1,1,233.45,234.17,15,1,1,1,233.4,234.25,110,50,2,1,233.39,234.41,10,600,1,2,233.31,234.43,110,5,2,1,AAPL,0.0,0.0,0.0,
2024-10-21 12:08:22.881949837+00:00,2024-10-21T12:08:22.882115852Z,10,2,38,C,B,0,233.76,29,130,166015,12147431,233.73,233.94,400,94,1,1,233.7,233.98,1200,44,1,3,233.66,234.0,1,154,1,7,233.58,234.05,505,400,2,2,233.53,234.12,10,28,1,1,233.45,234.13,15,400,1,1,233.4,234.17,110,1,2,1,233.39,234.25,10,50,1,1,233.31,234.41,110,600,2,2,233.3,234.43,100,5,1,1,AAPL,0.0,0.0,0.0,
2024-10-21 12:08:22.881992297+00:00,2024-10-21T12:08:22.882158439Z,10,2,38,A,B,1,233.71,30,130,166142,12147432,233.73,233.94,400,94,1,1,233.71,233.98,30,44,1,3,233.7,234.0,1200,154,1,7,233.66,234.05,1,400,1,2,233.58,234.12,505,28,2,1,233.53,234.13,10,400,1,1,233.45,234.17,15,1,1,1,233.4,234.25,110,50,2,1,233.39,234.41,10,600,1,2,233.31,234.43,110,5,2,1,AAPL,0.0,0.0,0.0,
2024-10-21 12:08:22.934444989+00:00,2024-10-21T12:08:22.934611176Z,10,2,38,C,B,0,233.73,200,130,166187,12147478,233.73,233.94,200,94,1,1,233.71,233.98,30,44,1,3,233.7,234.0,1200,154,1,7,233.66,234.05,1,400,1,2,233.58,234.12,505,28,2,1,233.53,234.13,10,400,1,1,233.45,234.17,15,1,1,1,233.4,234.25,110,50,2,1,233.39,234.41,10,600,1,2,233.31,234.43,110,5,2,1,AAPL,-200.0,-200.0,-200.0,
2024-10-21 12:08:25.917764011+00:00,2024-10-21T12:08:25.917930565Z,10,2,38,A,B,0,233.77,200,130,166554,12149527,233.77,233.94,200,94,1,1,233.71,233.98,30,44,1,3,233.7,234.0,1200,154,1,7,233.66,234.05,1,400,1,2,233.58,234.12,505,28,2,1,233.53,234.13,10,400,1,1,233.45,234.17,15,1,1,1,233.4,234.25,110,50,2,1,233.39,234.41,10,600,1,2,233.31,234.43,110,5,2,1,AAPL,0.0,0.0,0.0,
2024-10-21 12:08:36.931191504+00:00,2024-10-21T12:08:36.931357634Z,10,2,38,C,A,3,234.05,200,130,166130,12157931,233.77,233.94,200,94,1,1,233.71,233.98,30,44,1,3,233.7,234.0,1200,154,1,7,233.66,234.05,1,200,1,1,233.58,234.12,505,28,2,1,233.53,234.13,10,400,1,1,233.45,234.17,15,1,1,1,233.4,234.25,110,50,2,1,233.39,234.41,10,600,1,2,233.31,234.43,110,5,2,1,AAPL,0.0,200.0,0.0,
2024-10-21 12:08:36.931201585+00:00,2024-10-21T12:08:36.931367641Z,10,2,38,C,A,3,234.05,200,130,166056,12157932,233.77,233.94,200,94,1,1,233.71,233.98,30,44,1,3,233.7,234.0,1200,154,1,7,233.66,234.12,1,28,1,1,233.58,234.13,505,400,2,1,233.53,234.17,10,1,1,1,233.45,234.25,15,50,1,1,233.4,234.41,110,600,2,2,233.39,234.43,10,5,1,1,233.31,234.5,110,63,2,4,AAPL,0.0,0.0,0.0,
2024-10-21 12:08:36.931212780+00:00,2024-10-21T12:08:36.931379398Z,10,2,38,A,A,3,234.07,400,130,166618,12157933,233.77,233.94,200,94,1,1,233.71,233.98,30,44,1,3,233.7,234.0,1200,154,1,7,233.66,234.07,1,400,1,1,233.58,234.12,505,28,2,1,233.53,234.13,10,400,1,1,233.45,234.17,15,1,1,1,233.4,234.25,110,50,2,1,233.39,234.41,10,600,1,2,233.31,234.43,110,5,2,1,AAPL,0.0,0.0,0.0,
2024-10-21 12:08:36.985980884+00:00,2024-10-21T12:08:36.986147102Z,10,2,38,A,B,0,233.78,200,130,166218,12158018,233.78,233.94,200,94,1,1,233.71,233.98,30,44,1,3,233.7,234.0,1200,154,1,7,233.66,234.07,1,400,1,1,233.58,234.12,505,28,2,1,233.53,234.13,10,400,1,1,233.45,234.17,15,1,1,1,233.4,234.25,110,50,2,1,233.39,234.41,10,600,1,2,233.31,234.43,110,5,2,1,AAPL,0.0,0.0,0.0,
2024-10-21 12:08:37.008605354+00:00,2024-10-21T12:08:37.008771530Z,10,2,38,A,B,1,233.72,28,130,166176,12158236,233.78,233.94,200,94,1,1,233.72,233.98,28,44,1,3,233.71,234.0,30,154,1,7,233.7,234.07,1200,400,1,1,233.66,234.12,1,28,1,1,233.58,234.13,505,400,2,1,233.53,234.17,10,1,1,1,233.45,234.25,15,50,1,1,233.4,234.41,110,600,2,2,233.39,234.43,10,5,1,1,AAPL,0.0,0.0,0.0,
2024-10-21 12:08:37.008657827+00:00,2024-10-21T12:08:37.008823724Z,10,2,38,C,B,2,233.71,30,130,165897,12158237,233.78,233.94,200,94,1,1,233.72,233.98,28,44,1,3,233.7,234.0,1200,154,1,7,233.66,234.07,1,400,1,1,233.58,234.12,505,28,2,1,233.53,234.13,10,400,1,1,233.45,234.17,15,1,1,1,233.4,234.25,110,50,2,1,233.39,234.41,10,600,1,2,233.31,234.43,110,5,2,1,AAPL,0.0,0.0,0.0,
2024-10-21 12:08:37.017706043+00:00,2024-10-21T12:08:37.017872239Z,10,2,38,A,A,4,234.09,27,130,166196,12158260,233.78,233.94,200,94,1,1,233.72,233.98,28,44,1,3,233.7,234.0,1200,154,1,7,233.66,234.07,1,400,1,1,233.58,234.09,505,27,2,1,233.53,234.12,10,28,1,1,233.45,234.13,15,400,1,1,233.4,234.17,110,1,2,1,233.39,234.25,10,50,1,1,233.31,234.41,110,600,2,2,AAPL,0.0,0.0,0.0,
2024-10-21 12:08:37.017734583+00:00,2024-10-21T12:08:37.017900433Z,10,2,38,C,A,5,234.12,28,130,165850,12158261,233.78,233.94,200,94,1,1,233.72,233.98,28,44,1,3,233.7,234.0,1200,154,1,7,233.66,234.07,1,400,1,1,233.58,234.09,505,27,2,1,233.53,234.13,10,400,1,1,233.45,234.17,15,1,1,1,233.4,234.25,110,50,2,1,233.39,234.41,10,600,1,2,233.31,234.43,110,5,2,1,AAPL,0.0,0.0,0.0,
2024-10-21 12:08:37.054120455+00:00,2024-10-21T12:08:37.054287009Z,10,2,38,A,A,3,234.04,200,130,166554,12158303,233.78,233.94,200,94,1,1,233.72,233.98,28,44,1,3,233.7,234.0,1200,154,1,7,233.66,234.04,1,200,1,1,233.58,234.09,505,27,2,1,233.53,234.13,10,400,1,1,233.45,234.17,15,1,1,1,233.4,234.25,110,50,2,1,233.39,234.41,10,600,1,2,233.31,234.43,110,5,2,1,AAPL,0.0,0.0,0.0,
2024-10-21 12:08:37.140123992+00:00,2024-10-21T12:08:37.140290334Z,10,2,38,A,A,3,234.03,200,130,166342,12158500,233.78,233.94,200,94,1,1,233.72,233.98,28,44,1,3,233.7,234.0,1200,154,1,7,233.66,234.03,1,200,1,1,233.58,234.09,505,27,2,1,233.53,234.13,10,400,1,1,233.45,234.17,15,1,1,1,233.4,234.25,110,50,2,1,233.39,234.41,10,600,1,2,233.31,234.43,110,5,2,1,AAPL,0.0,0.0,0.0,
2024-10-21 12:08:37.210561446+00:00,2024-10-21T12:08:37.210727255Z,10,2,38,C,B,0,233.78,200,130,165809,12158736,233.72,233.94,28,94,1,1,233.7,233.98,1200,44,1,3,233.66,234.0,1,154,1,7,233.58,234.03,505,200,2,1,233.53,234.09,10,27,1,1,233.45,234.13,15,400,1,1,233.4,234.17,110,1,2,1,233.39,234.25,10,50,1,1,233.31,234.41,110,600,2,2,233.3,234.43,100,5,1,1,AAPL,0.0,0.0,0.0,
2024-10-21 12:08:37.210572545+00:00,2024-10-21T12:08:37.210738801Z,10,2,38,A,B,0,233.76,200,130,166256,12158737,233.76,233.94,200,94,1,1,233.72,233.98,28,44,1,3,233.7,234.0,1200,154,1,7,233.66,234.03,1,200,1,1,233.58,234.09,505,27,2,1,233.53,234.13,10,400,1,1,233.45,234.17,15,1,1,1,233.4,234.25,110,50,2,1,233.39,234.41,10,600,1,2,233.31,234.43,110,5,2,1,AAPL,0.0,0.0,0.0,
2024-10-21 12:08:37.269320274+00:00,2024-10-21T12:08:37.269487007Z,10,2,38,A,A,3,234.02,200,130,166733,12158910,233.76,233.94,200,94,1,1,233.72,233.98,28,44,1,3,233.7,234.0,1200,154,1,7,233.66,234.02,1,200,1,1,233.58,234.09,505,27,2,1,233.53,234.13,10,400,1,1,233.45,234.17,15,1,1,1,233.4,234.25,110,50,2,1,233.39,234.41,10,600,1,2,233.31,234.43,110,5,2,1,AAPL,0.0,0.0,0.0,
2024-10-21 12:08:37.922862859+00:00,2024-10-21T12:08:37.923028889Z,10,2,38,C,A,4,234.09,27,130,166030,12159796,233.76,233.94,200,94,1,1,233.72,233.98,28,44,1,3,233.7,234.0,1200,154,1,7,233.66,234.02,1,200,1,1,233.58,234.13,505,400,2,1,233.53,234.17,10,1,1,1,233.45,234.25,15,50,1,1,233.4,234.41,110,600,2,2,233.39,234.43,10,5,1,1,233.31,234.5,110,63,2,4,AAPL,0.0,0.0,0.0,
2024-10-21 12:08:37.922947266+00:00,2024-10-21T12:08:37.923113415Z,10,2,38,A,A,4,234.07,29,130,166149,12159797,233.76,233.94,200,94,1,1,233.72,233.98,28,44,1,3,233.7,234.0,1200,154,1,7,233.66,234.02,1,200,1,1,233.58,234.07,505,29,2,1,233.53,234.13,10,400,1,1,233.45,234.17,15,1,1,1,233.4,234.25,110,50,2,1,233.39,234.41,10,600,1,2,233.31,234.43,110,5,2,1,AAPL,0.0,0.0,0.0,
2024-10-21 12:08:38.864074729+00:00,2024-10-21T12:08:38.864240686Z,10,2,38,A,A,0,233.93,100,130,165957,12160370,233.76,233.93,200,100,1,1,233.72,233.94,28,94,1,1,233.7,233.98,1200,44,1,3,233.66,234.0,1,154,1,7,233.58,234.02,505,200,2,1,233.53,234.07,10,29,1,1,233.45,234.13,15,400,1,1,233.4,234.17,110,1,2,1,233.39,234.25,10,50,1,1,233.31,234.41,110,600,2,2,AAPL,0.0,0.0,0.0,
2024-10-21 12:08:38.864096354+00:00,2024-10-21T12:08:38.864263169Z,10,2,38,C,B,0,233.76,200,130,166815,12160371,233.72,233.93,28,100,1,1,233.7,233.94,1200,94,1,1,233.66,233.98,1,44,1,3,233.58,234.0,505,154,2,7,233.53,234.02,10,200,1,1,233.45,234.07,15,29,1,1,233.4,234.13,110,400,2,1,233.39,234.17,10,1,1,1,233.31,234.25,110,50,2,1,233.3,234.41,100,600,1,2,AAPL,0.0,0.0,0.0,
2024-10-21 12:08:38.864439490+00:00,2024-10-21T12:08:38.864605497Z,10,2,38,C,A,0,233.93,100,130,166007,12160377,233.72,233.94,28,94,1,1,233.7,233.98,1200,44,1,3,233.66,234.0,1,154,1,7,233.58,234.02,505,200,2,1,233.53,234.07,10,29,1,1,233.45,234.13,15,400,1,1,233.4,234.17,110,1,2,1,233.39,234.25,10,50,1,1,233.31,234.41,110,600,2,2,233.3,234.43,100,5,1,1,AAPL,0.0,0.0,0.0,
2024-10-21 12:08:38.972450149+00:00,2024-10-21T12:08:38.972616790Z,10,2,38,A,B,0,233.74,200,130,166641,12160439,233.74,233.94,200,94,1,1,233.72,233.98,28,44,1,3,233.7,234.0,1200,154,1,7,233.66,234.02,1,200,1,1,233.58,234.07,505,29,2,1,233.53,234.13,10,400,1,1,233.45,234.17,15,1,1,1,233.4,234.25,110,50,2,1,233.39,234.41,10,600,1,2,233.31,234.43,110,5,2,1,AAPL,0.0,0.0,0.0,
2024-10-21 12:08:38.985809168+00:00,2024-10-21T12:08:38.985975726Z,10,2,38,A,A,2,234.0,200,130,166558,12160448,233.74,233.94,200,94,1,1,233.72,233.98,28,44,1,3,233.7,234.0,1200,354,1,8,233.66,234.07,1,29,1,1,233.58,234.13,505,400,2,1,233.53,234.17,10,1,1,1,233.45,234.25,15,50,1,1,233.4,234.41,110,600,2,2,233.39,234.43,10,5,1,1,233.31,234.5,110,63,2,4,AAPL,0.0,-200.0,0.0,
2024-10-21 12:08:39.004863316+00:00,2024-10-21T12:08:39.005029517Z,10,2,38,C,A,2,234.0,200,130,166201,12160461,233.74,233.94,200,94,1,1,233.72,233.98,28,44,1,3,233.7,234.0,1200,154,1,7,233.66,234.07,1,29,1,1,233.58,234.13,505,400,2,1,233.53,234.17,10,1,1,1,233.45,234.25,15,50,1,1,233.4,234.41,110,600,2,2,233.39,234.43,10,5,1,1,233.31,234.5,110,63,2,4,AAPL,0.0,200.0,0.0,
2024-10-21 12:08:39.004876187+00:00,2024-10-21T12:08:39.005042528Z,10,2,38,A,A,3,234.02,200,130,166341,12160462,233.74,233.94,200,94,1,1,233.72,233.98,28,44,1,3,233.7,234.0,1200,154,1,7,233.66,234.02,1,200,1,1,233.58,234.07,505,29,2,1,233.53,234.13,10,400,1,1,233.45,234.17,15,1,1,1,233.4,234.25,110,50,2,1,233.39,234.41,10,600,1,2,233.31,234.43,110,5,2,1,AAPL,0.0,0.0,0.0,
2024-10-21 12:08:39.005322111+00:00,2024-10-21T12:08:39.005488223Z,10,2,38,A,B,0,233.75,29,130,166112,12160463,233.75,233.94,29,94,1,1,233.74,233.98,200,44,1,3,233.72,234.0,28,154,1,7,233.7,234.02,1200,200,1,1,233.66,234.07,1,29,1,1,233.58,234.13,505,400,2,1,233.53,234.17,10,1,1,1,233.45,234.25,15,50,1,1,233.4,234.41,110,600,2,2,233.39,234.43,10,5,1,1,AAPL,0.0,0.0,0.0,
2024-10-21 12:08:39.005350151+00:00,2024-10-21T12:08:39.005516016Z,10,2,38,C,B,2,233.72,28,130,165865,12160464,233.75,233.94,29,94,1,1,233.74,233.98,200,44,1,3,233.7,234.0,1200,154,1,7,233.66,234.02,1,200,1,1,233.58,234.07,505,29,2,1,233.53,234.13,10,400,1,1,233.45,234.17,15,1,1,1,233.4,234.25,110,50,2,1,233.39,234.41,10,600,1,2,233.31,234.43,110,5,2,1,AAPL,0.0,0.0,0.0,
2024-10-21 12:08:39.007699591+00:00,2024-10-21T12:08:39.007865569Z,10,2,38,C,A,3,234.02,200,130,165978,12160465,233.75,233.94,29,94,1,1,233.74,233.98,200,44,1,3,233.7,234.0,1200,154,1,7,233.66,234.07,1,29,1,1,233.58,234.13,505,400,2,1,233.53,234.17,10,1,1,1,233.45,234.25,15,50,1,1,233.4,234.41,110,600,2,2,233.39,234.43,10,5,1,1,233.31,234.5,110,63,2,4,AAPL,0.0,0.0,0.0,
2024-10-21 12:08:39.007712438+00:00,2024-10-21T12:08:39.007878744Z,10,2,38,A,A,3,234.06,400,130,166306,12160466,233.75,233.94,29,94,1,1,233.74,233.98,200,44,1,3,233.7,234.0,1200,154,1,7,233.66,234.06,1,400,1,1,233.58,234.07,505,29,2,1,233.53,234.13,10,400,1,1,233.45,234.17,15,1,1,1,233.4,234.25,110,50,2,1,233.39,234.41,10,600,1,2,233.31,234.43,110,5,2,1,AAPL,0.0,0.0,0.0,
2024-10-21 12:08:39.069736562+00:00,2024-10-21T12:08:39.069902920Z,10,2,38,A,B,0,233.75,200,130,166358,12160501,233.75,233.94,229,94,2,1,233.7,233.98,1200,44,1,3,233.66,234.0,1,154,1,7,233.58,234.06,505,400,2,1,233.53,234.07,10,29,1,1,233.45,234.13,15,400,1,1,233.4,234.17,110,1,2,1,233.39,234.25,10,50,1,1,233.31,234.41,110,600,2,2,233.3,234.43,100,5,1,1,AAPL,200.0,200.0,200.0,
2024-10-21 12:08:39.162773976+00:00,2024-10-21T12:08:39.162940859Z,10,2,38,A,B,0,233.76,200,130,166883,12160573,233.76,233.94,200,94,1,1,233.75,233.98,29,44,1,3,233.7,234.0,1200,154,1,7,233.66,234.06,1,400,1,1,233.58,234.07,505,29,2,1,233.53,234.13,10,400,1,1,233.45,234.17,15,1,1,1,233.4,234.25,110,50,2,1,233.39,234.41,10,600,1,2,233.31,234.43,110,5,2,1,AAPL,0.0,0.0,200.0,
2024-10-21 12:08:41.638527966+00:00,2024-10-21T12:08:41.638694239Z,10,2,38,A,B,0,233.77,200,130,166273,12161762,233.77,233.94,200,94,1,1,233.75,233.98,29,44,1,3,233.7,234.0,1200,154,1,7,233.66,234.06,1,400,1,1,233.58,234.07,505,29,2,1,233.53,234.13,10,400,1,1,233.45,234.17,15,1,1,1,233.4,234.25,110,50,2,1,233.39,234.41,10,600,1,2,233.31,234.43,110,5,2,1,AAPL,0.0,0.0,0.0,
2024-10-21 12:08:41.645312053+00:00,2024-10-21T12:08:41.645478168Z,10,2,38,A,B,1,233.76,28,130,166115,12161778,233.77,233.94,200,94,1,1,233.76,233.98,28,44,1,3,233.75,234.0,29,154,1,7,233.7,234.06,1200,400,1,1,233.66,234.07,1,29,1,1,233.58,234.13,505,400,2,1,233.53,234.17,10,1,1,1,233.45,234.25,15,50,1,1,233.4,234.41,110,600,2,2,233.39,234.43,10,5,1,1,AAPL,0.0,0.0,0.0,
2024-10-21 12:08:41.701297052+00:00,2024-10-21T12:08:41.701463079Z,10,2,38,C,B,1,233.76,28,130,166027,12161796,233.77,233.94,200,94,1,1,233.75,233.98,29,44,1,3,233.7,234.0,1200,154,1,7,233.66,234.06,1,400,1,1,233.58,234.07,505,29,2,1,233.53,234.13,10,400,1,1,233.45,234.17,15,1,1,1,233.4,234.25,110,50,2,1,233.39,234.41,10,600,1,2,233.31,234.43,110,5,2,1,AAPL,0.0,0.0,0.0,
2024-10-21 12:08:41.701320255+00:00,2024-10-21T12:08:41.701486252Z,10,2,38,C,B,1,233.75,29,130,165997,12161797,233.77,233.94,200,94,1,1,233.7,233.98,1200,44,1,3,233.66,234.0,1,154,1,7,233.58,234.06,505,400,2,1,233.53,234.07,10,29,1,1,233.45,234.13,15,400,1,1,233.4,234.17,110,1,2,1,233.39,234.25,10,50,1,1,233.31,234.41,110,600,2,2,233.3,234.43,100,5,1,1,AAPL,0.0,0.0,0.0,
2024-10-21 12:08:41.701391064+00:00,2024-10-21T12:08:41.701557283Z,10,2,38,A,B,1,233.76,30,130,166219,12161798,233.77,233.94,200,94,1,1,233.76,233.98,30,44,1,3,233.7,234.0,1200,154,1,7,233.66,234.06,1,400,1,1,233.58,234.07,505,29,2,1,233.53,234.13,10,400,1,1,233.45,234.17,15,1,1,1,233.4,234.25,110,50,2,1,233.39,234.41,10,600,1,2,233.31,234.43,110,5,2,1,AAPL,0.0,0.0,0.0,
2024-10-21 12:08:44.045776235+00:00,2024-10-21T12:08:44.045945399Z,10,2,38,T,B,0,233.94,94,0,169164,12162738,233.77,233.94,200,94,1,1,233.76,233.98,30,44,1,3,233.7,234.0,1200,154,1,7,233.66,234.06,1,400,1,1,233.58,234.07,505,29,2,1,233.53,234.13,10,400,1,1,233.45,234.17,15,1,1,1,233.4,234.25,110,50,2,1,233.39,234.41,10,600,1,2,233.31,234.43,110,5,2,1,AAPL,0.0,0.0,0.0,
2024-10-21 12:08:44.045776717+00:00,2024-10-21T12:08:44.045945399Z,10,2,38,T,N,0,233.94,94,130,168682,12162739,233.77,233.98,200,44,1,3,233.76,234.0,30,154,1,7,233.7,234.06,1200,400,1,1,233.66,234.07,1,29,1,1,233.58,234.13,505,400,2,1,233.53,234.17,10,1,1,1,233.45,234.25,15,50,1,1,233.4,234.41,110,600,2,2,233.39,234.43,10,5,1,1,233.31,234.5,110,63,2,4,AAPL,0.0,0.0,0.0,
2024-10-21 12:08:44.045799937+00:00,2024-10-21T12:08:44.045968264Z,10,2,38,A,B,0,233.86,100,130,168327,12162740,233.86,233.98,100,44,1,3,233.77,234.0,200,154,1,7,233.76,234.06,30,400,1,1,233.7,234.07,1200,29,1,1,233.66,234.13,1,400,1,1,233.58,234.17,505,1,2,1,233.53,234.25,10,50,1,1,233.45,234.41,15,600,1,2,233.4,234.43,110,5,2,1,233.39,234.5,10,63,1,4,AAPL,0.0,0.0,0.0,
2024-10-21 12:08:44.045814276+00:00,2024-10-21T12:08:44.045981222Z,10,2,38,A,B,1,233.81,100,130,166946,12162742,233.86,233.98,100,44,1,3,233.81,234.0,100,154,1,7,233.77,234.06,200,400,1,1,233.76,234.07,30,29,1,1,233.7,234.13,1200,400,1,1,233.66,234.17,1,1,1,1,233.58,234.25,505,50,2,1,233.53,234.41,10,600,1,2,233.45,234.43,15,5,1,1,233.4,234.5,110,63,2,4,AAPL,0.0,0.0,0.0,
2024-10-21 12:08:44.045826034+00:00,2024-10-21T12:08:44.045992597Z,10,2,38,C,B,0,233.86,100,130,166563,12162744,233.85,233.98,57,44,1,3,233.81,234.0,100,154,1,7,233.77,234.06,200,400,1,1,233.76,234.07,30,29,1,1,233.7,234.13,1200,400,1,1,233.66,234.17,1,1,1,1,233.58,234.25,505,50,2,1,233.53,234.41,10,600,1,2,233.45,234.43,15,5,1,1,233.4,234.5,110,63,2,4,AAPL,0.0,0.0,0.0,
2024-10-21 12:08:44.045839714+00:00,2024-10-21T12:08:44.046005890Z,10,2,38,A,B,1,233.8,57,130,166176,12162746,233.85,233.98,57,44,1,3,233.8,234.0,57,154,1,7,233.77,234.06,200,400,1,1,233.76,234.07,30,29,1,1,233.7,234.13,1200,400,1,1,233.66,234.17,1,1,1,1,233.58,234.25,505,50,2,1,233.53,234.41,10,600,1,2,233.45,234.43,15,5,1,1,233.4,234.5,110,63,2,4,AAPL,0.0,0.0,0.0,
2024-10-21 12:08:44.046075488+00:00,2024-10-21T12:08:44.046241847Z,10,2,38,A,B,0,233.88,100,130,166359,12162751,233.88,233.98,100,44,1,3,233.85,234.0,57,154,1,7,233.8,234.06,57,400,1,1,233.77,234.07,200,29,1,1,233.76,234.13,30,400,1,1,233.7,234.17,1200,1,1,1,233.66,234.25,1,50,1,1,233.58,234.41,505,600,2,2,233.53,234.43,10,5,1,1,233.45,234.5,15,63,1,4,AAPL,0.0,0.0,0.0,
2024-10-21 12:08:44.046577511+00:00,2024-10-21T12:08:44.046743441Z,10,2,38,C,B,0,233.88,100,130,165930,12162753,233.85,233.98,57,44,1,3,233.8,234.0,57,154,1,7,233.77,234.06,200,400,1,1,233.76,234.07,30,29,1,1,233.7,234.13,1200,400,1,1,233.66,234.17,1,1,1,1,233.58,234.25,505,50,2,1,233.53,234.41,10,600,1,2,233.45,234.43,15,5,1,1,233.4,234.5,110,63,2,4,AAPL,0.0,0.0,0.0,
2024-10-21 12:08:44.062697315+00:00,2024-10-21T12:08:44.062866261Z,10,2,38,T,N,0,233.94,44,130,168946,12162795,233.85,233.98,57,44,1,3,233.8,234.0,57,154,1,7,233.77,234.06,200,400,1,1,233.76,234.07,30,29,1,1,233.7,234.13,1200,400,1,1,233.66,234.17,1,1,1,1,233.58,234.25,505,50,2,1,233.53,234.41,10,600,1,2,233.45,234.43,15,5,1,1,233.4,234.5,110,63,2,4,AAPL,0.0,0.0,0.0,
2024-10-21 12:08:44.062714891+00:00,2024-10-21T12:08:44.062883209Z,10,2,38,T,N,0,233.94,27,0,168318,12162796,233.85,233.98,57,44,1,3,233.8,234.0,57,154,1,7,233.77,234.06,200,400,1,1,233.76,234.07,30,29,1,1,233.7,234.13,1200,400,1,1,233.66,234.17,1,1,1,1,233.58,234.25,505,50,2,1,233.53,234.41,10,600,1,2,233.45,234.43,15,5,1,1,233.4,234.5,110,63,2,4,AAPL,0.0,0.0,0.0,
2024-10-21 12:08:44.062714891+00:00,2024-10-21T12:08:44.062883209Z,10,2,38,T,N,0,233.95,17,130,168318,12162797,233.85,233.98,57,44,1,3,233.8,234.0,57,154,1,7,233.77,234.06,200,400,1,1,233.76,234.07,30,29,1,1,233.7,234.13,1200,400,1,1,233.66,234.17,1,1,1,1,233.58,234.25,505,50,2,1,233.53,234.41,10,600,1,2,233.45,234.43,15,5,1,1,233.4,234.5,110,63,2,4,AAPL,0.0,0.0,0.0,
2024-10-21 12:08:44.070991133+00:00,2024-10-21T12:08:44.071158229Z,10,2,38,T,N,0,233.95,37,130,167096,12162801,233.85,233.98,57,44,1,3,233.8,234.0,57,154,1,7,233.77,234.06,200,400,1,1,233.76,234.07,30,29,1,1,233.7,234.13,1200,400,1,1,233.66,234.17,1,1,1,1,233.58,234.25,505,50,2,1,233.53,234.41,10,600,1,2,233.45,234.43,15,5,1,1,233.4,234.5,110,63,2,4,AAPL,0.0,0.0,0.0,
2024-10-21 12:08:44.071001755+00:00,2024-10-21T12:08:44.071167823Z,10,2,38,A,B,0,233.89,100,130,166068,12162802,233.89,233.98,100,44,1,3,233.85,234.0,57,154,1,7,233.8,234.06,57,400,1,1,233.77,234.07,200,29,1,1,233.76,234.13,30,400,1,1,233.7,234.17,1200,1,1,1,233.66,234.25,1,50,1,1,233.58,234.41,505,600,2,2,233.53,234.43,10,5,1,1,233.45,234.5,15,63,1,4,AAPL,0.0,0.0,0.0,
2024-10-21 12:08:44.071247115+00:00,2024-10-21T12:08:44.071413124Z,10,2,38,C,B,0,233.89,100,130,166009,12162803,233.85,233.98,57,44,1,3,233.8,234.0,57,154,1,7,233.77,234.06,200,400,1,1,233.76,234.07,30,29,1,1,233.7,234.13,1200,400,1,1,233.66,234.17,1,1,1,1,233.58,234.25,505,50,2,1,233.53,234.41,10,600,1,2,233.45,234.43,15,5,1,1,233.4,234.5,110,63,2,4,AAPL,0.0,0.0,0.0,
2024-10-21 12:08:44.078717275+00:00,2024-10-21T12:08:44.078888724Z,10,2,38,T,N,0,233.95,46,0,171449,12162804,233.85,233.98,57,44,1,3,233.8,234.0,57,154,1,7,233.77,234.06,200,400,1,1,233.76,234.07,30,29,1,1,233.7,234.13,1200,400,1,1,233.66,234.17,1,1,1,1,233.58,234.25,505,50,2,1,233.53,234.41,10,600,1,2,233.45,234.43,15,5,1,1,233.4,234.5,110,63,2,4,AAPL,0.0,0.0,0.0,
2024-10-21 12:08:44.078717275+00:00,2024-10-21T12:08:44.078888724Z,10,2,38,T,N,0,233.96,10,0,171449,12162805,233.85,233.98,57,44,1,3,233.8,234.0,57,154,1,7,233.77,234.06,200,400,1,1,233.76,234.07,30,29,1,1,233.7,234.13,1200,400,1,1,233.66,234.17,1,1,1,1,233.58,234.25,505,50,2,1,233.53,234.41,10,600,1,2,233.45,234.43,15,5,1,1,233.4,234.5,110,63,2,4,AAPL,0.0,0.0,0.0,
2024-10-21 12:08:44.078717275+00:00,2024-10-21T12:08:44.078888724Z,10,2,38,T,B,0,233.98,4,0,171449,12162806,233.85,233.98,57,44,1,3,233.8,234.0,57,154,1,7,233.77,234.06,200,400,1,1,233.76,234.07,30,29,1,1,233.7,234.13,1200,400,1,1,233.66,234.17,1,1,1,1,233.58,234.25,505,50,2,1,233.53,234.41,10,600,1,2,233.45,234.43,15,5,1,1,233.4,234.5,110,63,2,4,AAPL,0.0,0.0,0.0,
2024-10-21 12:08:44.078717275+00:00,2024-10-21T12:08:44.078888724Z,10,2,38,T,B,0,233.98,9,0,171449,12162807,233.85,233.98,57,40,1,2,233.8,234.0,57,154,1,7,233.77,234.06,200,400,1,1,233.76,234.07,30,29,1,1,233.7,234.13,1200,400,1,1,233.66,234.17,1,1,1,1,233.58,234.25,505,50,2,1,233.53,234.41,10,600,1,2,233.45,234.43,15,5,1,1,233.4,234.5,110,63,2,4,AAPL,4.0,4.0,4.0,
2024-10-21 12:08:44.078717275+00:00,2024-10-21T12:08:44.078888724Z,10,2,38,T,B,0,233.98,31,130,171449,12162808,233.85,233.98,57,31,1,1,233.8,234.0,57,154,1,7,233.77,234.06,200,400,1,1,233.76,234.07,30,29,1,1,233.7,234.13,1200,400,1,1,233.66,234.17,1,1,1,1,233.58,234.25,505,50,2,1,233.53,234.41,10,600,1,2,233.45,234.43,15,5,1,1,233.4,234.5,110,63,2,4,AAPL,9.0,9.0,13.0,
2024-10-21 12:08:44.078717275+00:00,2024-10-21T12:08:44.078888724Z,10,2,38,C,A,0,233.98,31,130,171449,12162808,233.85,234.0,57,154,1,7,233.8,234.06,57,400,1,1,233.77,234.07,200,29,1,1,233.76,234.13,30,400,1,1,233.7,234.17,1200,1,1,1,233.66,234.25,1,50,1,1,233.58,234.41,505,600,2,2,233.53,234.43,10,5,1,1,233.45,234.5,15,63,1,4,233.4,234.75,110,1,2,1,AAPL,0.0,0.0,13.0,
2024-10-21 12:08:44.078746374+00:00,2024-10-21T12:08:44.078913355Z,10,2,38,A,B,0,233.92,100,130,166981,12162809,233.92,234.0,100,154,1,7,233.85,234.06,57,400,1,1,233.8,234.07,57,29,1,1,233.77,234.13,200,400,1,1,233.76,234.17,30,1,1,1,233.7,234.25,1200,50,1,1,233.66,234.41,1,600,1,2,233.58,234.43,505,5,2,1,233.53,234.5,10,63,1,4,233.45,234.75,15,1,1,1,AAPL,0.0,0.0,13.0,
2024-10-21 12:08:44.078758339+00:00,2024-10-21T12:08:44.078924745Z,10,2,38,A,B,1,233.91,57,130,166406,12162811,233.92,234.0,100,154,1,7,233.91,234.06,57,400,1,1,233.88,234.07,100,29,1,1,233.85,234.13,57,400,1,1,233.8,234.17,57,1,1,1,233.77,234.25,200,50,1,1,233.76,234.41,30,600,1,2,233.7,234.43,1200,5,1,1,233.66,234.5,1,63,1,4,233.58,234.75,505,1,2,1,AAPL,0.0,0.0,13.0,
2024-10-21 12:08:44.078760028+00:00,2024-10-21T12:08:44.078926114Z,10,2,38,A,B,2,233.88,100,130,166086,12162812,233.92,234.0,100,154,1,7,233.91,234.06,57,400,1,1,233.88,234.07,200,29,2,1,233.85,234.13,57,400,1,1,233.8,234.17,57,1,1,1,233.77,234.25,200,50,1,1,233.76,234.41,30,600,1,2,233.7,234.43,1200,5,1,1,233.66,234.5,1,63,1,4,233.58,234.75,505,1,2,1,AAPL,0.0,100.0,13.0,
2024-10-21 12:08:44.078772524+00:00,2024-10-21T12:08:44.078938721Z,10,2,38,A,B,0,233.87,57,130,166197,12162814,233.91,234.0,57,154,1,7,233.88,234.06,200,400,2,1,233.87,234.07,57,29,1,1,233.85,234.13,57,400,1,1,233.8,234.17,57,1,1,1,233.77,234.25,200,50,1,1,233.76,234.41,30,600,1,2,233.7,234.43,1200,5,1,1,233.66,234.5,1,63,1,4,233.58,234.75,505,1,2,1,AAPL,0.0,0.0,13.0,
2024-10-21 12:08:44.078783923+00:00,2024-10-21T12:08:44.078950012Z,10,2,38,C,B,1,233.88,100,130,166089,12162816,233.91,234.0,57,154,1,7,233.87,234.06,57,400,1,1,233.85,234.07,57,29,1,1,233.8,234.13,57,400,1,1,233.77,234.17,200,1,1,1,233.76,234.25,30,50,1,1,233.7,234.41,1200,600,1,2,233.66,234.43,1,5,1,1,233.58,234.5,505,63,2,4,233.53,234.75,10,1,1,1,AAPL,0.0,0.0,13.0,
2024-10-21 12:08:44.115212449+00:00,2024-10-21T12:08:44.115378536Z,10,2,38,C,A,2,234.07,29,130,166087,12162846,233.91,234.0,57,154,1,7,233.87,234.06,57,400,1,1,233.85,234.13,57,400,1,1,233.8,234.17,57,1,1,1,233.77,234.25,200,50,1,1,233.76,234.41,30,600,1,2,233.7,234.43,1200,5,1,1,233.66,234.5,1,63,1,4,233.58,234.75,505,1,2,1,233.53,234.79,10,2000,1,1,AAPL,0.0,0.0,13.0,
2024-10-21 12:08:44.115267046+00:00,2024-10-21T12:08:44.115433457Z,10,2,38,A,A,2,234.13,29,130,166411,12162847,233.91,234.0,57,154,1,7,233.87,234.06,57,400,1,1,233.85,234.13,57,429,1,2,233.8,234.17,57,1,1,1,233.77,234.25,200,50,1,1,233.76,234.41,30,600,1,2,233.7,234.43,1200,5,1,1,233.66,234.5,1,63,1,4,233.58,234.75,505,1,2,1,233.53,234.79,10,2000,1,1,AAPL,0.0,-29.0,13.0,
2024-10-21 12:08:44.149196088+00:00,2024-10-21T12:08:44.149362032Z,10,2,38,C,B,3,233.8,57,130,165944,12162860,233.91,234.0,57,154,1,7,233.87,234.06,57,400,1,1,233.85,234.13,57,429,1,2,233.77,234.17,200,1,1,1,233.76,234.25,30,50,1,1,233.7,234.41,1200,600,1,2,233.66,234.43,1,5,1,1,233.58,234.5,505,63,2,4,233.53,234.75,10,1,1,1,233.45,234.79,15,2000,1,1,AAPL,0.0,0.0,13.0,
2024-10-21 12:08:44.179409160+00:00,2024-10-21T12:08:44.179575366Z,10,2,38,C,B,1,233.87,57,130,166206,12162872,233.91,234.0,57,154,1,7,233.85,234.06,57,400,1,1,233.77,234.13,200,429,1,2,233.76,234.17,30,1,1,1,233.7,234.25,1200,50,1,1,233.66,234.41,1,600,1,2,233.58,234.43,505,5,2,1,233.53,234.5,10,63,1,4,233.45,234.75,15,1,1,1,233.4,234.79,110,2000,2,1,AAPL,0.0,0.0,13.0,
2024-10-21 12:08:44.303766562+00:00,2024-10-21T12:08:44.303932890Z,10,2,38,C,B,1,233.85,57,130,166328,12162939,233.91,234.0,57,154,1,7,233.77,234.06,200,400,1,1,233.76,234.13,30,429,1,2,233.7,234.17,1200,1,1,1,233.66,234.25,1,50,1,1,233.58,234.41,505,600,2,2,233.53,234.43,10,5,1,1,233.45,234.5,15,63,1,4,233.4,234.75,110,1,2,1,233.39,234.79,10,2000,1,1,AAPL,0.0,0.0,13.0,
2024-10-21 12:08:44.333763421+00:00,2024-10-21T12:08:44.333929473Z,10,2,38,C,B,0,233.91,57,130,166052,12162944,233.77,234.0,200,154,1,7,233.76,234.06,30,400,1,1,233.7,234.13,1200,429,1,2,233.66,234.17,1,1,1,1,233.58,234.25,505,50,2,1,233.53,234.41,10,600,1,2,233.45,234.43,15,5,1,1,233.4,234.5,110,63,2,4,233.39,234.75,10,1,1,1,233.31,234.79,110,2000,2,1,AAPL,0.0,0.0,13.0,
2024-10-21 12:08:45.554994588+00:00,2024-10-21T12:08:45.555160782Z,10,2,38,A,A,6,234.43,100,130,166194,12163887,233.77,234.0,200,154,1,7,233.76,234.06,30,400,1,1,233.7,234.13,1200,429,1,2,233.66,234.17,1,1,1,1,233.58,234.25,505,50,2,1,233.53,234.41,10,600,1,2,233.45,234.43,15,105,1,2,233.4,234.5,110,63,2,4,233.39,234.75,10,1,1,1,233.31,234.79,110,2000,2,1,AAPL,0.0,0.0,0.0,
2024-10-21 12:08:46.626940215+00:00,2024-10-21T12:08:46.627106793Z,10,2,38,A,B,0,233.9,1,130,166578,12164437,233.9,234.0,1,154,1,7,233.77,234.06,200,400,1,1,233.76,234.13,30,429,1,2,233.7,234.17,1200,1,1,1,233.66,234.25,1,50,1,1,233.58,234.41,505,600,2,2,233.53,234.43,10,105,1,2,233.45,234.5,15,63,1,4,233.4,234.75,110,1,2,1,233.39,234.79,10,2000,1,1,AAPL,0.0,0.0,0.0,
2024-10-21 12:08:56.736391728+00:00,2024-10-21T12:08:56.736557653Z,10,2,38,C,B,0,233.9,1,130,165925,12171166,233.77,234.0,200,154,1,7,233.76,234.06,30,400,1,1,233.7,234.13,1200,429,1,2,233.66,234.17,1,1,1,1,233.58,234.25,505,50,2,1,233.53,234.41,10,600,1,2,233.45,234.43,15,105,1,2,233.4,234.5,110,63,2,4,233.39,234.75,10,1,1,1,233.31,234.79,110,2000,2,1,AAPL,0.0,0.0,0.0,
2024-10-21 12:09:01.138241817+00:00,2024-10-21T12:09:01.138408018Z,10,2,38,C,B,0,233.77,200,130,166201,12174514,233.76,234.0,30,154,1,7,233.7,234.06,1200,400,1,1,233.66,234.13,1,429,1,2,233.58,234.17,505,1,2,1,233.53,234.25,10,50,1,1,233.45,234.41,15,600,1,2,233.4,234.43,110,105,2,2,233.39,234.5,10,63,1,4,233.31,234.75,110,1,2,1,233.3,234.79,100,2000,1,1,AAPL,0.0,0.0,0.0,
2024-10-21 12:09:01.138255251+00:00,2024-10-21T12:09:01.138421298Z,10,2,38,A,B,1,233.73,200,130,166047,12174515,233.76,234.0,30,154,1,7,233.73,234.06,200,400,1,1,233.7,234.13,1200,429,1,2,233.66,234.17,1,1,1,1,233.58,234.25,505,50,2,1,233.53,234.41,10,600,1,2,233.45,234.43,15,105,1,2,233.4,234.5,110,63,2,4,233.39,234.75,10,1,1,1,233.31,234.79,110,2000,2,1,AAPL,0.0,0.0,0.0,
2024-10-21 12:09:01.157397025+00:00,2024-10-21T12:09:01.157563262Z,10,2,38,A,B,2,233.7,30,130,166237,12174545,233.76,234.0,30,154,1,7,233.73,234.06,200,400,1,1,233.7,234.13,1230,429,2,2,233.66,234.17,1,1,1,1,233.58,234.25,505,50,2,1,233.53,234.41,10,600,1,2,233.45,234.43,15,105,1,2,233.4,234.5,110,63,2,4,233.39,234.75,10,1,1,1,233.31,234.79,110,2000,2,1,AAPL,0.0,30.0,0.0,
2024-10-21 12:09:01.157426276+00:00,2024-10-21T12:09:01.157592129Z,10,2,38,C,B,0,233.76,30,130,165853,12174546,233.73,234.0,200,154,1,7,233.7,234.06,1230,400,2,1,233.66,234.13,1,429,1,2,233.58,234.17,505,1,2,1,233.53,234.25,10,50,1,1,233.45,234.41,15,600,1,2,233.4,234.43,110,105,2,2,233.39,234.5,10,63,1,4,233.31,234.75,110,1,2,1,233.3,234.79,100,2000,1,1,AAPL,0.0,0.0,0.0,
2024-10-21 12:09:02.549437699+00:00,2024-10-21T12:09:02.549604073Z,10,2,38,A,A,1,234.05,400,130,166374,12175916,233.73,234.0,200,154,1,7,233.7,234.05,1230,400,2,1,233.66,234.13,1,429,1,2,233.58,234.17,505,1,2,1,233.53,234.25,10,50,1,1,233.45,234.41,15,600,1,2,233.4,234.43,110,105,2,2,233.39,234.5,10,63,1,4,233.31,234.75,110,1,2,1,233.3,234.79,100,2000,1,1,AAPL,0.0,0.0,0.0,
2024-10-21 12:09:02.576510264+00:00,2024-10-21T12:09:02.576676374Z,10,2,38,C,A,2,234.13,29,130,166110,12176238,233.73,234.0,200,154,1,7,233.7,234.05,1230,400,2,1,233.66,234.13,1,400,1,1,233.58,234.17,505,1,2,1,233.53,234.25,10,50,1,1,233.45,234.41,15,600,1,2,233.4,234.43,110,105,2,2,233.39,234.5,10,63,1,4,233.31,234.75,110,1,2,1,233.3,234.79,100,2000,1,1,AAPL,0.0,29.0,0.0,
2024-10-21 12:09:02.576563332+00:00,2024-10-21T12:09:02.576729551Z,10,2,38,A,A,2,234.12,29,130,166219,12176242,233.73,234.0,200,154,1,7,233.7,234.05,1230,400,2,1,233.66,234.12,1,29,1,1,233.58,234.13,505,400,2,1,233.53,234.17,10,1,1,1,233.45,234.25,15,50,1,1,233.4,234.41,110,600,2,2,233.39,234.43,10,105,1,2,233.31,234.5,110,63,2,4,233.3,234.75,100,1,1,1,AAPL,0.0,0.0,0.0,
2024-10-21 12:09:04.138843955+00:00,2024-10-21T12:09:04.139010031Z,10,2,38,C,B,1,233.7,30,130,166076,12177517,233.73,234.0,200,154,1,7,233.7,234.05,1200,400,1,1,233.66,234.12,1,29,1,1,233.58,234.13,505,400,2,1,233.53,234.17,10,1,1,1,233.45,234.25,15,50,1,1,233.4,234.41,110,600,2,2,233.39,234.43,10,105,1,2,233.31,234.5,110,63,2,4,233.3,234.75,100,1,1,1,AAPL,0.0,-30.0,0.0,
2024-10-21 12:09:04.138894379+00:00,2024-10-21T12:09:04.139060689Z,10,2,38,A,B,0,233.75,30,130,166310,12177518,233.75,234.0,30,154,1,7,233.73,234.05,200,400,1,1,233.7,234.12,1200,29,1,1,233.66,234.13,1,400,1,1,233.58,234.17,505,1,2,1,233.53,234.25,10,50,1,1,233.45,234.41,15,600,1,2,233.4,234.43,110,105,2,2,233.39,234.5,10,63,1,4,233.31,234.75,110,1,2,1,AAPL,0.0,0.0,0.0,
2024-10-21 12:09:04.194606283+00:00,2024-10-21T12:09:04.194772872Z,10,2,38,A,B,0,233.81,200,130,166589,12177532,233.81,234.0,200,154,1,7,233.75,234.05,30,400,1,1,233.7,234.12,1200,29,1,1,233.66,234.13,1,400,1,1,233.58,234.17,505,1,2,1,233.53,234.25,10,50,1,1,233.45,234.41,15,600,1,2,233.4,234.43,110,105,2,2,233.39,234.5,10,63,1,4,233.31,234.75,110,1,2,1,AAPL,0.0,0.0,0.0,
2024-10-21 12:09:06.506604143+00:00,2024-10-21T12:09:06.506770293Z,10,2,38,C,B,1,233.75,30,130,166150,12179760,233.81,234.0,200,154,1,7,233.7,234.05,1200,400,1,1,233.66,234.12,1,29,1,1,233.58,234.13,505,400,2,1,233.53,234.17,10,1,1,1,233.45,234.25,15,50,1,1,233.4,234.41,110,600,2,2,233.39,234.43,10,105,1,2,233.31,234.5,110,63,2,4,233.3,234.75,100,1,1,1,AAPL,0.0,0.0,0.0,
2024-10-21 12:09:06.565023952+00:00,2024-10-21T12:09:06.565190241Z,10,2,38,A,B,1,233.76,30,130,166289,12179817,233.81,234.0,200,154,1,7,233.76,234.05,30,400,1,1,233.7,234.12,1200,29,1,1,233.66,234.13,1,400,1,1,233.58,234.17,505,1,2,1,233.53,234.25,10,50,1,1,233.45,234.41,15,600,1,2,233.4,234.43,110,105,2,2,233.39,234.5,10,63,1,4,233.31,234.75,110,1,2,1,AAPL,0.0,0.0,0.0,
2024-10-21 12:09:06.773392628+00:00,2024-10-21T12:09:06.773559043Z,10,2,38,A,B,0,233.82,200,130,166415,12180059,233.82,234.0,200,154,1,7,233.76,234.05,30,400,1,1,233.7,234.12,1200,29,1,1,233.66,234.13,1,400,1,1,233.58,234.17,505,1,2,1,233.53,234.25,10,50,1,1,233.45,234.41,15,600,1,2,233.4,234.43,110,105,2,2,233.39,234.5,10,63,1,4,233.31,234.75,110,1,2,1,AAPL,0.0,0.0,0.0,
2024-10-21 12:09:10.542530771+00:00,2024-10-21T12:09:10.542697180Z,10,2,38,A,B,0,233.9,10,130,166409,12183116,233.9,234.0,10,154,1,7,233.82,234.05,200,400,1,1,233.76,234.12,30,29,1,1,233.7,234.13,1200,400,1,1,233.66,234.17,1,1,1,1,233.58,234.25,505,50,2,1,233.53,234.41,10,600,1,2,233.45,234.43,15,105,1,2,233.4,234.5,110,63,2,4,233.39,234.75,10,1,1,1,AAPL,0.0,0.0,0.0,
2024-10-21 12:09:12.689157352+00:00,2024-10-21T12:09:12.689323526Z,10,2,38,C,A,1,234.05,400,130,166174,12184428,233.9,234.0,10,154,1,7,233.82,234.12,200,29,1,1,233.76,234.13,30,400,1,1,233.7,234.17,1200,1,1,1,233.66,234.25,1,50,1,1,233.58,234.41,505,600,2,2,233.53,234.43,10,105,1,2,233.45,234.5,15,63,1,4,233.4,234.75,110,1,2,1,233.39,234.79,10,2000,1,1,AAPL,0.0,0.0,0.0,
2024-10-21 12:09:12.689170703+00:00,2024-10-21T12:09:12.689337452Z,10,2,38,A,A,1,234.06,200,130,166749,12184429,233.9,234.0,10,154,1,7,233.82,234.06,200,200,1,1,233.76,234.12,30,29,1,1,233.7,234.13,1200,400,1,1,233.66,234.17,1,1,1,1,233.58,234.25,505,50,2,1,233.53,234.41,10,600,1,2,233.45,234.43,15,105,1,2,233.4,234.5,110,63,2,4,233.39,234.75,10,1,1,1,AAPL,0.0,0.0,0.0,
2024-10-21 12:09:12.782576498+00:00,2024-10-21T12:09:12.782742680Z,10,2,38,A,A,1,234.06,200,130,166182,12184538,233.9,234.0,10,154,1,7,233.82,234.06,200,400,1,2,233.76,234.12,30,29,1,1,233.7,234.13,1200,400,1,1,233.66,234.17,1,1,1,1,233.58,234.25,505,50,2,1,233.53,234.41,10,600,1,2,233.45,234.43,15,105,1,2,233.4,234.5,110,63,2,4,233.39,234.75,10,1,1,1,AAPL,0.0,-200.0,0.0,
2024-10-21 12:09:13.223494596+00:00,2024-10-21T12:09:13.223660901Z,10,2,38,A,B,1,233.83,200,130,166305,12185116,233.9,234.0,10,154,1,7,233.83,234.06,200,400,1,2,233.76,234.12,30,29,1,1,233.7,234.13,1200,400,1,1,233.66,234.17,1,1,1,1,233.58,234.25,505,50,2,1,233.53,234.41,10,600,1,2,233.45,234.43,15,105,1,2,233.4,234.5,110,63,2,4,233.39,234.75,10,1,1,1,AAPL,0.0,0.0,0.0,
2024-10-21 12:09:13.230924474+00:00,2024-10-21T12:09:13.231090564Z,10,2,38,C,B,2,233.76,30,130,166090,12185219,233.9,234.0,10,154,1,7,233.83,234.06,200,400,1,2,233.7,234.12,1200,29,1,1,233.66,234.13,1,400,1,1,233.58,234.17,505,1,2,1,233.53,234.25,10,50,1,1,233.45,234.41,15,600,1,2,233.4,234.43,110,105,2,2,233.39,234.5,10,63,1,4,233.31,234.75,110,1,2,1,AAPL,0.0,0.0,0.0,
2024-10-21 12:09:13.230979969+00:00,2024-10-21T12:09:13.231145907Z,10,2,38,A,B,2,233.77,27,130,165938,12185224,233.9,234.0,10,154,1,7,233.83,234.06,200,400,1,2,233.77,234.12,27,29,1,1,233.7,234.13,1200,400,1,1,233.66,234.17,1,1,1,1,233.58,234.25,505,50,2,1,233.53,234.41,10,600,1,2,233.45,234.43,15,105,1,2,233.4,234.5,110,63,2,4,233.39,234.75,10,1,1,1,AAPL,0.0,0.0,0.0,
2024-10-21 12:09:13.352263576+00:00,2024-10-21T12:09:13.352430022Z,10,2,38,C,A,2,234.12,29,130,166446,12185591,233.9,234.0,10,154,1,7,233.83,234.06,200,400,1,2,233.77,234.13,27,400,1,1,233.7,234.17,1200,1,1,1,233.66,234.25,1,50,1,1,233.58,234.41,505,600,2,2,233.53,234.43,10,105,1,2,233.45,234.5,15,63,1,4,233.4,234.75,110,1,2,1,233.39,234.79,10,2000,1,1,AAPL,0.0,0.0,0.0,
2024-10-21 12:09:13.352324097+00:00,2024-10-21T12:09:13.352490529Z,10,2,38,A,A,3,234.14,28,130,166432,12185592,233.9,234.0,10,154,1,7,233.83,234.06,200,400,1,2,233.77,234.13,27,400,1,1,233.7,234.14,1200,28,1,1,233.66,234.17,1,1,1,1,233.58,234.25,505,50,2,1,233.53,234.41,10,600,1,2,233.45,234.43,15,105,1,2,233.4,234.5,110,63,2,4,233.39,234.75,10,1,1,1,AAPL,0.0,0.0,0.0,
2024-10-21 12:09:14.174258870+00:00,2024-10-21T12:09:14.174425372Z,10,2,38,C,A,1,234.06,200,130,166502,12186227,233.9,234.0,10,154,1,7,233.83,234.06,200,200,1,1,233.77,234.13,27,400,1,1,233.7,234.14,1200,28,1,1,233.66,234.17,1,1,1,1,233.58,234.25,505,50,2,1,233.53,234.41,10,600,1,2,233.45,234.43,15,105,1,2,233.4,234.5,110,63,2,4,233.39,234.75,10,1,1,1,AAPL,0.0,200.0,0.0,
2024-10-21 12:09:14.174269739+00:00,2024-10-21T12:09:14.174436198Z,10,2,38,C,A,1,234.06,200,130,166459,12186228,233.9,234.0,10,154,1,7,233.83,234.13,200,400,1,1,233.77,234.14,27,28,1,1,233.7,234.17,1200,1,1,1,233.66,234.25,1,50,1,1,233.58,234.41,505,600,2,2,233.53,234.43,10,105,1,2,233.45,234.5,15,63,1,4,233.4,234.75,110,1,2,1,233.39,234.79,10,2000,1,1,AAPL,0.0,0.0,0.0,
2024-10-21 12:09:14.199409178+00:00,2024-10-21T12:09:14.199575399Z,10,2,38,A,A,1,234.07,200,130,166221,12186266,233.9,234.0,10,154,1,7,233.83,234.07,200,200,1,1,233.77,234.13,27,400,1,1,233.7,234.14,1200,28,1,1,233.66,234.17,1,1,1,1,233.58,234.25,505,50,2,1,233.53,234.41,10,600,1,2,233.45,234.43,15,105,1,2,233.4,234.5,110,63,2,4,233.39,234.75,10,1,1,1,AAPL,0.0,0.0,0.0,
2024-10-21 12:09:15.368368108+00:00,2024-10-21T12:09:15.368534989Z,10,2,38,C,B,1,233.83,200,130,166881,12187413,233.9,234.0,10,154,1,7,233.77,234.07,27,200,1,1,233.7,234.13,1200,400,1,1,233.66,234.14,1,28,1,1,233.58,234.17,505,1,2,1,233.53,234.25,10,50,1,1,233.45,234.41,15,600,1,2,233.4,234.43,110,105,2,2,233.39,234.5,10,63,1,4,233.31,234.75,110,1,2,1,AAPL,0.0,0.0,0.0,
2024-10-21 12:09:15.368381335+00:00,2024-10-21T12:09:15.368547658Z,10,2,38,A,B,2,233.74,400,130,166323,12187414,233.9,234.0,10,154,1,7,233.77,234.07,27,200,1,1,233.74,234.13,400,400,1,1,233.7,234.14,1200,28,1,1,233.66,234.17,1,1,1,1,233.58,234.25,505,50,2,1,233.53,234.41,10,600,1,2,233.45,234.43,15,105,1,2,233.4,234.5,110,63,2,4,233.39,234.75,10,1,1,1,AAPL,0.0,0.0,0.0,
2024-10-21 12:09:15.368882161+00:00,2024-10-21T12:09:15.369048334Z,10,2,38,C,B,1,233.77,27,130,166173,12187416,233.9,234.0,10,154,1,7,233.74,234.07,400,200,1,1,233.7,234.13,1200,400,1,1,233.66,234.14,1,28,1,1,233.58,234.17,505,1,2,1,233.53,234.25,10,50,1,1,233.45,234.41,15,600,1,2,233.4,234.43,110,105,2,2,233.39,234.5,10,63,1,4,233.31,234.75,110,1,2,1,AAPL,0.0,0.0,0.0,
2024-10-21 12:09:15.368983400+00:00,2024-10-21T12:09:15.369149972Z,10,2,38,A,B,2,233.72,28,130,166572,12187417,233.9,234.0,10,154,1,7,233.74,234.07,400,200,1,1,233.72,234.13,28,400,1,1,233.7,234.14,1200,28,1,1,233.66,234.17,1,1,1,1,233.58,234.25,505,50,2,1,233.53,234.41,10,600,1,2,233.45,234.43,15,105,1,2,233.4,234.5,110,63,2,4,233.39,234.75,10,1,1,1,AAPL,0.0,0.0,0.0,
2024-10-21 12:09:15.972801291+00:00,2024-10-21T12:09:15.972968249Z,10,2,38,T,N,0,233.98,30,130,166958,12187912,233.9,234.0,10,154,1,7,233.74,234.07,400,200,1,1,233.72,234.13,28,400,1,1,233.7,234.14,1200,28,1,1,233.66,234.17,1,1,1,1,233.58,234.25,505,50,2,1,233.53,234.41,10,600,1,2,233.45,234.43,15,105,1,2,233.4,234.5,110,63,2,4,233.39,234.75,10,1,1,1,AAPL,0.0,0.0,0.0,
2024-10-21 12:09:16.178054946+00:00,2024-10-21T12:09:16.178222372Z,10,2,38,T,N,0,233.98,50,130,167426,12188119,233.9,234.0,10,154,1,7,233.74,234.07,400,200,1,1,233.72,234.13,28,400,1,1,233.7,234.14,1200,28,1,1,233.66,234.17,1,1,1,1,233.58,234.25,505,50,2,1,233.53,234.41,10,600,1,2,233.45,234.43,15,105,1,2,233.4,234.5,110,63,2,4,233.39,234.75,10,1,1,1,AAPL,0.0,0.0,0.0,
2024-10-21 12:09:17.673639410+00:00,2024-10-21T12:09:17.673807276Z,10,2,38,T,N,0,233.98,3,130,167866,12189121,233.9,234.0,10,154,1,7,233.74,234.07,400,200,1,1,233.72,234.13,28,400,1,1,233.7,234.14,1200,28,1,1,233.66,234.17,1,1,1,1,233.58,234.25,505,50,2,1,233.53,234.41,10,600,1,2,233.45,234.43,15,105,1,2,233.4,234.5,110,63,2,4,233.39,234.75,10,1,1,1,AAPL,0.0,0.0,0.0,
2024-10-21 12:09:18.369344833+00:00,2024-10-21T12:09:18.369511364Z,10,2,38,A,B,1,233.77,26,130,166531,12189523,233.9,234.0,10,154,1,7,233.77,234.07,26,200,1,1,233.74,234.13,400,400,1,1,233.72,234.14,28,28,1,1,233.7,234.17,1200,1,1,1,233.66,234.25,1,50,1,1,233.58,234.41,505,600,2,2,233.53,234.43,10,105,1,2,233.45,234.5,15,63,1,4,233.4,234.75,110,1,2,1,AAPL,0.0,0.0,0.0,
2024-10-21 12:09:18.369370009+00:00,2024-10-21T12:09:18.369536160Z,10,2,38,C,B,3,233.72,28,130,166151,12189524,233.9,234.0,10,154,1,7,233.77,234.07,26,200,1,1,233.74,234.13,400,400,1,1,233.7,234.14,1200,28,1,1,233.66,234.17,1,1,1,1,233.58,234.25,505,50,2,1,233.53,234.41,10,600,1,2,233.45,234.43,15,105,1,2,233.4,234.5,110,63,2,4,233.39,234.75,10,1,1,1,AAPL,0.0,0.0,0.0,
2024-10-21 12:09:18.424025933+00:00,2024-10-21T12:09:18.424192189Z,10,2,38,A,B,1,233.83,200,130,166256,12189542,233.9,234.0,10,154,1,7,233.83,234.07,200,200,1,1,233.77,234.13,26,400,1,1,233.7,234.14,1200,28,1,1,233.66,234.17,1,1,1,1,233.58,234.25,505,50,2,1,233.53,234.41,10,600,1,2,233.45,234.43,15,105,1,2,233.4,234.5,110,63,2,4,233.39,234.75,10,1,1,1,AAPL,0.0,0.0,0.0,
2024-10-21 12:09:26.336360989+00:00,2024-10-21T12:09:26.336527240Z,10,2,38,C,B,1,233.83,200,130,166251,12194498,233.9,234.0,10,154,1,7,233.77,234.07,26,200,1,1,233.7,234.13,1200,400,1,1,233.66,234.14,1,28,1,1,233.58,234.17,505,1,2,1,233.53,234.25,10,50,1,1,233.45,234.41,15,600,1,2,233.4,234.43,110,105,2,2,233.39,234.5,10,63,1,4,233.31,234.75,110,1,2,1,AAPL,0.0,0.0,0.0,
2024-10-21 12:09:26.336373029+00:00,2024-10-21T12:09:26.336539345Z,10,2,38,A,B,1,233.81,200,130,166316,12194499,233.9,234.0,10,154,1,7,233.81,234.07,200,200,1,1,233.77,234.13,26,400,1,1,233.7,234.14,1200,28,1,1,233.66,234.17,1,1,1,1,233.58,234.25,505,50,2,1,233.53,234.41,10,600,1,2,233.45,234.43,15,105,1,2,233.4,234.5,110,63,2,4,233.39,234.75,10,1,1,1,AAPL,0.0,0.0,0.0,
2024-10-21 12:09:26.336385729+00:00,2024-10-21T12:09:26.336551701Z,10,2,38,A,A,1,234.07,200,130,165972,12194500,233.9,234.0,10,154,1,7,233.81,234.07,200,400,1,2,233.77,234.13,26,400,1,1,233.7,234.14,1200,28,1,1,233.66,234.17,1,1,1,1,233.58,234.25,505,50,2,1,233.53,234.41,10,600,1,2,233.45,234.43,15,105,1,2,233.4,234.5,110,63,2,4,233.39,234.75,10,1,1,1,AAPL,0.0,-200.0,0.0,
2024-10-21 12:09:26.401883038+00:00,2024-10-21T12:09:26.402049735Z,10,2,38,A,B,1,233.82,200,130,166697,12194620,233.9,234.0,10,154,1,7,233.82,234.07,200,400,1,2,233.77,234.13,26,400,1,1,233.7,234.14,1200,28,1,1,233.66,234.17,1,1,1,1,233.58,234.25,505,50,2,1,233.53,234.41,10,600,1,2,233.45,234.43,15,105,1,2,233.4,234.5,110,63,2,4,233.39,234.75,10,1,1,1,AAPL,0.0,0.0,0.0,
2024-10-21 12:09:30.048768796+00:00,2024-10-21T12:09:30.048934813Z,10,2,38,C,A,1,234.07,200,130,166017,12197231,233.9,234.0,10,154,1,7,233.82,234.07,200,200,1,1,233.77,234.13,26,400,1,1,233.7,234.14,1200,28,1,1,233.66,234.17,1,1,1,1,233.58,234.25,505,50,2,1,233.53,234.41,10,600,1,2,233.45,234.43,15,105,1,2,233.4,234.5,110,63,2,4,233.39,234.75,10,1,1,1,AAPL,0.0,200.0,0.0,
2024-10-21 12:09:30.048780765+00:00,2024-10-21T12:09:30.048946954Z,10,2,38,A,A,1,234.06,200,130,166189,12197232,233.9,234.0,10,154,1,7,233.82,234.06,200,200,1,1,233.77,234.13,26,400,1,1,233.7,234.14,1200,28,1,1,233.66,234.17,1,1,1,1,233.58,234.25,505,50,2,1,233.53,234.41,10,600,1,2,233.45,234.43,15,105,1,2,233.4,234.5,110,63,2,4,233.39,234.75,10,1,1,1,AAPL,0.0,0.0,0.0,
2024-10-21 12:09:30.065483395+00:00,2024-10-21T12:09:30.065649441Z,10,2,38,C,A,3,234.14,28,130,166046,12197308,233.9,234.0,10,154,1,7,233.82,234.06,200,200,1,1,233.77,234.13,26,400,1,1,233.7,234.17,1200,1,1,1,233.66,234.25,1,50,1,1,233.58,234.41,505,600,2,2,233.53,234.43,10,105,1,2,233.45,234.5,15,63,1,4,233.4,234.75,110,1,2,1,233.39,234.79,10,2000,1,1,AAPL,0.0,0.0,0.0,
2024-10-21 12:09:30.066245031+00:00,2024-10-21T12:09:30.066411685Z,10,2,38,A,A,2,234.13,30,130,166654,12197309,233.9,234.0,10,154,1,7,233.82,234.06,200,200,1,1,233.77,234.13,26,430,1,2,233.7,234.17,1200,1,1,1,233.66,234.25,1,50,1,1,233.58,234.41,505,600,2,2,233.53,234.43,10,105,1,2,233.45,234.5,15,63,1,4,233.4,234.75,110,1,2,1,233.39,234.79,10,2000,1,1,AAPL,0.0,-30.0,0.0,
2024-10-21 12:09:32.077963808+00:00,2024-10-21T12:09:32.078130281Z,10,2,38,A,B,0,233.9,1,130,166473,12199244,233.9,234.0,11,154,2,7,233.82,234.06,200,200,1,1,233.77,234.13,26,430,1,2,233.7,234.17,1200,1,1,1,233.66,234.25,1,50,1,1,233.58,234.41,505,600,2,2,233.53,234.43,10,105,1,2,233.45,234.5,15,63,1,4,233.4,234.75,110,1,2,1,233.39,234.79,10,2000,1,1,AAPL,1.0,1.0,1.0,
2024-10-21 12:09:37.644355301+00:00,2024-10-21T12:09:37.644521809Z,10,2,38,A,B,1,233.83,200,130,166508,12202648,233.9,234.0,11,154,2,7,233.83,234.06,200,200,1,1,233.77,234.13,26,430,1,2,233.7,234.17,1200,1,1,1,233.66,234.25,1,50,1,1,233.58,234.41,505,600,2,2,233.53,234.43,10,105,1,2,233.45,234.5,15,63,1,4,233.4,234.75,110,1,2,1,233.39,234.79,10,2000,1,1,AAPL,0.0,0.0,0.0,
2024-10-21 12:09:38.208139554+00:00,2024-10-21T12:09:38.208305707Z,10,2,38,A,B,0,233.97,2,130,166153,12203420,233.97,234.0,2,154,1,7,233.9,234.06,11,200,2,1,233.83,234.13,200,430,1,2,233.77,234.17,26,1,1,1,233.7,234.25,1200,50,1,1,233.66,234.41,1,600,1,2,233.58,234.43,505,105,2,2,233.53,234.5,10,63,1,4,233.45,234.75,15,1,1,1,233.4,234.79,110,2000,2,1,AAPL,0.0,0.0,0.0,
2024-10-21 12:09:42.372615871+00:00,2024-10-21T12:09:42.372781724Z,10,2,38,C,A,1,234.06,200,130,165853,12205636,233.97,234.0,2,154,1,7,233.9,234.13,11,430,2,2,233.83,234.17,200,1,1,1,233.77,234.25,26,50,1,1,233.7,234.41,1200,600,1,2,233.66,234.43,1,105,1,2,233.58,234.5,505,63,2,4,233.53,234.75,10,1,1,1,233.45,234.79,15,2000,1,1,233.4,234.89,110,2,2,2,AAPL,0.0,0.0,0.0,
2024-10-21 12:09:42.372627823+00:00,2024-10-21T12:09:42.372793881Z,10,2,38,A,A,1,234.07,200,130,166058,12205637,233.97,234.0,2,154,1,7,233.9,234.07,11,200,2,1,233.83,234.13,200,430,1,2,233.77,234.17,26,1,1,1,233.7,234.25,1200,50,1,1,233.66,234.41,1,600,1,2,233.58,234.43,505,105,2,2,233.53,234.5,10,63,1,4,233.45,234.75,15,1,1,1,233.4,234.79,110,2000,2,1,AAPL,0.0,0.0,0.0,
2024-10-21 12:09:43.901315169+00:00,2024-10-21T12:09:43.901481889Z,10,2,38,A,B,1,233.95,10,130,166720,12207173,233.97,234.0,2,154,1,7,233.95,234.07,10,200,1,1,233.9,234.13,11,430,2,2,233.83,234.17,200,1,1,1,233.77,234.25,26,50,1,1,233.7,234.41,1200,600,1,2,233.66,234.43,1,105,1,2,233.58,234.5,505,63,2,4,233.53,234.75,10,1,1,1,233.45,234.79,15,2000,1,1,AAPL,0.0,0.0,0.0,
2024-10-21 12:09:45.133407519+00:00,2024-10-21T12:09:45.133575558Z,10,2,38,T,N,0,233.98,17,130,168039,12207963,233.97,234.0,2,154,1,7,233.95,234.07,10,200,1,1,233.9,234.13,11,430,2,2,233.83,234.17,200,1,1,1,233.77,234.25,26,50,1,1,233.7,234.41,1200,600,1,2,233.66,234.43,1,105,1,2,233.58,234.5,505,63,2,4,233.53,234.75,10,1,1,1,233.45,234.79,15,2000,1,1,AAPL,0.0,0.0,0.0,
2024-10-21 12:09:45.628579880+00:00,2024-10-21T12:09:45.628746056Z,10,2,38,A,B,9,233.5,100,130,166176,12208190,233.97,234.0,2,154,1,7,233.95,234.07,10,200,1,1,233.9,234.13,11,430,2,2,233.83,234.17,200,1,1,1,233.77,234.25,26,50,1,1,233.7,234.41,1200,600,1,2,233.66,234.43,1,105,1,2,233.58,234.5,505,63,2,4,233.53,234.75,10,1,1,1,233.5,234.79,100,2000,1,1,AAPL,0.0,0.0,0.0,
2024-10-21 12:09:48.089350946+00:00,2024-10-21T12:09:48.089517540Z,10,2,38,A,A,1,234.07,200,130,166594,12210108,233.97,234.0,2,154,1,7,233.95,234.07,10,400,1,2,233.9,234.13,11,430,2,2,233.83,234.17,200,1,1,1,233.77,234.25,26,50,1,1,233.7,234.41,1200,600,1,2,233.66,234.43,1,105,1,2,233.58,234.5,505,63,2,4,233.53,234.75,10,1,1,1,233.5,234.79,100,2000,1,1,AAPL,0.0,-200.0,0.0,
2024-10-21 12:09:48.587030358+00:00,2024-10-21T12:09:48.587196262Z,10,2,38,C,A,1,234.07,200,130,165904,12210833,233.97,234.0,2,154,1,7,233.95,234.07,10,200,1,1,233.9,234.13,11,430,2,2,233.83,234.17,200,1,1,1,233.77,234.25,26,50,1,1,233.7,234.41,1200,600,1,2,233.66,234.43,1,105,1,2,233.58,234.5,505,63,2,4,233.53,234.75,10,1,1,1,233.5,234.79,100,2000,1,1,AAPL,0.0,200.0,0.0,
2024-10-21 12:09:48.587043020+00:00,2024-10-21T12:09:48.587209868Z,10,2,38,A,A,1,234.06,200,130,166848,12210834,233.97,234.0,2,154,1,7,233.95,234.06,10,200,1,1,233.9,234.13,11,430,2,2,233.83,234.17,200,1,1,1,233.77,234.25,26,50,1,1,233.7,234.41,1200,600,1,2,233.66,234.43,1,105,1,2,233.58,234.5,505,63,2,4,233.53,234.75,10,1,1,1,233.5,234.79,100,2000,1,1,AAPL,0.0,0.0,0.0,
2024-10-21 12:09:49.792724444+00:00,2024-10-21T12:09:49.792890933Z,10,2,38,A,A,1,234.06,200,130,166489,12211836,233.97,234.0,2,154,1,7,233.95,234.06,10,400,1,2,233.9,234.13,11,430,2,2,233.83,234.17,200,1,1,1,233.77,234.25,26,50,1,1,233.7,234.41,1200,600,1,2,233.66,234.43,1,105,1,2,233.58,234.5,505,63,2,4,233.53,234.75,10,1,1,1,233.5,234.79,100,2000,1,1,AAPL,0.0,-200.0,0.0,
2024-10-21 12:09:53.122453611+00:00,2024-10-21T12:09:53.122619723Z,10,2,38,C,B,0,233.97,2,130,166112,12214081,233.95,234.0,10,154,1,7,233.9,234.06,11,400,2,2,233.83,234.13,200,430,1,2,233.77,234.17,26,1,1,1,233.7,234.25,1200,50,1,1,233.66,234.41,1,600,1,2,233.58,234.43,505,105,2,2,233.53,234.5,10,63,1,4,233.5,234.75,100,1,1,1,233.45,234.79,15,2000,1,1,AAPL,0.0,0.0,0.0,
2024-10-21 12:09:53.247009420+00:00,2024-10-21T12:09:53.247175609Z,10,2,38,A,B,3,233.81,30,130,166189,12214171,233.95,234.0,10,154,1,7,233.9,234.06,11,400,2,2,233.83,234.13,200,430,1,2,233.81,234.17,30,1,1,1,233.77,234.25,26,50,1,1,233.7,234.41,1200,600,1,2,233.66,234.43,1,105,1,2,233.58,234.5,505,63,2,4,233.53,234.75,10,1,1,1,233.5,234.79,100,2000,1,1,AAPL,0.0,0.0,0.0,
2024-10-21 12:09:53.247043259+00:00,2024-10-21T12:09:53.247209179Z,10,2,38,C,B,4,233.77,26,130,165920,12214172,233.95,234.0,10,154,1,7,233.9,234.06,11,400,2,2,233.83,234.13,200,430,1,2,233.81,234.17,30,1,1,1,233.7,234.25,1200,50,1,1,233.66,234.41,1,600,1,2,233.58,234.43,505,105,2,2,233.53,234.5,10,63,1,4,233.5,234.75,100,1,1,1,233.45,234.79,15,2000,1,1,AAPL,0.0,0.0,0.0,
2024-10-21 12:09:53.299918437+00:00,2024-10-21T12:09:53.300084898Z,10,2,38,A,B,2,233.86,200,130,166461,12214205,233.95,234.0,10,154,1,7,233.9,234.06,11,400,2,2,233.86,234.13,200,430,1,2,233.81,234.17,30,1,1,1,233.7,234.25,1200,50,1,1,233.66,234.41,1,600,1,2,233.58,234.43,505,105,2,2,233.53,234.5,10,63,1,4,233.5,234.75,100,1,1,1,233.45,234.79,15,2000,1,1,AAPL,0.0,0.0,0.0,
2024-10-21 12:09:54.363979828+00:00,2024-10-21T12:09:54.364146144Z,10,2,38,C,A,1,234.06,200,130,166316,12214797,233.95,234.0,10,154,1,7,233.9,234.06,11,200,2,1,233.86,234.13,200,430,1,2,233.81,234.17,30,1,1,1,233.7,234.25,1200,50,1,1,233.66,234.41,1,600,1,2,233.58,234.43,505,105,2,2,233.53,234.5,10,63,1,4,233.5,234.75,100,1,1,1,233.45,234.79,15,2000,1,1,AAPL,0.0,200.0,0.0,
2024-10-21 12:09:54.363990119+00:00,2024-10-21T12:09:54.364156991Z,10,2,38,C,A,1,234.06,200,130,166872,12214798,233.95,234.0,10,154,1,7,233.9,234.13,11,430,2,2,233.86,234.17,200,1,1,1,233.81,234.25,30,50,1,1,233.7,234.41,1200,600,1,2,233.66,234.43,1,105,1,2,233.58,234.5,505,63,2,4,233.53,234.75,10,1,1,1,233.5,234.79,100,2000,1,1,233.45,234.89,15,2,1,2,AAPL,0.0,0.0,0.0,
2024-10-21 12:09:54.402345010+00:00,2024-10-21T12:09:54.402511703Z,10,2,38,A,A,1,234.06,200,130,166693,12214808,233.95,234.0,10,154,1,7,233.9,234.06,11,200,2,1,233.86,234.13,200,430,1,2,233.81,234.17,30,1,1,1,233.7,234.25,1200,50,1,1,233.66,234.41,1,600,1,2,233.58,234.43,505,105,2,2,233.53,234.5,10,63,1,4,233.5,234.75,100,1,1,1,233.45,234.79,15,2000,1,1,AAPL,0.0,0.0,0.0,
2024-10-21 12:09:57.392602293+00:00,2024-10-21T12:09:57.392768641Z,10,2,38,A,A,1,234.05,200,130,166348,12217320,233.95,234.0,10,154,1,7,233.9,234.05,11,200,2,1,233.86,234.13,200,430,1,2,233.81,234.17,30,1,1,1,233.7,234.25,1200,50,1,1,233.66,234.41,1,600,1,2,233.58,234.43,505,105,2,2,233.53,234.5,10,63,1,4,233.5,234.75,100,1,1,1,233.45,234.79,15,2000,1,1,AAPL,0.0,0.0,0.0,
2024-10-21 12:09:57.432954262+00:00,2024-10-21T12:09:57.433120140Z,10,2,38,C,A,2,234.13,30,130,165878,12217490,233.95,234.0,10,154,1,7,233.9,234.05,11,200,2,1,233.86,234.13,200,400,1,1,233.81,234.17,30,1,1,1,233.7,234.25,1200,50,1,1,233.66,234.41,1,600,1,2,233.58,234.43,505,105,2,2,233.53,234.5,10,63,1,4,233.5,234.75,100,1,1,1,233.45,234.79,15,2000,1,1,AAPL,0.0,30.0,0.0,
2024-10-21 12:09:57.433015324+00:00,2024-10-21T12:09:57.433181540Z,10,2,38,A,A,2,234.12,27,130,166216,12217491,233.95,234.0,10,154,1,7,233.9,234.05,11,200,2,1,233.86,234.12,200,27,1,1,233.81,234.13,30,400,1,1,233.7,234.17,1200,1,1,1,233.66,234.25,1,50,1,1,233.58,234.41,505,600,2,2,233.53,234.43,10,105,1,2,233.5,234.5,100,63,1,4,233.45,234.75,15,1,1,1,AAPL,0.0,0.0,0.0,
2024-10-21 12:10:00.023818184+00:00,2024-10-21T12:10:00.023985986Z,10,2,38,T,N,0,233.98,2,130,167802,12219639,233.95,234.0,10,154,1,7,233.9,234.05,11,200,2,1,233.86,234.12,200,27,1,1,233.81,234.13,30,400,1,1,233.7,234.17,1200,1,1,1,233.66,234.25,1,50,1,1,233.58,234.41,505,600,2,2,233.53,234.43,10,105,1,2,233.5,234.5,100,63,1,4,233.45,234.75,15,1,1,1,AAPL,0.0,0.0,0.0,
2024-10-21 12:10:01.648302231+00:00,2024-10-21T12:10:01.648468232Z,10,2,38,C,B,2,233.86,200,130,166001,12221707,233.95,234.0,10,154,1,7,233.9,234.05,11,200,2,1,233.81,234.12,30,27,1,1,233.7,234.13,1200,400,1,1,233.66,234.17,1,1,1,1,233.58,234.25,505,50,2,1,233.53,234.41,10,600,1,2,233.5,234.43,100,105,1,2,233.45,234.5,15,63,1,4,233.4,234.75,110,1,2,1,AAPL,0.0,0.0,0.0,
2024-10-21 12:10:01.648314395+00:00,2024-10-21T12:10:01.648480569Z,10,2,38,A,B,2,233.84,200,130,166174,12221708,233.95,234.0,10,154,1,7,233.9,234.05,11,200,2,1,233.84,234.12,200,27,1,1,233.81,234.13,30,400,1,1,233.7,234.17,1200,1,1,1,233.66,234.25,1,50,1,1,233.58,234.41,505,600,2,2,233.53,234.43,10,105,1,2,233.5,234.5,100,63,1,4,233.45,234.75,15,1,1,1,AAPL,0.0,0.0,0.0,
2024-10-21 12:10:01.702573654+00:00,2024-10-21T12:10:01.702740055Z,10,2,38,A,A,1,234.04,200,130,166401,12221881,233.95,234.0,10,154,1,7,233.9,234.04,11,200,2,1,233.84,234.12,200,27,1,1,233.81,234.13,30,400,1,1,233.7,234.17,1200,1,1,1,233.66,234.25,1,50,1,1,233.58,234.41,505,600,2,2,233.53,234.43,10,105,1,2,233.5,234.5,100,63,1,4,233.45,234.75,15,1,1,1,AAPL,0.0,0.0,0.0,
2024-10-21 12:10:01.719020950+00:00,2024-10-21T12:10:01.719186937Z,10,2,38,C,A,1,234.04,200,130,165987,12221965,233.95,234.0,10,154,1,7,233.9,234.12,11,27,2,1,233.84,234.13,200,400,1,1,233.81,234.17,30,1,1,1,233.7,234.25,1200,50,1,1,233.66,234.41,1,600,1,2,233.58,234.43,505,105,2,2,233.53,234.5,10,63,1,4,233.5,234.75,100,1,1,1,233.45,234.79,15,2000,1,1,AAPL,0.0,0.0,0.0,
2024-10-21 12:10:01.719033080+00:00,2024-10-21T12:10:01.719199386Z,10,2,38,A,A,1,234.09,200,130,166306,12221966,233.95,234.0,10,154,1,7,233.9,234.09,11,200,2,1,233.84,234.12,200,27,1,1,233.81,234.13,30,400,1,1,233.7,234.17,1200,1,1,1,233.66,234.25,1,50,1,1,233.58,234.41,505,600,2,2,233.53,234.43,10,105,1,2,233.5,234.5,100,63,1,4,233.45,234.75,15,1,1,1,AAPL,0.0,0.0,0.0,
2024-10-21 12:10:01.724626959+00:00,2024-10-21T12:10:01.724794250Z,10,2,38,A,A,2,234.11,29,130,167291,12222034,233.95,234.0,10,154,1,7,233.9,234.09,11,200,2,1,233.84,234.11,200,29,1,1,233.81,234.12,30,27,1,1,233.7,234.13,1200,400,1,1,233.66,234.17,1,1,1,1,233.58,234.25,505,50,2,1,233.53,234.41,10,600,1,2,233.5,234.43,100,105,1,2,233.45,234.5,15,63,1,4,AAPL,0.0,0.0,0.0,
2024-10-21 12:10:01.726066241+00:00,2024-10-21T12:10:01.726233514Z,10,2,38,A,B,2,233.84,200,128,167273,12222037,233.95,234.0,10,154,1,7,233.9,234.09,11,200,2,1,233.84,234.11,400,29,2,1,233.81,234.12,30,27,1,1,233.7,234.13,1200,400,1,1,233.66,234.17,1,1,1,1,233.58,234.25,505,50,2,1,233.53,234.41,10,600,1,2,233.5,234.43,100,105,1,2,233.45,234.5,15,63,1,4,AAPL,0.0,200.0,0.0,
2024-10-21 12:10:01.751841665+00:00,2024-10-21T12:10:01.752007708Z,10,2,38,C,A,2,234.11,29,130,166043,12222181,233.95,234.0,10,154,1,7,233.9,234.09,11,200,2,1,233.84,234.12,400,27,2,1,233.81,234.13,30,400,1,1,233.7,234.17,1200,1,1,1,233.66,234.25,1,50,1,1,233.58,234.41,505,600,2,2,233.53,234.43,10,105,1,2,233.5,234.5,100,63,1,4,233.45,234.75,15,1,1,1,AAPL,0.0,0.0,0.0,
2024-10-21 12:10:01.781661443+00:00,2024-10-21T12:10:01.781827461Z,10,2,38,C,B,2,233.84,200,130,166018,12222265,233.95,234.0,10,154,1,7,233.9,234.09,11,200,2,1,233.84,234.12,200,27,1,1,233.81,234.13,30,400,1,1,233.7,234.17,1200,1,1,1,233.66,234.25,1,50,1,1,233.58,234.41,505,600,2,2,233.53,234.43,10,105,1,2,233.5,234.5,100,63,1,4,233.45,234.75,15,1,1,1,AAPL,0.0,-200.0,0.0,
2024-10-21 12:10:01.781673802+00:00,2024-10-21T12:10:01.781840313Z,10,2,38,A,B,2,233.87,400,130,166511,12222266,233.95,234.0,10,154,1,7,233.9,234.09,11,200,2,1,233.87,234.12,400,27,1,1,233.81,234.13,30,400,1,1,233.7,234.17,1200,1,1,1,233.66,234.25,1,50,1,1,233.58,234.41,505,600,2,2,233.53,234.43,10,105,1,2,233.5,234.5,100,63,1,4,233.45,234.75,15,1,1,1,AAPL,0.0,0.0,0.0,
2024-10-21 12:10:01.842775879+00:00,2024-10-21T12:10:01.842942268Z,10,2,38,C,A,2,234.12,27,130,166389,12222352,233.95,234.0,10,154,1,7,233.9,234.09,11,200,2,1,233.87,234.13,400,400,1,1,233.81,234.17,30,1,1,1,233.7,234.25,1200,50,1,1,233.66,234.41,1,600,1,2,233.58,234.43,505,105,2,2,233.53,234.5,10,63,1,4,233.5,234.75,100,1,1,1,233.45,234.79,15,2000,1,1,AAPL,0.0,0.0,0.0,
2024-10-21 12:10:02.294097461+00:00,2024-10-21T12:10:02.294263964Z,10,2,38,A,A,3,234.16,27,130,166503,12222991,233.95,234.0,10,154,1,7,233.9,234.09,11,200,2,1,233.87,234.13,400,400,1,1,233.81,234.16,30,27,1,1,233.7,234.17,1200,1,1,1,233.66,234.25,1,50,1,1,233.58,234.41,505,600,2,2,233.53,234.43,10,105,1,2,233.5,234.5,100,63,1,4,233.45,234.75,15,1,1,1,AAPL,0.0,0.0,0.0,
2024-10-21 12:10:03.086137168+00:00,2024-10-21T12:10:03.086305082Z,10,2,38,T,N,0,233.99,9,130,167914,12223722,233.95,234.0,10,154,1,7,233.9,234.09,11,200,2,1,233.87,234.13,400,400,1,1,233.81,234.16,30,27,1,1,233.7,234.17,1200,1,1,1,233.66,234.25,1,50,1,1,233.58,234.41,505,600,2,2,233.53,234.43,10,105,1,2,233.5,234.5,100,63,1,4,233.45,234.75,15,1,1,1,AAPL,0.0,0.0,0.0,
2024-10-21 12:10:03.188596704+00:00,2024-10-21T12:10:03.188762601Z,10,2,38,C,B,2,233.87,400,130,165897,12223900,233.95,234.0,10,154,1,7,233.9,234.09,11,200,2,1,233.81,234.13,30,400,1,1,233.7,234.16,1200,27,1,1,233.66,234.17,1,1,1,1,233.58,234.25,505,50,2,1,233.53,234.41,10,600,1,2,233.5,234.43,100,105,1,2,233.45,234.5,15,63,1,4,233.4,234.75,110,1,2,1,AAPL,0.0,0.0,0.0,
2024-10-21 12:10:03.188608784+00:00,2024-10-21T12:10:03.188775201Z,10,2,38,A,B,2,233.86,400,130,166417,12223901,233.95,234.0,10,154,1,7,233.9,234.09,11,200,2,1,233.86,234.13,400,400,1,1,233.81,234.16,30,27,1,1,233.7,234.17,1200,1,1,1,233.66,234.25,1,50,1,1,233.58,234.41,505,600,2,2,233.53,234.43,10,105,1,2,233.5,234.5,100,63,1,4,233.45,234.75,15,1,1,1,AAPL,0.0,0.0,0.0,
2024-10-21 12:10:03.188621108+00:00,2024-10-21T12:10:03.188787374Z,10,2,38,A,A,1,234.09,200,130,166266,12223902,233.95,234.0,10,154,1,7,233.9,234.09,11,400,2,2,233.86,234.13,400,400,1,1,233.81,234.16,30,27,1,1,233.7,234.17,1200,1,1,1,233.66,234.25,1,50,1,1,233.58,234.41,505,600,2,2,233.53,234.43,10,105,1,2,233.5,234.5,100,63,1,4,233.45,234.75,15,1,1,1,AAPL,0.0,-200.0,0.0,
2024-10-21 12:10:03.197531287+00:00,2024-10-21T12:10:03.197697662Z,10,2,38,A,B,4,233.79,26,130,166375,12224056,233.95,234.0,10,154,1,7,233.9,234.09,11,400,2,2,233.86,234.13,400,400,1,1,233.81,234.16,30,27,1,1,233.79,234.17,26,1,1,1,233.7,234.25,1200,50,1,1,233.66,234.41,1,600,1,2,233.58,234.43,505,105,2,2,233.53,234.5,10,63,1,4,233.5,234.75,100,1,1,1,AAPL,0.0,0.0,0.0,
2024-10-21 12:10:03.247731199+00:00,2024-10-21T12:10:03.247897243Z,10,2,38,C,A,1,234.09,200,130,166044,12224474,233.95,234.0,10,154,1,7,233.9,234.09,11,200,2,1,233.86,234.13,400,400,1,1,233.81,234.16,30,27,1,1,233.79,234.17,26,1,1,1,233.7,234.25,1200,50,1,1,233.66,234.41,1,600,1,2,233.58,234.43,505,105,2,2,233.53,234.5,10,63,1,4,233.5,234.75,100,1,1,1,AAPL,0.0,200.0,0.0,
2024-10-21 12:10:03.247744906+00:00,2024-10-21T12:10:03.247911445Z,10,2,38,A,A,1,234.08,400,130,166539,12224475,233.95,234.0,10,154,1,7,233.9,234.08,11,400,2,1,233.86,234.13,400,400,1,1,233.81,234.16,30,27,1,1,233.79,234.17,26,1,1,1,233.7,234.25,1200,50,1,1,233.66,234.41,1,600,1,2,233.58,234.43,505,105,2,2,233.53,234.5,10,63,1,4,233.5,234.75,100,1,1,1,AAPL,0.0,0.0,0.0,
2024-10-21 12:10:03.255005064+00:00,2024-10-21T12:10:03.255171170Z,10,2,38,C,B,3,233.81,30,130,166106,12224539,233.95,234.0,10,154,1,7,233.9,234.08,11,400,2,1,233.86,234.13,400,400,1,1,233.79,234.16,26,27,1,1,233.7,234.17,1200,1,1,1,233.66,234.25,1,50,1,1,233.58,234.41,505,600,2,2,233.53,234.43,10,105,1,2,233.5,234.5,100,63,1,4,233.45,234.75,15,1,1,1,AAPL,0.0,0.0,0.0,
2024-10-21 12:10:03.257914828+00:00,2024-10-21T12:10:03.258081034Z,10,2,38,C,A,3,234.16,27,130,166206,12224582,233.95,234.0,10,154,1,7,233.9,234.08,11,400,2,1,233.86,234.13,400,400,1,1,233.79,234.17,26,1,1,1,233.7,234.25,1200,50,1,1,233.66,234.41,1,600,1,2,233.58,234.43,505,105,2,2,233.53,234.5,10,63,1,4,233.5,234.75,100,1,1,1,233.45,234.79,15,2000,1,1,AAPL,0.0,0.0,0.0,
2024-10-21 12:10:03.459955473+00:00,2024-10-21T12:10:03.460121633Z,10,2,38,C,A,1,234.08,400,130,166160,12225012,233.95,234.0,10,154,1,7,233.9,234.13,11,400,2,1,233.86,234.17,400,1,1,1,233.79,234.25,26,50,1,1,233.7,234.41,1200,600,1,2,233.66,234.43,1,105,1,2,233.58,234.5,505,63,2,4,233.53,234.75,10,1,1,1,233.5,234.79,100,2000,1,1,233.45,234.89,15,2,1,2,AAPL,0.0,0.0,0.0,
2024-10-21 12:10:03.459967128+00:00,2024-10-21T12:10:03.460133284Z,10,2,38,A,A,1,234.1,400,130,166156,12225013,233.95,234.0,10,154,1,7,233.9,234.1,11,400,2,1,233.86,234.13,400,400,1,1,233.79,234.17,26,1,1,1,233.7,234.25,1200,50,1,1,233.66,234.41,1,600,1,2,233.58,234.43,505,105,2,2,233.53,234.5,10,63,1,4,233.5,234.75,100,1,1,1,233.45,234.79,15,2000,1,1,AAPL,0.0,0.0,0.0,
2024-10-21 12:10:03.514882942+00:00,2024-10-21T12:10:03.515049550Z,10,2,38,A,B,2,233.87,400,130,166608,12225080,233.95,234.0,10,154,1,7,233.9,234.1,11,400,2,1,233.87,234.13,400,400,1,1,233.79,234.17,26,1,1,1,233.7,234.25,1200,50,1,1,233.66,234.41,1,600,1,2,233.58,234.43,505,105,2,2,233.53,234.5,10,63,1,4,233.5,234.75,100,1,1,1,233.45,234.79,15,2000,1,1,AAPL,0.0,0.0,0.0,
2024-10-21 12:10:12.927978411+00:00,2024-10-21T12:10:12.928144456Z,10,2,38,C,B,3,233.79,26,130,166045,12232536,233.95,234.0,10,154,1,7,233.9,234.1,11,400,2,1,233.87,234.13,400,400,1,1,233.7,234.17,1200,1,1,1,233.66,234.25,1,50,1,1,233.58,234.41,505,600,2,2,233.53,234.43,10,105,1,2,233.5,234.5,100,63,1,4,233.45,234.75,15,1,1,1,233.4,234.79,110,2000,2,1,AAPL,0.0,0.0,0.0,
2024-10-21 12:10:12.928036467+00:00,2024-10-21T12:10:12.928202744Z,10,2,38,A,B,3,233.8,29,130,166277,12232537,233.95,234.0,10,154,1,7,233.9,234.1,11,400,2,1,233.87,234.13,400,400,1,1,233.8,234.17,29,1,1,1,233.7,234.25,1200,50,1,1,233.66,234.41,1,600,1,2,233.58,234.43,505,105,2,2,233.53,234.5,10,63,1,4,233.5,234.75,100,1,1,1,233.45,234.79,15,2000,1,1,AAPL,0.0,0.0,0.0,
2024-10-21 12:10:12.928066550+00:00,2024-10-21T12:10:12.928233491Z,10,2,38,A,A,3,234.16,28,130,166941,12232538,233.95,234.0,10,154,1,7,233.9,234.1,11,400,2,1,233.87,234.13,400,400,1,1,233.8,234.16,29,28,1,1,233.7,234.17,1200,1,1,1,233.66,234.25,1,50,1,1,233.58,234.41,505,600,2,2,233.53,234.43,10,105,1,2,233.5,234.5,100,63,1,4,233.45,234.75,15,1,1,1,AAPL,0.0,0.0,0.0,
2024-10-21 12:10:13.161741583+00:00,2024-10-21T12:10:13.161907732Z,10,2,38,C,B,2,233.87,400,130,166149,12232708,233.95,234.0,10,154,1,7,233.9,234.1,11,400,2,1,233.8,234.13,29,400,1,1,233.7,234.16,1200,28,1,1,233.66,234.17,1,1,1,1,233.58,234.25,505,50,2,1,233.53,234.41,10,600,1,2,233.5,234.43,100,105,1,2,233.45,234.5,15,63,1,4,233.4,234.75,110,1,2,1,AAPL,0.0,0.0,0.0,
2024-10-21 12:10:13.161754596+00:00,2024-10-21T12:10:13.161920820Z,10,2,38,A,B,2,233.84,200,130,166224,12232709,233.95,234.0,10,154,1,7,233.9,234.1,11,400,2,1,233.84,234.13,200,400,1,1,233.8,234.16,29,28,1,1,233.7,234.17,1200,1,1,1,233.66,234.25,1,50,1,1,233.58,234.41,505,600,2,2,233.53,234.43,10,105,1,2,233.5,234.5,100,63,1,4,233.45,234.75,15,1,1,1,AAPL,0.0,0.0,0.0,
2024-10-21 12:10:17.086432603+00:00,2024-10-21T12:10:17.086600126Z,10,2,38,T,N,0,233.99,2,130,167523,12235454,233.95,234.0,10,154,1,7,233.9,234.1,11,400,2,1,233.84,234.13,200,400,1,1,233.8,234.16,29,28,1,1,233.7,234.17,1200,1,1,1,233.66,234.25,1,50,1,1,233.58,234.41,505,600,2,2,233.53,234.43,10,105,1,2,233.5,234.5,100,63,1,4,233.45,234.75,15,1,1,1,AAPL,0.0,0.0,0.0,
