ts_event,ts_recv,rtype,publisher_id,instrument_id,action,side,depth,price,size,flags,ts_in_delta,sequence,bid_px_00,ask_px_00,bid_sz_00,ask_sz_00,bid_ct_00,ask_ct_00,bid_px_01,ask_px_01,bid_sz_01,ask_sz_01,bid_ct_01,ask_ct_01,bid_px_02,ask_px_02,bid_sz_02,ask_sz_02,bid_ct_02,ask_ct_02,bid_px_03,ask_px_03,bid_sz_03,ask_sz_03,bid_ct_03,ask_ct_03,bid_px_04,ask_px_04,bid_sz_04,ask_sz_04,bid_ct_04,ask_ct_04,bid_px_05,ask_px_05,bid_sz_05,ask_sz_05,bid_ct_05,ask_ct_05,bid_px_06,ask_px_06,bid_sz_06,ask_sz_06,bid_ct_06,ask_ct_06,bid_px_07,ask_px_07,bid_sz_07,ask_sz_07,bid_ct_07,ask_ct_07,bid_px_08,ask_px_08,bid_sz_08,ask_sz_08,bid_ct_08,ask_ct_08,bid_px_09,ask_px_09,bid_sz_09,ask_sz_09,bid_ct_09,ask_ct_09,symbol,best_level_ofi,multi_level_ofi,integrated_ofi_1s,cross_asset_ofi
2024-10-21 12:10:20.742267983+00:00,2024-10-21T12:10:20.742434348Z,10,2,38,A,B,0,233.96,20,130,166365,12237424,233.96,234.0,20,154,1,7,233.95,234.1,10,400,1,1,233.9,234.13,11,400,2,1,233.84,234.16,200,28,1,1,233.8,234.17,29,1,1,1,233.7,234.25,1200,50,1,1,233.66,234.41,1,600,1,2,233.58,234.43,505,105,2,2,233.53,234.5,10,63,1,4,233.5,234.75,100,1,1,1,AAPL,0.0,0.0,0.0,
2024-10-21 12:10:22.088936277+00:00,2024-10-21T12:10:22.089103804Z,10,2,38,T,N,0,233.99,5,130,167527,12238033,233.96,234.0,20,154,1,7,233.95,234.1,10,400,1,1,233.9,234.13,11,400,2,1,233.84,234.16,200,28,1,1,233.8,234.17,29,1,1,1,233.7,234.25,1200,50,1,1,233.66,234.41,1,600,1,2,233.58,234.43,505,105,2,2,233.53,234.5,10,63,1,4,233.5,234.75,100,1,1,1,AAPL,0.0,0.0,0.0,
2024-10-21 12:10:23.455694731+00:00,2024-10-21T12:10:23.455861213Z,10,2,38,A,B,3,233.84,200,130,166482,12239081,233.96,234.0,20,154,1,7,233.95,234.1,10,400,1,1,233.9,234.13,11,400,2,1,233.84,234.16,400,28,2,1,233.8,234.17,29,1,1,1,233.7,234.25,1200,50,1,1,233.66,234.41,1,600,1,2,233.58,234.43,505,105,2,2,233.53,234.5,10,63,1,4,233.5,234.75,100,1,1,1,AAPL,0.0,200.0,0.0,
2024-10-21 12:10:23.510549173+00:00,2024-10-21T12:10:23.510715158Z,10,2,38,C,B,3,233.84,200,130,165985,12239119,233.96,234.0,20,154,1,7,233.95,234.1,10,400,1,1,233.9,234.13,11,400,2,1,233.84,234.16,200,28,1,1,233.8,234.17,29,1,1,1,233.7,234.25,1200,50,1,1,233.66,234.41,1,600,1,2,233.58,234.43,505,105,2,2,233.53,234.5,10,63,1,4,233.5,234.75,100,1,1,1,AAPL,0.0,-200.0,0.0,
2024-10-21 12:10:23.510561501+00:00,2024-10-21T12:10:23.510728355Z,10,2,38,A,B,3,233.87,400,130,166854,12239120,233.96,234.0,20,154,1,7,233.95,234.1,10,400,1,1,233.9,234.13,11,400,2,1,233.87,234.16,400,28,1,1,233.8,234.17,29,1,1,1,233.7,234.25,1200,50,1,1,233.66,234.41,1,600,1,2,233.58,234.43,505,105,2,2,233.53,234.5,10,63,1,4,233.5,234.75,100,1,1,1,AAPL,0.0,0.0,0.0,
2024-10-21 12:10:24.014526498+00:00,2024-10-21T12:10:24.014692972Z,10,2,38,A,B,3,233.88,400,130,166474,12239510,233.96,234.0,20,154,1,7,233.95,234.1,10,400,1,1,233.9,234.13,11,400,2,1,233.88,234.16,400,28,1,1,233.8,234.17,29,1,1,1,233.7,234.25,1200,50,1,1,233.66,234.41,1,600,1,2,233.58,234.43,505,105,2,2,233.53,234.5,10,63,1,4,233.5,234.75,100,1,1,1,AAPL,0.0,0.0,0.0,
2024-10-21 12:10:29.982925320+00:00,2024-10-21T12:10:29.983091413Z,10,2,38,C,B,1,233.95,10,130,166093,12243847,233.96,234.0,20,154,1,7,233.9,234.1,11,400,2,1,233.88,234.13,400,400,1,1,233.8,234.16,29,28,1,1,233.7,234.17,1200,1,1,1,233.66,234.25,1,50,1,1,233.58,234.41,505,600,2,2,233.53,234.43,10,105,1,2,233.5,234.5,100,63,1,4,233.45,234.75,15,1,1,1,AAPL,0.0,0.0,0.0,
2024-10-21 12:10:32.696534026+00:00,2024-10-21T12:10:32.696700045Z,10,2,38,C,B,3,233.8,29,130,166019,12245508,233.96,234.0,20,154,1,7,233.9,234.1,11,400,2,1,233.88,234.13,400,400,1,1,233.7,234.16,1200,28,1,1,233.66,234.17,1,1,1,1,233.58,234.25,505,50,2,1,233.53,234.41,10,600,1,2,233.5,234.43,100,105,1,2,233.45,234.5,15,63,1,4,233.4,234.75,110,1,2,1,AAPL,0.0,0.0,0.0,
2024-10-21 12:10:32.696591804+00:00,2024-10-21T12:10:32.696757970Z,10,2,38,A,B,3,233.81,28,130,166166,12245509,233.96,234.0,20,154,1,7,233.9,234.1,11,400,2,1,233.88,234.13,400,400,1,1,233.81,234.16,28,28,1,1,233.7,234.17,1200,1,1,1,233.66,234.25,1,50,1,1,233.58,234.41,505,600,2,2,233.53,234.43,10,105,1,2,233.5,234.5,100,63,1,4,233.45,234.75,15,1,1,1,AAPL,0.0,0.0,0.0,
2024-10-21 12:10:36.255768918+00:00,2024-10-21T12:10:36.255935226Z,10,2,38,C,B,2,233.88,200,130,166308,12247980,233.96,234.0,20,154,1,7,233.9,234.1,11,400,2,1,233.88,234.13,200,400,1,1,233.81,234.16,28,28,1,1,233.7,234.17,1200,1,1,1,233.66,234.25,1,50,1,1,233.58,234.41,505,600,2,2,233.53,234.43,10,105,1,2,233.5,234.5,100,63,1,4,233.45,234.75,15,1,1,1,AAPL,0.0,-200.0,0.0,
2024-10-21 12:10:36.667879809+00:00,2024-10-21T12:10:36.668045674Z,10,2,38,C,A,1,234.1,400,130,165865,12248362,233.96,234.0,20,154,1,7,233.9,234.13,11,400,2,1,233.88,234.16,200,28,1,1,233.81,234.17,28,1,1,1,233.7,234.25,1200,50,1,1,233.66,234.41,1,600,1,2,233.58,234.43,505,105,2,2,233.53,234.5,10,63,1,4,233.5,234.75,100,1,1,1,233.45,234.79,15,2000,1,1,AAPL,0.0,0.0,0.0,
2024-10-21 12:10:36.667890580+00:00,2024-10-21T12:10:36.668056804Z,10,2,38,A,A,1,234.12,400,130,166224,12248363,233.96,234.0,20,154,1,7,233.9,234.12,11,400,2,1,233.88,234.13,200,400,1,1,233.81,234.16,28,28,1,1,233.7,234.17,1200,1,1,1,233.66,234.25,1,50,1,1,233.58,234.41,505,600,2,2,233.53,234.43,10,105,1,2,233.5,234.5,100,63,1,4,233.45,234.75,15,1,1,1,AAPL,0.0,0.0,0.0,
2024-10-21 12:10:36.718839166+00:00,2024-10-21T12:10:36.719005890Z,10,2,38,A,B,2,233.89,200,130,166724,12248396,233.96,234.0,20,154,1,7,233.9,234.12,11,400,2,1,233.89,234.13,200,400,1,1,233.81,234.16,28,28,1,1,233.7,234.17,1200,1,1,1,233.66,234.25,1,50,1,1,233.58,234.41,505,600,2,2,233.53,234.43,10,105,1,2,233.5,234.5,100,63,1,4,233.45,234.75,15,1,1,1,AAPL,0.0,0.0,0.0,
2024-10-21 12:10:36.743886554+00:00,2024-10-21T12:10:36.744053051Z,10,2,38,C,A,3,234.16,28,130,166497,12248576,233.96,234.0,20,154,1,7,233.9,234.12,11,400,2,1,233.89,234.13,200,400,1,1,233.81,234.17,28,1,1,1,233.7,234.25,1200,50,1,1,233.66,234.41,1,600,1,2,233.58,234.43,505,105,2,2,233.53,234.5,10,63,1,4,233.5,234.75,100,1,1,1,233.45,234.79,15,2000,1,1,AAPL,0.0,0.0,0.0,
2024-10-21 12:10:36.743997154+00:00,2024-10-21T12:10:36.744163347Z,10,2,38,A,A,4,234.18,29,130,166193,12248578,233.96,234.0,20,154,1,7,233.9,234.12,11,400,2,1,233.89,234.13,200,400,1,1,233.81,234.17,28,1,1,1,233.7,234.18,1200,29,1,1,233.66,234.25,1,50,1,1,233.58,234.41,505,600,2,2,233.53,234.43,10,105,1,2,233.5,234.5,100,63,1,4,233.45,234.75,15,1,1,1,AAPL,0.0,0.0,0.0,
2024-10-21 12:10:42.064737913+00:00,2024-10-21T12:10:42.064904504Z,10,2,38,C,B,2,233.89,200,130,166591,12252326,233.96,234.0,20,154,1,7,233.9,234.12,11,400,2,1,233.81,234.13,28,400,1,1,233.7,234.17,1200,1,1,1,233.66,234.18,1,29,1,1,233.58,234.25,505,50,2,1,233.53,234.41,10,600,1,2,233.5,234.43,100,105,1,2,233.45,234.5,15,63,1,4,233.4,234.75,110,1,2,1,AAPL,0.0,0.0,0.0,
2024-10-21 12:10:42.064751203+00:00,2024-10-21T12:10:42.064917654Z,10,2,38,A,B,2,233.86,200,130,166451,12252327,233.96,234.0,20,154,1,7,233.9,234.12,11,400,2,1,233.86,234.13,200,400,1,1,233.81,234.17,28,1,1,1,233.7,234.18,1200,29,1,1,233.66,234.25,1,50,1,1,233.58,234.41,505,600,2,2,233.53,234.43,10,105,1,2,233.5,234.5,100,63,1,4,233.45,234.75,15,1,1,1,AAPL,0.0,0.0,0.0,
2024-10-21 12:10:43.289649676+00:00,2024-10-21T12:10:43.289815837Z,10,2,38,A,A,1,234.11,400,130,166161,12253919,233.96,234.0,20,154,1,7,233.9,234.11,11,400,2,1,233.86,234.13,200,400,1,1,233.81,234.17,28,1,1,1,233.7,234.18,1200,29,1,1,233.66,234.25,1,50,1,1,233.58,234.41,505,600,2,2,233.53,234.43,10,105,1,2,233.5,234.5,100,63,1,4,233.45,234.75,15,1,1,1,AAPL,0.0,0.0,0.0,
2024-10-21 12:10:43.377793688+00:00,2024-10-21T12:10:43.377959609Z,10,2,38,C,A,4,234.18,29,130,165921,12254130,233.96,234.0,20,154,1,7,233.9,234.11,11,400,2,1,233.86,234.13,200,400,1,1,233.81,234.17,28,1,1,1,233.7,234.25,1200,50,1,1,233.66,234.41,1,600,1,2,233.58,234.43,505,105,2,2,233.53,234.5,10,63,1,4,233.5,234.75,100,1,1,1,233.45,234.79,15,2000,1,1,AAPL,0.0,0.0,0.0,
2024-10-21 12:10:43.377874040+00:00,2024-10-21T12:10:43.378040281Z,10,2,38,A,A,3,234.17,28,130,166241,12254131,233.96,234.0,20,154,1,7,233.9,234.11,11,400,2,1,233.86,234.13,200,400,1,1,233.81,234.17,28,29,1,2,233.7,234.25,1200,50,1,1,233.66,234.41,1,600,1,2,233.58,234.43,505,105,2,2,233.53,234.5,10,63,1,4,233.5,234.75,100,1,1,1,233.45,234.79,15,2000,1,1,AAPL,0.0,-28.0,0.0,
2024-10-21 12:10:45.117298924+00:00,2024-10-21T12:10:45.117465225Z,10,2,38,A,B,2,233.88,200,130,166301,12255855,233.96,234.0,20,154,1,7,233.9,234.11,11,400,2,1,233.88,234.13,200,400,1,1,233.81,234.17,28,29,1,2,233.7,234.25,1200,50,1,1,233.66,234.41,1,600,1,2,233.58,234.43,505,105,2,2,233.53,234.5,10,63,1,4,233.5,234.75,100,1,1,1,233.45,234.79,15,2000,1,1,AAPL,0.0,0.0,0.0,
2024-10-21 12:10:50.849951366+00:00,2024-10-21T12:10:50.850117869Z,10,2,38,A,B,2,233.89,200,130,166503,12260865,233.96,234.0,20,154,1,7,233.9,234.11,11,400,2,1,233.89,234.13,200,400,1,1,233.81,234.17,28,29,1,2,233.7,234.25,1200,50,1,1,233.66,234.41,1,600,1,2,233.58,234.43,505,105,2,2,233.53,234.5,10,63,1,4,233.5,234.75,100,1,1,1,233.45,234.79,15,2000,1,1,AAPL,0.0,0.0,0.0,
2024-10-21 12:10:52.970596564+00:00,2024-10-21T12:10:52.970762824Z,10,2,38,C,A,4,234.25,50,130,166260,12262701,233.96,234.0,20,154,1,7,233.9,234.11,11,400,2,1,233.89,234.13,200,400,1,1,233.81,234.17,28,29,1,2,233.7,234.41,1200,600,1,2,233.66,234.43,1,105,1,2,233.58,234.5,505,63,2,4,233.53,234.75,10,1,1,1,233.5,234.79,100,2000,1,1,233.45,234.89,15,2,1,2,AAPL,0.0,0.0,0.0,
2024-10-21 12:10:53.810283344+00:00,2024-10-21T12:10:53.810450187Z,10,2,38,C,B,0,233.96,20,130,166843,12263307,233.9,234.0,11,154,2,7,233.89,234.11,200,400,1,1,233.81,234.13,28,400,1,1,233.7,234.17,1200,29,1,2,233.66,234.41,1,600,1,2,233.58,234.43,505,105,2,2,233.53,234.5,10,63,1,4,233.5,234.75,100,1,1,1,233.45,234.79,15,2000,1,1,233.4,234.89,110,2,2,2,AAPL,0.0,0.0,0.0,
2024-10-21 12:10:53.881437911+00:00,2024-10-21T12:10:53.881603970Z,10,2,38,C,B,1,233.89,200,130,166059,12263356,233.9,234.0,11,154,2,7,233.81,234.11,28,400,1,1,233.7,234.13,1200,400,1,1,233.66,234.17,1,29,1,2,233.58,234.41,505,600,2,2,233.53,234.43,10,105,1,2,233.5,234.5,100,63,1,4,233.45,234.75,15,1,1,1,233.4,234.79,110,2000,2,1,233.39,234.89,10,2,1,2,AAPL,0.0,0.0,0.0,
2024-10-21 12:10:53.881449961+00:00,2024-10-21T12:10:53.881616413Z,10,2,38,A,B,1,233.86,200,130,166452,12263357,233.9,234.0,11,154,2,7,233.86,234.11,200,400,1,1,233.81,234.13,28,400,1,1,233.7,234.17,1200,29,1,2,233.66,234.41,1,600,1,2,233.58,234.43,505,105,2,2,233.53,234.5,10,63,1,4,233.5,234.75,100,1,1,1,233.45,234.79,15,2000,1,1,233.4,234.89,110,2,2,2,AAPL,0.0,0.0,0.0,
2024-10-21 12:10:54.127647992+00:00,2024-10-21T12:10:54.127813980Z,10,2,38,C,B,1,233.86,200,130,165988,12263603,233.9,234.0,11,154,2,7,233.81,234.11,28,400,1,1,233.7,234.13,1200,400,1,1,233.66,234.17,1,29,1,2,233.58,234.41,505,600,2,2,233.53,234.43,10,105,1,2,233.5,234.5,100,63,1,4,233.45,234.75,15,1,1,1,233.4,234.79,110,2000,2,1,233.39,234.89,10,2,1,2,AAPL,0.0,0.0,0.0,
2024-10-21 12:10:54.127659727+00:00,2024-10-21T12:10:54.127826075Z,10,2,38,A,B,2,233.78,400,130,166348,12263604,233.9,234.0,11,154,2,7,233.81,234.11,28,400,1,1,233.78,234.13,400,400,1,1,233.7,234.17,1200,29,1,2,233.66,234.41,1,600,1,2,233.58,234.43,505,105,2,2,233.53,234.5,10,63,1,4,233.5,234.75,100,1,1,1,233.45,234.79,15,2000,1,1,233.4,234.89,110,2,2,2,AAPL,0.0,0.0,0.0,
2024-10-21 12:10:54.146847471+00:00,2024-10-21T12:10:54.147013785Z,10,2,38,C,B,1,233.81,28,130,166314,12263624,233.9,234.0,11,154,2,7,233.78,234.11,400,400,1,1,233.7,234.13,1200,400,1,1,233.66,234.17,1,29,1,2,233.58,234.41,505,600,2,2,233.53,234.43,10,105,1,2,233.5,234.5,100,63,1,4,233.45,234.75,15,1,1,1,233.4,234.79,110,2000,2,1,233.39,234.89,10,2,1,2,AAPL,0.0,0.0,0.0,
2024-10-21 12:10:54.146889193+00:00,2024-10-21T12:10:54.147055569Z,10,2,38,A,B,2,233.76,27,130,166376,12263625,233.9,234.0,11,154,2,7,233.78,234.11,400,400,1,1,233.76,234.13,27,400,1,1,233.7,234.17,1200,29,1,2,233.66,234.41,1,600,1,2,233.58,234.43,505,105,2,2,233.53,234.5,10,63,1,4,233.5,234.75,100,1,1,1,233.45,234.79,15,2000,1,1,233.4,234.89,110,2,2,2,AAPL,0.0,0.0,0.0,
2024-10-21 12:10:54.146930519+00:00,2024-10-21T12:10:54.147097290Z,10,2,38,A,A,2,234.13,27,130,166771,12263626,233.9,234.0,11,154,2,7,233.78,234.11,400,400,1,1,233.76,234.13,27,427,1,2,233.7,234.17,1200,29,1,2,233.66,234.41,1,600,1,2,233.58,234.43,505,105,2,2,233.53,234.5,10,63,1,4,233.5,234.75,100,1,1,1,233.45,234.79,15,2000,1,1,233.4,234.89,110,2,2,2,AAPL,0.0,-27.0,0.0,
2024-10-21 12:10:54.147042446+00:00,2024-10-21T12:10:54.147208464Z,10,2,38,C,A,3,234.17,28,130,166018,12263627,233.9,234.0,11,154,2,7,233.78,234.11,400,400,1,1,233.76,234.13,27,427,1,2,233.7,234.17,1200,1,1,1,233.66,234.41,1,600,1,2,233.58,234.43,505,105,2,2,233.53,234.5,10,63,1,4,233.5,234.75,100,1,1,1,233.45,234.79,15,2000,1,1,233.4,234.89,110,2,2,2,AAPL,0.0,28.0,0.0,
2024-10-21 12:10:54.198356340+00:00,2024-10-21T12:10:54.198522999Z,10,2,38,A,A,1,234.06,200,130,166659,12263665,233.9,234.0,11,154,2,7,233.78,234.06,400,200,1,1,233.76,234.13,27,427,1,2,233.7,234.17,1200,1,1,1,233.66,234.41,1,600,1,2,233.58,234.43,505,105,2,2,233.53,234.5,10,63,1,4,233.5,234.75,100,1,1,1,233.45,234.79,15,2000,1,1,233.4,234.89,110,2,2,2,AAPL,0.0,0.0,0.0,
2024-10-21 12:10:57.184732013+00:00,2024-10-21T12:10:57.184898920Z,10,2,38,A,B,1,233.82,200,130,166907,12265734,233.9,234.0,11,154,2,7,233.82,234.06,200,200,1,1,233.76,234.13,27,427,1,2,233.7,234.17,1200,1,1,1,233.66,234.41,1,600,1,2,233.58,234.43,505,105,2,2,233.53,234.5,10,63,1,4,233.5,234.75,100,1,1,1,233.45,234.79,15,2000,1,1,233.4,234.89,110,2,2,2,AAPL,0.0,0.0,0.0,
2024-10-21 12:10:57.589931819+00:00,2024-10-21T12:10:57.590098060Z,10,2,38,A,B,1,233.83,200,130,166241,12266072,233.9,234.0,11,154,2,7,233.83,234.06,200,200,1,1,233.76,234.13,27,427,1,2,233.7,234.17,1200,1,1,1,233.66,234.41,1,600,1,2,233.58,234.43,505,105,2,2,233.53,234.5,10,63,1,4,233.5,234.75,100,1,1,1,233.45,234.79,15,2000,1,1,233.4,234.89,110,2,2,2,AAPL,0.0,0.0,0.0,
2024-10-21 12:10:57.806606311+00:00,2024-10-21T12:10:57.806772384Z,10,2,38,C,B,1,233.83,200,130,166073,12266374,233.9,234.0,11,154,2,7,233.76,234.06,27,200,1,1,233.7,234.13,1200,427,1,2,233.66,234.17,1,1,1,1,233.58,234.41,505,600,2,2,233.53,234.43,10,105,1,2,233.5,234.5,100,63,1,4,233.45,234.75,15,1,1,1,233.4,234.79,110,2000,2,1,233.39,234.89,10,2,1,2,AAPL,0.0,0.0,0.0,
2024-10-21 12:10:57.806619389+00:00,2024-10-21T12:10:57.806785593Z,10,2,38,A,B,1,233.78,400,130,166204,12266375,233.9,234.0,11,154,2,7,233.78,234.06,400,200,1,1,233.76,234.13,27,427,1,2,233.7,234.17,1200,1,1,1,233.66,234.41,1,600,1,2,233.58,234.43,505,105,2,2,233.53,234.5,10,63,1,4,233.5,234.75,100,1,1,1,233.45,234.79,15,2000,1,1,233.4,234.89,110,2,2,2,AAPL,0.0,0.0,0.0,
2024-10-21 12:10:59.771109174+00:00,2024-10-21T12:10:59.771275683Z,10,2,38,C,B,2,233.76,27,130,166509,12268147,233.9,234.0,11,154,2,7,233.78,234.06,400,200,1,1,233.7,234.13,1200,427,1,2,233.66,234.17,1,1,1,1,233.58,234.41,505,600,2,2,233.53,234.43,10,105,1,2,233.5,234.5,100,63,1,4,233.45,234.75,15,1,1,1,233.4,234.79,110,2000,2,1,233.39,234.89,10,2,1,2,AAPL,0.0,0.0,0.0,
2024-10-21 12:10:59.771161194+00:00,2024-10-21T12:10:59.771327492Z,10,2,38,A,B,2,233.77,30,130,166298,12268148,233.9,234.0,11,154,2,7,233.78,234.06,400,200,1,1,233.77,234.13,30,427,1,2,233.7,234.17,1200,1,1,1,233.66,234.41,1,600,1,2,233.58,234.43,505,105,2,2,233.53,234.5,10,63,1,4,233.5,234.75,100,1,1,1,233.45,234.79,15,2000,1,1,233.4,234.89,110,2,2,2,AAPL,0.0,0.0,0.0,
2024-10-21 12:11:00.807617417+00:00,2024-10-21T12:11:00.807783551Z,10,2,38,C,B,2,233.77,30,130,166134,12269676,233.9,234.0,11,154,2,7,233.78,234.06,400,200,1,1,233.7,234.13,1200,427,1,2,233.66,234.17,1,1,1,1,233.58,234.41,505,600,2,2,233.53,234.43,10,105,1,2,233.5,234.5,100,63,1,4,233.45,234.75,15,1,1,1,233.4,234.79,110,2000,2,1,233.39,234.89,10,2,1,2,AAPL,0.0,0.0,0.0,
2024-10-21 12:11:00.807657573+00:00,2024-10-21T12:11:00.807824165Z,10,2,38,A,B,1,233.82,26,130,166592,12269677,233.9,234.0,11,154,2,7,233.82,234.06,26,200,1,1,233.78,234.13,400,427,1,2,233.7,234.17,1200,1,1,1,233.66,234.41,1,600,1,2,233.58,234.43,505,105,2,2,233.53,234.5,10,63,1,4,233.5,234.75,100,1,1,1,233.45,234.79,15,2000,1,1,233.4,234.89,110,2,2,2,AAPL,0.0,0.0,0.0,
2024-10-21 12:11:00.863155159+00:00,2024-10-21T12:11:00.863321742Z,10,2,38,A,B,1,233.87,200,130,166583,12269733,233.9,234.0,11,154,2,7,233.87,234.06,200,200,1,1,233.82,234.13,26,427,1,2,233.7,234.17,1200,1,1,1,233.66,234.41,1,600,1,2,233.58,234.43,505,105,2,2,233.53,234.5,10,63,1,4,233.5,234.75,100,1,1,1,233.45,234.79,15,2000,1,1,233.4,234.89,110,2,2,2,AAPL,0.0,0.0,0.0,
2024-10-21 12:11:02.807100841+00:00,2024-10-21T12:11:02.807267623Z,10,2,38,A,B,1,233.88,200,130,166782,12271687,233.9,234.0,11,154,2,7,233.88,234.06,200,200,1,1,233.82,234.13,26,427,1,2,233.7,234.17,1200,1,1,1,233.66,234.41,1,600,1,2,233.58,234.43,505,105,2,2,233.53,234.5,10,63,1,4,233.5,234.75,100,1,1,1,233.45,234.79,15,2000,1,1,233.4,234.89,110,2,2,2,AAPL,0.0,0.0,0.0,
2024-10-21 12:11:08.220315875+00:00,2024-10-21T12:11:08.220481984Z,10,2,38,C,B,1,233.88,200,130,166109,12275485,233.9,234.0,11,154,2,7,233.82,234.06,26,200,1,1,233.7,234.13,1200,427,1,2,233.66,234.17,1,1,1,1,233.58,234.41,505,600,2,2,233.53,234.43,10,105,1,2,233.5,234.5,100,63,1,4,233.45,234.75,15,1,1,1,233.4,234.79,110,2000,2,1,233.39,234.89,10,2,1,2,AAPL,0.0,0.0,0.0,
2024-10-21 12:11:08.291449117+00:00,2024-10-21T12:11:08.291615657Z,10,2,38,A,B,2,233.78,400,130,166540,12275506,233.9,234.0,11,154,2,7,233.82,234.06,26,200,1,1,233.78,234.13,400,427,1,2,233.7,234.17,1200,1,1,1,233.66,234.41,1,600,1,2,233.58,234.43,505,105,2,2,233.53,234.5,10,63,1,4,233.5,234.75,100,1,1,1,233.45,234.79,15,2000,1,1,233.4,234.89,110,2,2,2,AAPL,0.0,0.0,0.0,
2024-10-21 12:11:08.292006615+00:00,2024-10-21T12:11:08.292173149Z,10,2,38,A,B,3,233.76,27,130,166534,12275507,233.9,234.0,11,154,2,7,233.82,234.06,26,200,1,1,233.78,234.13,400,427,1,2,233.76,234.17,27,1,1,1,233.7,234.41,1200,600,1,2,233.66,234.43,1,105,1,2,233.58,234.5,505,63,2,4,233.53,234.75,10,1,1,1,233.5,234.79,100,2000,1,1,233.45,234.89,15,2,1,2,AAPL,0.0,0.0,0.0,
2024-10-21 12:11:08.292044305+00:00,2024-10-21T12:11:08.292210524Z,10,2,38,C,B,1,233.82,26,130,166219,12275508,233.9,234.0,11,154,2,7,233.78,234.06,400,200,1,1,233.76,234.13,27,427,1,2,233.7,234.17,1200,1,1,1,233.66,234.41,1,600,1,2,233.58,234.43,505,105,2,2,233.53,234.5,10,63,1,4,233.5,234.75,100,1,1,1,233.45,234.79,15,2000,1,1,233.4,234.89,110,2,2,2,AAPL,0.0,0.0,0.0,
2024-10-21 12:11:10.442610415+00:00,2024-10-21T12:11:10.442776750Z,10,2,38,A,B,1,233.79,400,130,166335,12277136,233.9,234.0,11,154,2,7,233.79,234.06,400,200,1,1,233.76,234.13,27,427,1,2,233.7,234.17,1200,1,1,1,233.66,234.41,1,600,1,2,233.58,234.43,505,105,2,2,233.53,234.5,10,63,1,4,233.5,234.75,100,1,1,1,233.45,234.79,15,2000,1,1,233.4,234.89,110,2,2,2,AAPL,0.0,0.0,0.0,
2024-10-21 12:11:10.454786222+00:00,2024-10-21T12:11:10.454952399Z,10,2,38,C,B,2,233.76,27,130,166177,12277212,233.9,234.0,11,154,2,7,233.79,234.06,400,200,1,1,233.7,234.13,1200,427,1,2,233.66,234.17,1,1,1,1,233.58,234.41,505,600,2,2,233.53,234.43,10,105,1,2,233.5,234.5,100,63,1,4,233.45,234.75,15,1,1,1,233.4,234.79,110,2000,2,1,233.39,234.89,10,2,1,2,AAPL,0.0,0.0,0.0,
2024-10-21 12:11:10.454836386+00:00,2024-10-21T12:11:10.455002886Z,10,2,38,A,B,2,233.77,27,130,166500,12277213,233.9,234.0,11,154,2,7,233.79,234.06,400,200,1,1,233.77,234.13,27,427,1,2,233.7,234.17,1200,1,1,1,233.66,234.41,1,600,1,2,233.58,234.43,505,105,2,2,233.53,234.5,10,63,1,4,233.5,234.75,100,1,1,1,233.45,234.79,15,2000,1,1,233.4,234.89,110,2,2,2,AAPL,0.0,0.0,0.0,
2024-10-21 12:11:11.346234393+00:00,2024-10-21T12:11:11.346401450Z,10,2,38,A,B,1,233.83,200,130,167057,12278338,233.9,234.0,11,154,2,7,233.83,234.06,200,200,1,1,233.77,234.13,27,427,1,2,233.7,234.17,1200,1,1,1,233.66,234.41,1,600,1,2,233.58,234.43,505,105,2,2,233.53,234.5,10,63,1,4,233.5,234.75,100,1,1,1,233.45,234.79,15,2000,1,1,233.4,234.89,110,2,2,2,AAPL,0.0,0.0,0.0,
2024-10-21 12:11:18.869640062+00:00,2024-10-21T12:11:18.869806122Z,10,2,38,C,B,1,233.83,200,130,166060,12284656,233.9,234.0,11,154,2,7,233.77,234.06,27,200,1,1,233.7,234.13,1200,427,1,2,233.66,234.17,1,1,1,1,233.58,234.41,505,600,2,2,233.53,234.43,10,105,1,2,233.5,234.5,100,63,1,4,233.45,234.75,15,1,1,1,233.4,234.79,110,2000,2,1,233.39,234.89,10,2,1,2,AAPL,0.0,0.0,0.0,
2024-10-21 12:11:18.869653217+00:00,2024-10-21T12:11:18.869819499Z,10,2,38,A,B,1,233.78,400,130,166282,12284657,233.9,234.0,11,154,2,7,233.78,234.06,400,200,1,1,233.77,234.13,27,427,1,2,233.7,234.17,1200,1,1,1,233.66,234.41,1,600,1,2,233.58,234.43,505,105,2,2,233.53,234.5,10,63,1,4,233.5,234.75,100,1,1,1,233.45,234.79,15,2000,1,1,233.4,234.89,110,2,2,2,AAPL,0.0,0.0,0.0,
2024-10-21 12:11:21.873343400+00:00,2024-10-21T12:11:21.873509615Z,10,2,38,C,B,2,233.77,27,130,166215,12287082,233.9,234.0,11,154,2,7,233.78,234.06,400,200,1,1,233.7,234.13,1200,427,1,2,233.66,234.17,1,1,1,1,233.58,234.41,505,600,2,2,233.53,234.43,10,105,1,2,233.5,234.5,100,63,1,4,233.45,234.75,15,1,1,1,233.4,234.79,110,2000,2,1,233.39,234.89,10,2,1,2,AAPL,0.0,0.0,0.0,
2024-10-21 12:11:21.873432987+00:00,2024-10-21T12:11:21.873599230Z,10,2,38,A,B,1,233.81,26,130,166243,12287083,233.9,234.0,11,154,2,7,233.81,234.06,26,200,1,1,233.78,234.13,400,427,1,2,233.7,234.17,1200,1,1,1,233.66,234.41,1,600,1,2,233.58,234.43,505,105,2,2,233.53,234.5,10,63,1,4,233.5,234.75,100,1,1,1,233.45,234.79,15,2000,1,1,233.4,234.89,110,2,2,2,AAPL,0.0,0.0,0.0,
2024-10-21 12:11:21.928253749+00:00,2024-10-21T12:11:21.928420269Z,10,2,38,A,B,1,233.86,200,130,166520,12287102,233.9,234.0,11,154,2,7,233.86,234.06,200,200,1,1,233.81,234.13,26,427,1,2,233.7,234.17,1200,1,1,1,233.66,234.41,1,600,1,2,233.58,234.43,505,105,2,2,233.53,234.5,10,63,1,4,233.5,234.75,100,1,1,1,233.45,234.79,15,2000,1,1,233.4,234.89,110,2,2,2,AAPL,0.0,0.0,0.0,
2024-10-21 12:11:22.072355634+00:00,2024-10-21T12:11:22.072521728Z,10,2,38,C,B,1,233.86,200,130,166094,12287179,233.9,234.0,11,154,2,7,233.81,234.06,26,200,1,1,233.7,234.13,1200,427,1,2,233.66,234.17,1,1,1,1,233.58,234.41,505,600,2,2,233.53,234.43,10,105,1,2,233.5,234.5,100,63,1,4,233.45,234.75,15,1,1,1,233.4,234.79,110,2000,2,1,233.39,234.89,10,2,1,2,AAPL,0.0,0.0,0.0,
2024-10-21 12:11:22.072368471+00:00,2024-10-21T12:11:22.072534773Z,10,2,38,A,B,2,233.78,400,130,166302,12287180,233.9,234.0,11,154,2,7,233.81,234.06,26,200,1,1,233.78,234.13,400,427,1,2,233.7,234.17,1200,1,1,1,233.66,234.41,1,600,1,2,233.58,234.43,505,105,2,2,233.53,234.5,10,63,1,4,233.5,234.75,100,1,1,1,233.45,234.79,15,2000,1,1,233.4,234.89,110,2,2,2,AAPL,0.0,0.0,0.0,
2024-10-21 12:11:22.072864187+00:00,2024-10-21T12:11:22.073030139Z,10,2,38,C,B,1,233.81,26,130,165952,12287181,233.9,234.0,11,154,2,7,233.78,234.06,400,200,1,1,233.7,234.13,1200,427,1,2,233.66,234.17,1,1,1,1,233.58,234.41,505,600,2,2,233.53,234.43,10,105,1,2,233.5,234.5,100,63,1,4,233.45,234.75,15,1,1,1,233.4,234.79,110,2000,2,1,233.39,234.89,10,2,1,2,AAPL,0.0,0.0,0.0,
2024-10-21 12:11:22.937969054+00:00,2024-10-21T12:11:22.938136138Z,10,2,38,T,N,0,233.98,4,130,167084,12287694,233.9,234.0,11,154,2,7,233.78,234.06,400,200,1,1,233.7,234.13,1200,427,1,2,233.66,234.17,1,1,1,1,233.58,234.41,505,600,2,2,233.53,234.43,10,105,1,2,233.5,234.5,100,63,1,4,233.45,234.75,15,1,1,1,233.4,234.79,110,2000,2,1,233.39,234.89,10,2,1,2,AAPL,0.0,0.0,0.0,
2024-10-21 12:11:23.000862969+00:00,2024-10-21T12:11:23.001029527Z,10,2,38,A,B,2,233.76,30,130,166558,12287720,233.9,234.0,11,154,2,7,233.78,234.06,400,200,1,1,233.76,234.13,30,427,1,2,233.7,234.17,1200,1,1,1,233.66,234.41,1,600,1,2,233.58,234.43,505,105,2,2,233.53,234.5,10,63,1,4,233.5,234.75,100,1,1,1,233.45,234.79,15,2000,1,1,233.4,234.89,110,2,2,2,AAPL,0.0,0.0,0.0,
2024-10-21 12:11:25.072916074+00:00,2024-10-21T12:11:25.073082417Z,10,2,38,C,A,1,234.06,200,130,166343,12288985,233.9,234.0,11,154,2,7,233.78,234.13,400,427,1,2,233.76,234.17,30,1,1,1,233.7,234.41,1200,600,1,2,233.66,234.43,1,105,1,2,233.58,234.5,505,63,2,4,233.53,234.75,10,1,1,1,233.5,234.79,100,2000,1,1,233.45,234.89,15,2,1,2,233.4,235.0,110,213,2,6,AAPL,0.0,0.0,0.0,
2024-10-21 12:11:25.072929618+00:00,2024-10-21T12:11:25.073096247Z,10,2,38,A,A,1,234.12,400,130,166629,12288986,233.9,234.0,11,154,2,7,233.78,234.12,400,400,1,1,233.76,234.13,30,427,1,2,233.7,234.17,1200,1,1,1,233.66,234.41,1,600,1,2,233.58,234.43,505,105,2,2,233.53,234.5,10,63,1,4,233.5,234.75,100,1,1,1,233.45,234.79,15,2000,1,1,233.4,234.89,110,2,2,2,AAPL,0.0,0.0,0.0,
2024-10-21 12:11:25.073291984+00:00,2024-10-21T12:11:25.073458008Z,10,2,38,C,B,2,233.76,30,130,166024,12288987,233.9,234.0,11,154,2,7,233.78,234.12,400,400,1,1,233.7,234.13,1200,427,1,2,233.66,234.17,1,1,1,1,233.58,234.41,505,600,2,2,233.53,234.43,10,105,1,2,233.5,234.5,100,63,1,4,233.45,234.75,15,1,1,1,233.4,234.79,110,2000,2,1,233.39,234.89,10,2,1,2,AAPL,0.0,0.0,0.0,
2024-10-21 12:11:25.073388717+00:00,2024-10-21T12:11:25.073555014Z,10,2,38,A,B,1,233.81,26,130,166297,12288988,233.9,234.0,11,154,2,7,233.81,234.12,26,400,1,1,233.78,234.13,400,427,1,2,233.7,234.17,1200,1,1,1,233.66,234.41,1,600,1,2,233.58,234.43,505,105,2,2,233.53,234.5,10,63,1,4,233.5,234.75,100,1,1,1,233.45,234.79,15,2000,1,1,233.4,234.89,110,2,2,2,AAPL,0.0,0.0,0.0,
2024-10-21 12:11:25.073972612+00:00,2024-10-21T12:11:25.074138845Z,10,2,38,C,A,2,234.13,27,130,166233,12288989,233.9,234.0,11,154,2,7,233.81,234.12,26,400,1,1,233.78,234.13,400,400,1,1,233.7,234.17,1200,1,1,1,233.66,234.41,1,600,1,2,233.58,234.43,505,105,2,2,233.53,234.5,10,63,1,4,233.5,234.75,100,1,1,1,233.45,234.79,15,2000,1,1,233.4,234.89,110,2,2,2,AAPL,0.0,27.0,0.0,
2024-10-21 12:11:25.074100004+00:00,2024-10-21T12:11:25.074266365Z,10,2,38,A,A,4,234.18,30,130,166361,12288990,233.9,234.0,11,154,2,7,233.81,234.12,26,400,1,1,233.78,234.13,400,400,1,1,233.7,234.17,1200,1,1,1,233.66,234.18,1,30,1,1,233.58,234.41,505,600,2,2,233.53,234.43,10,105,1,2,233.5,234.5,100,63,1,4,233.45,234.75,15,1,1,1,233.4,234.79,110,2000,2,1,AAPL,0.0,0.0,0.0,
2024-10-21 12:11:25.129294511+00:00,2024-10-21T12:11:25.129461870Z,10,2,38,A,B,1,233.86,200,130,167359,12289009,233.9,234.0,11,154,2,7,233.86,234.12,200,400,1,1,233.81,234.13,26,400,1,1,233.7,234.17,1200,1,1,1,233.66,234.18,1,30,1,1,233.58,234.41,505,600,2,2,233.53,234.43,10,105,1,2,233.5,234.5,100,63,1,4,233.45,234.75,15,1,1,1,233.4,234.79,110,2000,2,1,AAPL,0.0,0.0,0.0,
2024-10-21 12:11:27.120005157+00:00,2024-10-21T12:11:27.120171307Z,10,2,38,C,B,1,233.86,200,130,166150,12290119,233.9,234.0,11,154,2,7,233.81,234.12,26,400,1,1,233.7,234.13,1200,400,1,1,233.66,234.17,1,1,1,1,233.58,234.18,505,30,2,1,233.53,234.41,10,600,1,2,233.5,234.43,100,105,1,2,233.45,234.5,15,63,1,4,233.4,234.75,110,1,2,1,233.39,234.79,10,2000,1,1,AAPL,0.0,0.0,0.0,
2024-10-21 12:11:27.120018111+00:00,2024-10-21T12:11:27.120184761Z,10,2,38,A,B,2,233.78,400,130,166650,12290120,233.9,234.0,11,154,2,7,233.81,234.12,26,400,1,1,233.78,234.13,400,400,1,1,233.7,234.17,1200,1,1,1,233.66,234.18,1,30,1,1,233.58,234.41,505,600,2,2,233.53,234.43,10,105,1,2,233.5,234.5,100,63,1,4,233.45,234.75,15,1,1,1,233.4,234.79,110,2000,2,1,AAPL,0.0,0.0,0.0,
2024-10-21 12:11:27.120506757+00:00,2024-10-21T12:11:27.120673190Z,10,2,38,C,B,1,233.81,26,130,166433,12290123,233.9,234.0,11,154,2,7,233.78,234.12,400,400,1,1,233.7,234.13,1200,400,1,1,233.66,234.17,1,1,1,1,233.58,234.18,505,30,2,1,233.53,234.41,10,600,1,2,233.5,234.43,100,105,1,2,233.45,234.5,15,63,1,4,233.4,234.75,110,1,2,1,233.39,234.79,10,2000,1,1,AAPL,0.0,0.0,0.0,
2024-10-21 12:11:27.120548454+00:00,2024-10-21T12:11:27.120714598Z,10,2,38,A,B,2,233.76,29,130,166144,12290124,233.9,234.0,11,154,2,7,233.78,234.12,400,400,1,1,233.76,234.13,29,400,1,1,233.7,234.17,1200,1,1,1,233.66,234.18,1,30,1,1,233.58,234.41,505,600,2,2,233.53,234.43,10,105,1,2,233.5,234.5,100,63,1,4,233.45,234.75,15,1,1,1,233.4,234.79,110,2000,2,1,AAPL,0.0,0.0,0.0,
2024-10-21 12:11:27.120650159+00:00,2024-10-21T12:11:27.120816314Z,10,2,38,A,A,2,234.13,27,130,166155,12290125,233.9,234.0,11,154,2,7,233.78,234.12,400,400,1,1,233.76,234.13,29,427,1,2,233.7,234.17,1200,1,1,1,233.66,234.18,1,30,1,1,233.58,234.41,505,600,2,2,233.53,234.43,10,105,1,2,233.5,234.5,100,63,1,4,233.45,234.75,15,1,1,1,233.4,234.79,110,2000,2,1,AAPL,0.0,-27.0,0.0,
2024-10-21 12:11:27.120720548+00:00,2024-10-21T12:11:27.120886583Z,10,2,38,C,A,4,234.18,30,130,166035,12290126,233.9,234.0,11,154,2,7,233.78,234.12,400,400,1,1,233.76,234.13,29,427,1,2,233.7,234.17,1200,1,1,1,233.66,234.41,1,600,1,2,233.58,234.43,505,105,2,2,233.53,234.5,10,63,1,4,233.5,234.75,100,1,1,1,233.45,234.79,15,2000,1,1,233.4,234.89,110,2,2,2,AAPL,0.0,0.0,0.0,
2024-10-21 12:11:27.177529449+00:00,2024-10-21T12:11:27.177695699Z,10,2,38,A,A,1,234.06,200,130,166250,12290153,233.9,234.0,11,154,2,7,233.78,234.06,400,200,1,1,233.76,234.13,29,427,1,2,233.7,234.17,1200,1,1,1,233.66,234.41,1,600,1,2,233.58,234.43,505,105,2,2,233.53,234.5,10,63,1,4,233.5,234.75,100,1,1,1,233.45,234.79,15,2000,1,1,233.4,234.89,110,2,2,2,AAPL,0.0,0.0,0.0,
2024-10-21 12:11:30.179103980+00:00,2024-10-21T12:11:30.179271563Z,10,2,38,A,B,1,233.82,200,130,167583,12292157,233.9,234.0,11,154,2,7,233.82,234.06,200,200,1,1,233.76,234.13,29,427,1,2,233.7,234.17,1200,1,1,1,233.66,234.41,1,600,1,2,233.58,234.43,505,105,2,2,233.53,234.5,10,63,1,4,233.5,234.75,100,1,1,1,233.45,234.79,15,2000,1,1,233.4,234.89,110,2,2,2,AAPL,0.0,0.0,0.0,
2024-10-21 12:11:34.156391256+00:00,2024-10-21T12:11:34.156557363Z,10,2,38,C,B,1,233.82,200,130,166107,12294618,233.9,234.0,11,154,2,7,233.76,234.06,29,200,1,1,233.7,234.13,1200,427,1,2,233.66,234.17,1,1,1,1,233.58,234.41,505,600,2,2,233.53,234.43,10,105,1,2,233.5,234.5,100,63,1,4,233.45,234.75,15,1,1,1,233.4,234.79,110,2000,2,1,233.39,234.89,10,2,1,2,AAPL,0.0,0.0,0.0,
2024-10-21 12:11:34.156403417+00:00,2024-10-21T12:11:34.156569858Z,10,2,38,A,B,1,233.78,400,130,166441,12294619,233.9,234.0,11,154,2,7,233.78,234.06,400,200,1,1,233.76,234.13,29,427,1,2,233.7,234.17,1200,1,1,1,233.66,234.41,1,600,1,2,233.58,234.43,505,105,2,2,233.53,234.5,10,63,1,4,233.5,234.75,100,1,1,1,233.45,234.79,15,2000,1,1,233.4,234.89,110,2,2,2,AAPL,0.0,0.0,0.0,
2024-10-21 12:11:36.738675617+00:00,2024-10-21T12:11:36.738842101Z,10,2,38,C,B,0,233.9,1,130,166484,12295779,233.9,234.0,10,154,1,7,233.78,234.06,400,200,1,1,233.76,234.13,29,427,1,2,233.7,234.17,1200,1,1,1,233.66,234.41,1,600,1,2,233.58,234.43,505,105,2,2,233.53,234.5,10,63,1,4,233.5,234.75,100,1,1,1,233.45,234.79,15,2000,1,1,233.4,234.89,110,2,2,2,AAPL,-1.0,-1.0,-1.0,
2024-10-21 12:11:37.210931791+00:00,2024-10-21T12:11:37.211098382Z,10,2,38,A,B,1,233.82,200,130,166591,12295954,233.9,234.0,10,154,1,7,233.82,234.06,200,200,1,1,233.76,234.13,29,427,1,2,233.7,234.17,1200,1,1,1,233.66,234.41,1,600,1,2,233.58,234.43,505,105,2,2,233.53,234.5,10,63,1,4,233.5,234.75,100,1,1,1,233.45,234.79,15,2000,1,1,233.4,234.89,110,2,2,2,AAPL,0.0,0.0,-1.0,
2024-10-21 12:11:40.138482175+00:00,2024-10-21T12:11:40.138648473Z,10,2,38,C,B,1,233.82,200,130,166298,12298108,233.9,234.0,10,154,1,7,233.76,234.06,29,200,1,1,233.7,234.13,1200,427,1,2,233.66,234.17,1,1,1,1,233.58,234.41,505,600,2,2,233.53,234.43,10,105,1,2,233.5,234.5,100,63,1,4,233.45,234.75,15,1,1,1,233.4,234.79,110,2000,2,1,233.39,234.89,10,2,1,2,AAPL,0.0,0.0,0.0,
2024-10-21 12:11:40.138496802+00:00,2024-10-21T12:11:40.138664034Z,10,2,38,A,B,1,233.78,400,130,167232,12298109,233.9,234.0,10,154,1,7,233.78,234.06,400,200,1,1,233.76,234.13,29,427,1,2,233.7,234.17,1200,1,1,1,233.66,234.41,1,600,1,2,233.58,234.43,505,105,2,2,233.53,234.5,10,63,1,4,233.5,234.75,100,1,1,1,233.45,234.79,15,2000,1,1,233.4,234.89,110,2,2,2,AAPL,0.0,0.0,0.0,
2024-10-21 12:11:43.193475620+00:00,2024-10-21T12:11:43.193642005Z,10,2,38,A,B,1,233.82,200,130,166385,12299803,233.9,234.0,10,154,1,7,233.82,234.06,200,200,1,1,233.76,234.13,29,427,1,2,233.7,234.17,1200,1,1,1,233.66,234.41,1,600,1,2,233.58,234.43,505,105,2,2,233.53,234.5,10,63,1,4,233.5,234.75,100,1,1,1,233.45,234.79,15,2000,1,1,233.4,234.89,110,2,2,2,AAPL,0.0,0.0,0.0,
2024-10-21 12:11:45.774723015+00:00,2024-10-21T12:11:45.774890873Z,10,2,38,T,N,0,233.98,50,130,167858,12301317,233.9,234.0,10,154,1,7,233.82,234.06,200,200,1,1,233.76,234.13,29,427,1,2,233.7,234.17,1200,1,1,1,233.66,234.41,1,600,1,2,233.58,234.43,505,105,2,2,233.53,234.5,10,63,1,4,233.5,234.75,100,1,1,1,233.45,234.79,15,2000,1,1,233.4,234.89,110,2,2,2,AAPL,0.0,0.0,0.0,
2024-10-21 12:11:45.843943302+00:00,2024-10-21T12:11:45.844109427Z,10,2,38,C,B,1,233.82,200,130,166125,12301621,233.9,234.0,10,154,1,7,233.76,234.06,29,200,1,1,233.7,234.13,1200,427,1,2,233.66,234.17,1,1,1,1,233.58,234.41,505,600,2,2,233.53,234.43,10,105,1,2,233.5,234.5,100,63,1,4,233.45,234.75,15,1,1,1,233.4,234.79,110,2000,2,1,233.39,234.89,10,2,1,2,AAPL,0.0,0.0,0.0,
2024-10-21 12:11:45.843955896+00:00,2024-10-21T12:11:45.844122189Z,10,2,38,A,B,1,233.78,400,130,166293,12301622,233.9,234.0,10,154,1,7,233.78,234.06,400,200,1,1,233.76,234.13,29,427,1,2,233.7,234.17,1200,1,1,1,233.66,234.41,1,600,1,2,233.58,234.43,505,105,2,2,233.53,234.5,10,63,1,4,233.5,234.75,100,1,1,1,233.45,234.79,15,2000,1,1,233.4,234.89,110,2,2,2,AAPL,0.0,0.0,0.0,
2024-10-21 12:11:48.580722768+00:00,2024-10-21T12:11:48.580889153Z,10,2,38,A,B,1,233.79,400,130,166385,12303381,233.9,234.0,10,154,1,7,233.79,234.06,400,200,1,1,233.76,234.13,29,427,1,2,233.7,234.17,1200,1,1,1,233.66,234.41,1,600,1,2,233.58,234.43,505,105,2,2,233.53,234.5,10,63,1,4,233.5,234.75,100,1,1,1,233.45,234.79,15,2000,1,1,233.4,234.89,110,2,2,2,AAPL,0.0,0.0,0.0,
2024-10-21 12:11:48.598471411+00:00,2024-10-21T12:11:48.598638403Z,10,2,38,C,B,2,233.76,29,130,166992,12303469,233.9,234.0,10,154,1,7,233.79,234.06,400,200,1,1,233.7,234.13,1200,427,1,2,233.66,234.17,1,1,1,1,233.58,234.41,505,600,2,2,233.53,234.43,10,105,1,2,233.5,234.5,100,63,1,4,233.45,234.75,15,1,1,1,233.4,234.79,110,2000,2,1,233.39,234.89,10,2,1,2,AAPL,0.0,0.0,0.0,
2024-10-21 12:11:48.598514970+00:00,2024-10-21T12:11:48.598681245Z,10,2,38,A,B,2,233.77,28,130,166275,12303470,233.9,234.0,10,154,1,7,233.79,234.06,400,200,1,1,233.77,234.13,28,427,1,2,233.7,234.17,1200,1,1,1,233.66,234.41,1,600,1,2,233.58,234.43,505,105,2,2,233.53,234.5,10,63,1,4,233.5,234.75,100,1,1,1,233.45,234.79,15,2000,1,1,233.4,234.89,110,2,2,2,AAPL,0.0,0.0,0.0,
2024-10-21 12:11:48.899046660+00:00,2024-10-21T12:11:48.899213107Z,10,2,38,A,B,1,233.83,200,130,166447,12303858,233.9,234.0,10,154,1,7,233.83,234.06,200,200,1,1,233.77,234.13,28,427,1,2,233.7,234.17,1200,1,1,1,233.66,234.41,1,600,1,2,233.58,234.43,505,105,2,2,233.53,234.5,10,63,1,4,233.5,234.75,100,1,1,1,233.45,234.79,15,2000,1,1,233.4,234.89,110,2,2,2,AAPL,0.0,0.0,0.0,
2024-10-21 12:11:50.834920978+00:00,2024-10-21T12:11:50.835087071Z,10,2,38,C,B,1,233.83,200,130,166093,12305321,233.9,234.0,10,154,1,7,233.77,234.06,28,200,1,1,233.7,234.13,1200,427,1,2,233.66,234.17,1,1,1,1,233.58,234.41,505,600,2,2,233.53,234.43,10,105,1,2,233.5,234.5,100,63,1,4,233.45,234.75,15,1,1,1,233.4,234.79,110,2000,2,1,233.39,234.89,10,2,1,2,AAPL,0.0,0.0,0.0,
2024-10-21 12:11:50.924089402+00:00,2024-10-21T12:11:50.924256645Z,10,2,38,A,B,1,233.83,200,130,167243,12305429,233.9,234.0,10,154,1,7,233.83,234.06,200,200,1,1,233.77,234.13,28,427,1,2,233.7,234.17,1200,1,1,1,233.66,234.41,1,600,1,2,233.58,234.43,505,105,2,2,233.53,234.5,10,63,1,4,233.5,234.75,100,1,1,1,233.45,234.79,15,2000,1,1,233.4,234.89,110,2,2,2,AAPL,0.0,0.0,0.0,
2024-10-21 12:11:53.326572732+00:00,2024-10-21T12:11:53.326738713Z,10,2,38,C,B,1,233.83,200,130,165981,12306983,233.9,234.0,10,154,1,7,233.77,234.06,28,200,1,1,233.7,234.13,1200,427,1,2,233.66,234.17,1,1,1,1,233.58,234.41,505,600,2,2,233.53,234.43,10,105,1,2,233.5,234.5,100,63,1,4,233.45,234.75,15,1,1,1,233.4,234.79,110,2000,2,1,233.39,234.89,10,2,1,2,AAPL,0.0,0.0,0.0,
2024-10-21 12:11:53.326585955+00:00,2024-10-21T12:11:53.326752130Z,10,2,38,A,B,1,233.79,400,130,166175,12306984,233.9,234.0,10,154,1,7,233.79,234.06,400,200,1,1,233.77,234.13,28,427,1,2,233.7,234.17,1200,1,1,1,233.66,234.41,1,600,1,2,233.58,234.43,505,105,2,2,233.53,234.5,10,63,1,4,233.5,234.75,100,1,1,1,233.45,234.79,15,2000,1,1,233.4,234.89,110,2,2,2,AAPL,0.0,0.0,0.0,
2024-10-21 12:11:56.382477901+00:00,2024-10-21T12:11:56.382644560Z,10,2,38,A,B,1,233.83,200,130,166659,12309100,233.9,234.0,10,154,1,7,233.83,234.06,200,200,1,1,233.77,234.13,28,427,1,2,233.7,234.17,1200,1,1,1,233.66,234.41,1,600,1,2,233.58,234.43,505,105,2,2,233.53,234.5,10,63,1,4,233.5,234.75,100,1,1,1,233.45,234.79,15,2000,1,1,233.4,234.89,110,2,2,2,AAPL,0.0,0.0,0.0,
2024-10-21 12:12:02.086529609+00:00,2024-10-21T12:12:02.086696137Z,10,2,38,A,A,0,233.97,20,130,166528,12315842,233.9,233.97,10,20,1,1,233.83,234.0,200,154,1,7,233.77,234.06,28,200,1,1,233.7,234.13,1200,427,1,2,233.66,234.17,1,1,1,1,233.58,234.41,505,600,2,2,233.53,234.43,10,105,1,2,233.5,234.5,100,63,1,4,233.45,234.75,15,1,1,1,233.4,234.79,110,2000,2,1,AAPL,0.0,0.0,0.0,
2024-10-21 12:12:02.213802116+00:00,2024-10-21T12:12:02.213968660Z,10,2,38,C,B,1,233.83,200,130,166544,12315992,233.9,233.97,10,20,1,1,233.77,234.0,28,154,1,7,233.7,234.06,1200,200,1,1,233.66,234.13,1,427,1,2,233.58,234.17,505,1,2,1,233.53,234.41,10,600,1,2,233.5,234.43,100,105,1,2,233.45,234.5,15,63,1,4,233.4,234.75,110,1,2,1,233.39,234.79,10,2000,1,1,AAPL,0.0,0.0,0.0,
2024-10-21 12:12:02.316648939+00:00,2024-10-21T12:12:02.316815369Z,10,2,38,A,B,1,233.82,200,130,166430,12316513,233.9,233.97,10,20,1,1,233.82,234.0,200,154,1,7,233.77,234.06,28,200,1,1,233.7,234.13,1200,427,1,2,233.66,234.17,1,1,1,1,233.58,234.41,505,600,2,2,233.53,234.43,10,105,1,2,233.5,234.5,100,63,1,4,233.45,234.75,15,1,1,1,233.4,234.79,110,2000,2,1,AAPL,0.0,0.0,0.0,
2024-10-21 12:12:08.967185824+00:00,2024-10-21T12:12:08.967352049Z,10,2,38,C,A,0,233.97,20,130,166225,12322349,233.9,234.0,10,154,1,7,233.82,234.06,200,200,1,1,233.77,234.13,28,427,1,2,233.7,234.17,1200,1,1,1,233.66,234.41,1,600,1,2,233.58,234.43,505,105,2,2,233.53,234.5,10,63,1,4,233.5,234.75,100,1,1,1,233.45,234.79,15,2000,1,1,233.4,234.89,110,2,2,2,AAPL,0.0,0.0,0.0,
2024-10-21 12:12:08.996704242+00:00,2024-10-21T12:12:08.996872145Z,10,2,38,T,N,0,233.96,4,130,167903,12322367,233.9,234.0,10,154,1,7,233.82,234.06,200,200,1,1,233.77,234.13,28,427,1,2,233.7,234.17,1200,1,1,1,233.66,234.41,1,600,1,2,233.58,234.43,505,105,2,2,233.53,234.5,10,63,1,4,233.5,234.75,100,1,1,1,233.45,234.79,15,2000,1,1,233.4,234.89,110,2,2,2,AAPL,0.0,0.0,0.0,
2024-10-21 12:12:08.996733815+00:00,2024-10-21T12:12:08.996899848Z,10,2,38,C,B,1,233.82,200,130,166033,12322368,233.9,234.0,10,154,1,7,233.77,234.06,28,200,1,1,233.7,234.13,1200,427,1,2,233.66,234.17,1,1,1,1,233.58,234.41,505,600,2,2,233.53,234.43,10,105,1,2,233.5,234.5,100,63,1,4,233.45,234.75,15,1,1,1,233.4,234.79,110,2000,2,1,233.39,234.89,10,2,1,2,AAPL,0.0,0.0,0.0,
2024-10-21 12:12:09.099739392+00:00,2024-10-21T12:12:09.099905611Z,10,2,38,A,B,1,233.82,200,130,166219,12322505,233.9,234.0,10,154,1,7,233.82,234.06,200,200,1,1,233.77,234.13,28,427,1,2,233.7,234.17,1200,1,1,1,233.66,234.41,1,600,1,2,233.58,234.43,505,105,2,2,233.53,234.5,10,63,1,4,233.5,234.75,100,1,1,1,233.45,234.79,15,2000,1,1,233.4,234.89,110,2,2,2,AAPL,0.0,0.0,0.0,
2024-10-21 12:12:10.232691130+00:00,2024-10-21T12:12:10.232857553Z,10,2,38,A,B,1,233.83,200,130,166423,12324515,233.9,234.0,10,154,1,7,233.83,234.06,200,200,1,1,233.77,234.13,28,427,1,2,233.7,234.17,1200,1,1,1,233.66,234.41,1,600,1,2,233.58,234.43,505,105,2,2,233.53,234.5,10,63,1,4,233.5,234.75,100,1,1,1,233.45,234.79,15,2000,1,1,233.4,234.89,110,2,2,2,AAPL,0.0,0.0,0.0,
2024-10-21 12:12:22.882127538+00:00,2024-10-21T12:12:22.882293776Z,10,2,38,C,B,1,233.83,200,130,166238,12335502,233.9,234.0,10,154,1,7,233.77,234.06,28,200,1,1,233.7,234.13,1200,427,1,2,233.66,234.17,1,1,1,1,233.58,234.41,505,600,2,2,233.53,234.43,10,105,1,2,233.5,234.5,100,63,1,4,233.45,234.75,15,1,1,1,233.4,234.79,110,2000,2,1,233.39,234.89,10,2,1,2,AAPL,0.0,0.0,0.0,
2024-10-21 12:12:22.882140909+00:00,2024-10-21T12:12:22.882306926Z,10,2,38,A,B,1,233.78,400,130,166017,12335503,233.9,234.0,10,154,1,7,233.78,234.06,400,200,1,1,233.77,234.13,28,427,1,2,233.7,234.17,1200,1,1,1,233.66,234.41,1,600,1,2,233.58,234.43,505,105,2,2,233.53,234.5,10,63,1,4,233.5,234.75,100,1,1,1,233.45,234.79,15,2000,1,1,233.4,234.89,110,2,2,2,AAPL,0.0,0.0,0.0,
2024-10-21 12:12:25.936845190+00:00,2024-10-21T12:12:25.937011711Z,10,2,38,A,B,1,233.82,200,130,166521,12338576,233.9,234.0,10,154,1,7,233.82,234.06,200,200,1,1,233.77,234.13,28,427,1,2,233.7,234.17,1200,1,1,1,233.66,234.41,1,600,1,2,233.58,234.43,505,105,2,2,233.53,234.5,10,63,1,4,233.5,234.75,100,1,1,1,233.45,234.79,15,2000,1,1,233.4,234.89,110,2,2,2,AAPL,0.0,0.0,0.0,
2024-10-21 12:12:28.133772380+00:00,2024-10-21T12:12:28.133938919Z,10,2,38,A,B,1,233.83,200,130,166539,12339995,233.9,234.0,10,154,1,7,233.83,234.06,200,200,1,1,233.77,234.13,28,427,1,2,233.7,234.17,1200,1,1,1,233.66,234.41,1,600,1,2,233.58,234.43,505,105,2,2,233.53,234.5,10,63,1,4,233.5,234.75,100,1,1,1,233.45,234.79,15,2000,1,1,233.4,234.89,110,2,2,2,AAPL,0.0,0.0,0.0,
2024-10-21 12:12:28.677449361+00:00,2024-10-21T12:12:28.677615324Z,10,2,38,C,B,1,233.83,200,130,165963,12340411,233.9,234.0,10,154,1,7,233.77,234.06,28,200,1,1,233.7,234.13,1200,427,1,2,233.66,234.17,1,1,1,1,233.58,234.41,505,600,2,2,233.53,234.43,10,105,1,2,233.5,234.5,100,63,1,4,233.45,234.75,15,1,1,1,233.4,234.79,110,2000,2,1,233.39,234.89,10,2,1,2,AAPL,0.0,0.0,0.0,
2024-10-21 12:12:28.677461375+00:00,2024-10-21T12:12:28.677627803Z,10,2,38,A,B,1,233.78,400,130,166428,12340412,233.9,234.0,10,154,1,7,233.78,234.06,400,200,1,1,233.77,234.13,28,427,1,2,233.7,234.17,1200,1,1,1,233.66,234.41,1,600,1,2,233.58,234.43,505,105,2,2,233.53,234.5,10,63,1,4,233.5,234.75,100,1,1,1,233.45,234.79,15,2000,1,1,233.4,234.89,110,2,2,2,AAPL,0.0,0.0,0.0,
2024-10-21 12:12:31.318823338+00:00,2024-10-21T12:12:31.318989443Z,10,2,38,C,A,1,234.06,200,130,166105,12341951,233.9,234.0,10,154,1,7,233.78,234.13,400,427,1,2,233.77,234.17,28,1,1,1,233.7,234.41,1200,600,1,2,233.66,234.43,1,105,1,2,233.58,234.5,505,63,2,4,233.53,234.75,10,1,1,1,233.5,234.79,100,2000,1,1,233.45,234.89,15,2,1,2,233.4,235.0,110,213,2,6,AAPL,0.0,0.0,0.0,
2024-10-21 12:12:31.397839079+00:00,2024-10-21T12:12:31.398006757Z,10,2,38,T,N,0,233.98,50,130,167678,12342316,233.9,234.0,10,154,1,7,233.78,234.13,400,427,1,2,233.77,234.17,28,1,1,1,233.7,234.41,1200,600,1,2,233.66,234.43,1,105,1,2,233.58,234.5,505,63,2,4,233.53,234.75,10,1,1,1,233.5,234.79,100,2000,1,1,233.45,234.89,15,2,1,2,233.4,235.0,110,213,2,6,AAPL,0.0,0.0,0.0,
2024-10-21 12:12:31.425804077+00:00,2024-10-21T12:12:31.425970357Z,10,2,38,A,A,1,234.07,200,130,166280,12342547,233.9,234.0,10,154,1,7,233.78,234.07,400,200,1,1,233.77,234.13,28,427,1,2,233.7,234.17,1200,1,1,1,233.66,234.41,1,600,1,2,233.58,234.43,505,105,2,2,233.53,234.5,10,63,1,4,233.5,234.75,100,1,1,1,233.45,234.79,15,2000,1,1,233.4,234.89,110,2,2,2,AAPL,0.0,0.0,0.0,
2024-10-21 12:12:31.453857757+00:00,2024-10-21T12:12:31.454024371Z,10,2,38,A,B,1,233.79,400,130,166614,12342589,233.9,234.0,10,154,1,7,233.79,234.07,400,200,1,1,233.77,234.13,28,427,1,2,233.7,234.17,1200,1,1,1,233.66,234.41,1,600,1,2,233.58,234.43,505,105,2,2,233.53,234.5,10,63,1,4,233.5,234.75,100,1,1,1,233.45,234.79,15,2000,1,1,233.4,234.89,110,2,2,2,AAPL,0.0,0.0,0.0,
2024-10-21 12:12:31.678952187+00:00,2024-10-21T12:12:31.679118349Z,10,2,38,C,B,2,233.77,28,130,166162,12343225,233.9,234.0,10,154,1,7,233.79,234.07,400,200,1,1,233.7,234.13,1200,427,1,2,233.66,234.17,1,1,1,1,233.58,234.41,505,600,2,2,233.53,234.43,10,105,1,2,233.5,234.5,100,63,1,4,233.45,234.75,15,1,1,1,233.4,234.79,110,2000,2,1,233.39,234.89,10,2,1,2,AAPL,0.0,0.0,0.0,
2024-10-21 12:12:31.679008317+00:00,2024-10-21T12:12:31.679174617Z,10,2,38,A,B,1,233.82,30,130,166300,12343226,233.9,234.0,10,154,1,7,233.82,234.07,30,200,1,1,233.79,234.13,400,427,1,2,233.7,234.17,1200,1,1,1,233.66,234.41,1,600,1,2,233.58,234.43,505,105,2,2,233.53,234.5,10,63,1,4,233.5,234.75,100,1,1,1,233.45,234.79,15,2000,1,1,233.4,234.89,110,2,2,2,AAPL,0.0,0.0,0.0,
2024-10-21 12:12:31.733377635+00:00,2024-10-21T12:12:31.733543975Z,10,2,38,A,B,1,233.87,200,130,166340,12343455,233.9,234.0,10,154,1,7,233.87,234.07,200,200,1,1,233.82,234.13,30,427,1,2,233.7,234.17,1200,1,1,1,233.66,234.41,1,600,1,2,233.58,234.43,505,105,2,2,233.53,234.5,10,63,1,4,233.5,234.75,100,1,1,1,233.45,234.79,15,2000,1,1,233.4,234.89,110,2,2,2,AAPL,0.0,0.0,0.0,
2024-10-21 12:12:41.238712131+00:00,2024-10-21T12:12:41.238878627Z,10,2,38,A,A,1,234.06,200,130,166496,12350539,233.9,234.0,10,154,1,7,233.87,234.06,200,200,1,1,233.82,234.13,30,427,1,2,233.7,234.17,1200,1,1,1,233.66,234.41,1,600,1,2,233.58,234.43,505,105,2,2,233.53,234.5,10,63,1,4,233.5,234.75,100,1,1,1,233.45,234.79,15,2000,1,1,233.4,234.89,110,2,2,2,AAPL,0.0,0.0,0.0,
2024-10-21 12:12:43.651347870+00:00,2024-10-21T12:12:43.651514581Z,10,2,38,C,B,1,233.87,200,130,166711,12352115,233.9,234.0,10,154,1,7,233.82,234.06,30,200,1,1,233.7,234.13,1200,427,1,2,233.66,234.17,1,1,1,1,233.58,234.41,505,600,2,2,233.53,234.43,10,105,1,2,233.5,234.5,100,63,1,4,233.45,234.75,15,1,1,1,233.4,234.79,110,2000,2,1,233.39,234.89,10,2,1,2,AAPL,0.0,0.0,0.0,
2024-10-21 12:12:43.731132036+00:00,2024-10-21T12:12:43.731298274Z,10,2,38,A,B,2,233.78,400,130,166238,12352210,233.9,234.0,10,154,1,7,233.82,234.06,30,200,1,1,233.78,234.13,400,427,1,2,233.7,234.17,1200,1,1,1,233.66,234.41,1,600,1,2,233.58,234.43,505,105,2,2,233.53,234.5,10,63,1,4,233.5,234.75,100,1,1,1,233.45,234.79,15,2000,1,1,233.4,234.89,110,2,2,2,AAPL,0.0,0.0,0.0,
2024-10-21 12:12:43.731655758+00:00,2024-10-21T12:12:43.731821725Z,10,2,38,C,B,1,233.82,30,130,165967,12352211,233.9,234.0,10,154,1,7,233.78,234.06,400,200,1,1,233.7,234.13,1200,427,1,2,233.66,234.17,1,1,1,1,233.58,234.41,505,600,2,2,233.53,234.43,10,105,1,2,233.5,234.5,100,63,1,4,233.45,234.75,15,1,1,1,233.4,234.79,110,2000,2,1,233.39,234.89,10,2,1,2,AAPL,0.0,0.0,0.0,
2024-10-21 12:12:43.731785539+00:00,2024-10-21T12:12:43.731951886Z,10,2,38,A,B,2,233.76,29,130,166347,12352212,233.9,234.0,10,154,1,7,233.78,234.06,400,200,1,1,233.76,234.13,29,427,1,2,233.7,234.17,1200,1,1,1,233.66,234.41,1,600,1,2,233.58,234.43,505,105,2,2,233.53,234.5,10,63,1,4,233.5,234.75,100,1,1,1,233.45,234.79,15,2000,1,1,233.4,234.89,110,2,2,2,AAPL,0.0,0.0,0.0,
2024-10-21 12:12:46.780372537+00:00,2024-10-21T12:12:46.780539855Z,10,2,38,A,B,1,233.82,200,128,167318,12353700,233.9,234.0,10,154,1,7,233.82,234.06,200,200,1,1,233.76,234.13,29,427,1,2,233.7,234.17,1200,1,1,1,233.66,234.41,1,600,1,2,233.58,234.43,505,105,2,2,233.53,234.5,10,63,1,4,233.5,234.75,100,1,1,1,233.45,234.79,15,2000,1,1,233.4,234.89,110,2,2,2,AAPL,0.0,0.0,0.0,
2024-10-21 12:12:47.484476304+00:00,2024-10-21T12:12:47.484642192Z,10,2,38,C,B,1,233.82,200,130,165888,12353973,233.9,234.0,10,154,1,7,233.76,234.06,29,200,1,1,233.7,234.13,1200,427,1,2,233.66,234.17,1,1,1,1,233.58,234.41,505,600,2,2,233.53,234.43,10,105,1,2,233.5,234.5,100,63,1,4,233.45,234.75,15,1,1,1,233.4,234.79,110,2000,2,1,233.39,234.89,10,2,1,2,AAPL,0.0,0.0,0.0,
2024-10-21 12:12:47.484693420+00:00,2024-10-21T12:12:47.484860069Z,10,2,38,A,A,0,233.99,100,130,166649,12353975,233.9,233.99,10,100,1,1,233.76,234.0,29,154,1,7,233.7,234.06,1200,200,1,1,233.66,234.13,1,427,1,2,233.58,234.17,505,1,2,1,233.53,234.41,10,600,1,2,233.5,234.43,100,105,1,2,233.45,234.5,15,63,1,4,233.4,234.75,110,1,2,1,233.39,234.79,10,2000,1,1,AAPL,0.0,0.0,0.0,
2024-10-21 12:12:47.485023375+00:00,2024-10-21T12:12:47.485189477Z,10,2,38,C,A,0,233.99,100,130,166102,12353978,233.9,234.0,10,154,1,7,233.76,234.06,29,200,1,1,233.7,234.13,1200,427,1,2,233.66,234.17,1,1,1,1,233.58,234.41,505,600,2,2,233.53,234.43,10,105,1,2,233.5,234.5,100,63,1,4,233.45,234.75,15,1,1,1,233.4,234.79,110,2000,2,1,233.39,234.89,10,2,1,2,AAPL,0.0,0.0,0.0,
2024-10-21 12:12:47.604468075+00:00,2024-10-21T12:12:47.604634522Z,10,2,38,A,B,1,233.78,400,130,166447,12354240,233.9,234.0,10,154,1,7,233.78,234.06,400,200,1,1,233.76,234.13,29,427,1,2,233.7,234.17,1200,1,1,1,233.66,234.41,1,600,1,2,233.58,234.43,505,105,2,2,233.53,234.5,10,63,1,4,233.5,234.75,100,1,1,1,233.45,234.79,15,2000,1,1,233.4,234.89,110,2,2,2,AAPL,0.0,0.0,0.0,
2024-10-21 12:12:47.736191420+00:00,2024-10-21T12:12:47.736357741Z,10,2,38,A,A,1,234.06,200,130,166321,12354295,233.9,234.0,10,154,1,7,233.78,234.06,400,400,1,2,233.76,234.13,29,427,1,2,233.7,234.17,1200,1,1,1,233.66,234.41,1,600,1,2,233.58,234.43,505,105,2,2,233.53,234.5,10,63,1,4,233.5,234.75,100,1,1,1,233.45,234.79,15,2000,1,1,233.4,234.89,110,2,2,2,AAPL,0.0,-200.0,0.0,
2024-10-21 12:12:48.104146428+00:00,2024-10-21T12:12:48.104314520Z,10,2,38,T,A,0,233.9,10,130,168092,12354546,233.9,234.0,10,154,1,7,233.78,234.06,400,400,1,2,233.76,234.13,29,427,1,2,233.7,234.17,1200,1,1,1,233.66,234.41,1,600,1,2,233.58,234.43,505,105,2,2,233.53,234.5,10,63,1,4,233.5,234.75,100,1,1,1,233.45,234.79,15,2000,1,1,233.4,234.89,110,2,2,2,AAPL,0.0,0.0,0.0,
2024-10-21 12:12:48.104146428+00:00,2024-10-21T12:12:48.104314520Z,10,2,38,C,B,0,233.9,10,130,168092,12354546,233.78,234.0,400,154,1,7,233.76,234.06,29,400,1,2,233.7,234.13,1200,427,1,2,233.66,234.17,1,1,1,1,233.58,234.41,505,600,2,2,233.53,234.43,10,105,1,2,233.5,234.5,100,63,1,4,233.45,234.75,15,1,1,1,233.4,234.79,110,2000,2,1,233.39,234.89,10,2,1,2,AAPL,0.0,0.0,0.0,
2024-10-21 12:12:48.104167967+00:00,2024-10-21T12:12:48.104334124Z,10,2,38,A,A,0,233.98,100,130,166157,12354547,233.78,233.98,400,100,1,1,233.76,234.0,29,154,1,7,233.7,234.06,1200,400,1,2,233.66,234.13,1,427,1,2,233.58,234.17,505,1,2,1,233.53,234.41,10,600,1,2,233.5,234.43,100,105,1,2,233.45,234.5,15,63,1,4,233.4,234.75,110,1,2,1,233.39,234.79,10,2000,1,1,AAPL,0.0,0.0,0.0,
2024-10-21 12:12:48.104178898+00:00,2024-10-21T12:12:48.104345015Z,10,2,38,C,B,0,233.78,400,130,166117,12354548,233.76,233.98,29,100,1,1,233.7,234.0,1200,154,1,7,233.66,234.06,1,400,1,2,233.58,234.13,505,427,2,2,233.53,234.17,10,1,1,1,233.5,234.41,100,600,1,2,233.45,234.43,15,105,1,2,233.4,234.5,110,63,2,4,233.39,234.75,10,1,1,1,233.31,234.79,110,2000,2,1,AAPL,0.0,0.0,0.0,
2024-10-21 12:12:48.104181225+00:00,2024-10-21T12:12:48.104347234Z,10,2,38,A,A,0,233.98,100,130,166009,12354549,233.76,233.98,29,200,1,2,233.7,234.0,1200,154,1,7,233.66,234.06,1,400,1,2,233.58,234.13,505,427,2,2,233.53,234.17,10,1,1,1,233.5,234.41,100,600,1,2,233.45,234.43,15,105,1,2,233.4,234.5,110,63,2,4,233.39,234.75,10,1,1,1,233.31,234.79,110,2000,2,1,AAPL,-100.0,-100.0,-100.0,
2024-10-21 12:12:48.104185923+00:00,2024-10-21T12:12:48.104351926Z,10,2,38,C,A,0,233.98,100,130,166003,12354550,233.76,233.98,29,100,1,1,233.7,234.0,1200,154,1,7,233.66,234.06,1,400,1,2,233.58,234.13,505,427,2,2,233.53,234.17,10,1,1,1,233.5,234.41,100,600,1,2,233.45,234.43,15,105,1,2,233.4,234.5,110,63,2,4,233.39,234.75,10,1,1,1,233.31,234.79,110,2000,2,1,AAPL,100.0,100.0,0.0,
2024-10-21 12:12:48.104190565+00:00,2024-10-21T12:12:48.104356853Z,10,2,38,A,A,0,233.95,14,130,166288,12354552,233.76,233.95,29,14,1,1,233.7,233.98,1200,100,1,1,233.66,234.0,1,154,1,7,233.58,234.06,505,400,2,2,233.53,234.13,10,427,1,2,233.5,234.17,100,1,1,1,233.45,234.41,15,600,1,2,233.4,234.43,110,105,2,2,233.39,234.5,10,63,1,4,233.31,234.75,110,1,2,1,AAPL,0.0,0.0,0.0,
2024-10-21 12:12:48.104196514+00:00,2024-10-21T12:12:48.104362882Z,10,2,38,A,A,0,233.95,16,130,166368,12354553,233.76,233.95,29,30,1,2,233.7,233.98,1200,100,1,1,233.66,234.0,1,154,1,7,233.58,234.06,505,400,2,2,233.53,234.13,10,427,1,2,233.5,234.17,100,1,1,1,233.45,234.41,15,600,1,2,233.4,234.43,110,105,2,2,233.39,234.5,10,63,1,4,233.31,234.75,110,1,2,1,AAPL,-16.0,-16.0,-16.0,
2024-10-21 12:12:48.104209602+00:00,2024-10-21T12:12:48.104375784Z,10,2,38,A,A,1,233.98,16,130,166182,12354554,233.76,233.95,29,30,1,2,233.7,233.98,1200,116,1,2,233.66,234.0,1,154,1,7,233.58,234.06,505,400,2,2,233.53,234.13,10,427,1,2,233.5,234.17,100,1,1,1,233.45,234.41,15,600,1,2,233.4,234.43,110,105,2,2,233.39,234.5,10,63,1,4,233.31,234.75,110,1,2,1,AAPL,0.0,-16.0,-16.0,
2024-10-21 12:12:48.104217612+00:00,2024-10-21T12:12:48.104385015Z,10,2,38,C,A,1,233.98,100,130,167403,12354555,233.76,233.95,29,30,1,2,233.7,233.98,1200,16,1,1,233.66,234.0,1,154,1,7,233.58,234.06,505,400,2,2,233.53,234.13,10,427,1,2,233.5,234.17,100,1,1,1,233.45,234.41,15,600,1,2,233.4,234.43,110,105,2,2,233.39,234.5,10,63,1,4,233.31,234.75,110,1,2,1,AAPL,0.0,100.0,-16.0,
2024-10-21 12:12:48.176175311+00:00,2024-10-21T12:12:48.176341448Z,10,2,38,A,B,1,233.71,27,130,166137,12354620,233.76,233.95,29,30,1,2,233.71,233.98,27,16,1,1,233.7,234.0,1200,154,1,7,233.66,234.06,1,400,1,2,233.58,234.13,505,427,2,2,233.53,234.17,10,1,1,1,233.5,234.41,100,600,1,2,233.45,234.43,15,105,1,2,233.4,234.5,110,63,2,4,233.39,234.75,10,1,1,1,AAPL,0.0,0.0,-16.0,
2024-10-21 12:12:48.176204532+00:00,2024-10-21T12:12:48.176370376Z,10,2,38,C,B,0,233.76,29,130,165844,12354621,233.71,233.95,27,30,1,2,233.7,233.98,1200,16,1,1,233.66,234.0,1,154,1,7,233.58,234.06,505,400,2,2,233.53,234.13,10,427,1,2,233.5,234.17,100,1,1,1,233.45,234.41,15,600,1,2,233.4,234.43,110,105,2,2,233.39,234.5,10,63,1,4,233.31,234.75,110,1,2,1,AAPL,0.0,0.0,-16.0,
2024-10-21 12:12:48.176852661+00:00,2024-10-21T12:12:48.177018480Z,10,2,38,C,B,0,233.71,27,130,165819,12354624,233.7,233.95,1200,30,1,2,233.66,233.98,1,16,1,1,233.58,234.0,505,154,2,7,233.53,234.06,10,400,1,2,233.5,234.13,100,427,1,2,233.45,234.17,15,1,1,1,233.4,234.41,110,600,2,2,233.39,234.43,10,105,1,2,233.31,234.5,110,63,2,4,233.3,234.75,100,1,1,1,AAPL,0.0,0.0,-16.0,
2024-10-21 12:12:48.179929431+00:00,2024-10-21T12:12:48.180095554Z,10,2,38,A,A,4,234.08,29,130,166123,12354625,233.7,233.95,1200,30,1,2,233.66,233.98,1,16,1,1,233.58,234.0,505,154,2,7,233.53,234.06,10,400,1,2,233.5,234.08,100,29,1,1,233.45,234.13,15,427,1,2,233.4,234.17,110,1,2,1,233.39,234.41,10,600,1,2,233.31,234.43,110,105,2,2,233.3,234.5,100,63,1,4,AAPL,0.0,0.0,-16.0,
2024-10-21 12:12:48.179967058+00:00,2024-10-21T12:12:48.180133214Z,10,2,38,C,A,5,234.13,27,130,166156,12354626,233.7,233.95,1200,30,1,2,233.66,233.98,1,16,1,1,233.58,234.0,505,154,2,7,233.53,234.06,10,400,1,2,233.5,234.08,100,29,1,1,233.45,234.13,15,400,1,1,233.4,234.17,110,1,2,1,233.39,234.41,10,600,1,2,233.31,234.43,110,105,2,2,233.3,234.5,100,63,1,4,AAPL,0.0,0.0,-16.0,
2024-10-21 12:12:48.204254179+00:00,2024-10-21T12:12:48.204420400Z,10,2,38,C,A,0,233.95,14,130,166221,12354640,233.7,233.95,1200,16,1,1,233.66,233.98,1,16,1,1,233.58,234.0,505,154,2,7,233.53,234.06,10,400,1,2,233.5,234.08,100,29,1,1,233.45,234.13,15,400,1,1,233.4,234.17,110,1,2,1,233.39,234.41,10,600,1,2,233.31,234.43,110,105,2,2,233.3,234.5,100,63,1,4,AAPL,14.0,14.0,-2.0,
2024-10-21 12:12:48.204281167+00:00,2024-10-21T12:12:48.204447035Z,10,2,38,C,A,1,233.98,16,130,165868,12354641,233.7,233.95,1200,16,1,1,233.66,234.0,1,154,1,7,233.58,234.06,505,400,2,2,233.53,234.08,10,29,1,1,233.5,234.13,100,400,1,1,233.45,234.17,15,1,1,1,233.4,234.41,110,600,2,2,233.39,234.43,10,105,1,2,233.31,234.5,110,63,2,4,233.3,234.75,100,1,1,1,AAPL,0.0,0.0,-2.0,
2024-10-21 12:12:48.213961498+00:00,2024-10-21T12:12:48.214127843Z,10,2,38,A,B,1,233.67,400,130,166345,12354647,233.7,233.95,1200,16,1,1,233.67,234.0,400,154,1,7,233.66,234.06,1,400,1,2,233.58,234.08,505,29,2,1,233.53,234.13,10,400,1,1,233.5,234.17,100,1,1,1,233.45,234.41,15,600,1,2,233.4,234.43,110,105,2,2,233.39,234.5,10,63,1,4,233.31,234.75,110,1,2,1,AAPL,0.0,0.0,-2.0,
2024-10-21 12:12:48.232970230+00:00,2024-10-21T12:12:48.233136592Z,10,2,38,C,A,2,234.06,200,130,166362,12354661,233.7,233.95,1200,16,1,1,233.67,234.0,400,154,1,7,233.66,234.06,1,200,1,1,233.58,234.08,505,29,2,1,233.53,234.13,10,400,1,1,233.5,234.17,100,1,1,1,233.45,234.41,15,600,1,2,233.4,234.43,110,105,2,2,233.39,234.5,10,63,1,4,233.31,234.75,110,1,2,1,AAPL,0.0,200.0,-2.0,
2024-10-21 12:12:48.232983049+00:00,2024-10-21T12:12:48.233149556Z,10,2,38,A,A,2,234.01,200,130,166507,12354662,233.7,233.95,1200,16,1,1,233.67,234.0,400,154,1,7,233.66,234.01,1,200,1,1,233.58,234.08,505,29,2,1,233.53,234.13,10,400,1,1,233.5,234.17,100,1,1,1,233.45,234.41,15,600,1,2,233.4,234.43,110,105,2,2,233.39,234.5,10,63,1,4,233.31,234.75,110,1,2,1,AAPL,0.0,0.0,-2.0,
2024-10-21 12:12:48.247336117+00:00,2024-10-21T12:12:48.247502164Z,10,2,38,C,B,1,233.67,400,130,166047,12354665,233.7,233.95,1200,16,1,1,233.66,234.0,1,154,1,7,233.58,234.01,505,200,2,1,233.53,234.08,10,29,1,1,233.5,234.13,100,400,1,1,233.45,234.17,15,1,1,1,233.4,234.41,110,600,2,2,233.39,234.43,10,105,1,2,233.31,234.5,110,63,2,4,233.3,234.75,100,1,1,1,AAPL,0.0,0.0,-2.0,
2024-10-21 12:12:48.247348435+00:00,2024-10-21T12:12:48.247514656Z,10,2,38,A,B,2,233.62,400,130,166221,12354666,233.7,233.95,1200,16,1,1,233.66,234.0,1,154,1,7,233.62,234.01,400,200,1,1,233.58,234.08,505,29,2,1,233.53,234.13,10,400,1,1,233.5,234.17,100,1,1,1,233.45,234.41,15,600,1,2,233.4,234.43,110,105,2,2,233.39,234.5,10,63,1,4,233.31,234.75,110,1,2,1,AAPL,0.0,0.0,-2.0,
2024-10-21 12:12:48.306851049+00:00,2024-10-21T12:12:48.307017573Z,10,2,38,A,B,0,233.72,400,130,166524,12354670,233.72,233.95,400,16,1,1,233.7,234.0,1200,154,1,7,233.66,234.01,1,200,1,1,233.58,234.08,505,29,2,1,233.53,234.13,10,400,1,1,233.5,234.17,100,1,1,1,233.45,234.41,15,600,1,2,233.4,234.43,110,105,2,2,233.39,234.5,10,63,1,4,233.31,234.75,110,1,2,1,AAPL,0.0,0.0,-2.0,
2024-10-21 12:12:48.347879918+00:00,2024-10-21T12:12:48.348045881Z,10,2,38,C,A,2,234.01,200,130,165963,12354690,233.72,233.95,400,16,1,1,233.7,234.0,1200,154,1,7,233.66,234.08,1,29,1,1,233.58,234.13,505,400,2,1,233.53,234.17,10,1,1,1,233.5,234.41,100,600,1,2,233.45,234.43,15,105,1,2,233.4,234.5,110,63,2,4,233.39,234.75,10,1,1,1,233.31,234.79,110,2000,2,1,AAPL,0.0,0.0,-2.0,
2024-10-21 12:12:48.347893041+00:00,2024-10-21T12:12:48.348059124Z,10,2,38,A,A,2,234.06,400,130,166083,12354691,233.72,233.95,400,16,1,1,233.7,234.0,1200,154,1,7,233.66,234.06,1,400,1,1,233.58,234.08,505,29,2,1,233.53,234.13,10,400,1,1,233.5,234.17,100,1,1,1,233.45,234.41,15,600,1,2,233.4,234.43,110,105,2,2,233.39,234.5,10,63,1,4,233.31,234.75,110,1,2,1,AAPL,0.0,0.0,-2.0,
2024-10-21 12:12:48.363762750+00:00,2024-10-21T12:12:48.363929061Z,10,2,38,C,A,0,233.95,16,130,166311,12354719,233.72,234.0,400,154,1,7,233.7,234.06,1200,400,1,1,233.66,234.08,1,29,1,1,233.58,234.13,505,400,2,1,233.53,234.17,10,1,1,1,233.5,234.41,100,600,1,2,233.45,234.43,15,105,1,2,233.4,234.5,110,63,2,4,233.39,234.75,10,1,1,1,233.31,234.79,110,2000,2,1,AAPL,0.0,0.0,-2.0,
2024-10-21 12:12:49.107274312+00:00,2024-10-21T12:12:49.107440196Z,10,2,38,C,B,0,233.72,400,130,165884,12355060,233.7,234.0,1200,154,1,7,233.66,234.06,1,400,1,1,233.58,234.08,505,29,2,1,233.53,234.13,10,400,1,1,233.5,234.17,100,1,1,1,233.45,234.41,15,600,1,2,233.4,234.43,110,105,2,2,233.39,234.5,10,63,1,4,233.31,234.75,110,1,2,1,233.3,234.79,100,2000,1,1,AAPL,0.0,0.0,14.0,
2024-10-21 12:12:49.117556478+00:00,2024-10-21T12:12:49.117722704Z,10,2,38,A,B,0,233.72,200,130,166226,12355064,233.72,234.0,200,154,1,7,233.7,234.06,1200,400,1,1,233.66,234.08,1,29,1,1,233.58,234.13,505,400,2,1,233.53,234.17,10,1,1,1,233.5,234.41,100,600,1,2,233.45,234.43,15,105,1,2,233.4,234.5,110,63,2,4,233.39,234.75,10,1,1,1,233.31,234.79,110,2000,2,1,AAPL,0.0,0.0,14.0,
2024-10-21 12:12:49.170094147+00:00,2024-10-21T12:12:49.170261083Z,10,2,38,A,B,3,233.65,28,130,166936,12355076,233.72,234.0,200,154,1,7,233.7,234.06,1200,400,1,1,233.66,234.08,1,29,1,1,233.65,234.13,28,400,1,1,233.58,234.17,505,1,2,1,233.53,234.41,10,600,1,2,233.5,234.43,100,105,1,2,233.45,234.5,15,63,1,4,233.4,234.75,110,1,2,1,233.39,234.79,10,2000,1,1,AAPL,0.0,0.0,14.0,
2024-10-21 12:12:49.179568062+00:00,2024-10-21T12:12:49.179734911Z,10,2,38,A,B,0,233.72,200,130,166849,12355080,233.72,234.0,400,154,2,7,233.7,234.06,1200,400,1,1,233.66,234.08,1,29,1,1,233.65,234.13,28,400,1,1,233.58,234.17,505,1,2,1,233.53,234.41,10,600,1,2,233.5,234.43,100,105,1,2,233.45,234.5,15,63,1,4,233.4,234.75,110,1,2,1,233.39,234.79,10,2000,1,1,AAPL,200.0,200.0,214.0,
2024-10-21 12:12:50.108656247+00:00,2024-10-21T12:12:50.108822491Z,10,2,38,C,B,0,233.72,200,130,166244,12355613,233.72,234.0,200,154,1,7,233.7,234.06,1200,400,1,1,233.66,234.08,1,29,1,1,233.65,234.13,28,400,1,1,233.58,234.17,505,1,2,1,233.53,234.41,10,600,1,2,233.5,234.43,100,105,1,2,233.45,234.5,15,63,1,4,233.4,234.75,110,1,2,1,233.39,234.79,10,2000,1,1,AAPL,-200.0,-200.0,0.0,
2024-10-21 12:12:50.108666090+00:00,2024-10-21T12:12:50.108831892Z,10,2,38,C,B,0,233.72,200,130,165802,12355614,233.7,234.0,1200,154,1,7,233.66,234.06,1,400,1,1,233.65,234.08,28,29,1,1,233.58,234.13,505,400,2,1,233.53,234.17,10,1,1,1,233.5,234.41,100,600,1,2,233.45,234.43,15,105,1,2,233.4,234.5,110,63,2,4,233.39,234.75,10,1,1,1,233.31,234.79,110,2000,2,1,AAPL,0.0,0.0,0.0,
2024-10-21 12:12:50.212175433+00:00,2024-10-21T12:12:50.212341929Z,10,2,38,A,B,0,233.72,400,130,166496,12355646,233.72,234.0,400,154,1,7,233.7,234.06,1200,400,1,1,233.66,234.08,1,29,1,1,233.65,234.13,28,400,1,1,233.58,234.17,505,1,2,1,233.53,234.41,10,600,1,2,233.5,234.43,100,105,1,2,233.45,234.5,15,63,1,4,233.4,234.75,110,1,2,1,233.39,234.79,10,2000,1,1,AAPL,0.0,0.0,-200.0,
2024-10-21 12:12:50.565304171+00:00,2024-10-21T12:12:50.565470381Z,10,2,38,C,B,3,233.65,28,130,166210,12355988,233.72,234.0,400,154,1,7,233.7,234.06,1200,400,1,1,233.66,234.08,1,29,1,1,233.58,234.13,505,400,2,1,233.53,234.17,10,1,1,1,233.5,234.41,100,600,1,2,233.45,234.43,15,105,1,2,233.4,234.5,110,63,2,4,233.39,234.75,10,1,1,1,233.31,234.79,110,2000,2,1,AAPL,0.0,0.0,-200.0,
2024-10-21 12:12:50.565427767+00:00,2024-10-21T12:12:50.565594035Z,10,2,38,A,B,1,233.71,26,130,166268,12355989,233.72,234.0,400,154,1,7,233.71,234.06,26,400,1,1,233.7,234.08,1200,29,1,1,233.66,234.13,1,400,1,1,233.58,234.17,505,1,2,1,233.53,234.41,10,600,1,2,233.5,234.43,100,105,1,2,233.45,234.5,15,63,1,4,233.4,234.75,110,1,2,1,233.39,234.79,10,2000,1,1,AAPL,0.0,0.0,-200.0,
2024-10-21 12:12:50.565500981+00:00,2024-10-21T12:12:50.565667034Z,10,2,38,C,A,2,234.08,29,130,166053,12355990,233.72,234.0,400,154,1,7,233.71,234.06,26,400,1,1,233.7,234.13,1200,400,1,1,233.66,234.17,1,1,1,1,233.58,234.41,505,600,2,2,233.53,234.43,10,105,1,2,233.5,234.5,100,63,1,4,233.45,234.75,15,1,1,1,233.4,234.79,110,2000,2,1,233.39,234.89,10,2,1,2,AAPL,0.0,0.0,-200.0,
2024-10-21 12:12:50.565554902+00:00,2024-10-21T12:12:50.565721409Z,10,2,38,A,A,2,234.13,30,130,166507,12355991,233.72,234.0,400,154,1,7,233.71,234.06,26,400,1,1,233.7,234.13,1200,430,1,2,233.66,234.17,1,1,1,1,233.58,234.41,505,600,2,2,233.53,234.43,10,105,1,2,233.5,234.5,100,63,1,4,233.45,234.75,15,1,1,1,233.4,234.79,110,2000,2,1,233.39,234.89,10,2,1,2,AAPL,0.0,-30.0,-200.0,
2024-10-21 12:12:50.573844808+00:00,2024-10-21T12:12:50.574010932Z,10,2,38,C,B,0,233.72,200,130,166124,12355992,233.72,234.0,200,154,1,7,233.71,234.06,26,400,1,1,233.7,234.13,1200,430,1,2,233.66,234.17,1,1,1,1,233.58,234.41,505,600,2,2,233.53,234.43,10,105,1,2,233.5,234.5,100,63,1,4,233.45,234.75,15,1,1,1,233.4,234.79,110,2000,2,1,233.39,234.89,10,2,1,2,AAPL,-200.0,-200.0,-400.0,
2024-10-21 12:12:50.619549454+00:00,2024-10-21T12:12:50.619715566Z,10,2,38,C,B,0,233.72,200,130,166112,12355999,233.71,234.0,26,154,1,7,233.7,234.06,1200,400,1,1,233.66,234.13,1,430,1,2,233.58,234.17,505,1,2,1,233.53,234.41,10,600,1,2,233.5,234.43,100,105,1,2,233.45,234.5,15,63,1,4,233.4,234.75,110,1,2,1,233.39,234.79,10,2000,1,1,233.31,234.89,110,2,2,2,AAPL,0.0,0.0,-400.0,
2024-10-21 12:12:50.619562205+00:00,2024-10-21T12:12:50.619728644Z,10,2,38,A,A,1,234.05,200,130,166439,12356000,233.71,234.0,26,154,1,7,233.7,234.05,1200,200,1,1,233.66,234.13,1,430,1,2,233.58,234.17,505,1,2,1,233.53,234.41,10,600,1,2,233.5,234.43,100,105,1,2,233.45,234.5,15,63,1,4,233.4,234.75,110,1,2,1,233.39,234.79,10,2000,1,1,233.31,234.89,110,2,2,2,AAPL,0.0,0.0,-400.0,
2024-10-21 12:12:50.622623771+00:00,2024-10-21T12:12:50.622790340Z,10,2,38,A,A,1,234.01,200,130,166569,12356003,233.71,234.0,26,154,1,7,233.7,234.01,1200,200,1,1,233.66,234.13,1,430,1,2,233.58,234.17,505,1,2,1,233.53,234.41,10,600,1,2,233.5,234.43,100,105,1,2,233.45,234.5,15,63,1,4,233.4,234.75,110,1,2,1,233.39,234.79,10,2000,1,1,233.31,234.89,110,2,2,2,AAPL,0.0,0.0,-400.0,
2024-10-21 12:12:50.641554545+00:00,2024-10-21T12:12:50.641720668Z,10,2,38,A,B,0,233.77,200,130,166123,12356008,233.77,234.0,200,154,1,7,233.71,234.01,26,200,1,1,233.7,234.13,1200,430,1,2,233.66,234.17,1,1,1,1,233.58,234.41,505,600,2,2,233.53,234.43,10,105,1,2,233.5,234.5,100,63,1,4,233.45,234.75,15,1,1,1,233.4,234.79,110,2000,2,1,233.39,234.89,10,2,1,2,AAPL,0.0,0.0,-400.0,
2024-10-21 12:12:50.682363924+00:00,2024-10-21T12:12:50.682530531Z,10,2,38,C,A,1,234.01,200,130,166607,12356017,233.77,234.0,200,154,1,7,233.71,234.13,26,430,1,2,233.7,234.17,1200,1,1,1,233.66,234.41,1,600,1,2,233.58,234.43,505,105,2,2,233.53,234.5,10,63,1,4,233.5,234.75,100,1,1,1,233.45,234.79,15,2000,1,1,233.4,234.89,110,2,2,2,233.39,235.0,10,213,1,6,AAPL,0.0,0.0,-400.0,
2024-10-21 12:12:50.682376586+00:00,2024-10-21T12:12:50.682542775Z,10,2,38,A,A,1,234.06,400,130,166189,12356018,233.77,234.0,200,154,1,7,233.71,234.06,26,400,1,1,233.7,234.13,1200,430,1,2,233.66,234.17,1,1,1,1,233.58,234.41,505,600,2,2,233.53,234.43,10,105,1,2,233.5,234.5,100,63,1,4,233.45,234.75,15,1,1,1,233.4,234.79,110,2000,2,1,233.39,234.89,10,2,1,2,AAPL,0.0,0.0,-400.0,
2024-10-21 12:12:50.736513051+00:00,2024-10-21T12:12:50.736679110Z,10,2,38,C,B,0,233.77,200,130,166059,12356039,233.71,234.0,26,154,1,7,233.7,234.06,1200,400,1,1,233.66,234.13,1,430,1,2,233.58,234.17,505,1,2,1,233.53,234.41,10,600,1,2,233.5,234.43,100,105,1,2,233.45,234.5,15,63,1,4,233.4,234.75,110,1,2,1,233.39,234.79,10,2000,1,1,233.31,234.89,110,2,2,2,AAPL,0.0,0.0,-400.0,
2024-10-21 12:12:50.837707032+00:00,2024-10-21T12:12:50.837873116Z,10,2,38,A,B,0,233.77,200,130,166084,12356086,233.77,234.0,200,154,1,7,233.71,234.06,26,400,1,1,233.7,234.13,1200,430,1,2,233.66,234.17,1,1,1,1,233.58,234.41,505,600,2,2,233.53,234.43,10,105,1,2,233.5,234.5,100,63,1,4,233.45,234.75,15,1,1,1,233.4,234.79,110,2000,2,1,233.39,234.89,10,2,1,2,AAPL,0.0,0.0,-400.0,
2024-10-21 12:12:50.886487788+00:00,2024-10-21T12:12:50.886653895Z,10,2,38,C,B,0,233.77,200,130,166107,12356099,233.71,234.0,26,154,1,7,233.7,234.06,1200,400,1,1,233.66,234.13,1,430,1,2,233.58,234.17,505,1,2,1,233.53,234.41,10,600,1,2,233.5,234.43,100,105,1,2,233.45,234.5,15,63,1,4,233.4,234.75,110,1,2,1,233.39,234.79,10,2000,1,1,233.31,234.89,110,2,2,2,AAPL,0.0,0.0,-400.0,
2024-10-21 12:12:50.986777714+00:00,2024-10-21T12:12:50.986944410Z,10,2,38,A,B,0,233.77,200,130,166696,12356148,233.77,234.0,200,154,1,7,233.71,234.06,26,400,1,1,233.7,234.13,1200,430,1,2,233.66,234.17,1,1,1,1,233.58,234.41,505,600,2,2,233.53,234.43,10,105,1,2,233.5,234.5,100,63,1,4,233.45,234.75,15,1,1,1,233.4,234.79,110,2000,2,1,233.39,234.89,10,2,1,2,AAPL,0.0,0.0,-400.0,
2024-10-21 12:12:51.039337327+00:00,2024-10-21T12:12:51.039503151Z,10,2,38,C,B,0,233.77,200,130,165824,12356173,233.71,234.0,26,154,1,7,233.7,234.06,1200,400,1,1,233.66,234.13,1,430,1,2,233.58,234.17,505,1,2,1,233.53,234.41,10,600,1,2,233.5,234.43,100,105,1,2,233.45,234.5,15,63,1,4,233.4,234.75,110,1,2,1,233.39,234.79,10,2000,1,1,233.31,234.89,110,2,2,2,AAPL,0.0,0.0,-400.0,
2024-10-21 12:12:51.147897247+00:00,2024-10-21T12:12:51.148063732Z,10,2,38,A,B,0,233.77,200,130,166485,12356223,233.77,234.0,200,154,1,7,233.71,234.06,26,400,1,1,233.7,234.13,1200,430,1,2,233.66,234.17,1,1,1,1,233.58,234.41,505,600,2,2,233.53,234.43,10,105,1,2,233.5,234.5,100,63,1,4,233.45,234.75,15,1,1,1,233.4,234.79,110,2000,2,1,233.39,234.89,10,2,1,2,AAPL,0.0,0.0,-200.0,
2024-10-21 12:12:51.221379329+00:00,2024-10-21T12:12:51.221545416Z,10,2,38,C,B,0,233.77,200,130,166087,12356261,233.71,234.0,26,154,1,7,233.7,234.06,1200,400,1,1,233.66,234.13,1,430,1,2,233.58,234.17,505,1,2,1,233.53,234.41,10,600,1,2,233.5,234.43,100,105,1,2,233.45,234.5,15,63,1,4,233.4,234.75,110,1,2,1,233.39,234.79,10,2000,1,1,233.31,234.89,110,2,2,2,AAPL,0.0,0.0,-200.0,
2024-10-21 12:12:51.329937404+00:00,2024-10-21T12:12:51.330104268Z,10,2,38,A,B,0,233.77,200,130,166864,12356295,233.77,234.0,200,154,1,7,233.71,234.06,26,400,1,1,233.7,234.13,1200,430,1,2,233.66,234.17,1,1,1,1,233.58,234.41,505,600,2,2,233.53,234.43,10,105,1,2,233.5,234.5,100,63,1,4,233.45,234.75,15,1,1,1,233.4,234.79,110,2000,2,1,233.39,234.89,10,2,1,2,AAPL,0.0,0.0,-200.0,
2024-10-21 12:12:51.374411634+00:00,2024-10-21T12:12:51.374577807Z,10,2,38,C,B,0,233.77,200,130,166173,12356317,233.71,234.0,26,154,1,7,233.7,234.06,1200,400,1,1,233.66,234.13,1,430,1,2,233.58,234.17,505,1,2,1,233.53,234.41,10,600,1,2,233.5,234.43,100,105,1,2,233.45,234.5,15,63,1,4,233.4,234.75,110,1,2,1,233.39,234.79,10,2000,1,1,233.31,234.89,110,2,2,2,AAPL,0.0,0.0,-200.0,
2024-10-21 12:12:51.475039269+00:00,2024-10-21T12:12:51.475205660Z,10,2,38,A,B,0,233.77,200,130,166391,12356344,233.77,234.0,200,154,1,7,233.71,234.06,26,400,1,1,233.7,234.13,1200,430,1,2,233.66,234.17,1,1,1,1,233.58,234.41,505,600,2,2,233.53,234.43,10,105,1,2,233.5,234.5,100,63,1,4,233.45,234.75,15,1,1,1,233.4,234.79,110,2000,2,1,233.39,234.89,10,2,1,2,AAPL,0.0,0.0,-200.0,
2024-10-21 12:12:51.507076220+00:00,2024-10-21T12:12:51.507242100Z,10,2,38,C,B,0,233.77,200,130,165880,12356356,233.71,234.0,26,154,1,7,233.7,234.06,1200,400,1,1,233.66,234.13,1,430,1,2,233.58,234.17,505,1,2,1,233.53,234.41,10,600,1,2,233.5,234.43,100,105,1,2,233.45,234.5,15,63,1,4,233.4,234.75,110,1,2,1,233.39,234.79,10,2000,1,1,233.31,234.89,110,2,2,2,AAPL,0.0,0.0,-200.0,
2024-10-21 12:12:51.709226597+00:00,2024-10-21T12:12:51.709392937Z,10,2,38,A,B,0,233.77,200,130,166340,12356415,233.77,234.0,200,154,1,7,233.71,234.06,26,400,1,1,233.7,234.13,1200,430,1,2,233.66,234.17,1,1,1,1,233.58,234.41,505,600,2,2,233.53,234.43,10,105,1,2,233.5,234.5,100,63,1,4,233.45,234.75,15,1,1,1,233.4,234.79,110,2000,2,1,233.39,234.89,10,2,1,2,AAPL,0.0,0.0,0.0,
2024-10-21 12:12:52.481246232+00:00,2024-10-21T12:12:52.481412276Z,10,2,38,C,B,0,233.77,200,130,166044,12356788,233.71,234.0,26,154,1,7,233.7,234.06,1200,400,1,1,233.66,234.13,1,430,1,2,233.58,234.17,505,1,2,1,233.53,234.41,10,600,1,2,233.5,234.43,100,105,1,2,233.45,234.5,15,63,1,4,233.4,234.75,110,1,2,1,233.39,234.79,10,2000,1,1,233.31,234.89,110,2,2,2,AAPL,0.0,0.0,0.0,
2024-10-21 12:12:52.582845276+00:00,2024-10-21T12:12:52.583011665Z,10,2,38,A,B,0,233.77,200,130,166389,12356899,233.77,234.0,200,154,1,7,233.71,234.06,26,400,1,1,233.7,234.13,1200,430,1,2,233.66,234.17,1,1,1,1,233.58,234.41,505,600,2,2,233.53,234.43,10,105,1,2,233.5,234.5,100,63,1,4,233.45,234.75,15,1,1,1,233.4,234.79,110,2000,2,1,233.39,234.89,10,2,1,2,AAPL,0.0,0.0,0.0,
2024-10-21 12:12:53.922861024+00:00,2024-10-21T12:12:53.923027418Z,10,2,38,C,B,1,233.71,26,130,166394,12357591,233.77,234.0,200,154,1,7,233.7,234.06,1200,400,1,1,233.66,234.13,1,430,1,2,233.58,234.17,505,1,2,1,233.53,234.41,10,600,1,2,233.5,234.43,100,105,1,2,233.45,234.5,15,63,1,4,233.4,234.75,110,1,2,1,233.39,234.79,10,2000,1,1,233.31,234.89,110,2,2,2,AAPL,0.0,0.0,0.0,
2024-10-21 12:12:53.922963386+00:00,2024-10-21T12:12:53.923129817Z,10,2,38,A,B,1,233.76,27,130,166431,12357592,233.77,234.0,200,154,1,7,233.76,234.06,27,400,1,1,233.7,234.13,1200,430,1,2,233.66,234.17,1,1,1,1,233.58,234.41,505,600,2,2,233.53,234.43,10,105,1,2,233.5,234.5,100,63,1,4,233.45,234.75,15,1,1,1,233.4,234.79,110,2000,2,1,233.39,234.89,10,2,1,2,AAPL,0.0,0.0,0.0,
2024-10-21 12:12:59.628865467+00:00,2024-10-21T12:12:59.629031962Z,10,2,38,A,B,0,233.78,200,130,166495,12361324,233.78,234.0,200,154,1,7,233.76,234.06,27,400,1,1,233.7,234.13,1200,430,1,2,233.66,234.17,1,1,1,1,233.58,234.41,505,600,2,2,233.53,234.43,10,105,1,2,233.5,234.5,100,63,1,4,233.45,234.75,15,1,1,1,233.4,234.79,110,2000,2,1,233.39,234.89,10,2,1,2,AAPL,0.0,0.0,0.0,
2024-10-21 12:12:59.643737494+00:00,2024-10-21T12:12:59.643903867Z,10,2,38,A,B,1,233.77,26,130,166373,12361417,233.78,234.0,200,154,1,7,233.77,234.06,26,400,1,1,233.76,234.13,27,430,1,2,233.7,234.17,1200,1,1,1,233.66,234.41,1,600,1,2,233.58,234.43,505,105,2,2,233.53,234.5,10,63,1,4,233.5,234.75,100,1,1,1,233.45,234.79,15,2000,1,1,233.4,234.89,110,2,2,2,AAPL,0.0,0.0,0.0,
2024-10-21 12:12:59.691625988+00:00,2024-10-21T12:12:59.691792264Z,10,2,38,C,B,2,233.76,27,130,166276,12361539,233.78,234.0,200,154,1,7,233.77,234.06,26,400,1,1,233.7,234.13,1200,430,1,2,233.66,234.17,1,1,1,1,233.58,234.41,505,600,2,2,233.53,234.43,10,105,1,2,233.5,234.5,100,63,1,4,233.45,234.75,15,1,1,1,233.4,234.79,110,2000,2,1,233.39,234.89,10,2,1,2,AAPL,0.0,0.0,0.0,
2024-10-21 12:12:59.691649558+00:00,2024-10-21T12:12:59.691815700Z,10,2,38,C,B,1,233.77,26,130,166142,12361540,233.78,234.0,200,154,1,7,233.7,234.06,1200,400,1,1,233.66,234.13,1,430,1,2,233.58,234.17,505,1,2,1,233.53,234.41,10,600,1,2,233.5,234.43,100,105,1,2,233.45,234.5,15,63,1,4,233.4,234.75,110,1,2,1,233.39,234.79,10,2000,1,1,233.31,234.89,110,2,2,2,AAPL,0.0,0.0,0.0,
2024-10-21 12:12:59.691721965+00:00,2024-10-21T12:12:59.691888302Z,10,2,38,A,B,1,233.77,26,130,166337,12361541,233.78,234.0,200,154,1,7,233.77,234.06,26,400,1,1,233.7,234.13,1200,430,1,2,233.66,234.17,1,1,1,1,233.58,234.41,505,600,2,2,233.53,234.43,10,105,1,2,233.5,234.5,100,63,1,4,233.45,234.75,15,1,1,1,233.4,234.79,110,2000,2,1,233.39,234.89,10,2,1,2,AAPL,0.0,0.0,0.0,
2024-10-21 12:13:11.883729412+00:00,2024-10-21T12:13:11.883895663Z,10,2,38,C,A,1,234.06,400,130,166251,12371151,233.78,234.0,200,154,1,7,233.77,234.13,26,430,1,2,233.7,234.17,1200,1,1,1,233.66,234.41,1,600,1,2,233.58,234.43,505,105,2,2,233.53,234.5,10,63,1,4,233.5,234.75,100,1,1,1,233.45,234.79,15,2000,1,1,233.4,234.89,110,2,2,2,233.39,235.0,10,213,1,6,AAPL,0.0,0.0,0.0,
2024-10-21 12:13:11.920609443+00:00,2024-10-21T12:13:11.920775720Z,10,2,38,A,A,1,234.06,200,130,166277,12371429,233.78,234.0,200,154,1,7,233.77,234.06,26,200,1,1,233.7,234.13,1200,430,1,2,233.66,234.17,1,1,1,1,233.58,234.41,505,600,2,2,233.53,234.43,10,105,1,2,233.5,234.5,100,63,1,4,233.45,234.75,15,1,1,1,233.4,234.79,110,2000,2,1,233.39,234.89,10,2,1,2,AAPL,0.0,0.0,0.0,
2024-10-21 12:13:11.948637105+00:00,2024-10-21T12:13:11.948803197Z,10,2,38,A,A,1,234.06,200,130,166092,12371519,233.78,234.0,200,154,1,7,233.77,234.06,26,400,1,2,233.7,234.13,1200,430,1,2,233.66,234.17,1,1,1,1,233.58,234.41,505,600,2,2,233.53,234.43,10,105,1,2,233.5,234.5,100,63,1,4,233.45,234.75,15,1,1,1,233.4,234.79,110,2000,2,1,233.39,234.89,10,2,1,2,AAPL,0.0,-200.0,0.0,
2024-10-21 12:13:21.542992246+00:00,2024-10-21T12:13:21.543158873Z,10,2,38,C,A,1,234.06,200,130,166627,12379437,233.78,234.0,200,154,1,7,233.77,234.06,26,200,1,1,233.7,234.13,1200,430,1,2,233.66,234.17,1,1,1,1,233.58,234.41,505,600,2,2,233.53,234.43,10,105,1,2,233.5,234.5,100,63,1,4,233.45,234.75,15,1,1,1,233.4,234.79,110,2000,2,1,233.39,234.89,10,2,1,2,AAPL,0.0,200.0,0.0,
2024-10-21 12:13:21.543002194+00:00,2024-10-21T12:13:21.543168132Z,10,2,38,C,A,1,234.06,200,130,165938,12379438,233.78,234.0,200,154,1,7,233.77,234.13,26,430,1,2,233.7,234.17,1200,1,1,1,233.66,234.41,1,600,1,2,233.58,234.43,505,105,2,2,233.53,234.5,10,63,1,4,233.5,234.75,100,1,1,1,233.45,234.79,15,2000,1,1,233.4,234.89,110,2,2,2,233.39,235.0,10,213,1,6,AAPL,0.0,0.0,0.0,
2024-10-21 12:13:21.543013145+00:00,2024-10-21T12:13:21.543179396Z,10,2,38,A,A,1,234.08,400,130,166251,12379439,233.78,234.0,200,154,1,7,233.77,234.08,26,400,1,1,233.7,234.13,1200,430,1,2,233.66,234.17,1,1,1,1,233.58,234.41,505,600,2,2,233.53,234.43,10,105,1,2,233.5,234.5,100,63,1,4,233.45,234.75,15,1,1,1,233.4,234.79,110,2000,2,1,233.39,234.89,10,2,1,2,AAPL,0.0,0.0,0.0,
2024-10-21 12:13:21.617135979+00:00,2024-10-21T12:13:21.617302321Z,10,2,38,C,B,1,233.77,26,130,166342,12379657,233.78,234.0,200,154,1,7,233.7,234.08,1200,400,1,1,233.66,234.13,1,430,1,2,233.58,234.17,505,1,2,1,233.53,234.41,10,600,1,2,233.5,234.43,100,105,1,2,233.45,234.5,15,63,1,4,233.4,234.75,110,1,2,1,233.39,234.79,10,2000,1,1,233.31,234.89,110,2,2,2,AAPL,0.0,0.0,0.0,
2024-10-21 12:13:21.617220419+00:00,2024-10-21T12:13:21.617386770Z,10,2,38,A,B,1,233.72,26,130,166351,12379659,233.78,234.0,200,154,1,7,233.72,234.08,26,400,1,1,233.7,234.13,1200,430,1,2,233.66,234.17,1,1,1,1,233.58,234.41,505,600,2,2,233.53,234.43,10,105,1,2,233.5,234.5,100,63,1,4,233.45,234.75,15,1,1,1,233.4,234.79,110,2000,2,1,233.39,234.89,10,2,1,2,AAPL,0.0,0.0,0.0,
2024-10-21 12:13:22.557831797+00:00,2024-10-21T12:13:22.557998386Z,10,2,38,A,A,1,234.07,400,130,166589,12380655,233.78,234.0,200,154,1,7,233.72,234.07,26,400,1,1,233.7,234.13,1200,430,1,2,233.66,234.17,1,1,1,1,233.58,234.41,505,600,2,2,233.53,234.43,10,105,1,2,233.5,234.5,100,63,1,4,233.45,234.75,15,1,1,1,233.4,234.79,110,2000,2,1,233.39,234.89,10,2,1,2,AAPL,0.0,0.0,0.0,
2024-10-21 12:13:25.371930587+00:00,2024-10-21T12:13:25.372097284Z,10,2,38,A,B,0,233.79,200,130,166697,12382998,233.79,234.0,200,154,1,7,233.72,234.07,26,400,1,1,233.7,234.13,1200,430,1,2,233.66,234.17,1,1,1,1,233.58,234.41,505,600,2,2,233.53,234.43,10,105,1,2,233.5,234.5,100,63,1,4,233.45,234.75,15,1,1,1,233.4,234.79,110,2000,2,1,233.39,234.89,10,2,1,2,AAPL,0.0,0.0,0.0,
2024-10-21 12:13:25.495542627+00:00,2024-10-21T12:13:25.495708682Z,10,2,38,C,B,1,233.72,26,130,166055,12383140,233.79,234.0,200,154,1,7,233.7,234.07,1200,400,1,1,233.66,234.13,1,430,1,2,233.58,234.17,505,1,2,1,233.53,234.41,10,600,1,2,233.5,234.43,100,105,1,2,233.45,234.5,15,63,1,4,233.4,234.75,110,1,2,1,233.39,234.79,10,2000,1,1,233.31,234.89,110,2,2,2,AAPL,0.0,0.0,0.0,
2024-10-21 12:13:25.495588580+00:00,2024-10-21T12:13:25.495754875Z,10,2,38,A,B,1,233.73,27,130,166295,12383141,233.79,234.0,200,154,1,7,233.73,234.07,27,400,1,1,233.7,234.13,1200,430,1,2,233.66,234.17,1,1,1,1,233.58,234.41,505,600,2,2,233.53,234.43,10,105,1,2,233.5,234.5,100,63,1,4,233.45,234.75,15,1,1,1,233.4,234.79,110,2000,2,1,233.39,234.89,10,2,1,2,AAPL,0.0,0.0,0.0,
2024-10-21 12:13:29.150340169+00:00,2024-10-21T12:13:29.150506254Z,10,2,38,A,A,3,234.15,30,130,166085,12386039,233.79,234.0,200,154,1,7,233.73,234.07,27,400,1,1,233.7,234.13,1200,430,1,2,233.66,234.15,1,30,1,1,233.58,234.17,505,1,2,1,233.53,234.41,10,600,1,2,233.5,234.43,100,105,1,2,233.45,234.5,15,63,1,4,233.4,234.75,110,1,2,1,233.39,234.79,10,2000,1,1,AAPL,0.0,0.0,0.0,
2024-10-21 12:13:29.268636112+00:00,2024-10-21T12:13:29.268802068Z,10,2,38,C,A,2,234.13,30,130,165956,12386279,233.79,234.0,200,154,1,7,233.73,234.07,27,400,1,1,233.7,234.13,1200,400,1,1,233.66,234.15,1,30,1,1,233.58,234.17,505,1,2,1,233.53,234.41,10,600,1,2,233.5,234.43,100,105,1,2,233.45,234.5,15,63,1,4,233.4,234.75,110,1,2,1,233.39,234.79,10,2000,1,1,AAPL,0.0,30.0,0.0,
2024-10-21 12:13:32.213682828+00:00,2024-10-21T12:13:32.213848825Z,10,2,38,C,A,1,234.07,400,130,165997,12388761,233.79,234.0,200,154,1,7,233.73,234.13,27,400,1,1,233.7,234.15,1200,30,1,1,233.66,234.17,1,1,1,1,233.58,234.41,505,600,2,2,233.53,234.43,10,105,1,2,233.5,234.5,100,63,1,4,233.45,234.75,15,1,1,1,233.4,234.79,110,2000,2,1,233.39,234.89,10,2,1,2,AAPL,0.0,0.0,0.0,
2024-10-21 12:13:32.213695191+00:00,2024-10-21T12:13:32.213862106Z,10,2,38,A,A,1,234.09,400,130,166915,12388762,233.79,234.0,200,154,1,7,233.73,234.09,27,400,1,1,233.7,234.13,1200,400,1,1,233.66,234.15,1,30,1,1,233.58,234.17,505,1,2,1,233.53,234.41,10,600,1,2,233.5,234.43,100,105,1,2,233.45,234.5,15,63,1,4,233.4,234.75,110,1,2,1,233.39,234.79,10,2000,1,1,AAPL,0.0,0.0,0.0,
2024-10-21 12:13:32.278804796+00:00,2024-10-21T12:13:32.278971542Z,10,2,38,A,B,0,233.8,200,130,166746,12388939,233.8,234.0,200,154,1,7,233.73,234.09,27,400,1,1,233.7,234.13,1200,400,1,1,233.66,234.15,1,30,1,1,233.58,234.17,505,1,2,1,233.53,234.41,10,600,1,2,233.5,234.43,100,105,1,2,233.45,234.5,15,63,1,4,233.4,234.75,110,1,2,1,233.39,234.79,10,2000,1,1,AAPL,0.0,0.0,0.0,
2024-10-21 12:13:32.362327800+00:00,2024-10-21T12:13:32.362493854Z,10,2,38,C,A,3,234.15,30,130,166054,12389254,233.8,234.0,200,154,1,7,233.73,234.09,27,400,1,1,233.7,234.13,1200,400,1,1,233.66,234.17,1,1,1,1,233.58,234.41,505,600,2,2,233.53,234.43,10,105,1,2,233.5,234.5,100,63,1,4,233.45,234.75,15,1,1,1,233.4,234.79,110,2000,2,1,233.39,234.89,10,2,1,2,AAPL,0.0,0.0,0.0,
2024-10-21 12:13:32.401872088+00:00,2024-10-21T12:13:32.402038108Z,10,2,38,C,B,1,233.73,27,130,166020,12389357,233.8,234.0,200,154,1,7,233.7,234.09,1200,400,1,1,233.66,234.13,1,400,1,1,233.58,234.17,505,1,2,1,233.53,234.41,10,600,1,2,233.5,234.43,100,105,1,2,233.45,234.5,15,63,1,4,233.4,234.75,110,1,2,1,233.39,234.79,10,2000,1,1,233.31,234.89,110,2,2,2,AAPL,0.0,0.0,0.0,
2024-10-21 12:13:32.412631196+00:00,2024-10-21T12:13:32.412797711Z,10,2,38,A,A,2,234.11,27,130,166515,12389377,233.8,234.0,200,154,1,7,233.7,234.09,1200,400,1,1,233.66,234.11,1,27,1,1,233.58,234.13,505,400,2,1,233.53,234.17,10,1,1,1,233.5,234.41,100,600,1,2,233.45,234.43,15,105,1,2,233.4,234.5,110,63,2,4,233.39,234.75,10,1,1,1,233.31,234.79,110,2000,2,1,AAPL,0.0,0.0,0.0,
2024-10-21 12:13:34.144724456+00:00,2024-10-21T12:13:34.144890619Z,10,2,38,A,B,0,233.89,100,130,166163,12390756,233.89,234.0,100,154,1,7,233.8,234.09,200,400,1,1,233.7,234.11,1200,27,1,1,233.66,234.13,1,400,1,1,233.58,234.17,505,1,2,1,233.53,234.41,10,600,1,2,233.5,234.43,100,105,1,2,233.45,234.5,15,63,1,4,233.4,234.75,110,1,2,1,233.39,234.79,10,2000,1,1,AAPL,0.0,0.0,0.0,
2024-10-21 12:13:34.145172866+00:00,2024-10-21T12:13:34.145338999Z,10,2,38,C,B,0,233.89,100,130,166133,12390759,233.8,234.0,200,154,1,7,233.7,234.09,1200,400,1,1,233.66,234.11,1,27,1,1,233.58,234.13,505,400,2,1,233.53,234.17,10,1,1,1,233.5,234.41,100,600,1,2,233.45,234.43,15,105,1,2,233.4,234.5,110,63,2,4,233.39,234.75,10,1,1,1,233.31,234.79,110,2000,2,1,AAPL,0.0,0.0,0.0,
2024-10-21 12:13:34.215278319+00:00,2024-10-21T12:13:34.215444342Z,10,2,38,C,A,2,234.11,27,130,166023,12390798,233.8,234.0,200,154,1,7,233.7,234.09,1200,400,1,1,233.66,234.13,1,400,1,1,233.58,234.17,505,1,2,1,233.53,234.41,10,600,1,2,233.5,234.43,100,105,1,2,233.45,234.5,15,63,1,4,233.4,234.75,110,1,2,1,233.39,234.79,10,2000,1,1,233.31,234.89,110,2,2,2,AAPL,0.0,0.0,0.0,
2024-10-21 12:13:34.277424242+00:00,2024-10-21T12:13:34.277590859Z,10,2,38,A,A,1,234.06,200,130,166617,12390835,233.8,234.0,200,154,1,7,233.7,234.06,1200,200,1,1,233.66,234.13,1,400,1,1,233.58,234.17,505,1,2,1,233.53,234.41,10,600,1,2,233.5,234.43,100,105,1,2,233.45,234.5,15,63,1,4,233.4,234.75,110,1,2,1,233.39,234.79,10,2000,1,1,233.31,234.89,110,2,2,2,AAPL,0.0,0.0,0.0,
2024-10-21 12:13:35.061077358+00:00,2024-10-21T12:13:35.061243869Z,10,2,38,A,B,0,233.81,200,130,166511,12391575,233.81,234.0,200,154,1,7,233.7,234.06,1200,200,1,1,233.66,234.13,1,400,1,1,233.58,234.17,505,1,2,1,233.53,234.41,10,600,1,2,233.5,234.43,100,105,1,2,233.45,234.5,15,63,1,4,233.4,234.75,110,1,2,1,233.39,234.79,10,2000,1,1,233.31,234.89,110,2,2,2,AAPL,0.0,0.0,0.0,
2024-10-21 12:13:35.075174042+00:00,2024-10-21T12:13:35.075339842Z,10,2,38,C,B,0,233.81,200,130,165800,12391728,233.7,234.0,1200,154,1,7,233.66,234.06,1,200,1,1,233.58,234.13,505,400,2,1,233.53,234.17,10,1,1,1,233.5,234.41,100,600,1,2,233.45,234.43,15,105,1,2,233.4,234.5,110,63,2,4,233.39,234.75,10,1,1,1,233.31,234.79,110,2000,2,1,233.3,234.89,100,2,1,2,AAPL,0.0,0.0,0.0,
2024-10-21 12:13:35.075183720+00:00,2024-10-21T12:13:35.075350085Z,10,2,38,A,B,0,233.74,200,130,166365,12391729,233.74,234.0,200,154,1,7,233.7,234.06,1200,200,1,1,233.66,234.13,1,400,1,1,233.58,234.17,505,1,2,1,233.53,234.41,10,600,1,2,233.5,234.43,100,105,1,2,233.45,234.5,15,63,1,4,233.4,234.75,110,1,2,1,233.39,234.79,10,2000,1,1,233.31,234.89,110,2,2,2,AAPL,0.0,0.0,0.0,
2024-10-21 12:13:35.077473825+00:00,2024-10-21T12:13:35.077639622Z,10,2,38,C,A,1,234.06,200,130,165797,12391777,233.74,234.0,200,154,1,7,233.7,234.13,1200,400,1,1,233.66,234.17,1,1,1,1,233.58,234.41,505,600,2,2,233.53,234.43,10,105,1,2,233.5,234.5,100,63,1,4,233.45,234.75,15,1,1,1,233.4,234.79,110,2000,2,1,233.39,234.89,10,2,1,2,233.31,235.0,110,213,2,6,AAPL,0.0,0.0,0.0,
2024-10-21 12:13:35.077485044+00:00,2024-10-21T12:13:35.077651330Z,10,2,38,A,A,1,234.08,200,130,166286,12391778,233.74,234.0,200,154,1,7,233.7,234.08,1200,200,1,1,233.66,234.13,1,400,1,1,233.58,234.17,505,1,2,1,233.53,234.41,10,600,1,2,233.5,234.43,100,105,1,2,233.45,234.5,15,63,1,4,233.4,234.75,110,1,2,1,233.39,234.79,10,2000,1,1,233.31,234.89,110,2,2,2,AAPL,0.0,0.0,0.0,
2024-10-21 12:13:35.086566953+00:00,2024-10-21T12:13:35.086732850Z,10,2,38,C,B,0,233.74,200,130,165897,12391883,233.7,234.0,1200,154,1,7,233.66,234.08,1,200,1,1,233.58,234.13,505,400,2,1,233.53,234.17,10,1,1,1,233.5,234.41,100,600,1,2,233.45,234.43,15,105,1,2,233.4,234.5,110,63,2,4,233.39,234.75,10,1,1,1,233.31,234.79,110,2000,2,1,233.3,234.89,100,2,1,2,AAPL,0.0,0.0,0.0,
2024-10-21 12:13:35.086579076+00:00,2024-10-21T12:13:35.086745457Z,10,2,38,A,B,0,233.72,400,130,166381,12391884,233.72,234.0,400,154,1,7,233.7,234.08,1200,200,1,1,233.66,234.13,1,400,1,1,233.58,234.17,505,1,2,1,233.53,234.41,10,600,1,2,233.5,234.43,100,105,1,2,233.45,234.5,15,63,1,4,233.4,234.75,110,1,2,1,233.39,234.79,10,2000,1,1,233.31,234.89,110,2,2,2,AAPL,0.0,0.0,0.0,
2024-10-21 12:13:35.108095991+00:00,2024-10-21T12:13:35.108265805Z,10,2,38,T,N,0,233.94,50,0,169814,12392002,233.72,234.0,400,154,1,7,233.7,234.08,1200,200,1,1,233.66,234.13,1,400,1,1,233.58,234.17,505,1,2,1,233.53,234.41,10,600,1,2,233.5,234.43,100,105,1,2,233.45,234.5,15,63,1,4,233.4,234.75,110,1,2,1,233.39,234.79,10,2000,1,1,233.31,234.89,110,2,2,2,AAPL,0.0,0.0,0.0,
2024-10-21 12:13:35.108095991+00:00,2024-10-21T12:13:35.108265805Z,10,2,38,T,N,0,233.93,50,0,169814,12392003,233.72,234.0,400,154,1,7,233.7,234.08,1200,200,1,1,233.66,234.13,1,400,1,1,233.58,234.17,505,1,2,1,233.53,234.41,10,600,1,2,233.5,234.43,100,105,1,2,233.45,234.5,15,63,1,4,233.4,234.75,110,1,2,1,233.39,234.79,10,2000,1,1,233.31,234.89,110,2,2,2,AAPL,0.0,0.0,0.0,
2024-10-21 12:13:35.108095991+00:00,2024-10-21T12:13:35.108265805Z,10,2,38,T,N,0,233.9,250,130,169814,12392004,233.72,234.0,400,154,1,7,233.7,234.08,1200,200,1,1,233.66,234.13,1,400,1,1,233.58,234.17,505,1,2,1,233.53,234.41,10,600,1,2,233.5,234.43,100,105,1,2,233.45,234.5,15,63,1,4,233.4,234.75,110,1,2,1,233.39,234.79,10,2000,1,1,233.31,234.89,110,2,2,2,AAPL,0.0,0.0,0.0,
2024-10-21 12:13:35.146372690+00:00,2024-10-21T12:13:35.146538430Z,10,2,38,C,B,0,233.72,400,130,165740,12392297,233.7,234.0,1200,154,1,7,233.66,234.08,1,200,1,1,233.58,234.13,505,400,2,1,233.53,234.17,10,1,1,1,233.5,234.41,100,600,1,2,233.45,234.43,15,105,1,2,233.4,234.5,110,63,2,4,233.39,234.75,10,1,1,1,233.31,234.79,110,2000,2,1,233.3,234.89,100,2,1,2,AAPL,0.0,0.0,0.0,
2024-10-21 12:13:35.146384339+00:00,2024-10-21T12:13:35.146551508Z,10,2,38,A,B,0,233.7,200,128,167169,12392298,233.7,234.0,1400,154,2,7,233.66,234.08,1,200,1,1,233.58,234.13,505,400,2,1,233.53,234.17,10,1,1,1,233.5,234.41,100,600,1,2,233.45,234.43,15,105,1,2,233.4,234.5,110,63,2,4,233.39,234.75,10,1,1,1,233.31,234.79,110,2000,2,1,233.3,234.89,100,2,1,2,AAPL,200.0,200.0,200.0,
2024-10-21 12:13:35.167869345+00:00,2024-10-21T12:13:35.168035257Z,10,2,38,C,B,0,233.7,200,130,165912,12392426,233.7,234.0,1200,154,1,7,233.66,234.08,1,200,1,1,233.58,234.13,505,400,2,1,233.53,234.17,10,1,1,1,233.5,234.41,100,600,1,2,233.45,234.43,15,105,1,2,233.4,234.5,110,63,2,4,233.39,234.75,10,1,1,1,233.31,234.79,110,2000,2,1,233.3,234.89,100,2,1,2,AAPL,-200.0,-200.0,0.0,
2024-10-21 12:13:35.175791647+00:00,2024-10-21T12:13:35.175958206Z,10,2,38,A,B,2,233.64,200,130,166559,12392448,233.7,234.0,1200,154,1,7,233.66,234.08,1,200,1,1,233.64,234.13,200,400,1,1,233.58,234.17,505,1,2,1,233.53,234.41,10,600,1,2,233.5,234.43,100,105,1,2,233.45,234.5,15,63,1,4,233.4,234.75,110,1,2,1,233.39,234.79,10,2000,1,1,233.31,234.89,110,2,2,2,AAPL,0.0,0.0,0.0,
2024-10-21 12:13:35.333929432+00:00,2024-10-21T12:13:35.334095780Z,10,2,38,A,B,2,233.65,200,130,166348,12392747,233.7,234.0,1200,154,1,7,233.66,234.08,1,200,1,1,233.65,234.13,200,400,1,1,233.58,234.17,505,1,2,1,233.53,234.41,10,600,1,2,233.5,234.43,100,105,1,2,233.45,234.5,15,63,1,4,233.4,234.75,110,1,2,1,233.39,234.79,10,2000,1,1,233.31,234.89,110,2,2,2,AAPL,0.0,0.0,0.0,
2024-10-21 12:13:35.352296693+00:00,2024-10-21T12:13:35.352463215Z,10,2,38,A,B,0,233.7,200,130,166522,12392766,233.7,234.0,1400,154,2,7,233.66,234.08,1,200,1,1,233.58,234.13,505,400,2,1,233.53,234.17,10,1,1,1,233.5,234.41,100,600,1,2,233.45,234.43,15,105,1,2,233.4,234.5,110,63,2,4,233.39,234.75,10,1,1,1,233.31,234.79,110,2000,2,1,233.3,234.89,100,2,1,2,AAPL,200.0,200.0,200.0,
2024-10-21 12:13:35.424351548+00:00,2024-10-21T12:13:35.424517936Z,10,2,38,A,B,0,233.72,200,130,166388,12392793,233.72,234.0,200,154,1,7,233.7,234.08,1200,200,1,1,233.66,234.13,1,400,1,1,233.58,234.17,505,1,2,1,233.53,234.41,10,600,1,2,233.5,234.43,100,105,1,2,233.45,234.5,15,63,1,4,233.4,234.75,110,1,2,1,233.39,234.79,10,2000,1,1,233.31,234.89,110,2,2,2,AAPL,0.0,0.0,200.0,
2024-10-21 12:13:38.131971887+00:00,2024-10-21T12:13:38.132138622Z,10,2,38,A,B,0,233.77,200,130,166735,12394618,233.77,234.0,200,154,1,7,233.7,234.08,1200,200,1,1,233.66,234.13,1,400,1,1,233.58,234.17,505,1,2,1,233.53,234.41,10,600,1,2,233.5,234.43,100,105,1,2,233.45,234.5,15,63,1,4,233.4,234.75,110,1,2,1,233.39,234.79,10,2000,1,1,233.31,234.89,110,2,2,2,AAPL,0.0,0.0,0.0,
2024-10-21 12:13:42.509087486+00:00,2024-10-21T12:13:42.509253965Z,10,2,38,A,B,1,233.76,29,130,166479,12397192,233.77,234.0,200,154,1,7,233.76,234.08,29,200,1,1,233.7,234.13,1200,400,1,1,233.66,234.17,1,1,1,1,233.58,234.41,505,600,2,2,233.53,234.43,10,105,1,2,233.5,234.5,100,63,1,4,233.45,234.75,15,1,1,1,233.4,234.79,110,2000,2,1,233.39,234.89,10,2,1,2,AAPL,0.0,0.0,0.0,
2024-10-21 12:13:42.509120725+00:00,2024-10-21T12:13:42.509287026Z,10,2,38,A,A,2,234.13,29,130,166301,12397193,233.77,234.0,200,154,1,7,233.76,234.08,29,200,1,1,233.7,234.13,1200,429,1,2,233.66,234.17,1,1,1,1,233.58,234.41,505,600,2,2,233.53,234.43,10,105,1,2,233.5,234.5,100,63,1,4,233.45,234.75,15,1,1,1,233.4,234.79,110,2000,2,1,233.39,234.89,10,2,1,2,AAPL,0.0,-29.0,0.0,
2024-10-21 12:13:45.327353906+00:00,2024-10-21T12:13:45.327521347Z,10,2,38,A,A,1,234.07,200,130,167441,12399281,233.77,234.0,200,154,1,7,233.76,234.07,29,200,1,1,233.7,234.13,1200,429,1,2,233.66,234.17,1,1,1,1,233.58,234.41,505,600,2,2,233.53,234.43,10,105,1,2,233.5,234.5,100,63,1,4,233.45,234.75,15,1,1,1,233.4,234.79,110,2000,2,1,233.39,234.89,10,2,1,2,AAPL,0.0,0.0,0.0,
2024-10-21 12:13:45.348280342+00:00,2024-10-21T12:13:45.348446565Z,10,2,38,C,A,2,234.13,29,130,166223,12399379,233.77,234.0,200,154,1,7,233.76,234.07,29,200,1,1,233.7,234.13,1200,400,1,1,233.66,234.17,1,1,1,1,233.58,234.41,505,600,2,2,233.53,234.43,10,105,1,2,233.5,234.5,100,63,1,4,233.45,234.75,15,1,1,1,233.4,234.79,110,2000,2,1,233.39,234.89,10,2,1,2,AAPL,0.0,29.0,0.0,
2024-10-21 12:13:45.348322946+00:00,2024-10-21T12:13:45.348489295Z,10,2,38,A,A,2,234.12,26,130,166349,12399380,233.77,234.0,200,154,1,7,233.76,234.07,29,200,1,1,233.7,234.12,1200,26,1,1,233.66,234.13,1,400,1,1,233.58,234.17,505,1,2,1,233.53,234.41,10,600,1,2,233.5,234.43,100,105,1,2,233.45,234.5,15,63,1,4,233.4,234.75,110,1,2,1,233.39,234.79,10,2000,1,1,AAPL,0.0,0.0,0.0,
2024-10-21 12:13:45.469056600+00:00,2024-10-21T12:13:45.469223815Z,10,2,38,T,N,0,233.98,18,130,167215,12399561,233.77,234.0,200,154,1,7,233.76,234.07,29,200,1,1,233.7,234.12,1200,26,1,1,233.66,234.13,1,400,1,1,233.58,234.17,505,1,2,1,233.53,234.41,10,600,1,2,233.5,234.43,100,105,1,2,233.45,234.5,15,63,1,4,233.4,234.75,110,1,2,1,233.39,234.79,10,2000,1,1,AAPL,0.0,0.0,0.0,
2024-10-21 12:13:45.811467280+00:00,2024-10-21T12:13:45.811636426Z,10,2,38,T,N,0,233.98,77,0,169146,12400065,233.77,234.0,200,154,1,7,233.76,234.07,29,200,1,1,233.7,234.12,1200,26,1,1,233.66,234.13,1,400,1,1,233.58,234.17,505,1,2,1,233.53,234.41,10,600,1,2,233.5,234.43,100,105,1,2,233.45,234.5,15,63,1,4,233.4,234.75,110,1,2,1,233.39,234.79,10,2000,1,1,AAPL,0.0,0.0,0.0,
2024-10-21 12:13:45.811467280+00:00,2024-10-21T12:13:45.811636426Z,10,2,38,T,B,0,234.0,20,0,169146,12400066,233.77,234.0,200,154,1,7,233.76,234.07,29,200,1,1,233.7,234.12,1200,26,1,1,233.66,234.13,1,400,1,1,233.58,234.17,505,1,2,1,233.53,234.41,10,600,1,2,233.5,234.43,100,105,1,2,233.45,234.5,15,63,1,4,233.4,234.75,110,1,2,1,233.39,234.79,10,2000,1,1,AAPL,0.0,0.0,0.0,
2024-10-21 12:13:45.811467280+00:00,2024-10-21T12:13:45.811636426Z,10,2,38,T,B,0,234.0,3,130,169146,12400067,233.77,234.0,200,134,1,6,233.76,234.07,29,200,1,1,233.7,234.12,1200,26,1,1,233.66,234.13,1,400,1,1,233.58,234.17,505,1,2,1,233.53,234.41,10,600,1,2,233.5,234.43,100,105,1,2,233.45,234.5,15,63,1,4,233.4,234.75,110,1,2,1,233.39,234.79,10,2000,1,1,AAPL,20.0,20.0,20.0,
2024-10-21 12:13:45.811467280+00:00,2024-10-21T12:13:45.811636426Z,10,2,38,C,A,0,234.0,3,130,169146,12400067,233.77,234.0,200,131,1,6,233.76,234.07,29,200,1,1,233.7,234.12,1200,26,1,1,233.66,234.13,1,400,1,1,233.58,234.17,505,1,2,1,233.53,234.41,10,600,1,2,233.5,234.43,100,105,1,2,233.45,234.5,15,63,1,4,233.4,234.75,110,1,2,1,233.39,234.79,10,2000,1,1,AAPL,3.0,3.0,23.0,
2024-10-21 12:13:45.811476289+00:00,2024-10-21T12:13:45.811643125Z,10,2,38,C,A,1,234.07,200,130,166836,12400068,233.77,234.0,200,131,1,6,233.76,234.12,29,26,1,1,233.7,234.13,1200,400,1,1,233.66,234.17,1,1,1,1,233.58,234.41,505,600,2,2,233.53,234.43,10,105,1,2,233.5,234.5,100,63,1,4,233.45,234.75,15,1,1,1,233.4,234.79,110,2000,2,1,233.39,234.89,10,2,1,2,AAPL,0.0,0.0,23.0,
2024-10-21 12:13:45.811491355+00:00,2024-10-21T12:13:45.811657243Z,10,2,38,A,B,0,233.9,100,130,165888,12400070,233.9,234.0,100,131,1,6,233.77,234.12,200,26,1,1,233.76,234.13,29,400,1,1,233.7,234.17,1200,1,1,1,233.66,234.41,1,600,1,2,233.58,234.43,505,105,2,2,233.53,234.5,10,63,1,4,233.5,234.75,100,1,1,1,233.45,234.79,15,2000,1,1,233.4,234.89,110,2,2,2,AAPL,0.0,0.0,23.0,
2024-10-21 12:13:45.811500957+00:00,2024-10-21T12:13:45.811666921Z,10,2,38,A,B,0,233.92,100,130,165964,12400071,233.92,234.0,100,131,1,6,233.9,234.12,100,26,1,1,233.77,234.13,200,400,1,1,233.76,234.17,29,1,1,1,233.7,234.41,1200,600,1,2,233.66,234.43,1,105,1,2,233.58,234.5,505,63,2,4,233.53,234.75,10,1,1,1,233.5,234.79,100,2000,1,1,233.45,234.89,15,2,1,2,AAPL,0.0,0.0,23.0,
2024-10-21 12:13:45.811510984+00:00,2024-10-21T12:13:45.811683758Z,10,2,38,T,B,0,234.0,27,0,172774,12400072,233.92,234.0,100,131,1,6,233.9,234.12,100,26,1,1,233.77,234.13,200,400,1,1,233.76,234.17,29,1,1,1,233.7,234.41,1200,600,1,2,233.66,234.43,1,105,1,2,233.58,234.5,505,63,2,4,233.53,234.75,10,1,1,1,233.5,234.79,100,2000,1,1,233.45,234.89,15,2,1,2,AAPL,0.0,0.0,23.0,
2024-10-21 12:13:45.811510984+00:00,2024-10-21T12:13:45.811683758Z,10,2,38,T,B,0,234.0,50,0,172774,12400073,233.92,234.0,100,104,1,5,233.9,234.12,100,26,1,1,233.77,234.13,200,400,1,1,233.76,234.17,29,1,1,1,233.7,234.41,1200,600,1,2,233.66,234.43,1,105,1,2,233.58,234.5,505,63,2,4,233.53,234.75,10,1,1,1,233.5,234.79,100,2000,1,1,233.45,234.89,15,2,1,2,AAPL,27.0,27.0,50.0,
2024-10-21 12:13:45.811510984+00:00,2024-10-21T12:13:45.811683758Z,10,2,38,T,B,0,234.0,2,0,172774,12400074,233.92,234.0,100,54,1,4,233.9,234.12,100,26,1,1,233.77,234.13,200,400,1,1,233.76,234.17,29,1,1,1,233.7,234.41,1200,600,1,2,233.66,234.43,1,105,1,2,233.58,234.5,505,63,2,4,233.53,234.75,10,1,1,1,233.5,234.79,100,2000,1,1,233.45,234.89,15,2,1,2,AAPL,50.0,50.0,100.0,
2024-10-21 12:13:45.811510984+00:00,2024-10-21T12:13:45.811683758Z,10,2,38,T,B,0,234.0,1,0,172774,12400075,233.92,234.0,100,52,1,3,233.9,234.12,100,26,1,1,233.77,234.13,200,400,1,1,233.76,234.17,29,1,1,1,233.7,234.41,1200,600,1,2,233.66,234.43,1,105,1,2,233.58,234.5,505,63,2,4,233.53,234.75,10,1,1,1,233.5,234.79,100,2000,1,1,233.45,234.89,15,2,1,2,AAPL,2.0,2.0,102.0,
2024-10-21 12:13:45.811510984+00:00,2024-10-21T12:13:45.811683758Z,10,2,38,T,B,0,234.0,50,0,172774,12400076,233.92,234.0,100,51,1,2,233.9,234.12,100,26,1,1,233.77,234.13,200,400,1,1,233.76,234.17,29,1,1,1,233.7,234.41,1200,600,1,2,233.66,234.43,1,105,1,2,233.58,234.5,505,63,2,4,233.53,234.75,10,1,1,1,233.5,234.79,100,2000,1,1,233.45,234.89,15,2,1,2,AAPL,1.0,1.0,103.0,
2024-10-21 12:13:45.811510984+00:00,2024-10-21T12:13:45.811683758Z,10,2,38,T,B,0,234.0,1,130,172774,12400077,233.92,234.0,100,1,1,1,233.9,234.12,100,26,1,1,233.77,234.13,200,400,1,1,233.76,234.17,29,1,1,1,233.7,234.41,1200,600,1,2,233.66,234.43,1,105,1,2,233.58,234.5,505,63,2,4,233.53,234.75,10,1,1,1,233.5,234.79,100,2000,1,1,233.45,234.89,15,2,1,2,AAPL,50.0,50.0,153.0,
2024-10-21 12:13:45.811510984+00:00,2024-10-21T12:13:45.811683758Z,10,2,38,C,A,0,234.0,1,130,172774,12400077,233.92,234.12,100,26,1,1,233.9,234.13,100,400,1,1,233.77,234.17,200,1,1,1,233.76,234.41,29,600,1,2,233.7,234.43,1200,105,1,2,233.66,234.5,1,63,1,4,233.58,234.75,505,1,2,1,233.53,234.79,10,2000,1,1,233.5,234.89,100,2,1,2,233.45,235.0,15,213,1,6,AAPL,0.0,0.0,153.0,
2024-10-21 12:13:45.811530148+00:00,2024-10-21T12:13:45.811695806Z,10,2,38,C,B,1,233.9,100,130,165658,12400078,233.92,234.12,100,26,1,1,233.77,234.13,200,400,1,1,233.76,234.17,29,1,1,1,233.7,234.41,1200,600,1,2,233.66,234.43,1,105,1,2,233.58,234.5,505,63,2,4,233.53,234.75,10,1,1,1,233.5,234.79,100,2000,1,1,233.45,234.89,15,2,1,2,233.4,235.0,110,213,2,6,AAPL,0.0,0.0,153.0,
2024-10-21 12:13:45.811542984+00:00,2024-10-21T12:13:45.811710080Z,10,2,38,A,B,0,233.96,100,130,167096,12400079,233.96,234.12,100,26,1,1,233.92,234.13,100,400,1,1,233.77,234.17,200,1,1,1,233.76,234.41,29,600,1,2,233.7,234.43,1200,105,1,2,233.66,234.5,1,63,1,4,233.58,234.75,505,1,2,1,233.53,234.79,10,2000,1,1,233.5,234.89,100,2,1,2,233.45,235.0,15,213,1,6,AAPL,0.0,0.0,153.0,
2024-10-21 12:13:45.811544514+00:00,2024-10-21T12:13:45.811712078Z,10,2,38,A,B,0,233.96,24,130,167564,12400080,233.96,234.12,124,26,2,1,233.92,234.13,100,400,1,1,233.77,234.17,200,1,1,1,233.76,234.41,29,600,1,2,233.7,234.43,1200,105,1,2,233.66,234.5,1,63,1,4,233.58,234.75,505,1,2,1,233.53,234.79,10,2000,1,1,233.5,234.89,100,2,1,2,233.45,235.0,15,213,1,6,AAPL,24.0,24.0,177.0,
2024-10-21 12:13:45.811549682+00:00,2024-10-21T12:13:45.811715761Z,10,2,38,A,B,1,233.94,100,130,166079,12400081,233.96,234.12,124,26,2,1,233.94,234.13,100,400,1,1,233.92,234.17,100,1,1,1,233.77,234.41,200,600,1,2,233.76,234.43,29,105,1,2,233.7,234.5,1200,63,1,4,233.66,234.75,1,1,1,1,233.58,234.79,505,2000,2,1,233.53,234.89,10,2,1,2,233.5,235.0,100,213,1,6,AAPL,0.0,0.0,177.0,
2024-10-21 12:13:45.811550754+00:00,2024-10-21T12:13:45.811718296Z,10,2,38,A,B,0,233.96,28,130,167542,12400082,233.96,234.12,152,26,3,1,233.94,234.13,100,400,1,1,233.92,234.17,100,1,1,1,233.77,234.41,200,600,1,2,233.76,234.43,29,105,1,2,233.7,234.5,1200,63,1,4,233.66,234.75,1,1,1,1,233.58,234.79,505,2000,2,1,233.53,234.89,10,2,1,2,233.5,235.0,100,213,1,6,AAPL,28.0,28.0,205.0,
2024-10-21 12:13:45.811554820+00:00,2024-10-21T12:13:45.811721349Z,10,2,38,A,B,0,233.96,100,130,166529,12400083,233.96,234.12,252,26,4,1,233.94,234.13,100,400,1,1,233.92,234.17,100,1,1,1,233.77,234.41,200,600,1,2,233.76,234.43,29,105,1,2,233.7,234.5,1200,63,1,4,233.66,234.75,1,1,1,1,233.58,234.79,505,2000,2,1,233.53,234.89,10,2,1,2,233.5,235.0,100,213,1,6,AAPL,100.0,100.0,305.0,
2024-10-21 12:13:45.811565809+00:00,2024-10-21T12:13:45.811732936Z,10,2,38,A,B,0,233.96,100,128,167127,12400085,233.96,234.12,352,26,5,1,233.94,234.13,100,400,1,1,233.93,234.17,28,1,1,1,233.92,234.41,100,600,1,2,233.77,234.43,200,105,1,2,233.76,234.5,29,63,1,4,233.7,234.75,1200,1,1,1,233.66,234.79,1,2000,1,1,233.58,234.89,505,2,2,2,233.53,235.0,10,213,1,6,AAPL,100.0,100.0,405.0,
2024-10-21 12:13:45.811576962+00:00,2024-10-21T12:13:45.811742859Z,10,2,38,A,B,0,233.96,100,130,165897,12400087,233.96,234.12,452,26,6,1,233.94,234.13,100,400,1,1,233.93,234.17,28,1,1,1,233.92,234.41,100,600,1,2,233.77,234.43,200,105,1,2,233.76,234.5,29,63,1,4,233.7,234.75,1200,1,1,1,233.66,234.79,1,2000,1,1,233.58,234.89,505,2,2,2,233.53,235.0,10,213,1,6,AAPL,100.0,100.0,505.0,
2024-10-21 12:13:45.811587865+00:00,2024-10-21T12:13:45.811753896Z,10,2,38,A,B,0,233.96,100,130,166031,12400088,233.96,234.12,552,26,7,1,233.94,234.13,100,400,1,1,233.93,234.17,28,1,1,1,233.92,234.41,100,600,1,2,233.77,234.43,200,105,1,2,233.76,234.5,29,63,1,4,233.7,234.75,1200,1,1,1,233.66,234.79,1,2000,1,1,233.58,234.89,505,2,2,2,233.53,235.0,10,213,1,6,AAPL,100.0,100.0,605.0,
2024-10-21 12:13:45.811599315+00:00,2024-10-21T12:13:45.811765786Z,10,2,38,A,B,1,233.94,100,130,166471,12400089,233.96,234.12,552,26,7,1,233.94,234.13,200,400,2,1,233.93,234.17,28,1,1,1,233.92,234.41,100,600,1,2,233.77,234.43,200,105,1,2,233.76,234.5,29,63,1,4,233.7,234.75,1200,1,1,1,233.66,234.79,1,2000,1,1,233.58,234.89,505,2,2,2,233.53,235.0,10,213,1,6,AAPL,0.0,100.0,605.0,
2024-10-21 12:13:45.811625820+00:00,2024-10-21T12:13:45.811791584Z,10,2,38,C,B,0,233.96,100,130,165764,12400091,233.96,234.12,452,26,6,1,233.94,234.13,200,400,2,1,233.93,234.17,28,1,1,1,233.92,234.41,100,600,1,2,233.77,234.43,200,105,1,2,233.76,234.5,29,63,1,4,233.7,234.75,1200,1,1,1,233.66,234.79,1,2000,1,1,233.58,234.89,505,2,2,2,233.53,235.0,10,213,1,6,AAPL,-100.0,-100.0,505.0,
2024-10-21 12:13:45.811631245+00:00,2024-10-21T12:13:45.811800458Z,10,2,38,T,N,0,234.0,145,130,169213,12400092,233.96,234.12,452,26,6,1,233.94,234.13,200,400,2,1,233.93,234.17,28,1,1,1,233.92,234.41,100,600,1,2,233.77,234.43,200,105,1,2,233.76,234.5,29,63,1,4,233.7,234.75,1200,1,1,1,233.66,234.79,1,2000,1,1,233.58,234.89,505,2,2,2,233.53,235.0,10,213,1,6,AAPL,0.0,0.0,505.0,
2024-10-21 12:13:45.811639570+00:00,2024-10-21T12:13:45.811805292Z,10,2,38,C,B,1,233.94,100,130,165722,12400093,233.96,234.12,452,26,6,1,233.94,234.13,100,400,1,1,233.93,234.17,28,1,1,1,233.92,234.41,100,600,1,2,233.77,234.43,200,105,1,2,233.76,234.5,29,63,1,4,233.7,234.75,1200,1,1,1,233.66,234.79,1,2000,1,1,233.58,234.89,505,2,2,2,233.53,235.0,10,213,1,6,AAPL,0.0,-100.0,505.0,
2024-10-21 12:13:45.811642361+00:00,2024-10-21T12:13:45.811808010Z,10,2,38,C,B,0,233.96,100,130,165649,12400094,233.96,234.12,352,26,5,1,233.94,234.13,100,400,1,1,233.93,234.17,28,1,1,1,233.92,234.41,100,600,1,2,233.77,234.43,200,105,1,2,233.76,234.5,29,63,1,4,233.7,234.75,1200,1,1,1,233.66,234.79,1,2000,1,1,233.58,234.89,505,2,2,2,233.53,235.0,10,213,1,6,AAPL,-100.0,-100.0,405.0,
2024-10-21 12:13:45.811656818+00:00,2024-10-21T12:13:45.811822560Z,10,2,38,C,B,0,233.96,100,130,165742,12400095,233.96,234.12,252,26,4,1,233.94,234.13,100,400,1,1,233.93,234.17,28,1,1,1,233.92,234.41,100,600,1,2,233.77,234.43,200,105,1,2,233.76,234.5,29,63,1,4,233.7,234.75,1200,1,1,1,233.66,234.79,1,2000,1,1,233.58,234.89,505,2,2,2,233.53,235.0,10,213,1,6,AAPL,-100.0,-100.0,305.0,
2024-10-21 12:13:45.811672313+00:00,2024-10-21T12:13:45.811837891Z,10,2,38,C,B,0,233.96,100,130,165578,12400096,233.96,234.12,152,26,3,1,233.94,234.13,100,400,1,1,233.93,234.17,28,1,1,1,233.92,234.41,100,600,1,2,233.77,234.43,200,105,1,2,233.76,234.5,29,63,1,4,233.7,234.75,1200,1,1,1,233.66,234.79,1,2000,1,1,233.58,234.89,505,2,2,2,233.53,235.0,10,213,1,6,AAPL,-100.0,-100.0,205.0,
2024-10-21 12:13:45.811687403+00:00,2024-10-21T12:13:45.811853381Z,10,2,38,C,B,0,233.96,100,130,165978,12400097,233.96,234.12,52,26,2,1,233.94,234.13,100,400,1,1,233.93,234.17,28,1,1,1,233.92,234.41,100,600,1,2,233.77,234.43,200,105,1,2,233.76,234.5,29,63,1,4,233.7,234.75,1200,1,1,1,233.66,234.79,1,2000,1,1,233.58,234.89,505,2,2,2,233.53,235.0,10,213,1,6,AAPL,-100.0,-100.0,105.0,
2024-10-21 12:13:45.811702067+00:00,2024-10-21T12:13:45.811867704Z,10,2,38,C,B,1,233.94,100,130,165637,12400098,233.96,234.12,52,26,2,1,233.93,234.13,28,400,1,1,233.92,234.17,100,1,1,1,233.77,234.41,200,600,1,2,233.76,234.43,29,105,1,2,233.7,234.5,1200,63,1,4,233.66,234.75,1,1,1,1,233.58,234.79,505,2000,2,1,233.53,234.89,10,2,1,2,233.5,235.0,100,213,1,6,AAPL,0.0,0.0,105.0,
2024-10-21 12:13:45.812035805+00:00,2024-10-21T12:13:45.812203001Z,10,2,38,A,B,3,233.9,100,130,167196,12400100,233.96,234.12,52,26,2,1,233.93,234.13,28,400,1,1,233.92,234.17,100,1,1,1,233.9,234.41,100,600,1,2,233.77,234.43,200,105,1,2,233.76,234.5,29,63,1,4,233.7,234.75,1200,1,1,1,233.66,234.79,1,2000,1,1,233.58,234.89,505,2,2,2,233.53,235.0,10,213,1,6,AAPL,0.0,0.0,105.0,
2024-10-21 12:13:45.812481448+00:00,2024-10-21T12:13:45.812647427Z,10,2,38,C,B,3,233.9,100,130,165979,12400102,233.96,234.12,52,26,2,1,233.93,234.13,28,400,1,1,233.92,234.17,100,1,1,1,233.77,234.41,200,600,1,2,233.76,234.43,29,105,1,2,233.7,234.5,1200,63,1,4,233.66,234.75,1,1,1,1,233.58,234.79,505,2000,2,1,233.53,234.89,10,2,1,2,233.5,235.0,100,213,1,6,AAPL,0.0,0.0,105.0,
2024-10-21 12:13:45.813014463+00:00,2024-10-21T12:13:45.813181508Z,10,2,38,T,N,0,234.08,1,130,167045,12400103,233.96,234.12,52,26,2,1,233.93,234.13,28,400,1,1,233.92,234.17,100,1,1,1,233.77,234.41,200,600,1,2,233.76,234.43,29,105,1,2,233.7,234.5,1200,63,1,4,233.66,234.75,1,1,1,1,233.58,234.79,505,2000,2,1,233.53,234.89,10,2,1,2,233.5,235.0,100,213,1,6,AAPL,0.0,0.0,105.0,
2024-10-21 12:13:45.813822327+00:00,2024-10-21T12:13:45.813988388Z,10,2,38,C,B,2,233.92,100,130,166061,12400110,233.96,234.12,52,26,2,1,233.93,234.13,28,400,1,1,233.77,234.17,200,1,1,1,233.76,234.41,29,600,1,2,233.7,234.43,1200,105,1,2,233.66,234.5,1,63,1,4,233.58,234.75,505,1,2,1,233.53,234.79,10,2000,1,1,233.5,234.89,100,2,1,2,233.45,235.0,15,213,1,6,AAPL,0.0,0.0,105.0,
2024-10-21 12:13:45.885550872+00:00,2024-10-21T12:13:45.885716957Z,10,2,38,C,A,0,234.12,26,130,166085,12401368,233.96,234.13,52,400,2,1,233.93,234.17,28,1,1,1,233.77,234.41,200,600,1,2,233.76,234.43,29,105,1,2,233.7,234.5,1200,63,1,4,233.66,234.75,1,1,1,1,233.58,234.79,505,2000,2,1,233.53,234.89,10,2,1,2,233.5,235.0,100,213,1,6,233.45,235.03,15,2,1,1,AAPL,0.0,0.0,105.0,
2024-10-21 12:13:45.885603142+00:00,2024-10-21T12:13:45.885769234Z,10,2,38,A,A,2,234.18,27,130,166092,12401370,233.96,234.13,52,400,2,1,233.93,234.17,28,1,1,1,233.77,234.18,200,27,1,1,233.76,234.41,29,600,1,2,233.7,234.43,1200,105,1,2,233.66,234.5,1,63,1,4,233.58,234.75,505,1,2,1,233.53,234.79,10,2000,1,1,233.5,234.89,100,2,1,2,233.45,235.0,15,213,1,6,AAPL,0.0,0.0,105.0,
2024-10-21 12:13:45.911619430+00:00,2024-10-21T12:13:45.911785815Z,10,2,38,C,B,0,233.96,24,130,166385,12401559,233.96,234.13,28,400,1,1,233.93,234.17,28,1,1,1,233.77,234.18,200,27,1,1,233.76,234.41,29,600,1,2,233.7,234.43,1200,105,1,2,233.66,234.5,1,63,1,4,233.58,234.75,505,1,2,1,233.53,234.79,10,2000,1,1,233.5,234.89,100,2,1,2,233.45,235.0,15,213,1,6,AAPL,-24.0,-24.0,81.0,
2024-10-21 12:13:45.911645974+00:00,2024-10-21T12:13:45.911812280Z,10,2,38,C,B,1,233.93,28,130,166306,12401560,233.96,234.13,28,400,1,1,233.77,234.17,200,1,1,1,233.76,234.18,29,27,1,1,233.7,234.41,1200,600,1,2,233.66,234.43,1,105,1,2,233.58,234.5,505,63,2,4,233.53,234.75,10,1,1,1,233.5,234.79,100,2000,1,1,233.45,234.89,15,2,1,2,233.4,235.0,110,213,2,6,AAPL,0.0,0.0,81.0,
2024-10-21 12:13:45.935267342+00:00,2024-10-21T12:13:45.935434703Z,10,2,38,A,B,1,233.78,200,128,167361,12401727,233.96,234.13,28,400,1,1,233.78,234.17,200,1,1,1,233.76,234.18,29,27,1,1,233.7,234.41,1200,600,1,2,233.66,234.43,1,105,1,2,233.58,234.5,505,63,2,4,233.53,234.75,10,1,1,1,233.5,234.79,100,2000,1,1,233.45,234.89,15,2,1,2,233.4,235.0,110,213,2,6,AAPL,0.0,0.0,81.0,
2024-10-21 12:13:45.969596688+00:00,2024-10-21T12:13:45.969762895Z,10,2,38,A,A,0,234.12,200,130,166207,12401874,233.96,234.12,28,200,1,1,233.78,234.13,200,400,1,1,233.76,234.17,29,1,1,1,233.7,234.18,1200,27,1,1,233.66,234.41,1,600,1,2,233.58,234.43,505,105,2,2,233.53,234.5,10,63,1,4,233.5,234.75,100,1,1,1,233.45,234.79,15,2000,1,1,233.4,234.89,110,2,2,2,AAPL,0.0,0.0,81.0,
2024-10-21 12:13:45.972210032+00:00,2024-10-21T12:13:45.972375870Z,10,2,38,C,A,0,234.12,200,130,165838,12401877,233.96,234.13,28,400,1,1,233.78,234.17,200,1,1,1,233.76,234.18,29,27,1,1,233.7,234.41,1200,600,1,2,233.66,234.43,1,105,1,2,233.58,234.5,505,63,2,4,233.53,234.75,10,1,1,1,233.5,234.79,100,2000,1,1,233.45,234.89,15,2,1,2,233.4,235.0,110,213,2,6,AAPL,0.0,0.0,81.0,
2024-10-21 12:13:45.973580511+00:00,2024-10-21T12:13:45.973746612Z,10,2,38,A,A,3,234.19,200,130,166101,12401884,233.96,234.13,28,400,1,1,233.78,234.17,200,1,1,1,233.76,234.18,29,27,1,1,233.7,234.19,1200,200,1,1,233.66,234.41,1,600,1,2,233.58,234.43,505,105,2,2,233.53,234.5,10,63,1,4,233.5,234.75,100,1,1,1,233.45,234.79,15,2000,1,1,233.4,234.89,110,2,2,2,AAPL,0.0,0.0,81.0,
2024-10-21 12:13:46.001375930+00:00,2024-10-21T12:13:46.001542260Z,10,2,38,A,A,3,234.19,200,130,166330,12401962,233.96,234.13,28,400,1,1,233.78,234.17,200,1,1,1,233.76,234.18,29,27,1,1,233.7,234.19,1200,400,1,2,233.66,234.41,1,600,1,2,233.58,234.43,505,105,2,2,233.53,234.5,10,63,1,4,233.5,234.75,100,1,1,1,233.45,234.79,15,2000,1,1,233.4,234.89,110,2,2,2,AAPL,0.0,-200.0,81.0,
2024-10-21 12:13:46.030378750+00:00,2024-10-21T12:13:46.030544628Z,10,2,38,C,A,3,234.19,200,130,165878,12402092,233.96,234.13,28,400,1,1,233.78,234.17,200,1,1,1,233.76,234.18,29,27,1,1,233.7,234.19,1200,200,1,1,233.66,234.41,1,600,1,2,233.58,234.43,505,105,2,2,233.53,234.5,10,63,1,4,233.5,234.75,100,1,1,1,233.45,234.79,15,2000,1,1,233.4,234.89,110,2,2,2,AAPL,0.0,200.0,81.0,
2024-10-21 12:13:46.030391116+00:00,2024-10-21T12:13:46.030557325Z,10,2,38,A,A,0,234.12,400,130,166209,12402093,233.96,234.12,28,400,1,1,233.78,234.13,200,400,1,1,233.76,234.17,29,1,1,1,233.7,234.18,1200,27,1,1,233.66,234.41,1,600,1,2,233.58,234.43,505,105,2,2,233.53,234.5,10,63,1,4,233.5,234.75,100,1,1,1,233.45,234.79,15,2000,1,1,233.4,234.89,110,2,2,2,AAPL,0.0,0.0,81.0,
2024-10-21 12:13:46.063235483+00:00,2024-10-21T12:13:46.063401404Z,10,2,38,C,B,0,233.96,28,130,165921,12402125,233.78,234.12,200,400,1,1,233.76,234.13,29,400,1,1,233.7,234.17,1200,1,1,1,233.66,234.18,1,27,1,1,233.58,234.41,505,600,2,2,233.53,234.43,10,105,1,2,233.5,234.5,100,63,1,4,233.45,234.75,15,1,1,1,233.4,234.79,110,2000,2,1,233.39,234.89,10,2,1,2,AAPL,0.0,0.0,81.0,
2024-10-21 12:13:46.072722298+00:00,2024-10-21T12:13:46.072888556Z,10,2,38,C,A,0,234.12,400,130,166258,12402143,233.78,234.13,200,400,1,1,233.76,234.17,29,1,1,1,233.7,234.18,1200,27,1,1,233.66,234.41,1,600,1,2,233.58,234.43,505,105,2,2,233.53,234.5,10,63,1,4,233.5,234.75,100,1,1,1,233.45,234.79,15,2000,1,1,233.4,234.89,110,2,2,2,233.39,235.0,10,213,1,6,AAPL,0.0,0.0,81.0,
2024-10-21 12:13:46.072745549+00:00,2024-10-21T12:13:46.072911952Z,10,2,38,A,A,0,234.13,200,130,166403,12402144,233.78,234.13,200,600,1,2,233.76,234.17,29,1,1,1,233.7,234.18,1200,27,1,1,233.66,234.41,1,600,1,2,233.58,234.43,505,105,2,2,233.53,234.5,10,63,1,4,233.5,234.75,100,1,1,1,233.45,234.79,15,2000,1,1,233.4,234.89,110,2,2,2,233.39,235.0,10,213,1,6,AAPL,-200.0,-200.0,-119.0,
2024-10-21 12:13:46.073052339+00:00,2024-10-21T12:13:46.073218239Z,10,2,38,C,B,1,233.76,29,130,165900,12402146,233.78,234.13,200,600,1,2,233.7,234.17,1200,1,1,1,233.66,234.18,1,27,1,1,233.58,234.41,505,600,2,2,233.53,234.43,10,105,1,2,233.5,234.5,100,63,1,4,233.45,234.75,15,1,1,1,233.4,234.79,110,2000,2,1,233.39,234.89,10,2,1,2,233.31,235.0,110,213,2,6,AAPL,0.0,0.0,-119.0,
2024-10-21 12:13:46.073137112+00:00,2024-10-21T12:13:46.073303600Z,10,2,38,A,B,0,233.81,27,130,166488,12402147,233.81,234.13,27,600,1,2,233.78,234.17,200,1,1,1,233.7,234.18,1200,27,1,1,233.66,234.41,1,600,1,2,233.58,234.43,505,105,2,2,233.53,234.5,10,63,1,4,233.5,234.75,100,1,1,1,233.45,234.79,15,2000,1,1,233.4,234.89,110,2,2,2,233.39,235.0,10,213,1,6,AAPL,0.0,0.0,-119.0,
2024-10-21 12:13:46.123324204+00:00,2024-10-21T12:13:46.123490913Z,10,2,38,A,B,0,233.83,200,130,166709,12402220,233.83,234.13,200,600,1,2,233.81,234.17,27,1,1,1,233.7,234.18,1200,27,1,1,233.66,234.41,1,600,1,2,233.58,234.43,505,105,2,2,233.53,234.5,10,63,1,4,233.5,234.75,100,1,1,1,233.45,234.79,15,2000,1,1,233.4,234.89,110,2,2,2,233.39,235.0,10,213,1,6,AAPL,0.0,0.0,-119.0,
2024-10-21 12:13:46.134353286+00:00,2024-10-21T12:13:46.134519400Z,10,2,38,C,B,0,233.83,200,130,166114,12402230,233.81,234.13,27,600,1,2,233.7,234.17,1200,1,1,1,233.66,234.18,1,27,1,1,233.58,234.41,505,600,2,2,233.53,234.43,10,105,1,2,233.5,234.5,100,63,1,4,233.45,234.75,15,1,1,1,233.4,234.79,110,2000,2,1,233.39,234.89,10,2,1,2,233.31,235.0,110,213,2,6,AAPL,0.0,0.0,-119.0,
2024-10-21 12:13:46.134366429+00:00,2024-10-21T12:13:46.134533664Z,10,2,38,A,B,1,233.78,200,130,167235,12402231,233.81,234.13,27,600,1,2,233.78,234.17,200,1,1,1,233.7,234.18,1200,27,1,1,233.66,234.41,1,600,1,2,233.58,234.43,505,105,2,2,233.53,234.5,10,63,1,4,233.5,234.75,100,1,1,1,233.45,234.79,15,2000,1,1,233.4,234.89,110,2,2,2,233.39,235.0,10,213,1,6,AAPL,0.0,0.0,-119.0,
2024-10-21 12:13:46.134809159+00:00,2024-10-21T12:13:46.134975052Z,10,2,38,C,B,0,233.81,27,130,165893,12402233,233.78,234.13,200,600,1,2,233.7,234.17,1200,1,1,1,233.66,234.18,1,27,1,1,233.58,234.41,505,600,2,2,233.53,234.43,10,105,1,2,233.5,234.5,100,63,1,4,233.45,234.75,15,1,1,1,233.4,234.79,110,2000,2,1,233.39,234.89,10,2,1,2,233.31,235.0,110,213,2,6,AAPL,0.0,0.0,-119.0,
2024-10-21 12:13:47.415362307+00:00,2024-10-21T12:13:47.415528384Z,10,2,38,A,B,1,233.76,27,130,166077,12403393,233.78,234.13,200,600,1,2,233.76,234.17,27,1,1,1,233.7,234.18,1200,27,1,1,233.66,234.41,1,600,1,2,233.58,234.43,505,105,2,2,233.53,234.5,10,63,1,4,233.5,234.75,100,1,1,1,233.45,234.79,15,2000,1,1,233.4,234.89,110,2,2,2,233.39,235.0,10,213,1,6,AAPL,0.0,0.0,0.0,
2024-10-21 12:13:48.136368928+00:00,2024-10-21T12:13:48.136535794Z,10,2,38,C,A,0,234.13,200,130,166866,12404229,233.78,234.13,200,400,1,1,233.76,234.17,27,1,1,1,233.7,234.18,1200,27,1,1,233.66,234.41,1,600,1,2,233.58,234.43,505,105,2,2,233.53,234.5,10,63,1,4,233.5,234.75,100,1,1,1,233.45,234.79,15,2000,1,1,233.4,234.89,110,2,2,2,233.39,235.0,10,213,1,6,AAPL,200.0,200.0,200.0,
2024-10-21 12:13:48.136382005+00:00,2024-10-21T12:13:48.136548342Z,10,2,38,A,A,1,234.16,200,130,166337,12404230,233.78,234.13,200,400,1,1,233.76,234.16,27,200,1,1,233.7,234.17,1200,1,1,1,233.66,234.18,1,27,1,1,233.58,234.41,505,600,2,2,233.53,234.43,10,105,1,2,233.5,234.5,100,63,1,4,233.45,234.75,15,1,1,1,233.4,234.79,110,2000,2,1,233.39,234.89,10,2,1,2,AAPL,0.0,0.0,200.0,
2024-10-21 12:13:54.483288659+00:00,2024-10-21T12:13:54.483454950Z,10,2,38,A,A,1,234.16,200,130,166291,12409382,233.78,234.13,200,400,1,1,233.76,234.16,27,400,1,2,233.7,234.17,1200,1,1,1,233.66,234.18,1,27,1,1,233.58,234.41,505,600,2,2,233.53,234.43,10,105,1,2,233.5,234.5,100,63,1,4,233.45,234.75,15,1,1,1,233.4,234.79,110,2000,2,1,233.39,234.89,10,2,1,2,AAPL,0.0,-200.0,0.0,
2024-10-21 12:13:54.519759447+00:00,2024-10-21T12:13:54.519925421Z,10,2,38,C,A,1,234.16,200,130,165974,12409407,233.78,234.13,200,400,1,1,233.76,234.16,27,200,1,1,233.7,234.17,1200,1,1,1,233.66,234.18,1,27,1,1,233.58,234.41,505,600,2,2,233.53,234.43,10,105,1,2,233.5,234.5,100,63,1,4,233.45,234.75,15,1,1,1,233.4,234.79,110,2000,2,1,233.39,234.89,10,2,1,2,AAPL,0.0,200.0,0.0,
2024-10-21 12:13:54.519772638+00:00,2024-10-21T12:13:54.519938916Z,10,2,38,A,A,1,234.15,200,130,166278,12409408,233.78,234.13,200,400,1,1,233.76,234.15,27,200,1,1,233.7,234.17,1200,1,1,1,233.66,234.18,1,27,1,1,233.58,234.41,505,600,2,2,233.53,234.43,10,105,1,2,233.5,234.5,100,63,1,4,233.45,234.75,15,1,1,1,233.4,234.79,110,2000,2,1,233.39,234.89,10,2,1,2,AAPL,0.0,0.0,0.0,
2024-10-21 12:13:55.034111535+00:00,2024-10-21T12:13:55.034277634Z,10,2,38,C,A,3,234.18,27,130,166099,12410122,233.78,234.13,200,400,1,1,233.76,234.15,27,200,1,1,233.7,234.17,1200,1,1,1,233.66,234.41,1,600,1,2,233.58,234.43,505,105,2,2,233.53,234.5,10,63,1,4,233.5,234.75,100,1,1,1,233.45,234.79,15,2000,1,1,233.4,234.89,110,2,2,2,233.39,235.0,10,213,1,6,AAPL,0.0,0.0,0.0,
2024-10-21 12:13:55.034202690+00:00,2024-10-21T12:13:55.034369213Z,10,2,38,A,A,2,234.17,28,130,166523,12410123,233.78,234.13,200,400,1,1,233.76,234.15,27,200,1,1,233.7,234.17,1200,29,1,2,233.66,234.41,1,600,1,2,233.58,234.43,505,105,2,2,233.53,234.5,10,63,1,4,233.5,234.75,100,1,1,1,233.45,234.79,15,2000,1,1,233.4,234.89,110,2,2,2,233.39,235.0,10,213,1,6,AAPL,0.0,-28.0,0.0,
2024-10-21 12:13:56.094538941+00:00,2024-10-21T12:13:56.094704759Z,10,2,38,C,B,0,233.78,200,130,165818,12410937,233.76,234.13,27,400,1,1,233.7,234.15,1200,200,1,1,233.66,234.17,1,29,1,2,233.58,234.41,505,600,2,2,233.53,234.43,10,105,1,2,233.5,234.5,100,63,1,4,233.45,234.75,15,1,1,1,233.4,234.79,110,2000,2,1,233.39,234.89,10,2,1,2,233.31,235.0,110,213,2,6,AAPL,0.0,0.0,0.0,
2024-10-21 12:13:56.094551306+00:00,2024-10-21T12:13:56.094717739Z,10,2,38,A,B,0,233.76,200,130,166433,12410939,233.76,234.13,227,400,2,1,233.7,234.15,1200,200,1,1,233.66,234.17,1,29,1,2,233.58,234.41,505,600,2,2,233.53,234.43,10,105,1,2,233.5,234.5,100,63,1,4,233.45,234.75,15,1,1,1,233.4,234.79,110,2000,2,1,233.39,234.89,10,2,1,2,233.31,235.0,110,213,2,6,AAPL,200.0,200.0,200.0,
2024-10-21 12:13:56.154206963+00:00,2024-10-21T12:13:56.154373830Z,10,2,38,A,A,1,234.15,200,130,166867,12411142,233.76,234.13,227,400,2,1,233.7,234.15,1200,400,1,2,233.66,234.17,1,29,1,2,233.58,234.41,505,600,2,2,233.53,234.43,10,105,1,2,233.5,234.5,100,63,1,4,233.45,234.75,15,1,1,1,233.4,234.79,110,2000,2,1,233.39,234.89,10,2,1,2,233.31,235.0,110,213,2,6,AAPL,0.0,-200.0,200.0,
2024-10-21 12:13:56.211718188+00:00,2024-10-21T12:13:56.211883968Z,10,2,38,C,A,1,234.15,200,130,165780,12411252,233.76,234.13,227,400,2,1,233.7,234.15,1200,200,1,1,233.66,234.17,1,29,1,2,233.58,234.41,505,600,2,2,233.53,234.43,10,105,1,2,233.5,234.5,100,63,1,4,233.45,234.75,15,1,1,1,233.4,234.79,110,2000,2,1,233.39,234.89,10,2,1,2,233.31,235.0,110,213,2,6,AAPL,0.0,200.0,200.0,
2024-10-21 12:13:56.211731379+00:00,2024-10-21T12:13:56.211897481Z,10,2,38,A,A,1,234.14,200,130,166102,12411253,233.76,234.13,227,400,2,1,233.7,234.14,1200,200,1,1,233.66,234.17,1,29,1,2,233.58,234.41,505,600,2,2,233.53,234.43,10,105,1,2,233.5,234.5,100,63,1,4,233.45,234.75,15,1,1,1,233.4,234.79,110,2000,2,1,233.39,234.89,10,2,1,2,233.31,235.0,110,213,2,6,AAPL,0.0,0.0,200.0,
2024-10-21 12:14:01.070964390+00:00,2024-10-21T12:14:01.071130699Z,10,2,38,C,A,2,234.17,28,130,166309,12416529,233.76,234.13,227,400,2,1,233.7,234.14,1200,200,1,1,233.66,234.17,1,1,1,1,233.58,234.41,505,600,2,2,233.53,234.43,10,105,1,2,233.5,234.5,100,63,1,4,233.45,234.75,15,1,1,1,233.4,234.79,110,2000,2,1,233.39,234.89,10,2,1,2,233.31,235.0,110,213,2,6,AAPL,0.0,28.0,0.0,
2024-10-21 12:14:01.071015450+00:00,2024-10-21T12:14:01.071182062Z,10,2,38,A,A,2,234.16,27,130,166612,12416530,233.76,234.13,227,400,2,1,233.7,234.14,1200,200,1,1,233.66,234.16,1,27,1,1,233.58,234.17,505,1,2,1,233.53,234.41,10,600,1,2,233.5,234.43,100,105,1,2,233.45,234.5,15,63,1,4,233.4,234.75,110,1,2,1,233.39,234.79,10,2000,1,1,233.31,234.89,110,2,2,2,AAPL,0.0,0.0,0.0,
2024-10-21 12:14:01.088137086+00:00,2024-10-21T12:14:01.088302919Z,10,2,38,C,B,0,233.76,27,130,165833,12416650,233.76,234.13,200,400,1,1,233.7,234.14,1200,200,1,1,233.66,234.16,1,27,1,1,233.58,234.17,505,1,2,1,233.53,234.41,10,600,1,2,233.5,234.43,100,105,1,2,233.45,234.5,15,63,1,4,233.4,234.75,110,1,2,1,233.39,234.79,10,2000,1,1,233.31,234.89,110,2,2,2,AAPL,-27.0,-27.0,-27.0,
2024-10-21 12:14:06.103454338+00:00,2024-10-21T12:14:06.103621053Z,10,2,38,A,B,0,233.97,5,130,166715,12421860,233.97,234.13,5,400,1,1,233.76,234.14,200,200,1,1,233.7,234.16,1200,27,1,1,233.66,234.17,1,1,1,1,233.58,234.41,505,600,2,2,233.53,234.43,10,105,1,2,233.5,234.5,100,63,1,4,233.45,234.75,15,1,1,1,233.4,234.79,110,2000,2,1,233.39,234.89,10,2,1,2,AAPL,0.0,0.0,0.0,
2024-10-21 12:14:07.746740079+00:00,2024-10-21T12:14:07.746906258Z,10,2,38,C,B,1,233.76,200,130,166179,12423513,233.97,234.13,5,400,1,1,233.7,234.14,1200,200,1,1,233.66,234.16,1,27,1,1,233.58,234.17,505,1,2,1,233.53,234.41,10,600,1,2,233.5,234.43,100,105,1,2,233.45,234.5,15,63,1,4,233.4,234.75,110,1,2,1,233.39,234.79,10,2000,1,1,233.31,234.89,110,2,2,2,AAPL,0.0,0.0,0.0,
2024-10-21 12:14:07.746754069+00:00,2024-10-21T12:14:07.746920572Z,10,2,38,A,B,1,233.73,200,130,166503,12423514,233.97,234.13,5,400,1,1,233.73,234.14,200,200,1,1,233.7,234.16,1200,27,1,1,233.66,234.17,1,1,1,1,233.58,234.41,505,600,2,2,233.53,234.43,10,105,1,2,233.5,234.5,100,63,1,4,233.45,234.75,15,1,1,1,233.4,234.79,110,2000,2,1,233.39,234.89,10,2,1,2,AAPL,0.0,0.0,0.0,
2024-10-21 12:14:10.801342166+00:00,2024-10-21T12:14:10.801508542Z,10,2,38,A,B,1,233.8,200,130,166376,12425721,233.97,234.13,5,400,1,1,233.8,234.14,200,200,1,1,233.7,234.16,1200,27,1,1,233.66,234.17,1,1,1,1,233.58,234.41,505,600,2,2,233.53,234.43,10,105,1,2,233.5,234.5,100,63,1,4,233.45,234.75,15,1,1,1,233.4,234.79,110,2000,2,1,233.39,234.89,10,2,1,2,AAPL,0.0,0.0,0.0,
2024-10-21 12:14:17.947438449+00:00,2024-10-21T12:14:17.947604712Z,10,2,38,A,B,1,233.81,200,130,166263,12431541,233.97,234.13,5,400,1,1,233.81,234.14,200,200,1,1,233.7,234.16,1200,27,1,1,233.66,234.17,1,1,1,1,233.58,234.41,505,600,2,2,233.53,234.43,10,105,1,2,233.5,234.5,100,63,1,4,233.45,234.75,15,1,1,1,233.4,234.79,110,2000,2,1,233.39,234.89,10,2,1,2,AAPL,0.0,0.0,0.0,
2024-10-21 12:14:17.957382887+00:00,2024-10-21T12:14:17.957549086Z,10,2,38,C,B,1,233.81,200,130,166199,12431585,233.97,234.13,5,400,1,1,233.7,234.14,1200,200,1,1,233.66,234.16,1,27,1,1,233.58,234.17,505,1,2,1,233.53,234.41,10,600,1,2,233.5,234.43,100,105,1,2,233.45,234.5,15,63,1,4,233.4,234.75,110,1,2,1,233.39,234.79,10,2000,1,1,233.31,234.89,110,2,2,2,AAPL,0.0,0.0,0.0,
2024-10-21 12:14:17.957395933+00:00,2024-10-21T12:14:17.957562118Z,10,2,38,A,B,1,233.74,200,130,166185,12431586,233.97,234.13,5,400,1,1,233.74,234.14,200,200,1,1,233.7,234.16,1200,27,1,1,233.66,234.17,1,1,1,1,233.58,234.41,505,600,2,2,233.53,234.43,10,105,1,2,233.5,234.5,100,63,1,4,233.45,234.75,15,1,1,1,233.4,234.79,110,2000,2,1,233.39,234.89,10,2,1,2,AAPL,0.0,0.0,0.0,
2024-10-21 12:14:17.957453277+00:00,2024-10-21T12:14:17.957619401Z,10,2,38,C,A,1,234.14,200,130,166124,12431587,233.97,234.13,5,400,1,1,233.74,234.16,200,27,1,1,233.7,234.17,1200,1,1,1,233.66,234.41,1,600,1,2,233.58,234.43,505,105,2,2,233.53,234.5,10,63,1,4,233.5,234.75,100,1,1,1,233.45,234.79,15,2000,1,1,233.4,234.89,110,2,2,2,233.39,235.0,10,213,1,6,AAPL,0.0,0.0,0.0,
2024-10-21 12:14:17.957465815+00:00,2024-10-21T12:14:17.957631871Z,10,2,38,A,A,1,234.15,200,130,166056,12431588,233.97,234.13,5,400,1,1,233.74,234.15,200,200,1,1,233.7,234.16,1200,27,1,1,233.66,234.17,1,1,1,1,233.58,234.41,505,600,2,2,233.53,234.43,10,105,1,2,233.5,234.5,100,63,1,4,233.45,234.75,15,1,1,1,233.4,234.79,110,2000,2,1,233.39,234.89,10,2,1,2,AAPL,0.0,0.0,0.0,
2024-10-21 12:14:18.056884935+00:00,2024-10-21T12:14:18.057051301Z,10,2,38,A,B,1,233.75,200,130,166366,12431913,233.97,234.13,5,400,1,1,233.75,234.15,200,200,1,1,233.7,234.16,1200,27,1,1,233.66,234.17,1,1,1,1,233.58,234.41,505,600,2,2,233.53,234.43,10,105,1,2,233.5,234.5,100,63,1,4,233.45,234.75,15,1,1,1,233.4,234.79,110,2000,2,1,233.39,234.89,10,2,1,2,AAPL,0.0,0.0,0.0,
2024-10-21 12:14:21.022254267+00:00,2024-10-21T12:14:21.022420708Z,10,2,38,A,B,1,233.77,200,130,166441,12433640,233.97,234.13,5,400,1,1,233.77,234.15,200,200,1,1,233.7,234.16,1200,27,1,1,233.66,234.17,1,1,1,1,233.58,234.41,505,600,2,2,233.53,234.43,10,105,1,2,233.5,234.5,100,63,1,4,233.45,234.75,15,1,1,1,233.4,234.79,110,2000,2,1,233.39,234.89,10,2,1,2,AAPL,0.0,0.0,0.0,
2024-10-21 12:14:21.336689135+00:00,2024-10-21T12:14:21.336855528Z,10,2,38,C,A,1,234.15,200,130,166393,12433903,233.97,234.13,5,400,1,1,233.77,234.16,200,27,1,1,233.7,234.17,1200,1,1,1,233.66,234.41,1,600,1,2,233.58,234.43,505,105,2,2,233.53,234.5,10,63,1,4,233.5,234.75,100,1,1,1,233.45,234.79,15,2000,1,1,233.4,234.89,110,2,2,2,233.39,235.0,10,213,1,6,AAPL,0.0,0.0,0.0,
2024-10-21 12:14:21.336700928+00:00,2024-10-21T12:14:21.336867325Z,10,2,38,A,A,2,234.17,200,130,166397,12433905,233.97,234.13,5,400,1,1,233.77,234.16,200,27,1,1,233.7,234.17,1200,201,1,2,233.66,234.41,1,600,1,2,233.58,234.43,505,105,2,2,233.53,234.5,10,63,1,4,233.5,234.75,100,1,1,1,233.45,234.79,15,2000,1,1,233.4,234.89,110,2,2,2,233.39,235.0,10,213,1,6,AAPL,0.0,-200.0,0.0,
2024-10-21 12:14:21.392627701+00:00,2024-10-21T12:14:21.392793975Z,10,2,38,A,B,1,233.78,200,130,166274,12433982,233.97,234.13,5,400,1,1,233.78,234.16,200,27,1,1,233.7,234.17,1200,201,1,2,233.66,234.41,1,600,1,2,233.58,234.43,505,105,2,2,233.53,234.5,10,63,1,4,233.5,234.75,100,1,1,1,233.45,234.79,15,2000,1,1,233.4,234.89,110,2,2,2,233.39,235.0,10,213,1,6,AAPL,0.0,0.0,0.0,
2024-10-21 12:14:21.426981432+00:00,2024-10-21T12:14:21.427147627Z,10,2,38,C,A,1,234.16,27,130,166195,12434166,233.97,234.13,5,400,1,1,233.78,234.17,200,201,1,2,233.7,234.41,1200,600,1,2,233.66,234.43,1,105,1,2,233.58,234.5,505,63,2,4,233.53,234.75,10,1,1,1,233.5,234.79,100,2000,1,1,233.45,234.89,15,2,1,2,233.4,235.0,110,213,2,6,233.39,235.03,10,2,1,1,AAPL,0.0,0.0,0.0,
2024-10-21 12:14:21.740586460+00:00,2024-10-21T12:14:21.740752948Z,10,2,38,A,B,2,233.76,29,130,166488,12434650,233.97,234.13,5,400,1,1,233.78,234.17,200,201,1,2,233.76,234.41,29,600,1,2,233.7,234.43,1200,105,1,2,233.66,234.5,1,63,1,4,233.58,234.75,505,1,2,1,233.53,234.79,10,2000,1,1,233.5,234.89,100,2,1,2,233.45,235.0,15,213,1,6,233.4,235.03,110,2,2,1,AAPL,0.0,0.0,0.0,
2024-10-21 12:14:21.740617322+00:00,2024-10-21T12:14:21.740783568Z,10,2,38,A,A,2,234.18,28,130,166246,12434651,233.97,234.13,5,400,1,1,233.78,234.17,200,201,1,2,233.76,234.18,29,28,1,1,233.7,234.41,1200,600,1,2,233.66,234.43,1,105,1,2,233.58,234.5,505,63,2,4,233.53,234.75,10,1,1,1,233.5,234.79,100,2000,1,1,233.45,234.89,15,2,1,2,233.4,235.0,110,213,2,6,AAPL,0.0,0.0,0.0,
2024-10-21 12:14:28.747219089+00:00,2024-10-21T12:14:28.747385812Z,10,2,38,A,B,1,233.79,200,130,166723,12439708,233.97,234.13,5,400,1,1,233.79,234.17,200,201,1,2,233.76,234.18,29,28,1,1,233.7,234.41,1200,600,1,2,233.66,234.43,1,105,1,2,233.58,234.5,505,63,2,4,233.53,234.75,10,1,1,1,233.5,234.79,100,2000,1,1,233.45,234.89,15,2,1,2,233.4,235.0,110,213,2,6,AAPL,0.0,0.0,0.0,
2024-10-21 12:14:37.348164372+00:00,2024-10-21T12:14:37.348331123Z,10,2,38,C,B,1,233.79,200,130,166751,12446142,233.97,234.13,5,400,1,1,233.76,234.17,29,201,1,2,233.7,234.18,1200,28,1,1,233.66,234.41,1,600,1,2,233.58,234.43,505,105,2,2,233.53,234.5,10,63,1,4,233.5,234.75,100,1,1,1,233.45,234.79,15,2000,1,1,233.4,234.89,110,2,2,2,233.39,235.0,10,213,1,6,AAPL,0.0,0.0,0.0,
2024-10-21 12:14:37.348177626+00:00,2024-10-21T12:14:37.348344285Z,10,2,38,A,B,1,233.77,200,130,166659,12446143,233.97,234.13,5,400,1,1,233.77,234.17,200,201,1,2,233.76,234.18,29,28,1,1,233.7,234.41,1200,600,1,2,233.66,234.43,1,105,1,2,233.58,234.5,505,63,2,4,233.53,234.75,10,1,1,1,233.5,234.79,100,2000,1,1,233.45,234.89,15,2,1,2,233.4,235.0,110,213,2,6,AAPL,0.0,0.0,0.0,
2024-10-21 12:14:37.485431160+00:00,2024-10-21T12:14:37.485597454Z,10,2,38,A,B,1,233.78,200,130,166294,12446234,233.97,234.13,5,400,1,1,233.78,234.17,200,201,1,2,233.76,234.18,29,28,1,1,233.7,234.41,1200,600,1,2,233.66,234.43,1,105,1,2,233.58,234.5,505,63,2,4,233.53,234.75,10,1,1,1,233.5,234.79,100,2000,1,1,233.45,234.89,15,2,1,2,233.4,235.0,110,213,2,6,AAPL,0.0,0.0,0.0,
2024-10-21 12:14:41.549166803+00:00,2024-10-21T12:14:41.549332947Z,10,2,38,C,B,2,233.76,29,130,166144,12448595,233.97,234.13,5,400,1,1,233.78,234.17,200,201,1,2,233.7,234.18,1200,28,1,1,233.66,234.41,1,600,1,2,233.58,234.43,505,105,2,2,233.53,234.5,10,63,1,4,233.5,234.75,100,1,1,1,233.45,234.79,15,2000,1,1,233.4,234.89,110,2,2,2,233.39,235.0,10,213,1,6,AAPL,0.0,0.0,0.0,
2024-10-21 12:14:41.549212050+00:00,2024-10-21T12:14:41.549378383Z,10,2,38,A,B,1,233.81,28,130,166333,12448596,233.97,234.13,5,400,1,1,233.81,234.17,28,201,1,2,233.78,234.18,200,28,1,1,233.7,234.41,1200,600,1,2,233.66,234.43,1,105,1,2,233.58,234.5,505,63,2,4,233.53,234.75,10,1,1,1,233.5,234.79,100,2000,1,1,233.45,234.89,15,2,1,2,233.4,235.0,110,213,2,6,AAPL,0.0,0.0,0.0,
2024-10-21 12:14:41.599590898+00:00,2024-10-21T12:14:41.599757577Z,10,2,38,A,B,1,233.87,200,130,166679,12448666,233.97,234.13,5,400,1,1,233.87,234.17,200,201,1,2,233.81,234.18,28,28,1,1,233.7,234.41,1200,600,1,2,233.66,234.43,1,105,1,2,233.58,234.5,505,63,2,4,233.53,234.75,10,1,1,1,233.5,234.79,100,2000,1,1,233.45,234.89,15,2,1,2,233.4,235.0,110,213,2,6,AAPL,0.0,0.0,0.0,
2024-10-21 12:14:43.205958056+00:00,2024-10-21T12:14:43.206124405Z,10,2,38,A,A,1,234.16,200,130,166349,12449507,233.97,234.13,5,400,1,1,233.87,234.16,200,200,1,1,233.81,234.17,28,1,1,1,233.7,234.18,1200,28,1,1,233.66,234.41,1,600,1,2,233.58,234.43,505,105,2,2,233.53,234.5,10,63,1,4,233.5,234.75,100,1,1,1,233.45,234.79,15,2000,1,1,233.4,234.89,110,2,2,2,AAPL,0.0,0.0,0.0,
2024-10-21 12:14:49.824694031+00:00,2024-10-21T12:14:49.824860694Z,10,2,38,A,A,1,234.16,200,130,166663,12453535,233.97,234.13,5,400,1,1,233.87,234.16,200,400,1,2,233.81,234.17,28,1,1,1,233.7,234.18,1200,28,1,1,233.66,234.41,1,600,1,2,233.58,234.43,505,105,2,2,233.53,234.5,10,63,1,4,233.5,234.75,100,1,1,1,233.45,234.79,15,2000,1,1,233.4,234.89,110,2,2,2,AAPL,0.0,-200.0,0.0,
2024-10-21 12:14:52.413893215+00:00,2024-10-21T12:14:52.414059791Z,10,2,38,C,B,1,233.87,200,130,166576,12455999,233.97,234.13,5,400,1,1,233.81,234.16,28,400,1,2,233.7,234.17,1200,1,1,1,233.66,234.18,1,28,1,1,233.58,234.41,505,600,2,2,233.53,234.43,10,105,1,2,233.5,234.5,100,63,1,4,233.45,234.75,15,1,1,1,233.4,234.79,110,2000,2,1,233.39,234.89,10,2,1,2,AAPL,0.0,0.0,0.0,
2024-10-21 12:14:52.413904869+00:00,2024-10-21T12:14:52.414071390Z,10,2,38,A,B,1,233.85,200,130,166521,12456000,233.97,234.13,5,400,1,1,233.85,234.16,200,400,1,2,233.81,234.17,28,1,1,1,233.7,234.18,1200,28,1,1,233.66,234.41,1,600,1,2,233.58,234.43,505,105,2,2,233.53,234.5,10,63,1,4,233.5,234.75,100,1,1,1,233.45,234.79,15,2000,1,1,233.4,234.89,110,2,2,2,AAPL,0.0,0.0,0.0,
2024-10-21 12:14:52.473339217+00:00,2024-10-21T12:14:52.473505418Z,10,2,38,C,A,1,234.16,200,130,166201,12456232,233.97,234.13,5,400,1,1,233.85,234.16,200,200,1,1,233.81,234.17,28,1,1,1,233.7,234.18,1200,28,1,1,233.66,234.41,1,600,1,2,233.58,234.43,505,105,2,2,233.53,234.5,10,63,1,4,233.5,234.75,100,1,1,1,233.45,234.79,15,2000,1,1,233.4,234.89,110,2,2,2,AAPL,0.0,200.0,0.0,
2024-10-21 12:14:52.473352225+00:00,2024-10-21T12:14:52.473518693Z,10,2,38,A,A,1,234.15,200,130,166468,12456234,233.97,234.13,5,400,1,1,233.85,234.15,200,200,1,1,233.81,234.17,28,1,1,1,233.7,234.18,1200,28,1,1,233.66,234.41,1,600,1,2,233.58,234.43,505,105,2,2,233.53,234.5,10,63,1,4,233.5,234.75,100,1,1,1,233.45,234.79,15,2000,1,1,233.4,234.89,110,2,2,2,AAPL,0.0,0.0,0.0,
2024-10-21 12:14:52.474399706+00:00,2024-10-21T12:14:52.474565706Z,10,2,38,C,A,3,234.18,28,130,166000,12456246,233.97,234.13,5,400,1,1,233.85,234.15,200,200,1,1,233.81,234.17,28,1,1,1,233.7,234.41,1200,600,1,2,233.66,234.43,1,105,1,2,233.58,234.5,505,63,2,4,233.53,234.75,10,1,1,1,233.5,234.79,100,2000,1,1,233.45,234.89,15,2,1,2,233.4,235.0,110,213,2,6,AAPL,0.0,0.0,0.0,
2024-10-21 12:14:52.474453011+00:00,2024-10-21T12:14:52.474619355Z,10,2,38,A,A,2,234.17,29,130,166344,12456247,233.97,234.13,5,400,1,1,233.85,234.15,200,200,1,1,233.81,234.17,28,30,1,2,233.7,234.41,1200,600,1,2,233.66,234.43,1,105,1,2,233.58,234.5,505,63,2,4,233.53,234.75,10,1,1,1,233.5,234.79,100,2000,1,1,233.45,234.89,15,2,1,2,233.4,235.0,110,213,2,6,AAPL,0.0,-29.0,0.0,
2024-10-21 12:14:53.024665699+00:00,2024-10-21T12:14:53.024832003Z,10,2,38,A,A,1,234.15,200,130,166304,12457068,233.97,234.13,5,400,1,1,233.85,234.15,200,400,1,2,233.81,234.17,28,30,1,2,233.7,234.41,1200,600,1,2,233.66,234.43,1,105,1,2,233.58,234.5,505,63,2,4,233.53,234.75,10,1,1,1,233.5,234.79,100,2000,1,1,233.45,234.89,15,2,1,2,233.4,235.0,110,213,2,6,AAPL,0.0,-200.0,0.0,
2024-10-21 12:14:59.069065580+00:00,2024-10-21T12:14:59.069231899Z,10,2,38,A,B,1,233.86,200,130,166319,12461167,233.97,234.13,5,400,1,1,233.86,234.15,200,400,1,2,233.81,234.17,28,30,1,2,233.7,234.41,1200,600,1,2,233.66,234.43,1,105,1,2,233.58,234.5,505,63,2,4,233.53,234.75,10,1,1,1,233.5,234.79,100,2000,1,1,233.45,234.89,15,2,1,2,233.4,235.0,110,213,2,6,AAPL,0.0,0.0,0.0,
2024-10-21 12:15:05.174000161+00:00,2024-10-21T12:15:05.174166268Z,10,2,38,C,A,1,234.15,200,130,166107,12470009,233.97,234.13,5,400,1,1,233.86,234.15,200,200,1,1,233.81,234.17,28,30,1,2,233.7,234.41,1200,600,1,2,233.66,234.43,1,105,1,2,233.58,234.5,505,63,2,4,233.53,234.75,10,1,1,1,233.5,234.79,100,2000,1,1,233.45,234.89,15,2,1,2,233.4,235.0,110,213,2,6,AAPL,0.0,200.0,0.0,
2024-10-21 12:15:05.174010189+00:00,2024-10-21T12:15:05.174176083Z,10,2,38,C,A,1,234.15,200,130,165894,12470010,233.97,234.13,5,400,1,1,233.86,234.17,200,30,1,2,233.81,234.41,28,600,1,2,233.7,234.43,1200,105,1,2,233.66,234.5,1,63,1,4,233.58,234.75,505,1,2,1,233.53,234.79,10,2000,1,1,233.5,234.89,100,2,1,2,233.45,235.0,15,213,1,6,233.4,235.03,110,2,2,1,AAPL,0.0,0.0,0.0,
2024-10-21 12:15:05.174024191+00:00,2024-10-21T12:15:05.174191104Z,10,2,38,A,A,1,234.16,200,130,166913,12470011,233.97,234.13,5,400,1,1,233.86,234.16,200,200,1,1,233.81,234.17,28,30,1,2,233.7,234.41,1200,600,1,2,233.66,234.43,1,105,1,2,233.58,234.5,505,63,2,4,233.53,234.75,10,1,1,1,233.5,234.79,100,2000,1,1,233.45,234.89,15,2,1,2,233.4,235.0,110,213,2,6,AAPL,0.0,0.0,0.0,
2024-10-21 12:15:08.174665588+00:00,2024-10-21T12:15:08.174832295Z,10,2,38,A,A,1,234.16,200,130,166707,12472897,233.97,234.13,5,400,1,1,233.86,234.16,200,400,1,2,233.81,234.17,28,30,1,2,233.7,234.41,1200,600,1,2,233.66,234.43,1,105,1,2,233.58,234.5,505,63,2,4,233.53,234.75,10,1,1,1,233.5,234.79,100,2000,1,1,233.45,234.89,15,2,1,2,233.4,235.0,110,213,2,6,AAPL,0.0,-200.0,0.0,
2024-10-21 12:15:12.192615974+00:00,2024-10-21T12:15:12.192782193Z,10,2,38,A,A,0,234.07,100,130,166219,12475949,233.97,234.07,5,100,1,1,233.86,234.13,200,400,1,1,233.81,234.16,28,400,1,2,233.7,234.17,1200,30,1,2,233.66,234.41,1,600,1,2,233.58,234.43,505,105,2,2,233.53,234.5,10,63,1,4,233.5,234.75,100,1,1,1,233.45,234.79,15,2000,1,1,233.4,234.89,110,2,2,2,AAPL,0.0,0.0,0.0,
2024-10-21 12:15:12.193015032+00:00,2024-10-21T12:15:12.193180932Z,10,2,38,C,A,0,234.07,100,130,165900,12475950,233.97,234.13,5,400,1,1,233.86,234.16,200,400,1,2,233.81,234.17,28,30,1,2,233.7,234.41,1200,600,1,2,233.66,234.43,1,105,1,2,233.58,234.5,505,63,2,4,233.53,234.75,10,1,1,1,233.5,234.79,100,2000,1,1,233.45,234.89,15,2,1,2,233.4,235.0,110,213,2,6,AAPL,0.0,0.0,0.0,
2024-10-21 12:15:12.197769369+00:00,2024-10-21T12:15:12.197936547Z,10,2,38,A,A,0,234.07,148,128,167178,12475955,233.97,234.07,5,148,1,1,233.86,234.13,200,400,1,1,233.81,234.16,28,400,1,2,233.7,234.17,1200,30,1,2,233.66,234.41,1,600,1,2,233.58,234.43,505,105,2,2,233.53,234.5,10,63,1,4,233.5,234.75,100,1,1,1,233.45,234.79,15,2000,1,1,233.4,234.89,110,2,2,2,AAPL,0.0,0.0,0.0,
2024-10-21 12:15:12.197802997+00:00,2024-10-21T12:15:12.197969503Z,10,2,38,C,B,1,233.86,200,130,166506,12475958,233.97,234.07,5,148,1,1,233.81,234.13,28,400,1,1,233.7,234.16,1200,400,1,2,233.66,234.17,1,30,1,2,233.58,234.41,505,600,2,2,233.53,234.43,10,105,1,2,233.5,234.5,100,63,1,4,233.45,234.75,15,1,1,1,233.4,234.79,110,2000,2,1,233.39,234.89,10,2,1,2,AAPL,0.0,0.0,0.0,
2024-10-21 12:15:12.201874823+00:00,2024-10-21T12:15:12.202040946Z,10,2,38,C,A,0,234.07,148,130,166123,12475962,233.97,234.13,5,400,1,1,233.81,234.16,28,400,1,2,233.7,234.17,1200,30,1,2,233.66,234.41,1,600,1,2,233.58,234.43,505,105,2,2,233.53,234.5,10,63,1,4,233.5,234.75,100,1,1,1,233.45,234.79,15,2000,1,1,233.4,234.89,110,2,2,2,233.39,235.0,10,213,1,6,AAPL,0.0,0.0,0.0,
2024-10-21 12:15:12.264450843+00:00,2024-10-21T12:15:12.264617436Z,10,2,38,A,B,2,233.75,28,130,166593,12476000,233.97,234.13,5,400,1,1,233.81,234.16,28,400,1,2,233.75,234.17,28,30,1,2,233.7,234.41,1200,600,1,2,233.66,234.43,1,105,1,2,233.58,234.5,505,63,2,4,233.53,234.75,10,1,1,1,233.5,234.79,100,2000,1,1,233.45,234.89,15,2,1,2,233.4,235.0,110,213,2,6,AAPL,0.0,0.0,0.0,
2024-10-21 12:15:12.264477828+00:00,2024-10-21T12:15:12.264644369Z,10,2,38,C,B,1,233.81,28,130,166541,12476001,233.97,234.13,5,400,1,1,233.75,234.16,28,400,1,2,233.7,234.17,1200,30,1,2,233.66,234.41,1,600,1,2,233.58,234.43,505,105,2,2,233.53,234.5,10,63,1,4,233.5,234.75,100,1,1,1,233.45,234.79,15,2000,1,1,233.4,234.89,110,2,2,2,233.39,235.0,10,213,1,6,AAPL,0.0,0.0,0.0,
2024-10-21 12:15:12.268335051+00:00,2024-10-21T12:15:12.268501792Z,10,2,38,A,B,4,233.63,200,130,166741,12476005,233.97,234.13,5,400,1,1,233.75,234.16,28,400,1,2,233.7,234.17,1200,30,1,2,233.66,234.41,1,600,1,2,233.63,234.43,200,105,1,2,233.58,234.5,505,63,2,4,233.53,234.75,10,1,1,1,233.5,234.79,100,2000,1,1,233.45,234.89,15,2,1,2,233.4,235.0,110,213,2,6,AAPL,0.0,0.0,0.0,
2024-10-21 12:15:12.268635983+00:00,2024-10-21T12:15:12.268802483Z,10,2,38,C,B,1,233.75,28,130,166500,12476006,233.97,234.13,5,400,1,1,233.7,234.16,1200,400,1,2,233.66,234.17,1,30,1,2,233.63,234.41,200,600,1,2,233.58,234.43,505,105,2,2,233.53,234.5,10,63,1,4,233.5,234.75,100,1,1,1,233.45,234.79,15,2000,1,1,233.4,234.89,110,2,2,2,233.39,235.0,10,213,1,6,AAPL,0.0,0.0,0.0,
2024-10-21 12:15:12.270227323+00:00,2024-10-21T12:15:12.270394146Z,10,2,38,C,A,2,234.17,29,130,166823,12476010,233.97,234.13,5,400,1,1,233.7,234.16,1200,400,1,2,233.66,234.17,1,1,1,1,233.63,234.41,200,600,1,2,233.58,234.43,505,105,2,2,233.53,234.5,10,63,1,4,233.5,234.75,100,1,1,1,233.45,234.79,15,2000,1,1,233.4,234.89,110,2,2,2,233.39,235.0,10,213,1,6,AAPL,0.0,29.0,0.0,
2024-10-21 12:15:12.270326143+00:00,2024-10-21T12:15:12.270492635Z,10,2,38,A,A,0,234.12,27,130,166492,12476011,233.97,234.12,5,27,1,1,233.7,234.13,1200,400,1,1,233.66,234.16,1,400,1,2,233.63,234.17,200,1,1,1,233.58,234.41,505,600,2,2,233.53,234.43,10,105,1,2,233.5,234.5,100,63,1,4,233.45,234.75,15,1,1,1,233.4,234.79,110,2000,2,1,233.39,234.89,10,2,1,2,AAPL,0.0,0.0,0.0,
2024-10-21 12:15:12.270365637+00:00,2024-10-21T12:15:12.270531958Z,10,2,38,A,A,2,234.15,26,130,166321,12476012,233.97,234.12,5,27,1,1,233.7,234.13,1200,400,1,1,233.66,234.15,1,26,1,1,233.63,234.16,200,400,1,2,233.58,234.17,505,1,2,1,233.53,234.41,10,600,1,2,233.5,234.43,100,105,1,2,233.45,234.5,15,63,1,4,233.4,234.75,110,1,2,1,233.39,234.79,10,2000,1,1,AAPL,0.0,0.0,0.0,
2024-10-21 12:15:12.318866641+00:00,2024-10-21T12:15:12.319033039Z,10,2,38,A,B,3,233.64,200,130,166398,12476109,233.97,234.12,5,27,1,1,233.7,234.13,1200,400,1,1,233.66,234.15,1,26,1,1,233.64,234.16,200,400,1,2,233.58,234.17,505,1,2,1,233.53,234.41,10,600,1,2,233.5,234.43,100,105,1,2,233.45,234.5,15,63,1,4,233.4,234.75,110,1,2,1,233.39,234.79,10,2000,1,1,AAPL,0.0,0.0,0.0,
2024-10-21 12:15:12.318878820+00:00,2024-10-21T12:15:12.319045020Z,10,2,38,C,A,3,234.16,200,130,166200,12476110,233.97,234.12,5,27,1,1,233.7,234.13,1200,400,1,1,233.66,234.15,1,26,1,1,233.64,234.16,200,200,1,1,233.58,234.17,505,1,2,1,233.53,234.41,10,600,1,2,233.5,234.43,100,105,1,2,233.45,234.5,15,63,1,4,233.4,234.75,110,1,2,1,233.39,234.79,10,2000,1,1,AAPL,0.0,200.0,0.0,
2024-10-21 12:15:12.318890689+00:00,2024-10-21T12:15:12.319057841Z,10,2,38,A,A,2,234.15,400,130,167152,12476111,233.97,234.12,5,27,1,1,233.7,234.13,1200,400,1,1,233.66,234.15,1,426,1,2,233.64,234.17,200,1,1,1,233.58,234.41,505,600,2,2,233.53,234.43,10,105,1,2,233.5,234.5,100,63,1,4,233.45,234.75,15,1,1,1,233.4,234.79,110,2000,2,1,233.39,234.89,10,2,1,2,AAPL,0.0,-400.0,0.0,
2024-10-21 12:15:12.327814809+00:00,2024-10-21T12:15:12.327981136Z,10,2,38,A,A,0,234.05,200,130,166327,12476126,233.97,234.05,5,200,1,1,233.7,234.12,1200,27,1,1,233.66,234.13,1,400,1,1,233.64,234.15,200,26,1,1,233.58,234.17,505,1,2,1,233.53,234.41,10,600,1,2,233.5,234.43,100,105,1,2,233.45,234.5,15,63,1,4,233.4,234.75,110,1,2,1,233.39,234.79,10,2000,1,1,AAPL,0.0,0.0,0.0,
2024-10-21 12:15:12.391011950+00:00,2024-10-21T12:15:12.391178086Z,10,2,38,C,A,1,234.12,27,130,166136,12476246,233.97,234.05,5,200,1,1,233.7,234.13,1200,400,1,1,233.66,234.15,1,26,1,1,233.64,234.17,200,1,1,1,233.58,234.41,505,600,2,2,233.53,234.43,10,105,1,2,233.5,234.5,100,63,1,4,233.45,234.75,15,1,1,1,233.4,234.79,110,2000,2,1,233.39,234.89,10,2,1,2,AAPL,0.0,0.0,0.0,
2024-10-21 12:15:12.404688523+00:00,2024-10-21T12:15:12.404855221Z,10,2,38,A,B,3,233.65,200,130,166698,12476254,233.97,234.05,5,200,1,1,233.7,234.13,1200,400,1,1,233.66,234.15,1,26,1,1,233.65,234.17,200,1,1,1,233.58,234.41,505,600,2,2,233.53,234.43,10,105,1,2,233.5,234.5,100,63,1,4,233.45,234.75,15,1,1,1,233.4,234.79,110,2000,2,1,233.39,234.89,10,2,1,2,AAPL,0.0,0.0,0.0,
2024-10-21 12:15:12.446815675+00:00,2024-10-21T12:15:12.446982743Z,10,2,38,A,B,2,233.69,200,130,167068,12476283,233.97,234.05,5,200,1,1,233.7,234.13,1200,400,1,1,233.69,234.15,200,26,1,1,233.66,234.17,1,1,1,1,233.58,234.41,505,600,2,2,233.53,234.43,10,105,1,2,233.5,234.5,100,63,1,4,233.45,234.75,15,1,1,1,233.4,234.79,110,2000,2,1,233.39,234.89,10,2,1,2,AAPL,0.0,0.0,0.0,
2024-10-21 12:15:12.518757844+00:00,2024-10-21T12:15:12.518924447Z,10,2,38,A,B,2,233.69,200,130,166603,12476376,233.97,234.05,5,200,1,1,233.7,234.13,1200,400,1,1,233.69,234.15,400,26,2,1,233.66,234.17,1,1,1,1,233.58,234.41,505,600,2,2,233.53,234.43,10,105,1,2,233.5,234.5,100,63,1,4,233.45,234.75,15,1,1,1,233.4,234.79,110,2000,2,1,233.39,234.89,10,2,1,2,AAPL,0.0,200.0,0.0,
2024-10-21 12:15:12.518889885+00:00,2024-10-21T12:15:12.519057354Z,10,2,38,C,A,0,234.05,200,130,167469,12476377,233.97,234.13,5,400,1,1,233.7,234.15,1200,26,1,1,233.69,234.17,400,1,2,1,233.66,234.41,1,600,1,2,233.58,234.43,505,105,2,2,233.53,234.5,10,63,1,4,233.5,234.75,100,1,1,1,233.45,234.79,15,2000,1,1,233.4,234.89,110,2,2,2,233.39,235.0,10,213,1,6,AAPL,0.0,0.0,0.0,
2024-10-21 12:15:12.518901713+00:00,2024-10-21T12:15:12.519068158Z,10,2,38,A,A,0,234.1,400,130,166445,12476378,233.97,234.1,5,400,1,1,233.7,234.13,1200,400,1,1,233.69,234.15,400,26,2,1,233.66,234.17,1,1,1,1,233.58,234.41,505,600,2,2,233.53,234.43,10,105,1,2,233.5,234.5,100,63,1,4,233.45,234.75,15,1,1,1,233.4,234.79,110,2000,2,1,233.39,234.89,10,2,1,2,AAPL,0.0,0.0,0.0,
2024-10-21 12:15:12.521642022+00:00,2024-10-21T12:15:12.521808610Z,10,2,38,C,A,0,234.1,200,130,166588,12476383,233.97,234.1,5,200,1,1,233.7,234.13,1200,400,1,1,233.69,234.15,400,26,2,1,233.66,234.17,1,1,1,1,233.58,234.41,505,600,2,2,233.53,234.43,10,105,1,2,233.5,234.5,100,63,1,4,233.45,234.75,15,1,1,1,233.4,234.79,110,2000,2,1,233.39,234.89,10,2,1,2,AAPL,200.0,200.0,200.0,
2024-10-21 12:15:12.529592990+00:00,2024-10-21T12:15:12.529759184Z,10,2,38,C,B,2,233.69,200,130,166194,12476384,233.97,234.1,5,200,1,1,233.7,234.13,1200,400,1,1,233.69,234.15,200,26,1,1,233.66,234.17,1,1,1,1,233.58,234.41,505,600,2,2,233.53,234.43,10,105,1,2,233.5,234.5,100,63,1,4,233.45,234.75,15,1,1,1,233.4,234.79,110,2000,2,1,233.39,234.89,10,2,1,2,AAPL,0.0,-200.0,200.0,
2024-10-21 12:15:12.529605412+00:00,2024-10-21T12:15:12.529771785Z,10,2,38,A,B,1,233.7,400,130,166373,12476385,233.97,234.1,5,200,1,1,233.7,234.13,1600,400,2,1,233.66,234.15,1,26,1,1,233.58,234.17,505,1,2,1,233.53,234.41,10,600,1,2,233.5,234.43,100,105,1,2,233.45,234.5,15,63,1,4,233.4,234.75,110,1,2,1,233.39,234.79,10,2000,1,1,233.31,234.89,110,2,2,2,AAPL,0.0,400.0,200.0,
2024-10-21 12:15:12.575103526+00:00,2024-10-21T12:15:12.575269816Z,10,2,38,A,B,1,233.87,400,130,166290,12476419,233.97,234.1,5,200,1,1,233.87,234.13,400,400,1,1,233.7,234.15,1200,26,1,1,233.66,234.17,1,1,1,1,233.58,234.41,505,600,2,2,233.53,234.43,10,105,1,2,233.5,234.5,100,63,1,4,233.45,234.75,15,1,1,1,233.4,234.79,110,2000,2,1,233.39,234.89,10,2,1,2,AAPL,0.0,0.0,200.0,
2024-10-21 12:15:12.619373396+00:00,2024-10-21T12:15:12.619539368Z,10,2,38,C,A,0,234.1,200,130,165972,12476439,233.97,234.13,5,400,1,1,233.87,234.15,400,26,1,1,233.7,234.17,1200,1,1,1,233.66,234.41,1,600,1,2,233.58,234.43,505,105,2,2,233.53,234.5,10,63,1,4,233.5,234.75,100,1,1,1,233.45,234.79,15,2000,1,1,233.4,234.89,110,2,2,2,233.39,235.0,10,213,1,6,AAPL,0.0,0.0,200.0,
2024-10-21 12:15:12.619385902+00:00,2024-10-21T12:15:12.619552121Z,10,2,38,A,A,1,234.15,200,130,166219,12476440,233.97,234.13,5,400,1,1,233.87,234.15,400,226,1,2,233.7,234.17,1200,1,1,1,233.66,234.41,1,600,1,2,233.58,234.43,505,105,2,2,233.53,234.5,10,63,1,4,233.5,234.75,100,1,1,1,233.45,234.79,15,2000,1,1,233.4,234.89,110,2,2,2,233.39,235.0,10,213,1,6,AAPL,0.0,-200.0,200.0,
2024-10-21 12:15:12.655937741+00:00,2024-10-21T12:15:12.656104126Z,10,2,38,C,A,1,234.15,26,130,166385,12476454,233.97,234.13,5,400,1,1,233.87,234.15,400,200,1,1,233.7,234.17,1200,1,1,1,233.66,234.41,1,600,1,2,233.58,234.43,505,105,2,2,233.53,234.5,10,63,1,4,233.5,234.75,100,1,1,1,233.45,234.79,15,2000,1,1,233.4,234.89,110,2,2,2,233.39,235.0,10,213,1,6,AAPL,0.0,26.0,200.0,
2024-10-21 12:15:12.669684284+00:00,2024-10-21T12:15:12.669851013Z,10,2,38,A,B,1,233.9,200,130,166729,12476460,233.97,234.13,5,400,1,1,233.9,234.15,200,200,1,1,233.7,234.17,1200,1,1,1,233.66,234.41,1,600,1,2,233.58,234.43,505,105,2,2,233.53,234.5,10,63,1,4,233.5,234.75,100,1,1,1,233.45,234.79,15,2000,1,1,233.4,234.89,110,2,2,2,233.39,235.0,10,213,1,6,AAPL,0.0,0.0,200.0,
2024-10-21 12:15:13.051576352+00:00,2024-10-21T12:15:13.051742504Z,10,2,38,A,A,3,234.22,30,130,166152,12476843,233.97,234.13,5,400,1,1,233.9,234.15,200,200,1,1,233.7,234.17,1200,1,1,1,233.66,234.22,1,30,1,1,233.58,234.41,505,600,2,2,233.53,234.43,10,105,1,2,233.5,234.5,100,63,1,4,233.45,234.75,15,1,1,1,233.4,234.79,110,2000,2,1,233.39,234.89,10,2,1,2,AAPL,0.0,0.0,200.0,
2024-10-21 12:15:13.051605161+00:00,2024-10-21T12:15:13.051772118Z,10,2,38,A,B,2,233.85,27,130,166957,12476844,233.97,234.13,5,400,1,1,233.9,234.15,200,200,1,1,233.85,234.17,27,1,1,1,233.7,234.22,1200,30,1,1,233.66,234.41,1,600,1,2,233.58,234.43,505,105,2,2,233.53,234.5,10,63,1,4,233.5,234.75,100,1,1,1,233.45,234.79,15,2000,1,1,233.4,234.89,110,2,2,2,AAPL,0.0,0.0,200.0,
2024-10-21 12:15:13.945967888+00:00,2024-10-21T12:15:13.946134251Z,10,2,38,A,A,1,234.15,200,130,166363,12477920,233.97,234.13,5,400,1,1,233.9,234.15,200,400,1,2,233.85,234.17,27,1,1,1,233.7,234.22,1200,30,1,1,233.66,234.41,1,600,1,2,233.58,234.43,505,105,2,2,233.53,234.5,10,63,1,4,233.5,234.75,100,1,1,1,233.45,234.79,15,2000,1,1,233.4,234.89,110,2,2,2,AAPL,0.0,-200.0,0.0,
2024-10-21 12:15:13.946489728+00:00,2024-10-21T12:15:13.946655760Z,10,2,38,C,A,3,234.22,30,130,166032,12477923,233.97,234.13,5,400,1,1,233.9,234.15,200,400,1,2,233.85,234.17,27,1,1,1,233.7,234.41,1200,600,1,2,233.66,234.43,1,105,1,2,233.58,234.5,505,63,2,4,233.53,234.75,10,1,1,1,233.5,234.79,100,2000,1,1,233.45,234.89,15,2,1,2,233.4,235.0,110,213,2,6,AAPL,0.0,0.0,0.0,
2024-10-21 12:15:13.946532120+00:00,2024-10-21T12:15:13.946698478Z,10,2,38,A,A,2,234.17,27,130,166358,12477924,233.97,234.13,5,400,1,1,233.9,234.15,200,400,1,2,233.85,234.17,27,28,1,2,233.7,234.41,1200,600,1,2,233.66,234.43,1,105,1,2,233.58,234.5,505,63,2,4,233.53,234.75,10,1,1,1,233.5,234.79,100,2000,1,1,233.45,234.89,15,2,1,2,233.4,235.0,110,213,2,6,AAPL,0.0,-27.0,0.0,
2024-10-21 12:15:14.001009338+00:00,2024-10-21T12:15:14.001175416Z,10,2,38,C,A,1,234.15,200,130,166078,12478031,233.97,234.13,5,400,1,1,233.9,234.15,200,200,1,1,233.85,234.17,27,28,1,2,233.7,234.41,1200,600,1,2,233.66,234.43,1,105,1,2,233.58,234.5,505,63,2,4,233.53,234.75,10,1,1,1,233.5,234.79,100,2000,1,1,233.45,234.89,15,2,1,2,233.4,235.0,110,213,2,6,AAPL,0.0,200.0,0.0,
2024-10-21 12:15:14.001022189+00:00,2024-10-21T12:15:14.001188780Z,10,2,38,A,A,0,234.1,400,130,166591,12478032,233.97,234.1,5,400,1,1,233.9,234.13,200,400,1,1,233.85,234.17,27,28,1,2,233.7,234.41,1200,600,1,2,233.66,234.43,1,105,1,2,233.58,234.5,505,63,2,4,233.53,234.75,10,1,1,1,233.5,234.79,100,2000,1,1,233.45,234.89,15,2,1,2,233.4,235.0,110,213,2,6,AAPL,0.0,0.0,0.0,
2024-10-21 12:15:14.207183672+00:00,2024-10-21T12:15:14.207349948Z,10,2,38,A,B,1,233.9,100,130,166276,12478133,233.97,234.1,5,400,1,1,233.9,234.13,300,400,2,1,233.85,234.17,27,28,1,2,233.7,234.41,1200,600,1,2,233.66,234.43,1,105,1,2,233.58,234.5,505,63,2,4,233.53,234.75,10,1,1,1,233.5,234.79,100,2000,1,1,233.45,234.89,15,2,1,2,233.4,235.0,110,213,2,6,AAPL,0.0,100.0,0.0,
2024-10-21 12:15:14.207479344+00:00,2024-10-21T12:15:14.207645338Z,10,2,38,C,B,1,233.9,100,130,165994,12478134,233.97,234.1,5,400,1,1,233.9,234.13,200,400,1,1,233.85,234.17,27,28,1,2,233.7,234.41,1200,600,1,2,233.66,234.43,1,105,1,2,233.58,234.5,505,63,2,4,233.53,234.75,10,1,1,1,233.5,234.79,100,2000,1,1,233.45,234.89,15,2,1,2,233.4,235.0,110,213,2,6,AAPL,0.0,-100.0,0.0,
2024-10-21 12:15:14.278377067+00:00,2024-10-21T12:15:14.278543569Z,10,2,38,C,A,0,234.1,200,130,166502,12478168,233.97,234.1,5,200,1,1,233.9,234.13,200,400,1,1,233.85,234.17,27,28,1,2,233.7,234.41,1200,600,1,2,233.66,234.43,1,105,1,2,233.58,234.5,505,63,2,4,233.53,234.75,10,1,1,1,233.5,234.79,100,2000,1,1,233.45,234.89,15,2,1,2,233.4,235.0,110,213,2,6,AAPL,200.0,200.0,200.0,
2024-10-21 12:15:14.278559734+00:00,2024-10-21T12:15:14.278726070Z,10,2,38,C,A,0,234.1,200,130,166336,12478169,233.97,234.13,5,400,1,1,233.9,234.17,200,28,1,2,233.85,234.41,27,600,1,2,233.7,234.43,1200,105,1,2,233.66,234.5,1,63,1,4,233.58,234.75,505,1,2,1,233.53,234.79,10,2000,1,1,233.5,234.89,100,2,1,2,233.45,235.0,15,213,1,6,233.4,235.03,110,2,2,1,AAPL,0.0,0.0,200.0,
2024-10-21 12:15:14.278572418+00:00,2024-10-21T12:15:14.278738674Z,10,2,38,A,A,1,234.16,200,130,166256,12478170,233.97,234.13,5,400,1,1,233.9,234.16,200,200,1,1,233.85,234.17,27,28,1,2,233.7,234.41,1200,600,1,2,233.66,234.43,1,105,1,2,233.58,234.5,505,63,2,4,233.53,234.75,10,1,1,1,233.5,234.79,100,2000,1,1,233.45,234.89,15,2,1,2,233.4,235.0,110,213,2,6,AAPL,0.0,0.0,200.0,
2024-10-21 12:15:14.278970387+00:00,2024-10-21T12:15:14.279136295Z,10,2,38,C,A,2,234.17,27,130,165908,12478171,233.97,234.13,5,400,1,1,233.9,234.16,200,200,1,1,233.85,234.17,27,1,1,1,233.7,234.41,1200,600,1,2,233.66,234.43,1,105,1,2,233.58,234.5,505,63,2,4,233.53,234.75,10,1,1,1,233.5,234.79,100,2000,1,1,233.45,234.89,15,2,1,2,233.4,235.0,110,213,2,6,AAPL,0.0,27.0,200.0,
2024-10-21 12:15:14.280591359+00:00,2024-10-21T12:15:14.280757598Z,10,2,38,A,A,1,234.16,200,130,166239,12478172,233.97,234.13,5,400,1,1,233.9,234.16,200,400,1,2,233.85,234.17,27,1,1,1,233.7,234.41,1200,600,1,2,233.66,234.43,1,105,1,2,233.58,234.5,505,63,2,4,233.53,234.75,10,1,1,1,233.5,234.79,100,2000,1,1,233.45,234.89,15,2,1,2,233.4,235.0,110,213,2,6,AAPL,0.0,-200.0,200.0,
2024-10-21 12:15:15.248901194+00:00,2024-10-21T12:15:15.249067573Z,10,2,38,C,A,1,234.16,200,130,166379,12479022,233.97,234.13,5,400,1,1,233.9,234.16,200,200,1,1,233.85,234.17,27,1,1,1,233.7,234.41,1200,600,1,2,233.66,234.43,1,105,1,2,233.58,234.5,505,63,2,4,233.53,234.75,10,1,1,1,233.5,234.79,100,2000,1,1,233.45,234.89,15,2,1,2,233.4,235.0,110,213,2,6,AAPL,0.0,200.0,200.0,
2024-10-21 12:15:15.248912868+00:00,2024-10-21T12:15:15.249079309Z,10,2,38,A,A,1,234.15,400,130,166441,12479023,233.97,234.13,5,400,1,1,233.9,234.15,200,400,1,1,233.85,234.17,27,1,1,1,233.7,234.41,1200,600,1,2,233.66,234.43,1,105,1,2,233.58,234.5,505,63,2,4,233.53,234.75,10,1,1,1,233.5,234.79,100,2000,1,1,233.45,234.89,15,2,1,2,233.4,235.0,110,213,2,6,AAPL,0.0,0.0,200.0,
2024-10-21 12:15:17.923034484+00:00,2024-10-21T12:15:17.923200888Z,10,2,38,A,A,3,234.22,27,130,166404,12482317,233.97,234.13,5,400,1,1,233.9,234.15,200,400,1,1,233.85,234.17,27,1,1,1,233.7,234.22,1200,27,1,1,233.66,234.41,1,600,1,2,233.58,234.43,505,105,2,2,233.53,234.5,10,63,1,4,233.5,234.75,100,1,1,1,233.45,234.79,15,2000,1,1,233.4,234.89,110,2,2,2,AAPL,0.0,0.0,0.0,
2024-10-21 12:15:24.014190176+00:00,2024-10-21T12:15:24.014356772Z,10,2,38,C,B,1,233.9,200,130,166596,12489125,233.97,234.13,5,400,1,1,233.85,234.15,27,400,1,1,233.7,234.17,1200,1,1,1,233.66,234.22,1,27,1,1,233.58,234.41,505,600,2,2,233.53,234.43,10,105,1,2,233.5,234.5,100,63,1,4,233.45,234.75,15,1,1,1,233.4,234.79,110,2000,2,1,233.39,234.89,10,2,1,2,AAPL,0.0,0.0,0.0,
2024-10-21 12:15:24.014202142+00:00,2024-10-21T12:15:24.014368498Z,10,2,38,A,B,1,233.87,400,130,166356,12489126,233.97,234.13,5,400,1,1,233.87,234.15,400,400,1,1,233.85,234.17,27,1,1,1,233.7,234.22,1200,27,1,1,233.66,234.41,1,600,1,2,233.58,234.43,505,105,2,2,233.53,234.5,10,63,1,4,233.5,234.75,100,1,1,1,233.45,234.79,15,2000,1,1,233.4,234.89,110,2,2,2,AAPL,0.0,0.0,0.0,
2024-10-21 12:15:24.014850794+00:00,2024-10-21T12:15:24.015016662Z,10,2,38,C,B,2,233.85,27,130,165868,12489129,233.97,234.13,5,400,1,1,233.87,234.15,400,400,1,1,233.7,234.17,1200,1,1,1,233.66,234.22,1,27,1,1,233.58,234.41,505,600,2,2,233.53,234.43,10,105,1,2,233.5,234.5,100,63,1,4,233.45,234.75,15,1,1,1,233.4,234.79,110,2000,2,1,233.39,234.89,10,2,1,2,AAPL,0.0,0.0,0.0,
2024-10-21 12:15:24.014897264+00:00,2024-10-21T12:15:24.015063463Z,10,2,38,A,B,2,233.79,29,130,166199,12489130,233.97,234.13,5,400,1,1,233.87,234.15,400,400,1,1,233.79,234.17,29,1,1,1,233.7,234.22,1200,27,1,1,233.66,234.41,1,600,1,2,233.58,234.43,505,105,2,2,233.53,234.5,10,63,1,4,233.5,234.75,100,1,1,1,233.45,234.79,15,2000,1,1,233.4,234.89,110,2,2,2,AAPL,0.0,0.0,0.0,
2024-10-21 12:15:24.015005588+00:00,2024-10-21T12:15:24.015171797Z,10,2,38,C,A,3,234.22,27,130,166209,12489131,233.97,234.13,5,400,1,1,233.87,234.15,400,400,1,1,233.79,234.17,29,1,1,1,233.7,234.41,1200,600,1,2,233.66,234.43,1,105,1,2,233.58,234.5,505,63,2,4,233.53,234.75,10,1,1,1,233.5,234.79,100,2000,1,1,233.45,234.89,15,2,1,2,233.4,235.0,110,213,2,6,AAPL,0.0,0.0,0.0,
2024-10-21 12:15:24.015059897+00:00,2024-10-21T12:15:24.015226111Z,10,2,38,A,A,2,234.17,30,130,166214,12489132,233.97,234.13,5,400,1,1,233.87,234.15,400,400,1,1,233.79,234.17,29,31,1,2,233.7,234.41,1200,600,1,2,233.66,234.43,1,105,1,2,233.58,234.5,505,63,2,4,233.53,234.75,10,1,1,1,233.5,234.79,100,2000,1,1,233.45,234.89,15,2,1,2,233.4,235.0,110,213,2,6,AAPL,0.0,-30.0,0.0,
2024-10-21 12:15:24.066509814+00:00,2024-10-21T12:15:24.066676377Z,10,2,38,A,A,0,234.1,200,130,166563,12489179,233.97,234.1,5,200,1,1,233.87,234.13,400,400,1,1,233.79,234.17,29,31,1,2,233.7,234.41,1200,600,1,2,233.66,234.43,1,105,1,2,233.58,234.5,505,63,2,4,233.53,234.75,10,1,1,1,233.5,234.79,100,2000,1,1,233.45,234.89,15,2,1,2,233.4,235.0,110,213,2,6,AAPL,0.0,0.0,0.0,
2024-10-21 12:15:27.519238798+00:00,2024-10-21T12:15:27.519404999Z,10,2,38,C,B,1,233.87,400,130,166201,12491655,233.97,234.1,5,200,1,1,233.79,234.13,29,400,1,1,233.7,234.17,1200,31,1,2,233.66,234.41,1,600,1,2,233.58,234.43,505,105,2,2,233.53,234.5,10,63,1,4,233.5,234.75,100,1,1,1,233.45,234.79,15,2000,1,1,233.4,234.89,110,2,2,2,233.39,235.0,10,213,1,6,AAPL,0.0,0.0,0.0,
2024-10-21 12:15:27.519251700+00:00,2024-10-21T12:15:27.519418174Z,10,2,38,A,B,1,233.84,200,130,166474,12491656,233.97,234.1,5,200,1,1,233.84,234.13,200,400,1,1,233.79,234.17,29,31,1,2,233.7,234.41,1200,600,1,2,233.66,234.43,1,105,1,2,233.58,234.5,505,63,2,4,233.53,234.75,10,1,1,1,233.5,234.79,100,2000,1,1,233.45,234.89,15,2,1,2,233.4,235.0,110,213,2,6,AAPL,0.0,0.0,0.0,
2024-10-21 12:15:29.175215826+00:00,2024-10-21T12:15:29.175384059Z,10,2,38,T,A,0,233.97,5,0,168233,12493180,233.97,234.1,5,200,1,1,233.84,234.13,200,400,1,1,233.79,234.17,29,31,1,2,233.7,234.41,1200,600,1,2,233.66,234.43,1,105,1,2,233.58,234.5,505,63,2,4,233.53,234.75,10,1,1,1,233.5,234.79,100,2000,1,1,233.45,234.89,15,2,1,2,233.4,235.0,110,213,2,6,AAPL,0.0,0.0,0.0,
2024-10-21 12:15:29.175215826+00:00,2024-10-21T12:15:29.175384059Z,10,2,38,A,N,0,233.95,295,130,168233,12493181,233.84,233.95,200,295,1,1,233.79,234.1,29,200,1,1,233.7,234.13,1200,400,1,1,233.66,234.17,1,31,1,2,233.58,234.41,505,600,2,2,233.53,234.43,10,105,1,2,233.5,234.5,100,63,1,4,233.45,234.75,15,1,1,1,233.4,234.79,110,2000,2,1,233.39,234.89,10,2,1,2,AAPL,0.0,0.0,0.0,
2024-10-21 12:15:29.175239385+00:00,2024-10-21T12:15:29.175406869Z,10,2,38,A,A,1,234.07,100,130,167484,12493182,233.84,233.95,200,295,1,1,233.79,234.07,29,100,1,1,233.7,234.1,1200,200,1,1,233.66,234.13,1,400,1,1,233.58,234.17,505,31,2,2,233.53,234.41,10,600,1,2,233.5,234.43,100,105,1,2,233.45,234.5,15,63,1,4,233.4,234.75,110,1,2,1,233.39,234.79,10,2000,1,1,AAPL,0.0,0.0,0.0,
2024-10-21 12:15:29.175244705+00:00,2024-10-21T12:15:29.175410757Z,10,2,38,A,A,1,234.04,38,130,166052,12493183,233.84,233.95,200,295,1,1,233.79,234.04,29,38,1,1,233.7,234.07,1200,100,1,1,233.66,234.1,1,200,1,1,233.58,234.13,505,400,2,1,233.53,234.17,10,31,1,2,233.5,234.41,100,600,1,2,233.45,234.43,15,105,1,2,233.4,234.5,110,63,2,4,233.39,234.75,10,1,1,1,AAPL,0.0,0.0,0.0,
2024-10-21 12:15:29.175252395+00:00,2024-10-21T12:15:29.175418381Z,10,2,38,A,A,2,234.07,100,130,165986,12493184,233.84,233.95,200,295,1,1,233.79,234.04,29,38,1,1,233.7,234.07,1200,200,1,2,233.66,234.1,1,200,1,1,233.58,234.13,505,400,2,1,233.53,234.17,10,31,1,2,233.5,234.41,100,600,1,2,233.45,234.43,15,105,1,2,233.4,234.5,110,63,2,4,233.39,234.75,10,1,1,1,AAPL,0.0,-100.0,0.0,
2024-10-21 12:15:29.175261243+00:00,2024-10-21T12:15:29.175428571Z,10,2,38,T,B,0,233.95,187,130,167328,12493185,233.84,233.95,200,295,1,1,233.79,234.04,29,38,1,1,233.7,234.07,1200,200,1,2,233.66,234.1,1,200,1,1,233.58,234.13,505,400,2,1,233.53,234.17,10,31,1,2,233.5,234.41,100,600,1,2,233.45,234.43,15,105,1,2,233.4,234.5,110,63,2,4,233.39,234.75,10,1,1,1,AAPL,0.0,0.0,0.0,
2024-10-21 12:15:29.175261243+00:00,2024-10-21T12:15:29.175428571Z,10,2,38,C,A,0,233.95,187,130,167328,12493185,233.84,233.95,200,108,1,1,233.79,234.04,29,38,1,1,233.7,234.07,1200,200,1,2,233.66,234.1,1,200,1,1,233.58,234.13,505,400,2,1,233.53,234.17,10,31,1,2,233.5,234.41,100,600,1,2,233.45,234.43,15,105,1,2,233.4,234.5,110,63,2,4,233.39,234.75,10,1,1,1,AAPL,187.0,187.0,187.0,
2024-10-21 12:15:29.175265540+00:00,2024-10-21T12:15:29.175431546Z,10,2,38,A,A,1,234.04,38,130,166006,12493186,233.84,233.95,200,108,1,1,233.79,234.04,29,76,1,2,233.7,234.07,1200,200,1,2,233.66,234.1,1,200,1,1,233.58,234.13,505,400,2,1,233.53,234.17,10,31,1,2,233.5,234.41,100,600,1,2,233.45,234.43,15,105,1,2,233.4,234.5,110,63,2,4,233.39,234.75,10,1,1,1,AAPL,0.0,-38.0,187.0,
2024-10-21 12:15:29.175269965+00:00,2024-10-21T12:15:29.175437237Z,10,2,38,T,B,0,233.95,108,130,167272,12493187,233.84,233.95,200,108,1,1,233.79,234.04,29,76,1,2,233.7,234.07,1200,200,1,2,233.66,234.1,1,200,1,1,233.58,234.13,505,400,2,1,233.53,234.17,10,31,1,2,233.5,234.41,100,600,1,2,233.45,234.43,15,105,1,2,233.4,234.5,110,63,2,4,233.39,234.75,10,1,1,1,AAPL,0.0,0.0,187.0,
2024-10-21 12:15:29.175269965+00:00,2024-10-21T12:15:29.175437237Z,10,2,38,C,A,0,233.95,108,130,167272,12493187,233.84,234.04,200,76,1,2,233.79,234.07,29,200,1,2,233.7,234.1,1200,200,1,1,233.66,234.13,1,400,1,1,233.58,234.17,505,31,2,2,233.53,234.41,10,600,1,2,233.5,234.43,100,105,1,2,233.45,234.5,15,63,1,4,233.4,234.75,110,1,2,1,233.39,234.79,10,2000,1,1,AAPL,0.0,0.0,187.0,
2024-10-21 12:15:29.175287761+00:00,2024-10-21T12:15:29.175453602Z,10,2,38,C,A,1,234.07,100,130,165841,12493188,233.84,234.04,200,76,1,2,233.79,234.07,29,100,1,1,233.7,234.1,1200,200,1,1,233.66,234.13,1,400,1,1,233.58,234.17,505,31,2,2,233.53,234.41,10,600,1,2,233.5,234.43,100,105,1,2,233.45,234.5,15,63,1,4,233.4,234.75,110,1,2,1,233.39,234.79,10,2000,1,1,AAPL,0.0,100.0,187.0,
2024-10-21 12:15:29.175293157+00:00,2024-10-21T12:15:29.175459603Z,10,2,38,C,A,0,234.04,38,130,166446,12493190,233.84,234.04,200,38,1,1,233.79,234.07,29,100,1,1,233.7,234.1,1200,200,1,1,233.66,234.13,1,400,1,1,233.58,234.17,505,31,2,2,233.53,234.41,10,600,1,2,233.5,234.43,100,105,1,2,233.45,234.5,15,63,1,4,233.4,234.75,110,1,2,1,233.39,234.79,10,2000,1,1,AAPL,38.0,38.0,225.0,
2024-10-21 12:15:29.175298862+00:00,2024-10-21T12:15:29.175464536Z,10,2,38,C,A,1,234.07,100,130,165674,12493191,233.84,234.04,200,38,1,1,233.79,234.1,29,200,1,1,233.7,234.13,1200,400,1,1,233.66,234.17,1,31,1,2,233.58,234.41,505,600,2,2,233.53,234.43,10,105,1,2,233.5,234.5,100,63,1,4,233.45,234.75,15,1,1,1,233.4,234.79,110,2000,2,1,233.39,234.89,10,2,1,2,AAPL,0.0,0.0,225.0,
2024-10-21 12:15:29.175307953+00:00,2024-10-21T12:15:29.175475521Z,10,2,38,A,A,1,234.08,38,130,167568,12493192,233.84,234.04,200,38,1,1,233.79,234.08,29,38,1,1,233.7,234.1,1200,200,1,1,233.66,234.13,1,400,1,1,233.58,234.17,505,31,2,2,233.53,234.41,10,600,1,2,233.5,234.43,100,105,1,2,233.45,234.5,15,63,1,4,233.4,234.75,110,1,2,1,233.39,234.79,10,2000,1,1,AAPL,0.0,0.0,225.0,
2024-10-21 12:15:29.175318339+00:00,2024-10-21T12:15:29.175484200Z,10,2,38,C,A,2,234.1,200,130,165861,12493193,233.84,234.04,200,38,1,1,233.79,234.08,29,38,1,1,233.7,234.13,1200,400,1,1,233.66,234.17,1,31,1,2,233.58,234.41,505,600,2,2,233.53,234.43,10,105,1,2,233.5,234.5,100,63,1,4,233.45,234.75,15,1,1,1,233.4,234.79,110,2000,2,1,233.39,234.89,10,2,1,2,AAPL,0.0,0.0,225.0,
2024-10-21 12:15:29.175376083+00:00,2024-10-21T12:15:29.175542211Z,10,2,38,A,B,0,233.89,38,130,166128,12493194,233.89,234.04,38,38,1,1,233.84,234.08,200,38,1,1,233.79,234.13,29,400,1,1,233.7,234.17,1200,31,1,2,233.66,234.41,1,600,1,2,233.58,234.43,505,105,2,2,233.53,234.5,10,63,1,4,233.5,234.75,100,1,1,1,233.45,234.79,15,2000,1,1,233.4,234.89,110,2,2,2,AAPL,0.0,0.0,225.0,
2024-10-21 12:15:29.175388906+00:00,2024-10-21T12:15:29.175555082Z,10,2,38,A,B,1,233.86,38,130,166176,12493195,233.89,234.04,38,38,1,1,233.86,234.08,38,38,1,1,233.84,234.13,200,400,1,1,233.79,234.17,29,31,1,2,233.7,234.41,1200,600,1,2,233.66,234.43,1,105,1,2,233.58,234.5,505,63,2,4,233.53,234.75,10,1,1,1,233.5,234.79,100,2000,1,1,233.45,234.89,15,2,1,2,AAPL,0.0,0.0,225.0,
2024-10-21 12:15:29.246390784+00:00,2024-10-21T12:15:29.246556838Z,10,2,38,C,B,2,233.84,200,130,166054,12493277,233.89,234.04,38,38,1,1,233.86,234.08,38,38,1,1,233.79,234.13,29,400,1,1,233.7,234.17,1200,31,1,2,233.66,234.41,1,600,1,2,233.58,234.43,505,105,2,2,233.53,234.5,10,63,1,4,233.5,234.75,100,1,1,1,233.45,234.79,15,2000,1,1,233.4,234.89,110,2,2,2,AAPL,0.0,0.0,225.0,
2024-10-21 12:15:29.246423576+00:00,2024-10-21T12:15:29.246589766Z,10,2,38,A,B,3,233.76,400,130,166190,12493278,233.89,234.04,38,38,1,1,233.86,234.08,38,38,1,1,233.79,234.13,29,400,1,1,233.76,234.17,400,31,1,2,233.7,234.41,1200,600,1,2,233.66,234.43,1,105,1,2,233.58,234.5,505,63,2,4,233.53,234.75,10,1,1,1,233.5,234.79,100,2000,1,1,233.45,234.89,15,2,1,2,AAPL,0.0,0.0,225.0,
2024-10-21 12:15:29.246816914+00:00,2024-10-21T12:15:29.246983004Z,10,2,38,C,B,2,233.79,29,130,166090,12493279,233.89,234.04,38,38,1,1,233.86,234.08,38,38,1,1,233.76,234.13,400,400,1,1,233.7,234.17,1200,31,1,2,233.66,234.41,1,600,1,2,233.58,234.43,505,105,2,2,233.53,234.5,10,63,1,4,233.5,234.75,100,1,1,1,233.45,234.79,15,2000,1,1,233.4,234.89,110,2,2,2,AAPL,0.0,0.0,225.0,
2024-10-21 12:15:29.246910849+00:00,2024-10-21T12:15:29.247077109Z,10,2,38,A,B,3,233.74,28,130,166260,12493280,233.89,234.04,38,38,1,1,233.86,234.08,38,38,1,1,233.76,234.13,400,400,1,1,233.74,234.17,28,31,1,2,233.7,234.41,1200,600,1,2,233.66,234.43,1,105,1,2,233.58,234.5,505,63,2,4,233.53,234.75,10,1,1,1,233.5,234.79,100,2000,1,1,233.45,234.89,15,2,1,2,AAPL,0.0,0.0,225.0,
2024-10-21 12:15:29.283764753+00:00,2024-10-21T12:15:29.283930892Z,10,2,38,C,A,1,234.08,38,130,166139,12493295,233.89,234.04,38,38,1,1,233.86,234.13,38,400,1,1,233.76,234.17,400,31,1,2,233.74,234.41,28,600,1,2,233.7,234.43,1200,105,1,2,233.66,234.5,1,63,1,4,233.58,234.75,505,1,2,1,233.53,234.79,10,2000,1,1,233.5,234.89,100,2,1,2,233.45,235.0,15,213,1,6,AAPL,0.0,0.0,225.0,
2024-10-21 12:15:29.283775550+00:00,2024-10-21T12:15:29.283941482Z,10,2,38,C,B,1,233.86,38,130,165932,12493296,233.89,234.04,38,38,1,1,233.76,234.13,400,400,1,1,233.74,234.17,28,31,1,2,233.7,234.41,1200,600,1,2,233.66,234.43,1,105,1,2,233.58,234.5,505,63,2,4,233.53,234.75,10,1,1,1,233.5,234.79,100,2000,1,1,233.45,234.89,15,2,1,2,233.4,235.0,110,213,2,6,AAPL,0.0,0.0,225.0,
2024-10-21 12:15:29.283823523+00:00,2024-10-21T12:15:29.283989568Z,10,2,38,A,A,1,234.1,400,130,166045,12493297,233.89,234.04,38,38,1,1,233.76,234.1,400,400,1,1,233.74,234.13,28,400,1,1,233.7,234.17,1200,31,1,2,233.66,234.41,1,600,1,2,233.58,234.43,505,105,2,2,233.53,234.5,10,63,1,4,233.5,234.75,100,1,1,1,233.45,234.79,15,2000,1,1,233.4,234.89,110,2,2,2,AAPL,0.0,0.0,225.0,
2024-10-21 12:15:29.425332139+00:00,2024-10-21T12:15:29.425498174Z,10,2,38,C,A,0,234.04,38,130,166035,12493515,233.89,234.1,38,400,1,1,233.76,234.13,400,400,1,1,233.74,234.17,28,31,1,2,233.7,234.41,1200,600,1,2,233.66,234.43,1,105,1,2,233.58,234.5,505,63,2,4,233.53,234.75,10,1,1,1,233.5,234.79,100,2000,1,1,233.45,234.89,15,2,1,2,233.4,235.0,110,213,2,6,AAPL,0.0,0.0,225.0,
2024-10-21 12:15:29.425342648+00:00,2024-10-21T12:15:29.425509152Z,10,2,38,C,B,0,233.89,38,130,166504,12493516,233.76,234.1,400,400,1,1,233.74,234.13,28,400,1,1,233.7,234.17,1200,31,1,2,233.66,234.41,1,600,1,2,233.58,234.43,505,105,2,2,233.53,234.5,10,63,1,4,233.5,234.75,100,1,1,1,233.45,234.79,15,2000,1,1,233.4,234.89,110,2,2,2,233.39,235.0,10,213,1,6,AAPL,0.0,0.0,225.0,
2024-10-21 12:15:29.496494580+00:00,2024-10-21T12:15:29.496660616Z,10,2,38,C,B,0,233.76,200,130,166036,12493549,233.76,234.1,200,400,1,1,233.74,234.13,28,400,1,1,233.7,234.17,1200,31,1,2,233.66,234.41,1,600,1,2,233.58,234.43,505,105,2,2,233.53,234.5,10,63,1,4,233.5,234.75,100,1,1,1,233.45,234.79,15,2000,1,1,233.4,234.89,110,2,2,2,233.39,235.0,10,213,1,6,AAPL,-200.0,-200.0,25.0,
2024-10-21 12:15:38.712816410+00:00,2024-10-21T12:15:38.712982908Z,10,2,38,C,A,0,234.1,200,130,166498,12503722,233.76,234.1,200,200,1,1,233.74,234.13,28,400,1,1,233.7,234.17,1200,31,1,2,233.66,234.41,1,600,1,2,233.58,234.43,505,105,2,2,233.53,234.5,10,63,1,4,233.5,234.75,100,1,1,1,233.45,234.79,15,2000,1,1,233.4,234.89,110,2,2,2,233.39,235.0,10,213,1,6,AAPL,200.0,200.0,200.0,
2024-10-21 12:15:38.816614723+00:00,2024-10-21T12:15:38.816780965Z,10,2,38,A,A,0,234.1,200,130,166242,12504039,233.76,234.1,200,400,1,2,233.74,234.13,28,400,1,1,233.7,234.17,1200,31,1,2,233.66,234.41,1,600,1,2,233.58,234.43,505,105,2,2,233.53,234.5,10,63,1,4,233.5,234.75,100,1,1,1,233.45,234.79,15,2000,1,1,233.4,234.89,110,2,2,2,233.39,235.0,10,213,1,6,AAPL,-200.0,-200.0,0.0,
2024-10-21 12:15:39.207080252+00:00,2024-10-21T12:15:39.207247997Z,10,2,38,A,A,0,234.0,22,130,167745,12504453,233.76,234.0,200,22,1,1,233.74,234.1,28,400,1,2,233.7,234.13,1200,400,1,1,233.66,234.17,1,31,1,2,233.58,234.41,505,600,2,2,233.53,234.43,10,105,1,2,233.5,234.5,100,63,1,4,233.45,234.75,15,1,1,1,233.4,234.79,110,2000,2,1,233.39,234.89,10,2,1,2,AAPL,0.0,0.0,0.0,
2024-10-21 12:15:39.207103673+00:00,2024-10-21T12:15:39.207269463Z,10,2,38,C,B,0,233.76,200,130,165790,12504456,233.74,234.0,28,22,1,1,233.7,234.1,1200,400,1,2,233.66,234.13,1,400,1,1,233.58,234.17,505,31,2,2,233.53,234.41,10,600,1,2,233.5,234.43,100,105,1,2,233.45,234.5,15,63,1,4,233.4,234.75,110,1,2,1,233.39,234.79,10,2000,1,1,233.31,234.89,110,2,2,2,AAPL,0.0,0.0,0.0,
2024-10-21 12:15:39.207167970+00:00,2024-10-21T12:15:39.207333984Z,10,2,38,C,A,1,234.1,200,130,166014,12504459,233.74,234.0,28,22,1,1,233.7,234.1,1200,200,1,1,233.66,234.13,1,400,1,1,233.58,234.17,505,31,2,2,233.53,234.41,10,600,1,2,233.5,234.43,100,105,1,2,233.45,234.5,15,63,1,4,233.4,234.75,110,1,2,1,233.39,234.79,10,2000,1,1,233.31,234.89,110,2,2,2,AAPL,0.0,200.0,0.0,
2024-10-21 12:15:39.207241805+00:00,2024-10-21T12:15:39.207408030Z,10,2,38,C,A,1,234.1,200,130,166225,12504461,233.74,234.0,28,22,1,1,233.7,234.13,1200,400,1,1,233.66,234.17,1,31,1,2,233.58,234.41,505,600,2,2,233.53,234.43,10,105,1,2,233.5,234.5,100,63,1,4,233.45,234.75,15,1,1,1,233.4,234.79,110,2000,2,1,233.39,234.89,10,2,1,2,233.31,235.0,110,213,2,6,AAPL,0.0,0.0,0.0,
2024-10-21 12:15:39.207535631+00:00,2024-10-21T12:15:39.207701481Z,10,2,38,C,A,0,234.0,22,130,165850,12504467,233.74,234.13,28,400,1,1,233.7,234.17,1200,31,1,2,233.66,234.41,1,600,1,2,233.58,234.43,505,105,2,2,233.53,234.5,10,63,1,4,233.5,234.75,100,1,1,1,233.45,234.79,15,2000,1,1,233.4,234.89,110,2,2,2,233.39,235.0,10,213,1,6,233.31,235.03,110,2,2,1,AAPL,0.0,0.0,0.0,
2024-10-21 12:15:39.274707573+00:00,2024-10-21T12:15:39.274873761Z,10,2,38,C,B,0,233.74,28,130,166188,12504518,233.7,234.13,1200,400,1,1,233.66,234.17,1,31,1,2,233.58,234.41,505,600,2,2,233.53,234.43,10,105,1,2,233.5,234.5,100,63,1,4,233.45,234.75,15,1,1,1,233.4,234.79,110,2000,2,1,233.39,234.89,10,2,1,2,233.31,235.0,110,213,2,6,233.3,235.03,100,2,1,1,AAPL,0.0,0.0,0.0,
2024-10-21 12:15:39.274794258+00:00,2024-10-21T12:15:39.274960881Z,10,2,38,A,B,1,233.69,28,130,166623,12504519,233.7,234.13,1200,400,1,1,233.69,234.17,28,31,1,2,233.66,234.41,1,600,1,2,233.58,234.43,505,105,2,2,233.53,234.5,10,63,1,4,233.5,234.75,100,1,1,1,233.45,234.79,15,2000,1,1,233.4,234.89,110,2,2,2,233.39,235.0,10,213,1,6,233.31,235.03,110,2,2,1,AAPL,0.0,0.0,0.0,
2024-10-21 12:15:39.314122970+00:00,2024-10-21T12:15:39.314289508Z,10,2,38,A,B,0,233.76,200,130,166538,12504563,233.76,234.13,200,400,1,1,233.7,234.17,1200,31,1,2,233.69,234.41,28,600,1,2,233.66,234.43,1,105,1,2,233.58,234.5,505,63,2,4,233.53,234.75,10,1,1,1,233.5,234.79,100,2000,1,1,233.45,234.89,15,2,1,2,233.4,235.0,110,213,2,6,233.39,235.03,10,2,1,1,AAPL,0.0,0.0,0.0,
2024-10-21 12:15:39.314137186+00:00,2024-10-21T12:15:39.314303543Z,10,2,38,A,A,0,234.1,400,130,166357,12504564,233.76,234.1,200,400,1,1,233.7,234.13,1200,400,1,1,233.69,234.17,28,31,1,2,233.66,234.41,1,600,1,2,233.58,234.43,505,105,2,2,233.53,234.5,10,63,1,4,233.5,234.75,100,1,1,1,233.45,234.79,15,2000,1,1,233.4,234.89,110,2,2,2,233.39,235.0,10,213,1,6,AAPL,0.0,0.0,0.0,
2024-10-21 12:15:40.360537773+00:00,2024-10-21T12:15:40.360705214Z,10,2,38,C,A,0,234.1,400,130,167441,12505301,233.76,234.13,200,400,1,1,233.7,234.17,1200,31,1,2,233.69,234.41,28,600,1,2,233.66,234.43,1,105,1,2,233.58,234.5,505,63,2,4,233.53,234.75,10,1,1,1,233.5,234.79,100,2000,1,1,233.45,234.89,15,2,1,2,233.4,235.0,110,213,2,6,233.39,235.03,10,2,1,1,AAPL,0.0,0.0,0.0,
2024-10-21 12:15:40.360548894+00:00,2024-10-21T12:15:40.360715053Z,10,2,38,A,A,1,234.15,400,130,166159,12505302,233.76,234.13,200,400,1,1,233.7,234.15,1200,400,1,1,233.69,234.17,28,31,1,2,233.66,234.41,1,600,1,2,233.58,234.43,505,105,2,2,233.53,234.5,10,63,1,4,233.5,234.75,100,1,1,1,233.45,234.79,15,2000,1,1,233.4,234.89,110,2,2,2,233.39,235.0,10,213,1,6,AAPL,0.0,0.0,0.0,
2024-10-21 12:15:40.361097351+00:00,2024-10-21T12:15:40.361263637Z,10,2,38,C,A,2,234.17,30,130,166286,12505308,233.76,234.13,200,400,1,1,233.7,234.15,1200,400,1,1,233.69,234.17,28,1,1,1,233.66,234.41,1,600,1,2,233.58,234.43,505,105,2,2,233.53,234.5,10,63,1,4,233.5,234.75,100,1,1,1,233.45,234.79,15,2000,1,1,233.4,234.89,110,2,2,2,233.39,235.0,10,213,1,6,AAPL,0.0,30.0,0.0,
2024-10-21 12:15:40.361146693+00:00,2024-10-21T12:15:40.361312977Z,10,2,38,A,A,3,234.22,27,130,166284,12505309,233.76,234.13,200,400,1,1,233.7,234.15,1200,400,1,1,233.69,234.17,28,1,1,1,233.66,234.22,1,27,1,1,233.58,234.41,505,600,2,2,233.53,234.43,10,105,1,2,233.5,234.5,100,63,1,4,233.45,234.75,15,1,1,1,233.4,234.79,110,2000,2,1,233.39,234.89,10,2,1,2,AAPL,0.0,0.0,0.0,
2024-10-21 12:15:43.400846263+00:00,2024-10-21T12:15:43.401012118Z,10,2,38,C,B,0,233.76,200,130,165855,12511389,233.7,234.13,1200,400,1,1,233.69,234.15,28,400,1,1,233.66,234.17,1,1,1,1,233.58,234.22,505,27,2,1,233.53,234.41,10,600,1,2,233.5,234.43,100,105,1,2,233.45,234.5,15,63,1,4,233.4,234.75,110,1,2,1,233.39,234.79,10,2000,1,1,233.31,234.89,110,2,2,2,AAPL,0.0,0.0,0.0,
2024-10-21 12:15:43.400859035+00:00,2024-10-21T12:15:43.401025404Z,10,2,38,A,B,0,233.74,200,130,166369,12511390,233.74,234.13,200,400,1,1,233.7,234.15,1200,400,1,1,233.69,234.17,28,1,1,1,233.66,234.22,1,27,1,1,233.58,234.41,505,600,2,2,233.53,234.43,10,105,1,2,233.5,234.5,100,63,1,4,233.45,234.75,15,1,1,1,233.4,234.79,110,2000,2,1,233.39,234.89,10,2,1,2,AAPL,0.0,0.0,0.0,
2024-10-21 12:15:43.425405296+00:00,2024-10-21T12:15:43.425571225Z,10,2,38,C,A,3,234.22,27,130,165929,12511697,233.74,234.13,200,400,1,1,233.7,234.15,1200,400,1,1,233.69,234.17,28,1,1,1,233.66,234.41,1,600,1,2,233.58,234.43,505,105,2,2,233.53,234.5,10,63,1,4,233.5,234.75,100,1,1,1,233.45,234.79,15,2000,1,1,233.4,234.89,110,2,2,2,233.39,235.0,10,213,1,6,AAPL,0.0,0.0,0.0,
2024-10-21 12:15:43.425456541+00:00,2024-10-21T12:15:43.425623021Z,10,2,38,A,A,3,234.21,26,130,166480,12511698,233.74,234.13,200,400,1,1,233.7,234.15,1200,400,1,1,233.69,234.17,28,1,1,1,233.66,234.21,1,26,1,1,233.58,234.41,505,600,2,2,233.53,234.43,10,105,1,2,233.5,234.5,100,63,1,4,233.45,234.75,15,1,1,1,233.4,234.79,110,2000,2,1,233.39,234.89,10,2,1,2,AAPL,0.0,0.0,0.0,
2024-10-21 12:15:43.454335483+00:00,2024-10-21T12:15:43.454501811Z,10,2,38,A,A,1,234.14,400,130,166328,12511807,233.74,234.13,200,400,1,1,233.7,234.14,1200,400,1,1,233.69,234.17,28,1,1,1,233.66,234.21,1,26,1,1,233.58,234.41,505,600,2,2,233.53,234.43,10,105,1,2,233.5,234.5,100,63,1,4,233.45,234.75,15,1,1,1,233.4,234.79,110,2000,2,1,233.39,234.89,10,2,1,2,AAPL,0.0,0.0,0.0,
2024-10-21 12:15:43.462325554+00:00,2024-10-21T12:15:43.462491808Z,10,2,38,A,A,0,234.13,400,130,166254,12511952,233.74,234.13,200,800,1,2,233.7,234.17,1200,1,1,1,233.69,234.21,28,26,1,1,233.66,234.41,1,600,1,2,233.58,234.43,505,105,2,2,233.53,234.5,10,63,1,4,233.5,234.75,100,1,1,1,233.45,234.79,15,2000,1,1,233.4,234.89,110,2,2,2,233.39,235.0,10,213,1,6,AAPL,-400.0,-400.0,-400.0,
2024-10-21 12:15:43.490467184+00:00,2024-10-21T12:15:43.490633387Z,10,2,38,A,B,3,233.66,30,130,166203,12512344,233.74,234.13,200,800,1,2,233.7,234.17,1200,1,1,1,233.69,234.21,28,26,1,1,233.66,234.41,31,600,2,2,233.58,234.43,505,105,2,2,233.53,234.5,10,63,1,4,233.5,234.75,100,1,1,1,233.45,234.79,15,2000,1,1,233.4,234.89,110,2,2,2,233.39,235.0,10,213,1,6,AAPL,0.0,30.0,-400.0,
2024-10-21 12:15:43.546099003+00:00,2024-10-21T12:15:43.546265076Z,10,2,38,C,B,2,233.69,28,130,166073,12512634,233.74,234.13,200,800,1,2,233.7,234.17,1200,1,1,1,233.66,234.21,31,26,2,1,233.58,234.41,505,600,2,2,233.53,234.43,10,105,1,2,233.5,234.5,100,63,1,4,233.45,234.75,15,1,1,1,233.4,234.79,110,2000,2,1,233.39,234.89,10,2,1,2,233.31,235.0,110,213,2,6,AAPL,0.0,0.0,-400.0,
2024-10-21 12:15:43.594813115+00:00,2024-10-21T12:15:43.594979866Z,10,2,38,A,A,0,234.12,200,130,166751,12512827,233.74,234.12,200,200,1,1,233.7,234.13,1200,400,1,1,233.66,234.17,31,1,2,1,233.58,234.21,505,26,2,1,233.53,234.41,10,600,1,2,233.5,234.43,100,105,1,2,233.45,234.5,15,63,1,4,233.4,234.75,110,1,2,1,233.39,234.79,10,2000,1,1,233.31,234.89,110,2,2,2,AAPL,0.0,0.0,-400.0,
2024-10-21 12:15:43.981284269+00:00,2024-10-21T12:15:43.981450269Z,10,2,38,A,A,3,234.19,28,130,166000,12513411,233.74,234.12,200,200,1,1,233.7,234.13,1200,400,1,1,233.66,234.17,31,1,2,1,233.58,234.19,505,28,2,1,233.53,234.21,10,26,1,1,233.5,234.41,100,600,1,2,233.45,234.43,15,105,1,2,233.4,234.5,110,63,2,4,233.39,234.75,10,1,1,1,233.31,234.79,110,2000,2,1,AAPL,0.0,0.0,-400.0,
2024-10-21 12:15:43.981579878+00:00,2024-10-21T12:15:43.981745796Z,10,2,38,C,A,4,234.21,26,130,165918,12513419,233.74,234.12,200,200,1,1,233.7,234.13,1200,400,1,1,233.66,234.17,31,1,2,1,233.58,234.19,505,28,2,1,233.53,234.41,10,600,1,2,233.5,234.43,100,105,1,2,233.45,234.5,15,63,1,4,233.4,234.75,110,1,2,1,233.39,234.79,10,2000,1,1,233.31,234.89,110,2,2,2,AAPL,0.0,0.0,-400.0,
2024-10-21 12:15:46.504444030+00:00,2024-10-21T12:15:46.504609799Z,10,2,38,C,B,0,233.74,200,130,165769,12517721,233.7,234.12,1200,200,1,1,233.66,234.13,31,400,2,1,233.58,234.17,505,1,2,1,233.53,234.19,10,28,1,1,233.5,234.41,100,600,1,2,233.45,234.43,15,105,1,2,233.4,234.5,110,63,2,4,233.39,234.75,10,1,1,1,233.31,234.79,110,2000,2,1,233.3,234.89,100,2,1,2,AAPL,0.0,0.0,0.0,
2024-10-21 12:15:46.504456348+00:00,2024-10-21T12:15:46.504623049Z,10,2,38,A,B,0,233.73,200,130,166701,12517722,233.73,234.12,200,200,1,1,233.7,234.13,1200,400,1,1,233.66,234.17,31,1,2,1,233.58,234.19,505,28,2,1,233.53,234.41,10,600,1,2,233.5,234.43,100,105,1,2,233.45,234.5,15,63,1,4,233.4,234.75,110,1,2,1,233.39,234.79,10,2000,1,1,233.31,234.89,110,2,2,2,AAPL,0.0,0.0,0.0,
2024-10-21 12:15:46.504469490+00:00,2024-10-21T12:15:46.504635795Z,10,2,38,A,A,0,234.12,200,130,166305,12517724,233.73,234.12,200,400,1,2,233.7,234.13,1200,400,1,1,233.66,234.17,31,1,2,1,233.58,234.19,505,28,2,1,233.53,234.41,10,600,1,2,233.5,234.43,100,105,1,2,233.45,234.5,15,63,1,4,233.4,234.75,110,1,2,1,233.39,234.79,10,2000,1,1,233.31,234.89,110,2,2,2,AAPL,-200.0,-200.0,-200.0,
2024-10-21 12:15:46.593690522+00:00,2024-10-21T12:15:46.593857210Z,10,2,38,A,A,3,234.18,30,130,166688,12518020,233.73,234.12,200,400,1,2,233.7,234.13,1200,400,1,1,233.66,234.17,31,1,2,1,233.58,234.18,505,30,2,1,233.53,234.19,10,28,1,1,233.5,234.41,100,600,1,2,233.45,234.43,15,105,1,2,233.4,234.5,110,63,2,4,233.39,234.75,10,1,1,1,233.31,234.79,110,2000,2,1,AAPL,0.0,0.0,-200.0,
2024-10-21 12:15:46.594059334+00:00,2024-10-21T12:15:46.594225497Z,10,2,38,C,A,4,234.19,28,130,166163,12518032,233.73,234.12,200,400,1,2,233.7,234.13,1200,400,1,1,233.66,234.17,31,1,2,1,233.58,234.18,505,30,2,1,233.53,234.41,10,600,1,2,233.5,234.43,100,105,1,2,233.45,234.5,15,63,1,4,233.4,234.75,110,1,2,1,233.39,234.79,10,2000,1,1,233.31,234.89,110,2,2,2,AAPL,0.0,0.0,-200.0,
2024-10-21 12:15:50.469736889+00:00,2024-10-21T12:15:50.469902981Z,10,2,38,C,A,0,234.12,200,130,166092,12522085,233.73,234.12,200,200,1,1,233.7,234.13,1200,400,1,1,233.66,234.17,31,1,2,1,233.58,234.18,505,30,2,1,233.53,234.41,10,600,1,2,233.5,234.43,100,105,1,2,233.45,234.5,15,63,1,4,233.4,234.75,110,1,2,1,233.39,234.79,10,2000,1,1,233.31,234.89,110,2,2,2,AAPL,200.0,200.0,200.0,
2024-10-21 12:15:55.593458354+00:00,2024-10-21T12:15:55.593624526Z,10,2,38,C,B,2,233.66,30,130,166172,12526601,233.73,234.12,200,200,1,1,233.7,234.13,1200,400,1,1,233.66,234.17,1,1,1,1,233.58,234.18,505,30,2,1,233.53,234.41,10,600,1,2,233.5,234.43,100,105,1,2,233.45,234.5,15,63,1,4,233.4,234.75,110,1,2,1,233.39,234.79,10,2000,1,1,233.31,234.89,110,2,2,2,AAPL,0.0,-30.0,0.0,
2024-10-21 12:15:55.593967834+00:00,2024-10-21T12:15:55.594134274Z,10,2,38,A,B,1,233.71,29,130,166440,12526613,233.73,234.12,200,200,1,1,233.71,234.13,29,400,1,1,233.7,234.17,1200,1,1,1,233.66,234.18,1,30,1,1,233.58,234.41,505,600,2,2,233.53,234.43,10,105,1,2,233.5,234.5,100,63,1,4,233.45,234.75,15,1,1,1,233.4,234.79,110,2000,2,1,233.39,234.89,10,2,1,2,AAPL,0.0,0.0,0.0,
2024-10-21 12:15:55.643523614+00:00,2024-10-21T12:15:55.643690186Z,10,2,38,A,B,0,233.77,200,130,166572,12526664,233.77,234.12,200,200,1,1,233.71,234.13,29,400,1,1,233.7,234.17,1200,1,1,1,233.66,234.18,1,30,1,1,233.58,234.41,505,600,2,2,233.53,234.43,10,105,1,2,233.5,234.5,100,63,1,4,233.45,234.75,15,1,1,1,233.4,234.79,110,2000,2,1,233.39,234.89,10,2,1,2,AAPL,0.0,0.0,0.0,
2024-10-21 12:16:00.253343668+00:00,2024-10-21T12:16:00.253510382Z,10,2,38,A,A,0,234.11,200,130,166714,12533252,233.77,234.11,200,200,1,1,233.71,234.13,29,400,1,1,233.7,234.17,1200,1,1,1,233.66,234.18,1,30,1,1,233.58,234.41,505,600,2,2,233.53,234.43,10,105,1,2,233.5,234.5,100,63,1,4,233.45,234.75,15,1,1,1,233.4,234.79,110,2000,2,1,233.39,234.89,10,2,1,2,AAPL,0.0,0.0,0.0,
2024-10-21 12:16:02.523121028+00:00,2024-10-21T12:16:02.523286908Z,10,2,38,C,B,0,233.77,200,130,165880,12536233,233.71,234.11,29,200,1,1,233.7,234.13,1200,400,1,1,233.66,234.17,1,1,1,1,233.58,234.18,505,30,2,1,233.53,234.41,10,600,1,2,233.5,234.43,100,105,1,2,233.45,234.5,15,63,1,4,233.4,234.75,110,1,2,1,233.39,234.79,10,2000,1,1,233.31,234.89,110,2,2,2,AAPL,0.0,0.0,0.0,
2024-10-21 12:16:02.523132984+00:00,2024-10-21T12:16:02.523299016Z,10,2,38,A,B,0,233.76,200,130,166032,12536234,233.76,234.11,200,200,1,1,233.71,234.13,29,400,1,1,233.7,234.17,1200,1,1,1,233.66,234.18,1,30,1,1,233.58,234.41,505,600,2,2,233.53,234.43,10,105,1,2,233.5,234.5,100,63,1,4,233.45,234.75,15,1,1,1,233.4,234.79,110,2000,2,1,233.39,234.89,10,2,1,2,AAPL,0.0,0.0,0.0,
2024-10-21 12:16:02.592915859+00:00,2024-10-21T12:16:02.593082475Z,10,2,38,A,A,2,234.17,27,130,166616,12536503,233.76,234.11,200,200,1,1,233.71,234.13,29,400,1,1,233.7,234.17,1200,28,1,2,233.66,234.18,1,30,1,1,233.58,234.41,505,600,2,2,233.53,234.43,10,105,1,2,233.5,234.5,100,63,1,4,233.45,234.75,15,1,1,1,233.4,234.79,110,2000,2,1,233.39,234.89,10,2,1,2,AAPL,0.0,-27.0,0.0,
2024-10-21 12:16:02.697358278+00:00,2024-10-21T12:16:02.697524299Z,10,2,38,C,A,3,234.18,30,130,166021,12536650,233.76,234.11,200,200,1,1,233.71,234.13,29,400,1,1,233.7,234.17,1200,28,1,2,233.66,234.41,1,600,1,2,233.58,234.43,505,105,2,2,233.53,234.5,10,63,1,4,233.5,234.75,100,1,1,1,233.45,234.79,15,2000,1,1,233.4,234.89,110,2,2,2,233.39,235.0,10,213,1,6,AAPL,0.0,0.0,0.0,
2024-10-21 12:16:04.305690771+00:00,2024-10-21T12:16:04.305857113Z,10,2,38,A,B,0,233.77,200,130,166342,12539302,233.77,234.11,200,200,1,1,233.71,234.13,29,400,1,1,233.7,234.17,1200,28,1,2,233.66,234.41,1,600,1,2,233.58,234.43,505,105,2,2,233.53,234.5,10,63,1,4,233.5,234.75,100,1,1,1,233.45,234.79,15,2000,1,1,233.4,234.89,110,2,2,2,233.39,235.0,10,213,1,6,AAPL,0.0,0.0,0.0,
2024-10-21 12:16:08.452195034+00:00,2024-10-21T12:16:08.452361078Z,10,2,38,C,B,0,233.77,200,130,166044,12544790,233.71,234.11,29,200,1,1,233.7,234.13,1200,400,1,1,233.66,234.17,1,28,1,2,233.58,234.41,505,600,2,2,233.53,234.43,10,105,1,2,233.5,234.5,100,63,1,4,233.45,234.75,15,1,1,1,233.4,234.79,110,2000,2,1,233.39,234.89,10,2,1,2,233.31,235.0,110,213,2,6,AAPL,0.0,0.0,0.0,
2024-10-21 12:16:08.452206841+00:00,2024-10-21T12:16:08.452373943Z,10,2,38,A,B,0,233.76,200,130,167102,12544791,233.76,234.11,200,200,1,1,233.71,234.13,29,400,1,1,233.7,234.17,1200,28,1,2,233.66,234.41,1,600,1,2,233.58,234.43,505,105,2,2,233.53,234.5,10,63,1,4,233.5,234.75,100,1,1,1,233.45,234.79,15,2000,1,1,233.4,234.89,110,2,2,2,233.39,235.0,10,213,1,6,AAPL,0.0,0.0,0.0,
2024-10-21 12:16:09.449805017+00:00,2024-10-21T12:16:09.449971056Z,10,2,38,C,B,1,233.71,29,130,166039,12545654,233.76,234.11,200,200,1,1,233.7,234.13,1200,400,1,1,233.66,234.17,1,28,1,2,233.58,234.41,505,600,2,2,233.53,234.43,10,105,1,2,233.5,234.5,100,63,1,4,233.45,234.75,15,1,1,1,233.4,234.79,110,2000,2,1,233.39,234.89,10,2,1,2,233.31,235.0,110,213,2,6,AAPL,0.0,0.0,0.0,
2024-10-21 12:16:09.449860480+00:00,2024-10-21T12:16:09.450027355Z,10,2,38,A,B,2,233.69,30,130,166875,12545655,233.76,234.11,200,200,1,1,233.7,234.13,1200,400,1,1,233.69,234.17,30,28,1,2,233.66,234.41,1,600,1,2,233.58,234.43,505,105,2,2,233.53,234.5,10,63,1,4,233.5,234.75,100,1,1,1,233.45,234.79,15,2000,1,1,233.4,234.89,110,2,2,2,233.39,235.0,10,213,1,6,AAPL,0.0,0.0,0.0,
2024-10-21 12:16:09.753811454+00:00,2024-10-21T12:16:09.753978514Z,10,2,38,C,B,0,233.76,200,130,167060,12546012,233.7,234.11,1200,200,1,1,233.69,234.13,30,400,1,1,233.66,234.17,1,28,1,2,233.58,234.41,505,600,2,2,233.53,234.43,10,105,1,2,233.5,234.5,100,63,1,4,233.45,234.75,15,1,1,1,233.4,234.79,110,2000,2,1,233.39,234.89,10,2,1,2,233.31,235.0,110,213,2,6,AAPL,0.0,0.0,0.0,
2024-10-21 12:16:09.753823460+00:00,2024-10-21T12:16:09.753989713Z,10,2,38,A,B,0,233.74,200,130,166253,12546013,233.74,234.11,200,200,1,1,233.7,234.13,1200,400,1,1,233.69,234.17,30,28,1,2,233.66,234.41,1,600,1,2,233.58,234.43,505,105,2,2,233.53,234.5,10,63,1,4,233.5,234.75,100,1,1,1,233.45,234.79,15,2000,1,1,233.4,234.89,110,2,2,2,233.39,235.0,10,213,1,6,AAPL,0.0,0.0,0.0,
2024-10-21 12:16:09.794081348+00:00,2024-10-21T12:16:09.794247866Z,10,2,38,A,A,0,234.1,200,130,166518,12546087,233.74,234.1,200,200,1,1,233.7,234.13,1200,400,1,1,233.69,234.17,30,28,1,2,233.66,234.41,1,600,1,2,233.58,234.43,505,105,2,2,233.53,234.5,10,63,1,4,233.5,234.75,100,1,1,1,233.45,234.79,15,2000,1,1,233.4,234.89,110,2,2,2,233.39,235.0,10,213,1,6,AAPL,0.0,0.0,0.0,
2024-10-21 12:16:09.813020869+00:00,2024-10-21T12:16:09.813187546Z,10,2,38,A,B,0,233.75,200,130,166677,12546174,233.75,234.1,200,200,1,1,233.7,234.13,1200,400,1,1,233.69,234.17,30,28,1,2,233.66,234.41,1,600,1,2,233.58,234.43,505,105,2,2,233.53,234.5,10,63,1,4,233.5,234.75,100,1,1,1,233.45,234.79,15,2000,1,1,233.4,234.89,110,2,2,2,233.39,235.0,10,213,1,6,AAPL,0.0,0.0,0.0,
2024-10-21 12:16:10.366504475+00:00,2024-10-21T12:16:10.366670967Z,10,2,38,A,A,0,234.09,200,130,166492,12546733,233.75,234.09,200,200,1,1,233.7,234.13,1200,400,1,1,233.69,234.17,30,28,1,2,233.66,234.41,1,600,1,2,233.58,234.43,505,105,2,2,233.53,234.5,10,63,1,4,233.5,234.75,100,1,1,1,233.45,234.79,15,2000,1,1,233.4,234.89,110,2,2,2,233.39,235.0,10,213,1,6,AAPL,0.0,0.0,0.0,
2024-10-21 12:16:10.387079865+00:00,2024-10-21T12:16:10.387245860Z,10,2,38,C,A,2,234.17,27,130,165995,12546807,233.75,234.09,200,200,1,1,233.7,234.13,1200,400,1,1,233.69,234.17,30,1,1,1,233.66,234.41,1,600,1,2,233.58,234.43,505,105,2,2,233.53,234.5,10,63,1,4,233.5,234.75,100,1,1,1,233.45,234.79,15,2000,1,1,233.4,234.89,110,2,2,2,233.39,235.0,10,213,1,6,AAPL,0.0,27.0,0.0,
2024-10-21 12:16:10.387136109+00:00,2024-10-21T12:16:10.387302448Z,10,2,38,A,A,2,234.16,29,130,166339,12546808,233.75,234.09,200,200,1,1,233.7,234.13,1200,400,1,1,233.69,234.16,30,29,1,1,233.66,234.17,1,1,1,1,233.58,234.41,505,600,2,2,233.53,234.43,10,105,1,2,233.5,234.5,100,63,1,4,233.45,234.75,15,1,1,1,233.4,234.79,110,2000,2,1,233.39,234.89,10,2,1,2,AAPL,0.0,0.0,0.0,
2024-10-21 12:16:12.011021598+00:00,2024-10-21T12:16:12.011187719Z,10,2,38,C,A,0,234.09,200,130,166121,12547958,233.75,234.13,200,400,1,1,233.7,234.16,1200,29,1,1,233.69,234.17,30,1,1,1,233.66,234.41,1,600,1,2,233.58,234.43,505,105,2,2,233.53,234.5,10,63,1,4,233.5,234.75,100,1,1,1,233.45,234.79,15,2000,1,1,233.4,234.89,110,2,2,2,233.39,235.0,10,213,1,6,AAPL,0.0,0.0,0.0,
2024-10-21 12:16:12.011034600+00:00,2024-10-21T12:16:12.011200956Z,10,2,38,A,A,0,234.11,200,130,166356,12547959,233.75,234.11,200,200,1,1,233.7,234.13,1200,400,1,1,233.69,234.16,30,29,1,1,233.66,234.17,1,1,1,1,233.58,234.41,505,600,2,2,233.53,234.43,10,105,1,2,233.5,234.5,100,63,1,4,233.45,234.75,15,1,1,1,233.4,234.79,110,2000,2,1,233.39,234.89,10,2,1,2,AAPL,0.0,0.0,0.0,
2024-10-21 12:16:12.100581387+00:00,2024-10-21T12:16:12.100747677Z,10,2,38,A,A,0,234.1,200,130,166290,12548144,233.75,234.1,200,200,1,1,233.7,234.13,1200,400,1,1,233.69,234.16,30,29,1,1,233.66,234.17,1,1,1,1,233.58,234.41,505,600,2,2,233.53,234.43,10,105,1,2,233.5,234.5,100,63,1,4,233.45,234.75,15,1,1,1,233.4,234.79,110,2000,2,1,233.39,234.89,10,2,1,2,AAPL,0.0,0.0,0.0,
2024-10-21 12:16:13.573710917+00:00,2024-10-21T12:16:13.573877503Z,10,2,38,A,A,0,234.09,200,130,166586,12549200,233.75,234.09,200,200,1,1,233.7,234.13,1200,400,1,1,233.69,234.16,30,29,1,1,233.66,234.17,1,1,1,1,233.58,234.41,505,600,2,2,233.53,234.43,10,105,1,2,233.5,234.5,100,63,1,4,233.45,234.75,15,1,1,1,233.4,234.79,110,2000,2,1,233.39,234.89,10,2,1,2,AAPL,0.0,0.0,0.0,
2024-10-21 12:16:14.439151195+00:00,2024-10-21T12:16:14.439317152Z,10,2,38,C,A,0,234.09,200,130,165957,12549789,233.75,234.13,200,400,1,1,233.7,234.16,1200,29,1,1,233.69,234.17,30,1,1,1,233.66,234.41,1,600,1,2,233.58,234.43,505,105,2,2,233.53,234.5,10,63,1,4,233.5,234.75,100,1,1,1,233.45,234.79,15,2000,1,1,233.4,234.89,110,2,2,2,233.39,235.0,10,213,1,6,AAPL,0.0,0.0,0.0,
2024-10-21 12:16:14.439163159+00:00,2024-10-21T12:16:14.439329197Z,10,2,38,A,A,0,234.1,200,130,166038,12549790,233.75,234.1,200,200,1,1,233.7,234.13,1200,400,1,1,233.69,234.16,30,29,1,1,233.66,234.17,1,1,1,1,233.58,234.41,505,600,2,2,233.53,234.43,10,105,1,2,233.5,234.5,100,63,1,4,233.45,234.75,15,1,1,1,233.4,234.79,110,2000,2,1,233.39,234.89,10,2,1,2,AAPL,0.0,0.0,0.0,
2024-10-21 12:16:14.647213365+00:00,2024-10-21T12:16:14.647379555Z,10,2,38,A,A,0,234.09,200,130,166190,12550175,233.75,234.09,200,200,1,1,233.7,234.13,1200,400,1,1,233.69,234.16,30,29,1,1,233.66,234.17,1,1,1,1,233.58,234.41,505,600,2,2,233.53,234.43,10,105,1,2,233.5,234.5,100,63,1,4,233.45,234.75,15,1,1,1,233.4,234.79,110,2000,2,1,233.39,234.89,10,2,1,2,AAPL,0.0,0.0,0.0,
2024-10-21 12:16:20.281774908+00:00,2024-10-21T12:16:20.281941255Z,10,2,38,C,B,0,233.75,200,130,166347,12556695,233.7,234.09,1200,200,1,1,233.69,234.13,30,400,1,1,233.66,234.16,1,29,1,1,233.58,234.17,505,1,2,1,233.53,234.41,10,600,1,2,233.5,234.43,100,105,1,2,233.45,234.5,15,63,1,4,233.4,234.75,110,1,2,1,233.39,234.79,10,2000,1,1,233.31,234.89,110,2,2,2,AAPL,0.0,0.0,0.0,
2024-10-21 12:16:20.281786576+00:00,2024-10-21T12:16:20.281953090Z,10,2,38,A,B,0,233.73,200,130,166514,12556696,233.73,234.09,200,200,1,1,233.7,234.13,1200,400,1,1,233.69,234.16,30,29,1,1,233.66,234.17,1,1,1,1,233.58,234.41,505,600,2,2,233.53,234.43,10,105,1,2,233.5,234.5,100,63,1,4,233.45,234.75,15,1,1,1,233.4,234.79,110,2000,2,1,233.39,234.89,10,2,1,2,AAPL,0.0,0.0,0.0,
2024-10-21 12:16:20.339168043+00:00,2024-10-21T12:16:20.339335090Z,10,2,38,A,B,0,233.74,200,130,167047,12556816,233.74,234.09,200,200,1,1,233.7,234.13,1200,400,1,1,233.69,234.16,30,29,1,1,233.66,234.17,1,1,1,1,233.58,234.41,505,600,2,2,233.53,234.43,10,105,1,2,233.5,234.5,100,63,1,4,233.45,234.75,15,1,1,1,233.4,234.79,110,2000,2,1,233.39,234.89,10,2,1,2,AAPL,0.0,0.0,0.0,
2024-10-21 12:16:20.352089791+00:00,2024-10-21T12:16:20.352255989Z,10,2,38,A,B,0,233.74,200,130,166198,12556912,233.74,234.09,400,200,2,1,233.7,234.13,1200,400,1,1,233.69,234.16,30,29,1,1,233.66,234.17,1,1,1,1,233.58,234.41,505,600,2,2,233.53,234.43,10,105,1,2,233.5,234.5,100,63,1,4,233.45,234.75,15,1,1,1,233.4,234.79,110,2000,2,1,233.39,234.89,10,2,1,2,AAPL,200.0,200.0,200.0,
2024-10-21 12:16:20.353055730+00:00,2024-10-21T12:16:20.353221672Z,10,2,38,C,B,0,233.74,200,130,165942,12556917,233.74,234.09,200,200,1,1,233.7,234.13,1200,400,1,1,233.69,234.16,30,29,1,1,233.66,234.17,1,1,1,1,233.58,234.41,505,600,2,2,233.53,234.43,10,105,1,2,233.5,234.5,100,63,1,4,233.45,234.75,15,1,1,1,233.4,234.79,110,2000,2,1,233.39,234.89,10,2,1,2,AAPL,-200.0,-200.0,0.0,
2024-10-21 12:16:20.448469192+00:00,2024-10-21T12:16:20.448635525Z,10,2,38,A,A,0,234.08,200,130,166333,12557144,233.74,234.08,200,200,1,1,233.7,234.13,1200,400,1,1,233.69,234.16,30,29,1,1,233.66,234.17,1,1,1,1,233.58,234.41,505,600,2,2,233.53,234.43,10,105,1,2,233.5,234.5,100,63,1,4,233.45,234.75,15,1,1,1,233.4,234.79,110,2000,2,1,233.39,234.89,10,2,1,2,AAPL,0.0,0.0,0.0,
2024-10-21 12:16:34.456311187+00:00,2024-10-21T12:16:34.456477234Z,10,2,38,C,A,2,234.16,29,130,166047,12569933,233.74,234.08,200,200,1,1,233.7,234.13,1200,400,1,1,233.69,234.17,30,1,1,1,233.66,234.41,1,600,1,2,233.58,234.43,505,105,2,2,233.53,234.5,10,63,1,4,233.5,234.75,100,1,1,1,233.45,234.79,15,2000,1,1,233.4,234.89,110,2,2,2,233.39,235.0,10,213,1,6,AAPL,0.0,0.0,0.0,
2024-10-21 12:16:34.456367935+00:00,2024-10-21T12:16:34.456534808Z,10,2,38,A,A,2,234.15,30,130,166873,12569937,233.74,234.08,200,200,1,1,233.7,234.13,1200,400,1,1,233.69,234.15,30,30,1,1,233.66,234.17,1,1,1,1,233.58,234.41,505,600,2,2,233.53,234.43,10,105,1,2,233.5,234.5,100,63,1,4,233.45,234.75,15,1,1,1,233.4,234.79,110,2000,2,1,233.39,234.89,10,2,1,2,AAPL,0.0,0.0,0.0,
2024-10-21 12:16:35.928124957+00:00,2024-10-21T12:16:35.928291181Z,10,2,38,C,B,2,233.69,30,130,166224,12572168,233.74,234.08,200,200,1,1,233.7,234.13,1200,400,1,1,233.66,234.15,1,30,1,1,233.58,234.17,505,1,2,1,233.53,234.41,10,600,1,2,233.5,234.43,100,105,1,2,233.45,234.5,15,63,1,4,233.4,234.75,110,1,2,1,233.39,234.79,10,2000,1,1,233.31,234.89,110,2,2,2,AAPL,0.0,0.0,0.0,
2024-10-21 12:16:35.928176126+00:00,2024-10-21T12:16:35.928342407Z,10,2,38,A,B,2,233.67,28,130,166281,12572169,233.74,234.08,200,200,1,1,233.7,234.13,1200,400,1,1,233.67,234.15,28,30,1,1,233.66,234.17,1,1,1,1,233.58,234.41,505,600,2,2,233.53,234.43,10,105,1,2,233.5,234.5,100,63,1,4,233.45,234.75,15,1,1,1,233.4,234.79,110,2000,2,1,233.39,234.89,10,2,1,2,AAPL,0.0,0.0,0.0,
2024-10-21 12:16:36.290091431+00:00,2024-10-21T12:16:36.290257872Z,10,2,38,A,A,1,234.1,100,130,166441,12572429,233.74,234.08,200,200,1,1,233.7,234.1,1200,100,1,1,233.67,234.13,28,400,1,1,233.66,234.15,1,30,1,1,233.58,234.17,505,1,2,1,233.53,234.41,10,600,1,2,233.5,234.43,100,105,1,2,233.45,234.5,15,63,1,4,233.4,234.75,110,1,2,1,233.39,234.79,10,2000,1,1,AAPL,0.0,0.0,0.0,
2024-10-21 12:16:37.672726079+00:00,2024-10-21T12:16:37.672891891Z,10,2,38,C,B,2,233.67,28,130,165812,12574327,233.74,234.08,200,200,1,1,233.7,234.1,1200,100,1,1,233.66,234.13,1,400,1,1,233.58,234.15,505,30,2,1,233.53,234.17,10,1,1,1,233.5,234.41,100,600,1,2,233.45,234.43,15,105,1,2,233.4,234.5,110,63,2,4,233.39,234.75,10,1,1,1,233.31,234.79,110,2000,2,1,AAPL,0.0,0.0,0.0,
2024-10-21 12:16:37.672903531+00:00,2024-10-21T12:16:37.673069955Z,10,2,38,A,B,2,233.68,27,130,166424,12574328,233.74,234.08,200,200,1,1,233.7,234.1,1200,100,1,1,233.68,234.13,27,400,1,1,233.66,234.15,1,30,1,1,233.58,234.17,505,1,2,1,233.53,234.41,10,600,1,2,233.5,234.43,100,105,1,2,233.45,234.5,15,63,1,4,233.4,234.75,110,1,2,1,233.39,234.79,10,2000,1,1,AAPL,0.0,0.0,0.0,
2024-10-21 12:16:41.310907658+00:00,2024-10-21T12:16:41.311074051Z,10,2,38,C,B,0,233.74,200,130,166393,12577924,233.7,234.08,1200,200,1,1,233.68,234.1,27,100,1,1,233.66,234.13,1,400,1,1,233.58,234.15,505,30,2,1,233.53,234.17,10,1,1,1,233.5,234.41,100,600,1,2,233.45,234.43,15,105,1,2,233.4,234.5,110,63,2,4,233.39,234.75,10,1,1,1,233.31,234.79,110,2000,2,1,AAPL,0.0,0.0,0.0,
2024-10-21 12:16:41.310921026+00:00,2024-10-21T12:16:41.311087986Z,10,2,38,A,B,1,233.69,200,130,166960,12577925,233.7,234.08,1200,200,1,1,233.69,234.1,200,100,1,1,233.68,234.13,27,400,1,1,233.66,234.15,1,30,1,1,233.58,234.17,505,1,2,1,233.53,234.41,10,600,1,2,233.5,234.43,100,105,1,2,233.45,234.5,15,63,1,4,233.4,234.75,110,1,2,1,233.39,234.79,10,2000,1,1,AAPL,0.0,0.0,0.0,
2024-10-21 12:16:42.498007357+00:00,2024-10-21T12:16:42.498174235Z,10,2,38,A,A,5,234.25,100,130,166878,12578938,233.7,234.08,1200,200,1,1,233.69,234.1,200,100,1,1,233.68,234.13,27,400,1,1,233.66,234.15,1,30,1,1,233.58,234.17,505,1,2,1,233.53,234.25,10,100,1,1,233.5,234.41,100,600,1,2,233.45,234.43,15,105,1,2,233.4,234.5,110,63,2,4,233.39,234.75,10,1,1,1,AAPL,0.0,0.0,0.0,
2024-10-21 12:16:44.366509790+00:00,2024-10-21T12:16:44.366676689Z,10,2,38,A,B,0,233.74,200,130,166899,12580824,233.74,234.08,200,200,1,1,233.7,234.1,1200,100,1,1,233.68,234.13,27,400,1,1,233.66,234.15,1,30,1,1,233.58,234.17,505,1,2,1,233.53,234.25,10,100,1,1,233.5,234.41,100,600,1,2,233.45,234.43,15,105,1,2,233.4,234.5,110,63,2,4,233.39,234.75,10,1,1,1,AAPL,0.0,0.0,0.0,
2024-10-21 12:16:44.533794596+00:00,2024-10-21T12:16:44.533960641Z,10,2,38,A,A,0,233.9,18,130,166045,12580968,233.74,233.9,200,18,1,1,233.7,234.08,1200,200,1,1,233.68,234.1,27,100,1,1,233.66,234.13,1,400,1,1,233.58,234.15,505,30,2,1,233.53,234.17,10,1,1,1,233.5,234.25,100,100,1,1,233.45,234.41,15,600,1,2,233.4,234.43,110,105,2,2,233.39,234.5,10,63,1,4,AAPL,0.0,0.0,0.0,
2024-10-21 12:16:44.802532155+00:00,2024-10-21T12:16:44.802698042Z,10,2,38,C,A,4,234.15,30,130,165887,12581165,233.74,233.9,200,18,1,1,233.7,234.08,1200,200,1,1,233.68,234.1,27,100,1,1,233.66,234.13,1,400,1,1,233.58,234.17,505,1,2,1,233.53,234.25,10,100,1,1,233.5,234.41,100,600,1,2,233.45,234.43,15,105,1,2,233.4,234.5,110,63,2,4,233.39,234.75,10,1,1,1,AAPL,0.0,0.0,0.0,
2024-10-21 12:16:44.802578420+00:00,2024-10-21T12:16:44.802744697Z,10,2,38,A,A,3,234.11,27,130,166277,12581166,233.74,233.9,200,18,1,1,233.7,234.08,1200,200,1,1,233.68,234.1,27,100,1,1,233.66,234.11,1,27,1,1,233.58,234.13,505,400,2,1,233.53,234.17,10,1,1,1,233.5,234.25,100,100,1,1,233.45,234.41,15,600,1,2,233.4,234.43,110,105,2,2,233.39,234.5,10,63,1,4,AAPL,0.0,0.0,0.0,
2024-10-21 12:16:47.612239006+00:00,2024-10-21T12:16:47.612405002Z,10,2,38,A,A,1,234.08,200,130,165996,12583335,233.74,233.9,200,18,1,1,233.7,234.08,1200,400,1,2,233.68,234.1,27,100,1,1,233.66,234.11,1,27,1,1,233.58,234.13,505,400,2,1,233.53,234.17,10,1,1,1,233.5,234.25,100,100,1,1,233.45,234.41,15,600,1,2,233.4,234.43,110,105,2,2,233.39,234.5,10,63,1,4,AAPL,0.0,-200.0,0.0,
2024-10-21 12:16:47.666876898+00:00,2024-10-21T12:16:47.667042872Z,10,2,38,C,A,1,234.08,200,130,165974,12583345,233.74,233.9,200,18,1,1,233.7,234.08,1200,200,1,1,233.68,234.1,27,100,1,1,233.66,234.11,1,27,1,1,233.58,234.13,505,400,2,1,233.53,234.17,10,1,1,1,233.5,234.25,100,100,1,1,233.45,234.41,15,600,1,2,233.4,234.43,110,105,2,2,233.39,234.5,10,63,1,4,AAPL,0.0,200.0,0.0,
2024-10-21 12:16:47.666890051+00:00,2024-10-21T12:16:47.667056416Z,10,2,38,A,A,1,234.04,200,130,166365,12583346,233.74,233.9,200,18,1,1,233.7,234.04,1200,200,1,1,233.68,234.1,27,100,1,1,233.66,234.11,1,27,1,1,233.58,234.13,505,400,2,1,233.53,234.17,10,1,1,1,233.5,234.25,100,100,1,1,233.45,234.41,15,600,1,2,233.4,234.43,110,105,2,2,233.39,234.5,10,63,1,4,AAPL,0.0,0.0,0.0,
2024-10-21 12:16:47.926797838+00:00,2024-10-21T12:16:47.926963883Z,10,2,38,C,B,0,233.74,200,130,166045,12583828,233.7,233.9,1200,18,1,1,233.68,234.04,27,200,1,1,233.66,234.1,1,100,1,1,233.58,234.11,505,27,2,1,233.53,234.13,10,400,1,1,233.5,234.17,100,1,1,1,233.45,234.25,15,100,1,1,233.4,234.41,110,600,2,2,233.39,234.43,10,105,1,2,233.31,234.5,110,63,2,4,AAPL,0.0,0.0,0.0,
2024-10-21 12:16:47.926810269+00:00,2024-10-21T12:16:47.926976599Z,10,2,38,A,B,1,233.68,200,130,166330,12583829,233.7,233.9,1200,18,1,1,233.68,234.04,227,200,2,1,233.66,234.1,1,100,1,1,233.58,234.11,505,27,2,1,233.53,234.13,10,400,1,1,233.5,234.17,100,1,1,1,233.45,234.25,15,100,1,1,233.4,234.41,110,600,2,2,233.39,234.43,10,105,1,2,233.31,234.5,110,63,2,4,AAPL,0.0,200.0,0.0,
2024-10-21 12:16:48.065603630+00:00,2024-10-21T12:16:48.065770361Z,10,2,38,C,A,3,234.11,27,130,166731,12584067,233.7,233.9,1200,18,1,1,233.68,234.04,227,200,2,1,233.66,234.1,1,100,1,1,233.58,234.13,505,400,2,1,233.53,234.17,10,1,1,1,233.5,234.25,100,100,1,1,233.45,234.41,15,600,1,2,233.4,234.43,110,105,2,2,233.39,234.5,10,63,1,4,233.31,234.75,110,1,2,1,AAPL,0.0,0.0,0.0,
2024-10-21 12:16:48.065661214+00:00,2024-10-21T12:16:48.065827712Z,10,2,38,A,A,2,234.06,29,130,166498,12584068,233.7,233.9,1200,18,1,1,233.68,234.04,227,200,2,1,233.66,234.06,1,29,1,1,233.58,234.1,505,100,2,1,233.53,234.13,10,400,1,1,233.5,234.17,100,1,1,1,233.45,234.25,15,100,1,1,233.4,234.41,110,600,2,2,233.39,234.43,10,105,1,2,233.31,234.5,110,63,2,4,AAPL,0.0,0.0,0.0,
2024-10-21 12:16:48.122967378+00:00,2024-10-21T12:16:48.123133937Z,10,2,38,A,A,1,234.01,200,130,166559,12584094,233.7,233.9,1200,18,1,1,233.68,234.01,227,200,2,1,233.66,234.06,1,29,1,1,233.58,234.1,505,100,2,1,233.53,234.13,10,400,1,1,233.5,234.17,100,1,1,1,233.45,234.25,15,100,1,1,233.4,234.41,110,600,2,2,233.39,234.43,10,105,1,2,233.31,234.5,110,63,2,4,AAPL,0.0,0.0,0.0,
2024-10-21 12:16:48.228366485+00:00,2024-10-21T12:16:48.228533367Z,10,2,38,A,A,1,234.01,200,130,166882,12584254,233.7,233.9,1200,18,1,1,233.68,234.01,227,400,2,2,233.66,234.06,1,29,1,1,233.58,234.1,505,100,2,1,233.53,234.13,10,400,1,1,233.5,234.17,100,1,1,1,233.45,234.25,15,100,1,1,233.4,234.41,110,600,2,2,233.39,234.43,10,105,1,2,233.31,234.5,110,63,2,4,AAPL,0.0,-200.0,0.0,
2024-10-21 12:16:48.283159712+00:00,2024-10-21T12:16:48.283326363Z,10,2,38,C,A,1,234.01,200,130,166651,12584287,233.7,233.9,1200,18,1,1,233.68,234.01,227,200,2,1,233.66,234.06,1,29,1,1,233.58,234.1,505,100,2,1,233.53,234.13,10,400,1,1,233.5,234.17,100,1,1,1,233.45,234.25,15,100,1,1,233.4,234.41,110,600,2,2,233.39,234.43,10,105,1,2,233.31,234.5,110,63,2,4,AAPL,0.0,200.0,0.0,
2024-10-21 12:16:48.283173265+00:00,2024-10-21T12:16:48.283339638Z,10,2,38,A,A,1,233.98,200,130,166373,12584288,233.7,233.9,1200,18,1,1,233.68,233.98,227,200,2,1,233.66,234.06,1,29,1,1,233.58,234.1,505,100,2,1,233.53,234.13,10,400,1,1,233.5,234.17,100,1,1,1,233.45,234.25,15,100,1,1,233.4,234.41,110,600,2,2,233.39,234.43,10,105,1,2,233.31,234.5,110,63,2,4,AAPL,0.0,0.0,0.0,
2024-10-21 12:16:49.563776410+00:00,2024-10-21T12:16:49.563943091Z,10,2,38,C,A,0,233.9,18,130,166681,12585847,233.7,233.98,1200,200,1,1,233.68,234.06,227,29,2,1,233.66,234.1,1,100,1,1,233.58,234.13,505,400,2,1,233.53,234.17,10,1,1,1,233.5,234.25,100,100,1,1,233.45,234.41,15,600,1,2,233.4,234.43,110,105,2,2,233.39,234.5,10,63,1,4,233.31,234.75,110,1,2,1,AAPL,0.0,0.0,0.0,
2024-10-21 12:16:49.564755651+00:00,2024-10-21T12:16:49.564921505Z,10,2,38,C,B,1,233.68,200,130,165854,12585849,233.7,233.98,1200,200,1,1,233.68,234.06,27,29,1,1,233.66,234.1,1,100,1,1,233.58,234.13,505,400,2,1,233.53,234.17,10,1,1,1,233.5,234.25,100,100,1,1,233.45,234.41,15,600,1,2,233.4,234.43,110,105,2,2,233.39,234.5,10,63,1,4,233.31,234.75,110,1,2,1,AAPL,0.0,-200.0,0.0,
2024-10-21 12:16:49.635124163+00:00,2024-10-21T12:16:49.635290441Z,10,2,38,C,A,0,233.98,200,130,166278,12585962,233.7,234.06,1200,29,1,1,233.68,234.1,27,100,1,1,233.66,234.13,1,400,1,1,233.58,234.17,505,1,2,1,233.53,234.25,10,100,1,1,233.5,234.41,100,600,1,2,233.45,234.43,15,105,1,2,233.4,234.5,110,63,2,4,233.39,234.75,10,1,1,1,233.31,234.79,110,2000,2,1,AAPL,0.0,0.0,0.0,
2024-10-21 12:16:49.635136826+00:00,2024-10-21T12:16:49.635302899Z,10,2,38,A,A,0,234.04,400,130,166073,12585963,233.7,234.04,1200,400,1,1,233.68,234.06,27,29,1,1,233.66,234.1,1,100,1,1,233.58,234.13,505,400,2,1,233.53,234.17,10,1,1,1,233.5,234.25,100,100,1,1,233.45,234.41,15,600,1,2,233.4,234.43,110,105,2,2,233.39,234.5,10,63,1,4,233.31,234.75,110,1,2,1,AAPL,0.0,0.0,0.0,
2024-10-21 12:16:49.635541646+00:00,2024-10-21T12:16:49.635707853Z,10,2,38,C,A,1,234.06,29,130,166207,12585964,233.7,234.04,1200,400,1,1,233.68,234.1,27,100,1,1,233.66,234.13,1,400,1,1,233.58,234.17,505,1,2,1,233.53,234.25,10,100,1,1,233.5,234.41,100,600,1,2,233.45,234.43,15,105,1,2,233.4,234.5,110,63,2,4,233.39,234.75,10,1,1,1,233.31,234.79,110,2000,2,1,AAPL,0.0,0.0,0.0,
2024-10-21 12:16:49.635636984+00:00,2024-10-21T12:16:49.635803361Z,10,2,38,A,A,2,234.11,29,130,166377,12585965,233.7,234.04,1200,400,1,1,233.68,234.1,27,100,1,1,233.66,234.11,1,29,1,1,233.58,234.13,505,400,2,1,233.53,234.17,10,1,1,1,233.5,234.25,100,100,1,1,233.45,234.41,15,600,1,2,233.4,234.43,110,105,2,2,233.39,234.5,10,63,1,4,233.31,234.75,110,1,2,1,AAPL,0.0,0.0,0.0,
2024-10-21 12:16:49.669495875+00:00,2024-10-21T12:16:49.669662206Z,10,2,38,A,B,1,233.68,200,130,166331,12585982,233.7,234.04,1200,400,1,1,233.68,234.1,227,100,2,1,233.66,234.11,1,29,1,1,233.58,234.13,505,400,2,1,233.53,234.17,10,1,1,1,233.5,234.25,100,100,1,1,233.45,234.41,15,600,1,2,233.4,234.43,110,105,2,2,233.39,234.5,10,63,1,4,233.31,234.75,110,1,2,1,AAPL,0.0,200.0,0.0,
2024-10-21 12:16:49.706243840+00:00,2024-10-21T12:16:49.706410056Z,10,2,38,C,A,0,234.04,200,130,166216,12585991,233.7,234.04,1200,200,1,1,233.68,234.1,227,100,2,1,233.66,234.11,1,29,1,1,233.58,234.13,505,400,2,1,233.53,234.17,10,1,1,1,233.5,234.25,100,100,1,1,233.45,234.41,15,600,1,2,233.4,234.43,110,105,2,2,233.39,234.5,10,63,1,4,233.31,234.75,110,1,2,1,AAPL,200.0,200.0,200.0,
2024-10-21 12:16:49.706441749+00:00,2024-10-21T12:16:49.706607779Z,10,2,38,C,A,0,234.04,200,130,166030,12585992,233.7,234.1,1200,100,1,1,233.68,234.11,227,29,2,1,233.66,234.13,1,400,1,1,233.58,234.17,505,1,2,1,233.53,234.25,10,100,1,1,233.5,234.41,100,600,1,2,233.45,234.43,15,105,1,2,233.4,234.5,110,63,2,4,233.39,234.75,10,1,1,1,233.31,234.79,110,2000,2,1,AAPL,0.0,0.0,200.0,
2024-10-21 12:16:49.706453582+00:00,2024-10-21T12:16:49.706619859Z,10,2,38,A,A,0,234.09,200,130,166277,12585993,233.7,234.09,1200,200,1,1,233.68,234.1,227,100,2,1,233.66,234.11,1,29,1,1,233.58,234.13,505,400,2,1,233.53,234.17,10,1,1,1,233.5,234.25,100,100,1,1,233.45,234.41,15,600,1,2,233.4,234.43,110,105,2,2,233.39,234.5,10,63,1,4,233.31,234.75,110,1,2,1,AAPL,0.0,0.0,200.0,
2024-10-21 12:16:49.707051448+00:00,2024-10-21T12:16:49.707217404Z,10,2,38,C,A,2,234.11,29,130,165956,12585994,233.7,234.09,1200,200,1,1,233.68,234.1,227,100,2,1,233.66,234.13,1,400,1,1,233.58,234.17,505,1,2,1,233.53,234.25,10,100,1,1,233.5,234.41,100,600,1,2,233.45,234.43,15,105,1,2,233.4,234.5,110,63,2,4,233.39,234.75,10,1,1,1,233.31,234.79,110,2000,2,1,AAPL,0.0,0.0,200.0,
